<mujoco model="template">
  
  
  <compiler inertiafromgeom="auto" angle="radian" balanceinertia="true" boundmass="0.25" boundinertia="0.01" inertiagrouprange="0 1">
    <lengthrange inttotal="50" useexisting="true" />
  </compiler>
  <option />
  <visual>
    <scale framelength="0.5" framewidth="0.01" />
  </visual>
  <default>
    <joint limited="true" damping="0.05" armature="0.01" stiffness="0" />
    <geom rgba="0.8 0.6 .4 1" margin="0.001" contype="0" conaffinity="0" />
    <site size="0.001" />
    <tendon width="0.005" rgba=".95 .3 .3 1" limited="false" />
    <default class="muscle">
      <muscle ctrllimited="true" ctrlrange="0 1" scale="200" />
    </default>
    <default class="motor">
      <general gainprm="5 0 0 0 0 0 0 0 0 0" />
    </default>
  </default>
  <option timestep="0.002" />
  
  <size njmax="1000" nconmax="400" nuser_jnt="1" nkey="1" />
  <worldbody>
    
    <body name="ground" euler="1.571 0 0">
      <geom name="ground-plane" pos="0 0 0" euler="-1.571 0 0" size="10 10 0.125" type="plane" rgba="1.0 0.7 0.4 1.0" condim="3" />
    </body>
    <light directional="true" />
    <body name="pelvis" pos="0 0 0" euler="1.571 0 0">
      <inertial mass="10.9677960104" pos="-0.0707000000 0.0000000000 0.0000000000" fullinertia="0.0957365568 0.0811153123 0.0539216599 0.0000000000 0.0000000000 0.0000000000" />
      <geom name="pelvis_geom_1" type="mesh" mesh="pelvis_geom_1_r_pelvis" rgba="1 1 1 1" group="0" />
      <geom name="pelvis_geom_2" type="mesh" mesh="pelvis_geom_2_l_pelvis" rgba="1 1 1 1" group="0" />
      <geom name="pelvis_geom_3" type="mesh" mesh="pelvis_geom_3_sacrum" rgba="1 1 1 1" group="0" />
      <geom name="Gmax1_at_pelvis_r_cylinder" type="cylinder" euler="-0.6 0.45 0" pos="-0.08732 -0.1012 0.06807" size="0.04357 0.0822" rgba="0.19 0.83 0.78 0.2" group="2" />
      <site name="Gmax1_at_pelvis_r_sidesite" pos="-0.1275 -0.09026 0.08407" size="0.0005" />
      <geom name="Gmax2_at_pelvis_r_cylinder" type="cylinder" euler="-0.75 0.39 0" pos="-0.09073 -0.08485 0.07589" size="0.04385 0.05412" rgba="0.19 0.83 0.78 0.2" group="2" />
      <geom name="Gmax3_at_pelvis_r_cylinder" type="cylinder" euler="-0.1 0 0" pos="-0.09413 -0.08996 0.07589" size="0.04315 0.05575" rgba="0.19 0.83 0.78 0.2" group="2" />
      <geom name="Gmax1_at_pelvis_l_cylinder" type="cylinder" euler="0.6 -0.45 0" pos="-0.08732 -0.1012 -0.06807" size="0.04357 0.0822" rgba="0.19 0.83 0.78 0.2" group="2" />
      <site name="Gmax1_at_pelvis_l_sidesite" pos="-0.1275 -0.09026 -0.08407" size="0.0005" />
      <geom name="Gmax2_at_pelvis_l_cylinder" type="cylinder" euler="0.75 -0.39 0" pos="-0.09073 -0.08485 -0.07589" size="0.04385 0.05412" rgba="0.19 0.83 0.78 0.2" group="2" />
      <geom name="Gmax3_at_pelvis_l_cylinder" type="cylinder" euler="0.1 0 0" pos="-0.09413 -0.08996 -0.07589" size="0.04315 0.05575" rgba="0.19 0.83 0.78 0.2" group="2" />
      <geom name="PS_at_brim_r_cylinder" type="cylinder" euler="-0.25 -0.27 0.1" pos="-0.08392 -0.06133 0.07321" size="0.05402 0.05561" rgba="0.19 0.83 0.78 0.2" group="2" />
      <site name="PS_at_brim_r_sidesite" pos="-0.07863 -0.114 0.08817" size="0.0005" />
      <geom name="PS_at_brim_l_cylinder" type="cylinder" euler="0.25 0.27 0.1" pos="-0.08392 -0.06133 -0.07321" size="0.05402 0.05561" rgba="0.19 0.83 0.78 0.2" group="2" />
      <site name="PS_at_brim_l_sidesite" pos="-0.07863 -0.114 -0.08817" size="0.0005" />
      <geom name="IL_at_brim_r_cylinder" type="cylinder" euler="-0.32 -0.24 0.9" pos="-0.08052 -0.06645 0.08437" size="0.05947 0.05543" rgba="0.19 0.83 0.78 0.2" group="2" />
      <site name="IL_at_brim_r_sidesite" pos="-0.03451 -0.09858 0.1069" size="0.0005" />
      <geom name="IL_at_brim_l_cylinder" type="cylinder" euler="0.32 0.24 0.9" pos="-0.08052 -0.06645 -0.08437" size="0.05947 0.05543" rgba="0.19 0.83 0.78 0.2" group="2" />
      <site name="IL_at_brim_l_sidesite" pos="-0.03451 -0.09858 -0.1069" size="0.0005" />
      <joint name="pelvis_tx" range="-40 40" limited="true" user="0.0" ref="0" axis="1 0 0" type="slide" damping="0" stiffness="0" />
      <joint name="pelvis_ty" range="-5 5" limited="true" user="0.93" ref="0" axis="0 1 0" type="slide" damping="0" stiffness="0" />
      <joint name="pelvis_tz" range="-40 40" limited="true" user="0.0" ref="0" axis="0 0 1" type="slide" damping="0" stiffness="0" />
      <joint name="pelvis_tilt" range="-3.142 3.142" limited="true" user="0.0" ref="0" axis="0 0 1" type="hinge" damping="0" stiffness="0" />
      <joint name="pelvis_list" range="-3.142 3.142" limited="true" user="0.0" ref="0" axis="1 0 0" type="hinge" damping="0" stiffness="0" />
      <joint name="pelvis_rotation" range="-3.142 3.142" limited="true" user="0.0" ref="0" axis="0 1 0" type="hinge" damping="0" stiffness="0" />
      <body name="femur_r" pos="-0.06382 -0.08023 0.08622" euler="-0 0 0">
        <inertial mass="8.6622958148" pos="0.0000000000 -0.1700000000 0.0000000000" fullinertia="0.1246996591 0.0326882602 0.1314980722 0.0000000000 0.0000000000 0.0000000000" />
        <geom name="femur_r_geom_1" type="mesh" mesh="femur_r_geom_1_r_femur" rgba="1 1 1 1" group="0" />
        <geom name="Gastroc_at_condyles_r_cylinder" type="cylinder" euler="0 0 0" pos="0.004422 -0.3648 0" size="0.02218 0.04425" rgba="0.19 0.83 0.78 0.2" group="2" />
        <geom name="KnExt_at_fem_r_cylinder" type="cylinder" euler="-0.06234 0.05076 0" pos="0.003173 -0.3583 0.001851" size="0.02218 0.04425" rgba="0.19 0.83 0.78 0.2" group="2" />
        <geom name="AB_at_femshaft_r_cylinder" type="cylinder" euler="1.662 0.1866 0" pos="0.01295 -0.1002 0.02068" size="0.0146 0.03113" rgba="0.19 0.83 0.78 0.2" group="2" />
        <geom name="AL_at_femshaft_r_cylinder" type="cylinder" euler="1.777 0.1365 0" pos="0.02718 -0.2063 0.01338" size="0.01779 0.04447" rgba="0.19 0.83 0.78 0.2" group="2" />
        <geom name="AMprox_at_femshaft_r_cylinder" type="cylinder" euler="1.611 0.1866 0" pos="0.004584 -0.06485 0.02248" size="0.01867 0.03113" rgba="0.19 0.83 0.78 0.2" group="2" />
        <geom name="AMmid_at_femshaft_r_cylinder" type="cylinder" euler="1.611 0.1366 0" pos="0.02035 -0.143 0.01822" size="0.01893 0.05338" rgba="0.19 0.83 0.78 0.2" group="2" />
        <geom name="AMdist_at_femshaft_r_cylinder" type="cylinder" euler="1.712 0.1866 0" pos="0.02795 -0.232 0.008288" size="0.01929 0.08894" rgba="0.19 0.83 0.78 0.2" group="2" />
        <geom name="AMisch_at_condyles_r_cylinder" type="cylinder" euler="1.711 -0.4634 0" pos="-0.02003 -0.3353 -0.002792" size="0.03541 0.1066" rgba="0.19 0.83 0.78 0.2" group="2" />
        <geom name="PECT_at_femshaft_r_cylinder" type="cylinder" euler="1.813 0.2763 0" pos="0.005382 -0.07518 0.02694" size="0.01328 0.02223" rgba="0.19 0.83 0.78 0.2" group="2" />
        <joint name="hip_flexion_r" range="-0.5236 2.094" limited="true" user="0.0" ref="0" axis="0 0 1" type="hinge" />
        <joint name="hip_adduction_r" range="-0.8727 0.5236" limited="true" user="0.0" ref="0" axis="1 0 0" type="hinge" />
        <joint name="hip_rotation_r" range="-0.6981 0.6981" limited="true" user="0.0" ref="0" axis="0 1 0" type="hinge" />
        <body name="tibia_r" pos="0.001926 -0.3587 -0.0007185" euler="-0 0 0">
          <inertial mass="3.4527556855" pos="0.0000000000 -0.1867000000 0.0000000000" fullinertia="0.046936989 0.01 0.0475888916 0.0 0.0 0.0" />
          <geom name="tibia_r_geom_1" type="mesh" mesh="tibia_r_geom_1_r_tibia" rgba="1 1 1 1" group="0" />
          <geom name="tibia_r_geom_2" type="mesh" mesh="tibia_r_geom_2_r_fibula" rgba="1 1 1 1" group="0" />
          <geom name="GasLat_at_shank_r_cylinder" type="cylinder" euler="2.967 -0.2797 -1.478" pos="-0.008306 -0.08974 -0.003812" size="0.06425 0.05772" rgba="0.19 0.83 0.78 0.2" group="2" />
          <site name="GasLat_at_shank_r_sidesite" pos="-0.07075 -0.08068 0.0128" size="0.0005" />
          <geom name="GasMed_at_shank_r_cylinder" type="cylinder" euler="2.967 0.02797 -1.478" pos="-0.008306 -0.08974 -0.003812" size="0.06417 0.05785" rgba="0.19 0.83 0.78 0.2" group="2" />
          <site name="GasMed_at_shank_r_sidesite" pos="-0.07317 -0.08411 -0.006646" size="0.0005" />
          <geom name="GR_at_condyles_r_cylinder" type="cylinder" euler="0 -0.4 0" pos="-0.003367 -0.02425 0" size="0.04212 0.05752" rgba="0.19 0.83 0.78 0.2" group="2" />
          <geom name="SM_at_condyles_r_cylinder" type="cylinder" euler="0 -0.1 0" pos="-0.001122 -0.02425 0" size="0.0411 0.05775" rgba="0.19 0.83 0.78 0.2" group="2" />
          <geom name="ST_at_condyles_r_cylinder" type="cylinder" euler="0 -0.2 0" pos="-0.002245 -0.02486 0" size="0.04965 0.0577" rgba="0.19 0.83 0.78 0.2" group="2" />
          <geom name="BF_at_gastroc_r_cylinder" type="cylinder" euler="0 0 0" pos="-0.0651 -0.07276 0" size="0.03503 0.08665" rgba="0.19 0.83 0.78 0.2" group="2" />
          <site name="BF_at_gastroc_r_sidesite" pos="-0.0651 -0.03673 0" size="0.0005" />
          <joint name="walker_knee_r_translation1" range="0 0.001423" limited="true" user="8.485342442902076e-08" ref="0" axis="-0.1243 0.9898 -0.07016" type="slide" />
          <joint name="walker_knee_r_translation2" range="0 0.006011" limited="true" user="6.808143371977993e-11" ref="0" axis="0.9922 0.124 -0.008789" type="slide" />
          <joint name="knee_angle_r" range="0 2.094" limited="true" user="0.0" ref="0" axis="-4.566e-07 -0.07071 -0.9975" type="hinge" />
          <joint name="walker_knee_r_rotation2" range="-0.001678 0.03354" limited="true" user="-1.4732523263838448e-08" ref="0" axis="0.9922 0.124 -0.008789" type="hinge" />
          <joint name="walker_knee_r_rotation3" range="0 0.2628" limited="true" user="1.0893911855935912e-08" ref="0" axis="-0.1243 0.9898 -0.07016" type="hinge" />
          <body name="talus_r" pos="-0.01122 -0.4851 0" euler="-0 0 0">
            <inertial mass="0.25" pos="0.0000000000 0.0000000000 0.0000000000" fullinertia="0.01 0.01 0.01 0.0 0.0 0.0" />
            <geom name="talus_r_geom_1" type="mesh" mesh="talus_r_geom_1_r_talus" rgba="1 1 1 0" group="0" />
            <joint name="ankle_angle_r" range="-0.6981 0.5236" limited="true" user="0.0" ref="0" type="hinge" axis="-0.105 -0.174 0.9791" />
            <body name="calcn_r" pos="-0.04704 -0.04145 0.007727" euler="-0 0 0">
              <inertial mass="1.1641118292" pos="0.1000000000 0.0300000000 0.0000000000" fullinertia="0.01 0.01 0.01 0.0 0.0 0.0" />
              <geom name="calcn_r_geom_1" type="mesh" mesh="calcn_r_geom_1_r_foot" rgba="1 1 1 1" group="0" />
              <joint name="subtalar_angle_r" range="-0.3491 0.3491" limited="true" user="0.0" ref="0" type="hinge" axis="0.7872 0.6047 -0.1209" />
              <body name="toes_r" pos="0.2039 -0.002257 0.001224" euler="-0 0 0">
                <inertial mass="0.25" pos="0.0346000000 0.0060000000 -0.0175000000" fullinertia="0.01 0.01 0.01 0.0 0.0 0.0" />
                <geom name="toes_r_geom_1" type="mesh" mesh="toes_r_geom_1_r_bofoot" rgba="1 1 1 1" group="0" />
                <joint name="mtp_angle_r" range="-0.5236 0.5236" limited="true" user="0.0" ref="0" type="hinge" axis="0.581 2.16e-06 -0.8139" />
                <site name="edl_r_edl_r-P5" pos="0.00031763566247999998 0.0049756477507199998 0.01620108747945" />
                <site name="edl_r_edl_r-P6" pos="0.046904199492880001 -0.00042345938304 0.026472365162500001" />
                <site name="ehl_r_ehl_r-P7" pos="0.031551809139680004 0.0043404586761599997 -0.02594291785925" />
                <site name="ehl_r_ehl_r-P8" pos="0.059609625992080008 0.0035994047558399996 -0.019695439680899998" />
                <site name="fdl_r_fdl_r-P6" pos="-0.00201169252904 -0.0082574579692799993 0.015565750715549999" />
                <site name="fdl_r_fdl_r-P7" pos="0.030175387935600002 -0.0075164040489600001 0.022766234039749998" />
                <site name="fdl_r_fdl_r-P8" pos="0.046692442384560003 -0.0063518907455999999 0.025625249477300001" />
                <site name="fhl_r_fhl_r-P6" pos="0.016411175894800002 -0.00677535012864 -0.028060707072249998" />
                <site name="fhl_r_fhl_r-P7" pos="0.059503747437920002 -0.01079821426752 -0.019165992377650001" />
              </body>
              <site name="edl_r_edl_r-P3" pos="0.10478358005645 0.0406219696812 0.00090661487255999998" />
              <site name="edl_r_edl_r-P4" pos="0.18425491335279998 0.0062061342568499999 0.014732491679099999" />
              <site name="ehl_r_ehl_r-P4" pos="0.11059855566350001 0.043894295016629996 -0.023911967263770002" />
              <site name="ehl_r_ehl_r-P5" pos="0.14742673450815 0.034867190643030004 -0.029125002780989999" />
              <site name="ehl_r_ehl_r-P6" pos="0.1977091706397 0.015684593849129999 -0.031731520539600003" />
              <site name="fdl_r_fdl_r-P3" pos="0.049712340483800001 0.035544223471050004 -0.031731520539600003" />
              <site name="fdl_r_fdl_r-P4" pos="0.080725543721400006 0.019859629621920002 -0.02980496393541" />
              <site name="fdl_r_fdl_r-P5" pos="0.1890437167939 -0.0091399431782700005 0.013145915652119998" />
              <site name="fhl_r_fhl_r-P3" pos="0.042643154451699999 0.031143510088919999 -0.027311773035869999" />
              <site name="fhl_r_fhl_r-P4" pos="0.1183518564729 0.0076730387175600002 -0.029011675921919999" />
              <site name="fhl_r_fhl_r-P5" pos="0.19679701760330001 -0.0059804566475099999 -0.030484925089830001" />
              <site name="gaslat_r_gaslat_r-P2" pos="0.0050168417002000006 0.034980029447699998 -0.0060063235307099994" />
              <site name="gasmed_r_gasmed_r-P2" pos="0.0050168417002000006 0.034980029447699998 -0.0060063235307099994" />
              <site name="perbrev_r_perbrev_r-P4" pos="0.053703010018050001 0.030466477260900002 0.026405158163309999" />
              <site name="perbrev_r_perbrev_r-P5" pos="0.077190950705349995 0.024711698222729998 0.038871112661009996" />
              <site name="perlong_r_perlong_r-P4" pos="0.049940378742899999 0.025952925074099999 0.025045235854470001" />
              <site name="perlong_r_perlong_r-P5" pos="0.077647027223549991 0.01196091329502 0.032184827975880001" />
              <site name="perlong_r_perlong_r-P6" pos="0.097144298376599991 0.0077858775222299998 0.013372569370259999" />
              <site name="perlong_r_perlong_r-P7" pos="0.13716501284865001 0.0095912983969500005 -0.02085214206888" />
              <site name="soleus_r_soleus_r-P2" pos="0.0050168417002000006 0.034980029447699998 -0.0060063235307099994" />
              <site name="tibant_r_tibant_r-P4" pos="0.1329463050553 0.020085307231260001 -0.034564692016349999" />
              <site name="tibpost_r_tibpost_r-P3" pos="0.04754597702235 0.037688160759780001 -0.03241148169402" />
              <site name="tibpost_r_tibpost_r-P4" pos="0.088022768012600006 0.017941369942530001 -0.031844847398670002" />
              <site name="RToe_marker" group="4" pos="0.274 0.01524 0.01559" rgba="1 0.1 0.5 0.5" size="0.01" />
              <site name="RMidfootLateral_marker" group="4" pos="0.1783 -0.01434 0.07063" rgba="1 0.1 0.5 0.5" size="0.01" />
              <site name="RHeel_marker" group="4" pos="-0.03268 0.01452 -0.0108" rgba="1 0.1 0.5 0.5" size="0.01" />
            </body>
          </body>
          <site name="bflh_r_bflh_r-P2" pos="-0.037826974495440001 -0.042444267309500003 0.029228978543380003" />
          <site name="bflh_r_bflh_r-P3" pos="-0.03221466373944 -0.055177547502350002 0.035005456516380005" />
          <site name="bfsh_r_bfsh_r-P2" pos="-0.033786110751119994 -0.050811851436230002 0.036738399908280005" />
          <site name="edl_r_edl_r-P1" pos="-0.017959394419199998 -0.14030862079169001 0.023683559689300002" />
          <site name="edl_r_edl_r-P2" pos="0.01840837927968 -0.4559727002392 0.01293931065952" />
          <site name="ehl_r_ehl_r-P1" pos="-0.015714470116799998 -0.18796746951349999 0.021835086737940001" />
          <site name="ehl_r_ehl_r-P2" pos="0.0079694812735200005 -0.35277249600952998 0.018946847751440003" />
          <site name="ehl_r_ehl_r-P3" pos="0.022449243024000001 -0.44784765478281002 -0.00323482766488" />
          <site name="fdl_r_fdl_r-P1" pos="-0.0025816629477599996 -0.22216542203144002 -0.00207953207028" />
          <site name="fdl_r_fdl_r-P2" pos="-0.019755333861119998 -0.44202672669464999 -0.014325665373040001" />
          <site name="fhl_r_fhl_r-P1" pos="-0.034796326687200001 -0.26230557197270998 0.023105911892000001" />
          <site name="fhl_r_fhl_r-P2" pos="-0.027163584059039996 -0.44517972940906997 -0.0087802465189600002" />
          <site name="GasLat_at_shank_r_cylinder_gaslat_r_1_sidesite" pos="-0.02662 -0.1012 0.05776" size="0.0005" />
          <site name="GasMed_at_shank_r_cylinder_gasmed_r_1_sidesite" pos="-0.005163 -0.107 -0.06657" size="0.0005" />
          <site name="grac_r_grac_r-P2" pos="-0.020675752825103998 -0.057663568873335007 -0.034208302556106004" />
          <site name="grac_r_grac_r-P3" pos="0.001997982629136 -0.084427711145354009 -0.018172799703058004" />
          <site name="GR_at_condyles_r_cylinder_grac_r_1_sidesite" pos="-0.01853 -0.01664 -0.03964" size="0.0005" />
          <site name="perbrev_r_perbrev_r-P1" pos="-0.027275830274159998 -0.30705395665044 0.028997919424460002" />
          <site name="perbrev_r_perbrev_r-P2" pos="-0.038051466925679997 -0.47210152181680998 0.028766860305540001" />
          <site name="perbrev_r_perbrev_r-P3" pos="-0.031990171309199997 -0.48556241802068001 0.029460037662300001" />
          <site name="perlong_r_perlong_r-P1" pos="-0.022449243024000001 -0.16650279718841002 0.03257933576772" />
          <site name="perlong_r_perlong_r-P2" pos="-0.035582050193039998 -0.47295040716300002 0.027380505592020002" />
          <site name="perlong_r_perlong_r-P3" pos="-0.030530970512639997 -0.48677511137238 0.027727094270400002" />
          <site name="recfem_r_recfem_r-P5" pos="0.036592266129119991 -0.076545204359303995 -0.00054298892946199999" />
          <site name="sart_r_sart_r-P3" pos="-0.02817379999512 -0.048629003403169994 -0.0421682892029" />
          <site name="sart_r_sart_r-P4" pos="-0.01784714820408 -0.072640331766830005 -0.030499803697440001" />
          <site name="sart_r_sart_r-P5" pos="0.015265485256319999 -0.0982281614877 -0.0030037685459600003" />
          <site name="semimem_r_semimem_r-P2" pos="-0.032551402384799998 -0.050569312765890002 -0.022643793654159999" />
          <site name="SM_at_condyles_r_cylinder_semimem_r_1_sidesite" pos="-0.03449 -0.009129 -0.02201" size="0.0005" />
          <site name="semiten_r_semiten_r-P2" pos="-0.035020819117439997 -0.06160482226636 -0.026456269116340001" />
          <site name="semiten_r_semiten_r-P3" pos="0.0021326780872799999 -0.093741196086409989 -0.013516958456820001" />
          <site name="ST_at_condyles_r_cylinder_semiten_r_1_sidesite" pos="-0.04237 -0.01956 -0.03045" size="0.0005" />
          <site name="soleus_r_soleus_r-P1" pos="-0.0085307123491199996 -0.11108271101572001 0.01132189682708" />
          <site name="tfl_r_tfl_r-P4" pos="0.012122591232960001 -0.049720427419700002 0.039973227573159999" />
          <site name="tibant_r_tibant_r-P1" pos="0.017285917128479999 -0.15910536774304002 0.018715788632519999" />
          <site name="tibant_r_tibant_r-P2" pos="0.02817379999512 -0.23113935283401998 0.014787783610880002" />
          <site name="tibant_r_tibant_r-P3" pos="0.02615336812296 -0.44372449738703001 -0.01524990184872" />
          <site name="tibpost_r_tibpost_r-P1" pos="-0.0046020948199200001 -0.15813521306167999 0.011899544624380001" />
          <site name="tibpost_r_tibpost_r-P2" pos="-0.01840837927968 -0.44323942004634997 -0.020217672905500004" />
          <site name="vasint_r_vasint_r-P5" pos="0.036558592264584001 -0.076642219827440003 0.00049677710567799999" />
          <site name="vaslat_r_vaslat_r-P5" pos="0.036524918400047998 -0.076860504630746007 0.0059035604884060001" />
          <site name="vasmed_r_vasmed_r-P5" pos="0.035806542623279994 -0.077090916367568998 -0.0078329041313879993" />
          <site name="RShankSuperior_marker" group="4" pos="-0.04353 -0.1676 0.05857" rgba="1 0.1 0.5 0.5" size="0.01" />
          <site name="RShankInferior_marker" group="4" pos="-0.02341 -0.3744 0.0526" rgba="1 0.1 0.5 0.5" size="0.01" />
          <site name="RShankLateral_marker" group="4" pos="0.03874 -0.2453 -0.0119" rgba="1 0.1 0.5 0.5" size="0.01" />
        </body>
        <body name="patella_r" pos="-0.007155 -0.363 -0.002434" euler="-0 0 0">
          <inertial mass="0.25" pos="0.0018 0.0264 0" fullinertia="0.01 0.01 0.01 0.0 0.0 0.0" />
          <geom name="patella_r_geom_1" type="mesh" mesh="patella_r_geom_1_r_patella" rgba="1 1 1 1" group="0" />
          <joint name="patellofemoral_r_translation1" range="-0.02008 0.04634" limited="true" user="0.046358158050911126" ref="0" axis="1 0 0" type="slide" />
          <joint name="patellofemoral_r_translation2" range="-0.0363 -0.009609" limited="true" user="-0.009633759440743413" ref="0" axis="0 1 0" type="slide" />
          <joint name="patellofemoral_r_translation3" limited="false" ref="0" axis="0 0 1" type="slide" />
          <joint name="patellofemoral_r_rotation1" range="-1.786 0.001137" limited="true" user="0.01050598499723554" ref="0" axis="0 0 1" type="hinge" />
          <site name="recfem_r_recfem_r-P2" pos="0.01 0.049000000000000002 0.00069999999999999999" />
          <site name="recfem_r_recfem_r-P3" pos="0.0121 0.043700000000000003 -0.001" />
          <site name="recfem_r_recfem_r-P4" pos="0.0050000000000000001 0.00247 3.0000000000000001e-05" />
          <site name="vasint_r_vasint_r-P3" pos="0.0057999999999999996 0.048000000000000001 -0.00059999999999999995" />
          <site name="vasint_r_vasint_r-P4" pos="0.0050000000000000001 0.00247 -0.00038999999999999999" />
          <site name="vaslat_r_vaslat_r-P3" pos="0.0103 0.042299999999999997 0.0141" />
          <site name="vaslat_r_vaslat_r-P4" pos="0.0050000000000000001 0.00247 0.0073299999999999997" />
          <site name="vasmed_r_vasmed_r-P3" pos="0.0063 0.044499999999999998 -0.017000000000000001" />
          <site name="vasmed_r_vasmed_r-P4" pos="0.0050000000000000001 0.00247 -0.0085000000000000006" />
        </body>
        <site name="addbrev_r_addbrev_r-P2" pos="-0.0017687462128000001 -0.10498430664019999 0.022037284170720001" />
        <site name="AB_at_femshaft_r_cylinder_addbrev_r_1_sidesite" pos="0.002091 -0.09455 0.01101" size="0.0005" />
        <site name="addlong_r_addlong_r-P2" pos="0.0099580411780639984 -0.21296689390224299 0.014010048531024001" />
        <site name="AL_at_femshaft_r_cylinder_addlong_r_1_sidesite" pos="0.009958 -0.213 0.01401" size="0.0005" />
        <site name="addmagDist_r_addmagDist_r-P2" pos="0.0099491974469999994 -0.23354559739875 0.017081107811040001" />
        <site name="AMdist_at_femshaft_r_cylinder_addmagDist_r_1_sidesite" pos="0.009949 -0.2335 0.01708" size="0.0005" />
        <site name="addmagIsch_r_addmagIsch_r-P2" pos="0.0042538346417839998 -0.34517594446778299 -0.028967080759344004" />
        <site name="AMisch_at_condyles_r_cylinder_addmagIsch_r_1_sidesite" pos="0.004254 -0.3452 -0.02897" size="0.0005" />
        <site name="addmagMid_r_addmagMid_r-P2" pos="0.0021401829174879997 -0.14448687625735998 0.025860620219616" />
        <site name="AMmid_at_femshaft_r_cylinder_addmagMid_r_1_sidesite" pos="0.00214 -0.1445 0.02586" size="0.0005" />
        <site name="addmagProx_r_addmagProx_r-P2" pos="-0.013504377334728 -0.070161545946153994 0.028338708399456" />
        <site name="AMprox_at_femshaft_r_cylinder_addmagProx_r_1_sidesite" pos="-0.01373 -0.06597 0.0154" size="0.0005" />
        <site name="bfsh_r_bfsh_r-P1" pos="0.0044218655320000001 -0.18781514518428999 0.020709736931520003" />
        <site name="gaslat_r_gaslat_r-P1" pos="-0.0026531193192 -0.33933063180146 0.024515372350560002" />
        <site name="gasmed_r_gasmed_r-P1" pos="0.0070749848512000005 -0.33701741826532 -0.018408655050239999" />
        <site name="glmax1_r_glmax1_r-P3" pos="-0.039266165924160004 -0.029004138953139996 0.026727951082560004" />
        <site name="glmax1_r_glmax1_r-P4" pos="-0.024497135047279999 -0.050356879286739993 0.041596480161600002" />
        <site name="glmax2_r_glmax2_r-P3" pos="-0.039796789787999998 -0.051958334811760001 0.02230279361856" />
        <site name="glmax2_r_glmax2_r-P4" pos="-0.013796220459839999 -0.090393267412239992 0.037082819548320003" />
        <site name="glmax3_r_glmax3_r-P3" pos="-0.024850884289839999 -0.10009097031375 0.0083192960323200012" />
        <site name="glmax3_r_glmax3_r-P4" pos="-0.0053062386384 -0.12624807722240999 0.036374794354079996" />
        <site name="glmed1_r_glmed1_r-P2_0" pos="-0.01228549427172616 -0.016276753673209486 0.052384677497075052" />
        <site name="glmed2_r_glmed2_r-P2_0" pos="-0.019488058397820425 -0.0088605838398971137 0.049673475474807771" />
        <site name="glmed3_r_glmed3_r-P2_0" pos="-0.027327128987760001 -0.00418157831533 0.045844631327040003" />
        <site name="glmin1_r_glmin1_r-P2" pos="0.0048546058998626242 -0.013780169896762574 0.04959522018793483" />
        <site name="glmin2_r_glmin2_r-P2" pos="0.0031338123002631144 -0.0080181932995790801 0.046432582271022635" />
        <site name="glmin3_r_glmin3_r-P2" pos="-0.003162639685971616 -0.0011269805249016973 0.045368174205393304" />
        <site name="iliacus_r_iliacus_r-P3" pos="-0.0020340581447199999 -0.05026790953535 0.01230193774992" />
        <site name="iliacus_r_iliacus_r-P4" pos="-0.01078935189808 -0.056673731635430005 0.017346617258879999" />
        <site name="piri_r_piri_r-P3" pos="-0.01308872197472 -0.0032029110500399996 0.038675876235360007" />
        <site name="psoas_r_psoas_r-P3" pos="-0.011673725004479999 -0.04154887389913 0.0040711448668799997" />
        <site name="psoas_r_psoas_r-P4" pos="-0.0207827680004 -0.046620149728359997 0.0077882771366400011" />
        <site name="KnExt_at_fem_r_cylinder_recfem_r_3_sidesite" pos="-0.01247 -0.3502 -0.01321" size="0.0005" />
        <site name="sart_r_sart_r-P2" pos="-0.0026531193192 -0.31744407295951999 -0.03725982584688" />
        <site name="tfl_r_tfl_r-P2" pos="0.02600056932816 -0.088524902633050004 0.052836380120160002" />
        <site name="tfl_r_tfl_r-P3" pos="0.009462792238479999 -0.36032749312950002 0.028675020366720001" />
        <site name="vasint_r_vasint_r-P1" pos="0.0256468200856 -0.17117780167435998 0.0274359762768" />
        <site name="vasint_r_vasint_r-P2" pos="0.029626499064400003 -0.18541296189675999 0.025223397544800002" />
        <site name="KnExt_at_fem_r_cylinder_vasint_r_4_sidesite" pos="-0.01345 -0.3653 -0.01273" size="0.0005" />
        <site name="KnExt_at_fem_r_cylinder_vasint_r_3_sidesite" pos="-0.01345 -0.3653 -0.01273" size="0.0005" />
        <site name="vaslat_r_vaslat_r-P1" pos="0.00424499091072 -0.16494991907706 0.030887599098720003" />
        <site name="vaslat_r_vaslat_r-P2" pos="0.023789636562159999 -0.23052062585149 0.03619778805552" />
        <site name="KnExt_at_fem_r_cylinder_vaslat_r_3_sidesite" pos="-0.01384 -0.3504 0.01548" size="0.0005" />
        <site name="vasmed_r_vasmed_r-P1" pos="0.0123812234896 -0.18674750816760999 0.016638592064640002" />
        <site name="vasmed_r_vasmed_r-P2" pos="0.031483682587839998 -0.24635724159890998 0.00079652834352" />
        <site name="KnExt_at_fem_r_cylinder_vasmed_r_4_sidesite" pos="-0.00563 -0.362 -0.01927" size="0.0005" />
        <site name="KnExt_at_fem_r_cylinder_vasmed_r_3_sidesite" pos="-0.00563 -0.362 -0.01927" size="0.0005" />
        <site name="RThighSuperior_marker" group="4" pos="-0.003898 -0.1073 0.08932" rgba="1 0.1 0.5 0.5" size="0.01" />
        <site name="RThighInferior_marker" group="4" pos="-0.02157 -0.322 0.04606" rgba="1 0.1 0.5 0.5" size="0.01" />
        <site name="RThighLateral_marker" group="4" pos="0.0692 -0.2212 0.05632" rgba="1 0.1 0.5 0.5" size="0.01" />
        <site name="R_HJC_marker" group="4" pos="0.001273 -0.002265 0.007793" rgba="1 0.1 0.5 0.5" size="0.01" />
      </body>
      <body name="femur_l" pos="-0.06382 -0.08023 -0.08622" euler="-0 0 0">
        <inertial mass="8.6622958148" pos="0.0000000000 -0.1700000000 0.0000000000" fullinertia="0.1246996591 0.0326882602 0.1314980722 0.0000000000 0.0000000000 0.0000000000" />
        <geom name="femur_l_geom_1" type="mesh" mesh="femur_l_geom_1_l_femur" rgba="1 1 1 1" group="0" />
        <geom name="Gastroc_at_condyles_l_cylinder" type="cylinder" euler="0 0 0" pos="0.004422 -0.3648 0" size="0.02218 0.04425" rgba="0.19 0.83 0.78 0.2" group="2" />
        <geom name="KnExt_at_fem_l_cylinder" type="cylinder" euler="0.06234 -0.05076 0" pos="0.003173 -0.3583 -0.001851" size="0.02218 0.04425" rgba="0.19 0.83 0.78 0.2" group="2" />
        <geom name="AB_at_femshaft_l_cylinder" type="cylinder" euler="-1.662 -0.1866 0" pos="0.01295 -0.1002 -0.02068" size="0.0146 0.03113" rgba="0.19 0.83 0.78 0.2" group="2" />
        <geom name="AL_at_femshaft_l_cylinder" type="cylinder" euler="-1.777 -0.1365 0" pos="0.02718 -0.2063 -0.01338" size="0.01779 0.04447" rgba="0.19 0.83 0.78 0.2" group="2" />
        <geom name="AMprox_at_femshaft_l_cylinder" type="cylinder" euler="-1.611 -0.1866 0" pos="0.004584 -0.06485 -0.02248" size="0.01867 0.03113" rgba="0.19 0.83 0.78 0.2" group="2" />
        <geom name="AMmid_at_femshaft_l_cylinder" type="cylinder" euler="-1.611 -0.1366 0" pos="0.02035 -0.143 -0.01822" size="0.01893 0.05338" rgba="0.19 0.83 0.78 0.2" group="2" />
        <geom name="AMdist_at_femshaft_l_cylinder" type="cylinder" euler="-1.712 -0.1866 0" pos="0.02795 -0.232 -0.008288" size="0.01929 0.08894" rgba="0.19 0.83 0.78 0.2" group="2" />
        <geom name="AMisch_at_condyles_l_cylinder" type="cylinder" euler="-1.711 0.4634 0" pos="-0.02003 -0.3353 0.002792" size="0.03541 0.1066" rgba="0.19 0.83 0.78 0.2" group="2" />
        <geom name="PECT_at_femshaft_l_cylinder" type="cylinder" euler="-1.813 -0.2763 0" pos="0.005382 -0.07518 -0.02694" size="0.01328 0.02223" rgba="0.19 0.83 0.78 0.2" group="2" />
        <joint name="hip_flexion_l" range="-0.5236 2.094" limited="true" user="0.0" ref="0" axis="0 0 1" type="hinge" />
        <joint name="hip_adduction_l" range="-0.8727 0.5236" limited="true" user="-0.0" ref="0" axis="-1 -0 -0" type="hinge" />
        <joint name="hip_rotation_l" range="-0.6981 0.6981" limited="true" user="-0.0" ref="0" axis="-0 -1 -0" type="hinge" />
        <body name="tibia_l" pos="0.001926 -0.3587 0.0007185" euler="-0 0 0">
          <inertial mass="3.4527556855" pos="0.0000000000 -0.1867000000 0.0000000000" fullinertia="0.046936989 0.01 0.0475888916 0.0 0.0 0.0" />
          <geom name="tibia_l_geom_1" type="mesh" mesh="tibia_l_geom_1_l_tibia" rgba="1 1 1 1" group="0" />
          <geom name="tibia_l_geom_2" type="mesh" mesh="tibia_l_geom_2_l_fibula" rgba="1 1 1 1" group="0" />
          <geom name="GasLat_at_shank_l_cylinder" type="cylinder" euler="-2.967 0.2797 -1.478" pos="-0.008306 -0.08974 0.003812" size="0.06425 0.05772" rgba="0.19 0.83 0.78 0.2" group="2" />
          <site name="GasLat_at_shank_l_sidesite" pos="-0.07075 -0.08068 -0.0128" size="0.0005" />
          <geom name="GasMed_at_shank_l_cylinder" type="cylinder" euler="-2.967 -0.02797 -1.478" pos="-0.008306 -0.08974 0.003812" size="0.06417 0.05785" rgba="0.19 0.83 0.78 0.2" group="2" />
          <site name="GasMed_at_shank_l_sidesite" pos="-0.07317 -0.08411 0.006646" size="0.0005" />
          <geom name="GR_at_condyles_l_cylinder" type="cylinder" euler="0 0.4 0" pos="-0.003367 -0.02425 0" size="0.04212 0.05752" rgba="0.19 0.83 0.78 0.2" group="2" />
          <geom name="SM_at_condyles_l_cylinder" type="cylinder" euler="0 0.1 0" pos="-0.001122 -0.02425 0" size="0.0411 0.05775" rgba="0.19 0.83 0.78 0.2" group="2" />
          <geom name="ST_at_condyles_l_cylinder" type="cylinder" euler="0 0.2 0" pos="-0.002245 -0.02486 0" size="0.04965 0.0577" rgba="0.19 0.83 0.78 0.2" group="2" />
          <geom name="BF_at_gastroc_l_cylinder" type="cylinder" euler="0 0 0" pos="-0.0651 -0.07276 0" size="0.03503 0.08665" rgba="0.19 0.83 0.78 0.2" group="2" />
          <joint name="walker_knee_l_translation1" range="0 0.001423" limited="true" user="8.485342442902076e-08" ref="0" axis="-0.1243 0.9898 0.07016" type="slide" />
          <joint name="walker_knee_l_translation2" range="-0.006011 0" limited="true" user="-6.808143371977993e-11" ref="0" axis="-0.9922 -0.124 -0.008789" type="slide" />
          <joint name="knee_angle_l" range="0 2.094" limited="true" user="0.0" ref="0" axis="4.566e-07 0.07071 -0.9975" type="hinge" />
          <joint name="walker_knee_l_rotation2" range="-0.001678 0.03354" limited="true" user="-1.4732523263838448e-08" ref="0" axis="-0.9922 -0.124 -0.008789" type="hinge" />
          <joint name="walker_knee_l_rotation3" range="-0.2628 0" limited="true" user="-1.0893911855935912e-08" ref="0" axis="-0.1243 0.9898 0.07016" type="hinge" />
          <body name="talus_l" pos="-0.01122 -0.4851 0" euler="-0 0 0">
            <inertial mass="0.25" pos="0.0000000000 0.0000000000 0.0000000000" fullinertia="0.01 0.01 0.01 0.0 0.0 0.0" />
            <geom name="talus_l_geom_1" type="mesh" mesh="talus_l_geom_1_l_talus" rgba="1 1 1 0" group="0" />
            <joint name="ankle_angle_l" range="-0.6981 0.5236" limited="true" user="0.0" ref="0" type="hinge" axis="0.105 0.174 0.9791" />
            <body name="calcn_l" pos="-0.04704 -0.04145 -0.007727" euler="-0 0 0">
              <inertial mass="1.1641118292" pos="0.1000000000 0.0300000000 0.0000000000" fullinertia="0.01 0.01 0.01 0.0 0.0 0.0" />
              <geom name="calcn_l_geom_1" type="mesh" mesh="calcn_l_geom_1_l_foot" rgba="1 1 1 1" group="0" />
              <joint name="subtalar_angle_l" range="-0.3491 0.3491" limited="true" user="0.0" ref="0" type="hinge" axis="-0.7872 -0.6047 -0.1209" />
              <body name="toes_l" pos="0.2039 -0.002257 -0.001224" euler="-0 0 0">
                <inertial mass="0.25" pos="0.0346000000 0.0060000000 0.0175000000" fullinertia="0.01 0.01 0.01 0.0 0.0 0.0" />
                <geom name="toes_l_geom_1" type="mesh" mesh="toes_l_geom_1_l_bofoot" rgba="1 1 1 1" group="0" />
                <joint name="mtp_angle_l" range="-0.5236 0.5236" limited="true" user="0.0" ref="0" type="hinge" axis="-0.581 2.16e-06 -0.8139" />
                <site name="edl_l_edl_l-P5" pos="0.00031763566247999998 0.0049756477507199998 -0.01620108747945" />
                <site name="edl_l_edl_l-P6" pos="0.046904199492880001 -0.00042345938304 -0.026472365162500001" />
                <site name="ehl_l_ehl_l-P7" pos="0.031551809139680004 0.0043404586761599997 0.02594291785925" />
                <site name="ehl_l_ehl_l-P8" pos="0.059609625992080008 0.0035994047558399996 0.019695439680899998" />
                <site name="fdl_l_fdl_l-P6" pos="-0.00201169252904 -0.0082574579692799993 -0.015565750715549999" />
                <site name="fdl_l_fdl_l-P7" pos="0.030175387935600002 -0.0075164040489600001 -0.022766234039749998" />
                <site name="fdl_l_fdl_l-P8" pos="0.046692442384560003 -0.0063518907455999999 -0.025625249477300001" />
                <site name="fhl_l_fhl_l-P6" pos="0.016411175894800002 -0.00677535012864 0.028060707072249998" />
                <site name="fhl_l_fhl_l-P7" pos="0.059503747437920002 -0.01079821426752 0.019165992377650001" />
              </body>
              <site name="edl_l_edl_l-P3" pos="0.10478358005645 0.0406219696812 -0.00090661487255999998" />
              <site name="edl_l_edl_l-P4" pos="0.18425491335279998 0.0062061342568499999 -0.014732491679099999" />
              <site name="ehl_l_ehl_l-P4" pos="0.11059855566350001 0.043894295016629996 0.023911967263770002" />
              <site name="ehl_l_ehl_l-P5" pos="0.14742673450815 0.034867190643030004 0.029125002780989999" />
              <site name="ehl_l_ehl_l-P6" pos="0.1977091706397 0.015684593849129999 0.031731520539600003" />
              <site name="fdl_l_fdl_l-P3" pos="0.049712340483800001 0.035544223471050004 0.031731520539600003" />
              <site name="fdl_l_fdl_l-P4" pos="0.080725543721400006 0.019859629621920002 0.02980496393541" />
              <site name="fdl_l_fdl_l-P5" pos="0.1890437167939 -0.0091399431782700005 -0.013145915652119998" />
              <site name="fhl_l_fhl_l-P3" pos="0.042643154451699999 0.031143510088919999 0.027311773035869999" />
              <site name="fhl_l_fhl_l-P4" pos="0.1183518564729 0.0076730387175600002 0.029011675921919999" />
              <site name="fhl_l_fhl_l-P5" pos="0.19679701760330001 -0.0059804566475099999 0.030484925089830001" />
              <site name="gaslat_l_gaslat_l-P2" pos="0.0050168417002000006 0.034980029447699998 0.0060063235307099994" />
              <site name="gasmed_l_gasmed_l-P2" pos="0.0050168417002000006 0.034980029447699998 0.0060063235307099994" />
              <site name="perbrev_l_perbrev_l-P4" pos="0.053703010018050001 0.030466477260900002 -0.026405158163309999" />
              <site name="perbrev_l_perbrev_l-P5" pos="0.077190950705349995 0.024711698222729998 -0.038871112661009996" />
              <site name="perlong_l_perlong_l-P4" pos="0.049940378742899999 0.025952925074099999 -0.025045235854470001" />
              <site name="perlong_l_perlong_l-P5" pos="0.077647027223549991 0.01196091329502 -0.032184827975880001" />
              <site name="perlong_l_perlong_l-P6" pos="0.097144298376599991 0.0077858775222299998 -0.013372569370259999" />
              <site name="perlong_l_perlong_l-P7" pos="0.13716501284865001 0.0095912983969500005 0.02085214206888" />
              <site name="soleus_l_soleus_l-P2" pos="0.0050168417002000006 0.034980029447699998 0.0060063235307099994" />
              <site name="tibant_l_tibant_l-P4" pos="0.1329463050553 0.020085307231260001 0.034564692016349999" />
              <site name="tibpost_l_tibpost_l-P3" pos="0.04754597702235 0.037688160759780001 0.03241148169402" />
              <site name="tibpost_l_tibpost_l-P4" pos="0.088022768012600006 0.017941369942530001 0.031844847398670002" />
              <site name="LToe_marker" group="4" pos="0.275 0.01521 -0.0137" rgba="1 0.1 0.5 0.5" size="0.01" />
              <site name="LHeel_marker" group="4" pos="-0.03132 0.01283 0.01152" rgba="1 0.1 0.5 0.5" size="0.01" />
              <site name="LMidfootLateral_marker" group="4" pos="0.1824 0.004222 -0.06702" rgba="1 0.1 0.5 0.5" size="0.01" />
            </body>
          </body>
          <site name="bflh_l_bflh_l-P2" pos="-0.037826974495440001 -0.042444267309500003 -0.029228978543380003" />
          <site name="bflh_l_bflh_l-P3" pos="-0.03221466373944 -0.055177547502350002 -0.035005456516380005" />
          <site name="bfsh_l_bfsh_l-P2" pos="-0.033786110751119994 -0.050811851436230002 -0.036738399908280005" />
          <site name="edl_l_edl_l-P1" pos="-0.017959394419199998 -0.14030862079169001 -0.023683559689300002" />
          <site name="edl_l_edl_l-P2" pos="0.01840837927968 -0.4559727002392 -0.01293931065952" />
          <site name="ehl_l_ehl_l-P1" pos="-0.015714470116799998 -0.18796746951349999 -0.021835086737940001" />
          <site name="ehl_l_ehl_l-P2" pos="0.0079694812735200005 -0.35277249600952998 -0.018946847751440003" />
          <site name="ehl_l_ehl_l-P3" pos="0.022449243024000001 -0.44784765478281002 0.00323482766488" />
          <site name="fdl_l_fdl_l-P1" pos="-0.0025816629477599996 -0.22216542203144002 0.00207953207028" />
          <site name="fdl_l_fdl_l-P2" pos="-0.019755333861119998 -0.44202672669464999 0.014325665373040001" />
          <site name="fhl_l_fhl_l-P1" pos="-0.034796326687200001 -0.26230557197270998 -0.023105911892000001" />
          <site name="fhl_l_fhl_l-P2" pos="-0.027163584059039996 -0.44517972940906997 0.0087802465189600002" />
          <site name="GasLat_at_shank_l_cylinder_gaslat_l_1_sidesite" pos="-0.02662 -0.1012 -0.05776" size="0.0005" />
          <site name="GasMed_at_shank_l_cylinder_gasmed_l_1_sidesite" pos="-0.005163 -0.107 0.06657" size="0.0005" />
          <site name="grac_l_grac_l-P2" pos="-0.020675752825103998 -0.057663568873335007 0.034208302556106004" />
          <site name="grac_l_grac_l-P3" pos="0.001997982629136 -0.084427711145354009 0.018172799703058004" />
          <site name="GR_at_condyles_l_cylinder_grac_l_1_sidesite" pos="-0.01853 -0.01664 0.03964" size="0.0005" />
          <site name="perbrev_l_perbrev_l-P1" pos="-0.027275830274159998 -0.30705395665044 -0.028997919424460002" />
          <site name="perbrev_l_perbrev_l-P2" pos="-0.038051466925679997 -0.47210152181680998 -0.028766860305540001" />
          <site name="perbrev_l_perbrev_l-P3" pos="-0.031990171309199997 -0.48556241802068001 -0.029460037662300001" />
          <site name="perlong_l_perlong_l-P1" pos="-0.022449243024000001 -0.16650279718841002 -0.03257933576772" />
          <site name="perlong_l_perlong_l-P2" pos="-0.035582050193039998 -0.47295040716300002 -0.027380505592020002" />
          <site name="perlong_l_perlong_l-P3" pos="-0.030530970512639997 -0.48677511137238 -0.027727094270400002" />
          <site name="recfem_l_recfem_l-P5" pos="0.036592266129119991 -0.076545204359303995 0.00054298892946199999" />
          <site name="sart_l_sart_l-P3" pos="-0.02817379999512 -0.048629003403169994 0.0421682892029" />
          <site name="sart_l_sart_l-P4" pos="-0.01784714820408 -0.072640331766830005 0.030499803697440001" />
          <site name="sart_l_sart_l-P5" pos="0.015265485256319999 -0.0982281614877 0.0030037685459600003" />
          <site name="semimem_l_semimem_l-P2" pos="-0.032551402384799998 -0.050569312765890002 0.022643793654159999" />
          <site name="SM_at_condyles_l_cylinder_semimem_l_1_sidesite" pos="-0.03449 -0.009129 0.02201" size="0.0005" />
          <site name="semiten_l_semiten_l-P2" pos="-0.035020819117439997 -0.06160482226636 0.026456269116340001" />
          <site name="semiten_l_semiten_l-P3" pos="0.0021326780872799999 -0.093741196086409989 0.013516958456820001" />
          <site name="ST_at_condyles_l_cylinder_semiten_l_1_sidesite" pos="-0.04237 -0.01956 0.03045" size="0.0005" />
          <site name="soleus_l_soleus_l-P1" pos="-0.0085307123491199996 -0.11108271101572001 -0.01132189682708" />
          <site name="tfl_l_tfl_l-P4" pos="0.012122591232960001 -0.049720427419700002 -0.039973227573159999" />
          <site name="tibant_l_tibant_l-P1" pos="0.017285917128479999 -0.15910536774304002 -0.018715788632519999" />
          <site name="tibant_l_tibant_l-P2" pos="0.02817379999512 -0.23113935283401998 -0.014787783610880002" />
          <site name="tibant_l_tibant_l-P3" pos="0.02615336812296 -0.44372449738703001 0.01524990184872" />
          <site name="tibpost_l_tibpost_l-P1" pos="-0.0046020948199200001 -0.15813521306167999 -0.011899544624380001" />
          <site name="tibpost_l_tibpost_l-P2" pos="-0.01840837927968 -0.44323942004634997 0.020217672905500004" />
          <site name="vasint_l_vasint_l-P5" pos="0.036558592264584001 -0.076642219827440003 -0.00049677710567799999" />
          <site name="vaslat_l_vaslat_l-P5" pos="0.036524918400047998 -0.076860504630746007 -0.0059035604884060001" />
          <site name="vasmed_l_vasmed_l-P5" pos="0.035806542623279994 -0.077090916367568998 0.0078329041313879993" />
          <site name="LShankSuperior_marker" group="4" pos="0.05984 -0.1566 -0.008041" rgba="1 0.1 0.5 0.5" size="0.01" />
          <site name="LShankInferior_marker" group="4" pos="-0.001117 -0.3864 -0.0386" rgba="1 0.1 0.5 0.5" size="0.01" />
          <site name="LShankLateral_marker" group="4" pos="0.03813 -0.2665 0.04784" rgba="1 0.1 0.5 0.5" size="0.01" />
        </body>
        <body name="patella_l" pos="-0.007155 -0.363 0.002434" euler="-0 0 0">
          <inertial mass="0.25" pos="0.0018 0.0264 0" fullinertia="0.01 0.01 0.01 0.0 0.0 0.0" />
          <geom name="patella_l_geom_1" type="mesh" mesh="patella_l_geom_1_l_patella" rgba="1 1 1 1" group="0" />
          <joint name="patellofemoral_l_translation1" range="-0.02008 0.04634" limited="true" user="0.046358158050911126" ref="0" axis="1 0 0" type="slide" />
          <joint name="patellofemoral_l_translation2" range="-0.0363 -0.009609" limited="true" user="-0.009633759440743413" ref="0" axis="0 1 0" type="slide" />
          <joint name="patellofemoral_l_translation3" limited="false" ref="0" axis="0 0 1" type="slide" />
          <joint name="patellofemoral_l_rotation1" range="-1.786 0.001137" limited="true" user="0.01050598499723554" ref="0" axis="0 0 1" type="hinge" />
          <site name="recfem_l_recfem_l-P2" pos="0.01 0.049000000000000002 -0.00069999999999999999" />
          <site name="recfem_l_recfem_l-P3" pos="0.0121 0.043700000000000003 0.001" />
          <site name="recfem_l_recfem_l-P4" pos="0.0050000000000000001 0.00247 -3.0000000000000001e-05" />
          <site name="vasint_l_vasint_l-P3" pos="0.0057999999999999996 0.048000000000000001 0.00059999999999999995" />
          <site name="vasint_l_vasint_l-P4" pos="0.0050000000000000001 0.00247 0.00038999999999999999" />
          <site name="vaslat_l_vaslat_l-P3" pos="0.0103 0.042299999999999997 -0.0141" />
          <site name="vaslat_l_vaslat_l-P4" pos="0.0050000000000000001 0.00247 -0.0073299999999999997" />
          <site name="vasmed_l_vasmed_l-P3" pos="0.0063 0.044499999999999998 0.017000000000000001" />
          <site name="vasmed_l_vasmed_l-P4" pos="0.0050000000000000001 0.00247 0.0085000000000000006" />
        </body>
        <site name="addbrev_l_addbrev_l-P2" pos="-0.0017687462128000001 -0.10498430664019999 -0.022037284170720001" />
        <site name="AB_at_femshaft_l_cylinder_addbrev_l_1_sidesite" pos="0.002091 -0.09455 -0.01101" size="0.0005" />
        <site name="addlong_l_addlong_l-P2" pos="0.0099580411780639984 -0.21296689390224299 -0.014010048531024001" />
        <site name="AL_at_femshaft_l_cylinder_addlong_l_1_sidesite" pos="0.009958 -0.213 -0.01401" size="0.0005" />
        <site name="addmagDist_l_addmagDist_l-P2" pos="0.0099491974469999994 -0.23354559739875 -0.017081107811040001" />
        <site name="AMdist_at_femshaft_l_cylinder_addmagDist_l_1_sidesite" pos="0.009949 -0.2335 -0.01708" size="0.0005" />
        <site name="addmagIsch_l_addmagIsch_l-P2" pos="0.0042538346417839998 -0.34517594446778299 0.028967080759344004" />
        <site name="AMisch_at_condyles_l_cylinder_addmagIsch_l_1_sidesite" pos="0.004254 -0.3452 0.02897" size="0.0005" />
        <site name="addmagMid_l_addmagMid_l-P2" pos="0.0021401829174879997 -0.14448687625735998 -0.025860620219616" />
        <site name="AMmid_at_femshaft_l_cylinder_addmagMid_l_1_sidesite" pos="0.00214 -0.1445 -0.02586" size="0.0005" />
        <site name="addmagProx_l_addmagProx_l-P2" pos="-0.013504377334728 -0.070161545946153994 -0.028338708399456" />
        <site name="AMprox_at_femshaft_l_cylinder_addmagProx_l_1_sidesite" pos="-0.01373 -0.06597 -0.0154" size="0.0005" />
        <site name="bfsh_l_bfsh_l-P1" pos="0.0044218655320000001 -0.18781514518428999 -0.020709736931520003" />
        <site name="gaslat_l_gaslat_l-P1" pos="-0.0026531193192 -0.33933063180146 -0.024515372350560002" />
        <site name="gasmed_l_gasmed_l-P1" pos="0.0070749848512000005 -0.33701741826532 0.018408655050239999" />
        <site name="glmax1_l_glmax1_l-P3" pos="-0.039266165924160004 -0.029004138953139996 -0.026727951082560004" />
        <site name="glmax1_l_glmax1_l-P4" pos="-0.024497135047279999 -0.050356879286739993 -0.041596480161600002" />
        <site name="glmax2_l_glmax2_l-P3" pos="-0.039796789787999998 -0.051958334811760001 -0.02230279361856" />
        <site name="glmax2_l_glmax2_l-P4" pos="-0.013796220459839999 -0.090393267412239992 -0.037082819548320003" />
        <site name="glmax3_l_glmax3_l-P3" pos="-0.024850884289839999 -0.10009097031375 -0.0083192960323200012" />
        <site name="glmax3_l_glmax3_l-P4" pos="-0.0053062386384 -0.12624807722240999 -0.036374794354079996" />
        <site name="glmed1_l_glmed1_l-P2" pos="-0.0123812234896 -0.016014555250199999 -0.052216858075199997" />
        <site name="glmed2_l_glmed2_l-P2" pos="-0.019456208340799998 -0.0088969751390000004 -0.0495617635968" />
        <site name="glmed3_l_glmed3_l-P2" pos="-0.027327128987760001 -0.00418157831533 -0.045844631327040003" />
        <site name="glmin1_l_glmin1_l-P2" pos="0.0044218655320000001 -0.013345462708499999 -0.0495617635968" />
        <site name="glmin2_l_glmin2_l-P2" pos="0.0035374924256000003 -0.0080072776250999997 -0.0460216376256" />
        <site name="glmin3_l_glmin3_l-P2" pos="-0.0035374924256000003 -0.00088969751389999998 -0.045136606132799996" />
        <site name="iliacus_l_iliacus_l-P3" pos="-0.0020340581447199999 -0.05026790953535 -0.01230193774992" />
        <site name="iliacus_l_iliacus_l-P4" pos="-0.01078935189808 -0.056673731635430005 -0.017346617258879999" />
        <site name="piri_l_piri_l-P3" pos="-0.01308872197472 -0.0032029110500399996 -0.038675876235360007" />
        <site name="psoas_l_psoas_l-P3" pos="-0.011673725004479999 -0.04154887389913 -0.0040711448668799997" />
        <site name="psoas_l_psoas_l-P4" pos="-0.0207827680004 -0.046620149728359997 -0.0077882771366400011" />
        <site name="KnExt_at_fem_l_cylinder_recfem_l_3_sidesite" pos="-0.01247 -0.3502 0.01321" size="0.0005" />
        <site name="sart_l_sart_l-P2" pos="-0.0026531193192 -0.31744407295951999 0.03725982584688" />
        <site name="tfl_l_tfl_l-P2" pos="0.02600056932816 -0.088524902633050004 -0.052836380120160002" />
        <site name="tfl_l_tfl_l-P3" pos="0.009462792238479999 -0.36032749312950002 -0.028675020366720001" />
        <site name="vasint_l_vasint_l-P1" pos="0.0256468200856 -0.17117780167435998 -0.0274359762768" />
        <site name="vasint_l_vasint_l-P2" pos="0.029626499064400003 -0.18541296189675999 -0.025223397544800002" />
        <site name="KnExt_at_fem_l_cylinder_vasint_l_4_sidesite" pos="-0.01345 -0.3653 0.01273" size="0.0005" />
        <site name="KnExt_at_fem_l_cylinder_vasint_l_3_sidesite" pos="-0.01345 -0.3653 0.01273" size="0.0005" />
        <site name="vaslat_l_vaslat_l-P1" pos="0.00424499091072 -0.16494991907706 -0.030887599098720003" />
        <site name="vaslat_l_vaslat_l-P2" pos="0.023789636562159999 -0.23052062585149 -0.03619778805552" />
        <site name="KnExt_at_fem_l_cylinder_vaslat_l_3_sidesite" pos="-0.01384 -0.3504 -0.01548" size="0.0005" />
        <site name="vasmed_l_vasmed_l-P1" pos="0.0123812234896 -0.18674750816760999 -0.016638592064640002" />
        <site name="vasmed_l_vasmed_l-P2" pos="0.031483682587839998 -0.24635724159890998 -0.00079652834352" />
        <site name="KnExt_at_fem_l_cylinder_vasmed_l_4_sidesite" pos="-0.00563 -0.362 0.01927" size="0.0005" />
        <site name="KnExt_at_fem_l_cylinder_vasmed_l_3_sidesite" pos="-0.00563 -0.362 0.01927" size="0.0005" />
        <site name="LThighSuperior_marker" group="4" pos="0.03069 -0.1155 -0.05636" rgba="1 0.1 0.5 0.5" size="0.01" />
        <site name="LThighInferior_marker" group="4" pos="0.0361 -0.3339 0.005959" rgba="1 0.1 0.5 0.5" size="0.01" />
        <site name="LThighLateral_marker" group="4" pos="0.08269 -0.2454 0.0307" rgba="1 0.1 0.5 0.5" size="0.01" />
        <site name="L_HJC_marker" group="4" pos="0.005557 0.00338 -0.002462" rgba="1 0.1 0.5 0.5" size="0.01" />
      </body>
      <body name="torso" pos="-0.1142 0.08331 0" euler="-0 0 0">
        <inertial mass="31.8841848423" pos="-0.0300000000 0.3200000000 0.0000000000" fullinertia="1.3731863138 0.7035891896 1.3330477379 0.0000000000 0.0000000000 0.0000000000" />
        <geom name="torso_geom_1" type="mesh" mesh="torso_geom_1_hat_spine" rgba="1 1 1 1" group="0" />
        <geom name="torso_geom_2" type="mesh" mesh="torso_geom_2_hat_jaw" rgba="1 1 1 1" group="0" />
        <geom name="torso_geom_3" type="mesh" mesh="torso_geom_3_hat_skull" rgba="1 1 1 1" group="0" />
        <geom name="torso_geom_4" type="mesh" mesh="torso_geom_4_hat_ribs_scap" rgba="1 1 1 1" group="0" />
        <joint name="lumbar_extension" range="-1.571 1.571" limited="true" user="0.0" ref="0" axis="0 0 1" type="hinge" />
        <joint name="lumbar_bending" range="-1.571 1.571" limited="true" user="0.0" ref="0" axis="1 0 0" type="hinge" />
        <joint name="lumbar_rotation" range="-1.571 1.571" limited="true" user="0.0" ref="0" axis="0 1 0" type="hinge" />
        <site name="Sternum_marker" group="4" pos="0.05554 0.3449 0.0004619" rgba="1 0.1 0.5 0.5" size="0.01" />
        <site name="Neck_marker" group="4" pos="-0.09362 0.3756 0.002888" rgba="1 0.1 0.5 0.5" size="0.01" />
        <site name="RShoulder_marker" group="4" pos="0.0005735 0.3731 0.1566" rgba="1 0.1 0.5 0.5" size="0.01" />
        <site name="LShoulder_marker" group="4" pos="-0.0004452 0.3717 -0.1563" rgba="1 0.1 0.5 0.5" size="0.01" />
      </body>
      <site name="addbrev_r_addbrev_r-P1" pos="-0.021660599930759999 -0.096089802341200001 0.01718583834506" />
      <site name="addlong_r_addlong_r-P1" pos="-0.0085961962028880002 -0.090876419448220003 0.021069391425632002" />
      <site name="addmagDist_r_addmagDist_r-P1" pos="-0.083966011459344 -0.13050835175426601 0.044437667720798005" />
      <site name="addmagIsch_r_addmagIsch_r-P1" pos="-0.10163471025103202 -0.13264481650844798 0.046546838790419001" />
      <site name="addmagMid_r_addmagMid_r-P1" pos="-0.059719748290776004 -0.12343450673084999 0.031849599114806004" />
      <site name="addmagProx_r_addmagProx_r-P1" pos="-0.035133266275128007 -0.10994104512548999 0.015232902169485002" />
      <site name="bflh_r_bflh_r-P1" pos="-0.11794253365440001 -0.12174782403017999 0.065395462793539999" />
      <site name="glmax1_r_glmax1_r-P1" pos="-0.13960313358516002 0.035267001923099998 0.062828746677070002" />
      <site name="glmax1_r_glmax1_r-P2" pos="-0.14255169692652003 -0.024738012943159998 0.086933558901310007" />
      <site name="Gmax1_at_pelvis_r_cylinder_glmax1_r_2_sidesite" pos="-0.1075 -0.09985 0.1101" size="0.0005" />
      <site name="glmax2_r_glmax2_r-P1" pos="-0.14935607386812003 0.0088934178762599993 0.051557515035180003" />
      <site name="glmax2_r_glmax2_r-P2" pos="-0.15241804349184002 -0.062253925133819998 0.090727834899569995" />
      <site name="Gmax2_at_pelvis_r_cylinder_glmax2_r_2_sidesite" pos="-0.1253 -0.1011 0.1006" size="0.0005" />
      <site name="glmax3_r_glmax3_r-P1" pos="-0.14742816706800002 -0.053667176839499994 0.010043671760099999" />
      <site name="glmax3_r_glmax3_r-P2" pos="-0.14436619744428 -0.12910789399674 0.048544413507149997" />
      <site name="glmed1_r_glmed1_r-P1" pos="-0.055724905369183612 0.026734693536435664 0.12865762196155009" />
      <site name="glmed2_r_glmed2_r-P1" pos="-0.096086109923942328 0.055848534931323884 0.091490618857543962" />
      <site name="glmed3_r_glmed3_r-P1" pos="-0.1132540900359503 0.015905304096224721 0.071311887025485243" />
      <site name="glmin1_r_glmin1_r-P1" pos="-0.033545050631961448 -0.00011062251380025604 0.13219091093363367" />
      <site name="glmin2_r_glmin2_r-P1" pos="-0.069858268203317461 0.010222591847254218 0.11287450079951358" />
      <site name="glmin3_r_glmin3_r-P1" pos="-0.089477556782040002 -0.015844595066899999 0.089053889606220002" />
      <site name="grac_r_grac_r-P1" pos="-0.053709215325696003 -0.13219503445493599 0.027408064269784" />
      <site name="iliacus_r_iliacus_r-P1" pos="-0.068610800827800009 0.031586966939820001 0.094075725486270009" />
      <site name="iliacus_r_iliacus_r-P2" pos="-0.015309848118600001 -0.056938319046859996 0.08436684278484001" />
      <site name="IL_at_brim_r_cylinder_iliacus_r_2_sidesite" pos="-0.0278 -0.09504 0.09212" size="0.0005" />
      <site name="piri_r_piri_r-P1" pos="-0.11545893607071601 -0.0066751745668939995 0.015076667275439" />
      <site name="piri_r_piri_r-P2" pos="-0.115697089263672 -0.031341631274267999 0.067984498180588007" />
      <site name="psoas_r_psoas_r-P1" pos="-0.068724207110160002 0.063378380267599996 0.043522577627100004" />
      <site name="psoas_r_psoas_r-P2" pos="-0.023248287883800001 -0.066853968862919999 0.073207207495840004" />
      <site name="PS_at_brim_r_cylinder_psoas_r_2_sidesite" pos="-0.04147 -0.09526 0.08181" size="0.0005" />
      <site name="recfem_r_recfem_r-P1" pos="-0.027217507766400004 -0.039662599264239998 0.10411939724637" />
      <site name="sart_r_sart_r-P1" pos="-0.022114225060200002 -0.01594681826088 0.11784574865184" />
      <site name="semimem_r_semimem_r-P1" pos="-0.11193200068932001 -0.11653444113719999 0.068520160674460012" />
      <site name="semiten_r_semiten_r-P1" pos="-0.11771572108968001 -0.12808566205694 0.05747212173835" />
      <site name="tfl_r_tfl_r-P1" pos="-0.023066594859758417 0.01109259285204231 0.14429134553288248" />
      <site name="addbrev_l_addbrev_l-P1" pos="-0.021660599930759999 -0.096089802341200001 -0.01718583834506" />
      <site name="addlong_l_addlong_l-P1" pos="-0.0085961962028880002 -0.090876419448220003 -0.021069391425632002" />
      <site name="addmagDist_l_addmagDist_l-P1" pos="-0.083966011459344 -0.13050835175426601 -0.044437667720798005" />
      <site name="addmagIsch_l_addmagIsch_l-P1" pos="-0.10163471025103202 -0.13264481650844798 -0.046546838790419001" />
      <site name="addmagMid_l_addmagMid_l-P1" pos="-0.059719748290776004 -0.12343450673084999 -0.031849599114806004" />
      <site name="addmagProx_l_addmagProx_l-P1" pos="-0.035133266275128007 -0.10994104512548999 -0.015232902169485002" />
      <site name="bflh_l_bflh_l-P1" pos="-0.11794253365440001 -0.12174782403017999 -0.065395462793539999" />
      <site name="glmax1_l_glmax1_l-P1" pos="-0.13960313358516002 0.035267001923099998 -0.062828746677070002" />
      <site name="glmax1_l_glmax1_l-P2" pos="-0.14255169692652003 -0.024738012943159998 -0.086933558901310007" />
      <site name="Gmax1_at_pelvis_l_cylinder_glmax1_l_2_sidesite" pos="-0.1075 -0.09985 -0.1101" size="0.0005" />
      <site name="glmax2_l_glmax2_l-P1" pos="-0.14935607386812003 0.0088934178762599993 -0.051557515035180003" />
      <site name="glmax2_l_glmax2_l-P2" pos="-0.15241804349184002 -0.062253925133819998 -0.090727834899569995" />
      <site name="Gmax2_at_pelvis_l_cylinder_glmax2_l_2_sidesite" pos="-0.1253 -0.1011 -0.1006" size="0.0005" />
      <site name="glmax3_l_glmax3_l-P1" pos="-0.14742816706800002 -0.053667176839499994 -0.010043671760099999" />
      <site name="glmax3_l_glmax3_l-P2" pos="-0.14436619744428 -0.12910789399674 -0.048544413507149997" />
      <site name="glmed1_l_glmed1_l-P1" pos="-0.055569078356400008 0.026578030434799997 -0.12833580582350002" />
      <site name="glmed2_l_glmed2_l-P1" pos="-0.096395340006000016 0.056222756688999995 -0.091509009369800012" />
      <site name="glmed3_l_glmed3_l-P1" pos="-0.11340628236000001 0.016355711036799999 -0.071421665849600011" />
      <site name="glmin1_l_glmin1_l-P1" pos="-0.034021884708000001 0 -0.1316836964102" />
      <site name="glmin2_l_glmin2_l-P1" pos="-0.069858269933760014 0.010222319398 -0.11271231641890002" />
      <site name="glmin3_l_glmin3_l-P1" pos="-0.089477556782040002 -0.015844595066899999 -0.089053889606220002" />
      <site name="grac_l_grac_l-P1" pos="-0.053709215325696003 -0.13219503445493599 -0.027408064269784" />
      <site name="iliacus_l_iliacus_l-P1" pos="-0.068610800827800009 0.031586966939820001 -0.094075725486270009" />
      <site name="iliacus_l_iliacus_l-P2" pos="-0.015309848118600001 -0.056938319046859996 -0.08436684278484001" />
      <site name="IL_at_brim_l_cylinder_iliacus_l_2_sidesite" pos="-0.0278 -0.09504 -0.09212" size="0.0005" />
      <site name="piri_l_piri_l-P1" pos="-0.11545893607071601 -0.0066751745668939995 -0.015076667275439" />
      <site name="piri_l_piri_l-P2" pos="-0.115697089263672 -0.031341631274267999 -0.067984498180588007" />
      <site name="psoas_l_psoas_l-P1" pos="-0.068724207110160002 0.063378380267599996 -0.043522577627100004" />
      <site name="psoas_l_psoas_l-P2" pos="-0.023248287883800001 -0.066853968862919999 -0.073207207495840004" />
      <site name="PS_at_brim_l_cylinder_psoas_l_2_sidesite" pos="-0.04147 -0.09526 -0.08181" size="0.0005" />
      <site name="recfem_l_recfem_l-P1" pos="-0.027217507766400004 -0.039662599264239998 -0.10411939724637" />
      <site name="sart_l_sart_l-P1" pos="-0.022114225060200002 -0.01594681826088 -0.11784574865184" />
      <site name="semimem_l_semimem_l-P1" pos="-0.11193200068932001 -0.11653444113719999 -0.068520160674460012" />
      <site name="semiten_l_semiten_l-P1" pos="-0.11771572108968001 -0.12808566205694 -0.05747212173835" />
      <site name="tfl_l_tfl_l-P1" pos="-0.022681256472000002 0.011244551337799998 -0.1439592952281" />
      <site name="RAsis_marker" group="4" pos="0.01494 0.01184 0.1436" rgba="1 0.1 0.5 0.5" size="0.01" />
      <site name="LAsis_marker" group="4" pos="0.01415 0.01177 -0.141" rgba="1 0.1 0.5 0.5" size="0.01" />
      <site name="RPsis_marker" group="4" pos="-0.1768 0.02491 0.05459" rgba="1 0.1 0.5 0.5" size="0.01" />
      <site name="LPsis_marker" group="4" pos="-0.1774 0.02468 -0.05326" rgba="1 0.1 0.5 0.5" size="0.01" />
    </body>
  </worldbody>
  <asset>
    <texture type="skybox" builtin="gradient" rgb1="1 1 1" rgb2="0.6 0.8 1" width="256" height="256" />
    <mesh name="pelvis_geom_1_r_pelvis" file="Geometry/r_pelvis.stl" scale="1.1340628236000001 1.0222319397999999 1.1159635289000001" />
    <mesh name="pelvis_geom_2_l_pelvis" file="Geometry/l_pelvis.stl" scale="1.1340628236000001 1.0222319397999999 1.1159635289000001" />
    <mesh name="pelvis_geom_3_sacrum" file="Geometry/sacrum.stl" scale="1.1340628236000001 1.0222319397999999 1.1159635289000001" />
    <mesh name="femur_r_geom_1_r_femur" file="Geometry/r_femur.stl" scale="0.8843731064 0.88969751389999996 0.88503149280000004" />
    <mesh name="tibia_r_geom_1_r_tibia" file="Geometry/r_tibia.stl" scale="1.1224621511999999 1.2126933517 1.1552955946000001" />
    <mesh name="tibia_r_geom_2_r_fibula" file="Geometry/r_fibula.stl" scale="1.1224621511999999 1.2126933517 1.1552955946000001" />
    <mesh name="talus_r_geom_1_r_talus" file="Geometry/r_talus.stl" scale="0.96461705320000002 0.98812069970000005 0.97562538860000003" />
    <mesh name="calcn_r_geom_1_r_foot" file="Geometry/r_foot.stl" scale="1.1401912955 1.1283880467 1.1332685907" />
    <mesh name="toes_r_geom_1_r_bofoot" file="Geometry/r_bofoot.stl" scale="1.0587855416 1.0586484575999999 1.0588946065" />
    <mesh name="patella_r_geom_1_r_patella" file="Geometry/r_patella.stl" scale="1 1 1" />
    <mesh name="femur_l_geom_1_l_femur" file="Geometry/l_femur.stl" scale="0.8843731064 0.88969751389999996 0.88503149280000004" />
    <mesh name="tibia_l_geom_1_l_tibia" file="Geometry/l_tibia.stl" scale="1.1224621511999999 1.2126933517 1.1552955946000001" />
    <mesh name="tibia_l_geom_2_l_fibula" file="Geometry/l_fibula.stl" scale="1.1224621511999999 1.2126933517 1.1552955946000001" />
    <mesh name="talus_l_geom_1_l_talus" file="Geometry/l_talus.stl" scale="0.96461705320000002 0.98812069970000005 0.97562538860000003" />
    <mesh name="calcn_l_geom_1_l_foot" file="Geometry/l_foot.stl" scale="1.1401912955 1.1283880467 1.1332685907" />
    <mesh name="toes_l_geom_1_l_bofoot" file="Geometry/l_bofoot.stl" scale="1.0587855416 1.0586484575999999 1.0588946065" />
    <mesh name="patella_l_geom_1_l_patella" file="Geometry/l_patella.stl" scale="1 1 1" />
    <mesh name="torso_geom_1_hat_spine" file="Geometry/hat_spine.stl" scale="1.1530451152000001 0.89450816720000004 1.0867378760999999" />
    <mesh name="torso_geom_2_hat_jaw" file="Geometry/hat_jaw.stl" scale="1.1530451152000001 0.89450816720000004 1.0867378760999999" />
    <mesh name="torso_geom_3_hat_skull" file="Geometry/hat_skull.stl" scale="1.1530451152000001 0.89450816720000004 1.0867378760999999" />
    <mesh name="torso_geom_4_hat_ribs_scap" file="Geometry/hat_ribs_scap.stl" scale="1.1530451152000001 0.89450816720000004 1.0867378760999999" />
  </asset>
  <tendon>
    
    <spatial name="addbrev_r_tendon">
      <site site="addbrev_r_addbrev_r-P1" />
      <geom geom="AB_at_femshaft_r_cylinder" sidesite="AB_at_femshaft_r_cylinder_addbrev_r_1_sidesite" />
      <site site="addbrev_r_addbrev_r-P2" />
    </spatial>
    <spatial name="addlong_r_tendon">
      <site site="addlong_r_addlong_r-P1" />
      <geom geom="AL_at_femshaft_r_cylinder" sidesite="AL_at_femshaft_r_cylinder_addlong_r_1_sidesite" />
      <site site="addlong_r_addlong_r-P2" />
    </spatial>
    <spatial name="addmagDist_r_tendon">
      <site site="addmagDist_r_addmagDist_r-P1" />
      <geom geom="AMdist_at_femshaft_r_cylinder" sidesite="AMdist_at_femshaft_r_cylinder_addmagDist_r_1_sidesite" />
      <site site="addmagDist_r_addmagDist_r-P2" />
    </spatial>
    <spatial name="addmagIsch_r_tendon">
      <site site="addmagIsch_r_addmagIsch_r-P1" />
      <geom geom="AMisch_at_condyles_r_cylinder" sidesite="AMisch_at_condyles_r_cylinder_addmagIsch_r_1_sidesite" />
      <site site="addmagIsch_r_addmagIsch_r-P2" />
    </spatial>
    <spatial name="addmagMid_r_tendon">
      <site site="addmagMid_r_addmagMid_r-P1" />
      <geom geom="AMmid_at_femshaft_r_cylinder" sidesite="AMmid_at_femshaft_r_cylinder_addmagMid_r_1_sidesite" />
      <site site="addmagMid_r_addmagMid_r-P2" />
    </spatial>
    <spatial name="addmagProx_r_tendon">
      <site site="addmagProx_r_addmagProx_r-P1" />
      <geom geom="AMprox_at_femshaft_r_cylinder" sidesite="AMprox_at_femshaft_r_cylinder_addmagProx_r_1_sidesite" />
      <site site="addmagProx_r_addmagProx_r-P2" />
    </spatial>
    <spatial name="bflh_r_tendon">
      <site site="bflh_r_bflh_r-P1" />
      <site site="bflh_r_bflh_r-P2" />
      <site site="bflh_r_bflh_r-P3" />
    </spatial>
    <spatial name="bfsh_r_tendon">
      <site site="bfsh_r_bfsh_r-P1" />
      <site site="bfsh_r_bfsh_r-P2" />
    </spatial>
    <spatial name="edl_r_tendon">
      <site site="edl_r_edl_r-P1" />
      <site site="edl_r_edl_r-P2" />
      <site site="edl_r_edl_r-P3" />
      <site site="edl_r_edl_r-P4" />
      <site site="edl_r_edl_r-P5" />
      <site site="edl_r_edl_r-P6" />
    </spatial>
    <spatial name="ehl_r_tendon">
      <site site="ehl_r_ehl_r-P1" />
      <site site="ehl_r_ehl_r-P2" />
      <site site="ehl_r_ehl_r-P3" />
      <site site="ehl_r_ehl_r-P4" />
      <site site="ehl_r_ehl_r-P5" />
      <site site="ehl_r_ehl_r-P6" />
      <site site="ehl_r_ehl_r-P7" />
      <site site="ehl_r_ehl_r-P8" />
    </spatial>
    <spatial name="fdl_r_tendon">
      <site site="fdl_r_fdl_r-P1" />
      <site site="fdl_r_fdl_r-P2" />
      <site site="fdl_r_fdl_r-P3" />
      <site site="fdl_r_fdl_r-P4" />
      <site site="fdl_r_fdl_r-P5" />
      <site site="fdl_r_fdl_r-P6" />
      <site site="fdl_r_fdl_r-P7" />
      <site site="fdl_r_fdl_r-P8" />
    </spatial>
    <spatial name="fhl_r_tendon">
      <site site="fhl_r_fhl_r-P1" />
      <site site="fhl_r_fhl_r-P2" />
      <site site="fhl_r_fhl_r-P3" />
      <site site="fhl_r_fhl_r-P4" />
      <site site="fhl_r_fhl_r-P5" />
      <site site="fhl_r_fhl_r-P6" />
      <site site="fhl_r_fhl_r-P7" />
    </spatial>
    <spatial name="gaslat_r_tendon">
      <site site="gaslat_r_gaslat_r-P1" />
      <geom geom="GasLat_at_shank_r_cylinder" sidesite="GasLat_at_shank_r_cylinder_gaslat_r_1_sidesite" />
      <site site="gaslat_r_gaslat_r-P2" />
    </spatial>
    <spatial name="gasmed_r_tendon">
      <site site="gasmed_r_gasmed_r-P1" />
      <geom geom="GasMed_at_shank_r_cylinder" sidesite="GasMed_at_shank_r_cylinder_gasmed_r_1_sidesite" />
      <site site="gasmed_r_gasmed_r-P2" />
    </spatial>
    <spatial name="glmax1_r_tendon">
      <site site="glmax1_r_glmax1_r-P1" />
      <site site="glmax1_r_glmax1_r-P2" />
      <geom geom="Gmax1_at_pelvis_r_cylinder" sidesite="Gmax1_at_pelvis_r_cylinder_glmax1_r_2_sidesite" />
      <site site="glmax1_r_glmax1_r-P3" />
      <site site="glmax1_r_glmax1_r-P4" />
    </spatial>
    <spatial name="glmax2_r_tendon">
      <site site="glmax2_r_glmax2_r-P1" />
      <site site="glmax2_r_glmax2_r-P2" />
      <geom geom="Gmax2_at_pelvis_r_cylinder" sidesite="Gmax2_at_pelvis_r_cylinder_glmax2_r_2_sidesite" />
      <site site="glmax2_r_glmax2_r-P3" />
      <site site="glmax2_r_glmax2_r-P4" />
    </spatial>
    <spatial name="glmax3_r_tendon">
      <site site="glmax3_r_glmax3_r-P1" />
      <site site="glmax3_r_glmax3_r-P2" />
      <site site="glmax3_r_glmax3_r-P3" />
      <site site="glmax3_r_glmax3_r-P4" />
    </spatial>
    <spatial name="glmed1_r_tendon">
      <site site="glmed1_r_glmed1_r-P1" />
      <site site="glmed1_r_glmed1_r-P2_0" />
    </spatial>
    <spatial name="glmed2_r_tendon">
      <site site="glmed2_r_glmed2_r-P1" />
      <site site="glmed2_r_glmed2_r-P2_0" />
    </spatial>
    <spatial name="glmed3_r_tendon">
      <site site="glmed3_r_glmed3_r-P1" />
      <site site="glmed3_r_glmed3_r-P2_0" />
    </spatial>
    <spatial name="glmin1_r_tendon">
      <site site="glmin1_r_glmin1_r-P1" />
      <site site="glmin1_r_glmin1_r-P2" />
    </spatial>
    <spatial name="glmin2_r_tendon">
      <site site="glmin2_r_glmin2_r-P1" />
      <site site="glmin2_r_glmin2_r-P2" />
    </spatial>
    <spatial name="glmin3_r_tendon">
      <site site="glmin3_r_glmin3_r-P1" />
      <site site="glmin3_r_glmin3_r-P2" />
    </spatial>
    <spatial name="grac_r_tendon">
      <site site="grac_r_grac_r-P1" />
      <geom geom="GR_at_condyles_r_cylinder" sidesite="GR_at_condyles_r_cylinder_grac_r_1_sidesite" />
      <site site="grac_r_grac_r-P2" />
      <site site="grac_r_grac_r-P3" />
    </spatial>
    <spatial name="iliacus_r_tendon">
      <site site="iliacus_r_iliacus_r-P1" />
      <site site="iliacus_r_iliacus_r-P2" />
      <geom geom="IL_at_brim_r_cylinder" sidesite="IL_at_brim_r_cylinder_iliacus_r_2_sidesite" />
      <site site="iliacus_r_iliacus_r-P3" />
      <site site="iliacus_r_iliacus_r-P4" />
    </spatial>
    <spatial name="perbrev_r_tendon">
      <site site="perbrev_r_perbrev_r-P1" />
      <site site="perbrev_r_perbrev_r-P2" />
      <site site="perbrev_r_perbrev_r-P3" />
      <site site="perbrev_r_perbrev_r-P4" />
      <site site="perbrev_r_perbrev_r-P5" />
    </spatial>
    <spatial name="perlong_r_tendon">
      <site site="perlong_r_perlong_r-P1" />
      <site site="perlong_r_perlong_r-P2" />
      <site site="perlong_r_perlong_r-P3" />
      <site site="perlong_r_perlong_r-P4" />
      <site site="perlong_r_perlong_r-P5" />
      <site site="perlong_r_perlong_r-P6" />
      <site site="perlong_r_perlong_r-P7" />
    </spatial>
    <spatial name="piri_r_tendon">
      <site site="piri_r_piri_r-P1" />
      <site site="piri_r_piri_r-P2" />
      <site site="piri_r_piri_r-P3" />
    </spatial>
    <spatial name="psoas_r_tendon">
      <site site="psoas_r_psoas_r-P1" />
      <site site="psoas_r_psoas_r-P2" />
      <geom geom="PS_at_brim_r_cylinder" sidesite="PS_at_brim_r_cylinder_psoas_r_2_sidesite" />
      <site site="psoas_r_psoas_r-P3" />
      <site site="psoas_r_psoas_r-P4" />
    </spatial>
    <spatial name="recfem_r_tendon">
      <site site="recfem_r_recfem_r-P1" />
      <site site="recfem_r_recfem_r-P2" />
      <site site="recfem_r_recfem_r-P3" />
      <geom geom="KnExt_at_fem_r_cylinder" sidesite="KnExt_at_fem_r_cylinder_recfem_r_3_sidesite" />
      <site site="recfem_r_recfem_r-P4" />
      <site site="recfem_r_recfem_r-P5" />
    </spatial>
    <spatial name="sart_r_tendon">
      <site site="sart_r_sart_r-P1" />
      <site site="sart_r_sart_r-P2" />
      <site site="sart_r_sart_r-P3" />
      <site site="sart_r_sart_r-P4" />
      <site site="sart_r_sart_r-P5" />
    </spatial>
    <spatial name="semimem_r_tendon">
      <site site="semimem_r_semimem_r-P1" />
      <geom geom="SM_at_condyles_r_cylinder" sidesite="SM_at_condyles_r_cylinder_semimem_r_1_sidesite" />
      <site site="semimem_r_semimem_r-P2" />
    </spatial>
    <spatial name="semiten_r_tendon">
      <site site="semiten_r_semiten_r-P1" />
      <geom geom="ST_at_condyles_r_cylinder" sidesite="ST_at_condyles_r_cylinder_semiten_r_1_sidesite" />
      <site site="semiten_r_semiten_r-P2" />
      <site site="semiten_r_semiten_r-P3" />
    </spatial>
    <spatial name="soleus_r_tendon">
      <site site="soleus_r_soleus_r-P1" />
      <site site="soleus_r_soleus_r-P2" />
    </spatial>
    <spatial name="tfl_r_tendon">
      <site site="tfl_r_tfl_r-P1" />
      <site site="tfl_r_tfl_r-P2" />
      <site site="tfl_r_tfl_r-P3" />
      <site site="tfl_r_tfl_r-P4" />
    </spatial>
    <spatial name="tibant_r_tendon">
      <site site="tibant_r_tibant_r-P1" />
      <site site="tibant_r_tibant_r-P2" />
      <site site="tibant_r_tibant_r-P3" />
      <site site="tibant_r_tibant_r-P4" />
    </spatial>
    <spatial name="tibpost_r_tendon">
      <site site="tibpost_r_tibpost_r-P1" />
      <site site="tibpost_r_tibpost_r-P2" />
      <site site="tibpost_r_tibpost_r-P3" />
      <site site="tibpost_r_tibpost_r-P4" />
    </spatial>
    <spatial name="vasint_r_tendon">
      <site site="vasint_r_vasint_r-P1" />
      <site site="vasint_r_vasint_r-P2" />
      <site site="vasint_r_vasint_r-P3" />
      <geom geom="KnExt_at_fem_r_cylinder" sidesite="KnExt_at_fem_r_cylinder_vasint_r_3_sidesite" />
      <site site="vasint_r_vasint_r-P4" />
      <geom geom="KnExt_at_fem_r_cylinder" sidesite="KnExt_at_fem_r_cylinder_vasint_r_4_sidesite" />
      <site site="vasint_r_vasint_r-P5" />
    </spatial>
    <spatial name="vaslat_r_tendon">
      <site site="vaslat_r_vaslat_r-P1" />
      <site site="vaslat_r_vaslat_r-P2" />
      <site site="vaslat_r_vaslat_r-P3" />
      <geom geom="KnExt_at_fem_r_cylinder" sidesite="KnExt_at_fem_r_cylinder_vaslat_r_3_sidesite" />
      <site site="vaslat_r_vaslat_r-P4" />
      <site site="vaslat_r_vaslat_r-P5" />
    </spatial>
    <spatial name="vasmed_r_tendon">
      <site site="vasmed_r_vasmed_r-P1" />
      <site site="vasmed_r_vasmed_r-P2" />
      <site site="vasmed_r_vasmed_r-P3" />
      <geom geom="KnExt_at_fem_r_cylinder" sidesite="KnExt_at_fem_r_cylinder_vasmed_r_3_sidesite" />
      <site site="vasmed_r_vasmed_r-P4" />
      <geom geom="KnExt_at_fem_r_cylinder" sidesite="KnExt_at_fem_r_cylinder_vasmed_r_4_sidesite" />
      <site site="vasmed_r_vasmed_r-P5" />
    </spatial>
    <spatial name="addbrev_l_tendon">
      <site site="addbrev_l_addbrev_l-P1" />
      <geom geom="AB_at_femshaft_l_cylinder" sidesite="AB_at_femshaft_l_cylinder_addbrev_l_1_sidesite" />
      <site site="addbrev_l_addbrev_l-P2" />
    </spatial>
    <spatial name="addlong_l_tendon">
      <site site="addlong_l_addlong_l-P1" />
      <geom geom="AL_at_femshaft_l_cylinder" sidesite="AL_at_femshaft_l_cylinder_addlong_l_1_sidesite" />
      <site site="addlong_l_addlong_l-P2" />
    </spatial>
    <spatial name="addmagDist_l_tendon">
      <site site="addmagDist_l_addmagDist_l-P1" />
      <geom geom="AMdist_at_femshaft_l_cylinder" sidesite="AMdist_at_femshaft_l_cylinder_addmagDist_l_1_sidesite" />
      <site site="addmagDist_l_addmagDist_l-P2" />
    </spatial>
    <spatial name="addmagIsch_l_tendon">
      <site site="addmagIsch_l_addmagIsch_l-P1" />
      <geom geom="AMisch_at_condyles_l_cylinder" sidesite="AMisch_at_condyles_l_cylinder_addmagIsch_l_1_sidesite" />
      <site site="addmagIsch_l_addmagIsch_l-P2" />
    </spatial>
    <spatial name="addmagMid_l_tendon">
      <site site="addmagMid_l_addmagMid_l-P1" />
      <geom geom="AMmid_at_femshaft_l_cylinder" sidesite="AMmid_at_femshaft_l_cylinder_addmagMid_l_1_sidesite" />
      <site site="addmagMid_l_addmagMid_l-P2" />
    </spatial>
    <spatial name="addmagProx_l_tendon">
      <site site="addmagProx_l_addmagProx_l-P1" />
      <geom geom="AMprox_at_femshaft_l_cylinder" sidesite="AMprox_at_femshaft_l_cylinder_addmagProx_l_1_sidesite" />
      <site site="addmagProx_l_addmagProx_l-P2" />
    </spatial>
    <spatial name="bflh_l_tendon">
      <site site="bflh_l_bflh_l-P1" />
      <site site="bflh_l_bflh_l-P2" />
      <site site="bflh_l_bflh_l-P3" />
    </spatial>
    <spatial name="bfsh_l_tendon">
      <site site="bfsh_l_bfsh_l-P1" />
      <site site="bfsh_l_bfsh_l-P2" />
    </spatial>
    <spatial name="edl_l_tendon">
      <site site="edl_l_edl_l-P1" />
      <site site="edl_l_edl_l-P2" />
      <site site="edl_l_edl_l-P3" />
      <site site="edl_l_edl_l-P4" />
      <site site="edl_l_edl_l-P5" />
      <site site="edl_l_edl_l-P6" />
    </spatial>
    <spatial name="ehl_l_tendon">
      <site site="ehl_l_ehl_l-P1" />
      <site site="ehl_l_ehl_l-P2" />
      <site site="ehl_l_ehl_l-P3" />
      <site site="ehl_l_ehl_l-P4" />
      <site site="ehl_l_ehl_l-P5" />
      <site site="ehl_l_ehl_l-P6" />
      <site site="ehl_l_ehl_l-P7" />
      <site site="ehl_l_ehl_l-P8" />
    </spatial>
    <spatial name="fdl_l_tendon">
      <site site="fdl_l_fdl_l-P1" />
      <site site="fdl_l_fdl_l-P2" />
      <site site="fdl_l_fdl_l-P3" />
      <site site="fdl_l_fdl_l-P4" />
      <site site="fdl_l_fdl_l-P5" />
      <site site="fdl_l_fdl_l-P6" />
      <site site="fdl_l_fdl_l-P7" />
      <site site="fdl_l_fdl_l-P8" />
    </spatial>
    <spatial name="fhl_l_tendon">
      <site site="fhl_l_fhl_l-P1" />
      <site site="fhl_l_fhl_l-P2" />
      <site site="fhl_l_fhl_l-P3" />
      <site site="fhl_l_fhl_l-P4" />
      <site site="fhl_l_fhl_l-P5" />
      <site site="fhl_l_fhl_l-P6" />
      <site site="fhl_l_fhl_l-P7" />
    </spatial>
    <spatial name="gaslat_l_tendon">
      <site site="gaslat_l_gaslat_l-P1" />
      <geom geom="GasLat_at_shank_l_cylinder" sidesite="GasLat_at_shank_l_cylinder_gaslat_l_1_sidesite" />
      <site site="gaslat_l_gaslat_l-P2" />
    </spatial>
    <spatial name="gasmed_l_tendon">
      <site site="gasmed_l_gasmed_l-P1" />
      <geom geom="GasMed_at_shank_l_cylinder" sidesite="GasMed_at_shank_l_cylinder_gasmed_l_1_sidesite" />
      <site site="gasmed_l_gasmed_l-P2" />
    </spatial>
    <spatial name="glmax1_l_tendon">
      <site site="glmax1_l_glmax1_l-P1" />
      <site site="glmax1_l_glmax1_l-P2" />
      <geom geom="Gmax1_at_pelvis_l_cylinder" sidesite="Gmax1_at_pelvis_l_cylinder_glmax1_l_2_sidesite" />
      <site site="glmax1_l_glmax1_l-P3" />
      <site site="glmax1_l_glmax1_l-P4" />
    </spatial>
    <spatial name="glmax2_l_tendon">
      <site site="glmax2_l_glmax2_l-P1" />
      <site site="glmax2_l_glmax2_l-P2" />
      <geom geom="Gmax2_at_pelvis_l_cylinder" sidesite="Gmax2_at_pelvis_l_cylinder_glmax2_l_2_sidesite" />
      <site site="glmax2_l_glmax2_l-P3" />
      <site site="glmax2_l_glmax2_l-P4" />
    </spatial>
    <spatial name="glmax3_l_tendon">
      <site site="glmax3_l_glmax3_l-P1" />
      <site site="glmax3_l_glmax3_l-P2" />
      <site site="glmax3_l_glmax3_l-P3" />
      <site site="glmax3_l_glmax3_l-P4" />
    </spatial>
    <spatial name="glmed1_l_tendon">
      <site site="glmed1_l_glmed1_l-P1" />
      <site site="glmed1_l_glmed1_l-P2" />
    </spatial>
    <spatial name="glmed2_l_tendon">
      <site site="glmed2_l_glmed2_l-P1" />
      <site site="glmed2_l_glmed2_l-P2" />
    </spatial>
    <spatial name="glmed3_l_tendon">
      <site site="glmed3_l_glmed3_l-P1" />
      <site site="glmed3_l_glmed3_l-P2" />
    </spatial>
    <spatial name="glmin1_l_tendon">
      <site site="glmin1_l_glmin1_l-P1" />
      <site site="glmin1_l_glmin1_l-P2" />
    </spatial>
    <spatial name="glmin2_l_tendon">
      <site site="glmin2_l_glmin2_l-P1" />
      <site site="glmin2_l_glmin2_l-P2" />
    </spatial>
    <spatial name="glmin3_l_tendon">
      <site site="glmin3_l_glmin3_l-P1" />
      <site site="glmin3_l_glmin3_l-P2" />
    </spatial>
    <spatial name="grac_l_tendon">
      <site site="grac_l_grac_l-P1" />
      <geom geom="GR_at_condyles_l_cylinder" sidesite="GR_at_condyles_l_cylinder_grac_l_1_sidesite" />
      <site site="grac_l_grac_l-P2" />
      <site site="grac_l_grac_l-P3" />
    </spatial>
    <spatial name="iliacus_l_tendon">
      <site site="iliacus_l_iliacus_l-P1" />
      <site site="iliacus_l_iliacus_l-P2" />
      <geom geom="IL_at_brim_l_cylinder" sidesite="IL_at_brim_l_cylinder_iliacus_l_2_sidesite" />
      <site site="iliacus_l_iliacus_l-P3" />
      <site site="iliacus_l_iliacus_l-P4" />
    </spatial>
    <spatial name="perbrev_l_tendon">
      <site site="perbrev_l_perbrev_l-P1" />
      <site site="perbrev_l_perbrev_l-P2" />
      <site site="perbrev_l_perbrev_l-P3" />
      <site site="perbrev_l_perbrev_l-P4" />
      <site site="perbrev_l_perbrev_l-P5" />
    </spatial>
    <spatial name="perlong_l_tendon">
      <site site="perlong_l_perlong_l-P1" />
      <site site="perlong_l_perlong_l-P2" />
      <site site="perlong_l_perlong_l-P3" />
      <site site="perlong_l_perlong_l-P4" />
      <site site="perlong_l_perlong_l-P5" />
      <site site="perlong_l_perlong_l-P6" />
      <site site="perlong_l_perlong_l-P7" />
    </spatial>
    <spatial name="piri_l_tendon">
      <site site="piri_l_piri_l-P1" />
      <site site="piri_l_piri_l-P2" />
      <site site="piri_l_piri_l-P3" />
    </spatial>
    <spatial name="psoas_l_tendon">
      <site site="psoas_l_psoas_l-P1" />
      <site site="psoas_l_psoas_l-P2" />
      <geom geom="PS_at_brim_l_cylinder" sidesite="PS_at_brim_l_cylinder_psoas_l_2_sidesite" />
      <site site="psoas_l_psoas_l-P3" />
      <site site="psoas_l_psoas_l-P4" />
    </spatial>
    <spatial name="recfem_l_tendon">
      <site site="recfem_l_recfem_l-P1" />
      <site site="recfem_l_recfem_l-P2" />
      <site site="recfem_l_recfem_l-P3" />
      <geom geom="KnExt_at_fem_l_cylinder" sidesite="KnExt_at_fem_l_cylinder_recfem_l_3_sidesite" />
      <site site="recfem_l_recfem_l-P4" />
      <site site="recfem_l_recfem_l-P5" />
    </spatial>
    <spatial name="sart_l_tendon">
      <site site="sart_l_sart_l-P1" />
      <site site="sart_l_sart_l-P2" />
      <site site="sart_l_sart_l-P3" />
      <site site="sart_l_sart_l-P4" />
      <site site="sart_l_sart_l-P5" />
    </spatial>
    <spatial name="semimem_l_tendon">
      <site site="semimem_l_semimem_l-P1" />
      <geom geom="SM_at_condyles_l_cylinder" sidesite="SM_at_condyles_l_cylinder_semimem_l_1_sidesite" />
      <site site="semimem_l_semimem_l-P2" />
    </spatial>
    <spatial name="semiten_l_tendon">
      <site site="semiten_l_semiten_l-P1" />
      <geom geom="ST_at_condyles_l_cylinder" sidesite="ST_at_condyles_l_cylinder_semiten_l_1_sidesite" />
      <site site="semiten_l_semiten_l-P2" />
      <site site="semiten_l_semiten_l-P3" />
    </spatial>
    <spatial name="soleus_l_tendon">
      <site site="soleus_l_soleus_l-P1" />
      <site site="soleus_l_soleus_l-P2" />
    </spatial>
    <spatial name="tfl_l_tendon">
      <site site="tfl_l_tfl_l-P1" />
      <site site="tfl_l_tfl_l-P2" />
      <site site="tfl_l_tfl_l-P3" />
      <site site="tfl_l_tfl_l-P4" />
    </spatial>
    <spatial name="tibant_l_tendon">
      <site site="tibant_l_tibant_l-P1" />
      <site site="tibant_l_tibant_l-P2" />
      <site site="tibant_l_tibant_l-P3" />
      <site site="tibant_l_tibant_l-P4" />
    </spatial>
    <spatial name="tibpost_l_tendon">
      <site site="tibpost_l_tibpost_l-P1" />
      <site site="tibpost_l_tibpost_l-P2" />
      <site site="tibpost_l_tibpost_l-P3" />
      <site site="tibpost_l_tibpost_l-P4" />
    </spatial>
    <spatial name="vasint_l_tendon">
      <site site="vasint_l_vasint_l-P1" />
      <site site="vasint_l_vasint_l-P2" />
      <site site="vasint_l_vasint_l-P3" />
      <geom geom="KnExt_at_fem_l_cylinder" sidesite="KnExt_at_fem_l_cylinder_vasint_l_3_sidesite" />
      <site site="vasint_l_vasint_l-P4" />
      <geom geom="KnExt_at_fem_l_cylinder" sidesite="KnExt_at_fem_l_cylinder_vasint_l_4_sidesite" />
      <site site="vasint_l_vasint_l-P5" />
    </spatial>
    <spatial name="vaslat_l_tendon">
      <site site="vaslat_l_vaslat_l-P1" />
      <site site="vaslat_l_vaslat_l-P2" />
      <site site="vaslat_l_vaslat_l-P3" />
      <geom geom="KnExt_at_fem_l_cylinder" sidesite="KnExt_at_fem_l_cylinder_vaslat_l_3_sidesite" />
      <site site="vaslat_l_vaslat_l-P4" />
      <site site="vaslat_l_vaslat_l-P5" />
    </spatial>
    <spatial name="vasmed_l_tendon">
      <site site="vasmed_l_vasmed_l-P1" />
      <site site="vasmed_l_vasmed_l-P2" />
      <site site="vasmed_l_vasmed_l-P3" />
      <geom geom="KnExt_at_fem_l_cylinder" sidesite="KnExt_at_fem_l_cylinder_vasmed_l_3_sidesite" />
      <site site="vasmed_l_vasmed_l-P4" />
      <geom geom="KnExt_at_fem_l_cylinder" sidesite="KnExt_at_fem_l_cylinder_vasmed_l_4_sidesite" />
      <site site="vasmed_l_vasmed_l-P5" />
    </spatial>
  </tendon>
  <actuator>
    
    <motor name="lumbar_ext" ctrllimited="false" joint="lumbar_extension" class="motor" />
    <motor name="lumbar_bend" ctrllimited="false" joint="lumbar_bending" class="motor" />
    <motor name="lumbar_rot" ctrllimited="false" joint="lumbar_rotation" class="motor" />
    <muscle name="addbrev_r" lengthrange="0.01 1" force="625.81967213114797" tendon="addbrev_r_tendon" class="muscle" timeconst="0.01 0.04" />
    <muscle name="addlong_r" lengthrange="0.01 1" force="916.79999999999995" tendon="addlong_r_tendon" class="muscle" timeconst="0.01 0.04" />
    <muscle name="addmagDist_r" lengthrange="0.01 1" force="597.29508196721395" tendon="addmagDist_r_tendon" class="muscle" timeconst="0.01 0.04" />
    <muscle name="addmagIsch_r" lengthrange="0.01 1" force="597.29508196721395" tendon="addmagIsch_r_tendon" class="muscle" timeconst="0.01 0.04" />
    <muscle name="addmagMid_r" lengthrange="0.01 1" force="597.29508196721395" tendon="addmagMid_r_tendon" class="muscle" timeconst="0.01 0.04" />
    <muscle name="addmagProx_r" lengthrange="0.01 1" force="597.29508196721395" tendon="addmagProx_r_tendon" class="muscle" timeconst="0.01 0.04" />
    <muscle name="bflh_r" lengthrange="0.01 1" force="1313.18360655738" tendon="bflh_r_tendon" class="muscle" timeconst="0.01 0.04" />
    <muscle name="bfsh_r" lengthrange="0.01 1" force="557.11475409835998" tendon="bfsh_r_tendon" class="muscle" timeconst="0.01 0.04" />
    <muscle name="edl_r" lengthrange="0.01 1" force="603.49815560000002" tendon="edl_r_tendon" class="muscle" timeconst="0.01 0.04" />
    <muscle name="ehl_r" lengthrange="0.01 1" force="285.86754739999998" tendon="ehl_r_tendon" class="muscle" timeconst="0.01 0.04" />
    <muscle name="fdl_r" lengthrange="0.01 1" force="423.17704918032803" tendon="fdl_r_tendon" class="muscle" timeconst="0.01 0.04" />
    <muscle name="fhl_r" lengthrange="0.01 1" force="907.83934426229405" tendon="fhl_r_tendon" class="muscle" timeconst="0.01 0.04" />
    <muscle name="gaslat_r" lengthrange="0.01 1" force="1575.0590163934401" tendon="gaslat_r_tendon" class="muscle" timeconst="0.01 0.04" />
    <muscle name="gasmed_r" lengthrange="0.01 1" force="3115.5147540983598" tendon="gasmed_r_tendon" class="muscle" timeconst="0.01 0.04" />
    <muscle name="glmax1_r" lengthrange="0.01 1" force="983.78360655737799" tendon="glmax1_r_tendon" class="muscle" timeconst="0.01 0.04" />
    <muscle name="glmax2_r" lengthrange="0.01 1" force="1406.0459016393499" tendon="glmax2_r_tendon" class="muscle" timeconst="0.01 0.04" />
    <muscle name="glmax3_r" lengthrange="0.01 1" force="947.75409836065603" tendon="glmax3_r_tendon" class="muscle" timeconst="0.01 0.04" />
    <muscle name="glmed1_r" lengthrange="0.01 1" force="1093.4667688" tendon="glmed1_r_tendon" class="muscle" timeconst="0.01 0.04" />
    <muscle name="glmed2_r" lengthrange="0.01 1" force="765.09166159999995" tendon="glmed2_r_tendon" class="muscle" timeconst="0.01 0.04" />
    <muscle name="glmed3_r" lengthrange="0.01 1" force="871.19926420000002" tendon="glmed3_r_tendon" class="muscle" timeconst="0.01 0.04" />
    <muscle name="glmin1_r" lengthrange="0.01 1" force="374.04590163934398" tendon="glmin1_r_tendon" class="muscle" timeconst="0.01 0.04" />
    <muscle name="glmin2_r" lengthrange="0.01 1" force="394.81967213114802" tendon="glmin2_r_tendon" class="muscle" timeconst="0.01 0.04" />
    <muscle name="glmin3_r" lengthrange="0.01 1" force="446.77377049180399" tendon="glmin3_r_tendon" class="muscle" timeconst="0.01 0.04" />
    <muscle name="grac_r" lengthrange="0.01 1" force="281.31147540983602" tendon="grac_r_tendon" class="muscle" timeconst="0.01 0.04" />
    <muscle name="iliacus_r" lengthrange="0.01 1" force="1021.14098360656" tendon="iliacus_r_tendon" class="muscle" timeconst="0.01 0.04" />
    <muscle name="perbrev_r" lengthrange="0.01 1" force="521.20159880000006" tendon="perbrev_r_tendon" class="muscle" timeconst="0.01 0.04" />
    <muscle name="perlong_r" lengthrange="0.01 1" force="1115.3714213999999" tendon="perlong_r_tendon" class="muscle" timeconst="0.01 0.04" />
    <muscle name="piri_r" lengthrange="0.01 1" force="1029.7868852459001" tendon="piri_r_tendon" class="muscle" timeconst="0.01 0.04" />
    <muscle name="psoas_r" lengthrange="0.01 1" force="1426.79016393443" tendon="psoas_r_tendon" class="muscle" timeconst="0.01 0.04" />
    <muscle name="recfem_r" lengthrange="0.01 1" force="2191.7409836065599" tendon="recfem_r_tendon" class="muscle" timeconst="0.01 0.04" />
    <muscle name="sart_r" lengthrange="0.01 1" force="249.41311475409799" tendon="sart_r_tendon" class="muscle" timeconst="0.01 0.04" />
    <muscle name="semimem_r" lengthrange="0.01 1" force="2200.9868852458999" tendon="semimem_r_tendon" class="muscle" timeconst="0.01 0.04" />
    <muscle name="semiten_r" lengthrange="0.01 1" force="591.29508196721395" tendon="semiten_r_tendon" class="muscle" timeconst="0.01 0.04" />
    <muscle name="soleus_r" lengthrange="0.01 1" force="6194.8426229508204" tendon="soleus_r_tendon" class="muscle" timeconst="0.01 0.04" />
    <muscle name="tfl_r" lengthrange="0.01 1" force="411.20655737704999" tendon="tfl_r_tendon" class="muscle" timeconst="0.01 0.04" />
    <muscle name="tibant_r" lengthrange="0.01 1" force="1227.4524590163901" tendon="tibant_r_tendon" class="muscle" timeconst="0.01 0.04" />
    <muscle name="tibpost_r" lengthrange="0.01 1" force="1730.1540983606501" tendon="tibpost_r_tendon" class="muscle" timeconst="0.01 0.04" />
    <muscle name="vasint_r" lengthrange="0.01 1" force="1697.36065573771" tendon="vasint_r_tendon" class="muscle" timeconst="0.01 0.04" />
    <muscle name="vaslat_r" lengthrange="0.01 1" force="5148.7672131147601" tendon="vaslat_r_tendon" class="muscle" timeconst="0.01 0.04" />
    <muscle name="vasmed_r" lengthrange="0.01 1" force="2747.82295081966" tendon="vasmed_r_tendon" class="muscle" timeconst="0.01 0.04" />
    <muscle name="addbrev_l" lengthrange="0.01 1" force="625.81967213114797" tendon="addbrev_l_tendon" class="muscle" timeconst="0.01 0.04" />
    <muscle name="addlong_l" lengthrange="0.01 1" force="916.79999999999995" tendon="addlong_l_tendon" class="muscle" timeconst="0.01 0.04" />
    <muscle name="addmagDist_l" lengthrange="0.01 1" force="597.29508196721395" tendon="addmagDist_l_tendon" class="muscle" timeconst="0.01 0.04" />
    <muscle name="addmagIsch_l" lengthrange="0.01 1" force="597.29508196721395" tendon="addmagIsch_l_tendon" class="muscle" timeconst="0.01 0.04" />
    <muscle name="addmagMid_l" lengthrange="0.01 1" force="597.29508196721395" tendon="addmagMid_l_tendon" class="muscle" timeconst="0.01 0.04" />
    <muscle name="addmagProx_l" lengthrange="0.01 1" force="597.29508196721395" tendon="addmagProx_l_tendon" class="muscle" timeconst="0.01 0.04" />
    <muscle name="bflh_l" lengthrange="0.01 1" force="1313.18360655738" tendon="bflh_l_tendon" class="muscle" timeconst="0.01 0.04" />
    <muscle name="bfsh_l" lengthrange="0.01 1" force="557.11475409835998" tendon="bfsh_l_tendon" class="muscle" timeconst="0.01 0.04" />
    <muscle name="edl_l" lengthrange="0.01 1" force="603.49815560000002" tendon="edl_l_tendon" class="muscle" timeconst="0.01 0.04" />
    <muscle name="ehl_l" lengthrange="0.01 1" force="285.86754739999998" tendon="ehl_l_tendon" class="muscle" timeconst="0.01 0.04" />
    <muscle name="fdl_l" lengthrange="0.01 1" force="423.17704918032803" tendon="fdl_l_tendon" class="muscle" timeconst="0.01 0.04" />
    <muscle name="fhl_l" lengthrange="0.01 1" force="907.83934426229405" tendon="fhl_l_tendon" class="muscle" timeconst="0.01 0.04" />
    <muscle name="gaslat_l" lengthrange="0.01 1" force="1575.0590163934401" tendon="gaslat_l_tendon" class="muscle" timeconst="0.01 0.04" />
    <muscle name="gasmed_l" lengthrange="0.01 1" force="3115.5147540983598" tendon="gasmed_l_tendon" class="muscle" timeconst="0.01 0.04" />
    <muscle name="glmax1_l" lengthrange="0.01 1" force="983.78360655737799" tendon="glmax1_l_tendon" class="muscle" timeconst="0.01 0.04" />
    <muscle name="glmax2_l" lengthrange="0.01 1" force="1406.0459016393499" tendon="glmax2_l_tendon" class="muscle" timeconst="0.01 0.04" />
    <muscle name="glmax3_l" lengthrange="0.01 1" force="947.75409836065603" tendon="glmax3_l_tendon" class="muscle" timeconst="0.01 0.04" />
    <muscle name="glmed1_l" lengthrange="0.01 1" force="1093.4667688" tendon="glmed1_l_tendon" class="muscle" timeconst="0.01 0.04" />
    <muscle name="glmed2_l" lengthrange="0.01 1" force="765.09166159999995" tendon="glmed2_l_tendon" class="muscle" timeconst="0.01 0.04" />
    <muscle name="glmed3_l" lengthrange="0.01 1" force="871.19926420000002" tendon="glmed3_l_tendon" class="muscle" timeconst="0.01 0.04" />
    <muscle name="glmin1_l" lengthrange="0.01 1" force="374.04590163934398" tendon="glmin1_l_tendon" class="muscle" timeconst="0.01 0.04" />
    <muscle name="glmin2_l" lengthrange="0.01 1" force="394.81967213114802" tendon="glmin2_l_tendon" class="muscle" timeconst="0.01 0.04" />
    <muscle name="glmin3_l" lengthrange="0.01 1" force="446.77377049180399" tendon="glmin3_l_tendon" class="muscle" timeconst="0.01 0.04" />
    <muscle name="grac_l" lengthrange="0.01 1" force="281.31147540983602" tendon="grac_l_tendon" class="muscle" timeconst="0.01 0.04" />
    <muscle name="iliacus_l" lengthrange="0.01 1" force="1021.14098360656" tendon="iliacus_l_tendon" class="muscle" timeconst="0.01 0.04" />
    <muscle name="perbrev_l" lengthrange="0.01 1" force="521.20159880000006" tendon="perbrev_l_tendon" class="muscle" timeconst="0.01 0.04" />
    <muscle name="perlong_l" lengthrange="0.01 1" force="1115.3714213999999" tendon="perlong_l_tendon" class="muscle" timeconst="0.01 0.04" />
    <muscle name="piri_l" lengthrange="0.01 1" force="1029.7868852459001" tendon="piri_l_tendon" class="muscle" timeconst="0.01 0.04" />
    <muscle name="psoas_l" lengthrange="0.01 1" force="1426.79016393443" tendon="psoas_l_tendon" class="muscle" timeconst="0.01 0.04" />
    <muscle name="recfem_l" lengthrange="0.01 1" force="2191.7409836065599" tendon="recfem_l_tendon" class="muscle" timeconst="0.01 0.04" />
    <muscle name="sart_l" lengthrange="0.01 1" force="249.41311475409799" tendon="sart_l_tendon" class="muscle" timeconst="0.01 0.04" />
    <muscle name="semimem_l" lengthrange="0.01 1" force="2200.9868852458999" tendon="semimem_l_tendon" class="muscle" timeconst="0.01 0.04" />
    <muscle name="semiten_l" lengthrange="0.01 1" force="591.29508196721395" tendon="semiten_l_tendon" class="muscle" timeconst="0.01 0.04" />
    <muscle name="soleus_l" lengthrange="0.01 1" force="6194.8426229508204" tendon="soleus_l_tendon" class="muscle" timeconst="0.01 0.04" />
    <muscle name="tfl_l" lengthrange="0.01 1" force="411.20655737704999" tendon="tfl_l_tendon" class="muscle" timeconst="0.01 0.04" />
    <muscle name="tibant_l" lengthrange="0.01 1" force="1227.4524590163901" tendon="tibant_l_tendon" class="muscle" timeconst="0.01 0.04" />
    <muscle name="tibpost_l" lengthrange="0.01 1" force="1730.1540983606501" tendon="tibpost_l_tendon" class="muscle" timeconst="0.01 0.04" />
    <muscle name="vasint_l" lengthrange="0.01 1" force="1697.36065573771" tendon="vasint_l_tendon" class="muscle" timeconst="0.01 0.04" />
    <muscle name="vaslat_l" lengthrange="0.01 1" force="5148.7672131147601" tendon="vaslat_l_tendon" class="muscle" timeconst="0.01 0.04" />
    <muscle name="vasmed_l" lengthrange="0.01 1" force="2747.82295081966" tendon="vasmed_l_tendon" class="muscle" timeconst="0.01 0.04" />
  </actuator>
  <equality>
    
    <joint joint1="walker_knee_r_translation1" joint2="knee_angle_r" polycoef="8.485e-08 0.002784 -0.002053 0.0004996 5.057e-07" solimp="0.9999 0.9999 0.001 0.5 2" active="true" />
    <joint joint1="walker_knee_r_translation2" joint2="knee_angle_r" polycoef="6.808e-11 0.005204 -0.001112 -2.317e-06 5.526e-07" solimp="0.9999 0.9999 0.001 0.5 2" active="true" />
    <joint joint1="walker_knee_r_rotation2" joint2="knee_angle_r" polycoef="-1.473e-08 0.0791 -0.03285 -0.02522 0.01083" solimp="0.9999 0.9999 0.001 0.5 2" active="true" />
    <joint joint1="walker_knee_r_rotation3" joint2="knee_angle_r" polycoef="1.089e-08 0.3695 -0.1695 0.02516 3.505e-07" solimp="0.9999 0.9999 0.001 0.5 2" active="true" />
    <joint name="mtp_angle_r_locked" active="true" joint1="mtp_angle_r" polycoef="0.0 0 0 0 0" solimp="0.9999 0.9999 0.001 0.5 2" />
    <joint joint1="patellofemoral_r_translation1" joint2="knee_angle_r" polycoef="0.04636 -0.01328 -0.03011 0.0118 -0.0007775" solimp="0.9999 0.9999 0.001 0.5 2" active="true" />
    <joint joint1="patellofemoral_r_translation2" joint2="knee_angle_r" polycoef="-0.009634 -0.0434 0.008253 0.01171 -0.003111" solimp="0.9999 0.9999 0.001 0.5 2" active="true" />
    <joint joint1="patellofemoral_r_rotation1" joint2="knee_angle_r" polycoef="0.01051 0.02476 -1.316 0.7163 -0.1383" solimp="0.9999 0.9999 0.001 0.5 2" active="true" />
    <joint name="patellofemoral_r_translation3_locked" active="true" joint1="patellofemoral_r_translation3" polycoef="0.0024338366052 0 0 0 0" solimp="0.9999 0.9999 0.001 0.5 2" />
    <joint joint1="walker_knee_l_translation1" joint2="knee_angle_l" polycoef="8.485e-08 0.002784 -0.002053 0.0004996 5.057e-07" solimp="0.9999 0.9999 0.001 0.5 2" active="true" />
    <joint joint1="walker_knee_l_translation2" joint2="knee_angle_l" polycoef="-6.808e-11 -0.005204 0.001112 2.317e-06 -5.526e-07" solimp="0.9999 0.9999 0.001 0.5 2" active="true" />
    <joint joint1="walker_knee_l_rotation2" joint2="knee_angle_l" polycoef="-1.473e-08 0.0791 -0.03285 -0.02522 0.01083" solimp="0.9999 0.9999 0.001 0.5 2" active="true" />
    <joint joint1="walker_knee_l_rotation3" joint2="knee_angle_l" polycoef="-1.089e-08 -0.3695 0.1695 -0.02516 -3.505e-07" solimp="0.9999 0.9999 0.001 0.5 2" active="true" />
    <joint name="mtp_angle_l_locked" active="true" joint1="mtp_angle_l" polycoef="0.0 0 0 0 0" solimp="0.9999 0.9999 0.001 0.5 2" />
    <joint joint1="patellofemoral_l_translation1" joint2="knee_angle_l" polycoef="0.04636 -0.01328 -0.03011 0.0118 -0.0007775" solimp="0.9999 0.9999 0.001 0.5 2" active="true" />
    <joint joint1="patellofemoral_l_translation2" joint2="knee_angle_l" polycoef="-0.009634 -0.0434 0.008253 0.01171 -0.003111" solimp="0.9999 0.9999 0.001 0.5 2" active="true" />
    <joint joint1="patellofemoral_l_rotation1" joint2="knee_angle_l" polycoef="0.01051 0.02476 -1.316 0.7163 -0.1383" solimp="0.9999 0.9999 0.001 0.5 2" active="true" />
    <joint name="patellofemoral_l_translation3_locked" active="true" joint1="patellofemoral_l_translation3" polycoef="-0.0024338366052 0 0 0 0" solimp="0.9999 0.9999 0.001 0.5 2" />
  </equality>
  <contact>
    
    <pair geom1="ground-plane" geom2="pelvis_geom_1" />
    <pair geom1="ground-plane" geom2="pelvis_geom_2" />
    <pair geom1="ground-plane" geom2="pelvis_geom_3" />
    <pair geom1="ground-plane" geom2="femur_r_geom_1" />
    <pair geom1="ground-plane" geom2="tibia_r_geom_1" />
    <pair geom1="ground-plane" geom2="tibia_r_geom_2" />
    <pair geom1="ground-plane" geom2="talus_r_geom_1" />
    <pair geom1="ground-plane" geom2="calcn_r_geom_1" />
    <pair geom1="ground-plane" geom2="toes_r_geom_1" />
    <pair geom1="ground-plane" geom2="patella_r_geom_1" />
    <pair geom1="ground-plane" geom2="femur_l_geom_1" />
    <pair geom1="ground-plane" geom2="tibia_l_geom_1" />
    <pair geom1="ground-plane" geom2="tibia_l_geom_2" />
    <pair geom1="ground-plane" geom2="talus_l_geom_1" />
    <pair geom1="ground-plane" geom2="calcn_l_geom_1" />
    <pair geom1="ground-plane" geom2="toes_l_geom_1" />
    <pair geom1="ground-plane" geom2="patella_l_geom_1" />
    <pair geom1="ground-plane" geom2="torso_geom_1" />
    <pair geom1="ground-plane" geom2="torso_geom_2" />
    <pair geom1="ground-plane" geom2="torso_geom_3" />
    <pair geom1="ground-plane" geom2="torso_geom_4" />
  </contact>
  <keyframe>
    <key name="default-pose" qpos="0 0.93 0 0 0 0 0 0 0 8.485e-08 6.808e-11 0 -1.473e-08 1.089e-08 0 0 0 0.04636 -0.009634 0.002434 0.01051 0 -0 -0 8.485e-08 -6.808e-11 0 -1.473e-08 -1.089e-08 0 0 0 0.04636 -0.009634 -0.002434 0.01051 0 0 0" />
  </keyframe>
</mujoco>