<mujoco model="template">
  <!-- This model has been converted from an OpenSim model. Model conversion by MyoConverter https://github.com/MyoHub/myoconverter. This model is licensed under Apache 2.0. -->
  <!-- Note: inertiagrouprange="0 1" means that groups 0-1 will be used to infer masses/inertias, and groups 2-5 are
  only for visualisation (e.g. wrapping objects) !-->
  <compiler inertiafromgeom="auto" angle="radian" balanceinertia="true" boundmass="0.001" boundinertia="0.001" inertiagrouprange="0 1">
    <lengthrange inttotal="50" useexisting="true"/>
  </compiler>
  <option collision="predefined"/>
  <visual>
    <scale framelength="0.5" framewidth="0.01"/>
  </visual>
  <default>
    <joint limited="true" damping="0.05" armature="0.00001" stiffness="0"/>
    <geom rgba="0.8 0.6 .4 1" margin="0.001"/>
    <site size="0.001"/>
    <tendon width="0.005" rgba=".95 .3 .3 1" limited="false"/>
    <default class="muscle">
      <muscle ctrllimited="true" ctrlrange="0 1" scale="200"/>
    </default>
    <default class="motor">
      <general gainprm="5 0 0 0 0 0 0 0 0 0"/>
    </default>
  </default>
  <option timestep="0.002"/>
  <!-- nuser_jnt=1, the parameter is used to store default value of the joint, and nkey=1 to store keyframe with
   default joint positions set !-->
  <size njmax="1000" nconmax="400" nuser_jnt="1" nkey="1"/>
  <worldbody>
    <!-- The converter script assumes a body named 'ground' exists as a child element of worldbody -->
    <body name="ground" euler="1.571 0 0">
      <geom name="ground-plane" pos="0 0 0" euler="-1.571 0 0" size="10 10 0.125" type="plane" rgba="1.0 0.7 0.4 1.0" condim="3"/>
    </body>
    <light directional="true"/>
    <body name="pelvis" pos="0 0 0" euler="1.571 0 0">
      <inertial mass="10.2627234097" pos="-0.070699999999999999 0 0" fullinertia="0.089582063899999995 0.0759007565 0.050455267499999998 0 0 0"/>
      <geom name="pelvis_geom_1" type="mesh" mesh="pelvis_geom_1_r_pelvis" rgba="1 1 1 1" group="0"/>
      <geom name="pelvis_geom_2" type="mesh" mesh="pelvis_geom_2_l_pelvis" rgba="1 1 1 1" group="0"/>
      <geom name="pelvis_geom_3" type="mesh" mesh="pelvis_geom_3_sacrum" rgba="1 1 1 1" group="0"/>
      <geom name="Gmax1_at_pelvis_r_cylinder" type="cylinder" euler="-0.6 0.45 0" pos="-0.079 -0.09987 0.06313" size="0.04086 0.07699" rgba="0.19 0.83 0.78 0.2" group="2"/>
      <site name="Gmax1_at_pelvis_r_sidesite" pos="-0.1167 -0.08959 0.07815" size="0.0005"/>
      <geom name="Gmax2_at_pelvis_r_cylinder" type="cylinder" euler="-0.75 0.39 0" pos="-0.08207 -0.08373 0.07037" size="0.04093 0.05116" rgba="0.19 0.83 0.78 0.2" group="2"/>
      <geom name="Gmax3_at_pelvis_r_cylinder" type="cylinder" euler="-0.1 0 0" pos="-0.08515 -0.08878 0.07037" size="0.0407 0.05173" rgba="0.19 0.83 0.78 0.2" group="2"/>
      <geom name="Gmax1_at_pelvis_l_cylinder" type="cylinder" euler="0.6 -0.45 0" pos="-0.079 -0.09987 -0.06313" size="0.04086 0.07699" rgba="0.19 0.83 0.78 0.2" group="2"/>
      <site name="Gmax1_at_pelvis_l_sidesite" pos="-0.1167 -0.08959 -0.07815" size="0.0005"/>
      <geom name="Gmax2_at_pelvis_l_cylinder" type="cylinder" euler="0.75 -0.39 0" pos="-0.08207 -0.08373 -0.07037" size="0.04093 0.05116" rgba="0.19 0.83 0.78 0.2" group="2"/>
      <geom name="Gmax3_at_pelvis_l_cylinder" type="cylinder" euler="0.1 0 0" pos="-0.08515 -0.08878 -0.07037" size="0.0407 0.05173" rgba="0.19 0.83 0.78 0.2" group="2"/>
      <geom name="PS_at_brim_r_cylinder" type="cylinder" euler="-0.25 -0.27 0.1" pos="-0.07592 -0.06053 0.06789" size="0.05092 0.05164" rgba="0.19 0.83 0.78 0.2" group="2"/>
      <site name="PS_at_brim_r_sidesite" pos="-0.07092 -0.1102 0.08201" size="0.0005"/>
      <geom name="PS_at_brim_l_cylinder" type="cylinder" euler="0.25 0.27 0.1" pos="-0.07592 -0.06053 -0.06789" size="0.05092 0.05164" rgba="0.19 0.83 0.78 0.2" group="2"/>
      <site name="PS_at_brim_l_sidesite" pos="-0.07092 -0.1102 -0.08201" size="0.0005"/>
      <geom name="IL_at_brim_r_cylinder" type="cylinder" euler="-0.32 -0.24 0.9" pos="-0.07284 -0.06557 0.07823" size="0.05594 0.0516" rgba="0.19 0.83 0.78 0.2" group="2"/>
      <site name="IL_at_brim_r_sidesite" pos="-0.02952 -0.09583 0.09943" size="0.0005"/>
      <geom name="IL_at_brim_l_cylinder" type="cylinder" euler="0.32 0.24 0.9" pos="-0.07284 -0.06557 -0.07823" size="0.05594 0.0516" rgba="0.19 0.83 0.78 0.2" group="2"/>
      <site name="IL_at_brim_l_sidesite" pos="-0.02952 -0.09583 -0.09943" size="0.0005"/>
      <joint name="pelvis_tx" range="-40 40" limited="true" user="0.0" ref="0" axis="1 0 0" type="slide" damping="0" stiffness="0"/>
      <joint name="pelvis_ty" range="-5 5" limited="true" user="0.93" ref="0" axis="0 1 0" type="slide" damping="0" stiffness="0"/>
      <joint name="pelvis_tz" range="-40 40" limited="true" user="0.0" ref="0" axis="0 0 1" type="slide" damping="0" stiffness="0"/>
      <joint name="pelvis_tilt" range="-3.142 3.142" limited="true" user="0.0" ref="0" axis="0 0 1" type="hinge" damping="0" stiffness="0"/>
      <joint name="pelvis_list" range="-3.142 3.142" limited="true" user="0.0" ref="0" axis="1 0 0" type="hinge" damping="0" stiffness="0"/>
      <joint name="pelvis_rotation" range="-3.142 3.142" limited="true" user="0.0" ref="0" axis="0 1 0" type="hinge" damping="0" stiffness="0"/>
      <body name="femur_r" pos="-0.05773 -0.07918 0.07995" euler="-0 0 0">
        <inertial mass="8.1054339409999994" pos="0 -0.17000000000000001 0" fullinertia="0.1166832525 0.030586872000000001 0.12304462469999999 0 0 0"/>
        <geom name="femur_r_geom_1" type="mesh" mesh="femur_r_geom_1_r_femur" rgba="1 1 1 1" group="0"/>
        <geom name="Gastroc_at_condyles_r_cylinder" type="cylinder" euler="0 0 0" pos="0.00526 -0.4246 0" size="0.0261 0.05167" rgba="0.19 0.83 0.78 0.2" group="2"/>
        <geom name="KnExt_at_fem_r_cylinder" type="cylinder" euler="-0.06234 0.05076 0" pos="0.003775 -0.4171 0.002161" size="0.0261 0.05167" rgba="0.19 0.83 0.78 0.2" group="2"/>
        <geom name="AB_at_femshaft_r_cylinder" type="cylinder" euler="1.662 0.1866 0" pos="0.01541 -0.1166 0.02415" size="0.0172 0.03627" rgba="0.19 0.83 0.78 0.2" group="2"/>
        <geom name="AL_at_femshaft_r_cylinder" type="cylinder" euler="1.777 0.1365 0" pos="0.03233 -0.2402 0.01562" size="0.02096 0.05179" rgba="0.19 0.83 0.78 0.2" group="2"/>
        <geom name="AMprox_at_femshaft_r_cylinder" type="cylinder" euler="1.611 0.1866 0" pos="0.005453 -0.07549 0.02625" size="0.022 0.03627" rgba="0.19 0.83 0.78 0.2" group="2"/>
        <geom name="AMmid_at_femshaft_r_cylinder" type="cylinder" euler="1.611 0.1366 0" pos="0.02421 -0.1664 0.02127" size="0.02231 0.06216" rgba="0.19 0.83 0.78 0.2" group="2"/>
        <geom name="AMdist_at_femshaft_r_cylinder" type="cylinder" euler="1.712 0.1866 0" pos="0.03325 -0.27 0.009677" size="0.02273 0.1036" rgba="0.19 0.83 0.78 0.2" group="2"/>
        <geom name="AMisch_at_condyles_r_cylinder" type="cylinder" euler="1.711 -0.4634 0" pos="-0.02383 -0.3903 -0.00326" size="0.04165 0.1247" rgba="0.19 0.83 0.78 0.2" group="2"/>
        <geom name="PECT_at_femshaft_r_cylinder" type="cylinder" euler="1.813 0.2763 0" pos="0.006403 -0.08751 0.03146" size="0.01563 0.02592" rgba="0.19 0.83 0.78 0.2" group="2"/>
        <joint name="hip_flexion_r" range="-0.5236 2.094" limited="true" user="0.0" ref="0" axis="0 0 1" type="hinge"/>
        <joint name="hip_adduction_r" range="-0.8727 0.5236" limited="true" user="0.0" ref="0" axis="1 0 0" type="hinge"/>
        <joint name="hip_rotation_r" range="-0.6981 0.6981" limited="true" user="0.0" ref="0" axis="0 1 0" type="hinge"/>
        <body name="tibia_r" pos="0.0002302 -0.4186 -0.001261" euler="-0 0 0">
          <inertial mass="3.23079282" pos="0 -0.1867 0" fullinertia="0.043919611099999999 0.0044442463999999999 0.044529605700000002 0 0 0"/>
          <geom name="tibia_r_geom_1" type="mesh" mesh="tibia_r_geom_1_r_tibia" rgba="1 1 1 1" group="0"/>
          <geom name="tibia_r_geom_2" type="mesh" mesh="tibia_r_geom_2_r_fibula" rgba="1 1 1 1" group="0"/>
          <geom name="GasLat_at_shank_r_cylinder" type="cylinder" euler="2.967 -0.2797 -1.478" pos="-0.007997 -0.08059 -0.003514" size="0.05962 0.05334" rgba="0.19 0.83 0.78 0.2" group="2"/>
          <site name="GasLat_at_shank_r_sidesite" pos="-0.06601 -0.07218 0.01192" size="0.0005"/>
          <geom name="GasMed_at_shank_r_cylinder" type="cylinder" euler="2.967 0.02797 -1.478" pos="-0.007997 -0.08059 -0.003514" size="0.05965 0.05329" rgba="0.19 0.83 0.78 0.2" group="2"/>
          <site name="GasMed_at_shank_r_sidesite" pos="-0.06836 -0.07536 -0.006151" size="0.0005"/>
          <geom name="GR_at_condyles_r_cylinder" type="cylinder" euler="0 -0.4 0" pos="-0.003242 -0.02178 0" size="0.03901 0.05337" rgba="0.19 0.83 0.78 0.2" group="2"/>
          <geom name="SM_at_condyles_r_cylinder" type="cylinder" euler="0 -0.1 0" pos="-0.001081 -0.02178 0" size="0.03818 0.05326" rgba="0.19 0.83 0.78 0.2" group="2"/>
          <geom name="ST_at_condyles_r_cylinder" type="cylinder" euler="0 -0.2 0" pos="-0.002161 -0.02233 0" size="0.04609 0.05328" rgba="0.19 0.83 0.78 0.2" group="2"/>
          <geom name="BF_at_gastroc_r_cylinder" type="cylinder" euler="0 0 0" pos="-0.06268 -0.06534 0" size="0.03255 0.07987" rgba="0.19 0.83 0.78 0.2" group="2"/>
          <site name="BF_at_gastroc_r_sidesite" pos="-0.06268 -0.0318 0" size="0.0005"/>
          <joint name="walker_knee_r_translation1" range="0 0.001656" limited="true" user="9.877164921807263e-08" ref="0" axis="-0.1243 0.9898 -0.07016" type="slide"/>
          <joint name="walker_knee_r_translation2" range="0 0.007019" limited="true" user="7.949387155481435e-11" ref="0" axis="0.9922 0.124 -0.008789" type="slide"/>
          <joint name="knee_angle_r" range="0 2.094" limited="true" user="0.0" ref="0" axis="-4.566e-07 -0.07071 -0.9975" type="hinge"/>
          <joint name="walker_knee_r_rotation2" range="-0.001678 0.03354" limited="true" user="-1.4732523263838448e-08" ref="0" axis="0.9922 0.124 -0.008789" type="hinge"/>
          <joint name="walker_knee_r_rotation3" range="0 0.2628" limited="true" user="1.0893911855935912e-08" ref="0" axis="-0.1243 0.9898 -0.07016" type="hinge"/>
          <body name="talus_r" pos="-0.01081 -0.4356 0" euler="-0 0 -1.735e-18">
            <inertial mass="0.087142085499999994" pos="0 0 0" fullinertia="0.00087142090000000001 0.00087142090000000001 0.00087142090000000001 0 0 0"/>
            <geom name="talus_r_geom_1" type="mesh" mesh="talus_r_geom_1_r_talus" rgba="1 1 1 0" group="0"/>
            <joint name="ankle_angle_r" range="-0.6981 0.5236" limited="true" user="0.0" ref="0" type="hinge" axis="-0.105 -0.174 0.9791"/>
            <body name="calcn_r" pos="-0.04987 -0.04307 0.008172" euler="-0 0 0">
              <inertial mass="1.0892760688000001" pos="0.10000000000000001 0.029999999999999999 0" fullinertia="0.0012199892 0.0033985412999999998 0.0035728255000000001 0 0 0"/>
              <geom name="calcn_r_geom_1" type="mesh" mesh="calcn_r_geom_1_r_foot" rgba="1 1 1 1" group="0"/>
              <joint name="subtalar_angle_r" range="-0.3491 0.3491" limited="true" user="0.0" ref="0" type="hinge" axis="0.7872 0.6047 -0.1209"/>
              <body name="toes_r" pos="0.1595 -0.001752 0.0009638" euler="-0 0 0">
                <inertial mass="0.18874975720000001" pos="0.034599999999999999 0.0060000000000000001 -0.017500000000000002" fullinertia="0.0005494308 0.00063657290000000005 0.00087142090000000001 0 0 0"/>
                <geom name="toes_r_geom_1" type="mesh" mesh="toes_r_geom_1_r_bofoot" rgba="1 1 1 1" group="0"/>
                <joint name="mtp_angle_r" range="-0.5236 0.5236" limited="true" user="0.0" ref="0" type="hinge" axis="0.581 2.16e-06 -0.8139"/>
              </body>
              <site name="RTOE_marker" group="4" pos="0.1841 0.01248 0.01295" rgba="1 0.1 0.5 0.5" size="0.01"/>
              <site name="RHEE_marker" group="4" pos="-0.01277 0.02009 -0.001019" rgba="1 0.1 0.5 0.5" size="0.01"/>
              <site name="RLatFoot_marker" group="4" pos="0.1113 0.01755 0.0407" rgba="1 0.1 0.5 0.5" size="0.01"/>
            </body>
          </body>
          <site name="RANK_marker" group="4" pos="-0.02098 -0.4183 0.05563" rgba="1 0.1 0.5 0.5" size="0.01"/>
          <site name="RANKmed_marker" group="4" pos="0.01494 -0.3995 -0.03393" rgba="1 0.1 0.5 0.5" size="0.01"/>
          <site name="RTIB_marker" group="4" pos="0.0158 -0.2138 0.05833" rgba="1 0.1 0.5 0.5" size="0.01"/>
          <site name="RTIB2_marker" group="4" pos="-0.05381 -0.216 0.06813" rgba="1 0.1 0.5 0.5" size="0.01"/>
          <site name="RTIB3_marker" group="4" pos="-0.01972 -0.2654 0.06454" rgba="1 0.1 0.5 0.5" size="0.01"/>
        </body>
        <body name="patella_r" pos="-0.008511 -0.4225 -0.002842" euler="-0 0 0">
          <inertial mass="0.065380909823214067" pos="0.0018 0.0264 0" fullinertia="2.1768353966661763e-06 9.9436627352939266e-06 9.9436627352939266e-06 0 0 0"/>
          <geom name="patella_r_geom_1" type="mesh" mesh="patella_r_geom_1_r_patella" rgba="1 1 1 1" group="0"/>
          <joint name="patellofemoral_r_translation1" range="-0.02388 0.05513" limited="true" user="0.05515011545973533" ref="0" axis="1 0 0" type="slide"/>
          <joint name="patellofemoral_r_translation2" range="-0.04225 -0.01118" limited="true" user="-0.011213952937498647" ref="0" axis="0 1 0" type="slide"/>
          <joint name="patellofemoral_r_translation3" limited="false" ref="0" axis="0 0 1" type="slide"/>
          <joint name="patellofemoral_r_rotation1" range="-1.786 0.001137" limited="true" user="0.01050598499723554" ref="0" axis="0 0 1" type="hinge"/>
        </body>
        <site name="RKNE_marker" group="4" pos="-0.0009574 -0.4282 0.05637" rgba="1 0.1 0.5 0.5" size="0.01"/>
        <site name="RKNEmed_marker" group="4" pos="-0.02814 -0.4057 -0.06099" rgba="1 0.1 0.5 0.5" size="0.01"/>
        <site name="RTHI_marker" group="4" pos="0.0467 -0.166 0.08276" rgba="1 0.1 0.5 0.5" size="0.01"/>
        <site name="RTHI2_marker" group="4" pos="-0.05619 -0.1669 0.0704" rgba="1 0.1 0.5 0.5" size="0.01"/>
        <site name="RTHI3_marker" group="4" pos="-0.000924 -0.2408 0.0809" rgba="1 0.1 0.5 0.5" size="0.01"/>
      </body>
      <body name="femur_l" pos="-0.05773 -0.07918 -0.07995" euler="-0 0 0">
        <inertial mass="8.1054339409999994" pos="0 -0.17000000000000001 0" fullinertia="0.1166832525 0.030586872000000001 0.12304462469999999 0 0 0"/>
        <geom name="femur_l_geom_1" type="mesh" mesh="femur_l_geom_1_l_femur" rgba="1 1 1 1" group="0"/>
        <geom name="Gastroc_at_condyles_l_cylinder" type="cylinder" euler="0 0 0" pos="0.00526 -0.4246 0" size="0.0261 0.05167" rgba="0.19 0.83 0.78 0.2" group="2"/>
        <geom name="KnExt_at_fem_l_cylinder" type="cylinder" euler="0.06234 -0.05076 0" pos="0.003775 -0.4171 -0.002161" size="0.0261 0.05167" rgba="0.19 0.83 0.78 0.2" group="2"/>
        <geom name="AB_at_femshaft_l_cylinder" type="cylinder" euler="-1.662 -0.1866 0" pos="0.01541 -0.1166 -0.02415" size="0.0172 0.03627" rgba="0.19 0.83 0.78 0.2" group="2"/>
        <geom name="AL_at_femshaft_l_cylinder" type="cylinder" euler="-1.777 -0.1365 0" pos="0.03233 -0.2402 -0.01562" size="0.02096 0.05179" rgba="0.19 0.83 0.78 0.2" group="2"/>
        <geom name="AMprox_at_femshaft_l_cylinder" type="cylinder" euler="-1.611 -0.1866 0" pos="0.005453 -0.07549 -0.02625" size="0.022 0.03627" rgba="0.19 0.83 0.78 0.2" group="2"/>
        <geom name="AMmid_at_femshaft_l_cylinder" type="cylinder" euler="-1.611 -0.1366 0" pos="0.02421 -0.1664 -0.02127" size="0.02231 0.06216" rgba="0.19 0.83 0.78 0.2" group="2"/>
        <geom name="AMdist_at_femshaft_l_cylinder" type="cylinder" euler="-1.712 -0.1866 0" pos="0.03325 -0.27 -0.009677" size="0.02273 0.1036" rgba="0.19 0.83 0.78 0.2" group="2"/>
        <geom name="AMisch_at_condyles_l_cylinder" type="cylinder" euler="-1.711 0.4634 0" pos="-0.02383 -0.3903 0.00326" size="0.04165 0.1247" rgba="0.19 0.83 0.78 0.2" group="2"/>
        <geom name="PECT_at_femshaft_l_cylinder" type="cylinder" euler="-1.813 -0.2763 0" pos="0.006403 -0.08751 -0.03146" size="0.01563 0.02592" rgba="0.19 0.83 0.78 0.2" group="2"/>
        <joint name="hip_flexion_l" range="-0.5236 2.094" limited="true" user="0.0" ref="0" axis="0 0 1" type="hinge"/>
        <joint name="hip_adduction_l" range="-0.8727 0.5236" limited="true" user="-0.0" ref="0" axis="-1 -0 -0" type="hinge"/>
        <joint name="hip_rotation_l" range="-0.6981 0.6981" limited="true" user="-0.0" ref="0" axis="-0 -1 -0" type="hinge"/>
        <body name="tibia_l" pos="0.0002302 -0.4186 0.001261" euler="-0 0 0">
          <inertial mass="3.23079282" pos="0 -0.1867 0" fullinertia="0.043919611099999999 0.0044442463999999999 0.044529605700000002 0 0 0"/>
          <geom name="tibia_l_geom_1" type="mesh" mesh="tibia_l_geom_1_l_tibia" rgba="1 1 1 1" group="0"/>
          <geom name="tibia_l_geom_2" type="mesh" mesh="tibia_l_geom_2_l_fibula" rgba="1 1 1 1" group="0"/>
          <geom name="GasLat_at_shank_l_cylinder" type="cylinder" euler="-2.967 0.2797 -1.478" pos="-0.007997 -0.08059 0.003514" size="0.05962 0.05334" rgba="0.19 0.83 0.78 0.2" group="2"/>
          <site name="GasLat_at_shank_l_sidesite" pos="-0.06601 -0.07218 -0.01192" size="0.0005"/>
          <geom name="GasMed_at_shank_l_cylinder" type="cylinder" euler="-2.967 -0.02797 -1.478" pos="-0.007997 -0.08059 0.003514" size="0.05965 0.05329" rgba="0.19 0.83 0.78 0.2" group="2"/>
          <site name="GasMed_at_shank_l_sidesite" pos="-0.06836 -0.07536 0.006151" size="0.0005"/>
          <geom name="GR_at_condyles_l_cylinder" type="cylinder" euler="0 0.4 0" pos="-0.003242 -0.02178 0" size="0.03901 0.05337" rgba="0.19 0.83 0.78 0.2" group="2"/>
          <geom name="SM_at_condyles_l_cylinder" type="cylinder" euler="0 0.1 0" pos="-0.001081 -0.02178 0" size="0.03818 0.05326" rgba="0.19 0.83 0.78 0.2" group="2"/>
          <geom name="ST_at_condyles_l_cylinder" type="cylinder" euler="0 0.2 0" pos="-0.002161 -0.02233 0" size="0.04609 0.05328" rgba="0.19 0.83 0.78 0.2" group="2"/>
          <geom name="BF_at_gastroc_l_cylinder" type="cylinder" euler="0 0 0" pos="-0.06268 -0.06534 0" size="0.03255 0.07987" rgba="0.19 0.83 0.78 0.2" group="2"/>
          <joint name="walker_knee_l_translation1" range="0 0.001656" limited="true" user="9.877164921807263e-08" ref="0" axis="-0.1243 0.9898 0.07016" type="slide"/>
          <joint name="walker_knee_l_translation2" range="-0.007019 0" limited="true" user="-7.949387155481435e-11" ref="0" axis="-0.9922 -0.124 -0.008789" type="slide"/>
          <joint name="knee_angle_l" range="0 2.094" limited="true" user="0.0" ref="0" axis="4.566e-07 0.07071 -0.9975" type="hinge"/>
          <joint name="walker_knee_l_rotation2" range="-0.001678 0.03354" limited="true" user="-1.4732523263838448e-08" ref="0" axis="-0.9922 -0.124 -0.008789" type="hinge"/>
          <joint name="walker_knee_l_rotation3" range="-0.2628 0" limited="true" user="-1.0893911855935912e-08" ref="0" axis="-0.1243 0.9898 0.07016" type="hinge"/>
          <body name="talus_l" pos="-0.01081 -0.4356 0" euler="-0 0 -1.735e-18">
            <inertial mass="0.087142085499999994" pos="0 0 0" fullinertia="0.00087142090000000001 0.00087142090000000001 0.00087142090000000001 0 0 0"/>
            <geom name="talus_l_geom_1" type="mesh" mesh="talus_l_geom_1_l_talus" rgba="1 1 1 0" group="0"/>
            <joint name="ankle_angle_l" range="-0.6981 0.5236" limited="true" user="0.0" ref="0" type="hinge" axis="0.105 0.174 0.9791"/>
            <body name="calcn_l" pos="-0.04987 -0.04307 -0.008172" euler="-0 0 0">
              <inertial mass="1.0892760688000001" pos="0.10000000000000001 0.029999999999999999 0" fullinertia="0.0012199892 0.0033985412999999998 0.0035728255000000001 0 0 0"/>
              <geom name="calcn_l_geom_1" type="mesh" mesh="calcn_l_geom_1_l_foot" rgba="1 1 1 1" group="0"/>
              <joint name="subtalar_angle_l" range="-0.3491 0.3491" limited="true" user="0.0" ref="0" type="hinge" axis="-0.7872 -0.6047 -0.1209"/>
              <body name="toes_l" pos="0.1595 -0.001752 -0.0009638" euler="-0 0 0">
                <inertial mass="0.18874975720000001" pos="0.034599999999999999 0.0060000000000000001 0.017500000000000002" fullinertia="0.0005494308 0.00063657290000000005 0.00087142090000000001 0 0 0"/>
                <geom name="toes_l_geom_1" type="mesh" mesh="toes_l_geom_1_l_bofoot" rgba="1 1 1 1" group="0"/>
                <joint name="mtp_angle_l" range="-0.5236 0.5236" limited="true" user="0.0" ref="0" type="hinge" axis="-0.581 2.16e-06 -0.8139"/>
              </body>
              <site name="LTOE_marker" group="4" pos="0.1795 0.01193 -0.008255" rgba="1 0.1 0.5 0.5" size="0.01"/>
              <site name="LHEE_marker" group="4" pos="-0.01286 0.02091 0.0006656" rgba="1 0.1 0.5 0.5" size="0.01"/>
              <site name="LLatFoot_marker" group="4" pos="0.1113 0.01503 -0.04714" rgba="1 0.1 0.5 0.5" size="0.01"/>
            </body>
          </body>
          <site name="LANK_marker" group="4" pos="-0.02191 -0.4207 -0.05585" rgba="1 0.1 0.5 0.5" size="0.01"/>
          <site name="LANKmed_marker" group="4" pos="0.01203 -0.4028 0.03273" rgba="1 0.1 0.5 0.5" size="0.01"/>
          <site name="LTIB_marker" group="4" pos="0.01856 -0.2305 -0.05554" rgba="1 0.1 0.5 0.5" size="0.01"/>
          <site name="LTIB2_marker" group="4" pos="-0.04936 -0.2418 -0.06717" rgba="1 0.1 0.5 0.5" size="0.01"/>
          <site name="LTIB3_marker" group="4" pos="-0.0113 -0.2776 -0.0636" rgba="1 0.1 0.5 0.5" size="0.01"/>
        </body>
        <body name="patella_l" pos="-0.008511 -0.4225 0.002842" euler="-0 0 0">
          <inertial mass="0.065380909823214067" pos="0.0018 0.0264 0" fullinertia="2.1768353966661763e-06 9.9436627352939266e-06 9.9436627352939266e-06 0 0 0"/>
          <geom name="patella_l_geom_1" type="mesh" mesh="patella_l_geom_1_l_patella" rgba="1 1 1 1" group="0"/>
          <joint name="patellofemoral_l_translation1" range="-0.02388 0.05513" limited="true" user="0.05515011545973533" ref="0" axis="1 0 0" type="slide"/>
          <joint name="patellofemoral_l_translation2" range="-0.04225 -0.01118" limited="true" user="-0.011213952937498647" ref="0" axis="0 1 0" type="slide"/>
          <joint name="patellofemoral_l_translation3" limited="false" ref="0" axis="0 0 1" type="slide"/>
          <joint name="patellofemoral_l_rotation1" range="-1.786 0.001137" limited="true" user="0.01050598499723554" ref="0" axis="0 0 1" type="hinge"/>
        </body>
        <site name="LKNE_marker" group="4" pos="-0.0009274 -0.4273 -0.05871" rgba="1 0.1 0.5 0.5" size="0.01"/>
        <site name="LKNEmed_marker" group="4" pos="-0.02391 -0.4118 0.05322" rgba="1 0.1 0.5 0.5" size="0.01"/>
        <site name="LTHI_marker" group="4" pos="0.06445 -0.1785 -0.1007" rgba="1 0.1 0.5 0.5" size="0.01"/>
        <site name="LTHI2_marker" group="4" pos="-0.04279 -0.1643 -0.08636" rgba="1 0.1 0.5 0.5" size="0.01"/>
        <site name="LTHI3_marker" group="4" pos="0.001754 -0.2438 -0.095" rgba="1 0.1 0.5 0.5" size="0.01"/>
      </body>
      <body name="torso" pos="-0.1033 0.08222 0" euler="-0 0 0">
        <inertial mass="29.8344872453" pos="-0.029999999999999999 0.32000000000000001 0" fullinertia="1.2849100507 0.65835845599999998 1.2473518119 0 0 0"/>
        <geom name="torso_geom_1" type="mesh" mesh="torso_geom_1_hat_spine" rgba="1 1 1 1" group="0"/>
        <geom name="torso_geom_2" type="mesh" mesh="torso_geom_2_hat_jaw" rgba="1 1 1 1" group="0"/>
        <geom name="torso_geom_3" type="mesh" mesh="torso_geom_3_hat_skull" rgba="1 1 1 1" group="0"/>
        <geom name="torso_geom_4" type="mesh" mesh="torso_geom_4_hat_ribs_scap" rgba="1 1 1 1" group="0"/>
        <joint name="lumbar_extension" range="-1.571 1.571" limited="true" user="0.0" ref="0" axis="0 0 1" type="hinge"/>
        <joint name="lumbar_bending" range="-1.571 1.571" limited="true" user="0.0" ref="0" axis="1 0 0" type="hinge"/>
        <joint name="lumbar_rotation" range="-1.571 1.571" limited="true" user="0.0" ref="0" axis="0 1 0" type="hinge"/>
        <site name="CLAV_marker" group="4" pos="0.02766 0.387 0.001007" rgba="1 0.1 0.5 0.5" size="0.01"/>
        <site name="RSHO_marker" group="4" pos="-0.02314 0.3962 0.2036" rgba="1 0.1 0.5 0.5" size="0.01"/>
        <site name="LSHO_marker" group="4" pos="-0.0283 0.3999 -0.198" rgba="1 0.1 0.5 0.5" size="0.01"/>
        <site name="C7_marker" group="4" pos="-0.08174 0.4306 -0.005021" rgba="1 0.1 0.5 0.5" size="0.01"/>
        <site name="T10_marker" group="4" pos="-0.1129 0.1975 -4.856e-05" rgba="1 0.1 0.5 0.5" size="0.01"/>
        <site name="RBAK_marker" group="4" pos="-0.1417 0.3112 0.09869" rgba="1 0.1 0.5 0.5" size="0.01"/>
        <site name="STRN_marker" group="4" pos="0.1156 0.2273 0.002486" rgba="1 0.1 0.5 0.5" size="0.01"/>
      </body>
      <site name="RASI_marker" group="4" pos="0.01311 0.01554 0.1322" rgba="1 0.1 0.5 0.5" size="0.01"/>
      <site name="LASI_marker" group="4" pos="0.0123 0.01675 -0.1377" rgba="1 0.1 0.5 0.5" size="0.01"/>
      <site name="RPSI_marker" group="4" pos="-0.1658 0.04571 0.05563" rgba="1 0.1 0.5 0.5" size="0.01"/>
      <site name="LPSI_marker" group="4" pos="-0.1617 0.04833 -0.05695" rgba="1 0.1 0.5 0.5" size="0.01"/>
      <site name="SACR_marker" group="4" pos="-0.1661 0.0508 0.0001781" rgba="1 0.1 0.5 0.5" size="0.01"/>
    </body>
  </worldbody>
  <asset>
    <texture type="skybox" builtin="gradient" rgb1="1 1 1" rgb2="0.6 0.8 1" width="256" height="256"/>
    <mesh name="pelvis_geom_1_r_pelvis" file="Geometry/r_pelvis.stl" scale="1.0259106713999999 1.0088089439000001 1.0348375638"/>
    <mesh name="pelvis_geom_2_l_pelvis" file="Geometry/l_pelvis.stl" scale="1.0259106713999999 1.0088089439000001 1.0348375638"/>
    <mesh name="pelvis_geom_3_sacrum" file="Geometry/sacrum.stl" scale="1.0259106713999999 1.0088089439000001 1.0348375638"/>
    <mesh name="femur_r_geom_1_r_femur" file="Geometry/r_femur.stl" scale="1.0520969981999999 1.0356316359 1.0333886957"/>
    <mesh name="tibia_r_geom_1_r_tibia" file="Geometry/r_tibia.stl" scale="1.0806115543999999 1.0890604392000001 1.0649901819000001"/>
    <mesh name="tibia_r_geom_2_r_fibula" file="Geometry/r_fibula.stl" scale="1.0806115543999999 1.0890604392000001 1.0649901819000001"/>
    <mesh name="talus_r_geom_1_r_talus" file="Geometry/r_talus.stl" scale="1.0226245804 1.0267018264000001 1.0318715833000001"/>
    <mesh name="calcn_r_geom_1_r_foot" file="Geometry/r_foot.stl" scale="0.89180648340000002 0.87613486340000002 0.8924495201"/>
    <mesh name="toes_r_geom_1_r_bofoot" file="Geometry/r_bofoot.stl" scale="1.0240918612000001 1.0245541482 1.0251290830999999"/>
    <mesh name="patella_r_geom_1_r_patella" file="Geometry/r_patella.stl" scale="1 1 1"/>
    <mesh name="femur_l_geom_1_l_femur" file="Geometry/l_femur.stl" scale="1.0520969981999999 1.0356316359 1.0333886957"/>
    <mesh name="tibia_l_geom_1_l_tibia" file="Geometry/l_tibia.stl" scale="1.0806115543999999 1.0890604392000001 1.0649901819000001"/>
    <mesh name="tibia_l_geom_2_l_fibula" file="Geometry/l_fibula.stl" scale="1.0806115543999999 1.0890604392000001 1.0649901819000001"/>
    <mesh name="talus_l_geom_1_l_talus" file="Geometry/l_talus.stl" scale="1.0226245804 1.0267018264000001 1.0318715833000001"/>
    <mesh name="calcn_l_geom_1_l_foot" file="Geometry/l_foot.stl" scale="0.89180648340000002 0.87613486340000002 0.8924495201"/>
    <mesh name="toes_l_geom_1_l_bofoot" file="Geometry/l_bofoot.stl" scale="1.0240918612000001 1.0245541482 1.0251290830999999"/>
    <mesh name="patella_l_geom_1_l_patella" file="Geometry/l_patella.stl" scale="1 1 1"/>
    <mesh name="torso_geom_1_hat_spine" file="Geometry/hat_spine.stl" scale="1.1416956143999999 0.99196010759999997 1.0549967257999999"/>
    <mesh name="torso_geom_2_hat_jaw" file="Geometry/hat_jaw.stl" scale="1.1416956143999999 0.99196010759999997 1.0549967257999999"/>
    <mesh name="torso_geom_3_hat_skull" file="Geometry/hat_skull.stl" scale="1.1416956143999999 0.99196010759999997 1.0549967257999999"/>
    <mesh name="torso_geom_4_hat_ribs_scap" file="Geometry/hat_ribs_scap.stl" scale="1.1416956143999999 0.99196010759999997 1.0549967257999999"/>
  </asset>
  <tendon>
    <!-- Leave this comment here to make 'tendon' element pretty printed !-->
  </tendon>
  <actuator>
    <!-- Leave this comment here to make 'actuator' element pretty printed !-->
    <motor name="lumbar_ext" ctrllimited="false" joint="lumbar_extension" class="motor"/>
    <motor name="lumbar_bend" ctrllimited="false" joint="lumbar_bending" class="motor"/>
    <motor name="lumbar_rot" ctrllimited="false" joint="lumbar_rotation" class="motor"/>
  </actuator>
  <equality>
    <!-- Leave this comment here to make 'equality' element pretty printed !-->
    <joint joint1="walker_knee_r_translation1" joint2="knee_angle_r" polycoef="9.877e-08 0.00324 -0.00239 0.0005816 5.886e-07" solimp="0.9999 0.9999 0.001 0.5 2" active="true"/>
    <joint joint1="walker_knee_r_translation2" joint2="knee_angle_r" polycoef="7.949e-11 0.006076 -0.001298 -2.706e-06 6.452e-07" solimp="0.9999 0.9999 0.001 0.5 2" active="true"/>
    <joint joint1="walker_knee_r_rotation2" joint2="knee_angle_r" polycoef="-1.473e-08 0.0791 -0.03285 -0.02522 0.01083" solimp="0.9999 0.9999 0.001 0.5 2" active="true"/>
    <joint joint1="walker_knee_r_rotation3" joint2="knee_angle_r" polycoef="1.089e-08 0.3695 -0.1695 0.02516 3.505e-07" solimp="0.9999 0.9999 0.001 0.5 2" active="true"/>
    <joint name="mtp_angle_r_locked" active="true" joint1="mtp_angle_r" polycoef="0.0 0 0 0 0" solimp="0.9999 0.9999 0.001 0.5 2"/>
    <joint joint1="patellofemoral_r_translation1" joint2="knee_angle_r" polycoef="0.05515 -0.0158 -0.03583 0.01403 -0.000925" solimp="0.9999 0.9999 0.001 0.5 2" active="true"/>
    <joint joint1="patellofemoral_r_translation2" joint2="knee_angle_r" polycoef="-0.01121 -0.05052 0.009607 0.01364 -0.003621" solimp="0.9999 0.9999 0.001 0.5 2" active="true"/>
    <joint joint1="patellofemoral_r_rotation1" joint2="knee_angle_r" polycoef="0.01051 0.02476 -1.316 0.7163 -0.1383" solimp="0.9999 0.9999 0.001 0.5 2" active="true"/>
    <joint name="patellofemoral_r_translation3_locked" active="true" joint1="patellofemoral_r_translation3" polycoef="0.002841818913175 0 0 0 0" solimp="0.9999 0.9999 0.001 0.5 2"/>
    <joint joint1="walker_knee_l_translation1" joint2="knee_angle_l" polycoef="9.877e-08 0.00324 -0.00239 0.0005816 5.886e-07" solimp="0.9999 0.9999 0.001 0.5 2" active="true"/>
    <joint joint1="walker_knee_l_translation2" joint2="knee_angle_l" polycoef="-7.949e-11 -0.006076 0.001298 2.706e-06 -6.452e-07" solimp="0.9999 0.9999 0.001 0.5 2" active="true"/>
    <joint joint1="walker_knee_l_rotation2" joint2="knee_angle_l" polycoef="-1.473e-08 0.0791 -0.03285 -0.02522 0.01083" solimp="0.9999 0.9999 0.001 0.5 2" active="true"/>
    <joint joint1="walker_knee_l_rotation3" joint2="knee_angle_l" polycoef="-1.089e-08 -0.3695 0.1695 -0.02516 -3.505e-07" solimp="0.9999 0.9999 0.001 0.5 2" active="true"/>
    <joint name="mtp_angle_l_locked" active="true" joint1="mtp_angle_l" polycoef="0.0 0 0 0 0" solimp="0.9999 0.9999 0.001 0.5 2"/>
    <joint joint1="patellofemoral_l_translation1" joint2="knee_angle_l" polycoef="0.05515 -0.0158 -0.03583 0.01403 -0.000925" solimp="0.9999 0.9999 0.001 0.5 2" active="true"/>
    <joint joint1="patellofemoral_l_translation2" joint2="knee_angle_l" polycoef="-0.01121 -0.05052 0.009607 0.01364 -0.003621" solimp="0.9999 0.9999 0.001 0.5 2" active="true"/>
    <joint joint1="patellofemoral_l_rotation1" joint2="knee_angle_l" polycoef="0.01051 0.02476 -1.316 0.7163 -0.1383" solimp="0.9999 0.9999 0.001 0.5 2" active="true"/>
    <joint name="patellofemoral_l_translation3_locked" active="true" joint1="patellofemoral_l_translation3" polycoef="-0.002841818913175 0 0 0 0" solimp="0.9999 0.9999 0.001 0.5 2"/>
  </equality>
  <contact>
    <!-- Leave this comment here to make 'contact' element pretty printed !-->
    <pair geom1="ground-plane" geom2="pelvis_geom_1"/>
    <pair geom1="ground-plane" geom2="pelvis_geom_2"/>
    <pair geom1="ground-plane" geom2="pelvis_geom_3"/>
    <pair geom1="ground-plane" geom2="femur_r_geom_1"/>
    <pair geom1="ground-plane" geom2="tibia_r_geom_1"/>
    <pair geom1="ground-plane" geom2="tibia_r_geom_2"/>
    <pair geom1="ground-plane" geom2="talus_r_geom_1"/>
    <pair geom1="ground-plane" geom2="calcn_r_geom_1"/>
    <pair geom1="ground-plane" geom2="toes_r_geom_1"/>
    <pair geom1="ground-plane" geom2="patella_r_geom_1"/>
    <pair geom1="ground-plane" geom2="femur_l_geom_1"/>
    <pair geom1="ground-plane" geom2="tibia_l_geom_1"/>
    <pair geom1="ground-plane" geom2="tibia_l_geom_2"/>
    <pair geom1="ground-plane" geom2="talus_l_geom_1"/>
    <pair geom1="ground-plane" geom2="calcn_l_geom_1"/>
    <pair geom1="ground-plane" geom2="toes_l_geom_1"/>
    <pair geom1="ground-plane" geom2="patella_l_geom_1"/>
    <pair geom1="ground-plane" geom2="torso_geom_1"/>
    <pair geom1="ground-plane" geom2="torso_geom_2"/>
    <pair geom1="ground-plane" geom2="torso_geom_3"/>
    <pair geom1="ground-plane" geom2="torso_geom_4"/>
  </contact>
  <keyframe>
    <key name="default-pose" qpos="0 0.93 0 0 0 0 0 0 0 9.877e-08 7.949e-11 0 -1.473e-08 1.089e-08 0 0 0 0.05515 -0.01121 0.002842 0.01051 0 -0 -0 9.877e-08 -7.949e-11 0 -1.473e-08 -1.089e-08 0 0 0 0.05515 -0.01121 -0.002842 0.01051 0 0 0"/>
  </keyframe>
</mujoco>
