<mujoco model="template">
  <!-- This model has been converted from an OpenSim model. Model conversion by MyoConverter https://github.com/MyoHub/myoconverter. This model is licensed under Apache 2.0. -->
  <!-- Note: inertiagrouprange="0 1" means that groups 0-1 will be used to infer masses/inertias, and groups 2-5 are
  only for visualisation (e.g. wrapping objects) !-->
  <compiler inertiafromgeom="auto" angle="radian" balanceinertia="true" boundmass="0.001" boundinertia="0.001" inertiagrouprange="0 1">
    <lengthrange inttotal="50" useexisting="true"/>
  </compiler>
  <option/>
  <visual>
    <scale framelength="0.5" framewidth="0.01"/>
  </visual>
  <default>
    <joint limited="true" damping="0.05" armature="0.00001" stiffness="0"/>
    <geom rgba="0.8 0.6 .4 1" margin="0.001"/>
    <site size="0.001"/>
    <tendon width="0.005" rgba=".95 .3 .3 1" limited="false"/>
    <default class="muscle">
      <muscle ctrllimited="true" ctrlrange="0 1" scale="200"/>
    </default>
    <default class="motor">
      <general gainprm="5 0 0 0 0 0 0 0 0 0"/>
    </default>
  </default>
  <option timestep="0.002"/>
  <!-- nuser_jnt=1, the parameter is used to store default value of the joint, and nkey=1 to store keyframe with
   default joint positions set !-->
  <size njmax="1000" nconmax="400" nuser_jnt="1" nkey="1"/>
  <worldbody>
    <!-- The converter script assumes a body named 'ground' exists as a child element of worldbody -->
    <body name="ground" euler="1.571 0 0">
      <geom name="ground-plane" pos="0 0 0" euler="-1.571 0 0" size="10 10 0.125" type="plane" rgba="1.0 0.7 0.4 1.0" condim="3"/>
    </body>
    <light directional="true"/>
    <body name="pelvis" pos="0 0 0" euler="1.571 0 0">
      <inertial mass="9.6359922091" pos="-0.0707000000 0.0000000000 0.0000000000" fullinertia="0.0841114035 0.0712655958 0.0473740298 0.0000000000 0.0000000000 0.0000000000"/>
      <geom name="pelvis_geom_1" type="mesh" mesh="pelvis_geom_1_r_pelvis" rgba="1 1 1 1" group="0"/>
      <geom name="pelvis_geom_2" type="mesh" mesh="pelvis_geom_2_l_pelvis" rgba="1 1 1 1" group="0"/>
      <geom name="pelvis_geom_3" type="mesh" mesh="pelvis_geom_3_sacrum" rgba="1 1 1 1" group="0"/>
      <geom name="Gmax1_at_pelvis_r_cylinder" type="cylinder" euler="-0.6 0.45 0" pos="-0.07616 -0.1001 0.06858" size="0.04115 0.08034" rgba="0.19 0.83 0.78 0.2" group="2"/>
      <site name="Gmax1_at_pelvis_r_sidesite" pos="-0.1141 -0.08977 0.08371" size="0.0005"/>
      <geom name="Gmax2_at_pelvis_r_cylinder" type="cylinder" euler="-0.75 0.39 0" pos="-0.07912 -0.08394 0.07645" size="0.04134 0.05307" rgba="0.19 0.83 0.78 0.2" group="2"/>
      <geom name="Gmax3_at_pelvis_r_cylinder" type="cylinder" euler="-0.1 0 0" pos="-0.08209 -0.089 0.07645" size="0.04003 0.05616" rgba="0.19 0.83 0.78 0.2" group="2"/>
      <geom name="Gmax1_at_pelvis_l_cylinder" type="cylinder" euler="0.6 -0.45 0" pos="-0.07616 -0.1001 -0.06858" size="0.04115 0.08034" rgba="0.19 0.83 0.78 0.2" group="2"/>
      <site name="Gmax1_at_pelvis_l_sidesite" pos="-0.1141 -0.08977 -0.08371" size="0.0005"/>
      <geom name="Gmax2_at_pelvis_l_cylinder" type="cylinder" euler="0.75 -0.39 0" pos="-0.07912 -0.08394 -0.07645" size="0.04134 0.05307" rgba="0.19 0.83 0.78 0.2" group="2"/>
      <geom name="Gmax3_at_pelvis_l_cylinder" type="cylinder" euler="0.1 0 0" pos="-0.08209 -0.089 -0.07645" size="0.04003 0.05616" rgba="0.19 0.83 0.78 0.2" group="2"/>
      <geom name="PS_at_brim_r_cylinder" type="cylinder" euler="-0.25 -0.27 0.1" pos="-0.07319 -0.06068 0.07375" size="0.05043 0.05545" rgba="0.19 0.83 0.78 0.2" group="2"/>
      <site name="PS_at_brim_r_sidesite" pos="-0.06824 -0.1099 0.08774" size="0.0005"/>
      <geom name="PS_at_brim_l_cylinder" type="cylinder" euler="0.25 0.27 0.1" pos="-0.07319 -0.06068 -0.07375" size="0.05043 0.05545" rgba="0.19 0.83 0.78 0.2" group="2"/>
      <site name="PS_at_brim_l_sidesite" pos="-0.06824 -0.1099 -0.08774" size="0.0005"/>
      <geom name="IL_at_brim_r_cylinder" type="cylinder" euler="-0.32 -0.24 0.9" pos="-0.07022 -0.06574 0.08499" size="0.05544 0.05535" rgba="0.19 0.83 0.78 0.2" group="2"/>
      <site name="IL_at_brim_r_sidesite" pos="-0.02728 -0.09573 0.106" size="0.0005"/>
      <geom name="IL_at_brim_l_cylinder" type="cylinder" euler="0.32 0.24 0.9" pos="-0.07022 -0.06574 -0.08499" size="0.05544 0.05535" rgba="0.19 0.83 0.78 0.2" group="2"/>
      <site name="IL_at_brim_l_sidesite" pos="-0.02728 -0.09573 -0.106" size="0.0005"/>
      <joint name="pelvis_tx" range="-40 40" limited="true" user="0.0" ref="0" axis="1 0 0" type="slide" damping="0" stiffness="0"/>
      <joint name="pelvis_ty" range="-5 5" limited="true" user="0.93" ref="0" axis="0 1 0" type="slide" damping="0" stiffness="0"/>
      <joint name="pelvis_tz" range="-40 40" limited="true" user="0.0" ref="0" axis="0 0 1" type="slide" damping="0" stiffness="0"/>
      <joint name="pelvis_tilt" range="-3.142 3.142" limited="true" user="0.0" ref="0" axis="0 0 1" type="hinge" damping="0" stiffness="0"/>
      <joint name="pelvis_list" range="-3.142 3.142" limited="true" user="0.0" ref="0" axis="1 0 0" type="hinge" damping="0" stiffness="0"/>
      <joint name="pelvis_rotation" range="-3.142 3.142" limited="true" user="0.0" ref="0" axis="0 1 0" type="hinge" damping="0" stiffness="0"/>
      <body name="femur_r" pos="-0.05566 -0.07938 0.08686" euler="-0 0 0">
        <inertial mass="7.6104456087" pos="0.0000000000 -0.1700000000 0.0000000000" fullinertia="0.1095575577 0.0287189714 0.1155304492 0.0000000000 0.0000000000 0.0000000000"/>
        <geom name="femur_r_geom_1" type="mesh" mesh="femur_r_geom_1_r_femur" rgba="1 1 1 1" group="0"/>
        <geom name="Gastroc_at_condyles_r_cylinder" type="cylinder" euler="0 0 0" pos="0.004714 -0.3853 0" size="0.02353 0.04811" rgba="0.19 0.83 0.78 0.2" group="2"/>
        <geom name="KnExt_at_fem_r_cylinder" type="cylinder" euler="-0.06234 0.05076 0" pos="0.003383 -0.3785 0.002012" size="0.02353 0.0481" rgba="0.19 0.83 0.78 0.2" group="2"/>
        <geom name="AB_at_femshaft_r_cylinder" type="cylinder" euler="1.662 0.1866 0" pos="0.01381 -0.1058 0.02248" size="0.01571 0.0329" rgba="0.19 0.83 0.78 0.2" group="2"/>
        <geom name="AL_at_femshaft_r_cylinder" type="cylinder" euler="1.777 0.1365 0" pos="0.02897 -0.2179 0.01454" size="0.01913 0.04704" rgba="0.19 0.83 0.78 0.2" group="2"/>
        <geom name="AMprox_at_femshaft_r_cylinder" type="cylinder" euler="1.611 0.1866 0" pos="0.004886 -0.0685 0.02444" size="0.0201 0.0329" rgba="0.19 0.83 0.78 0.2" group="2"/>
        <geom name="AMmid_at_femshaft_r_cylinder" type="cylinder" euler="1.611 0.1366 0" pos="0.0217 -0.151 0.01981" size="0.02038 0.05639" rgba="0.19 0.83 0.78 0.2" group="2"/>
        <geom name="AMdist_at_femshaft_r_cylinder" type="cylinder" euler="1.712 0.1866 0" pos="0.0298 -0.245 0.00901" size="0.02076 0.09403" rgba="0.19 0.83 0.78 0.2" group="2"/>
        <geom name="AMisch_at_condyles_r_cylinder" type="cylinder" euler="1.711 -0.4634 0" pos="-0.02135 -0.3541 -0.003035" size="0.03808 0.1129" rgba="0.19 0.83 0.78 0.2" group="2"/>
        <geom name="PECT_at_femshaft_r_cylinder" type="cylinder" euler="1.813 0.2763 0" pos="0.005737 -0.07941 0.02929" size="0.01428 0.02353" rgba="0.19 0.83 0.78 0.2" group="2"/>
        <joint name="hip_flexion_r" range="-0.5236 2.094" limited="true" user="0.0" ref="0" axis="0 0 1" type="hinge"/>
        <joint name="hip_adduction_r" range="-0.8727 0.5236" limited="true" user="0.0" ref="0" axis="1 0 0" type="hinge"/>
        <joint name="hip_rotation_r" range="-0.6981 0.6981" limited="true" user="0.0" ref="0" axis="0 1 0" type="hinge"/>
        <body name="tibia_r" pos="-0.0003866 -0.3802 -0.001335" euler="-0 0 0">
          <inertial mass="3.0334924951" pos="0.0000000000 -0.1867000000 0.0000000000" fullinertia="0.0412374974 0.0041728420 0.0418102405 0.0000000000 0.0000000000 0.0000000000"/>
          <geom name="tibia_r_geom_1" type="mesh" mesh="tibia_r_geom_1_r_tibia" rgba="1 1 1 1" group="0"/>
          <geom name="tibia_r_geom_2" type="mesh" mesh="tibia_r_geom_2_r_fibula" rgba="1 1 1 1" group="0"/>
          <geom name="GasLat_at_shank_r_cylinder" type="cylinder" euler="2.967 -0.2797 -1.478" pos="-0.006623 -0.06691 -0.002913" size="0.04944 0.04422" rgba="0.19 0.83 0.78 0.2" group="2"/>
          <site name="GasLat_at_shank_r_sidesite" pos="-0.05489 -0.0599 0.009932" size="0.0005"/>
          <geom name="GasMed_at_shank_r_cylinder" type="cylinder" euler="2.967 0.02797 -1.478" pos="-0.006623 -0.06691 -0.002913" size="0.04946 0.04417" rgba="0.19 0.83 0.78 0.2" group="2"/>
          <site name="GasMed_at_shank_r_sidesite" pos="-0.05685 -0.06255 -0.005107" size="0.0005"/>
          <geom name="GR_at_condyles_r_cylinder" type="cylinder" euler="0 -0.4 0" pos="-0.002685 -0.01808 0" size="0.03235 0.04423" rgba="0.19 0.83 0.78 0.2" group="2"/>
          <geom name="SM_at_condyles_r_cylinder" type="cylinder" euler="0 -0.1 0" pos="-0.000895 -0.01808 0" size="0.03166 0.04415" rgba="0.19 0.83 0.78 0.2" group="2"/>
          <geom name="ST_at_condyles_r_cylinder" type="cylinder" euler="0 -0.2 0" pos="-0.00179 -0.01853 0" size="0.03822 0.04417" rgba="0.19 0.83 0.78 0.2" group="2"/>
          <geom name="BF_at_gastroc_r_cylinder" type="cylinder" euler="0 0 0" pos="-0.05191 -0.05425 0" size="0.02699 0.06621" rgba="0.19 0.83 0.78 0.2" group="2"/>
          <site name="BF_at_gastroc_r_sidesite" pos="-0.05191 -0.02626 0" size="0.0005"/>
          <joint name="walker_knee_r_translation1" range="0 0.001503" limited="true" user="8.96251289327684e-08" ref="0" axis="-0.1243 0.9898 -0.07016" type="slide"/>
          <joint name="walker_knee_r_translation2" range="0 0.006535" limited="true" user="7.401422617153708e-11" ref="0" axis="0.9922 0.124 -0.008789" type="slide"/>
          <joint name="knee_angle_r" range="0 2.094" limited="true" user="0.0" ref="0" axis="-4.566e-07 -0.07071 -0.9975" type="hinge"/>
          <joint name="walker_knee_r_rotation2" range="-0.001678 0.03354" limited="true" user="-1.4732523263838448e-08" ref="0" axis="0.9922 0.124 -0.008789" type="hinge"/>
          <joint name="walker_knee_r_rotation3" range="0 0.2628" limited="true" user="1.0893911855935912e-08" ref="0" axis="-0.1243 0.9898 -0.07016" type="hinge"/>
          <body name="talus_r" pos="-0.00895 -0.3617 0" euler="-0 0 0">
            <inertial mass="0.0818204314" pos="0.0000000000 0.0000000000 0.0000000000" fullinertia="0.0008182043 0.0008182043 0.0008182043 0.0000000000 0.0000000000 0.0000000000"/>
            <geom name="talus_r_geom_1" type="mesh" mesh="talus_r_geom_1_r_talus" rgba="1 1 1 0" group="0"/>
            <joint name="ankle_angle_r" range="-0.6981 0.5236" limited="true" user="0.0" ref="0" type="hinge" axis="-0.105 -0.174 0.9791"/>
            <body name="calcn_r" pos="-0.05456 -0.04903 0.009057" euler="-0 0 0">
              <inertial mass="1.0227553928" pos="0.1000000000 0.0300000000 0.0000000000" fullinertia="0.0011454860 0.0031909968 0.0033546377 0.0000000000 0.0000000000 0.0000000000"/>
              <geom name="calcn_r_geom_1" type="mesh" mesh="calcn_r_geom_1_r_foot" rgba="1 1 1 1" group="0"/>
              <joint name="subtalar_angle_r" range="-0.3491 0.3491" limited="true" user="0.0" ref="0" type="hinge" axis="0.7872 0.6047 -0.1209"/>
              <body name="toes_r" pos="0.1777 -0.001986 0.001085" euler="-0 0 0">
                <inertial mass="0.1772230545" pos="0.0346000000 0.0060000000 -0.0175000000" fullinertia="0.0005158778 0.0005976983 0.0008182043 0.0000000000 0.0000000000 0.0000000000"/>
                <geom name="toes_r_geom_1" type="mesh" mesh="toes_r_geom_1_r_bofoot" rgba="1 1 1 1" group="0"/>
                <joint name="mtp_angle_r" range="-0.5236 0.5236" limited="true" user="0.0" ref="0" type="hinge" axis="0.581 2.16e-06 -0.8139"/>
                <site name="edl_r_edl_r-P5" pos="0.00029851120983 0.0046731716841900001 0.015217040167109999"/>
                <site name="edl_r_edl_r-P6" pos="0.044080155318230001 -0.00039771673908 0.024864444717500003"/>
                <site name="ehl_r_ehl_r-P7" pos="0.02965211350978 0.0040765965755700006 -0.024367155823150001"/>
                <site name="ehl_r_ehl_r-P8" pos="0.056020603711430007 0.0033805922821799998 -0.018499146869819998"/>
                <site name="fdl_r_fdl_r-P6" pos="-0.00189057099559 -0.0077554764120599997 0.01462029349389"/>
                <site name="fdl_r_fdl_r-P7" pos="0.028358564933850004 -0.0070594721186700007 0.021383422457049998"/>
                <site name="fdl_r_fdl_r-P8" pos="0.043881147845010002 -0.0059657510862000003 0.02406878248654"/>
                <site name="fhl_r_fhl_r-P6" pos="0.01542307917455 -0.00636346782528 -0.02635631140055"/>
                <site name="fhl_r_fhl_r-P7" pos="0.055921099974820004 -0.010141776846540001 -0.018001857975470003"/>
              </body>
              <site name="edl_r_edl_r-P3" pos="0.091311885490499997 0.035744450057999998 0.00080382968080000008"/>
              <site name="edl_r_edl_r-P4" pos="0.160565839992 0.0054609576477500001 0.013062232312999999"/>
              <site name="ehl_r_ehl_r-P4" pos="0.096379248015000002 0.038623864090449996 -0.021201007831100002"/>
              <site name="ehl_r_ehl_r-P5" pos="0.1284725440035 0.030680652966450003 -0.0258230284957"/>
              <site name="ehl_r_ehl_r-P6" pos="0.172290325833 0.01380132932795 -0.028134038828000002"/>
              <site name="fdl_r_fdl_r-P3" pos="0.043320981581999998 0.031276393800750001 -0.028134038828000002"/>
              <site name="fdl_r_fdl_r-P4" pos="0.070346915046000005 0.017475064472800002 -0.0264259007563"/>
              <site name="fdl_r_fdl_r-P5" pos="0.164738962071 -0.0080425012630500007 0.0116555303716"/>
              <site name="fhl_r_fhl_r-P3" pos="0.037160658513000003 0.027404078377800001 -0.024215369134099999"/>
              <site name="fhl_r_fhl_r-P4" pos="0.103135731381 0.0067517294553999995 -0.025722549785600003"/>
              <site name="fhl_r_fhl_r-P5" pos="0.17149544543700002 -0.0052623773696500002 -0.027028773016900001"/>
              <site name="gaslat_r_gaslat_r-P2" pos="0.0043718421780000001 0.030779943105500002 -0.0053253716352999999"/>
              <site name="gasmed_r_gasmed_r-P2" pos="0.0043718421780000001 0.030779943105500002 -0.0053253716352999999"/>
              <site name="perbrev_r_perbrev_r-P4" pos="0.046798583314500007 0.0268083375435 0.0234115394533"/>
              <site name="perbrev_r_perbrev_r-P5" pos="0.067266753511499994 0.021744540451950001 0.034464197564299998"/>
              <site name="perlong_r_perlong_r-P4" pos="0.043519701681 0.022836731981500002 0.022205794932100002"/>
              <site name="perlong_r_perlong_r-P5" pos="0.067664193709499998 0.0105247547393 0.028535953668400001"/>
              <site name="perlong_r_perlong_r-P6" pos="0.084654762174000003 0.0068510195944500004 0.011856487791799999"/>
              <site name="perlong_r_perlong_r-P7" pos="0.1195301395485 0.0084396618192500005 -0.018488082658400001"/>
              <site name="soleus_r_soleus_r-P2" pos="0.0043718421780000001 0.030779943105500002 -0.0053253716352999999"/>
              <site name="tibant_r_tibant_r-P4" pos="0.115853817717 0.017673644750900001 -0.030646006580499999"/>
              <site name="tibpost_r_tibpost_r-P3" pos="0.041433140641499999 0.033162906442700001 -0.028736911088599999"/>
              <site name="tibpost_r_tibpost_r-P4" pos="0.076705958214000003 0.015787132108950001 -0.028234517538099999"/>
              <site name="R1MT_marker" group="4" pos="0.1871 0.026 -0.02559" rgba="1 0.1 0.5 0.5" size="0.01"/>
              <site name="R5MT_marker" group="4" pos="0.1498 0.01278 0.07692" rgba="1 0.1 0.5 0.5" size="0.01"/>
              <site name="RCAL_marker" group="4" pos="-0.01791 0.01881 -0.0008101" rgba="1 0.1 0.5 0.5" size="0.01"/>
            </body>
          </body>
          <site name="bflh_r_bflh_r-P2" pos="-0.030162482560570001 -0.031644485397000002 0.022335567567280001"/>
          <site name="bflh_r_bflh_r-P3" pos="-0.02568733678007 -0.041137831016100003 0.026749711355280002"/>
          <site name="bfsh_r_bfsh_r-P2" pos="-0.02694037759861 -0.037882969660980002 0.02807395449168"/>
          <site name="edl_r_edl_r-P1" pos="-0.0143204664976 -0.10460762744094 0.0180979895308"/>
          <site name="edl_r_edl_r-P2" pos="0.014678478160040002 -0.33995218597920002 0.0098876820851199997"/>
          <site name="ehl_r_ehl_r-P1" pos="-0.012530408185400001 -0.140139863901 0.01668546351864"/>
          <site name="ehl_r_ehl_r-P2" pos="0.0063547070083100005 -0.26301088005678003 0.014478391624640001"/>
          <site name="ehl_r_ehl_r-P3" pos="0.017900583122000002 -0.33389452734606001 -0.0024719205212799999"/>
          <site name="fdl_r_fdl_r-P1" pos="-0.0020585670590299999 -0.16563627784944002 -0.00158909176368"/>
          <site name="fdl_r_fdl_r-P2" pos="-0.015752513147360002 -0.32955471220589999 -0.010947076594239999"/>
          <site name="fhl_r_fhl_r-P1" pos="-0.0277459038391 -0.19556291975345999 0.017656575152"/>
          <site name="fhl_r_fhl_r-P2" pos="-0.021659705577619998 -0.33190544540681999 -0.00670949855776"/>
          <site name="grac_r_grac_r-P2" pos="-0.016486437055361999 -0.042991293732210001 -0.026140559512536"/>
          <site name="grac_r_grac_r-P3" pos="0.0015931518978579999 -0.062945402095404002 -0.013886896357048002"/>
          <site name="GR_at_condyles_r_cylinder_grac_r_1_sidesite" pos="-0.01363 -0.001682 -0.02967" size="0.0005"/>
          <site name="perbrev_r_perbrev_r-P1" pos="-0.021749208493229998 -0.22892524864343999 0.022159001815760002"/>
          <site name="perbrev_r_perbrev_r-P2" pos="-0.03034148839179 -0.35197709043005998 0.02198243606424"/>
          <site name="perbrev_r_perbrev_r-P3" pos="-0.025508330948850001 -0.36201291294167998 0.0225121333188"/>
          <site name="perlong_r_perlong_r-P1" pos="-0.017900583122000002 -0.12413679557166001 0.02489577096432"/>
          <site name="perlong_r_perlong_r-P2" pos="-0.028372424248369998 -0.35260998013800005 0.020923041555119998"/>
          <site name="perlong_r_perlong_r-P3" pos="-0.024344793045919997 -0.36291704109588002 0.021187890182400002"/>
          <site name="recfem_r_recfem_r-P5" pos="0.029177950488859999 -0.057068569093103996 -0.00041492951607199999"/>
          <site name="sart_r_sart_r-P3" pos="-0.022465231818110002 -0.036255538983419995 -0.032223249652399998"/>
          <site name="sart_r_sart_r-P4" pos="-0.014230963581990001 -0.054157276436580006 -0.023306679200640001"/>
          <site name="sart_r_sart_r-P5" pos="0.012172396522959998 -0.073234380490200007 -0.00229535476976"/>
          <site name="semimem_r_semimem_r-P2" pos="-0.025955845526900001 -0.037702144030140002 -0.017303443648959999"/>
          <site name="SM_at_condyles_r_cylinder_semimem_r_1_sidesite" pos="-0.02596 -0.0377 -0.0173" size="0.0005"/>
          <site name="semiten_r_semiten_r-P2" pos="-0.027924909670319999 -0.045929710233359997 -0.020216778549040002"/>
          <site name="semiten_r_semiten_r-P3" pos="0.0017005553965900001 -0.069889106319659999 -0.010329096463920001"/>
          <site name="ST_at_condyles_r_cylinder_semiten_r_1_sidesite" pos="-0.0308 -0.003424 -0.02164" size="0.0005"/>
          <site name="soleus_r_soleus_r-P1" pos="-0.0068022215863600003 -0.082818138924720008 0.0086517218244799993"/>
          <site name="tfl_r_tfl_r-P4" pos="0.0096663148858800001 -0.037069254322200006 0.030545875012959998"/>
          <site name="tibant_r_tibant_r-P1" pos="0.013783449003940001 -0.11862161383104002 0.014301825873119999"/>
          <site name="tibant_r_tibant_r-P2" pos="0.022465231818110002 -0.17232682619052 0.011300208097280001"/>
          <site name="tibant_r_tibant_r-P3" pos="0.020854179337130001 -0.33082049162178001 -0.011653339600320001"/>
          <site name="tibpost_r_tibpost_r-P1" pos="-0.0036696195400100005 -0.11789831130768 0.0090931362032800004"/>
          <site name="tibpost_r_tibpost_r-P2" pos="-0.014678478160040002 -0.33045884036009998 -0.015449503258000001"/>
          <site name="vasint_r_vasint_r-P5" pos="0.029151099614177001 -0.057140899345440005 0.00037961636576799997"/>
          <site name="vaslat_r_vaslat_r-P5" pos="0.029124248739493999 -0.057303642413196007 0.0045112549513359997"/>
          <site name="vasmed_r_vasmed_r-P5" pos="0.028551430079589997 -0.057475426762494002 -0.005985578976528"/>
          <site name="RLM_marker" group="4" pos="-0.005528 -0.372 0.05308" rgba="1 0.1 0.5 0.5" size="0.01"/>
          <site name="RMM_marker" group="4" pos="-0.0004889 -0.3585 -0.0376" rgba="1 0.1 0.5 0.5" size="0.01"/>
          <site name="RS1_marker" group="4" pos="0.02602 -0.1741 -0.01321" rgba="1 0.1 0.5 0.5" size="0.01"/>
          <site name="RS2_marker" group="4" pos="0.02496 -0.1387 0.02904" rgba="1 0.1 0.5 0.5" size="0.01"/>
          <site name="RS3_marker" group="4" pos="0.0204 -0.0871 -0.02163" rgba="1 0.1 0.5 0.5" size="0.01"/>
        </body>
        <body name="patella_r" pos="-0.007627 -0.3834 -0.002646" euler="-0 0 0">
          <inertial mass="0.073912113787673484" pos="0.0018 0.0264 0" fullinertia="2.4608789625362283e-06 1.1241157909006952e-05 1.1241157909006952e-05 0 0 0"/>
          <geom name="patella_r_geom_1" type="mesh" mesh="patella_r_geom_1_r_patella" rgba="1 1 1 1" group="0"/>
          <joint name="patellofemoral_r_translation1" range="-0.0214 0.0494" limited="true" user="0.04941922471118752" ref="0" axis="1 0 0" type="slide"/>
          <joint name="patellofemoral_r_translation2" range="-0.03834 -0.01015" limited="true" user="-0.010175510744391558" ref="0" axis="0 1 0" type="slide"/>
          <joint name="patellofemoral_r_translation3" limited="false" ref="0" axis="0 0 1" type="slide"/>
          <joint name="patellofemoral_r_rotation1" range="-1.786 0.001137" limited="true" user="0.01050598499723554" ref="0" axis="0 0 1" type="hinge"/>
          <site name="recfem_r_recfem_r-P2" pos="0.01 0.049000000000000002 0.00069999999999999999"/>
          <site name="recfem_r_recfem_r-P3" pos="0.0121 0.043700000000000003 -0.001"/>
          <site name="recfem_r_recfem_r-P4" pos="0.0050000000000000001 0.00247 3.0000000000000001e-05"/>
          <site name="vasint_r_vasint_r-P3" pos="0.0057999999999999996 0.048000000000000001 -0.00059999999999999995"/>
          <site name="vasint_r_vasint_r-P4" pos="0.0050000000000000001 0.00247 -0.00038999999999999999"/>
          <site name="vaslat_r_vaslat_r-P3" pos="0.0103 0.042299999999999997 0.0141"/>
          <site name="vaslat_r_vaslat_r-P4" pos="0.0050000000000000001 0.00247 0.0073299999999999997"/>
          <site name="vasmed_r_vasmed_r-P3" pos="0.0063 0.044499999999999998 -0.017000000000000001"/>
          <site name="vasmed_r_vasmed_r-P4" pos="0.0050000000000000001 0.00247 -0.0085000000000000006"/>
        </body>
        <site name="addbrev_r_addbrev_r-P2" pos="-0.0018855379554000001 -0.1108880647042 0.023957671028699997"/>
        <site name="AB_at_femshaft_r_cylinder_addbrev_r_1_sidesite" pos="0.001501 -0.09987 0.01286" size="0.0005"/>
        <site name="addlong_r_addlong_r-P2" pos="0.010615578688902 -0.22494301735800301 0.01523092097929"/>
        <site name="AL_at_femshaft_r_cylinder_addlong_r_1_sidesite" pos="0.01062 -0.2249 0.01523" size="0.0005"/>
        <site name="addmagDist_r_addmagDist_r-P2" pos="0.010606150999125 -0.24667895749875002 0.018569600435900002"/>
        <site name="AMdist_at_femshaft_r_cylinder_addmagDist_r_1_sidesite" pos="0.01061 -0.2467 0.01857" size="0.0005"/>
        <site name="addmagIsch_r_addmagIsch_r-P2" pos="0.0045347187827370003 -0.36458680053634296 -0.031491348303990002"/>
        <site name="AMisch_at_condyles_r_cylinder_addmagIsch_r_1_sidesite" pos="0.004535 -0.3646 -0.03149" size="0.0005"/>
        <site name="addmagMid_r_addmagMid_r-P2" pos="0.002281500926034 -0.15261204837255998 0.02811418262886"/>
        <site name="AMmid_at_femshaft_r_cylinder_addmagMid_r_1_sidesite" pos="0.002282 -0.1526 0.02811" size="0.0005"/>
        <site name="addmagProx_r_addmagProx_r-P2" pos="-0.014396082289479001 -0.074107057479433996 0.030808217925259999"/>
        <site name="AMprox_at_femshaft_r_cylinder_addmagProx_r_1_sidesite" pos="-0.0151 -0.06936 0.01773" size="0.0005"/>
        <site name="bfsh_r_bfsh_r-P1" pos="0.0047138448885000002 -0.19837686829709 0.022514437834199999"/>
        <site name="gaslat_r_gaslat_r-P1" pos="-0.0028283069331000001 -0.35841277862866 0.0266517063251"/>
        <site name="Gastroc_at_condyles_r_cylinder_gaslat_r_1_sidesite" pos="-0.009128 -0.4031 0.02396" size="0.0005"/>
        <site name="gasmed_r_gasmed_r-P1" pos="0.0075421518216000002 -0.35596948228772002 -0.0200128336304"/>
        <site name="Gastroc_at_condyles_r_cylinder_gasmed_r_1_sidesite" pos="9.027e-05 -0.4009 -0.01752" size="0.0005"/>
        <site name="glmax1_r_glmax1_r-P3" pos="-0.041858942609880004 -0.030635177197939997 0.0290570949826"/>
        <site name="glmax1_r_glmax1_r-P4" pos="-0.02611470068229 -0.05318868188354 0.045221306761000002"/>
        <site name="glmax2_r_glmax2_r-P3" pos="-0.042424603996499999 -0.054880194734960003 0.024246317667599999"/>
        <site name="glmax2_r_glmax2_r-P4" pos="-0.01470719605212 -0.095476503169039995 0.040314313899699999"/>
        <site name="glmax3_r_glmax3_r-P3" pos="-0.026491808273369999 -0.10571955321375 0.0090442613521999997"/>
        <site name="glmax3_r_glmax3_r-P4" pos="-0.0056566138662000002 -0.13334759645361 0.039544589529299998"/>
        <site name="glmed1_r_glmed1_r-P2_0" pos="-0.013096715392265436 -0.017192071579563657 0.05694961596433705"/>
        <site name="glmed2_r_glmed2_r-P2_0" pos="-0.02077487065143873 -0.0093588558671232319 0.054002152672643078"/>
        <site name="glmed3_r_glmed3_r-P2_0" pos="-0.029131561410930002 -0.00441672800093 0.049839652983399998"/>
        <site name="glmin1_r_glmin1_r-P2" pos="0.0051751594527568228 -0.014555093232972428 0.053917078014412298"/>
        <site name="glmin2_r_glmin2_r-P2" pos="0.0033407404603803563 -0.0084690937709546252 0.050478839517812665"/>
        <site name="glmin3_r_glmin3_r-P2" pos="-0.003371471341676373 -0.0011903559052303195 0.049321676136014271"/>
        <site name="iliacus_r_iliacus_r-P3" pos="-0.0021683686487100002 -0.053094708947350001 0.013373960935699999"/>
        <site name="iliacus_r_iliacus_r-P4" pos="-0.011501781527940002 -0.059860760353030007 0.018858247074799998"/>
        <site name="piri_r_piri_r-P3" pos="-0.01395298086996 -0.0033830257028399997 0.0420461937331"/>
        <site name="psoas_r_psoas_r-P3" pos="-0.012444550505640001 -0.04388536120073 0.0044259151297999996"/>
        <site name="psoas_r_psoas_r-P4" pos="-0.02215507097595 -0.049241818563560004 0.0084669680744000001"/>
        <site name="KnExt_at_fem_r_cylinder_recfem_r_3_sidesite" pos="-0.01398 -0.3713 -0.01376" size="0.0005"/>
        <site name="sart_r_sart_r-P2" pos="-0.0028283069331000001 -0.33529543632592002 -0.040506744992299996"/>
        <site name="tfl_r_tfl_r-P2" pos="0.027717407944380001 -0.093503071509050004 0.0574406811411"/>
        <site name="tfl_r_tfl_r-P3" pos="0.01008762806139 -0.38059039156950003 0.031173837001199998"/>
        <site name="vasint_r_vasint_r-P1" pos="0.027340300353300002 -0.18080392922955998 0.029826819352999998"/>
        <site name="vasint_r_vasint_r-P2" pos="0.031582760752950002 -0.19583959901996001 0.027421430695500001"/>
        <site name="KnExt_at_fem_r_cylinder_vasint_r_4_sidesite" pos="-0.01456 -0.3858 -0.01306" size="0.0005"/>
        <site name="KnExt_at_fem_r_cylinder_vasint_r_3_sidesite" pos="-0.01456 -0.3858 -0.01306" size="0.0005"/>
        <site name="vaslat_r_vaslat_r-P1" pos="0.0045252910929599998 -0.17422582369626 0.033579225658700002"/>
        <site name="vaslat_r_vaslat_r-P2" pos="0.025360485500130002 -0.24348387766828999 0.039352158436700001"/>
        <site name="KnExt_at_fem_r_cylinder_vaslat_r_3_sidesite" pos="-0.01642 -0.3712 0.01452" size="0.0005"/>
        <site name="vasmed_r_vasmed_r-P1" pos="0.0131987656878 -0.19724919306281 0.018088522704399999"/>
        <site name="vasmed_r_vasmed_r-P2" pos="0.033562575606119999 -0.26021106031010999 0.00086593991670000001"/>
        <site name="KnExt_at_fem_r_cylinder_vasmed_r_4_sidesite" pos="-0.006668 -0.3826 -0.01999" size="0.0005"/>
        <site name="KnExt_at_fem_r_cylinder_vasmed_r_3_sidesite" pos="-0.006668 -0.3826 -0.01999" size="0.0005"/>
        <site name="RLFE_marker" group="4" pos="0.007257 -0.3814 0.05969" rgba="1 0.1 0.5 0.5" size="0.01"/>
        <site name="RMFE_marker" group="4" pos="-0.00408 -0.381 -0.05531" rgba="1 0.1 0.5 0.5" size="0.01"/>
        <site name="RT1_marker" group="4" pos="0.04956 -0.2905 0.06198" rgba="1 0.1 0.5 0.5" size="0.01"/>
        <site name="RT2_marker" group="4" pos="0.08597 -0.2396 -0.004408" rgba="1 0.1 0.5 0.5" size="0.01"/>
        <site name="RT3_marker" group="4" pos="0.05205 -0.1935 0.07381" rgba="1 0.1 0.5 0.5" size="0.01"/>
        <site name="RTRC_marker" group="4" pos="-0.01729 -0.02113 0.08677" rgba="1 0.1 0.5 0.5" size="0.01"/>
      </body>
      <body name="femur_l" pos="-0.05566 -0.07938 -0.08686" euler="-0 0 0">
        <inertial mass="7.6104456087" pos="0.0000000000 -0.1700000000 0.0000000000" fullinertia="0.1095575577 0.0287189714 0.1155304492 0.0000000000 0.0000000000 0.0000000000"/>
        <geom name="femur_l_geom_1" type="mesh" mesh="femur_l_geom_1_l_femur" rgba="1 1 1 1" group="0"/>
        <geom name="Gastroc_at_condyles_l_cylinder" type="cylinder" euler="0 0 0" pos="0.004714 -0.3853 0" size="0.02353 0.04811" rgba="0.19 0.83 0.78 0.2" group="2"/>
        <geom name="KnExt_at_fem_l_cylinder" type="cylinder" euler="0.06234 -0.05076 0" pos="0.003383 -0.3785 -0.002012" size="0.02353 0.0481" rgba="0.19 0.83 0.78 0.2" group="2"/>
        <geom name="AB_at_femshaft_l_cylinder" type="cylinder" euler="-1.662 -0.1866 0" pos="0.01381 -0.1058 -0.02248" size="0.01571 0.0329" rgba="0.19 0.83 0.78 0.2" group="2"/>
        <geom name="AL_at_femshaft_l_cylinder" type="cylinder" euler="-1.777 -0.1365 0" pos="0.02897 -0.2179 -0.01454" size="0.01913 0.04704" rgba="0.19 0.83 0.78 0.2" group="2"/>
        <geom name="AMprox_at_femshaft_l_cylinder" type="cylinder" euler="-1.611 -0.1866 0" pos="0.004886 -0.0685 -0.02444" size="0.0201 0.0329" rgba="0.19 0.83 0.78 0.2" group="2"/>
        <geom name="AMmid_at_femshaft_l_cylinder" type="cylinder" euler="-1.611 -0.1366 0" pos="0.0217 -0.151 -0.01981" size="0.02038 0.05639" rgba="0.19 0.83 0.78 0.2" group="2"/>
        <geom name="AMdist_at_femshaft_l_cylinder" type="cylinder" euler="-1.712 -0.1866 0" pos="0.0298 -0.245 -0.00901" size="0.02076 0.09403" rgba="0.19 0.83 0.78 0.2" group="2"/>
        <geom name="AMisch_at_condyles_l_cylinder" type="cylinder" euler="-1.711 0.4634 0" pos="-0.02135 -0.3541 0.003035" size="0.03808 0.1129" rgba="0.19 0.83 0.78 0.2" group="2"/>
        <geom name="PECT_at_femshaft_l_cylinder" type="cylinder" euler="-1.813 -0.2763 0" pos="0.005737 -0.07941 -0.02929" size="0.01428 0.02353" rgba="0.19 0.83 0.78 0.2" group="2"/>
        <joint name="hip_flexion_l" range="-0.5236 2.094" limited="true" user="0.0" ref="0" axis="0 0 1" type="hinge"/>
        <joint name="hip_adduction_l" range="-0.8727 0.5236" limited="true" user="-0.0" ref="0" axis="-1 -0 -0" type="hinge"/>
        <joint name="hip_rotation_l" range="-0.6981 0.6981" limited="true" user="-0.0" ref="0" axis="-0 -1 -0" type="hinge"/>
        <body name="tibia_l" pos="-0.0003866 -0.3802 0.001335" euler="-0 0 0">
          <inertial mass="3.0334924951" pos="0.0000000000 -0.1867000000 0.0000000000" fullinertia="0.0412374974 0.0041728420 0.0418102405 0.0000000000 0.0000000000 0.0000000000"/>
          <geom name="tibia_l_geom_1" type="mesh" mesh="tibia_l_geom_1_l_tibia" rgba="1 1 1 1" group="0"/>
          <geom name="tibia_l_geom_2" type="mesh" mesh="tibia_l_geom_2_l_fibula" rgba="1 1 1 1" group="0"/>
          <geom name="GasLat_at_shank_l_cylinder" type="cylinder" euler="-2.967 0.2797 -1.478" pos="-0.006623 -0.06691 0.002913" size="0.04944 0.04422" rgba="0.19 0.83 0.78 0.2" group="2"/>
          <site name="GasLat_at_shank_l_sidesite" pos="-0.05489 -0.0599 -0.009932" size="0.0005"/>
          <geom name="GasMed_at_shank_l_cylinder" type="cylinder" euler="-2.967 -0.02797 -1.478" pos="-0.006623 -0.06691 0.002913" size="0.04946 0.04417" rgba="0.19 0.83 0.78 0.2" group="2"/>
          <site name="GasMed_at_shank_l_sidesite" pos="-0.05685 -0.06255 0.005107" size="0.0005"/>
          <geom name="GR_at_condyles_l_cylinder" type="cylinder" euler="0 0.4 0" pos="-0.002685 -0.01808 0" size="0.03235 0.04423" rgba="0.19 0.83 0.78 0.2" group="2"/>
          <geom name="SM_at_condyles_l_cylinder" type="cylinder" euler="0 0.1 0" pos="-0.000895 -0.01808 0" size="0.03166 0.04415" rgba="0.19 0.83 0.78 0.2" group="2"/>
          <geom name="ST_at_condyles_l_cylinder" type="cylinder" euler="0 0.2 0" pos="-0.00179 -0.01853 0" size="0.03822 0.04417" rgba="0.19 0.83 0.78 0.2" group="2"/>
          <geom name="BF_at_gastroc_l_cylinder" type="cylinder" euler="0 0 0" pos="-0.05191 -0.05425 0" size="0.02699 0.06621" rgba="0.19 0.83 0.78 0.2" group="2"/>
          <joint name="walker_knee_l_translation1" range="0 0.001503" limited="true" user="8.96251289327684e-08" ref="0" axis="-0.1243 0.9898 0.07016" type="slide"/>
          <joint name="walker_knee_l_translation2" range="-0.006535 0" limited="true" user="-7.401422617153708e-11" ref="0" axis="-0.9922 -0.124 -0.008789" type="slide"/>
          <joint name="knee_angle_l" range="0 2.094" limited="true" user="0.0" ref="0" axis="4.566e-07 0.07071 -0.9975" type="hinge"/>
          <joint name="walker_knee_l_rotation2" range="-0.001678 0.03354" limited="true" user="-1.4732523263838448e-08" ref="0" axis="-0.9922 -0.124 -0.008789" type="hinge"/>
          <joint name="walker_knee_l_rotation3" range="-0.2628 0" limited="true" user="-1.0893911855935912e-08" ref="0" axis="-0.1243 0.9898 0.07016" type="hinge"/>
          <body name="talus_l" pos="-0.00895 -0.3617 0" euler="-0 0 0">
            <inertial mass="0.0818204314" pos="0.0000000000 0.0000000000 0.0000000000" fullinertia="0.0008182043 0.0008182043 0.0008182043 0.0000000000 0.0000000000 0.0000000000"/>
            <geom name="talus_l_geom_1" type="mesh" mesh="talus_l_geom_1_l_talus" rgba="1 1 1 0" group="0"/>
            <joint name="ankle_angle_l" range="-0.6981 0.5236" limited="true" user="0.0" ref="0" type="hinge" axis="0.105 0.174 0.9791"/>
            <body name="calcn_l" pos="-0.05456 -0.04903 -0.009057" euler="-0 0 0">
              <inertial mass="1.0227553928" pos="0.1000000000 0.0300000000 0.0000000000" fullinertia="0.0011454860 0.0031909968 0.0033546377 0.0000000000 0.0000000000 0.0000000000"/>
              <geom name="calcn_l_geom_1" type="mesh" mesh="calcn_l_geom_1_l_foot" rgba="1 1 1 1" group="0"/>
              <joint name="subtalar_angle_l" range="-0.3491 0.3491" limited="true" user="0.0" ref="0" type="hinge" axis="-0.7872 -0.6047 -0.1209"/>
              <body name="toes_l" pos="0.1777 -0.001986 -0.001085" euler="-0 0 0">
                <inertial mass="0.1772230545" pos="0.0346000000 0.0060000000 0.0175000000" fullinertia="0.0005158778 0.0005976983 0.0008182043 0.0000000000 0.0000000000 0.0000000000"/>
                <geom name="toes_l_geom_1" type="mesh" mesh="toes_l_geom_1_l_bofoot" rgba="1 1 1 1" group="0"/>
                <joint name="mtp_angle_l" range="-0.5236 0.5236" limited="true" user="0.0" ref="0" type="hinge" axis="-0.581 2.16e-06 -0.8139"/>
                <site name="edl_l_edl_l-P5" pos="0.00029851120983 0.0046731716841900001 -0.015217040167109999"/>
                <site name="edl_l_edl_l-P6" pos="0.044080155318230001 -0.00039771673908 -0.024864444717500003"/>
                <site name="ehl_l_ehl_l-P7" pos="0.02965211350978 0.0040765965755700006 0.024367155823150001"/>
                <site name="ehl_l_ehl_l-P8" pos="0.056020603711430007 0.0033805922821799998 0.018499146869819998"/>
                <site name="fdl_l_fdl_l-P6" pos="-0.00189057099559 -0.0077554764120599997 -0.01462029349389"/>
                <site name="fdl_l_fdl_l-P7" pos="0.028358564933850004 -0.0070594721186700007 -0.021383422457049998"/>
                <site name="fdl_l_fdl_l-P8" pos="0.043881147845010002 -0.0059657510862000003 -0.02406878248654"/>
                <site name="fhl_l_fhl_l-P6" pos="0.01542307917455 -0.00636346782528 0.02635631140055"/>
                <site name="fhl_l_fhl_l-P7" pos="0.055921099974820004 -0.010141776846540001 0.018001857975470003"/>
              </body>
              <site name="edl_l_edl_l-P3" pos="0.091311885490499997 0.035744450057999998 -0.00080382968080000008"/>
              <site name="edl_l_edl_l-P4" pos="0.160565839992 0.0054609576477500001 -0.013062232312999999"/>
              <site name="ehl_l_ehl_l-P4" pos="0.096379248015000002 0.038623864090449996 0.021201007831100002"/>
              <site name="ehl_l_ehl_l-P5" pos="0.1284725440035 0.030680652966450003 0.0258230284957"/>
              <site name="ehl_l_ehl_l-P6" pos="0.172290325833 0.01380132932795 0.028134038828000002"/>
              <site name="fdl_l_fdl_l-P3" pos="0.043320981581999998 0.031276393800750001 0.028134038828000002"/>
              <site name="fdl_l_fdl_l-P4" pos="0.070346915046000005 0.017475064472800002 0.0264259007563"/>
              <site name="fdl_l_fdl_l-P5" pos="0.164738962071 -0.0080425012630500007 -0.0116555303716"/>
              <site name="fhl_l_fhl_l-P3" pos="0.037160658513000003 0.027404078377800001 0.024215369134099999"/>
              <site name="fhl_l_fhl_l-P4" pos="0.103135731381 0.0067517294553999995 0.025722549785600003"/>
              <site name="fhl_l_fhl_l-P5" pos="0.17149544543700002 -0.0052623773696500002 0.027028773016900001"/>
              <site name="gaslat_l_gaslat_l-P2" pos="0.0043718421780000001 0.030779943105500002 0.0053253716352999999"/>
              <site name="gasmed_l_gasmed_l-P2" pos="0.0043718421780000001 0.030779943105500002 0.0053253716352999999"/>
              <site name="perbrev_l_perbrev_l-P4" pos="0.046798583314500007 0.0268083375435 -0.0234115394533"/>
              <site name="perbrev_l_perbrev_l-P5" pos="0.067266753511499994 0.021744540451950001 -0.034464197564299998"/>
              <site name="perlong_l_perlong_l-P4" pos="0.043519701681 0.022836731981500002 -0.022205794932100002"/>
              <site name="perlong_l_perlong_l-P5" pos="0.067664193709499998 0.0105247547393 -0.028535953668400001"/>
              <site name="perlong_l_perlong_l-P6" pos="0.084654762174000003 0.0068510195944500004 -0.011856487791799999"/>
              <site name="perlong_l_perlong_l-P7" pos="0.1195301395485 0.0084396618192500005 0.018488082658400001"/>
              <site name="soleus_l_soleus_l-P2" pos="0.0043718421780000001 0.030779943105500002 0.0053253716352999999"/>
              <site name="tibant_l_tibant_l-P4" pos="0.115853817717 0.017673644750900001 0.030646006580499999"/>
              <site name="tibpost_l_tibpost_l-P3" pos="0.041433140641499999 0.033162906442700001 0.028736911088599999"/>
              <site name="tibpost_l_tibpost_l-P4" pos="0.076705958214000003 0.015787132108950001 0.028234517538099999"/>
              <site name="L1MT_marker" group="4" pos="0.1876 0.02686 0.0261" rgba="1 0.1 0.5 0.5" size="0.01"/>
              <site name="L5MT_marker" group="4" pos="0.1509 0.01599 -0.06818" rgba="1 0.1 0.5 0.5" size="0.01"/>
              <site name="LCAL_marker" group="4" pos="-0.01831 0.01717 0.0008953" rgba="1 0.1 0.5 0.5" size="0.01"/>
            </body>
          </body>
          <site name="bflh_l_bflh_l-P2" pos="-0.030162482560570001 -0.031644485397000002 -0.022335567567280001"/>
          <site name="bflh_l_bflh_l-P3" pos="-0.02568733678007 -0.041137831016100003 -0.026749711355280002"/>
          <site name="bfsh_l_bfsh_l-P2" pos="-0.02694037759861 -0.037882969660980002 -0.02807395449168"/>
          <site name="edl_l_edl_l-P1" pos="-0.0143204664976 -0.10460762744094 -0.0180979895308"/>
          <site name="edl_l_edl_l-P2" pos="0.014678478160040002 -0.33995218597920002 -0.0098876820851199997"/>
          <site name="ehl_l_ehl_l-P1" pos="-0.012530408185400001 -0.140139863901 -0.01668546351864"/>
          <site name="ehl_l_ehl_l-P2" pos="0.0063547070083100005 -0.26301088005678003 -0.014478391624640001"/>
          <site name="ehl_l_ehl_l-P3" pos="0.017900583122000002 -0.33389452734606001 0.0024719205212799999"/>
          <site name="fdl_l_fdl_l-P1" pos="-0.0020585670590299999 -0.16563627784944002 0.00158909176368"/>
          <site name="fdl_l_fdl_l-P2" pos="-0.015752513147360002 -0.32955471220589999 0.010947076594239999"/>
          <site name="fhl_l_fhl_l-P1" pos="-0.0277459038391 -0.19556291975345999 -0.017656575152"/>
          <site name="fhl_l_fhl_l-P2" pos="-0.021659705577619998 -0.33190544540681999 0.00670949855776"/>
          <site name="grac_l_grac_l-P2" pos="-0.016486437055361999 -0.042991293732210001 0.026140559512536"/>
          <site name="grac_l_grac_l-P3" pos="0.0015931518978579999 -0.062945402095404002 0.013886896357048002"/>
          <site name="GR_at_condyles_l_cylinder_grac_l_1_sidesite" pos="-0.01363 -0.001682 0.02967" size="0.0005"/>
          <site name="perbrev_l_perbrev_l-P1" pos="-0.021749208493229998 -0.22892524864343999 -0.022159001815760002"/>
          <site name="perbrev_l_perbrev_l-P2" pos="-0.03034148839179 -0.35197709043005998 -0.02198243606424"/>
          <site name="perbrev_l_perbrev_l-P3" pos="-0.025508330948850001 -0.36201291294167998 -0.0225121333188"/>
          <site name="perlong_l_perlong_l-P1" pos="-0.017900583122000002 -0.12413679557166001 -0.02489577096432"/>
          <site name="perlong_l_perlong_l-P2" pos="-0.028372424248369998 -0.35260998013800005 -0.020923041555119998"/>
          <site name="perlong_l_perlong_l-P3" pos="-0.024344793045919997 -0.36291704109588002 -0.021187890182400002"/>
          <site name="recfem_l_recfem_l-P5" pos="0.029177950488859999 -0.057068569093103996 0.00041492951607199999"/>
          <site name="sart_l_sart_l-P3" pos="-0.022465231818110002 -0.036255538983419995 0.032223249652399998"/>
          <site name="sart_l_sart_l-P4" pos="-0.014230963581990001 -0.054157276436580006 0.023306679200640001"/>
          <site name="sart_l_sart_l-P5" pos="0.012172396522959998 -0.073234380490200007 0.00229535476976"/>
          <site name="semimem_l_semimem_l-P2" pos="-0.025955845526900001 -0.037702144030140002 0.017303443648959999"/>
          <site name="SM_at_condyles_l_cylinder_semimem_l_1_sidesite" pos="-0.02596 -0.0377 0.0173" size="0.0005"/>
          <site name="semiten_l_semiten_l-P2" pos="-0.027924909670319999 -0.045929710233359997 0.020216778549040002"/>
          <site name="semiten_l_semiten_l-P3" pos="0.0017005553965900001 -0.069889106319659999 0.010329096463920001"/>
          <site name="ST_at_condyles_l_cylinder_semiten_l_1_sidesite" pos="-0.0308 -0.003424 0.02164" size="0.0005"/>
          <site name="soleus_l_soleus_l-P1" pos="-0.0068022215863600003 -0.082818138924720008 -0.0086517218244799993"/>
          <site name="tfl_l_tfl_l-P4" pos="0.0096663148858800001 -0.037069254322200006 -0.030545875012959998"/>
          <site name="tibant_l_tibant_l-P1" pos="0.013783449003940001 -0.11862161383104002 -0.014301825873119999"/>
          <site name="tibant_l_tibant_l-P2" pos="0.022465231818110002 -0.17232682619052 -0.011300208097280001"/>
          <site name="tibant_l_tibant_l-P3" pos="0.020854179337130001 -0.33082049162178001 0.011653339600320001"/>
          <site name="tibpost_l_tibpost_l-P1" pos="-0.0036696195400100005 -0.11789831130768 -0.0090931362032800004"/>
          <site name="tibpost_l_tibpost_l-P2" pos="-0.014678478160040002 -0.33045884036009998 0.015449503258000001"/>
          <site name="vasint_l_vasint_l-P5" pos="0.029151099614177001 -0.057140899345440005 -0.00037961636576799997"/>
          <site name="vaslat_l_vaslat_l-P5" pos="0.029124248739493999 -0.057303642413196007 -0.0045112549513359997"/>
          <site name="vasmed_l_vasmed_l-P5" pos="0.028551430079589997 -0.057475426762494002 0.005985578976528"/>
          <site name="LLM_marker" group="4" pos="-0.006635 -0.37 -0.05165" rgba="1 0.1 0.5 0.5" size="0.01"/>
          <site name="LMM_marker" group="4" pos="0.002955 -0.3573 0.04213" rgba="1 0.1 0.5 0.5" size="0.01"/>
          <site name="LS1_marker" group="4" pos="0.0215 -0.1833 0.004295" rgba="1 0.1 0.5 0.5" size="0.01"/>
          <site name="LS2_marker" group="4" pos="0.02291 -0.1349 -0.04349" rgba="1 0.1 0.5 0.5" size="0.01"/>
          <site name="LS3_marker" group="4" pos="0.02852 -0.08354 0.005605" rgba="1 0.1 0.5 0.5" size="0.01"/>
        </body>
        <body name="patella_l" pos="-0.007627 -0.3834 0.002646" euler="-0 0 0">
          <inertial mass="0.073912113787673484" pos="0.0018 0.0264 0" fullinertia="2.4608789625362283e-06 1.1241157909006952e-05 1.1241157909006952e-05 0 0 0"/>
          <geom name="patella_l_geom_1" type="mesh" mesh="patella_l_geom_1_l_patella" rgba="1 1 1 1" group="0"/>
          <joint name="patellofemoral_l_translation1" range="-0.0214 0.0494" limited="true" user="0.04941922471118752" ref="0" axis="1 0 0" type="slide"/>
          <joint name="patellofemoral_l_translation2" range="-0.03834 -0.01015" limited="true" user="-0.010175510744391558" ref="0" axis="0 1 0" type="slide"/>
          <joint name="patellofemoral_l_translation3" limited="false" ref="0" axis="0 0 1" type="slide"/>
          <joint name="patellofemoral_l_rotation1" range="-1.786 0.001137" limited="true" user="0.01050598499723554" ref="0" axis="0 0 1" type="hinge"/>
          <site name="recfem_l_recfem_l-P2" pos="0.01 0.049000000000000002 -0.00069999999999999999"/>
          <site name="recfem_l_recfem_l-P3" pos="0.0121 0.043700000000000003 0.001"/>
          <site name="recfem_l_recfem_l-P4" pos="0.0050000000000000001 0.00247 -3.0000000000000001e-05"/>
          <site name="vasint_l_vasint_l-P3" pos="0.0057999999999999996 0.048000000000000001 0.00059999999999999995"/>
          <site name="vasint_l_vasint_l-P4" pos="0.0050000000000000001 0.00247 0.00038999999999999999"/>
          <site name="vaslat_l_vaslat_l-P3" pos="0.0103 0.042299999999999997 -0.0141"/>
          <site name="vaslat_l_vaslat_l-P4" pos="0.0050000000000000001 0.00247 -0.0073299999999999997"/>
          <site name="vasmed_l_vasmed_l-P3" pos="0.0063 0.044499999999999998 0.017000000000000001"/>
          <site name="vasmed_l_vasmed_l-P4" pos="0.0050000000000000001 0.00247 0.0085000000000000006"/>
        </body>
        <site name="addbrev_l_addbrev_l-P2" pos="-0.0018855379554000001 -0.1108880647042 -0.023957671028699997"/>
        <site name="AB_at_femshaft_l_cylinder_addbrev_l_1_sidesite" pos="0.001501 -0.09987 -0.01286" size="0.0005"/>
        <site name="addlong_l_addlong_l-P2" pos="0.010615578688902 -0.22494301735800301 -0.01523092097929"/>
        <site name="AL_at_femshaft_l_cylinder_addlong_l_1_sidesite" pos="0.01062 -0.2249 -0.01523" size="0.0005"/>
        <site name="addmagDist_l_addmagDist_l-P2" pos="0.010606150999125 -0.24667895749875002 -0.018569600435900002"/>
        <site name="AMdist_at_femshaft_l_cylinder_addmagDist_l_1_sidesite" pos="0.01061 -0.2467 -0.01857" size="0.0005"/>
        <site name="addmagIsch_l_addmagIsch_l-P2" pos="0.0045347187827370003 -0.36458680053634296 0.031491348303990002"/>
        <site name="AMisch_at_condyles_l_cylinder_addmagIsch_l_1_sidesite" pos="0.004535 -0.3646 0.03149" size="0.0005"/>
        <site name="addmagMid_l_addmagMid_l-P2" pos="0.002281500926034 -0.15261204837255998 -0.02811418262886"/>
        <site name="AMmid_at_femshaft_l_cylinder_addmagMid_l_1_sidesite" pos="0.002282 -0.1526 -0.02811" size="0.0005"/>
        <site name="addmagProx_l_addmagProx_l-P2" pos="-0.014396082289479001 -0.074107057479433996 -0.030808217925259999"/>
        <site name="AMprox_at_femshaft_l_cylinder_addmagProx_l_1_sidesite" pos="-0.0151 -0.06936 -0.01773" size="0.0005"/>
        <site name="bfsh_l_bfsh_l-P1" pos="0.0047138448885000002 -0.19837686829709 -0.022514437834199999"/>
        <site name="gaslat_l_gaslat_l-P1" pos="-0.0028283069331000001 -0.35841277862866 -0.0266517063251"/>
        <site name="Gastroc_at_condyles_l_cylinder_gaslat_l_1_sidesite" pos="-0.009128 -0.4031 -0.02396" size="0.0005"/>
        <site name="gasmed_l_gasmed_l-P1" pos="0.0075421518216000002 -0.35596948228772002 0.0200128336304"/>
        <site name="Gastroc_at_condyles_l_cylinder_gasmed_l_1_sidesite" pos="9.027e-05 -0.4009 0.01752" size="0.0005"/>
        <site name="glmax1_l_glmax1_l-P3" pos="-0.041858942609880004 -0.030635177197939997 -0.0290570949826"/>
        <site name="glmax1_l_glmax1_l-P4" pos="-0.02611470068229 -0.05318868188354 -0.045221306761000002"/>
        <site name="glmax2_l_glmax2_l-P3" pos="-0.042424603996499999 -0.054880194734960003 -0.024246317667599999"/>
        <site name="glmax2_l_glmax2_l-P4" pos="-0.01470719605212 -0.095476503169039995 -0.040314313899699999"/>
        <site name="glmax3_l_glmax3_l-P3" pos="-0.026491808273369999 -0.10571955321375 -0.0090442613521999997"/>
        <site name="glmax3_l_glmax3_l-P4" pos="-0.0056566138662000002 -0.13334759645361 -0.039544589529299998"/>
        <site name="glmed1_l_glmed1_l-P2" pos="-0.0131987656878 -0.0169151285142 -0.056767172316999993"/>
        <site name="glmed2_l_glmed2_l-P2" pos="-0.020740917509399999 -0.0093972936189999998 -0.053880705927999997"/>
        <site name="glmed3_l_glmed3_l-P2" pos="-0.029131561410930002 -0.00441672800093 -0.049839652983399998"/>
        <site name="glmin1_l_glmin1_l-P2" pos="0.0047138448885000002 -0.014095940428499999 -0.053880705927999997"/>
        <site name="glmin2_l_glmin2_l-P2" pos="0.0037710759108000001 -0.0084575642571 -0.050032084075999995"/>
        <site name="glmin3_l_glmin3_l-P2" pos="-0.0037710759108000001 -0.00093972936190000003 -0.049069928612999997"/>
        <site name="iliacus_l_iliacus_l-P3" pos="-0.0021683686487100002 -0.053094708947350001 -0.013373960935699999"/>
        <site name="iliacus_l_iliacus_l-P4" pos="-0.011501781527940002 -0.059860760353030007 -0.018858247074799998"/>
        <site name="piri_l_piri_l-P3" pos="-0.01395298086996 -0.0033830257028399997 -0.0420461937331"/>
        <site name="psoas_l_psoas_l-P3" pos="-0.012444550505640001 -0.04388536120073 -0.0044259151297999996"/>
        <site name="psoas_l_psoas_l-P4" pos="-0.02215507097595 -0.049241818563560004 -0.0084669680744000001"/>
        <site name="KnExt_at_fem_l_cylinder_recfem_l_3_sidesite" pos="-0.01398 -0.3713 0.01376" size="0.0005"/>
        <site name="sart_l_sart_l-P2" pos="-0.0028283069331000001 -0.33529543632592002 0.040506744992299996"/>
        <site name="tfl_l_tfl_l-P2" pos="0.027717407944380001 -0.093503071509050004 -0.0574406811411"/>
        <site name="tfl_l_tfl_l-P3" pos="0.01008762806139 -0.38059039156950003 -0.031173837001199998"/>
        <site name="vasint_l_vasint_l-P1" pos="0.027340300353300002 -0.18080392922955998 -0.029826819352999998"/>
        <site name="vasint_l_vasint_l-P2" pos="0.031582760752950002 -0.19583959901996001 -0.027421430695500001"/>
        <site name="KnExt_at_fem_l_cylinder_vasint_l_4_sidesite" pos="-0.01456 -0.3858 0.01306" size="0.0005"/>
        <site name="KnExt_at_fem_l_cylinder_vasint_l_3_sidesite" pos="-0.01456 -0.3858 0.01306" size="0.0005"/>
        <site name="vaslat_l_vaslat_l-P1" pos="0.0045252910929599998 -0.17422582369626 -0.033579225658700002"/>
        <site name="vaslat_l_vaslat_l-P2" pos="0.025360485500130002 -0.24348387766828999 -0.039352158436700001"/>
        <site name="KnExt_at_fem_l_cylinder_vaslat_l_3_sidesite" pos="-0.01642 -0.3712 -0.01452" size="0.0005"/>
        <site name="vasmed_l_vasmed_l-P1" pos="0.0131987656878 -0.19724919306281 -0.018088522704399999"/>
        <site name="vasmed_l_vasmed_l-P2" pos="0.033562575606119999 -0.26021106031010999 -0.00086593991670000001"/>
        <site name="KnExt_at_fem_l_cylinder_vasmed_l_4_sidesite" pos="-0.006668 -0.3826 0.01999" size="0.0005"/>
        <site name="KnExt_at_fem_l_cylinder_vasmed_l_3_sidesite" pos="-0.006668 -0.3826 0.01999" size="0.0005"/>
        <site name="LLFE_marker" group="4" pos="-0.001616 -0.3814 -0.06295" rgba="1 0.1 0.5 0.5" size="0.01"/>
        <site name="LMFE_marker" group="4" pos="-0.004326 -0.3818 0.05332" rgba="1 0.1 0.5 0.5" size="0.01"/>
        <site name="LT1_marker" group="4" pos="0.0335 -0.3015 -0.06434" rgba="1 0.1 0.5 0.5" size="0.01"/>
        <site name="LT2_marker" group="4" pos="0.09275 -0.2512 0.01124" rgba="1 0.1 0.5 0.5" size="0.01"/>
        <site name="LT3_marker" group="4" pos="0.0675 -0.1988 -0.06123" rgba="1 0.1 0.5 0.5" size="0.01"/>
        <site name="LTRC_marker" group="4" pos="-0.01729 -0.01869 -0.08665" rgba="1 0.1 0.5 0.5" size="0.01"/>
      </body>
      <body name="torso" pos="-0.0996 0.08242 0" euler="-0 0 0">
        <inertial mass="28.0125338258" pos="-0.0300000000 0.3200000000 0.0000000000" fullinertia="1.2064422614 0.6181533594 1.1711776554 0.0000000000 0.0000000000 0.0000000000"/>
        <geom name="torso_geom_1" type="mesh" mesh="torso_geom_1_hat_spine" rgba="1 1 1 1" group="0"/>
        <geom name="torso_geom_2" type="mesh" mesh="torso_geom_2_hat_jaw" rgba="1 1 1 1" group="0"/>
        <geom name="torso_geom_3" type="mesh" mesh="torso_geom_3_hat_skull" rgba="1 1 1 1" group="0"/>
        <geom name="torso_geom_4" type="mesh" mesh="torso_geom_4_hat_ribs_scap" rgba="1 1 1 1" group="0"/>
        <joint name="lumbar_extension" range="-1.571 1.571" limited="true" user="0.0" ref="0" axis="0 0 1" type="hinge"/>
        <joint name="lumbar_bending" range="-1.571 1.571" limited="true" user="0.0" ref="0" axis="1 0 0" type="hinge"/>
        <joint name="lumbar_rotation" range="-1.571 1.571" limited="true" user="0.0" ref="0" axis="0 1 0" type="hinge"/>
        <site name="C7_marker" group="4" pos="-0.09345 0.3619 -0.0009399" rgba="1 0.1 0.5 0.5" size="0.01"/>
        <site name="CLAV_marker" group="4" pos="0.07371 0.3428 0.0001027" rgba="1 0.1 0.5 0.5" size="0.01"/>
        <site name="LACR_marker" group="4" pos="0.001117 0.3683 -0.1434" rgba="1 0.1 0.5 0.5" size="0.01"/>
        <site name="RACR_marker" group="4" pos="0.0009341 0.3672 0.143" rgba="1 0.1 0.5 0.5" size="0.01"/>
      </body>
      <site name="addbrev_r_addbrev_r-P1" pos="-0.01889085671709 -0.095063936189399997 0.017313145947019999"/>
      <site name="addlong_r_addlong_r-P1" pos="-0.0074969996814419999 -0.08990621199189 0.021225467238944001"/>
      <site name="addmagDist_r_addmagDist_r-P1" pos="-0.073229268656196 -0.129115029077667 0.044766848805865997"/>
      <site name="addmagIsch_r_addmagIsch_r-P1" pos="-0.08863866905683801 -0.13122868468017598 0.046891643990272992"/>
      <site name="addmagMid_r_addmagMid_r-P1" pos="-0.052083377734133997 -0.12211670526457499 0.032085531514802"/>
      <site name="addmagProx_r_addmagProx_r-P1" pos="-0.030640771785102001 -0.10876730145925501 0.015345742998494999"/>
      <site name="bflh_r_bflh_r-P1" pos="-0.1028612093496 -0.12044802978890999 0.06587989301918"/>
      <site name="glmax1_r_glmax1_r-P1" pos="-0.12175206606668999 0.034890487218449999 0.063294163429690006"/>
      <site name="glmax1_r_glmax1_r-P2" pos="-0.12432359630043001 -0.024473906976419997 0.087577536965769989"/>
      <site name="Gmax1_at_pelvis_r_cylinder_glmax1_r_2_sidesite" pos="-0.1035 -0.09101 0.1096" size="0.0005"/>
      <site name="glmax2_r_glmax2_r-P1" pos="-0.13025789683983002 0.0087984706898699989 0.051939437841059997"/>
      <site name="glmax2_r_glmax2_r-P2" pos="-0.13292833208256 -0.061589294829090001 0.091399919837189994"/>
      <site name="Gmax2_at_pelvis_r_cylinder_glmax2_r_2_sidesite" pos="-0.1174 -0.09389 0.1002" size="0.0005"/>
      <site name="Gmax2_at_pelvis_r_cylinder_glmax2_r_1_sidesite" pos="-0.1329 -0.06159 0.0914" size="0.0005"/>
      <site name="glmax3_r_glmax3_r-P1" pos="-0.12857651168699999 -0.05309421968025 0.010118072306699999"/>
      <site name="glmax3_r_glmax3_r-P2" pos="-0.12590607644426999 -0.12772952277363001 0.048904016149049996"/>
      <site name="glmed1_r_glmed1_r-P1" pos="-0.048599355801208929 0.026449270770340368 0.12961067953121524"/>
      <site name="glmed2_r_glmed2_r-P1" pos="-0.083799568842877661 0.055252289333791844 0.092168354272874356"/>
      <site name="glmed3_r_glmed3_r-P1" pos="-0.098772277514590529 0.015735497179061288 0.071840144370060255"/>
      <site name="glmin1_r_glmin1_r-P1" pos="-0.02925564144490797 -0.00010944149469344441 0.13317014206184369"/>
      <site name="glmin2_r_glmin2_r-P1" pos="-0.060925484028669326 0.010113454241553596 0.1137106416807845"/>
      <site name="glmin3_r_glmin3_r-P1" pos="-0.07803605209311 -0.01567543628655 0.089713574452739989"/>
      <site name="grac_r_grac_r-P1" pos="-0.046841412257664 -0.13078370455333199 0.027611095094727998"/>
      <site name="iliacus_r_iliacus_r-P1" pos="-0.059837530438949994 0.031249740726089999 0.094772610606089991"/>
      <site name="iliacus_r_iliacus_r-P2" pos="-0.013352176213649999 -0.056330438784569996 0.084991807376279996"/>
      <site name="IL_at_brim_r_cylinder_iliacus_r_2_sidesite" pos="-0.02362 -0.09643 0.0935" size="0.0005"/>
      <site name="piri_r_piri_r-P1" pos="-0.10069518965271899 -0.0066039096097529996 0.015188350762612999"/>
      <site name="piri_r_piri_r-P2" pos="-0.10090289017159799 -0.031007024293265999 0.068488107213796001"/>
      <site name="psoas_r_psoas_r-P1" pos="-0.059936435447940001 0.0627017451462 0.043844979995700001"/>
      <site name="psoas_r_psoas_r-P2" pos="-0.02027552684295 -0.066140227944539998 0.073749504813280006"/>
      <site name="PS_at_brim_r_cylinder_psoas_r_2_sidesite" pos="-0.03069 -0.08885 0.08047" size="0.0005"/>
      <site name="recfem_r_recfem_r-P1" pos="-0.023737202157600001 -0.03923915663988 0.10489068291279"/>
      <site name="sart_r_sart_r-P1" pos="-0.019286476753050001 -0.015776568133559998 0.11871871506527999"/>
      <site name="semimem_r_semimem_r-P1" pos="-0.097619243873129993 -0.11529030559140001 0.06902773773682"/>
      <site name="semiten_r_semiten_r-P1" pos="-0.10266339933162 -0.12671820430352998 0.057897858199449995"/>
      <site name="tfl_r_tfl_r-P1" pos="-0.02011706692518982 0.010974167012199266 0.14536021309782457"/>
      <site name="addbrev_l_addbrev_l-P1" pos="-0.01889085671709 -0.095063936189399997 -0.017313145947019999"/>
      <site name="addlong_l_addlong_l-P1" pos="-0.0074969996814419999 -0.08990621199189 -0.021225467238944001"/>
      <site name="addmagDist_l_addmagDist_l-P1" pos="-0.073229268656196 -0.129115029077667 -0.044766848805865997"/>
      <site name="addmagIsch_l_addmagIsch_l-P1" pos="-0.08863866905683801 -0.13122868468017598 -0.046891643990272992"/>
      <site name="addmagMid_l_addmagMid_l-P1" pos="-0.052083377734133997 -0.12211670526457499 -0.032085531514802"/>
      <site name="addmagProx_l_addmagProx_l-P1" pos="-0.030640771785102001 -0.10876730145925501 -0.015345742998494999"/>
      <site name="bflh_l_bflh_l-P1" pos="-0.1028612093496 -0.12044802978890999 -0.06587989301918"/>
      <site name="glmax1_l_glmax1_l-P1" pos="-0.12175206606668999 0.034890487218449999 -0.063294163429690006"/>
      <site name="glmax1_l_glmax1_l-P2" pos="-0.12432359630043001 -0.024473906976419997 -0.087577536965769989"/>
      <site name="Gmax1_at_pelvis_l_cylinder_glmax1_l_2_sidesite" pos="-0.1035 -0.09101 -0.1096" size="0.0005"/>
      <site name="glmax2_l_glmax2_l-P1" pos="-0.13025789683983002 0.0087984706898699989 -0.051939437841059997"/>
      <site name="glmax2_l_glmax2_l-P2" pos="-0.13292833208256 -0.061589294829090001 -0.091399919837189994"/>
      <site name="Gmax2_at_pelvis_l_cylinder_glmax2_l_2_sidesite" pos="-0.1174 -0.09389 -0.1002" size="0.0005"/>
      <site name="Gmax2_at_pelvis_l_cylinder_glmax2_l_1_sidesite" pos="-0.1329 -0.06159 -0.0914" size="0.0005"/>
      <site name="glmax3_l_glmax3_l-P1" pos="-0.12857651168699999 -0.05309421968025 -0.010118072306699999"/>
      <site name="glmax3_l_glmax3_l-P2" pos="-0.12590607644426999 -0.12772952277363001 -0.048904016149049996"/>
      <site name="glmed1_l_glmed1_l-P1" pos="-0.048463454405099998 0.026294280222599997 -0.1292864794745"/>
      <site name="glmed2_l_glmed2_l-P1" pos="-0.0840692576415 0.055622515855500002 -0.092186881016599997"/>
      <site name="glmed3_l_glmed3_l-P1" pos="-0.098905008990000001 0.016181095521599999 -0.071950736403200002"/>
      <site name="glmin1_l_glmin1_l-P1" pos="-0.029671502696999998 0 -0.13265917024339999"/>
      <site name="glmin2_l_glmin2_l-P1" pos="-0.060925485537840003 0.010113184701 -0.11354725588630001"/>
      <site name="glmin3_l_glmin3_l-P1" pos="-0.07803605209311 -0.01567543628655 -0.089713574452739989"/>
      <site name="grac_l_grac_l-P1" pos="-0.046841412257664 -0.13078370455333199 -0.027611095094727998"/>
      <site name="iliacus_l_iliacus_l-P1" pos="-0.059837530438949994 0.031249740726089999 -0.094772610606089991"/>
      <site name="iliacus_l_iliacus_l-P2" pos="-0.013352176213649999 -0.056330438784569996 -0.084991807376279996"/>
      <site name="IL_at_brim_l_cylinder_iliacus_l_2_sidesite" pos="-0.02362 -0.09643 -0.0935" size="0.0005"/>
      <site name="piri_l_piri_l-P1" pos="-0.10069518965271899 -0.0066039096097529996 -0.015188350762612999"/>
      <site name="piri_l_piri_l-P2" pos="-0.10090289017159799 -0.031007024293265999 -0.068488107213796001"/>
      <site name="psoas_l_psoas_l-P1" pos="-0.059936435447940001 0.0627017451462 -0.043844979995700001"/>
      <site name="psoas_l_psoas_l-P2" pos="-0.02027552684295 -0.066140227944539998 -0.073749504813280006"/>
      <site name="PS_at_brim_l_cylinder_psoas_l_2_sidesite" pos="-0.03069 -0.08885 -0.08047" size="0.0005"/>
      <site name="recfem_l_recfem_l-P1" pos="-0.023737202157600001 -0.03923915663988 -0.10489068291279"/>
      <site name="sart_l_sart_l-P1" pos="-0.019286476753050001 -0.015776568133559998 -0.11871871506527999"/>
      <site name="semimem_l_semimem_l-P1" pos="-0.097619243873129993 -0.11529030559140001 -0.06902773773682"/>
      <site name="semiten_l_semiten_l-P1" pos="-0.10266339933162 -0.12671820430352998 -0.057897858199449995"/>
      <site name="tfl_l_tfl_l-P1" pos="-0.019781001797999999 0.0111245031711 -0.14502570306269999"/>
      <site name="LASI_marker" group="4" pos="0.02445 0.009665 -0.1432" rgba="1 0.1 0.5 0.5" size="0.01"/>
      <site name="RASI_marker" group="4" pos="0.02637 0.01142 0.1428" rgba="1 0.1 0.5 0.5" size="0.01"/>
      <site name="SACR_marker" group="4" pos="-0.1904 0.02374 0.001791" rgba="1 0.1 0.5 0.5" size="0.01"/>
    </body>
  </worldbody>
  <asset>
    <texture type="skybox" builtin="gradient" rgb1="1 1 1" rgb2="0.6 0.8 1" width="256" height="256"/>
    <mesh name="pelvis_geom_1_r_pelvis" file="Geometry/r_pelvis.stl" scale="0.98905008989999998 1.0113184701 1.1242302563"/>
    <mesh name="pelvis_geom_2_l_pelvis" file="Geometry/l_pelvis.stl" scale="0.98905008989999998 1.0113184701 1.1242302563"/>
    <mesh name="pelvis_geom_3_sacrum" file="Geometry/sacrum.stl" scale="0.98905008989999998 1.0113184701 1.1242302563"/>
    <mesh name="femur_r_geom_1_r_femur" file="Geometry/r_femur.stl" scale="0.94276897770000001 0.9397293619 0.96215546299999999"/>
    <mesh name="tibia_r_geom_1_r_tibia" file="Geometry/r_tibia.stl" scale="0.8950291561 0.90412815420000003 0.88282875760000001"/>
    <mesh name="tibia_r_geom_2_r_fibula" file="Geometry/r_fibula.stl" scale="0.8950291561 0.90412815420000003 0.88282875760000001"/>
    <mesh name="talus_r_geom_1_r_talus" file="Geometry/r_talus.stl" scale="1.1187850816 1.1686660952000001 1.1435667483"/>
    <mesh name="calcn_r_geom_1_r_foot" file="Geometry/r_foot.stl" scale="0.99360049500000003 0.99290139050000004 1.004787101"/>
    <mesh name="toes_r_geom_1_r_bofoot" file="Geometry/r_bofoot.stl" scale="0.99503736610000004 0.99429184770000001 0.99457778870000002"/>
    <mesh name="patella_r_geom_1_r_patella" file="Geometry/r_patella.stl" scale="1 1 1"/>
    <mesh name="femur_l_geom_1_l_femur" file="Geometry/l_femur.stl" scale="0.94276897770000001 0.9397293619 0.96215546299999999"/>
    <mesh name="tibia_l_geom_1_l_tibia" file="Geometry/l_tibia.stl" scale="0.8950291561 0.90412815420000003 0.88282875760000001"/>
    <mesh name="tibia_l_geom_2_l_fibula" file="Geometry/l_fibula.stl" scale="0.8950291561 0.90412815420000003 0.88282875760000001"/>
    <mesh name="talus_l_geom_1_l_talus" file="Geometry/l_talus.stl" scale="1.1187850816 1.1686660952000001 1.1435667483"/>
    <mesh name="calcn_l_geom_1_l_foot" file="Geometry/l_foot.stl" scale="0.99360049500000003 0.99290139050000004 1.004787101"/>
    <mesh name="toes_l_geom_1_l_bofoot" file="Geometry/l_bofoot.stl" scale="0.99503736610000004 0.99429184770000001 0.99457778870000002"/>
    <mesh name="patella_l_geom_1_l_patella" file="Geometry/l_patella.stl" scale="1 1 1"/>
    <mesh name="torso_geom_1_hat_spine" file="Geometry/hat_spine.stl" scale="1.1227755961000001 0.86796849760000006 1.0175567952"/>
    <mesh name="torso_geom_2_hat_jaw" file="Geometry/hat_jaw.stl" scale="1.1227755961000001 0.86796849760000006 1.0175567952"/>
    <mesh name="torso_geom_3_hat_skull" file="Geometry/hat_skull.stl" scale="1.1227755961000001 0.86796849760000006 1.0175567952"/>
    <mesh name="torso_geom_4_hat_ribs_scap" file="Geometry/hat_ribs_scap.stl" scale="1.1227755961000001 0.86796849760000006 1.0175567952"/>
  </asset>
  <tendon>
    <!-- Leave this comment here to make 'tendon' element pretty printed !-->
    <spatial name="addbrev_r_tendon">
      <site site="addbrev_r_addbrev_r-P1"/>
      <geom geom="AB_at_femshaft_r_cylinder" sidesite="AB_at_femshaft_r_cylinder_addbrev_r_1_sidesite"/>
      <site site="addbrev_r_addbrev_r-P2"/>
    </spatial>
    <spatial name="addlong_r_tendon">
      <site site="addlong_r_addlong_r-P1"/>
      <geom geom="AL_at_femshaft_r_cylinder" sidesite="AL_at_femshaft_r_cylinder_addlong_r_1_sidesite"/>
      <site site="addlong_r_addlong_r-P2"/>
    </spatial>
    <spatial name="addmagDist_r_tendon">
      <site site="addmagDist_r_addmagDist_r-P1"/>
      <geom geom="AMdist_at_femshaft_r_cylinder" sidesite="AMdist_at_femshaft_r_cylinder_addmagDist_r_1_sidesite"/>
      <site site="addmagDist_r_addmagDist_r-P2"/>
    </spatial>
    <spatial name="addmagIsch_r_tendon">
      <site site="addmagIsch_r_addmagIsch_r-P1"/>
      <geom geom="AMisch_at_condyles_r_cylinder" sidesite="AMisch_at_condyles_r_cylinder_addmagIsch_r_1_sidesite"/>
      <site site="addmagIsch_r_addmagIsch_r-P2"/>
    </spatial>
    <spatial name="addmagMid_r_tendon">
      <site site="addmagMid_r_addmagMid_r-P1"/>
      <geom geom="AMmid_at_femshaft_r_cylinder" sidesite="AMmid_at_femshaft_r_cylinder_addmagMid_r_1_sidesite"/>
      <site site="addmagMid_r_addmagMid_r-P2"/>
    </spatial>
    <spatial name="addmagProx_r_tendon">
      <site site="addmagProx_r_addmagProx_r-P1"/>
      <geom geom="AMprox_at_femshaft_r_cylinder" sidesite="AMprox_at_femshaft_r_cylinder_addmagProx_r_1_sidesite"/>
      <site site="addmagProx_r_addmagProx_r-P2"/>
    </spatial>
    <spatial name="bflh_r_tendon">
      <site site="bflh_r_bflh_r-P1"/>
      <site site="bflh_r_bflh_r-P2"/>
      <site site="bflh_r_bflh_r-P3"/>
    </spatial>
    <spatial name="bfsh_r_tendon">
      <site site="bfsh_r_bfsh_r-P1"/>
      <site site="bfsh_r_bfsh_r-P2"/>
    </spatial>
    <spatial name="edl_r_tendon">
      <site site="edl_r_edl_r-P1"/>
      <site site="edl_r_edl_r-P2"/>
      <site site="edl_r_edl_r-P3"/>
      <site site="edl_r_edl_r-P4"/>
      <site site="edl_r_edl_r-P5"/>
      <site site="edl_r_edl_r-P6"/>
    </spatial>
    <spatial name="ehl_r_tendon">
      <site site="ehl_r_ehl_r-P1"/>
      <site site="ehl_r_ehl_r-P2"/>
      <site site="ehl_r_ehl_r-P3"/>
      <site site="ehl_r_ehl_r-P4"/>
      <site site="ehl_r_ehl_r-P5"/>
      <site site="ehl_r_ehl_r-P6"/>
      <site site="ehl_r_ehl_r-P7"/>
      <site site="ehl_r_ehl_r-P8"/>
    </spatial>
    <spatial name="fdl_r_tendon">
      <site site="fdl_r_fdl_r-P1"/>
      <site site="fdl_r_fdl_r-P2"/>
      <site site="fdl_r_fdl_r-P3"/>
      <site site="fdl_r_fdl_r-P4"/>
      <site site="fdl_r_fdl_r-P5"/>
      <site site="fdl_r_fdl_r-P6"/>
      <site site="fdl_r_fdl_r-P7"/>
      <site site="fdl_r_fdl_r-P8"/>
    </spatial>
    <spatial name="fhl_r_tendon">
      <site site="fhl_r_fhl_r-P1"/>
      <site site="fhl_r_fhl_r-P2"/>
      <site site="fhl_r_fhl_r-P3"/>
      <site site="fhl_r_fhl_r-P4"/>
      <site site="fhl_r_fhl_r-P5"/>
      <site site="fhl_r_fhl_r-P6"/>
      <site site="fhl_r_fhl_r-P7"/>
    </spatial>
    <spatial name="gaslat_r_tendon">
      <site site="gaslat_r_gaslat_r-P1"/>
      <geom geom="Gastroc_at_condyles_r_cylinder" sidesite="Gastroc_at_condyles_r_cylinder_gaslat_r_1_sidesite"/>
      <site site="gaslat_r_gaslat_r-P2"/>
    </spatial>
    <spatial name="gasmed_r_tendon">
      <site site="gasmed_r_gasmed_r-P1"/>
      <geom geom="Gastroc_at_condyles_r_cylinder" sidesite="Gastroc_at_condyles_r_cylinder_gasmed_r_1_sidesite"/>
      <site site="gasmed_r_gasmed_r-P2"/>
    </spatial>
    <spatial name="glmax1_r_tendon">
      <site site="glmax1_r_glmax1_r-P1"/>
      <site site="glmax1_r_glmax1_r-P2"/>
      <geom geom="Gmax1_at_pelvis_r_cylinder" sidesite="Gmax1_at_pelvis_r_cylinder_glmax1_r_2_sidesite"/>
      <site site="glmax1_r_glmax1_r-P3"/>
      <site site="glmax1_r_glmax1_r-P4"/>
    </spatial>
    <spatial name="glmax2_r_tendon">
      <site site="glmax2_r_glmax2_r-P1"/>
      <geom geom="Gmax2_at_pelvis_r_cylinder" sidesite="Gmax2_at_pelvis_r_cylinder_glmax2_r_1_sidesite"/>
      <site site="glmax2_r_glmax2_r-P2"/>
      <geom geom="Gmax2_at_pelvis_r_cylinder" sidesite="Gmax2_at_pelvis_r_cylinder_glmax2_r_2_sidesite"/>
      <site site="glmax2_r_glmax2_r-P3"/>
      <site site="glmax2_r_glmax2_r-P4"/>
    </spatial>
    <spatial name="glmax3_r_tendon">
      <site site="glmax3_r_glmax3_r-P1"/>
      <site site="glmax3_r_glmax3_r-P2"/>
      <site site="glmax3_r_glmax3_r-P3"/>
      <site site="glmax3_r_glmax3_r-P4"/>
    </spatial>
    <spatial name="glmed1_r_tendon">
      <site site="glmed1_r_glmed1_r-P1"/>
      <site site="glmed1_r_glmed1_r-P2_0"/>
    </spatial>
    <spatial name="glmed2_r_tendon">
      <site site="glmed2_r_glmed2_r-P1"/>
      <site site="glmed2_r_glmed2_r-P2_0"/>
    </spatial>
    <spatial name="glmed3_r_tendon">
      <site site="glmed3_r_glmed3_r-P1"/>
      <site site="glmed3_r_glmed3_r-P2_0"/>
    </spatial>
    <spatial name="glmin1_r_tendon">
      <site site="glmin1_r_glmin1_r-P1"/>
      <site site="glmin1_r_glmin1_r-P2"/>
    </spatial>
    <spatial name="glmin2_r_tendon">
      <site site="glmin2_r_glmin2_r-P1"/>
      <site site="glmin2_r_glmin2_r-P2"/>
    </spatial>
    <spatial name="glmin3_r_tendon">
      <site site="glmin3_r_glmin3_r-P1"/>
      <site site="glmin3_r_glmin3_r-P2"/>
    </spatial>
    <spatial name="grac_r_tendon">
      <site site="grac_r_grac_r-P1"/>
      <geom geom="GR_at_condyles_r_cylinder" sidesite="GR_at_condyles_r_cylinder_grac_r_1_sidesite"/>
      <site site="grac_r_grac_r-P2"/>
      <site site="grac_r_grac_r-P3"/>
    </spatial>
    <spatial name="iliacus_r_tendon">
      <site site="iliacus_r_iliacus_r-P1"/>
      <site site="iliacus_r_iliacus_r-P2"/>
      <geom geom="IL_at_brim_r_cylinder" sidesite="IL_at_brim_r_cylinder_iliacus_r_2_sidesite"/>
      <site site="iliacus_r_iliacus_r-P3"/>
      <site site="iliacus_r_iliacus_r-P4"/>
    </spatial>
    <spatial name="perbrev_r_tendon">
      <site site="perbrev_r_perbrev_r-P1"/>
      <site site="perbrev_r_perbrev_r-P2"/>
      <site site="perbrev_r_perbrev_r-P3"/>
      <site site="perbrev_r_perbrev_r-P4"/>
      <site site="perbrev_r_perbrev_r-P5"/>
    </spatial>
    <spatial name="perlong_r_tendon">
      <site site="perlong_r_perlong_r-P1"/>
      <site site="perlong_r_perlong_r-P2"/>
      <site site="perlong_r_perlong_r-P3"/>
      <site site="perlong_r_perlong_r-P4"/>
      <site site="perlong_r_perlong_r-P5"/>
      <site site="perlong_r_perlong_r-P6"/>
      <site site="perlong_r_perlong_r-P7"/>
    </spatial>
    <spatial name="piri_r_tendon">
      <site site="piri_r_piri_r-P1"/>
      <site site="piri_r_piri_r-P2"/>
      <site site="piri_r_piri_r-P3"/>
    </spatial>
    <spatial name="psoas_r_tendon">
      <site site="psoas_r_psoas_r-P1"/>
      <site site="psoas_r_psoas_r-P2"/>
      <geom geom="PS_at_brim_r_cylinder" sidesite="PS_at_brim_r_cylinder_psoas_r_2_sidesite"/>
      <site site="psoas_r_psoas_r-P3"/>
      <site site="psoas_r_psoas_r-P4"/>
    </spatial>
    <spatial name="recfem_r_tendon">
      <site site="recfem_r_recfem_r-P1"/>
      <site site="recfem_r_recfem_r-P2"/>
      <site site="recfem_r_recfem_r-P3"/>
      <geom geom="KnExt_at_fem_r_cylinder" sidesite="KnExt_at_fem_r_cylinder_recfem_r_3_sidesite"/>
      <site site="recfem_r_recfem_r-P4"/>
      <site site="recfem_r_recfem_r-P5"/>
    </spatial>
    <spatial name="sart_r_tendon">
      <site site="sart_r_sart_r-P1"/>
      <site site="sart_r_sart_r-P2"/>
      <site site="sart_r_sart_r-P3"/>
      <site site="sart_r_sart_r-P4"/>
      <site site="sart_r_sart_r-P5"/>
    </spatial>
    <spatial name="semimem_r_tendon">
      <site site="semimem_r_semimem_r-P1"/>
      <geom geom="SM_at_condyles_r_cylinder" sidesite="SM_at_condyles_r_cylinder_semimem_r_1_sidesite"/>
      <site site="semimem_r_semimem_r-P2"/>
    </spatial>
    <spatial name="semiten_r_tendon">
      <site site="semiten_r_semiten_r-P1"/>
      <geom geom="ST_at_condyles_r_cylinder" sidesite="ST_at_condyles_r_cylinder_semiten_r_1_sidesite"/>
      <site site="semiten_r_semiten_r-P2"/>
      <site site="semiten_r_semiten_r-P3"/>
    </spatial>
    <spatial name="soleus_r_tendon">
      <site site="soleus_r_soleus_r-P1"/>
      <site site="soleus_r_soleus_r-P2"/>
    </spatial>
    <spatial name="tfl_r_tendon">
      <site site="tfl_r_tfl_r-P1"/>
      <site site="tfl_r_tfl_r-P2"/>
      <site site="tfl_r_tfl_r-P3"/>
      <site site="tfl_r_tfl_r-P4"/>
    </spatial>
    <spatial name="tibant_r_tendon">
      <site site="tibant_r_tibant_r-P1"/>
      <site site="tibant_r_tibant_r-P2"/>
      <site site="tibant_r_tibant_r-P3"/>
      <site site="tibant_r_tibant_r-P4"/>
    </spatial>
    <spatial name="tibpost_r_tendon">
      <site site="tibpost_r_tibpost_r-P1"/>
      <site site="tibpost_r_tibpost_r-P2"/>
      <site site="tibpost_r_tibpost_r-P3"/>
      <site site="tibpost_r_tibpost_r-P4"/>
    </spatial>
    <spatial name="vasint_r_tendon">
      <site site="vasint_r_vasint_r-P1"/>
      <site site="vasint_r_vasint_r-P2"/>
      <site site="vasint_r_vasint_r-P3"/>
      <geom geom="KnExt_at_fem_r_cylinder" sidesite="KnExt_at_fem_r_cylinder_vasint_r_3_sidesite"/>
      <site site="vasint_r_vasint_r-P4"/>
      <geom geom="KnExt_at_fem_r_cylinder" sidesite="KnExt_at_fem_r_cylinder_vasint_r_4_sidesite"/>
      <site site="vasint_r_vasint_r-P5"/>
    </spatial>
    <spatial name="vaslat_r_tendon">
      <site site="vaslat_r_vaslat_r-P1"/>
      <site site="vaslat_r_vaslat_r-P2"/>
      <site site="vaslat_r_vaslat_r-P3"/>
      <geom geom="KnExt_at_fem_r_cylinder" sidesite="KnExt_at_fem_r_cylinder_vaslat_r_3_sidesite"/>
      <site site="vaslat_r_vaslat_r-P4"/>
      <site site="vaslat_r_vaslat_r-P5"/>
    </spatial>
    <spatial name="vasmed_r_tendon">
      <site site="vasmed_r_vasmed_r-P1"/>
      <site site="vasmed_r_vasmed_r-P2"/>
      <site site="vasmed_r_vasmed_r-P3"/>
      <geom geom="KnExt_at_fem_r_cylinder" sidesite="KnExt_at_fem_r_cylinder_vasmed_r_3_sidesite"/>
      <site site="vasmed_r_vasmed_r-P4"/>
      <geom geom="KnExt_at_fem_r_cylinder" sidesite="KnExt_at_fem_r_cylinder_vasmed_r_4_sidesite"/>
      <site site="vasmed_r_vasmed_r-P5"/>
    </spatial>
    <spatial name="addbrev_l_tendon">
      <site site="addbrev_l_addbrev_l-P1"/>
      <geom geom="AB_at_femshaft_l_cylinder" sidesite="AB_at_femshaft_l_cylinder_addbrev_l_1_sidesite"/>
      <site site="addbrev_l_addbrev_l-P2"/>
    </spatial>
    <spatial name="addlong_l_tendon">
      <site site="addlong_l_addlong_l-P1"/>
      <geom geom="AL_at_femshaft_l_cylinder" sidesite="AL_at_femshaft_l_cylinder_addlong_l_1_sidesite"/>
      <site site="addlong_l_addlong_l-P2"/>
    </spatial>
    <spatial name="addmagDist_l_tendon">
      <site site="addmagDist_l_addmagDist_l-P1"/>
      <geom geom="AMdist_at_femshaft_l_cylinder" sidesite="AMdist_at_femshaft_l_cylinder_addmagDist_l_1_sidesite"/>
      <site site="addmagDist_l_addmagDist_l-P2"/>
    </spatial>
    <spatial name="addmagIsch_l_tendon">
      <site site="addmagIsch_l_addmagIsch_l-P1"/>
      <geom geom="AMisch_at_condyles_l_cylinder" sidesite="AMisch_at_condyles_l_cylinder_addmagIsch_l_1_sidesite"/>
      <site site="addmagIsch_l_addmagIsch_l-P2"/>
    </spatial>
    <spatial name="addmagMid_l_tendon">
      <site site="addmagMid_l_addmagMid_l-P1"/>
      <geom geom="AMmid_at_femshaft_l_cylinder" sidesite="AMmid_at_femshaft_l_cylinder_addmagMid_l_1_sidesite"/>
      <site site="addmagMid_l_addmagMid_l-P2"/>
    </spatial>
    <spatial name="addmagProx_l_tendon">
      <site site="addmagProx_l_addmagProx_l-P1"/>
      <geom geom="AMprox_at_femshaft_l_cylinder" sidesite="AMprox_at_femshaft_l_cylinder_addmagProx_l_1_sidesite"/>
      <site site="addmagProx_l_addmagProx_l-P2"/>
    </spatial>
    <spatial name="bflh_l_tendon">
      <site site="bflh_l_bflh_l-P1"/>
      <site site="bflh_l_bflh_l-P2"/>
      <site site="bflh_l_bflh_l-P3"/>
    </spatial>
    <spatial name="bfsh_l_tendon">
      <site site="bfsh_l_bfsh_l-P1"/>
      <site site="bfsh_l_bfsh_l-P2"/>
    </spatial>
    <spatial name="edl_l_tendon">
      <site site="edl_l_edl_l-P1"/>
      <site site="edl_l_edl_l-P2"/>
      <site site="edl_l_edl_l-P3"/>
      <site site="edl_l_edl_l-P4"/>
      <site site="edl_l_edl_l-P5"/>
      <site site="edl_l_edl_l-P6"/>
    </spatial>
    <spatial name="ehl_l_tendon">
      <site site="ehl_l_ehl_l-P1"/>
      <site site="ehl_l_ehl_l-P2"/>
      <site site="ehl_l_ehl_l-P3"/>
      <site site="ehl_l_ehl_l-P4"/>
      <site site="ehl_l_ehl_l-P5"/>
      <site site="ehl_l_ehl_l-P6"/>
      <site site="ehl_l_ehl_l-P7"/>
      <site site="ehl_l_ehl_l-P8"/>
    </spatial>
    <spatial name="fdl_l_tendon">
      <site site="fdl_l_fdl_l-P1"/>
      <site site="fdl_l_fdl_l-P2"/>
      <site site="fdl_l_fdl_l-P3"/>
      <site site="fdl_l_fdl_l-P4"/>
      <site site="fdl_l_fdl_l-P5"/>
      <site site="fdl_l_fdl_l-P6"/>
      <site site="fdl_l_fdl_l-P7"/>
      <site site="fdl_l_fdl_l-P8"/>
    </spatial>
    <spatial name="fhl_l_tendon">
      <site site="fhl_l_fhl_l-P1"/>
      <site site="fhl_l_fhl_l-P2"/>
      <site site="fhl_l_fhl_l-P3"/>
      <site site="fhl_l_fhl_l-P4"/>
      <site site="fhl_l_fhl_l-P5"/>
      <site site="fhl_l_fhl_l-P6"/>
      <site site="fhl_l_fhl_l-P7"/>
    </spatial>
    <spatial name="gaslat_l_tendon">
      <site site="gaslat_l_gaslat_l-P1"/>
      <geom geom="Gastroc_at_condyles_l_cylinder" sidesite="Gastroc_at_condyles_l_cylinder_gaslat_l_1_sidesite"/>
      <site site="gaslat_l_gaslat_l-P2"/>
    </spatial>
    <spatial name="gasmed_l_tendon">
      <site site="gasmed_l_gasmed_l-P1"/>
      <geom geom="Gastroc_at_condyles_l_cylinder" sidesite="Gastroc_at_condyles_l_cylinder_gasmed_l_1_sidesite"/>
      <site site="gasmed_l_gasmed_l-P2"/>
    </spatial>
    <spatial name="glmax1_l_tendon">
      <site site="glmax1_l_glmax1_l-P1"/>
      <site site="glmax1_l_glmax1_l-P2"/>
      <geom geom="Gmax1_at_pelvis_l_cylinder" sidesite="Gmax1_at_pelvis_l_cylinder_glmax1_l_2_sidesite"/>
      <site site="glmax1_l_glmax1_l-P3"/>
      <site site="glmax1_l_glmax1_l-P4"/>
    </spatial>
    <spatial name="glmax2_l_tendon">
      <site site="glmax2_l_glmax2_l-P1"/>
      <geom geom="Gmax2_at_pelvis_l_cylinder" sidesite="Gmax2_at_pelvis_l_cylinder_glmax2_l_1_sidesite"/>
      <site site="glmax2_l_glmax2_l-P2"/>
      <geom geom="Gmax2_at_pelvis_l_cylinder" sidesite="Gmax2_at_pelvis_l_cylinder_glmax2_l_2_sidesite"/>
      <site site="glmax2_l_glmax2_l-P3"/>
      <site site="glmax2_l_glmax2_l-P4"/>
    </spatial>
    <spatial name="glmax3_l_tendon">
      <site site="glmax3_l_glmax3_l-P1"/>
      <site site="glmax3_l_glmax3_l-P2"/>
      <site site="glmax3_l_glmax3_l-P3"/>
      <site site="glmax3_l_glmax3_l-P4"/>
    </spatial>
    <spatial name="glmed1_l_tendon">
      <site site="glmed1_l_glmed1_l-P1"/>
      <site site="glmed1_l_glmed1_l-P2"/>
    </spatial>
    <spatial name="glmed2_l_tendon">
      <site site="glmed2_l_glmed2_l-P1"/>
      <site site="glmed2_l_glmed2_l-P2"/>
    </spatial>
    <spatial name="glmed3_l_tendon">
      <site site="glmed3_l_glmed3_l-P1"/>
      <site site="glmed3_l_glmed3_l-P2"/>
    </spatial>
    <spatial name="glmin1_l_tendon">
      <site site="glmin1_l_glmin1_l-P1"/>
      <site site="glmin1_l_glmin1_l-P2"/>
    </spatial>
    <spatial name="glmin2_l_tendon">
      <site site="glmin2_l_glmin2_l-P1"/>
      <site site="glmin2_l_glmin2_l-P2"/>
    </spatial>
    <spatial name="glmin3_l_tendon">
      <site site="glmin3_l_glmin3_l-P1"/>
      <site site="glmin3_l_glmin3_l-P2"/>
    </spatial>
    <spatial name="grac_l_tendon">
      <site site="grac_l_grac_l-P1"/>
      <geom geom="GR_at_condyles_l_cylinder" sidesite="GR_at_condyles_l_cylinder_grac_l_1_sidesite"/>
      <site site="grac_l_grac_l-P2"/>
      <site site="grac_l_grac_l-P3"/>
    </spatial>
    <spatial name="iliacus_l_tendon">
      <site site="iliacus_l_iliacus_l-P1"/>
      <site site="iliacus_l_iliacus_l-P2"/>
      <geom geom="IL_at_brim_l_cylinder" sidesite="IL_at_brim_l_cylinder_iliacus_l_2_sidesite"/>
      <site site="iliacus_l_iliacus_l-P3"/>
      <site site="iliacus_l_iliacus_l-P4"/>
    </spatial>
    <spatial name="perbrev_l_tendon">
      <site site="perbrev_l_perbrev_l-P1"/>
      <site site="perbrev_l_perbrev_l-P2"/>
      <site site="perbrev_l_perbrev_l-P3"/>
      <site site="perbrev_l_perbrev_l-P4"/>
      <site site="perbrev_l_perbrev_l-P5"/>
    </spatial>
    <spatial name="perlong_l_tendon">
      <site site="perlong_l_perlong_l-P1"/>
      <site site="perlong_l_perlong_l-P2"/>
      <site site="perlong_l_perlong_l-P3"/>
      <site site="perlong_l_perlong_l-P4"/>
      <site site="perlong_l_perlong_l-P5"/>
      <site site="perlong_l_perlong_l-P6"/>
      <site site="perlong_l_perlong_l-P7"/>
    </spatial>
    <spatial name="piri_l_tendon">
      <site site="piri_l_piri_l-P1"/>
      <site site="piri_l_piri_l-P2"/>
      <site site="piri_l_piri_l-P3"/>
    </spatial>
    <spatial name="psoas_l_tendon">
      <site site="psoas_l_psoas_l-P1"/>
      <site site="psoas_l_psoas_l-P2"/>
      <geom geom="PS_at_brim_l_cylinder" sidesite="PS_at_brim_l_cylinder_psoas_l_2_sidesite"/>
      <site site="psoas_l_psoas_l-P3"/>
      <site site="psoas_l_psoas_l-P4"/>
    </spatial>
    <spatial name="recfem_l_tendon">
      <site site="recfem_l_recfem_l-P1"/>
      <site site="recfem_l_recfem_l-P2"/>
      <site site="recfem_l_recfem_l-P3"/>
      <geom geom="KnExt_at_fem_l_cylinder" sidesite="KnExt_at_fem_l_cylinder_recfem_l_3_sidesite"/>
      <site site="recfem_l_recfem_l-P4"/>
      <site site="recfem_l_recfem_l-P5"/>
    </spatial>
    <spatial name="sart_l_tendon">
      <site site="sart_l_sart_l-P1"/>
      <site site="sart_l_sart_l-P2"/>
      <site site="sart_l_sart_l-P3"/>
      <site site="sart_l_sart_l-P4"/>
      <site site="sart_l_sart_l-P5"/>
    </spatial>
    <spatial name="semimem_l_tendon">
      <site site="semimem_l_semimem_l-P1"/>
      <geom geom="SM_at_condyles_l_cylinder" sidesite="SM_at_condyles_l_cylinder_semimem_l_1_sidesite"/>
      <site site="semimem_l_semimem_l-P2"/>
    </spatial>
    <spatial name="semiten_l_tendon">
      <site site="semiten_l_semiten_l-P1"/>
      <geom geom="ST_at_condyles_l_cylinder" sidesite="ST_at_condyles_l_cylinder_semiten_l_1_sidesite"/>
      <site site="semiten_l_semiten_l-P2"/>
      <site site="semiten_l_semiten_l-P3"/>
    </spatial>
    <spatial name="soleus_l_tendon">
      <site site="soleus_l_soleus_l-P1"/>
      <site site="soleus_l_soleus_l-P2"/>
    </spatial>
    <spatial name="tfl_l_tendon">
      <site site="tfl_l_tfl_l-P1"/>
      <site site="tfl_l_tfl_l-P2"/>
      <site site="tfl_l_tfl_l-P3"/>
      <site site="tfl_l_tfl_l-P4"/>
    </spatial>
    <spatial name="tibant_l_tendon">
      <site site="tibant_l_tibant_l-P1"/>
      <site site="tibant_l_tibant_l-P2"/>
      <site site="tibant_l_tibant_l-P3"/>
      <site site="tibant_l_tibant_l-P4"/>
    </spatial>
    <spatial name="tibpost_l_tendon">
      <site site="tibpost_l_tibpost_l-P1"/>
      <site site="tibpost_l_tibpost_l-P2"/>
      <site site="tibpost_l_tibpost_l-P3"/>
      <site site="tibpost_l_tibpost_l-P4"/>
    </spatial>
    <spatial name="vasint_l_tendon">
      <site site="vasint_l_vasint_l-P1"/>
      <site site="vasint_l_vasint_l-P2"/>
      <site site="vasint_l_vasint_l-P3"/>
      <geom geom="KnExt_at_fem_l_cylinder" sidesite="KnExt_at_fem_l_cylinder_vasint_l_3_sidesite"/>
      <site site="vasint_l_vasint_l-P4"/>
      <geom geom="KnExt_at_fem_l_cylinder" sidesite="KnExt_at_fem_l_cylinder_vasint_l_4_sidesite"/>
      <site site="vasint_l_vasint_l-P5"/>
    </spatial>
    <spatial name="vaslat_l_tendon">
      <site site="vaslat_l_vaslat_l-P1"/>
      <site site="vaslat_l_vaslat_l-P2"/>
      <site site="vaslat_l_vaslat_l-P3"/>
      <geom geom="KnExt_at_fem_l_cylinder" sidesite="KnExt_at_fem_l_cylinder_vaslat_l_3_sidesite"/>
      <site site="vaslat_l_vaslat_l-P4"/>
      <site site="vaslat_l_vaslat_l-P5"/>
    </spatial>
    <spatial name="vasmed_l_tendon">
      <site site="vasmed_l_vasmed_l-P1"/>
      <site site="vasmed_l_vasmed_l-P2"/>
      <site site="vasmed_l_vasmed_l-P3"/>
      <geom geom="KnExt_at_fem_l_cylinder" sidesite="KnExt_at_fem_l_cylinder_vasmed_l_3_sidesite"/>
      <site site="vasmed_l_vasmed_l-P4"/>
      <geom geom="KnExt_at_fem_l_cylinder" sidesite="KnExt_at_fem_l_cylinder_vasmed_l_4_sidesite"/>
      <site site="vasmed_l_vasmed_l-P5"/>
    </spatial>
  </tendon>
  <actuator>
    <!-- Leave this comment here to make 'actuator' element pretty printed !-->
    <motor name="lumbar_ext" ctrllimited="false" joint="lumbar_extension" class="motor"/>
    <motor name="lumbar_bend" ctrllimited="false" joint="lumbar_bending" class="motor"/>
    <motor name="lumbar_rot" ctrllimited="false" joint="lumbar_rotation" class="motor"/>
    <muscle name="addbrev_r" lengthrange="0.01 1" force="625.81967213114797" tendon="addbrev_r_tendon" class="muscle" timeconst="0.01 0.04"/>
    <muscle name="addlong_r" lengthrange="0.01 1" force="916.79999999999995" tendon="addlong_r_tendon" class="muscle" timeconst="0.01 0.04"/>
    <muscle name="addmagDist_r" lengthrange="0.01 1" force="597.29508196721395" tendon="addmagDist_r_tendon" class="muscle" timeconst="0.01 0.04"/>
    <muscle name="addmagIsch_r" lengthrange="0.01 1" force="597.29508196721395" tendon="addmagIsch_r_tendon" class="muscle" timeconst="0.01 0.04"/>
    <muscle name="addmagMid_r" lengthrange="0.01 1" force="597.29508196721395" tendon="addmagMid_r_tendon" class="muscle" timeconst="0.01 0.04"/>
    <muscle name="addmagProx_r" lengthrange="0.01 1" force="597.29508196721395" tendon="addmagProx_r_tendon" class="muscle" timeconst="0.01 0.04"/>
    <muscle name="bflh_r" lengthrange="0.01 1" force="1313.18360655738" tendon="bflh_r_tendon" class="muscle" timeconst="0.01 0.04"/>
    <muscle name="bfsh_r" lengthrange="0.01 1" force="557.11475409835998" tendon="bfsh_r_tendon" class="muscle" timeconst="0.01 0.04"/>
    <muscle name="edl_r" lengthrange="0.01 1" force="603.49815560000002" tendon="edl_r_tendon" class="muscle" timeconst="0.01 0.04"/>
    <muscle name="ehl_r" lengthrange="0.01 1" force="285.86754739999998" tendon="ehl_r_tendon" class="muscle" timeconst="0.01 0.04"/>
    <muscle name="fdl_r" lengthrange="0.01 1" force="423.17704918032803" tendon="fdl_r_tendon" class="muscle" timeconst="0.01 0.04"/>
    <muscle name="fhl_r" lengthrange="0.01 1" force="907.83934426229405" tendon="fhl_r_tendon" class="muscle" timeconst="0.01 0.04"/>
    <muscle name="gaslat_r" lengthrange="0.01 1" force="1575.0590163934401" tendon="gaslat_r_tendon" class="muscle" timeconst="0.01 0.04"/>
    <muscle name="gasmed_r" lengthrange="0.01 1" force="3115.5147540983598" tendon="gasmed_r_tendon" class="muscle" timeconst="0.01 0.04"/>
    <muscle name="glmax1_r" lengthrange="0.01 1" force="983.78360655737799" tendon="glmax1_r_tendon" class="muscle" timeconst="0.01 0.04"/>
    <muscle name="glmax2_r" lengthrange="0.01 1" force="1406.0459016393499" tendon="glmax2_r_tendon" class="muscle" timeconst="0.01 0.04"/>
    <muscle name="glmax3_r" lengthrange="0.01 1" force="947.75409836065603" tendon="glmax3_r_tendon" class="muscle" timeconst="0.01 0.04"/>
    <muscle name="glmed1_r" lengthrange="0.01 1" force="1093.4667688" tendon="glmed1_r_tendon" class="muscle" timeconst="0.01 0.04"/>
    <muscle name="glmed2_r" lengthrange="0.01 1" force="765.09166159999995" tendon="glmed2_r_tendon" class="muscle" timeconst="0.01 0.04"/>
    <muscle name="glmed3_r" lengthrange="0.01 1" force="871.19926420000002" tendon="glmed3_r_tendon" class="muscle" timeconst="0.01 0.04"/>
    <muscle name="glmin1_r" lengthrange="0.01 1" force="374.04590163934398" tendon="glmin1_r_tendon" class="muscle" timeconst="0.01 0.04"/>
    <muscle name="glmin2_r" lengthrange="0.01 1" force="394.81967213114802" tendon="glmin2_r_tendon" class="muscle" timeconst="0.01 0.04"/>
    <muscle name="glmin3_r" lengthrange="0.01 1" force="446.77377049180399" tendon="glmin3_r_tendon" class="muscle" timeconst="0.01 0.04"/>
    <muscle name="grac_r" lengthrange="0.01 1" force="281.31147540983602" tendon="grac_r_tendon" class="muscle" timeconst="0.01 0.04"/>
    <muscle name="iliacus_r" lengthrange="0.01 1" force="1021.14098360656" tendon="iliacus_r_tendon" class="muscle" timeconst="0.01 0.04"/>
    <muscle name="perbrev_r" lengthrange="0.01 1" force="521.20159880000006" tendon="perbrev_r_tendon" class="muscle" timeconst="0.01 0.04"/>
    <muscle name="perlong_r" lengthrange="0.01 1" force="1115.3714213999999" tendon="perlong_r_tendon" class="muscle" timeconst="0.01 0.04"/>
    <muscle name="piri_r" lengthrange="0.01 1" force="1029.7868852459001" tendon="piri_r_tendon" class="muscle" timeconst="0.01 0.04"/>
    <muscle name="psoas_r" lengthrange="0.01 1" force="1426.79016393443" tendon="psoas_r_tendon" class="muscle" timeconst="0.01 0.04"/>
    <muscle name="recfem_r" lengthrange="0.01 1" force="2191.7409836065599" tendon="recfem_r_tendon" class="muscle" timeconst="0.01 0.04"/>
    <muscle name="sart_r" lengthrange="0.01 1" force="249.41311475409799" tendon="sart_r_tendon" class="muscle" timeconst="0.01 0.04"/>
    <muscle name="semimem_r" lengthrange="0.01 1" force="2200.9868852458999" tendon="semimem_r_tendon" class="muscle" timeconst="0.01 0.04"/>
    <muscle name="semiten_r" lengthrange="0.01 1" force="591.29508196721395" tendon="semiten_r_tendon" class="muscle" timeconst="0.01 0.04"/>
    <muscle name="soleus_r" lengthrange="0.01 1" force="6194.8426229508204" tendon="soleus_r_tendon" class="muscle" timeconst="0.01 0.04"/>
    <muscle name="tfl_r" lengthrange="0.01 1" force="411.20655737704999" tendon="tfl_r_tendon" class="muscle" timeconst="0.01 0.04"/>
    <muscle name="tibant_r" lengthrange="0.01 1" force="1227.4524590163901" tendon="tibant_r_tendon" class="muscle" timeconst="0.01 0.04"/>
    <muscle name="tibpost_r" lengthrange="0.01 1" force="1730.1540983606501" tendon="tibpost_r_tendon" class="muscle" timeconst="0.01 0.04"/>
    <muscle name="vasint_r" lengthrange="0.01 1" force="1697.36065573771" tendon="vasint_r_tendon" class="muscle" timeconst="0.01 0.04"/>
    <muscle name="vaslat_r" lengthrange="0.01 1" force="5148.7672131147601" tendon="vaslat_r_tendon" class="muscle" timeconst="0.01 0.04"/>
    <muscle name="vasmed_r" lengthrange="0.01 1" force="2747.82295081966" tendon="vasmed_r_tendon" class="muscle" timeconst="0.01 0.04"/>
    <muscle name="addbrev_l" lengthrange="0.01 1" force="625.81967213114797" tendon="addbrev_l_tendon" class="muscle" timeconst="0.01 0.04"/>
    <muscle name="addlong_l" lengthrange="0.01 1" force="916.79999999999995" tendon="addlong_l_tendon" class="muscle" timeconst="0.01 0.04"/>
    <muscle name="addmagDist_l" lengthrange="0.01 1" force="597.29508196721395" tendon="addmagDist_l_tendon" class="muscle" timeconst="0.01 0.04"/>
    <muscle name="addmagIsch_l" lengthrange="0.01 1" force="597.29508196721395" tendon="addmagIsch_l_tendon" class="muscle" timeconst="0.01 0.04"/>
    <muscle name="addmagMid_l" lengthrange="0.01 1" force="597.29508196721395" tendon="addmagMid_l_tendon" class="muscle" timeconst="0.01 0.04"/>
    <muscle name="addmagProx_l" lengthrange="0.01 1" force="597.29508196721395" tendon="addmagProx_l_tendon" class="muscle" timeconst="0.01 0.04"/>
    <muscle name="bflh_l" lengthrange="0.01 1" force="1313.18360655738" tendon="bflh_l_tendon" class="muscle" timeconst="0.01 0.04"/>
    <muscle name="bfsh_l" lengthrange="0.01 1" force="557.11475409835998" tendon="bfsh_l_tendon" class="muscle" timeconst="0.01 0.04"/>
    <muscle name="edl_l" lengthrange="0.01 1" force="603.49815560000002" tendon="edl_l_tendon" class="muscle" timeconst="0.01 0.04"/>
    <muscle name="ehl_l" lengthrange="0.01 1" force="285.86754739999998" tendon="ehl_l_tendon" class="muscle" timeconst="0.01 0.04"/>
    <muscle name="fdl_l" lengthrange="0.01 1" force="423.17704918032803" tendon="fdl_l_tendon" class="muscle" timeconst="0.01 0.04"/>
    <muscle name="fhl_l" lengthrange="0.01 1" force="907.83934426229405" tendon="fhl_l_tendon" class="muscle" timeconst="0.01 0.04"/>
    <muscle name="gaslat_l" lengthrange="0.01 1" force="1575.0590163934401" tendon="gaslat_l_tendon" class="muscle" timeconst="0.01 0.04"/>
    <muscle name="gasmed_l" lengthrange="0.01 1" force="3115.5147540983598" tendon="gasmed_l_tendon" class="muscle" timeconst="0.01 0.04"/>
    <muscle name="glmax1_l" lengthrange="0.01 1" force="983.78360655737799" tendon="glmax1_l_tendon" class="muscle" timeconst="0.01 0.04"/>
    <muscle name="glmax2_l" lengthrange="0.01 1" force="1406.0459016393499" tendon="glmax2_l_tendon" class="muscle" timeconst="0.01 0.04"/>
    <muscle name="glmax3_l" lengthrange="0.01 1" force="947.75409836065603" tendon="glmax3_l_tendon" class="muscle" timeconst="0.01 0.04"/>
    <muscle name="glmed1_l" lengthrange="0.01 1" force="1093.4667688" tendon="glmed1_l_tendon" class="muscle" timeconst="0.01 0.04"/>
    <muscle name="glmed2_l" lengthrange="0.01 1" force="765.09166159999995" tendon="glmed2_l_tendon" class="muscle" timeconst="0.01 0.04"/>
    <muscle name="glmed3_l" lengthrange="0.01 1" force="871.19926420000002" tendon="glmed3_l_tendon" class="muscle" timeconst="0.01 0.04"/>
    <muscle name="glmin1_l" lengthrange="0.01 1" force="374.04590163934398" tendon="glmin1_l_tendon" class="muscle" timeconst="0.01 0.04"/>
    <muscle name="glmin2_l" lengthrange="0.01 1" force="394.81967213114802" tendon="glmin2_l_tendon" class="muscle" timeconst="0.01 0.04"/>
    <muscle name="glmin3_l" lengthrange="0.01 1" force="446.77377049180399" tendon="glmin3_l_tendon" class="muscle" timeconst="0.01 0.04"/>
    <muscle name="grac_l" lengthrange="0.01 1" force="281.31147540983602" tendon="grac_l_tendon" class="muscle" timeconst="0.01 0.04"/>
    <muscle name="iliacus_l" lengthrange="0.01 1" force="1021.14098360656" tendon="iliacus_l_tendon" class="muscle" timeconst="0.01 0.04"/>
    <muscle name="perbrev_l" lengthrange="0.01 1" force="521.20159880000006" tendon="perbrev_l_tendon" class="muscle" timeconst="0.01 0.04"/>
    <muscle name="perlong_l" lengthrange="0.01 1" force="1115.3714213999999" tendon="perlong_l_tendon" class="muscle" timeconst="0.01 0.04"/>
    <muscle name="piri_l" lengthrange="0.01 1" force="1029.7868852459001" tendon="piri_l_tendon" class="muscle" timeconst="0.01 0.04"/>
    <muscle name="psoas_l" lengthrange="0.01 1" force="1426.79016393443" tendon="psoas_l_tendon" class="muscle" timeconst="0.01 0.04"/>
    <muscle name="recfem_l" lengthrange="0.01 1" force="2191.7409836065599" tendon="recfem_l_tendon" class="muscle" timeconst="0.01 0.04"/>
    <muscle name="sart_l" lengthrange="0.01 1" force="249.41311475409799" tendon="sart_l_tendon" class="muscle" timeconst="0.01 0.04"/>
    <muscle name="semimem_l" lengthrange="0.01 1" force="2200.9868852458999" tendon="semimem_l_tendon" class="muscle" timeconst="0.01 0.04"/>
    <muscle name="semiten_l" lengthrange="0.01 1" force="591.29508196721395" tendon="semiten_l_tendon" class="muscle" timeconst="0.01 0.04"/>
    <muscle name="soleus_l" lengthrange="0.01 1" force="6194.8426229508204" tendon="soleus_l_tendon" class="muscle" timeconst="0.01 0.04"/>
    <muscle name="tfl_l" lengthrange="0.01 1" force="411.20655737704999" tendon="tfl_l_tendon" class="muscle" timeconst="0.01 0.04"/>
    <muscle name="tibant_l" lengthrange="0.01 1" force="1227.4524590163901" tendon="tibant_l_tendon" class="muscle" timeconst="0.01 0.04"/>
    <muscle name="tibpost_l" lengthrange="0.01 1" force="1730.1540983606501" tendon="tibpost_l_tendon" class="muscle" timeconst="0.01 0.04"/>
    <muscle name="vasint_l" lengthrange="0.01 1" force="1697.36065573771" tendon="vasint_l_tendon" class="muscle" timeconst="0.01 0.04"/>
    <muscle name="vaslat_l" lengthrange="0.01 1" force="5148.7672131147601" tendon="vaslat_l_tendon" class="muscle" timeconst="0.01 0.04"/>
    <muscle name="vasmed_l" lengthrange="0.01 1" force="2747.82295081966" tendon="vasmed_l_tendon" class="muscle" timeconst="0.01 0.04"/>
  </actuator>
  <equality>
    <!-- Leave this comment here to make 'equality' element pretty printed !-->
    <joint joint1="walker_knee_r_translation1" joint2="knee_angle_r" polycoef="8.963e-08 0.00294 -0.002169 0.0005277 5.341e-07" solimp="0.9999 0.9999 0.001 0.5 2" active="true"/>
    <joint joint1="walker_knee_r_translation2" joint2="knee_angle_r" polycoef="7.401e-11 0.005657 -0.001209 -2.519e-06 6.007e-07" solimp="0.9999 0.9999 0.001 0.5 2" active="true"/>
    <joint joint1="walker_knee_r_rotation2" joint2="knee_angle_r" polycoef="-1.473e-08 0.0791 -0.03285 -0.02522 0.01083" solimp="0.9999 0.9999 0.001 0.5 2" active="true"/>
    <joint joint1="walker_knee_r_rotation3" joint2="knee_angle_r" polycoef="1.089e-08 0.3695 -0.1695 0.02516 3.505e-07" solimp="0.9999 0.9999 0.001 0.5 2" active="true"/>
    <joint name="mtp_angle_r_locked" active="true" joint1="mtp_angle_r" polycoef="0.0 0 0 0 0" solimp="0.9999 0.9999 0.001 0.5 2"/>
    <joint joint1="patellofemoral_r_translation1" joint2="knee_angle_r" polycoef="0.04942 -0.01416 -0.0321 0.01258 -0.0008288" solimp="0.9999 0.9999 0.001 0.5 2" active="true"/>
    <joint joint1="patellofemoral_r_translation2" joint2="knee_angle_r" polycoef="-0.01018 -0.04584 0.008717 0.01237 -0.003286" solimp="0.9999 0.9999 0.001 0.5 2" active="true"/>
    <joint joint1="patellofemoral_r_rotation1" joint2="knee_angle_r" polycoef="0.01051 0.02476 -1.316 0.7163 -0.1383" solimp="0.9999 0.9999 0.001 0.5 2" active="true"/>
    <joint name="patellofemoral_r_translation3_locked" active="true" joint1="patellofemoral_r_translation3" polycoef="0.00264592752325 0 0 0 0" solimp="0.9999 0.9999 0.001 0.5 2"/>
    <joint joint1="walker_knee_l_translation1" joint2="knee_angle_l" polycoef="8.963e-08 0.00294 -0.002169 0.0005277 5.341e-07" solimp="0.9999 0.9999 0.001 0.5 2" active="true"/>
    <joint joint1="walker_knee_l_translation2" joint2="knee_angle_l" polycoef="-7.401e-11 -0.005657 0.001209 2.519e-06 -6.007e-07" solimp="0.9999 0.9999 0.001 0.5 2" active="true"/>
    <joint joint1="walker_knee_l_rotation2" joint2="knee_angle_l" polycoef="-1.473e-08 0.0791 -0.03285 -0.02522 0.01083" solimp="0.9999 0.9999 0.001 0.5 2" active="true"/>
    <joint joint1="walker_knee_l_rotation3" joint2="knee_angle_l" polycoef="-1.089e-08 -0.3695 0.1695 -0.02516 -3.505e-07" solimp="0.9999 0.9999 0.001 0.5 2" active="true"/>
    <joint name="mtp_angle_l_locked" active="true" joint1="mtp_angle_l" polycoef="0.0 0 0 0 0" solimp="0.9999 0.9999 0.001 0.5 2"/>
    <joint joint1="patellofemoral_l_translation1" joint2="knee_angle_l" polycoef="0.04942 -0.01416 -0.0321 0.01258 -0.0008288" solimp="0.9999 0.9999 0.001 0.5 2" active="true"/>
    <joint joint1="patellofemoral_l_translation2" joint2="knee_angle_l" polycoef="-0.01018 -0.04584 0.008717 0.01237 -0.003286" solimp="0.9999 0.9999 0.001 0.5 2" active="true"/>
    <joint joint1="patellofemoral_l_rotation1" joint2="knee_angle_l" polycoef="0.01051 0.02476 -1.316 0.7163 -0.1383" solimp="0.9999 0.9999 0.001 0.5 2" active="true"/>
    <joint name="patellofemoral_l_translation3_locked" active="true" joint1="patellofemoral_l_translation3" polycoef="-0.00264592752325 0 0 0 0" solimp="0.9999 0.9999 0.001 0.5 2"/>
  </equality>
  <contact>
    <!-- Leave this comment here to make 'contact' element pretty printed !-->
    <pair geom1="ground-plane" geom2="pelvis_geom_1"/>
    <pair geom1="ground-plane" geom2="pelvis_geom_2"/>
    <pair geom1="ground-plane" geom2="pelvis_geom_3"/>
    <pair geom1="ground-plane" geom2="femur_r_geom_1"/>
    <pair geom1="ground-plane" geom2="tibia_r_geom_1"/>
    <pair geom1="ground-plane" geom2="tibia_r_geom_2"/>
    <pair geom1="ground-plane" geom2="talus_r_geom_1"/>
    <pair geom1="ground-plane" geom2="calcn_r_geom_1"/>
    <pair geom1="ground-plane" geom2="toes_r_geom_1"/>
    <pair geom1="ground-plane" geom2="patella_r_geom_1"/>
    <pair geom1="ground-plane" geom2="femur_l_geom_1"/>
    <pair geom1="ground-plane" geom2="tibia_l_geom_1"/>
    <pair geom1="ground-plane" geom2="tibia_l_geom_2"/>
    <pair geom1="ground-plane" geom2="talus_l_geom_1"/>
    <pair geom1="ground-plane" geom2="calcn_l_geom_1"/>
    <pair geom1="ground-plane" geom2="toes_l_geom_1"/>
    <pair geom1="ground-plane" geom2="patella_l_geom_1"/>
    <pair geom1="ground-plane" geom2="torso_geom_1"/>
    <pair geom1="ground-plane" geom2="torso_geom_2"/>
    <pair geom1="ground-plane" geom2="torso_geom_3"/>
    <pair geom1="ground-plane" geom2="torso_geom_4"/>
  </contact>
  <keyframe>
    <key name="default-pose" qpos="0 0.93 0 0 0 0 0 0 0 8.963e-08 7.401e-11 0 -1.473e-08 1.089e-08 0 0 0 0.04942 -0.01018 0.002646 0.01051 0 -0 -0 8.963e-08 -7.401e-11 0 -1.473e-08 -1.089e-08 0 0 0 0.04942 -0.01018 -0.002646 0.01051 0 0 0"/>
  </keyframe>
</mujoco>
