<mujoco model="template">
  <!-- This model has been converted from an OpenSim model. Model conversion by MyoConverter https://github.com/MyoHub/myoconverter. This model is licensed under Apache 2.0. -->
  <!-- Note: inertiagrouprange="0 1" means that groups 0-1 will be used to infer masses/inertias, and groups 2-5 are
  only for visualisation (e.g. wrapping objects) !-->
  <compiler inertiafromgeom="auto" angle="radian" balanceinertia="true" boundmass="0.001" boundinertia="0.001" inertiagrouprange="0 1">
    <lengthrange inttotal="50" useexisting="true"/>
  </compiler>
  <option/>
  <visual>
    <scale framelength="0.5" framewidth="0.01"/>
  </visual>
  <default>
    <joint limited="true" damping="0.05" armature="0.00001" stiffness="0"/>
    <geom rgba="0.8 0.6 .4 1" margin="0.001"/>
    <site size="0.001"/>
    <tendon width="0.005" rgba=".95 .3 .3 1" limited="false"/>
    <default class="muscle">
      <muscle ctrllimited="true" ctrlrange="0 1" scale="200"/>
    </default>
    <default class="motor">
      <general gainprm="5 0 0 0 0 0 0 0 0 0"/>
    </default>
  </default>
  <option timestep="0.002"/>
  <!-- nuser_jnt=1, the parameter is used to store default value of the joint, and nkey=1 to store keyframe with
   default joint positions set !-->
  <size njmax="1000" nconmax="400" nuser_jnt="1" nkey="1"/>
  <worldbody>
    <!-- The converter script assumes a body named 'ground' exists as a child element of worldbody -->
    <body name="ground" euler="1.571 0 0">
      <geom name="ground-plane" pos="0 0 0" euler="-1.571 0 0" size="10 10 0.125" type="plane" rgba="1.0 0.7 0.4 1.0" condim="3"/>
    </body>
    <light directional="true"/>
    <body name="pelvis" pos="0 0 0" euler="1.571 0 0">
      <inertial mass="12.6913068120" pos="-0.0707000000 0.0000000000 0.0000000000" fullinertia="0.1107808729 0.0938620042 0.0623950636 0.0000000000 0.0000000000 0.0000000000"/>
      <geom name="pelvis_geom_1" type="mesh" mesh="pelvis_geom_1_r_pelvis" rgba="1 1 1 1" group="0"/>
      <geom name="pelvis_geom_2" type="mesh" mesh="pelvis_geom_2_l_pelvis" rgba="1 1 1 1" group="0"/>
      <geom name="pelvis_geom_3" type="mesh" mesh="pelvis_geom_3_sacrum" rgba="1 1 1 1" group="0"/>
      <geom name="Gmax1_at_pelvis_r_cylinder" type="cylinder" euler="-0.6 0.45 0" pos="-0.08347 -0.1079 0.07061" size="0.04412 0.08449" rgba="0.19 0.83 0.78 0.2" group="2"/>
      <site name="Gmax1_at_pelvis_r_sidesite" pos="-0.1241 -0.09678 0.0868" size="0.0005"/>
      <geom name="Gmax2_at_pelvis_r_cylinder" type="cylinder" euler="-0.75 0.39 0" pos="-0.08672 -0.09043 0.07871" size="0.04424 0.05602" rgba="0.19 0.83 0.78 0.2" group="2"/>
      <geom name="Gmax3_at_pelvis_r_cylinder" type="cylinder" euler="-0.1 0 0" pos="-0.08998 -0.09588 0.07871" size="0.04349 0.05784" rgba="0.19 0.83 0.78 0.2" group="2"/>
      <geom name="Gmax1_at_pelvis_l_cylinder" type="cylinder" euler="0.6 -0.45 0" pos="-0.08347 -0.1079 -0.07061" size="0.04412 0.08449" rgba="0.19 0.83 0.78 0.2" group="2"/>
      <site name="Gmax1_at_pelvis_l_sidesite" pos="-0.1241 -0.09678 -0.0868" size="0.0005"/>
      <geom name="Gmax2_at_pelvis_l_cylinder" type="cylinder" euler="0.75 -0.39 0" pos="-0.08672 -0.09043 -0.07871" size="0.04424 0.05602" rgba="0.19 0.83 0.78 0.2" group="2"/>
      <geom name="Gmax3_at_pelvis_l_cylinder" type="cylinder" euler="0.1 0 0" pos="-0.08998 -0.09588 -0.07871" size="0.04349 0.05784" rgba="0.19 0.83 0.78 0.2" group="2"/>
      <geom name="PS_at_brim_r_cylinder" type="cylinder" euler="-0.25 -0.27 0.1" pos="-0.08022 -0.06537 0.07593" size="0.05457 0.05743" rgba="0.19 0.83 0.78 0.2" group="2"/>
      <site name="PS_at_brim_r_sidesite" pos="-0.07487 -0.1186 0.09105" size="0.0005"/>
      <geom name="PS_at_brim_l_cylinder" type="cylinder" euler="0.25 0.27 0.1" pos="-0.08022 -0.06537 -0.07593" size="0.05457 0.05743" rgba="0.19 0.83 0.78 0.2" group="2"/>
      <site name="PS_at_brim_l_sidesite" pos="-0.07487 -0.1186 -0.09105" size="0.0005"/>
      <geom name="IL_at_brim_r_cylinder" type="cylinder" euler="-0.32 -0.24 0.9" pos="-0.07697 -0.07082 0.08751" size="0.05996 0.05736" rgba="0.19 0.83 0.78 0.2" group="2"/>
      <site name="IL_at_brim_r_sidesite" pos="-0.03058 -0.1032 0.1102" size="0.0005"/>
      <geom name="IL_at_brim_l_cylinder" type="cylinder" euler="0.32 0.24 0.9" pos="-0.07697 -0.07082 -0.08751" size="0.05996 0.05736" rgba="0.19 0.83 0.78 0.2" group="2"/>
      <site name="IL_at_brim_l_sidesite" pos="-0.03058 -0.1032 -0.1102" size="0.0005"/>
      <joint name="pelvis_tx" range="-40 40" limited="true" user="0.0" ref="0" axis="1 0 0" type="slide" damping="0" stiffness="0"/>
      <joint name="pelvis_ty" range="-5 5" limited="true" user="0.93" ref="0" axis="0 1 0" type="slide" damping="0" stiffness="0"/>
      <joint name="pelvis_tz" range="-40 40" limited="true" user="0.0" ref="0" axis="0 0 1" type="slide" damping="0" stiffness="0"/>
      <joint name="pelvis_tilt" range="-3.142 3.142" limited="true" user="0.0" ref="0" axis="0 0 1" type="hinge" damping="0" stiffness="0"/>
      <joint name="pelvis_list" range="-3.142 3.142" limited="true" user="0.0" ref="0" axis="1 0 0" type="hinge" damping="0" stiffness="0"/>
      <joint name="pelvis_rotation" range="-3.142 3.142" limited="true" user="0.0" ref="0" axis="0 1 0" type="hinge" damping="0" stiffness="0"/>
      <body name="femur_r" pos="-0.06101 -0.08552 0.08943" euler="-0 0 0">
        <inertial mass="10.0235137285" pos="0.0000000000 -0.1700000000 0.0000000000" fullinertia="0.1442953199 0.0378249868 0.1521620550 0.0000000000 0.0000000000 0.0000000000"/>
        <geom name="femur_r_geom_1" type="mesh" mesh="femur_r_geom_1_r_femur" rgba="1 1 1 1" group="0"/>
        <geom name="Gastroc_at_condyles_r_cylinder" type="cylinder" euler="0 0 0" pos="0.005599 -0.4601 0" size="0.02803 0.05543" rgba="0.19 0.83 0.78 0.2" group="2"/>
        <geom name="KnExt_at_fem_r_cylinder" type="cylinder" euler="-0.06234 0.05076 0" pos="0.004018 -0.452 0.002318" size="0.02803 0.05543" rgba="0.19 0.83 0.78 0.2" group="2"/>
        <geom name="AB_at_femshaft_r_cylinder" type="cylinder" euler="1.662 0.1866 0" pos="0.0164 -0.1264 0.0259" size="0.01839 0.03927" rgba="0.19 0.83 0.78 0.2" group="2"/>
        <geom name="AL_at_femshaft_r_cylinder" type="cylinder" euler="1.777 0.1365 0" pos="0.03442 -0.2603 0.01675" size="0.0224 0.05608" rgba="0.19 0.83 0.78 0.2" group="2"/>
        <geom name="AMprox_at_femshaft_r_cylinder" type="cylinder" euler="1.611 0.1866 0" pos="0.005804 -0.08181 0.02816" size="0.02351 0.03928" rgba="0.19 0.83 0.78 0.2" group="2"/>
        <geom name="AMmid_at_femshaft_r_cylinder" type="cylinder" euler="1.611 0.1366 0" pos="0.02577 -0.1804 0.02282" size="0.02384 0.06733" rgba="0.19 0.83 0.78 0.2" group="2"/>
        <geom name="AMdist_at_femshaft_r_cylinder" type="cylinder" euler="1.712 0.1866 0" pos="0.0354 -0.2926 0.01038" size="0.02429 0.1122" rgba="0.19 0.83 0.78 0.2" group="2"/>
        <geom name="AMisch_at_condyles_r_cylinder" type="cylinder" euler="1.711 -0.4634 0" pos="-0.02537 -0.4229 -0.003497" size="0.04458 0.1346" rgba="0.19 0.83 0.78 0.2" group="2"/>
        <geom name="PECT_at_femshaft_r_cylinder" type="cylinder" euler="1.813 0.2763 0" pos="0.006815 -0.09483 0.03374" size="0.01672 0.02803" rgba="0.19 0.83 0.78 0.2" group="2"/>
        <joint name="hip_flexion_r" range="-0.5236 2.094" limited="true" user="0.0" ref="0" axis="0 0 1" type="hinge"/>
        <joint name="hip_adduction_r" range="-0.8727 0.5236" limited="true" user="0.0" ref="0" axis="1 0 0" type="hinge"/>
        <joint name="hip_rotation_r" range="-0.6981 0.6981" limited="true" user="0.0" ref="0" axis="0 1 0" type="hinge"/>
        <body name="tibia_r" pos="-0.0006652 -0.4542 -0.001524" euler="-0 0 0">
          <inertial mass="3.9953315790" pos="0.0000000000 -0.1867000000 0.0000000000" fullinertia="0.0543128015 0.0054959382 0.0550671460 0.0000000000 0.0000000000 0.0000000000"/>
          <geom name="tibia_r_geom_1" type="mesh" mesh="tibia_r_geom_1_r_tibia" rgba="1 1 1 1" group="0"/>
          <geom name="tibia_r_geom_2" type="mesh" mesh="tibia_r_geom_2_r_fibula" rgba="1 1 1 1" group="0"/>
          <geom name="GasLat_at_shank_r_cylinder" type="cylinder" euler="2.967 -0.2797 -1.478" pos="-0.007679 -0.0771 -0.003387" size="0.05715 0.05139" rgba="0.19 0.83 0.78 0.2" group="2"/>
          <site name="GasLat_at_shank_r_sidesite" pos="-0.06333 -0.06903 0.01142" size="0.0005"/>
          <geom name="GasMed_at_shank_r_cylinder" type="cylinder" euler="2.967 0.02797 -1.478" pos="-0.007679 -0.0771 -0.003387" size="0.05718 0.05135" rgba="0.19 0.83 0.78 0.2" group="2"/>
          <site name="GasMed_at_shank_r_sidesite" pos="-0.06558 -0.07208 -0.005917" size="0.0005"/>
          <geom name="GR_at_condyles_r_cylinder" type="cylinder" euler="0 -0.4 0" pos="-0.003113 -0.02084 0" size="0.0374 0.05141" rgba="0.19 0.83 0.78 0.2" group="2"/>
          <geom name="SM_at_condyles_r_cylinder" type="cylinder" euler="0 -0.1 0" pos="-0.001038 -0.02084 0" size="0.0366 0.05133" rgba="0.19 0.83 0.78 0.2" group="2"/>
          <geom name="ST_at_condyles_r_cylinder" type="cylinder" euler="0 -0.2 0" pos="-0.002075 -0.02136 0" size="0.04418 0.05135" rgba="0.19 0.83 0.78 0.2" group="2"/>
          <geom name="BF_at_gastroc_r_cylinder" type="cylinder" euler="0 0 0" pos="-0.06019 -0.06251 0" size="0.03119 0.07699" rgba="0.19 0.83 0.78 0.2" group="2"/>
          <site name="BF_at_gastroc_r_sidesite" pos="-0.06019 -0.03032 0" size="0.0005"/>
          <joint name="walker_knee_r_translation1" range="0 0.001795" limited="true" user="1.070344343196035e-07" ref="0" axis="-0.1243 0.9898 -0.07016" type="slide"/>
          <joint name="walker_knee_r_translation2" range="0 0.007529" limited="true" user="8.527246964096236e-11" ref="0" axis="0.9922 0.124 -0.008789" type="slide"/>
          <joint name="knee_angle_r" range="0 2.094" limited="true" user="0.0" ref="0" axis="-4.566e-07 -0.07071 -0.9975" type="hinge"/>
          <joint name="walker_knee_r_rotation2" range="-0.001678 0.03354" limited="true" user="-1.4732523263838448e-08" ref="0" axis="0.9922 0.124 -0.008789" type="hinge"/>
          <joint name="walker_knee_r_rotation3" range="0 0.2628" limited="true" user="1.0893911855935912e-08" ref="0" axis="-0.1243 0.9898 -0.07016" type="hinge"/>
          <body name="talus_r" pos="-0.01038 -0.4168 0" euler="-0 0 0">
            <inertial mass="0.1077634950" pos="0.0000000000 0.0000000000 0.0000000000" fullinertia="0.0010776350 0.0010776350 0.0010776350 0.0000000000 0.0000000000 0.0000000000"/>
            <geom name="talus_r_geom_1" type="mesh" mesh="talus_r_geom_1_r_talus" rgba="1 1 1 0" group="0"/>
            <joint name="ankle_angle_r" range="-0.6981 0.5236" limited="true" user="0.0" ref="0" type="hinge" axis="-0.105 -0.174 0.9791"/>
            <body name="calcn_r" pos="-0.06194 -0.05483 0.01016" euler="-0 0 0">
              <inertial mass="1.3470436881" pos="0.1000000000 0.0300000000 0.0000000000" fullinertia="0.0015086889 0.0042027763 0.0044183033 0.0000000000 0.0000000000 0.0000000000"/>
              <geom name="calcn_r_geom_1" type="mesh" mesh="calcn_r_geom_1_r_foot" rgba="1 1 1 1" group="0"/>
              <joint name="subtalar_angle_r" range="-0.3491 0.3491" limited="true" user="0.0" ref="0" type="hinge" axis="0.7872 0.6047 -0.1209"/>
              <body name="toes_r" pos="0.1991 -0.002208 0.0012" euler="-0 0 0">
                <inertial mass="0.2334157303" pos="0.0346000000 0.0060000000 -0.0175000000" fullinertia="0.0006794488 0.0007872123 0.0010776350 0.0000000000 0.0000000000 0.0000000000"/>
                <geom name="toes_r_geom_1" type="mesh" mesh="toes_r_geom_1_r_bofoot" rgba="1 1 1 1" group="0"/>
                <joint name="mtp_angle_r" range="-0.5236 0.5236" limited="true" user="0.0" ref="0" type="hinge" axis="0.581 2.16e-06 -0.8139"/>
                <site name="edl_r_edl_r-P5" pos="0.00033983472944999993 0.0053227449446800008 0.017331813241830002"/>
                <site name="edl_r_edl_r-P6" pos="0.050182261715449997 -0.00045299956976000008 0.028319956277500002"/>
                <site name="ehl_r_ehl_r-P7" pos="0.0337569164587 0.0046432455900400011 -0.027753557151950003"/>
                <site name="ehl_r_ehl_r-P8" pos="0.063775650893449998 0.0038504963429599999 -0.021070047470459999"/>
                <site name="fdl_r_fdl_r-P6" pos="-0.0021522866198499997 -0.00883349161032 0.01665213429117"/>
                <site name="fdl_r_fdl_r-P7" pos="0.032284299297750001 -0.0080407423632400006 0.024355162398650002"/>
                <site name="fdl_r_fdl_r-P8" pos="0.049955705229149994 -0.0067949935464000008 0.02741371767662"/>
                <site name="fhl_r_fhl_r-P6" pos="0.017558127688249998 -0.0072479931161600012 -0.030019153654150001"/>
                <site name="fhl_r_fhl_r-P7" pos="0.063662372650299989 -0.011551489028880002 -0.020503648344910003"/>
              </body>
              <site name="edl_r_edl_r-P3" pos="0.10231319153644 0.039737870924400003 0.00088898495719999992"/>
              <site name="edl_r_edl_r-P4" pos="0.17991090046016001 0.0060710636134499998 0.014446005554499998"/>
              <site name="ehl_r_ehl_r-P4" pos="0.10799107267720001 0.042938977193310003 -0.02344697824615"/>
              <site name="ehl_r_ehl_r-P5" pos="0.14395098656868002 0.03410833921011 -0.028558641750049997"/>
              <site name="ehl_r_ehl_r-P6" pos="0.19304795878584002 0.01534323349581 -0.031114473501999997"/>
              <site name="fdl_r_fdl_r-P3" pos="0.048540317203360002 0.034770637058850001 -0.031114473501999997"/>
              <site name="fdl_r_fdl_r-P4" pos="0.078822349954080009 0.019427403563040003 -0.029225380467949997"/>
              <site name="fdl_r_fdl_r-P5" pos="0.18458680257608001 -0.0089410209579900007 0.012890281879399997"/>
              <site name="fhl_r_fhl_r-P3" pos="0.041637795032240008 0.030465701042040001 -0.026780671835649996"/>
              <site name="fhl_r_fhl_r-P4" pos="0.11556158086488001 0.0075060422857200007 -0.028447518630399998"/>
              <site name="fhl_r_fhl_r-P5" pos="0.19215731076376003 -0.0058502976638700006 -0.029892119185849997"/>
              <site name="gaslat_r_gaslat_r-P2" pos="0.0048985641214400006 0.034218722184900005 -0.0058895253414499998"/>
              <site name="gasmed_r_gasmed_r-P2" pos="0.0048985641214400006 0.034218722184900005 -0.0058895253414499998"/>
              <site name="perbrev_r_perbrev_r-P4" pos="0.052436902299960009 0.029803403193300004 0.025891686878450001"/>
              <site name="perbrev_r_perbrev_r-P5" pos="0.075371088868519995 0.024173871479010001 0.038115230039949995"/>
              <site name="perlong_r_perlong_r-P4" pos="0.048762979208880002 0.025388084201700002 0.024558209442650001"/>
              <site name="perlong_r_perlong_r-P5" pos="0.075816412879559994 0.011700595327740001 0.031558965980599998"/>
              <site name="perlong_r_perlong_r-P6" pos="0.094854014351520008 0.0076164252605100003 0.013112528118699998"/>
              <site name="perlong_r_perlong_r-P7" pos="0.13393119632028003 0.0093825528571500009 -0.020446654015599999"/>
              <site name="soleus_r_soleus_r-P2" pos="0.0048985641214400006 0.034218722184900005 -0.0058895253414499998"/>
              <site name="tibant_r_tibant_r-P4" pos="0.12981194921816 0.019648169512620002 -0.033892551493249996"/>
              <site name="tibpost_r_tibpost_r-P3" pos="0.046425028150920006 0.036867913579860002 -0.031781212219899997"/>
              <site name="tibpost_r_tibpost_r-P4" pos="0.08594753413072001 0.017550892991610001 -0.031225596621649997"/>
              <site name="R1MT_marker" group="4" pos="0.2117 0.02653 -0.02823" rgba="1 0.1 0.5 0.5" size="0.01"/>
              <site name="R5MT_marker" group="4" pos="0.1666 0.01422 0.08405" rgba="1 0.1 0.5 0.5" size="0.01"/>
              <site name="RCAL_marker" group="4" pos="-0.02028 0.02106 -0.001034" rgba="1 0.1 0.5 0.5" size="0.01"/>
            </body>
          </body>
          <site name="bflh_r_bflh_r-P2" pos="-0.034970443736639996 -0.036466452659000004 0.025970263187330003"/>
          <site name="bflh_r_bflh_r-P3" pos="-0.029781950600639998 -0.047406388456699998 0.031102726267830002"/>
          <site name="bfsh_r_bfsh_r-P2" pos="-0.031234728678719997 -0.043655553326059998 0.032642465191980004"/>
          <site name="edl_r_edl_r-P1" pos="-0.016603178035199999 -0.12054767350418 0.021043098630050001"/>
          <site name="edl_r_edl_r-P2" pos="0.017018257486080001 -0.39175389142240002 0.011496717300320002"/>
          <site name="ehl_r_ehl_r-P1" pos="-0.0145277807808 -0.161494290347 0.019400710444290002"/>
          <site name="ehl_r_ehl_r-P2" pos="0.0073676602531199996 -0.30308831652866003 0.016834478904040003"/>
          <site name="ehl_r_ehl_r-P3" pos="0.020753972544 -0.38477317048482002 -0.0028741793250800004"/>
          <site name="fdl_r_fdl_r-P1" pos="-0.0023867068425599998 -0.19087583220368001 -0.00184768670898"/>
          <site name="fdl_r_fdl_r-P2" pos="-0.018263495838720001 -0.37977205697729999 -0.012728508439640001"/>
          <site name="fhl_r_fhl_r-P1" pos="-0.032168657443200001 -0.22536267743262001 0.020529852322000001"/>
          <site name="fhl_r_fhl_r-P2" pos="-0.025112306778239998 -0.38248099346053999 -0.0078013438823600007"/>
          <site name="grac_r_grac_r-P2" pos="-0.019114408713023997 -0.049542280683870003 -0.030394446362721005"/>
          <site name="grac_r_grac_r-P3" pos="0.0018471035564159998 -0.072536983831988006 -0.016146728851253001"/>
          <site name="GR_at_condyles_r_cylinder_grac_r_1_sidesite" pos="-0.01584 0.0002761 -0.03363" size="0.0005"/>
          <site name="perbrev_r_perbrev_r-P1" pos="-0.025216076640959997 -0.26380873752167999 0.025764964664110004"/>
          <site name="perbrev_r_perbrev_r-P2" pos="-0.035177983462079995 -0.40561114343282001 0.025559666140889999"/>
          <site name="perbrev_r_perbrev_r-P3" pos="-0.029574410875199998 -0.41717621841896002 0.026175561710550001"/>
          <site name="perlong_r_perlong_r-P1" pos="-0.020753972544 -0.14305268428802001 0.028947091774020002"/>
          <site name="perlong_r_perlong_r-P2" pos="-0.032895046482239995 -0.40634047248600003 0.02432787500157"/>
          <site name="perlong_r_perlong_r-P3" pos="-0.028225402659839995 -0.41821811706635997 0.024635822786400002"/>
          <site name="recfem_r_recfem_r-P5" pos="0.033828975246719996 -0.065764642623887995 -0.00048245152956700001"/>
          <site name="sart_r_sart_r-P3" pos="-0.026046235542719998 -0.041780135760740002 -0.037466980487650001"/>
          <site name="sart_r_sart_r-P4" pos="-0.016499408172479999 -0.062409728979260004 -0.027099405065040001"/>
          <site name="sart_r_sart_r-P5" pos="0.014112701329919998 -0.084393790439400013 -0.0026688808018600001"/>
          <site name="semimem_r_semimem_r-P2" pos="-0.0300932601888 -0.043447173596580006 -0.020119255275560001"/>
          <site name="SM_at_condyles_r_cylinder_semimem_r_1_sidesite" pos="-0.03009 -0.04345 -0.02012" size="0.0005"/>
          <site name="semiten_r_semiten_r-P2" pos="-0.03237619716864 -0.052928451287920002 -0.023506680908690004"/>
          <site name="semiten_r_semiten_r-P3" pos="0.0019716273916799997 -0.08053876544402 -0.012009963608370002"/>
          <site name="ST_at_condyles_r_cylinder_semiten_r_1_sidesite" pos="-0.03443 -0.002247 -0.02404" size="0.0005"/>
          <site name="soleus_r_soleus_r-P1" pos="-0.0078865095667199989 -0.095437916101840006 0.01005962763778"/>
          <site name="tfl_r_tfl_r-P4" pos="0.011207145173759999 -0.042717844543400003 0.035516644517059999"/>
          <site name="tibant_r_tibant_r-P1" pos="0.015980558858880001 -0.13669710253888001 0.016629180380820001"/>
          <site name="tibant_r_tibant_r-P2" pos="0.026046235542719998 -0.19858588219444001 0.013139105486080003"/>
          <site name="tibant_r_tibant_r-P3" pos="0.02417837801376 -0.38123071508366002 -0.013549702532520001"/>
          <site name="tibpost_r_tibpost_r-P1" pos="-0.0042545643715200003 -0.13586358362095999 0.010572873945830001"/>
          <site name="tibpost_r_tibpost_r-P2" pos="-0.017018257486080001 -0.3808139556247 -0.017963620781750005"/>
          <site name="vasint_r_vasint_r-P5" pos="0.033797844287904 -0.065847994515680006 0.00044139182492300004"/>
          <site name="vaslat_r_vaslat_r-P5" pos="0.033766713329087997 -0.066035536272212009 0.0052453772682710008"/>
          <site name="vasmed_r_vasmed_r-P5" pos="0.033102586207679995 -0.06623349701521801 -0.0069596199371579999"/>
          <site name="RLM_marker" group="4" pos="-0.006446 -0.4292 0.06123" rgba="1 0.1 0.5 0.5" size="0.01"/>
          <site name="RMM_marker" group="4" pos="-0.0003002 -0.4131 -0.0434" rgba="1 0.1 0.5 0.5" size="0.01"/>
          <site name="RS1_marker" group="4" pos="0.03485 -0.2364 0.01276" rgba="1 0.1 0.5 0.5" size="0.01"/>
          <site name="RS2_marker" group="4" pos="0.02531 -0.1728 0.07627" rgba="1 0.1 0.5 0.5" size="0.01"/>
          <site name="RS3_marker" group="4" pos="0.03904 -0.1061 0.008384" rgba="1 0.1 0.5 0.5" size="0.01"/>
        </body>
        <body name="patella_r" pos="-0.00906 -0.4578 -0.003048" euler="-0 0 0">
          <inertial mass="0.071344156094027403" pos="0.0018 0.0264 0" fullinertia="2.3753796750563648e-06 1.0850601930309737e-05 1.0850601930309737e-05 0 0 0"/>
          <geom name="patella_r_geom_1" type="mesh" mesh="patella_r_geom_1_r_patella" rgba="1 1 1 1" group="0"/>
          <joint name="patellofemoral_r_translation1" range="-0.02542 0.05868" limited="true" user="0.05870274596325426" ref="0" axis="1 0 0" type="slide"/>
          <joint name="patellofemoral_r_translation2" range="-0.04579 -0.01212" limited="true" user="-0.01215206102797061" ref="0" axis="0 1 0" type="slide"/>
          <joint name="patellofemoral_r_translation3" limited="false" ref="0" axis="0 0 1" type="slide"/>
          <joint name="patellofemoral_r_rotation1" range="-1.786 0.001137" limited="true" user="0.01050598499723554" ref="0" axis="0 0 1" type="hinge"/>
          <site name="recfem_r_recfem_r-P2" pos="0.01 0.049000000000000002 0.00069999999999999999"/>
          <site name="recfem_r_recfem_r-P3" pos="0.0121 0.043700000000000003 -0.001"/>
          <site name="recfem_r_recfem_r-P4" pos="0.0050000000000000001 0.00247 3.0000000000000001e-05"/>
          <site name="vasint_r_vasint_r-P3" pos="0.0057999999999999996 0.048000000000000001 -0.00059999999999999995"/>
          <site name="vasint_r_vasint_r-P4" pos="0.0050000000000000001 0.00247 -0.00038999999999999999"/>
          <site name="vaslat_r_vaslat_r-P3" pos="0.0103 0.042299999999999997 0.0141"/>
          <site name="vaslat_r_vaslat_r-P4" pos="0.0050000000000000001 0.00247 0.0073299999999999997"/>
          <site name="vasmed_r_vasmed_r-P3" pos="0.0063 0.044499999999999998 -0.017000000000000001"/>
          <site name="vasmed_r_vasmed_r-P4" pos="0.0050000000000000001 0.00247 -0.0085000000000000006"/>
        </body>
        <site name="addbrev_r_addbrev_r-P2" pos="-0.0022397408346000003 -0.132427606182 0.02760185174727"/>
        <site name="AB_at_femshaft_r_cylinder_addbrev_r_1_sidesite" pos="0.001478 -0.1191 0.0159" size="0.0005"/>
        <site name="addlong_r_addlong_r-P2" pos="0.012609740898797999 -0.26863725501512997 0.017547683259409003"/>
        <site name="AL_at_femshaft_r_cylinder_addlong_r_1_sidesite" pos="0.01261 -0.2686 0.01755" size="0.0005"/>
        <site name="addmagDist_r_addmagDist_r-P2" pos="0.012598542194624999 -0.29459531036250003 0.021394206374390004"/>
        <site name="AMdist_at_femshaft_r_cylinder_addmagDist_r_1_sidesite" pos="0.0126 -0.2946 0.02139" size="0.0005"/>
        <site name="addmagIsch_r_addmagIsch_r-P2" pos="0.0053865767072130005 -0.43540625737652999 -0.036281470188279007"/>
        <site name="AMisch_at_condyles_r_cylinder_addmagIsch_r_1_sidesite" pos="0.005387 -0.4354 -0.03628" size="0.0005"/>
        <site name="addmagMid_r_addmagMid_r-P2" pos="0.0027100864098660001 -0.18225629867759999 0.032390606749205998"/>
        <site name="AMmid_at_femshaft_r_cylinder_addmagMid_r_1_sidesite" pos="0.00271 -0.1823 0.03239" size="0.0005"/>
        <site name="addmagProx_r_addmagProx_r-P2" pos="-0.017100421272171002 -0.088502042572140005 0.035494429435645999"/>
        <site name="AMprox_at_femshaft_r_cylinder_addmagProx_r_1_sidesite" pos="-0.01787 -0.08231 0.02184" size="0.0005"/>
        <site name="bfsh_r_bfsh_r-P1" pos="0.0055993520865 -0.23691074292390002 0.025939089593820002"/>
        <site name="gaslat_r_gaslat_r-P1" pos="-0.0033596112519000002 -0.4280329576086 0.030705674433710001"/>
        <site name="Gastroc_at_condyles_r_cylinder_gaslat_r_1_sidesite" pos="-0.01055 -0.4795 0.0276" size="0.0005"/>
        <site name="gasmed_r_gasmed_r-P1" pos="0.0089589633384000011 -0.42511506120120002 -0.023056968527840001"/>
        <site name="Gastroc_at_condyles_r_cylinder_gasmed_r_1_sidesite" pos="-3.325e-05 -0.4783 -0.02187" size="0.0005"/>
        <site name="glmax1_r_glmax1_r-P3" pos="-0.049722246528120004 -0.036585931877399995 0.033476944689460005"/>
        <site name="glmax1_r_glmax1_r-P4" pos="-0.031020410559209999 -0.063520360253399993 0.052099880808100005"/>
        <site name="glmax2_r_glmax2_r-P3" pos="-0.050394168778499997 -0.065540442381600006 0.02793440417796"/>
        <site name="glmax2_r_glmax2_r-P4" pos="-0.01746997850988 -0.11402241345839999 0.04644648948637"/>
        <site name="glmax3_r_glmax3_r-P3" pos="-0.031468358726129998 -0.12625513301249999 0.010419976161620001"/>
        <site name="glmax3_r_glmax3_r-P4" pos="-0.0067192225038000004 -0.15924980777309999 0.045559683004529998"/>
        <site name="glmed1_r_glmed1_r-P2_0" pos="-0.015556965151077252 -0.020531559376245279 0.065612173029194809"/>
        <site name="glmed2_r_glmed2_r-P2_0" pos="-0.024677480502740365 -0.011176774366038268 0.062216373633235254"/>
        <site name="glmed3_r_glmed3_r-P2_0" pos="-0.03460399589457 -0.0052746588903000002 0.057420719699140005"/>
        <site name="glmin1_r_glmin1_r-P2" pos="0.0061473257107925545 -0.017382359045944824 0.062118358341969146"/>
        <site name="glmin2_r_glmin2_r-P2" pos="0.0039683066604336613 -0.010114179714563354 0.058157132347121297"/>
        <site name="glmin3_r_glmin3_r-P2" pos="-0.00400481041233365 -0.0014215775471847353 0.056823953839347872"/>
        <site name="iliacus_r_iliacus_r-P3" pos="-0.0025757019597900002 -0.063408133468499994 0.015408262621970001"/>
        <site name="iliacus_r_iliacus_r-P4" pos="-0.013662419091060002 -0.071488461981300003 0.021726758805080001"/>
        <site name="piri_r_piri_r-P3" pos="-0.016574082176040002 -0.0040401642563999999 0.048441804070510006"/>
        <site name="psoas_r_psoas_r-P3" pos="-0.01478228950836 -0.052409908548300001 0.0050991372705800004"/>
        <site name="psoas_r_psoas_r-P4" pos="-0.02631695480655 -0.058806835287600001 0.0097548713002400013"/>
        <site name="KnExt_at_fem_r_cylinder_recfem_r_3_sidesite" pos="-0.01901 -0.448 -0.0149" size="0.0005"/>
        <site name="KnExt_at_fem_r_cylinder_recfem_r_2_sidesite" pos="0.00304 -0.4141 -0.004048" size="0.0005"/>
        <site name="sart_r_sart_r-P2" pos="-0.0033596112519000002 -0.40042516852319998 -0.046668191106830001"/>
        <site name="tfl_r_tfl_r-P2" pos="0.03292419026862 -0.11166565097550001 0.06617793370731001"/>
        <site name="tfl_r_tfl_r-P3" pos="0.01198261346511 -0.45451847884500002 0.035915662514520004"/>
        <site name="vasint_r_vasint_r-P1" pos="0.032476242101700005 -0.21592433414759998 0.0343637511713"/>
        <site name="vasint_r_vasint_r-P2" pos="0.037515658979550004 -0.23388061973159999 0.031592480915550003"/>
        <site name="KnExt_at_fem_r_cylinder_vasint_r_3_sidesite" pos="-0.01915 -0.447 -0.01444" size="0.0005"/>
        <site name="vaslat_r_vaslat_r-P1" pos="0.0053753780030399998 -0.20806845920460001 0.038686932770270001"/>
        <site name="vaslat_r_vaslat_r-P2" pos="0.030124514225370002 -0.2907795996759 0.045337981384070004"/>
        <site name="KnExt_at_fem_r_cylinder_vaslat_r_3_sidesite" pos="-0.02302 -0.448 0.01212" size="0.0005"/>
        <site name="KnExt_at_fem_r_cylinder_vaslat_r_2_sidesite" pos="0.00124 -0.4155 0.01105" size="0.0005"/>
        <site name="vasmed_r_vasmed_r-P1" pos="0.015678185842200001 -0.2355640215051 0.020839952323240003"/>
        <site name="vasmed_r_vasmed_r-P2" pos="0.039867386855880003 -0.31075596738809996 0.00099765729207000001"/>
        <site name="KnExt_at_fem_r_cylinder_vasmed_r_4_sidesite" pos="-0.01029 -0.4579 -0.02224" size="0.0005"/>
        <site name="KnExt_at_fem_r_cylinder_vasmed_r_3_sidesite" pos="-0.01029 -0.4579 -0.02224" size="0.0005"/>
        <site name="RLFE_marker" group="4" pos="0.01023 -0.4544 0.06833" rgba="1 0.1 0.5 0.5" size="0.01"/>
        <site name="RMFE_marker" group="4" pos="-0.005669 -0.455 -0.06251" rgba="1 0.1 0.5 0.5" size="0.01"/>
        <site name="RT1_marker" group="4" pos="0.08951 -0.3169 0.04785" rgba="1 0.1 0.5 0.5" size="0.01"/>
        <site name="RT2_marker" group="4" pos="0.09649 -0.2463 -0.04822" rgba="1 0.1 0.5 0.5" size="0.01"/>
        <site name="RT3_marker" group="4" pos="0.09163 -0.2313 0.06542" rgba="1 0.1 0.5 0.5" size="0.01"/>
        <site name="RTRC_marker" group="4" pos="-0.02053 -0.02524 0.09997" rgba="1 0.1 0.5 0.5" size="0.01"/>
      </body>
      <body name="femur_l" pos="-0.06101 -0.08552 -0.08943" euler="-0 0 0">
        <inertial mass="10.0235137285" pos="0.0000000000 -0.1700000000 0.0000000000" fullinertia="0.1442953199 0.0378249868 0.1521620550 0.0000000000 0.0000000000 0.0000000000"/>
        <geom name="femur_l_geom_1" type="mesh" mesh="femur_l_geom_1_l_femur" rgba="1 1 1 1" group="0"/>
        <geom name="Gastroc_at_condyles_l_cylinder" type="cylinder" euler="0 0 0" pos="0.005599 -0.4601 0" size="0.02803 0.05543" rgba="0.19 0.83 0.78 0.2" group="2"/>
        <geom name="KnExt_at_fem_l_cylinder" type="cylinder" euler="0.06234 -0.05076 0" pos="0.004018 -0.452 -0.002318" size="0.02803 0.05543" rgba="0.19 0.83 0.78 0.2" group="2"/>
        <geom name="AB_at_femshaft_l_cylinder" type="cylinder" euler="-1.662 -0.1866 0" pos="0.0164 -0.1264 -0.0259" size="0.01839 0.03927" rgba="0.19 0.83 0.78 0.2" group="2"/>
        <geom name="AL_at_femshaft_l_cylinder" type="cylinder" euler="-1.777 -0.1365 0" pos="0.03442 -0.2603 -0.01675" size="0.0224 0.05608" rgba="0.19 0.83 0.78 0.2" group="2"/>
        <geom name="AMprox_at_femshaft_l_cylinder" type="cylinder" euler="-1.611 -0.1866 0" pos="0.005804 -0.08181 -0.02816" size="0.02351 0.03928" rgba="0.19 0.83 0.78 0.2" group="2"/>
        <geom name="AMmid_at_femshaft_l_cylinder" type="cylinder" euler="-1.611 -0.1366 0" pos="0.02577 -0.1804 -0.02282" size="0.02384 0.06733" rgba="0.19 0.83 0.78 0.2" group="2"/>
        <geom name="AMdist_at_femshaft_l_cylinder" type="cylinder" euler="-1.712 -0.1866 0" pos="0.0354 -0.2926 -0.01038" size="0.02429 0.1122" rgba="0.19 0.83 0.78 0.2" group="2"/>
        <geom name="AMisch_at_condyles_l_cylinder" type="cylinder" euler="-1.711 0.4634 0" pos="-0.02537 -0.4229 0.003497" size="0.04458 0.1346" rgba="0.19 0.83 0.78 0.2" group="2"/>
        <geom name="PECT_at_femshaft_l_cylinder" type="cylinder" euler="-1.813 -0.2763 0" pos="0.006815 -0.09483 -0.03374" size="0.01672 0.02803" rgba="0.19 0.83 0.78 0.2" group="2"/>
        <joint name="hip_flexion_l" range="-0.5236 2.094" limited="true" user="0.0" ref="0" axis="0 0 1" type="hinge"/>
        <joint name="hip_adduction_l" range="-0.8727 0.5236" limited="true" user="-0.0" ref="0" axis="-1 -0 -0" type="hinge"/>
        <joint name="hip_rotation_l" range="-0.6981 0.6981" limited="true" user="-0.0" ref="0" axis="-0 -1 -0" type="hinge"/>
        <body name="tibia_l" pos="-0.0006652 -0.4542 0.001524" euler="-0 0 0">
          <inertial mass="3.9953315790" pos="0.0000000000 -0.1867000000 0.0000000000" fullinertia="0.0543128015 0.0054959382 0.0550671460 0.0000000000 0.0000000000 0.0000000000"/>
          <geom name="tibia_l_geom_1" type="mesh" mesh="tibia_l_geom_1_l_tibia" rgba="1 1 1 1" group="0"/>
          <geom name="tibia_l_geom_2" type="mesh" mesh="tibia_l_geom_2_l_fibula" rgba="1 1 1 1" group="0"/>
          <geom name="GasLat_at_shank_l_cylinder" type="cylinder" euler="-2.967 0.2797 -1.478" pos="-0.007679 -0.0771 0.003387" size="0.05715 0.05139" rgba="0.19 0.83 0.78 0.2" group="2"/>
          <site name="GasLat_at_shank_l_sidesite" pos="-0.06333 -0.06903 -0.01142" size="0.0005"/>
          <geom name="GasMed_at_shank_l_cylinder" type="cylinder" euler="-2.967 -0.02797 -1.478" pos="-0.007679 -0.0771 0.003387" size="0.05718 0.05135" rgba="0.19 0.83 0.78 0.2" group="2"/>
          <site name="GasMed_at_shank_l_sidesite" pos="-0.06558 -0.07208 0.005917" size="0.0005"/>
          <geom name="GR_at_condyles_l_cylinder" type="cylinder" euler="0 0.4 0" pos="-0.003113 -0.02084 0" size="0.0374 0.05141" rgba="0.19 0.83 0.78 0.2" group="2"/>
          <geom name="SM_at_condyles_l_cylinder" type="cylinder" euler="0 0.1 0" pos="-0.001038 -0.02084 0" size="0.0366 0.05133" rgba="0.19 0.83 0.78 0.2" group="2"/>
          <geom name="ST_at_condyles_l_cylinder" type="cylinder" euler="0 0.2 0" pos="-0.002075 -0.02136 0" size="0.04418 0.05135" rgba="0.19 0.83 0.78 0.2" group="2"/>
          <geom name="BF_at_gastroc_l_cylinder" type="cylinder" euler="0 0 0" pos="-0.06019 -0.06251 0" size="0.03119 0.07699" rgba="0.19 0.83 0.78 0.2" group="2"/>
          <joint name="walker_knee_l_translation1" range="0 0.001795" limited="true" user="1.070344343196035e-07" ref="0" axis="-0.1243 0.9898 0.07016" type="slide"/>
          <joint name="walker_knee_l_translation2" range="-0.007529 0" limited="true" user="-8.527246964096236e-11" ref="0" axis="-0.9922 -0.124 -0.008789" type="slide"/>
          <joint name="knee_angle_l" range="0 2.094" limited="true" user="0.0" ref="0" axis="4.566e-07 0.07071 -0.9975" type="hinge"/>
          <joint name="walker_knee_l_rotation2" range="-0.001678 0.03354" limited="true" user="-1.4732523263838448e-08" ref="0" axis="-0.9922 -0.124 -0.008789" type="hinge"/>
          <joint name="walker_knee_l_rotation3" range="-0.2628 0" limited="true" user="-1.0893911855935912e-08" ref="0" axis="-0.1243 0.9898 0.07016" type="hinge"/>
          <body name="talus_l" pos="-0.01038 -0.4168 0" euler="-0 0 0">
            <inertial mass="0.1077634950" pos="0.0000000000 0.0000000000 0.0000000000" fullinertia="0.0010776350 0.0010776350 0.0010776350 0.0000000000 0.0000000000 0.0000000000"/>
            <geom name="talus_l_geom_1" type="mesh" mesh="talus_l_geom_1_l_talus" rgba="1 1 1 0" group="0"/>
            <joint name="ankle_angle_l" range="-0.6981 0.5236" limited="true" user="0.0" ref="0" type="hinge" axis="0.105 0.174 0.9791"/>
            <body name="calcn_l" pos="-0.06194 -0.05483 -0.01016" euler="-0 0 0">
              <inertial mass="1.3470436881" pos="0.1000000000 0.0300000000 0.0000000000" fullinertia="0.0015086889 0.0042027763 0.0044183033 0.0000000000 0.0000000000 0.0000000000"/>
              <geom name="calcn_l_geom_1" type="mesh" mesh="calcn_l_geom_1_l_foot" rgba="1 1 1 1" group="0"/>
              <joint name="subtalar_angle_l" range="-0.3491 0.3491" limited="true" user="0.0" ref="0" type="hinge" axis="-0.7872 -0.6047 -0.1209"/>
              <body name="toes_l" pos="0.1991 -0.002208 -0.0012" euler="-0 0 0">
                <inertial mass="0.2334157303" pos="0.0346000000 0.0060000000 0.0175000000" fullinertia="0.0006794488 0.0007872123 0.0010776350 0.0000000000 0.0000000000 0.0000000000"/>
                <geom name="toes_l_geom_1" type="mesh" mesh="toes_l_geom_1_l_bofoot" rgba="1 1 1 1" group="0"/>
                <joint name="mtp_angle_l" range="-0.5236 0.5236" limited="true" user="0.0" ref="0" type="hinge" axis="-0.581 2.16e-06 -0.8139"/>
                <site name="edl_l_edl_l-P5" pos="0.00033983472944999993 0.0053227449446800008 -0.017331813241830002"/>
                <site name="edl_l_edl_l-P6" pos="0.050182261715449997 -0.00045299956976000008 -0.028319956277500002"/>
                <site name="ehl_l_ehl_l-P7" pos="0.0337569164587 0.0046432455900400011 0.027753557151950003"/>
                <site name="ehl_l_ehl_l-P8" pos="0.063775650893449998 0.0038504963429599999 0.021070047470459999"/>
                <site name="fdl_l_fdl_l-P6" pos="-0.0021522866198499997 -0.00883349161032 -0.01665213429117"/>
                <site name="fdl_l_fdl_l-P7" pos="0.032284299297750001 -0.0080407423632400006 -0.024355162398650002"/>
                <site name="fdl_l_fdl_l-P8" pos="0.049955705229149994 -0.0067949935464000008 -0.02741371767662"/>
                <site name="fhl_l_fhl_l-P6" pos="0.017558127688249998 -0.0072479931161600012 0.030019153654150001"/>
                <site name="fhl_l_fhl_l-P7" pos="0.063662372650299989 -0.011551489028880002 0.020503648344910003"/>
              </body>
              <site name="edl_l_edl_l-P3" pos="0.10231319153644 0.039737870924400003 -0.00088898495719999992"/>
              <site name="edl_l_edl_l-P4" pos="0.17991090046016001 0.0060710636134499998 -0.014446005554499998"/>
              <site name="ehl_l_ehl_l-P4" pos="0.10799107267720001 0.042938977193310003 0.02344697824615"/>
              <site name="ehl_l_ehl_l-P5" pos="0.14395098656868002 0.03410833921011 0.028558641750049997"/>
              <site name="ehl_l_ehl_l-P6" pos="0.19304795878584002 0.01534323349581 0.031114473501999997"/>
              <site name="fdl_l_fdl_l-P3" pos="0.048540317203360002 0.034770637058850001 0.031114473501999997"/>
              <site name="fdl_l_fdl_l-P4" pos="0.078822349954080009 0.019427403563040003 0.029225380467949997"/>
              <site name="fdl_l_fdl_l-P5" pos="0.18458680257608001 -0.0089410209579900007 -0.012890281879399997"/>
              <site name="fhl_l_fhl_l-P3" pos="0.041637795032240008 0.030465701042040001 0.026780671835649996"/>
              <site name="fhl_l_fhl_l-P4" pos="0.11556158086488001 0.0075060422857200007 0.028447518630399998"/>
              <site name="fhl_l_fhl_l-P5" pos="0.19215731076376003 -0.0058502976638700006 0.029892119185849997"/>
              <site name="gaslat_l_gaslat_l-P2" pos="0.0048985641214400006 0.034218722184900005 0.0058895253414499998"/>
              <site name="gasmed_l_gasmed_l-P2" pos="0.0048985641214400006 0.034218722184900005 0.0058895253414499998"/>
              <site name="perbrev_l_perbrev_l-P4" pos="0.052436902299960009 0.029803403193300004 -0.025891686878450001"/>
              <site name="perbrev_l_perbrev_l-P5" pos="0.075371088868519995 0.024173871479010001 -0.038115230039949995"/>
              <site name="perlong_l_perlong_l-P4" pos="0.048762979208880002 0.025388084201700002 -0.024558209442650001"/>
              <site name="perlong_l_perlong_l-P5" pos="0.075816412879559994 0.011700595327740001 -0.031558965980599998"/>
              <site name="perlong_l_perlong_l-P6" pos="0.094854014351520008 0.0076164252605100003 -0.013112528118699998"/>
              <site name="perlong_l_perlong_l-P7" pos="0.13393119632028003 0.0093825528571500009 0.020446654015599999"/>
              <site name="soleus_l_soleus_l-P2" pos="0.0048985641214400006 0.034218722184900005 0.0058895253414499998"/>
              <site name="tibant_l_tibant_l-P4" pos="0.12981194921816 0.019648169512620002 0.033892551493249996"/>
              <site name="tibpost_l_tibpost_l-P3" pos="0.046425028150920006 0.036867913579860002 0.031781212219899997"/>
              <site name="tibpost_l_tibpost_l-P4" pos="0.08594753413072001 0.017550892991610001 0.031225596621649997"/>
              <site name="L1MT_marker" group="4" pos="0.2118 0.02917 0.02919" rgba="1 0.1 0.5 0.5" size="0.01"/>
              <site name="L5MT_marker" group="4" pos="0.1684 0.01623 -0.07513" rgba="1 0.1 0.5 0.5" size="0.01"/>
              <site name="LCAL_marker" group="4" pos="-0.02056 0.02131 0.001423" rgba="1 0.1 0.5 0.5" size="0.01"/>
            </body>
          </body>
          <site name="bflh_l_bflh_l-P2" pos="-0.034970443736639996 -0.036466452659000004 -0.025970263187330003"/>
          <site name="bflh_l_bflh_l-P3" pos="-0.029781950600639998 -0.047406388456699998 -0.031102726267830002"/>
          <site name="bfsh_l_bfsh_l-P2" pos="-0.031234728678719997 -0.043655553326059998 -0.032642465191980004"/>
          <site name="edl_l_edl_l-P1" pos="-0.016603178035199999 -0.12054767350418 -0.021043098630050001"/>
          <site name="edl_l_edl_l-P2" pos="0.017018257486080001 -0.39175389142240002 -0.011496717300320002"/>
          <site name="ehl_l_ehl_l-P1" pos="-0.0145277807808 -0.161494290347 -0.019400710444290002"/>
          <site name="ehl_l_ehl_l-P2" pos="0.0073676602531199996 -0.30308831652866003 -0.016834478904040003"/>
          <site name="ehl_l_ehl_l-P3" pos="0.020753972544 -0.38477317048482002 0.0028741793250800004"/>
          <site name="fdl_l_fdl_l-P1" pos="-0.0023867068425599998 -0.19087583220368001 0.00184768670898"/>
          <site name="fdl_l_fdl_l-P2" pos="-0.018263495838720001 -0.37977205697729999 0.012728508439640001"/>
          <site name="fhl_l_fhl_l-P1" pos="-0.032168657443200001 -0.22536267743262001 -0.020529852322000001"/>
          <site name="fhl_l_fhl_l-P2" pos="-0.025112306778239998 -0.38248099346053999 0.0078013438823600007"/>
          <site name="grac_l_grac_l-P2" pos="-0.019114408713023997 -0.049542280683870003 0.030394446362721005"/>
          <site name="grac_l_grac_l-P3" pos="0.0018471035564159998 -0.072536983831988006 0.016146728851253001"/>
          <site name="GR_at_condyles_l_cylinder_grac_l_1_sidesite" pos="-0.01584 0.0002761 0.03363" size="0.0005"/>
          <site name="perbrev_l_perbrev_l-P1" pos="-0.025216076640959997 -0.26380873752167999 -0.025764964664110004"/>
          <site name="perbrev_l_perbrev_l-P2" pos="-0.035177983462079995 -0.40561114343282001 -0.025559666140889999"/>
          <site name="perbrev_l_perbrev_l-P3" pos="-0.029574410875199998 -0.41717621841896002 -0.026175561710550001"/>
          <site name="perlong_l_perlong_l-P1" pos="-0.020753972544 -0.14305268428802001 -0.028947091774020002"/>
          <site name="perlong_l_perlong_l-P2" pos="-0.032895046482239995 -0.40634047248600003 -0.02432787500157"/>
          <site name="perlong_l_perlong_l-P3" pos="-0.028225402659839995 -0.41821811706635997 -0.024635822786400002"/>
          <site name="recfem_l_recfem_l-P5" pos="0.033828975246719996 -0.065764642623887995 0.00048245152956700001"/>
          <site name="sart_l_sart_l-P3" pos="-0.026046235542719998 -0.041780135760740002 0.037466980487650001"/>
          <site name="sart_l_sart_l-P4" pos="-0.016499408172479999 -0.062409728979260004 0.027099405065040001"/>
          <site name="sart_l_sart_l-P5" pos="0.014112701329919998 -0.084393790439400013 0.0026688808018600001"/>
          <site name="semimem_l_semimem_l-P2" pos="-0.0300932601888 -0.043447173596580006 0.020119255275560001"/>
          <site name="SM_at_condyles_l_cylinder_semimem_l_1_sidesite" pos="-0.03009 -0.04345 0.02012" size="0.0005"/>
          <site name="semiten_l_semiten_l-P2" pos="-0.03237619716864 -0.052928451287920002 0.023506680908690004"/>
          <site name="semiten_l_semiten_l-P3" pos="0.0019716273916799997 -0.08053876544402 0.012009963608370002"/>
          <site name="ST_at_condyles_l_cylinder_semiten_l_1_sidesite" pos="-0.03443 -0.002247 0.02404" size="0.0005"/>
          <site name="soleus_l_soleus_l-P1" pos="-0.0078865095667199989 -0.095437916101840006 -0.01005962763778"/>
          <site name="tfl_l_tfl_l-P4" pos="0.011207145173759999 -0.042717844543400003 -0.035516644517059999"/>
          <site name="tibant_l_tibant_l-P1" pos="0.015980558858880001 -0.13669710253888001 -0.016629180380820001"/>
          <site name="tibant_l_tibant_l-P2" pos="0.026046235542719998 -0.19858588219444001 -0.013139105486080003"/>
          <site name="tibant_l_tibant_l-P3" pos="0.02417837801376 -0.38123071508366002 0.013549702532520001"/>
          <site name="tibpost_l_tibpost_l-P1" pos="-0.0042545643715200003 -0.13586358362095999 -0.010572873945830001"/>
          <site name="tibpost_l_tibpost_l-P2" pos="-0.017018257486080001 -0.3808139556247 0.017963620781750005"/>
          <site name="vasint_l_vasint_l-P5" pos="0.033797844287904 -0.065847994515680006 -0.00044139182492300004"/>
          <site name="vaslat_l_vaslat_l-P5" pos="0.033766713329087997 -0.066035536272212009 -0.0052453772682710008"/>
          <site name="vasmed_l_vasmed_l-P5" pos="0.033102586207679995 -0.06623349701521801 0.0069596199371579999"/>
          <site name="LLM_marker" group="4" pos="-0.007175 -0.4254 -0.05952" rgba="1 0.1 0.5 0.5" size="0.01"/>
          <site name="LMM_marker" group="4" pos="0.00403 -0.4117 0.04885" rgba="1 0.1 0.5 0.5" size="0.01"/>
          <site name="LS1_marker" group="4" pos="0.02882 -0.2117 -0.002826" rgba="1 0.1 0.5 0.5" size="0.01"/>
          <site name="LS2_marker" group="4" pos="0.02533 -0.1737 -0.05982" rgba="1 0.1 0.5 0.5" size="0.01"/>
          <site name="LS3_marker" group="4" pos="0.02842 -0.09669 -0.001971" rgba="1 0.1 0.5 0.5" size="0.01"/>
        </body>
        <body name="patella_l" pos="-0.00906 -0.4578 0.003048" euler="-0 0 0">
          <inertial mass="0.071344156094027403" pos="0.0018 0.0264 0" fullinertia="2.3753796750563648e-06 1.0850601930309737e-05 1.0850601930309737e-05 0 0 0"/>
          <geom name="patella_l_geom_1" type="mesh" mesh="patella_l_geom_1_l_patella" rgba="1 1 1 1" group="0"/>
          <joint name="patellofemoral_l_translation1" range="-0.02542 0.05868" limited="true" user="0.05870274596325426" ref="0" axis="1 0 0" type="slide"/>
          <joint name="patellofemoral_l_translation2" range="-0.04579 -0.01212" limited="true" user="-0.01215206102797061" ref="0" axis="0 1 0" type="slide"/>
          <joint name="patellofemoral_l_translation3" limited="false" ref="0" axis="0 0 1" type="slide"/>
          <joint name="patellofemoral_l_rotation1" range="-1.786 0.001137" limited="true" user="0.01050598499723554" ref="0" axis="0 0 1" type="hinge"/>
          <site name="recfem_l_recfem_l-P2" pos="0.01 0.049000000000000002 -0.00069999999999999999"/>
          <site name="recfem_l_recfem_l-P3" pos="0.0121 0.043700000000000003 0.001"/>
          <site name="recfem_l_recfem_l-P4" pos="0.0050000000000000001 0.00247 -3.0000000000000001e-05"/>
          <site name="vasint_l_vasint_l-P3" pos="0.0057999999999999996 0.048000000000000001 0.00059999999999999995"/>
          <site name="vasint_l_vasint_l-P4" pos="0.0050000000000000001 0.00247 0.00038999999999999999"/>
          <site name="vaslat_l_vaslat_l-P3" pos="0.0103 0.042299999999999997 -0.0141"/>
          <site name="vaslat_l_vaslat_l-P4" pos="0.0050000000000000001 0.00247 -0.0073299999999999997"/>
          <site name="vasmed_l_vasmed_l-P3" pos="0.0063 0.044499999999999998 0.017000000000000001"/>
          <site name="vasmed_l_vasmed_l-P4" pos="0.0050000000000000001 0.00247 0.0085000000000000006"/>
        </body>
        <site name="addbrev_l_addbrev_l-P2" pos="-0.0022397408346000003 -0.132427606182 -0.02760185174727"/>
        <site name="AB_at_femshaft_l_cylinder_addbrev_l_1_sidesite" pos="0.001478 -0.1191 -0.0159" size="0.0005"/>
        <site name="addlong_l_addlong_l-P2" pos="0.012609740898797999 -0.26863725501512997 -0.017547683259409003"/>
        <site name="AL_at_femshaft_l_cylinder_addlong_l_1_sidesite" pos="0.01261 -0.2686 -0.01755" size="0.0005"/>
        <site name="addmagDist_l_addmagDist_l-P2" pos="0.012598542194624999 -0.29459531036250003 -0.021394206374390004"/>
        <site name="AMdist_at_femshaft_l_cylinder_addmagDist_l_1_sidesite" pos="0.0126 -0.2946 -0.02139" size="0.0005"/>
        <site name="addmagIsch_l_addmagIsch_l-P2" pos="0.0053865767072130005 -0.43540625737652999 0.036281470188279007"/>
        <site name="AMisch_at_condyles_l_cylinder_addmagIsch_l_1_sidesite" pos="0.005387 -0.4354 0.03628" size="0.0005"/>
        <site name="addmagMid_l_addmagMid_l-P2" pos="0.0027100864098660001 -0.18225629867759999 -0.032390606749205998"/>
        <site name="AMmid_at_femshaft_l_cylinder_addmagMid_l_1_sidesite" pos="0.00271 -0.1823 -0.03239" size="0.0005"/>
        <site name="addmagProx_l_addmagProx_l-P2" pos="-0.017100421272171002 -0.088502042572140005 -0.035494429435645999"/>
        <site name="AMprox_at_femshaft_l_cylinder_addmagProx_l_1_sidesite" pos="-0.01787 -0.08231 -0.02184" size="0.0005"/>
        <site name="bfsh_l_bfsh_l-P1" pos="0.0055993520865 -0.23691074292390002 -0.025939089593820002"/>
        <site name="gaslat_l_gaslat_l-P1" pos="-0.0033596112519000002 -0.4280329576086 -0.030705674433710001"/>
        <site name="Gastroc_at_condyles_l_cylinder_gaslat_l_1_sidesite" pos="-0.01055 -0.4795 -0.0276" size="0.0005"/>
        <site name="gasmed_l_gasmed_l-P1" pos="0.0089589633384000011 -0.42511506120120002 0.023056968527840001"/>
        <site name="Gastroc_at_condyles_l_cylinder_gasmed_l_1_sidesite" pos="-3.325e-05 -0.4783 0.02187" size="0.0005"/>
        <site name="glmax1_l_glmax1_l-P3" pos="-0.049722246528120004 -0.036585931877399995 -0.033476944689460005"/>
        <site name="glmax1_l_glmax1_l-P4" pos="-0.031020410559209999 -0.063520360253399993 -0.052099880808100005"/>
        <site name="glmax2_l_glmax2_l-P3" pos="-0.050394168778499997 -0.065540442381600006 -0.02793440417796"/>
        <site name="glmax2_l_glmax2_l-P4" pos="-0.01746997850988 -0.11402241345839999 -0.04644648948637"/>
        <site name="glmax3_l_glmax3_l-P3" pos="-0.031468358726129998 -0.12625513301249999 -0.010419976161620001"/>
        <site name="glmax3_l_glmax3_l-P4" pos="-0.0067192225038000004 -0.15924980777309999 -0.045559683004529998"/>
        <site name="glmed1_l_glmed1_l-P2" pos="-0.015678185842200001 -0.020200821281999997 -0.065401978035699998"/>
        <site name="glmed2_l_glmed2_l-P2" pos="-0.024637149180600001 -0.01122267849 -0.062076453728800003"/>
        <site name="glmed3_l_glmed3_l-P2" pos="-0.03460399589457 -0.0052746588903000002 -0.057420719699140005"/>
        <site name="glmin1_l_glmin1_l-P2" pos="0.0055993520865 -0.016834017734999998 -0.062076453728800003"/>
        <site name="glmin2_l_glmin2_l-P2" pos="0.0044794816692000005 -0.010100410640999999 -0.057642421319599998"/>
        <site name="glmin3_l_glmin3_l-P2" pos="-0.0044794816692000005 -0.001122267849 -0.056533913217300003"/>
        <site name="iliacus_l_iliacus_l-P3" pos="-0.0025757019597900002 -0.063408133468499994 -0.015408262621970001"/>
        <site name="iliacus_l_iliacus_l-P4" pos="-0.013662419091060002 -0.071488461981300003 -0.021726758805080001"/>
        <site name="piri_l_piri_l-P3" pos="-0.016574082176040002 -0.0040401642563999999 -0.048441804070510006"/>
        <site name="psoas_l_psoas_l-P3" pos="-0.01478228950836 -0.052409908548300001 -0.0050991372705800004"/>
        <site name="psoas_l_psoas_l-P4" pos="-0.02631695480655 -0.058806835287600001 -0.0097548713002400013"/>
        <site name="KnExt_at_fem_l_cylinder_recfem_l_3_sidesite" pos="-0.01901 -0.448 0.0149" size="0.0005"/>
        <site name="KnExt_at_fem_l_cylinder_recfem_l_2_sidesite" pos="0.00304 -0.4141 0.004048" size="0.0005"/>
        <site name="sart_l_sart_l-P2" pos="-0.0033596112519000002 -0.40042516852319998 0.046668191106830001"/>
        <site name="tfl_l_tfl_l-P2" pos="0.03292419026862 -0.11166565097550001 -0.06617793370731001"/>
        <site name="tfl_l_tfl_l-P3" pos="0.01198261346511 -0.45451847884500002 -0.035915662514520004"/>
        <site name="vasint_l_vasint_l-P1" pos="0.032476242101700005 -0.21592433414759998 -0.0343637511713"/>
        <site name="vasint_l_vasint_l-P2" pos="0.037515658979550004 -0.23388061973159999 -0.031592480915550003"/>
        <site name="KnExt_at_fem_l_cylinder_vasint_l_3_sidesite" pos="-0.01915 -0.447 0.01444" size="0.0005"/>
        <site name="vaslat_l_vaslat_l-P1" pos="0.0053753780030399998 -0.20806845920460001 -0.038686932770270001"/>
        <site name="vaslat_l_vaslat_l-P2" pos="0.030124514225370002 -0.2907795996759 -0.045337981384070004"/>
        <site name="KnExt_at_fem_l_cylinder_vaslat_l_3_sidesite" pos="-0.02302 -0.448 -0.01212" size="0.0005"/>
        <site name="KnExt_at_fem_l_cylinder_vaslat_l_2_sidesite" pos="0.00124 -0.4155 -0.01105" size="0.0005"/>
        <site name="vasmed_l_vasmed_l-P1" pos="0.015678185842200001 -0.2355640215051 -0.020839952323240003"/>
        <site name="vasmed_l_vasmed_l-P2" pos="0.039867386855880003 -0.31075596738809996 -0.00099765729207000001"/>
        <site name="KnExt_at_fem_l_cylinder_vasmed_l_4_sidesite" pos="-0.01029 -0.4579 0.02224" size="0.0005"/>
        <site name="KnExt_at_fem_l_cylinder_vasmed_l_3_sidesite" pos="-0.01029 -0.4579 0.02224" size="0.0005"/>
        <site name="LLFE_marker" group="4" pos="-0.001173 -0.456 -0.07108" rgba="1 0.1 0.5 0.5" size="0.01"/>
        <site name="LMFE_marker" group="4" pos="-0.004447 -0.4545 0.0605" rgba="1 0.1 0.5 0.5" size="0.01"/>
        <site name="LT1_marker" group="4" pos="0.0775 -0.3281 -0.05544" rgba="1 0.1 0.5 0.5" size="0.01"/>
        <site name="LT2_marker" group="4" pos="0.1021 -0.2773 0.02321" rgba="1 0.1 0.5 0.5" size="0.01"/>
        <site name="LT3_marker" group="4" pos="0.0862 -0.2281 -0.07144" rgba="1 0.1 0.5 0.5" size="0.01"/>
        <site name="LTRC_marker" group="4" pos="-0.02053 -0.02232 -0.09983" rgba="1 0.1 0.5 0.5" size="0.01"/>
      </body>
      <body name="torso" pos="-0.1092 0.0888 0" euler="-0 0 0">
        <inertial mass="36.8945567461" pos="-0.0300000000 0.3200000000 0.0000000000" fullinertia="1.5889727345 0.8141532051 1.5425266681 0.0000000000 0.0000000000 0.0000000000"/>
        <geom name="torso_geom_1" type="mesh" mesh="torso_geom_1_hat_spine" rgba="1 1 1 1" group="0"/>
        <geom name="torso_geom_2" type="mesh" mesh="torso_geom_2_hat_jaw" rgba="1 1 1 1" group="0"/>
        <geom name="torso_geom_3" type="mesh" mesh="torso_geom_3_hat_skull" rgba="1 1 1 1" group="0"/>
        <geom name="torso_geom_4" type="mesh" mesh="torso_geom_4_hat_ribs_scap" rgba="1 1 1 1" group="0"/>
        <joint name="lumbar_extension" range="-1.571 1.571" limited="true" user="0.0" ref="0" axis="0 0 1" type="hinge"/>
        <joint name="lumbar_bending" range="-1.571 1.571" limited="true" user="0.0" ref="0" axis="1 0 0" type="hinge"/>
        <joint name="lumbar_rotation" range="-1.571 1.571" limited="true" user="0.0" ref="0" axis="0 1 0" type="hinge"/>
        <site name="C7_marker" group="4" pos="-0.09637 0.3974 -0.000979" rgba="1 0.1 0.5 0.5" size="0.01"/>
        <site name="CLAV_marker" group="4" pos="0.07516 0.3768 -0.0003446" rgba="1 0.1 0.5 0.5" size="0.01"/>
        <site name="LACR_marker" group="4" pos="0.001776 0.4039 -0.1595" rgba="1 0.1 0.5 0.5" size="0.01"/>
        <site name="RACR_marker" group="4" pos="0.001989 0.4018 0.1587" rgba="1 0.1 0.5 0.5" size="0.01"/>
      </body>
      <site name="addbrev_r_addbrev_r-P1" pos="-0.02070549626933 -0.1024147631674 0.017825420040120003"/>
      <site name="addlong_r_addlong_r-P1" pos="-0.0082171550639540004 -0.096858217506190003 0.021853501971264001"/>
      <site name="addmagDist_r_addmagDist_r-P1" pos="-0.080263609622051993 -0.139098859718957 0.046091443246596003"/>
      <site name="addmagIsch_r_addmagIsch_r-P1" pos="-0.097153223856405999 -0.14137595392129598 0.048279108433337999"/>
      <site name="addmagMid_r_addmagMid_r-P1" pos="-0.057086462489157996 -0.13155938991982499 0.033034901814612001"/>
      <site name="addmagProx_r_addmagProx_r-P1" pos="-0.033584098137374001 -0.11717774232610501 0.015799804126470002"/>
      <site name="bflh_r_bflh_r-P1" pos="-0.11274196921519999 -0.12976168397061 0.067829195737080003"/>
      <site name="glmax1_r_glmax1_r-P1" pos="-0.13344746548452999 0.037588397119950004 0.065166957679140006"/>
      <site name="glmax1_r_glmax1_r-P2" pos="-0.13626601471491001 -0.026366353921820001 0.090168845527620001"/>
      <site name="Gmax1_at_pelvis_r_cylinder_glmax1_r_2_sidesite" pos="-0.1164 -0.1008 0.1156" size="0.0005"/>
      <site name="glmax2_r_glmax2_r-P1" pos="-0.14277035909271002 0.0094788131867699996 0.053476260120359997"/>
      <site name="glmax2_r_glmax2_r-P2" pos="-0.14569731406271999 -0.066351692307390006 0.094104327874139998"/>
      <site name="Gmax2_at_pelvis_r_cylinder_glmax2_r_2_sidesite" pos="-0.1305 -0.104 0.1044" size="0.0005"/>
      <site name="Gmax2_at_pelvis_r_cylinder_glmax2_r_1_sidesite" pos="-0.1457 -0.06635 0.0941" size="0.0005"/>
      <site name="glmax3_r_glmax3_r-P1" pos="-0.14092746151900001 -0.057199734747749996 0.0104174532702"/>
      <site name="glmax3_r_glmax3_r-P2" pos="-0.13800050654898999 -0.13760621902173001 0.050351024139299996"/>
      <site name="glmed1_r_glmed1_r-P1" pos="-0.053267768386778699 0.028494462889670304 0.13344569562338632"/>
      <site name="glmed2_r_glmed2_r-P1" pos="-0.091849283811356305 0.059524677321407975 0.094895499312957793"/>
      <site name="glmed3_r_glmed3_r-P1" pos="-0.10826025808249416 0.016952245841199941 0.07396580338766244"/>
      <site name="glmin1_r_glmin1_r-P1" pos="-0.032065913360424338 -0.0001179040676096595 0.13711047814873908"/>
      <site name="glmin2_r_glmin2_r-P1" pos="-0.066777933957939684 0.010895477953799903 0.11707519576131367"/>
      <site name="glmin3_r_glmin3_r-P1" pos="-0.085532128568069993 -0.01688754073505 0.092368085662439994"/>
      <site name="grac_r_grac_r-P1" pos="-0.051340958288767995 -0.14089656566817199 0.028428072479567999"/>
      <site name="iliacus_r_iliacus_r-P1" pos="-0.06558547247615 0.033666129594389999 0.097576812297540005"/>
      <site name="iliacus_r_iliacus_r-P2" pos="-0.014634774850049999 -0.060686194770469999 0.087506607469680003"/>
      <site name="IL_at_brim_r_cylinder_iliacus_r_2_sidesite" pos="-0.02112 -0.09422 0.09452" size="0.0005"/>
      <site name="piri_r_piri_r-P1" pos="-0.11036788351730299 -0.0071145574838630005 0.015637754853378"/>
      <site name="piri_r_piri_r-P2" pos="-0.110595535570526 -0.033404645092686001 0.070514583691175997"/>
      <site name="psoas_r_psoas_r-P1" pos="-0.065693878215780002 0.067550162940199998 0.045142297504199999"/>
      <site name="psoas_r_psoas_r-P2" pos="-0.02222317662415 -0.071254526714340002 0.075931659391680006"/>
      <site name="PS_at_brim_r_cylinder_psoas_r_2_sidesite" pos="-0.03506 -0.09699 0.08291" size="0.0005"/>
      <site name="recfem_r_recfem_r-P1" pos="-0.0260173775112 -0.042273327775479999 0.10799426556774"/>
      <site name="sart_r_sart_r-P1" pos="-0.021139119227850001 -0.01699649261076 0.12223145170368001"/>
      <site name="semimem_r_semimem_r-P1" pos="-0.10699646501481 -0.12420513830940001 0.071070181198920002"/>
      <site name="semiten_r_semiten_r-P1" pos="-0.11252515773594 -0.13651670026463 0.059610982601699995"/>
      <site name="tfl_r_tfl_r-P1" pos="-0.022049495182108598 0.01182274541288353 0.14966123797021802"/>
      <site name="addbrev_l_addbrev_l-P1" pos="-0.02070549626933 -0.1024147631674 -0.017825420040120003"/>
      <site name="addlong_l_addlong_l-P1" pos="-0.0082171550639540004 -0.096858217506190003 -0.021853501971264001"/>
      <site name="addmagDist_l_addmagDist_l-P1" pos="-0.080263609622051993 -0.139098859718957 -0.046091443246596003"/>
      <site name="addmagIsch_l_addmagIsch_l-P1" pos="-0.097153223856405999 -0.14137595392129598 -0.048279108433337999"/>
      <site name="addmagMid_l_addmagMid_l-P1" pos="-0.057086462489157996 -0.13155938991982499 -0.033034901814612001"/>
      <site name="addmagProx_l_addmagProx_l-P1" pos="-0.033584098137374001 -0.11717774232610501 -0.015799804126470002"/>
      <site name="bflh_l_bflh_l-P1" pos="-0.11274196921519999 -0.12976168397061 -0.067829195737080003"/>
      <site name="glmax1_l_glmax1_l-P1" pos="-0.13344746548452999 0.037588397119950004 -0.065166957679140006"/>
      <site name="glmax1_l_glmax1_l-P2" pos="-0.13626601471491001 -0.026366353921820001 -0.090168845527620001"/>
      <site name="Gmax1_at_pelvis_l_cylinder_glmax1_l_2_sidesite" pos="-0.1164 -0.1008 -0.1156" size="0.0005"/>
      <site name="glmax2_l_glmax2_l-P1" pos="-0.14277035909271002 0.0094788131867699996 -0.053476260120359997"/>
      <site name="glmax2_l_glmax2_l-P2" pos="-0.14569731406271999 -0.066351692307390006 -0.094104327874139998"/>
      <site name="Gmax2_at_pelvis_l_cylinder_glmax2_l_2_sidesite" pos="-0.1305 -0.104 -0.1044" size="0.0005"/>
      <site name="Gmax2_at_pelvis_l_cylinder_glmax2_l_1_sidesite" pos="-0.1457 -0.06635 -0.0941" size="0.0005"/>
      <site name="glmax3_l_glmax3_l-P1" pos="-0.14092746151900001 -0.057199734747749996 -0.0104174532702"/>
      <site name="glmax3_l_glmax3_l-P2" pos="-0.13800050654898999 -0.13760621902173001 -0.050351024139299996"/>
      <site name="glmed1_l_glmed1_l-P1" pos="-0.0531188124187 0.0283274876846 -0.13311190289700001"/>
      <site name="glmed2_l_glmed2_l-P1" pos="-0.092144878685500003 0.059923531640500002 -0.094914574239600008"/>
      <site name="glmed3_l_glmed3_l-P1" pos="-0.10840573963 0.017432300113600002 -0.074079667699200005"/>
      <site name="glmin1_l_glmin1_l-P1" pos="-0.032521721888999995 0 -0.13658438732039999"/>
      <site name="glmin2_l_glmin2_l-P1" pos="-0.066777935612079994 0.010895187571 -0.11690697558780001"/>
      <site name="glmin3_l_glmin3_l-P1" pos="-0.085532128568069993 -0.01688754073505 -0.092368085662439994"/>
      <site name="grac_l_grac_l-P1" pos="-0.051340958288767995 -0.14089656566817199 -0.028428072479567999"/>
      <site name="iliacus_l_iliacus_l-P1" pos="-0.06558547247615 0.033666129594389999 -0.097576812297540005"/>
      <site name="iliacus_l_iliacus_l-P2" pos="-0.014634774850049999 -0.060686194770469999 -0.087506607469680003"/>
      <site name="IL_at_brim_l_cylinder_iliacus_l_2_sidesite" pos="-0.02112 -0.09422 -0.09452" size="0.0005"/>
      <site name="piri_l_piri_l-P1" pos="-0.11036788351730299 -0.0071145574838630005 -0.015637754853378"/>
      <site name="piri_l_piri_l-P2" pos="-0.110595535570526 -0.033404645092686001 -0.070514583691175997"/>
      <site name="psoas_l_psoas_l-P1" pos="-0.065693878215780002 0.067550162940199998 -0.045142297504199999"/>
      <site name="psoas_l_psoas_l-P2" pos="-0.02222317662415 -0.071254526714340002 -0.075931659391680006"/>
      <site name="PS_at_brim_l_cylinder_psoas_l_2_sidesite" pos="-0.03506 -0.09699 -0.08291" size="0.0005"/>
      <site name="recfem_l_recfem_l-P1" pos="-0.0260173775112 -0.042273327775479999 -0.10799426556774"/>
      <site name="sart_l_sart_l-P1" pos="-0.021139119227850001 -0.01699649261076 -0.12223145170368001"/>
      <site name="semimem_l_semimem_l-P1" pos="-0.10699646501481 -0.12420513830940001 -0.071070181198920002"/>
      <site name="semiten_l_semiten_l-P1" pos="-0.11252515773594 -0.13651670026463 -0.059610982601699995"/>
      <site name="tfl_l_tfl_l-P1" pos="-0.021681147926 0.0119847063281 -0.14931683020620001"/>
      <site name="LASI_marker" group="4" pos="0.02549 0.01216 -0.1472" rgba="1 0.1 0.5 0.5" size="0.01"/>
      <site name="RASI_marker" group="4" pos="0.02522 0.01519 0.1481" rgba="1 0.1 0.5 0.5" size="0.01"/>
      <site name="SACR_marker" group="4" pos="-0.2084 0.02576 0.001144" rgba="1 0.1 0.5 0.5" size="0.01"/>
    </body>
  </worldbody>
  <asset>
    <texture type="skybox" builtin="gradient" rgb1="1 1 1" rgb2="0.6 0.8 1" width="256" height="256"/>
    <mesh name="pelvis_geom_1_r_pelvis" file="Geometry/r_pelvis.stl" scale="1.0840573963 1.0895187571 1.1574948078"/>
    <mesh name="pelvis_geom_2_l_pelvis" file="Geometry/l_pelvis.stl" scale="1.0840573963 1.0895187571 1.1574948078"/>
    <mesh name="pelvis_geom_3_sacrum" file="Geometry/sacrum.stl" scale="1.0840573963 1.0895187571 1.1574948078"/>
    <mesh name="femur_r_geom_1_r_femur" file="Geometry/r_femur.stl" scale="1.1198704173 1.122267849 1.1085081023000001"/>
    <mesh name="tibia_r_geom_1_r_tibia" file="Geometry/r_tibia.stl" scale="1.0376986271999999 1.0418986474 1.0264926161000001"/>
    <mesh name="tibia_r_geom_2_r_fibula" file="Geometry/r_fibula.stl" scale="1.0376986271999999 1.0418986474 1.0264926161000001"/>
    <mesh name="talus_r_geom_1_r_talus" file="Geometry/r_talus.stl" scale="1.2700435902 1.3070374730000001 1.2825100691"/>
    <mesh name="calcn_r_geom_1_r_foot" file="Geometry/r_foot.stl" scale="1.1133100276000001 1.1038297479000001 1.1112311964999999"/>
    <mesh name="toes_r_geom_1_r_bofoot" file="Geometry/r_bofoot.stl" scale="1.1327824314999999 1.1324989244000001 1.1327982511000001"/>
    <mesh name="patella_r_geom_1_r_patella" file="Geometry/r_patella.stl" scale="1 1 1"/>
    <mesh name="femur_l_geom_1_l_femur" file="Geometry/l_femur.stl" scale="1.1198704173 1.122267849 1.1085081023000001"/>
    <mesh name="tibia_l_geom_1_l_tibia" file="Geometry/l_tibia.stl" scale="1.0376986271999999 1.0418986474 1.0264926161000001"/>
    <mesh name="tibia_l_geom_2_l_fibula" file="Geometry/l_fibula.stl" scale="1.0376986271999999 1.0418986474 1.0264926161000001"/>
    <mesh name="talus_l_geom_1_l_talus" file="Geometry/l_talus.stl" scale="1.2700435902 1.3070374730000001 1.2825100691"/>
    <mesh name="calcn_l_geom_1_l_foot" file="Geometry/l_foot.stl" scale="1.1133100276000001 1.1038297479000001 1.1112311964999999"/>
    <mesh name="toes_l_geom_1_l_bofoot" file="Geometry/l_bofoot.stl" scale="1.1327824314999999 1.1324989244000001 1.1327982511000001"/>
    <mesh name="patella_l_geom_1_l_patella" file="Geometry/l_patella.stl" scale="1 1 1"/>
    <mesh name="torso_geom_1_hat_spine" file="Geometry/hat_spine.stl" scale="1.1762715912999999 0.95209158439999997 1.1209076874999999"/>
    <mesh name="torso_geom_2_hat_jaw" file="Geometry/hat_jaw.stl" scale="1.1762715912999999 0.95209158439999997 1.1209076874999999"/>
    <mesh name="torso_geom_3_hat_skull" file="Geometry/hat_skull.stl" scale="1.1762715912999999 0.95209158439999997 1.1209076874999999"/>
    <mesh name="torso_geom_4_hat_ribs_scap" file="Geometry/hat_ribs_scap.stl" scale="1.1762715912999999 0.95209158439999997 1.1209076874999999"/>
  </asset>
  <tendon>
    <!-- Leave this comment here to make 'tendon' element pretty printed !-->
    <spatial name="addbrev_r_tendon">
      <site site="addbrev_r_addbrev_r-P1"/>
      <geom geom="AB_at_femshaft_r_cylinder" sidesite="AB_at_femshaft_r_cylinder_addbrev_r_1_sidesite"/>
      <site site="addbrev_r_addbrev_r-P2"/>
    </spatial>
    <spatial name="addlong_r_tendon">
      <site site="addlong_r_addlong_r-P1"/>
      <geom geom="AL_at_femshaft_r_cylinder" sidesite="AL_at_femshaft_r_cylinder_addlong_r_1_sidesite"/>
      <site site="addlong_r_addlong_r-P2"/>
    </spatial>
    <spatial name="addmagDist_r_tendon">
      <site site="addmagDist_r_addmagDist_r-P1"/>
      <geom geom="AMdist_at_femshaft_r_cylinder" sidesite="AMdist_at_femshaft_r_cylinder_addmagDist_r_1_sidesite"/>
      <site site="addmagDist_r_addmagDist_r-P2"/>
    </spatial>
    <spatial name="addmagIsch_r_tendon">
      <site site="addmagIsch_r_addmagIsch_r-P1"/>
      <geom geom="AMisch_at_condyles_r_cylinder" sidesite="AMisch_at_condyles_r_cylinder_addmagIsch_r_1_sidesite"/>
      <site site="addmagIsch_r_addmagIsch_r-P2"/>
    </spatial>
    <spatial name="addmagMid_r_tendon">
      <site site="addmagMid_r_addmagMid_r-P1"/>
      <geom geom="AMmid_at_femshaft_r_cylinder" sidesite="AMmid_at_femshaft_r_cylinder_addmagMid_r_1_sidesite"/>
      <site site="addmagMid_r_addmagMid_r-P2"/>
    </spatial>
    <spatial name="addmagProx_r_tendon">
      <site site="addmagProx_r_addmagProx_r-P1"/>
      <geom geom="AMprox_at_femshaft_r_cylinder" sidesite="AMprox_at_femshaft_r_cylinder_addmagProx_r_1_sidesite"/>
      <site site="addmagProx_r_addmagProx_r-P2"/>
    </spatial>
    <spatial name="bflh_r_tendon">
      <site site="bflh_r_bflh_r-P1"/>
      <site site="bflh_r_bflh_r-P2"/>
      <site site="bflh_r_bflh_r-P3"/>
    </spatial>
    <spatial name="bfsh_r_tendon">
      <site site="bfsh_r_bfsh_r-P1"/>
      <site site="bfsh_r_bfsh_r-P2"/>
    </spatial>
    <spatial name="edl_r_tendon">
      <site site="edl_r_edl_r-P1"/>
      <site site="edl_r_edl_r-P2"/>
      <site site="edl_r_edl_r-P3"/>
      <site site="edl_r_edl_r-P4"/>
      <site site="edl_r_edl_r-P5"/>
      <site site="edl_r_edl_r-P6"/>
    </spatial>
    <spatial name="ehl_r_tendon">
      <site site="ehl_r_ehl_r-P1"/>
      <site site="ehl_r_ehl_r-P2"/>
      <site site="ehl_r_ehl_r-P3"/>
      <site site="ehl_r_ehl_r-P4"/>
      <site site="ehl_r_ehl_r-P5"/>
      <site site="ehl_r_ehl_r-P6"/>
      <site site="ehl_r_ehl_r-P7"/>
      <site site="ehl_r_ehl_r-P8"/>
    </spatial>
    <spatial name="fdl_r_tendon">
      <site site="fdl_r_fdl_r-P1"/>
      <site site="fdl_r_fdl_r-P2"/>
      <site site="fdl_r_fdl_r-P3"/>
      <site site="fdl_r_fdl_r-P4"/>
      <site site="fdl_r_fdl_r-P5"/>
      <site site="fdl_r_fdl_r-P6"/>
      <site site="fdl_r_fdl_r-P7"/>
      <site site="fdl_r_fdl_r-P8"/>
    </spatial>
    <spatial name="fhl_r_tendon">
      <site site="fhl_r_fhl_r-P1"/>
      <site site="fhl_r_fhl_r-P2"/>
      <site site="fhl_r_fhl_r-P3"/>
      <site site="fhl_r_fhl_r-P4"/>
      <site site="fhl_r_fhl_r-P5"/>
      <site site="fhl_r_fhl_r-P6"/>
      <site site="fhl_r_fhl_r-P7"/>
    </spatial>
    <spatial name="gaslat_r_tendon">
      <site site="gaslat_r_gaslat_r-P1"/>
      <geom geom="Gastroc_at_condyles_r_cylinder" sidesite="Gastroc_at_condyles_r_cylinder_gaslat_r_1_sidesite"/>
      <site site="gaslat_r_gaslat_r-P2"/>
    </spatial>
    <spatial name="gasmed_r_tendon">
      <site site="gasmed_r_gasmed_r-P1"/>
      <geom geom="Gastroc_at_condyles_r_cylinder" sidesite="Gastroc_at_condyles_r_cylinder_gasmed_r_1_sidesite"/>
      <site site="gasmed_r_gasmed_r-P2"/>
    </spatial>
    <spatial name="glmax1_r_tendon">
      <site site="glmax1_r_glmax1_r-P1"/>
      <site site="glmax1_r_glmax1_r-P2"/>
      <geom geom="Gmax1_at_pelvis_r_cylinder" sidesite="Gmax1_at_pelvis_r_cylinder_glmax1_r_2_sidesite"/>
      <site site="glmax1_r_glmax1_r-P3"/>
      <site site="glmax1_r_glmax1_r-P4"/>
    </spatial>
    <spatial name="glmax2_r_tendon">
      <site site="glmax2_r_glmax2_r-P1"/>
      <geom geom="Gmax2_at_pelvis_r_cylinder" sidesite="Gmax2_at_pelvis_r_cylinder_glmax2_r_1_sidesite"/>
      <site site="glmax2_r_glmax2_r-P2"/>
      <geom geom="Gmax2_at_pelvis_r_cylinder" sidesite="Gmax2_at_pelvis_r_cylinder_glmax2_r_2_sidesite"/>
      <site site="glmax2_r_glmax2_r-P3"/>
      <site site="glmax2_r_glmax2_r-P4"/>
    </spatial>
    <spatial name="glmax3_r_tendon">
      <site site="glmax3_r_glmax3_r-P1"/>
      <site site="glmax3_r_glmax3_r-P2"/>
      <site site="glmax3_r_glmax3_r-P3"/>
      <site site="glmax3_r_glmax3_r-P4"/>
    </spatial>
    <spatial name="glmed1_r_tendon">
      <site site="glmed1_r_glmed1_r-P1"/>
      <site site="glmed1_r_glmed1_r-P2_0"/>
    </spatial>
    <spatial name="glmed2_r_tendon">
      <site site="glmed2_r_glmed2_r-P1"/>
      <site site="glmed2_r_glmed2_r-P2_0"/>
    </spatial>
    <spatial name="glmed3_r_tendon">
      <site site="glmed3_r_glmed3_r-P1"/>
      <site site="glmed3_r_glmed3_r-P2_0"/>
    </spatial>
    <spatial name="glmin1_r_tendon">
      <site site="glmin1_r_glmin1_r-P1"/>
      <site site="glmin1_r_glmin1_r-P2"/>
    </spatial>
    <spatial name="glmin2_r_tendon">
      <site site="glmin2_r_glmin2_r-P1"/>
      <site site="glmin2_r_glmin2_r-P2"/>
    </spatial>
    <spatial name="glmin3_r_tendon">
      <site site="glmin3_r_glmin3_r-P1"/>
      <site site="glmin3_r_glmin3_r-P2"/>
    </spatial>
    <spatial name="grac_r_tendon">
      <site site="grac_r_grac_r-P1"/>
      <geom geom="GR_at_condyles_r_cylinder" sidesite="GR_at_condyles_r_cylinder_grac_r_1_sidesite"/>
      <site site="grac_r_grac_r-P2"/>
      <site site="grac_r_grac_r-P3"/>
    </spatial>
    <spatial name="iliacus_r_tendon">
      <site site="iliacus_r_iliacus_r-P1"/>
      <site site="iliacus_r_iliacus_r-P2"/>
      <geom geom="IL_at_brim_r_cylinder" sidesite="IL_at_brim_r_cylinder_iliacus_r_2_sidesite"/>
      <site site="iliacus_r_iliacus_r-P3"/>
      <site site="iliacus_r_iliacus_r-P4"/>
    </spatial>
    <spatial name="perbrev_r_tendon">
      <site site="perbrev_r_perbrev_r-P1"/>
      <site site="perbrev_r_perbrev_r-P2"/>
      <site site="perbrev_r_perbrev_r-P3"/>
      <site site="perbrev_r_perbrev_r-P4"/>
      <site site="perbrev_r_perbrev_r-P5"/>
    </spatial>
    <spatial name="perlong_r_tendon">
      <site site="perlong_r_perlong_r-P1"/>
      <site site="perlong_r_perlong_r-P2"/>
      <site site="perlong_r_perlong_r-P3"/>
      <site site="perlong_r_perlong_r-P4"/>
      <site site="perlong_r_perlong_r-P5"/>
      <site site="perlong_r_perlong_r-P6"/>
      <site site="perlong_r_perlong_r-P7"/>
    </spatial>
    <spatial name="piri_r_tendon">
      <site site="piri_r_piri_r-P1"/>
      <site site="piri_r_piri_r-P2"/>
      <site site="piri_r_piri_r-P3"/>
    </spatial>
    <spatial name="psoas_r_tendon">
      <site site="psoas_r_psoas_r-P1"/>
      <site site="psoas_r_psoas_r-P2"/>
      <geom geom="PS_at_brim_r_cylinder" sidesite="PS_at_brim_r_cylinder_psoas_r_2_sidesite"/>
      <site site="psoas_r_psoas_r-P3"/>
      <site site="psoas_r_psoas_r-P4"/>
    </spatial>
    <spatial name="recfem_r_tendon">
      <site site="recfem_r_recfem_r-P1"/>
      <site site="recfem_r_recfem_r-P2"/>
      <geom geom="KnExt_at_fem_r_cylinder" sidesite="KnExt_at_fem_r_cylinder_recfem_r_2_sidesite"/>
      <site site="recfem_r_recfem_r-P3"/>
      <geom geom="KnExt_at_fem_r_cylinder" sidesite="KnExt_at_fem_r_cylinder_recfem_r_3_sidesite"/>
      <site site="recfem_r_recfem_r-P4"/>
      <site site="recfem_r_recfem_r-P5"/>
    </spatial>
    <spatial name="sart_r_tendon">
      <site site="sart_r_sart_r-P1"/>
      <site site="sart_r_sart_r-P2"/>
      <site site="sart_r_sart_r-P3"/>
      <site site="sart_r_sart_r-P4"/>
      <site site="sart_r_sart_r-P5"/>
    </spatial>
    <spatial name="semimem_r_tendon">
      <site site="semimem_r_semimem_r-P1"/>
      <geom geom="SM_at_condyles_r_cylinder" sidesite="SM_at_condyles_r_cylinder_semimem_r_1_sidesite"/>
      <site site="semimem_r_semimem_r-P2"/>
    </spatial>
    <spatial name="semiten_r_tendon">
      <site site="semiten_r_semiten_r-P1"/>
      <geom geom="ST_at_condyles_r_cylinder" sidesite="ST_at_condyles_r_cylinder_semiten_r_1_sidesite"/>
      <site site="semiten_r_semiten_r-P2"/>
      <site site="semiten_r_semiten_r-P3"/>
    </spatial>
    <spatial name="soleus_r_tendon">
      <site site="soleus_r_soleus_r-P1"/>
      <site site="soleus_r_soleus_r-P2"/>
    </spatial>
    <spatial name="tfl_r_tendon">
      <site site="tfl_r_tfl_r-P1"/>
      <site site="tfl_r_tfl_r-P2"/>
      <site site="tfl_r_tfl_r-P3"/>
      <site site="tfl_r_tfl_r-P4"/>
    </spatial>
    <spatial name="tibant_r_tendon">
      <site site="tibant_r_tibant_r-P1"/>
      <site site="tibant_r_tibant_r-P2"/>
      <site site="tibant_r_tibant_r-P3"/>
      <site site="tibant_r_tibant_r-P4"/>
    </spatial>
    <spatial name="tibpost_r_tendon">
      <site site="tibpost_r_tibpost_r-P1"/>
      <site site="tibpost_r_tibpost_r-P2"/>
      <site site="tibpost_r_tibpost_r-P3"/>
      <site site="tibpost_r_tibpost_r-P4"/>
    </spatial>
    <spatial name="vasint_r_tendon">
      <site site="vasint_r_vasint_r-P1"/>
      <site site="vasint_r_vasint_r-P2"/>
      <site site="vasint_r_vasint_r-P3"/>
      <geom geom="KnExt_at_fem_r_cylinder" sidesite="KnExt_at_fem_r_cylinder_vasint_r_3_sidesite"/>
      <site site="vasint_r_vasint_r-P4"/>
      <site site="vasint_r_vasint_r-P5"/>
    </spatial>
    <spatial name="vaslat_r_tendon">
      <site site="vaslat_r_vaslat_r-P1"/>
      <site site="vaslat_r_vaslat_r-P2"/>
      <geom geom="KnExt_at_fem_r_cylinder" sidesite="KnExt_at_fem_r_cylinder_vaslat_r_2_sidesite"/>
      <site site="vaslat_r_vaslat_r-P3"/>
      <geom geom="KnExt_at_fem_r_cylinder" sidesite="KnExt_at_fem_r_cylinder_vaslat_r_3_sidesite"/>
      <site site="vaslat_r_vaslat_r-P4"/>
      <site site="vaslat_r_vaslat_r-P5"/>
    </spatial>
    <spatial name="vasmed_r_tendon">
      <site site="vasmed_r_vasmed_r-P1"/>
      <site site="vasmed_r_vasmed_r-P2"/>
      <site site="vasmed_r_vasmed_r-P3"/>
      <geom geom="KnExt_at_fem_r_cylinder" sidesite="KnExt_at_fem_r_cylinder_vasmed_r_3_sidesite"/>
      <site site="vasmed_r_vasmed_r-P4"/>
      <geom geom="KnExt_at_fem_r_cylinder" sidesite="KnExt_at_fem_r_cylinder_vasmed_r_4_sidesite"/>
      <site site="vasmed_r_vasmed_r-P5"/>
    </spatial>
    <spatial name="addbrev_l_tendon">
      <site site="addbrev_l_addbrev_l-P1"/>
      <geom geom="AB_at_femshaft_l_cylinder" sidesite="AB_at_femshaft_l_cylinder_addbrev_l_1_sidesite"/>
      <site site="addbrev_l_addbrev_l-P2"/>
    </spatial>
    <spatial name="addlong_l_tendon">
      <site site="addlong_l_addlong_l-P1"/>
      <geom geom="AL_at_femshaft_l_cylinder" sidesite="AL_at_femshaft_l_cylinder_addlong_l_1_sidesite"/>
      <site site="addlong_l_addlong_l-P2"/>
    </spatial>
    <spatial name="addmagDist_l_tendon">
      <site site="addmagDist_l_addmagDist_l-P1"/>
      <geom geom="AMdist_at_femshaft_l_cylinder" sidesite="AMdist_at_femshaft_l_cylinder_addmagDist_l_1_sidesite"/>
      <site site="addmagDist_l_addmagDist_l-P2"/>
    </spatial>
    <spatial name="addmagIsch_l_tendon">
      <site site="addmagIsch_l_addmagIsch_l-P1"/>
      <geom geom="AMisch_at_condyles_l_cylinder" sidesite="AMisch_at_condyles_l_cylinder_addmagIsch_l_1_sidesite"/>
      <site site="addmagIsch_l_addmagIsch_l-P2"/>
    </spatial>
    <spatial name="addmagMid_l_tendon">
      <site site="addmagMid_l_addmagMid_l-P1"/>
      <geom geom="AMmid_at_femshaft_l_cylinder" sidesite="AMmid_at_femshaft_l_cylinder_addmagMid_l_1_sidesite"/>
      <site site="addmagMid_l_addmagMid_l-P2"/>
    </spatial>
    <spatial name="addmagProx_l_tendon">
      <site site="addmagProx_l_addmagProx_l-P1"/>
      <geom geom="AMprox_at_femshaft_l_cylinder" sidesite="AMprox_at_femshaft_l_cylinder_addmagProx_l_1_sidesite"/>
      <site site="addmagProx_l_addmagProx_l-P2"/>
    </spatial>
    <spatial name="bflh_l_tendon">
      <site site="bflh_l_bflh_l-P1"/>
      <site site="bflh_l_bflh_l-P2"/>
      <site site="bflh_l_bflh_l-P3"/>
    </spatial>
    <spatial name="bfsh_l_tendon">
      <site site="bfsh_l_bfsh_l-P1"/>
      <site site="bfsh_l_bfsh_l-P2"/>
    </spatial>
    <spatial name="edl_l_tendon">
      <site site="edl_l_edl_l-P1"/>
      <site site="edl_l_edl_l-P2"/>
      <site site="edl_l_edl_l-P3"/>
      <site site="edl_l_edl_l-P4"/>
      <site site="edl_l_edl_l-P5"/>
      <site site="edl_l_edl_l-P6"/>
    </spatial>
    <spatial name="ehl_l_tendon">
      <site site="ehl_l_ehl_l-P1"/>
      <site site="ehl_l_ehl_l-P2"/>
      <site site="ehl_l_ehl_l-P3"/>
      <site site="ehl_l_ehl_l-P4"/>
      <site site="ehl_l_ehl_l-P5"/>
      <site site="ehl_l_ehl_l-P6"/>
      <site site="ehl_l_ehl_l-P7"/>
      <site site="ehl_l_ehl_l-P8"/>
    </spatial>
    <spatial name="fdl_l_tendon">
      <site site="fdl_l_fdl_l-P1"/>
      <site site="fdl_l_fdl_l-P2"/>
      <site site="fdl_l_fdl_l-P3"/>
      <site site="fdl_l_fdl_l-P4"/>
      <site site="fdl_l_fdl_l-P5"/>
      <site site="fdl_l_fdl_l-P6"/>
      <site site="fdl_l_fdl_l-P7"/>
      <site site="fdl_l_fdl_l-P8"/>
    </spatial>
    <spatial name="fhl_l_tendon">
      <site site="fhl_l_fhl_l-P1"/>
      <site site="fhl_l_fhl_l-P2"/>
      <site site="fhl_l_fhl_l-P3"/>
      <site site="fhl_l_fhl_l-P4"/>
      <site site="fhl_l_fhl_l-P5"/>
      <site site="fhl_l_fhl_l-P6"/>
      <site site="fhl_l_fhl_l-P7"/>
    </spatial>
    <spatial name="gaslat_l_tendon">
      <site site="gaslat_l_gaslat_l-P1"/>
      <geom geom="Gastroc_at_condyles_l_cylinder" sidesite="Gastroc_at_condyles_l_cylinder_gaslat_l_1_sidesite"/>
      <site site="gaslat_l_gaslat_l-P2"/>
    </spatial>
    <spatial name="gasmed_l_tendon">
      <site site="gasmed_l_gasmed_l-P1"/>
      <geom geom="Gastroc_at_condyles_l_cylinder" sidesite="Gastroc_at_condyles_l_cylinder_gasmed_l_1_sidesite"/>
      <site site="gasmed_l_gasmed_l-P2"/>
    </spatial>
    <spatial name="glmax1_l_tendon">
      <site site="glmax1_l_glmax1_l-P1"/>
      <site site="glmax1_l_glmax1_l-P2"/>
      <geom geom="Gmax1_at_pelvis_l_cylinder" sidesite="Gmax1_at_pelvis_l_cylinder_glmax1_l_2_sidesite"/>
      <site site="glmax1_l_glmax1_l-P3"/>
      <site site="glmax1_l_glmax1_l-P4"/>
    </spatial>
    <spatial name="glmax2_l_tendon">
      <site site="glmax2_l_glmax2_l-P1"/>
      <geom geom="Gmax2_at_pelvis_l_cylinder" sidesite="Gmax2_at_pelvis_l_cylinder_glmax2_l_1_sidesite"/>
      <site site="glmax2_l_glmax2_l-P2"/>
      <geom geom="Gmax2_at_pelvis_l_cylinder" sidesite="Gmax2_at_pelvis_l_cylinder_glmax2_l_2_sidesite"/>
      <site site="glmax2_l_glmax2_l-P3"/>
      <site site="glmax2_l_glmax2_l-P4"/>
    </spatial>
    <spatial name="glmax3_l_tendon">
      <site site="glmax3_l_glmax3_l-P1"/>
      <site site="glmax3_l_glmax3_l-P2"/>
      <site site="glmax3_l_glmax3_l-P3"/>
      <site site="glmax3_l_glmax3_l-P4"/>
    </spatial>
    <spatial name="glmed1_l_tendon">
      <site site="glmed1_l_glmed1_l-P1"/>
      <site site="glmed1_l_glmed1_l-P2"/>
    </spatial>
    <spatial name="glmed2_l_tendon">
      <site site="glmed2_l_glmed2_l-P1"/>
      <site site="glmed2_l_glmed2_l-P2"/>
    </spatial>
    <spatial name="glmed3_l_tendon">
      <site site="glmed3_l_glmed3_l-P1"/>
      <site site="glmed3_l_glmed3_l-P2"/>
    </spatial>
    <spatial name="glmin1_l_tendon">
      <site site="glmin1_l_glmin1_l-P1"/>
      <site site="glmin1_l_glmin1_l-P2"/>
    </spatial>
    <spatial name="glmin2_l_tendon">
      <site site="glmin2_l_glmin2_l-P1"/>
      <site site="glmin2_l_glmin2_l-P2"/>
    </spatial>
    <spatial name="glmin3_l_tendon">
      <site site="glmin3_l_glmin3_l-P1"/>
      <site site="glmin3_l_glmin3_l-P2"/>
    </spatial>
    <spatial name="grac_l_tendon">
      <site site="grac_l_grac_l-P1"/>
      <geom geom="GR_at_condyles_l_cylinder" sidesite="GR_at_condyles_l_cylinder_grac_l_1_sidesite"/>
      <site site="grac_l_grac_l-P2"/>
      <site site="grac_l_grac_l-P3"/>
    </spatial>
    <spatial name="iliacus_l_tendon">
      <site site="iliacus_l_iliacus_l-P1"/>
      <site site="iliacus_l_iliacus_l-P2"/>
      <geom geom="IL_at_brim_l_cylinder" sidesite="IL_at_brim_l_cylinder_iliacus_l_2_sidesite"/>
      <site site="iliacus_l_iliacus_l-P3"/>
      <site site="iliacus_l_iliacus_l-P4"/>
    </spatial>
    <spatial name="perbrev_l_tendon">
      <site site="perbrev_l_perbrev_l-P1"/>
      <site site="perbrev_l_perbrev_l-P2"/>
      <site site="perbrev_l_perbrev_l-P3"/>
      <site site="perbrev_l_perbrev_l-P4"/>
      <site site="perbrev_l_perbrev_l-P5"/>
    </spatial>
    <spatial name="perlong_l_tendon">
      <site site="perlong_l_perlong_l-P1"/>
      <site site="perlong_l_perlong_l-P2"/>
      <site site="perlong_l_perlong_l-P3"/>
      <site site="perlong_l_perlong_l-P4"/>
      <site site="perlong_l_perlong_l-P5"/>
      <site site="perlong_l_perlong_l-P6"/>
      <site site="perlong_l_perlong_l-P7"/>
    </spatial>
    <spatial name="piri_l_tendon">
      <site site="piri_l_piri_l-P1"/>
      <site site="piri_l_piri_l-P2"/>
      <site site="piri_l_piri_l-P3"/>
    </spatial>
    <spatial name="psoas_l_tendon">
      <site site="psoas_l_psoas_l-P1"/>
      <site site="psoas_l_psoas_l-P2"/>
      <geom geom="PS_at_brim_l_cylinder" sidesite="PS_at_brim_l_cylinder_psoas_l_2_sidesite"/>
      <site site="psoas_l_psoas_l-P3"/>
      <site site="psoas_l_psoas_l-P4"/>
    </spatial>
    <spatial name="recfem_l_tendon">
      <site site="recfem_l_recfem_l-P1"/>
      <site site="recfem_l_recfem_l-P2"/>
      <geom geom="KnExt_at_fem_l_cylinder" sidesite="KnExt_at_fem_l_cylinder_recfem_l_2_sidesite"/>
      <site site="recfem_l_recfem_l-P3"/>
      <geom geom="KnExt_at_fem_l_cylinder" sidesite="KnExt_at_fem_l_cylinder_recfem_l_3_sidesite"/>
      <site site="recfem_l_recfem_l-P4"/>
      <site site="recfem_l_recfem_l-P5"/>
    </spatial>
    <spatial name="sart_l_tendon">
      <site site="sart_l_sart_l-P1"/>
      <site site="sart_l_sart_l-P2"/>
      <site site="sart_l_sart_l-P3"/>
      <site site="sart_l_sart_l-P4"/>
      <site site="sart_l_sart_l-P5"/>
    </spatial>
    <spatial name="semimem_l_tendon">
      <site site="semimem_l_semimem_l-P1"/>
      <geom geom="SM_at_condyles_l_cylinder" sidesite="SM_at_condyles_l_cylinder_semimem_l_1_sidesite"/>
      <site site="semimem_l_semimem_l-P2"/>
    </spatial>
    <spatial name="semiten_l_tendon">
      <site site="semiten_l_semiten_l-P1"/>
      <geom geom="ST_at_condyles_l_cylinder" sidesite="ST_at_condyles_l_cylinder_semiten_l_1_sidesite"/>
      <site site="semiten_l_semiten_l-P2"/>
      <site site="semiten_l_semiten_l-P3"/>
    </spatial>
    <spatial name="soleus_l_tendon">
      <site site="soleus_l_soleus_l-P1"/>
      <site site="soleus_l_soleus_l-P2"/>
    </spatial>
    <spatial name="tfl_l_tendon">
      <site site="tfl_l_tfl_l-P1"/>
      <site site="tfl_l_tfl_l-P2"/>
      <site site="tfl_l_tfl_l-P3"/>
      <site site="tfl_l_tfl_l-P4"/>
    </spatial>
    <spatial name="tibant_l_tendon">
      <site site="tibant_l_tibant_l-P1"/>
      <site site="tibant_l_tibant_l-P2"/>
      <site site="tibant_l_tibant_l-P3"/>
      <site site="tibant_l_tibant_l-P4"/>
    </spatial>
    <spatial name="tibpost_l_tendon">
      <site site="tibpost_l_tibpost_l-P1"/>
      <site site="tibpost_l_tibpost_l-P2"/>
      <site site="tibpost_l_tibpost_l-P3"/>
      <site site="tibpost_l_tibpost_l-P4"/>
    </spatial>
    <spatial name="vasint_l_tendon">
      <site site="vasint_l_vasint_l-P1"/>
      <site site="vasint_l_vasint_l-P2"/>
      <site site="vasint_l_vasint_l-P3"/>
      <geom geom="KnExt_at_fem_l_cylinder" sidesite="KnExt_at_fem_l_cylinder_vasint_l_3_sidesite"/>
      <site site="vasint_l_vasint_l-P4"/>
      <site site="vasint_l_vasint_l-P5"/>
    </spatial>
    <spatial name="vaslat_l_tendon">
      <site site="vaslat_l_vaslat_l-P1"/>
      <site site="vaslat_l_vaslat_l-P2"/>
      <geom geom="KnExt_at_fem_l_cylinder" sidesite="KnExt_at_fem_l_cylinder_vaslat_l_2_sidesite"/>
      <site site="vaslat_l_vaslat_l-P3"/>
      <geom geom="KnExt_at_fem_l_cylinder" sidesite="KnExt_at_fem_l_cylinder_vaslat_l_3_sidesite"/>
      <site site="vaslat_l_vaslat_l-P4"/>
      <site site="vaslat_l_vaslat_l-P5"/>
    </spatial>
    <spatial name="vasmed_l_tendon">
      <site site="vasmed_l_vasmed_l-P1"/>
      <site site="vasmed_l_vasmed_l-P2"/>
      <site site="vasmed_l_vasmed_l-P3"/>
      <geom geom="KnExt_at_fem_l_cylinder" sidesite="KnExt_at_fem_l_cylinder_vasmed_l_3_sidesite"/>
      <site site="vasmed_l_vasmed_l-P4"/>
      <geom geom="KnExt_at_fem_l_cylinder" sidesite="KnExt_at_fem_l_cylinder_vasmed_l_4_sidesite"/>
      <site site="vasmed_l_vasmed_l-P5"/>
    </spatial>
  </tendon>
  <actuator>
    <!-- Leave this comment here to make 'actuator' element pretty printed !-->
    <motor name="lumbar_ext" ctrllimited="false" joint="lumbar_extension" class="motor"/>
    <motor name="lumbar_bend" ctrllimited="false" joint="lumbar_bending" class="motor"/>
    <motor name="lumbar_rot" ctrllimited="false" joint="lumbar_rotation" class="motor"/>
    <muscle name="addbrev_r" lengthrange="0.01 1" force="625.81967213114797" tendon="addbrev_r_tendon" class="muscle" timeconst="0.01 0.04"/>
    <muscle name="addlong_r" lengthrange="0.01 1" force="916.79999999999995" tendon="addlong_r_tendon" class="muscle" timeconst="0.01 0.04"/>
    <muscle name="addmagDist_r" lengthrange="0.01 1" force="597.29508196721395" tendon="addmagDist_r_tendon" class="muscle" timeconst="0.01 0.04"/>
    <muscle name="addmagIsch_r" lengthrange="0.01 1" force="597.29508196721395" tendon="addmagIsch_r_tendon" class="muscle" timeconst="0.01 0.04"/>
    <muscle name="addmagMid_r" lengthrange="0.01 1" force="597.29508196721395" tendon="addmagMid_r_tendon" class="muscle" timeconst="0.01 0.04"/>
    <muscle name="addmagProx_r" lengthrange="0.01 1" force="597.29508196721395" tendon="addmagProx_r_tendon" class="muscle" timeconst="0.01 0.04"/>
    <muscle name="bflh_r" lengthrange="0.01 1" force="1313.18360655738" tendon="bflh_r_tendon" class="muscle" timeconst="0.01 0.04"/>
    <muscle name="bfsh_r" lengthrange="0.01 1" force="557.11475409835998" tendon="bfsh_r_tendon" class="muscle" timeconst="0.01 0.04"/>
    <muscle name="edl_r" lengthrange="0.01 1" force="603.49815560000002" tendon="edl_r_tendon" class="muscle" timeconst="0.01 0.04"/>
    <muscle name="ehl_r" lengthrange="0.01 1" force="285.86754739999998" tendon="ehl_r_tendon" class="muscle" timeconst="0.01 0.04"/>
    <muscle name="fdl_r" lengthrange="0.01 1" force="423.17704918032803" tendon="fdl_r_tendon" class="muscle" timeconst="0.01 0.04"/>
    <muscle name="fhl_r" lengthrange="0.01 1" force="907.83934426229405" tendon="fhl_r_tendon" class="muscle" timeconst="0.01 0.04"/>
    <muscle name="gaslat_r" lengthrange="0.01 1" force="1575.0590163934401" tendon="gaslat_r_tendon" class="muscle" timeconst="0.01 0.04"/>
    <muscle name="gasmed_r" lengthrange="0.01 1" force="3115.5147540983598" tendon="gasmed_r_tendon" class="muscle" timeconst="0.01 0.04"/>
    <muscle name="glmax1_r" lengthrange="0.01 1" force="983.78360655737799" tendon="glmax1_r_tendon" class="muscle" timeconst="0.01 0.04"/>
    <muscle name="glmax2_r" lengthrange="0.01 1" force="1406.0459016393499" tendon="glmax2_r_tendon" class="muscle" timeconst="0.01 0.04"/>
    <muscle name="glmax3_r" lengthrange="0.01 1" force="947.75409836065603" tendon="glmax3_r_tendon" class="muscle" timeconst="0.01 0.04"/>
    <muscle name="glmed1_r" lengthrange="0.01 1" force="1093.4667688" tendon="glmed1_r_tendon" class="muscle" timeconst="0.01 0.04"/>
    <muscle name="glmed2_r" lengthrange="0.01 1" force="765.09166159999995" tendon="glmed2_r_tendon" class="muscle" timeconst="0.01 0.04"/>
    <muscle name="glmed3_r" lengthrange="0.01 1" force="871.19926420000002" tendon="glmed3_r_tendon" class="muscle" timeconst="0.01 0.04"/>
    <muscle name="glmin1_r" lengthrange="0.01 1" force="374.04590163934398" tendon="glmin1_r_tendon" class="muscle" timeconst="0.01 0.04"/>
    <muscle name="glmin2_r" lengthrange="0.01 1" force="394.81967213114802" tendon="glmin2_r_tendon" class="muscle" timeconst="0.01 0.04"/>
    <muscle name="glmin3_r" lengthrange="0.01 1" force="446.77377049180399" tendon="glmin3_r_tendon" class="muscle" timeconst="0.01 0.04"/>
    <muscle name="grac_r" lengthrange="0.01 1" force="281.31147540983602" tendon="grac_r_tendon" class="muscle" timeconst="0.01 0.04"/>
    <muscle name="iliacus_r" lengthrange="0.01 1" force="1021.14098360656" tendon="iliacus_r_tendon" class="muscle" timeconst="0.01 0.04"/>
    <muscle name="perbrev_r" lengthrange="0.01 1" force="521.20159880000006" tendon="perbrev_r_tendon" class="muscle" timeconst="0.01 0.04"/>
    <muscle name="perlong_r" lengthrange="0.01 1" force="1115.3714213999999" tendon="perlong_r_tendon" class="muscle" timeconst="0.01 0.04"/>
    <muscle name="piri_r" lengthrange="0.01 1" force="1029.7868852459001" tendon="piri_r_tendon" class="muscle" timeconst="0.01 0.04"/>
    <muscle name="psoas_r" lengthrange="0.01 1" force="1426.79016393443" tendon="psoas_r_tendon" class="muscle" timeconst="0.01 0.04"/>
    <muscle name="recfem_r" lengthrange="0.01 1" force="2191.7409836065599" tendon="recfem_r_tendon" class="muscle" timeconst="0.01 0.04"/>
    <muscle name="sart_r" lengthrange="0.01 1" force="249.41311475409799" tendon="sart_r_tendon" class="muscle" timeconst="0.01 0.04"/>
    <muscle name="semimem_r" lengthrange="0.01 1" force="2200.9868852458999" tendon="semimem_r_tendon" class="muscle" timeconst="0.01 0.04"/>
    <muscle name="semiten_r" lengthrange="0.01 1" force="591.29508196721395" tendon="semiten_r_tendon" class="muscle" timeconst="0.01 0.04"/>
    <muscle name="soleus_r" lengthrange="0.01 1" force="6194.8426229508204" tendon="soleus_r_tendon" class="muscle" timeconst="0.01 0.04"/>
    <muscle name="tfl_r" lengthrange="0.01 1" force="411.20655737704999" tendon="tfl_r_tendon" class="muscle" timeconst="0.01 0.04"/>
    <muscle name="tibant_r" lengthrange="0.01 1" force="1227.4524590163901" tendon="tibant_r_tendon" class="muscle" timeconst="0.01 0.04"/>
    <muscle name="tibpost_r" lengthrange="0.01 1" force="1730.1540983606501" tendon="tibpost_r_tendon" class="muscle" timeconst="0.01 0.04"/>
    <muscle name="vasint_r" lengthrange="0.01 1" force="1697.36065573771" tendon="vasint_r_tendon" class="muscle" timeconst="0.01 0.04"/>
    <muscle name="vaslat_r" lengthrange="0.01 1" force="5148.7672131147601" tendon="vaslat_r_tendon" class="muscle" timeconst="0.01 0.04"/>
    <muscle name="vasmed_r" lengthrange="0.01 1" force="2747.82295081966" tendon="vasmed_r_tendon" class="muscle" timeconst="0.01 0.04"/>
    <muscle name="addbrev_l" lengthrange="0.01 1" force="625.81967213114797" tendon="addbrev_l_tendon" class="muscle" timeconst="0.01 0.04"/>
    <muscle name="addlong_l" lengthrange="0.01 1" force="916.79999999999995" tendon="addlong_l_tendon" class="muscle" timeconst="0.01 0.04"/>
    <muscle name="addmagDist_l" lengthrange="0.01 1" force="597.29508196721395" tendon="addmagDist_l_tendon" class="muscle" timeconst="0.01 0.04"/>
    <muscle name="addmagIsch_l" lengthrange="0.01 1" force="597.29508196721395" tendon="addmagIsch_l_tendon" class="muscle" timeconst="0.01 0.04"/>
    <muscle name="addmagMid_l" lengthrange="0.01 1" force="597.29508196721395" tendon="addmagMid_l_tendon" class="muscle" timeconst="0.01 0.04"/>
    <muscle name="addmagProx_l" lengthrange="0.01 1" force="597.29508196721395" tendon="addmagProx_l_tendon" class="muscle" timeconst="0.01 0.04"/>
    <muscle name="bflh_l" lengthrange="0.01 1" force="1313.18360655738" tendon="bflh_l_tendon" class="muscle" timeconst="0.01 0.04"/>
    <muscle name="bfsh_l" lengthrange="0.01 1" force="557.11475409835998" tendon="bfsh_l_tendon" class="muscle" timeconst="0.01 0.04"/>
    <muscle name="edl_l" lengthrange="0.01 1" force="603.49815560000002" tendon="edl_l_tendon" class="muscle" timeconst="0.01 0.04"/>
    <muscle name="ehl_l" lengthrange="0.01 1" force="285.86754739999998" tendon="ehl_l_tendon" class="muscle" timeconst="0.01 0.04"/>
    <muscle name="fdl_l" lengthrange="0.01 1" force="423.17704918032803" tendon="fdl_l_tendon" class="muscle" timeconst="0.01 0.04"/>
    <muscle name="fhl_l" lengthrange="0.01 1" force="907.83934426229405" tendon="fhl_l_tendon" class="muscle" timeconst="0.01 0.04"/>
    <muscle name="gaslat_l" lengthrange="0.01 1" force="1575.0590163934401" tendon="gaslat_l_tendon" class="muscle" timeconst="0.01 0.04"/>
    <muscle name="gasmed_l" lengthrange="0.01 1" force="3115.5147540983598" tendon="gasmed_l_tendon" class="muscle" timeconst="0.01 0.04"/>
    <muscle name="glmax1_l" lengthrange="0.01 1" force="983.78360655737799" tendon="glmax1_l_tendon" class="muscle" timeconst="0.01 0.04"/>
    <muscle name="glmax2_l" lengthrange="0.01 1" force="1406.0459016393499" tendon="glmax2_l_tendon" class="muscle" timeconst="0.01 0.04"/>
    <muscle name="glmax3_l" lengthrange="0.01 1" force="947.75409836065603" tendon="glmax3_l_tendon" class="muscle" timeconst="0.01 0.04"/>
    <muscle name="glmed1_l" lengthrange="0.01 1" force="1093.4667688" tendon="glmed1_l_tendon" class="muscle" timeconst="0.01 0.04"/>
    <muscle name="glmed2_l" lengthrange="0.01 1" force="765.09166159999995" tendon="glmed2_l_tendon" class="muscle" timeconst="0.01 0.04"/>
    <muscle name="glmed3_l" lengthrange="0.01 1" force="871.19926420000002" tendon="glmed3_l_tendon" class="muscle" timeconst="0.01 0.04"/>
    <muscle name="glmin1_l" lengthrange="0.01 1" force="374.04590163934398" tendon="glmin1_l_tendon" class="muscle" timeconst="0.01 0.04"/>
    <muscle name="glmin2_l" lengthrange="0.01 1" force="394.81967213114802" tendon="glmin2_l_tendon" class="muscle" timeconst="0.01 0.04"/>
    <muscle name="glmin3_l" lengthrange="0.01 1" force="446.77377049180399" tendon="glmin3_l_tendon" class="muscle" timeconst="0.01 0.04"/>
    <muscle name="grac_l" lengthrange="0.01 1" force="281.31147540983602" tendon="grac_l_tendon" class="muscle" timeconst="0.01 0.04"/>
    <muscle name="iliacus_l" lengthrange="0.01 1" force="1021.14098360656" tendon="iliacus_l_tendon" class="muscle" timeconst="0.01 0.04"/>
    <muscle name="perbrev_l" lengthrange="0.01 1" force="521.20159880000006" tendon="perbrev_l_tendon" class="muscle" timeconst="0.01 0.04"/>
    <muscle name="perlong_l" lengthrange="0.01 1" force="1115.3714213999999" tendon="perlong_l_tendon" class="muscle" timeconst="0.01 0.04"/>
    <muscle name="piri_l" lengthrange="0.01 1" force="1029.7868852459001" tendon="piri_l_tendon" class="muscle" timeconst="0.01 0.04"/>
    <muscle name="psoas_l" lengthrange="0.01 1" force="1426.79016393443" tendon="psoas_l_tendon" class="muscle" timeconst="0.01 0.04"/>
    <muscle name="recfem_l" lengthrange="0.01 1" force="2191.7409836065599" tendon="recfem_l_tendon" class="muscle" timeconst="0.01 0.04"/>
    <muscle name="sart_l" lengthrange="0.01 1" force="249.41311475409799" tendon="sart_l_tendon" class="muscle" timeconst="0.01 0.04"/>
    <muscle name="semimem_l" lengthrange="0.01 1" force="2200.9868852458999" tendon="semimem_l_tendon" class="muscle" timeconst="0.01 0.04"/>
    <muscle name="semiten_l" lengthrange="0.01 1" force="591.29508196721395" tendon="semiten_l_tendon" class="muscle" timeconst="0.01 0.04"/>
    <muscle name="soleus_l" lengthrange="0.01 1" force="6194.8426229508204" tendon="soleus_l_tendon" class="muscle" timeconst="0.01 0.04"/>
    <muscle name="tfl_l" lengthrange="0.01 1" force="411.20655737704999" tendon="tfl_l_tendon" class="muscle" timeconst="0.01 0.04"/>
    <muscle name="tibant_l" lengthrange="0.01 1" force="1227.4524590163901" tendon="tibant_l_tendon" class="muscle" timeconst="0.01 0.04"/>
    <muscle name="tibpost_l" lengthrange="0.01 1" force="1730.1540983606501" tendon="tibpost_l_tendon" class="muscle" timeconst="0.01 0.04"/>
    <muscle name="vasint_l" lengthrange="0.01 1" force="1697.36065573771" tendon="vasint_l_tendon" class="muscle" timeconst="0.01 0.04"/>
    <muscle name="vaslat_l" lengthrange="0.01 1" force="5148.7672131147601" tendon="vaslat_l_tendon" class="muscle" timeconst="0.01 0.04"/>
    <muscle name="vasmed_l" lengthrange="0.01 1" force="2747.82295081966" tendon="vasmed_l_tendon" class="muscle" timeconst="0.01 0.04"/>
  </actuator>
  <equality>
    <!-- Leave this comment here to make 'equality' element pretty printed !-->
    <joint joint1="walker_knee_r_translation1" joint2="knee_angle_r" polycoef="1.07e-07 0.003511 -0.00259 0.0006302 6.379e-07" solimp="0.9999 0.9999 0.001 0.5 2" active="true"/>
    <joint joint1="walker_knee_r_translation2" joint2="knee_angle_r" polycoef="8.527e-11 0.006518 -0.001393 -2.903e-06 6.921e-07" solimp="0.9999 0.9999 0.001 0.5 2" active="true"/>
    <joint joint1="walker_knee_r_rotation2" joint2="knee_angle_r" polycoef="-1.473e-08 0.0791 -0.03285 -0.02522 0.01083" solimp="0.9999 0.9999 0.001 0.5 2" active="true"/>
    <joint joint1="walker_knee_r_rotation3" joint2="knee_angle_r" polycoef="1.089e-08 0.3695 -0.1695 0.02516 3.505e-07" solimp="0.9999 0.9999 0.001 0.5 2" active="true"/>
    <joint name="mtp_angle_r_locked" active="true" joint1="mtp_angle_r" polycoef="0.0 0 0 0 0" solimp="0.9999 0.9999 0.001 0.5 2"/>
    <joint joint1="patellofemoral_r_translation1" joint2="knee_angle_r" polycoef="0.0587 -0.01682 -0.03813 0.01494 -0.0009845" solimp="0.9999 0.9999 0.001 0.5 2" active="true"/>
    <joint joint1="patellofemoral_r_translation2" joint2="knee_angle_r" polycoef="-0.01215 -0.05475 0.01041 0.01478 -0.003924" solimp="0.9999 0.9999 0.001 0.5 2" active="true"/>
    <joint joint1="patellofemoral_r_rotation1" joint2="knee_angle_r" polycoef="0.01051 0.02476 -1.316 0.7163 -0.1383" solimp="0.9999 0.9999 0.001 0.5 2" active="true"/>
    <joint name="patellofemoral_r_translation3_locked" active="true" joint1="patellofemoral_r_translation3" polycoef="0.003048397281325 0 0 0 0" solimp="0.9999 0.9999 0.001 0.5 2"/>
    <joint joint1="walker_knee_l_translation1" joint2="knee_angle_l" polycoef="1.07e-07 0.003511 -0.00259 0.0006302 6.379e-07" solimp="0.9999 0.9999 0.001 0.5 2" active="true"/>
    <joint joint1="walker_knee_l_translation2" joint2="knee_angle_l" polycoef="-8.527e-11 -0.006518 0.001393 2.903e-06 -6.921e-07" solimp="0.9999 0.9999 0.001 0.5 2" active="true"/>
    <joint joint1="walker_knee_l_rotation2" joint2="knee_angle_l" polycoef="-1.473e-08 0.0791 -0.03285 -0.02522 0.01083" solimp="0.9999 0.9999 0.001 0.5 2" active="true"/>
    <joint joint1="walker_knee_l_rotation3" joint2="knee_angle_l" polycoef="-1.089e-08 -0.3695 0.1695 -0.02516 -3.505e-07" solimp="0.9999 0.9999 0.001 0.5 2" active="true"/>
    <joint name="mtp_angle_l_locked" active="true" joint1="mtp_angle_l" polycoef="0.0 0 0 0 0" solimp="0.9999 0.9999 0.001 0.5 2"/>
    <joint joint1="patellofemoral_l_translation1" joint2="knee_angle_l" polycoef="0.0587 -0.01682 -0.03813 0.01494 -0.0009845" solimp="0.9999 0.9999 0.001 0.5 2" active="true"/>
    <joint joint1="patellofemoral_l_translation2" joint2="knee_angle_l" polycoef="-0.01215 -0.05475 0.01041 0.01478 -0.003924" solimp="0.9999 0.9999 0.001 0.5 2" active="true"/>
    <joint joint1="patellofemoral_l_rotation1" joint2="knee_angle_l" polycoef="0.01051 0.02476 -1.316 0.7163 -0.1383" solimp="0.9999 0.9999 0.001 0.5 2" active="true"/>
    <joint name="patellofemoral_l_translation3_locked" active="true" joint1="patellofemoral_l_translation3" polycoef="-0.003048397281325 0 0 0 0" solimp="0.9999 0.9999 0.001 0.5 2"/>
  </equality>
  <contact>
    <!-- Leave this comment here to make 'contact' element pretty printed !-->
    <pair geom1="ground-plane" geom2="pelvis_geom_1"/>
    <pair geom1="ground-plane" geom2="pelvis_geom_2"/>
    <pair geom1="ground-plane" geom2="pelvis_geom_3"/>
    <pair geom1="ground-plane" geom2="femur_r_geom_1"/>
    <pair geom1="ground-plane" geom2="tibia_r_geom_1"/>
    <pair geom1="ground-plane" geom2="tibia_r_geom_2"/>
    <pair geom1="ground-plane" geom2="talus_r_geom_1"/>
    <pair geom1="ground-plane" geom2="calcn_r_geom_1"/>
    <pair geom1="ground-plane" geom2="toes_r_geom_1"/>
    <pair geom1="ground-plane" geom2="patella_r_geom_1"/>
    <pair geom1="ground-plane" geom2="femur_l_geom_1"/>
    <pair geom1="ground-plane" geom2="tibia_l_geom_1"/>
    <pair geom1="ground-plane" geom2="tibia_l_geom_2"/>
    <pair geom1="ground-plane" geom2="talus_l_geom_1"/>
    <pair geom1="ground-plane" geom2="calcn_l_geom_1"/>
    <pair geom1="ground-plane" geom2="toes_l_geom_1"/>
    <pair geom1="ground-plane" geom2="patella_l_geom_1"/>
    <pair geom1="ground-plane" geom2="torso_geom_1"/>
    <pair geom1="ground-plane" geom2="torso_geom_2"/>
    <pair geom1="ground-plane" geom2="torso_geom_3"/>
    <pair geom1="ground-plane" geom2="torso_geom_4"/>
  </contact>
  <keyframe>
    <key name="default-pose" qpos="0 0.93 0 0 0 0 0 0 0 1.07e-07 8.527e-11 0 -1.473e-08 1.089e-08 0 0 0 0.0587 -0.01215 0.003048 0.01051 0 -0 -0 1.07e-07 -8.527e-11 0 -1.473e-08 -1.089e-08 0 0 0 0.0587 -0.01215 -0.003048 0.01051 0 0 0"/>
  </keyframe>
</mujoco>
