<mujoco model="template">
  <!-- This model has been converted from an OpenSim model. Model conversion by MyoConverter https://github.com/MyoHub/myoconverter. This model is licensed under Apache 2.0. -->
  <!-- Note: inertiagrouprange="0 1" means that groups 0-1 will be used to infer masses/inertias, and groups 2-5 are
  only for visualisation (e.g. wrapping objects) !-->
  <compiler inertiafromgeom="auto" angle="radian" balanceinertia="true" boundmass="0.001" boundinertia="0.001" inertiagrouprange="0 1">
    <lengthrange inttotal="50" useexisting="true"/>
  </compiler>
  <option collision="predefined"/>
  <visual>
    <scale framelength="0.5" framewidth="0.01"/>
  </visual>
  <default>
    <joint limited="true" damping="0.05" armature="0.00001" stiffness="0"/>
    <geom rgba="0.8 0.6 .4 1" margin="0.001"/>
    <site size="0.001"/>
    <tendon width="0.005" rgba=".95 .3 .3 1" limited="false"/>
    <default class="muscle">
      <muscle ctrllimited="true" ctrlrange="0 1" scale="200"/>
    </default>
    <default class="motor">
      <general gainprm="5 0 0 0 0 0 0 0 0 0"/>
    </default>
  </default>
  <option timestep="0.002"/>
  <!-- nuser_jnt=1, the parameter is used to store default value of the joint, and nkey=1 to store keyframe with
   default joint positions set !-->
  <size njmax="1000" nconmax="400" nuser_jnt="1" nkey="1"/>
  <worldbody>
    <!-- The converter script assumes a body named 'ground' exists as a child element of worldbody -->
    <body name="ground" euler="1.571 0 0">
      <geom name="ground-plane" pos="0 0 0" euler="-1.571 0 0" size="10 10 0.125" type="plane" rgba="1.0 0.7 0.4 1.0" condim="3"/>
    </body>
    <light directional="true"/>
    <body name="pelvis" pos="0 0 0" euler="1.571 0 0">
      <inertial mass="10.2627234097" pos="-0.0707000000 0.0000000000 0.0000000000" fullinertia="0.0895820639 0.0759007565 0.0504552675 0.0000000000 0.0000000000 0.0000000000"/>
      <geom name="pelvis_geom_1" type="mesh" mesh="pelvis_geom_1_r_pelvis" rgba="1 1 1 1" group="0"/>
      <geom name="pelvis_geom_2" type="mesh" mesh="pelvis_geom_2_l_pelvis" rgba="1 1 1 1" group="0"/>
      <geom name="pelvis_geom_3" type="mesh" mesh="pelvis_geom_3_sacrum" rgba="1 1 1 1" group="0"/>
      <geom name="Gmax1_at_pelvis_r_cylinder" type="cylinder" euler="-0.6 0.45 0" pos="-0.079 -0.09987 0.06313" size="0.04086 0.07699" rgba="0.19 0.83 0.78 0.2" group="2"/>
      <site name="Gmax1_at_pelvis_r_sidesite" pos="-0.1167 -0.08959 0.07815" size="0.0005"/>
      <geom name="Gmax2_at_pelvis_r_cylinder" type="cylinder" euler="-0.75 0.39 0" pos="-0.08207 -0.08373 0.07037" size="0.04093 0.05116" rgba="0.19 0.83 0.78 0.2" group="2"/>
      <geom name="Gmax3_at_pelvis_r_cylinder" type="cylinder" euler="-0.1 0 0" pos="-0.08515 -0.08878 0.07037" size="0.0407 0.05173" rgba="0.19 0.83 0.78 0.2" group="2"/>
      <geom name="Gmax1_at_pelvis_l_cylinder" type="cylinder" euler="0.6 -0.45 0" pos="-0.079 -0.09987 -0.06313" size="0.04086 0.07699" rgba="0.19 0.83 0.78 0.2" group="2"/>
      <site name="Gmax1_at_pelvis_l_sidesite" pos="-0.1167 -0.08959 -0.07815" size="0.0005"/>
      <geom name="Gmax2_at_pelvis_l_cylinder" type="cylinder" euler="0.75 -0.39 0" pos="-0.08207 -0.08373 -0.07037" size="0.04093 0.05116" rgba="0.19 0.83 0.78 0.2" group="2"/>
      <geom name="Gmax3_at_pelvis_l_cylinder" type="cylinder" euler="0.1 0 0" pos="-0.08515 -0.08878 -0.07037" size="0.0407 0.05173" rgba="0.19 0.83 0.78 0.2" group="2"/>
      <geom name="PS_at_brim_r_cylinder" type="cylinder" euler="-0.25 -0.27 0.1" pos="-0.07592 -0.06053 0.06789" size="0.05092 0.05164" rgba="0.19 0.83 0.78 0.2" group="2"/>
      <site name="PS_at_brim_r_sidesite" pos="-0.07092 -0.1102 0.08201" size="0.0005"/>
      <geom name="PS_at_brim_l_cylinder" type="cylinder" euler="0.25 0.27 0.1" pos="-0.07592 -0.06053 -0.06789" size="0.05092 0.05164" rgba="0.19 0.83 0.78 0.2" group="2"/>
      <site name="PS_at_brim_l_sidesite" pos="-0.07092 -0.1102 -0.08201" size="0.0005"/>
      <geom name="IL_at_brim_r_cylinder" type="cylinder" euler="-0.32 -0.24 0.9" pos="-0.07284 -0.06557 0.07823" size="0.05594 0.0516" rgba="0.19 0.83 0.78 0.2" group="2"/>
      <site name="IL_at_brim_r_sidesite" pos="-0.02952 -0.09583 0.09943" size="0.0005"/>
      <geom name="IL_at_brim_l_cylinder" type="cylinder" euler="0.32 0.24 0.9" pos="-0.07284 -0.06557 -0.07823" size="0.05594 0.0516" rgba="0.19 0.83 0.78 0.2" group="2"/>
      <site name="IL_at_brim_l_sidesite" pos="-0.02952 -0.09583 -0.09943" size="0.0005"/>
      <joint name="pelvis_tx" range="-40 40" limited="true" user="0.0" ref="0" axis="1 0 0" type="slide" damping="0" stiffness="0"/>
      <joint name="pelvis_ty" range="-5 5" limited="true" user="0.93" ref="0" axis="0 1 0" type="slide" damping="0" stiffness="0"/>
      <joint name="pelvis_tz" range="-40 40" limited="true" user="0.0" ref="0" axis="0 0 1" type="slide" damping="0" stiffness="0"/>
      <joint name="pelvis_tilt" range="-3.142 3.142" limited="true" user="0.0" ref="0" axis="0 0 1" type="hinge" damping="0" stiffness="0"/>
      <joint name="pelvis_list" range="-3.142 3.142" limited="true" user="0.0" ref="0" axis="1 0 0" type="hinge" damping="0" stiffness="0"/>
      <joint name="pelvis_rotation" range="-3.142 3.142" limited="true" user="0.0" ref="0" axis="0 1 0" type="hinge" damping="0" stiffness="0"/>
      <body name="femur_r" pos="-0.05773 -0.07918 0.07995" euler="-0 0 0">
        <inertial mass="8.1054339410" pos="0.0000000000 -0.1700000000 0.0000000000" fullinertia="0.1166832525 0.0305868720 0.1230446247 0.0000000000 0.0000000000 0.0000000000"/>
        <geom name="femur_r_geom_1" type="mesh" mesh="femur_r_geom_1_r_femur" rgba="1 1 1 1" group="0"/>
        <geom name="Gastroc_at_condyles_r_cylinder" type="cylinder" euler="0 0 0" pos="0.00526 -0.4246 0" size="0.0261 0.05167" rgba="0.19 0.83 0.78 0.2" group="2"/>
        <geom name="KnExt_at_fem_r_cylinder" type="cylinder" euler="-0.06234 0.05076 0" pos="0.003775 -0.4171 0.002161" size="0.0261 0.05167" rgba="0.19 0.83 0.78 0.2" group="2"/>
        <geom name="AB_at_femshaft_r_cylinder" type="cylinder" euler="1.662 0.1866 0" pos="0.01541 -0.1166 0.02415" size="0.0172 0.03627" rgba="0.19 0.83 0.78 0.2" group="2"/>
        <geom name="AL_at_femshaft_r_cylinder" type="cylinder" euler="1.777 0.1365 0" pos="0.03233 -0.2402 0.01562" size="0.02096 0.05179" rgba="0.19 0.83 0.78 0.2" group="2"/>
        <geom name="AMprox_at_femshaft_r_cylinder" type="cylinder" euler="1.611 0.1866 0" pos="0.005453 -0.07549 0.02625" size="0.022 0.03627" rgba="0.19 0.83 0.78 0.2" group="2"/>
        <geom name="AMmid_at_femshaft_r_cylinder" type="cylinder" euler="1.611 0.1366 0" pos="0.02421 -0.1664 0.02127" size="0.02231 0.06216" rgba="0.19 0.83 0.78 0.2" group="2"/>
        <geom name="AMdist_at_femshaft_r_cylinder" type="cylinder" euler="1.712 0.1866 0" pos="0.03325 -0.27 0.009677" size="0.02273 0.1036" rgba="0.19 0.83 0.78 0.2" group="2"/>
        <geom name="AMisch_at_condyles_r_cylinder" type="cylinder" euler="1.711 -0.4634 0" pos="-0.02383 -0.3903 -0.00326" size="0.04165 0.1247" rgba="0.19 0.83 0.78 0.2" group="2"/>
        <geom name="PECT_at_femshaft_r_cylinder" type="cylinder" euler="1.813 0.2763 0" pos="0.006403 -0.08751 0.03146" size="0.01563 0.02592" rgba="0.19 0.83 0.78 0.2" group="2"/>
        <joint name="hip_flexion_r" range="-0.5236 2.094" limited="true" user="0.0" ref="0" axis="0 0 1" type="hinge"/>
        <joint name="hip_adduction_r" range="-0.8727 0.5236" limited="true" user="0.0" ref="0" axis="1 0 0" type="hinge"/>
        <joint name="hip_rotation_r" range="-0.6981 0.6981" limited="true" user="0.0" ref="0" axis="0 1 0" type="hinge"/>
        <body name="tibia_r" pos="0.0002302 -0.4186 -0.001261" euler="-0 0 0">
          <inertial mass="3.2307928200" pos="0.0000000000 -0.1867000000 0.0000000000" fullinertia="0.0439196111 0.0044442464 0.0445296057 0.0000000000 0.0000000000 0.0000000000"/>
          <geom name="tibia_r_geom_1" type="mesh" mesh="tibia_r_geom_1_r_tibia" rgba="1 1 1 1" group="0"/>
          <geom name="tibia_r_geom_2" type="mesh" mesh="tibia_r_geom_2_r_fibula" rgba="1 1 1 1" group="0"/>
          <geom name="GasLat_at_shank_r_cylinder" type="cylinder" euler="2.967 -0.2797 -1.478" pos="-0.007997 -0.08059 -0.003514" size="0.05962 0.05334" rgba="0.19 0.83 0.78 0.2" group="2"/>
          <site name="GasLat_at_shank_r_sidesite" pos="-0.06601 -0.07218 0.01192" size="0.0005"/>
          <geom name="GasMed_at_shank_r_cylinder" type="cylinder" euler="2.967 0.02797 -1.478" pos="-0.007997 -0.08059 -0.003514" size="0.05965 0.05329" rgba="0.19 0.83 0.78 0.2" group="2"/>
          <site name="GasMed_at_shank_r_sidesite" pos="-0.06836 -0.07536 -0.006151" size="0.0005"/>
          <geom name="GR_at_condyles_r_cylinder" type="cylinder" euler="0 -0.4 0" pos="-0.003242 -0.02178 0" size="0.03901 0.05337" rgba="0.19 0.83 0.78 0.2" group="2"/>
          <geom name="SM_at_condyles_r_cylinder" type="cylinder" euler="0 -0.1 0" pos="-0.001081 -0.02178 0" size="0.03818 0.05326" rgba="0.19 0.83 0.78 0.2" group="2"/>
          <geom name="ST_at_condyles_r_cylinder" type="cylinder" euler="0 -0.2 0" pos="-0.002161 -0.02233 0" size="0.04609 0.05328" rgba="0.19 0.83 0.78 0.2" group="2"/>
          <geom name="BF_at_gastroc_r_cylinder" type="cylinder" euler="0 0 0" pos="-0.06268 -0.06534 0" size="0.03255 0.07987" rgba="0.19 0.83 0.78 0.2" group="2"/>
          <site name="BF_at_gastroc_r_sidesite" pos="-0.06268 -0.0318 0" size="0.0005"/>
          <joint name="walker_knee_r_translation1" range="0 0.001656" limited="true" user="9.877164921807263e-08" ref="0" axis="-0.1243 0.9898 -0.07016" type="slide"/>
          <joint name="walker_knee_r_translation2" range="0 0.007019" limited="true" user="7.949387155481435e-11" ref="0" axis="0.9922 0.124 -0.008789" type="slide"/>
          <joint name="knee_angle_r" range="0 2.094" limited="true" user="0.0" ref="0" axis="-4.566e-07 -0.07071 -0.9975" type="hinge"/>
          <joint name="walker_knee_r_rotation2" range="-0.001678 0.03354" limited="true" user="-1.4732523263838448e-08" ref="0" axis="0.9922 0.124 -0.008789" type="hinge"/>
          <joint name="walker_knee_r_rotation3" range="0 0.2628" limited="true" user="1.0893911855935912e-08" ref="0" axis="-0.1243 0.9898 -0.07016" type="hinge"/>
          <body name="talus_r" pos="-0.01081 -0.4356 0" euler="-0 0 -1.735e-18">
            <inertial mass="0.0871420855" pos="0.0000000000 0.0000000000 0.0000000000" fullinertia="0.0008714209 0.0008714209 0.0008714209 0.0000000000 0.0000000000 0.0000000000"/>
            <geom name="talus_r_geom_1" type="mesh" mesh="talus_r_geom_1_r_talus" rgba="1 1 1 0" group="0"/>
            <joint name="ankle_angle_r" range="-0.6981 0.5236" limited="true" user="0.0" ref="0" type="hinge" axis="-0.105 -0.174 0.9791"/>
            <body name="calcn_r" pos="-0.04987 -0.04307 0.008172" euler="-0 0 0">
              <inertial mass="1.0892760688" pos="0.1000000000 0.0300000000 0.0000000000" fullinertia="0.0012199892 0.0033985413 0.0035728255 0.0000000000 0.0000000000 0.0000000000"/>
              <geom name="calcn_r_geom_1" type="mesh" mesh="calcn_r_geom_1_r_foot" rgba="1 1 1 1" group="0"/>
              <joint name="subtalar_angle_r" range="-0.3491 0.3491" limited="true" user="0.0" ref="0" type="hinge" axis="0.7872 0.6047 -0.1209"/>
              <body name="toes_r" pos="0.1595 -0.001752 0.0009638" euler="-0 0 0">
                <inertial mass="0.1887497572" pos="0.0346000000 0.0060000000 -0.0175000000" fullinertia="0.0005494308 0.0006365729 0.0008714209 0.0000000000 0.0000000000 0.0000000000"/>
                <geom name="toes_r_geom_1" type="mesh" mesh="toes_r_geom_1_r_bofoot" rgba="1 1 1 1" group="0"/>
                <joint name="mtp_angle_r" range="-0.5236 0.5236" limited="true" user="0.0" ref="0" type="hinge" axis="0.581 2.16e-06 -0.8139"/>
                <site name="edl_r_edl_r-P5" pos="0.00030722755835999998 0.0048154044965400006 0.015684474971429999"/>
                <site name="edl_r_edl_r-P6" pos="0.04536726945116 -0.00040982165928000005 0.025628227077499999"/>
                <site name="ehl_r_ehl_r-P7" pos="0.030517937463760001 0.00420067200762 -0.02511566253595"/>
                <site name="ehl_r_ehl_r-P8" pos="0.057656371785560004 0.0034834841038799999 -0.019067400945659996"/>
                <site name="fdl_r_fdl_r-P6" pos="-0.0019457745362800002 -0.0079915223559600002 0.015069397521569999"/>
                <site name="fdl_r_fdl_r-P7" pos="0.029186618044200002 -0.0072743344522200005 0.022040275286649997"/>
                <site name="fdl_r_fdl_r-P8" pos="0.045162451078920002 -0.0061473248892000001 0.024808123811019999"/>
                <site name="fhl_r_fhl_r-P6" pos="0.0158734238486 -0.0065571465484800008 -0.027165920702149998"/>
                <site name="fhl_r_fhl_r-P7" pos="0.057553962599440005 -0.010450452311640001 -0.018554836404110001"/>
              </body>
              <site name="edl_r_edl_r-P3" pos="0.081957015824459994 0.031540855082399996 0.00071395961608000007"/>
              <site name="edl_r_edl_r-P4" pos="0.14411592771744 0.0048187417487000001 0.011601843761299999"/>
              <site name="ehl_r_ehl_r-P4" pos="0.086505228889800001 0.034081646186260001 -0.01883068487411"/>
              <site name="ehl_r_ehl_r-P5" pos="0.11531057830362 0.02707256727906 -0.02293595266657"/>
              <site name="ehl_r_ehl_r-P6" pos="0.15463924422156 0.012178274601259999 -0.024988586562800001"/>
              <site name="fdl_r_fdl_r-P3" pos="0.038882762676240003 0.027598248197100002 -0.024988586562800001"/>
              <site name="fdl_r_fdl_r-P4" pos="0.063139899024720003 0.015419973595840001 -0.023471422378630001"/>
              <site name="fdl_r_fdl_r-P5" pos="0.14786151494772001 -0.00709669239354 0.01035241443316"/>
              <site name="fhl_r_fhl_r-P3" pos="0.03335356247916 0.024181322229839999 -0.02150803343441"/>
              <site name="fhl_r_fhl_r-P4" pos="0.09256951297692001 0.00595771707112 -0.022846707714560002"/>
              <site name="fhl_r_fhl_r-P5" pos="0.15392579903483999 -0.0046435147760200005 -0.024006892090689999"/>
              <site name="gaslat_r_gaslat_r-P2" pos="0.00392394852696 0.027160180765399999 -0.0047299824565300002"/>
              <site name="gasmed_r_gasmed_r-P2" pos="0.00392394852696 0.027160180765399999 -0.0047299824565300002"/>
              <site name="perbrev_r_perbrev_r-P4" pos="0.042004085368140001 0.023655641311800001 0.020794073818330001"/>
              <site name="perbrev_r_perbrev_r-P5" pos="0.060375298926179995 0.019187353508460001 0.030611018539429997"/>
              <site name="perlong_r_perlong_r-P4" pos="0.039061123972919998 0.020151101858200002 0.019723134394210001"/>
              <site name="perlong_r_perlong_r-P5" pos="0.060732021519539998 0.009287029552040001 0.025345566370840001"/>
              <site name="perlong_r_perlong_r-P6" pos="0.07598191238568 0.0060453305574599998 0.01053090433718"/>
              <site name="perlong_r_perlong_r-P7" pos="0.10728431995302 0.0074471463389000009 -0.016421071169839999"/>
              <site name="soleus_r_soleus_r-P2" pos="0.00392394852696 0.027160180765399999 -0.0047299824565300002"/>
              <site name="tibant_r_tibant_r-P4" pos="0.10398463596443999 0.01559520056852 -0.027219710363050001"/>
              <site name="tibpost_r_tibpost_r-P3" pos="0.037188330357779999 0.029262904437560001 -0.025524056274859999"/>
              <site name="tibpost_r_tibpost_r-P4" pos="0.068847460518480008 0.013930544328060001 -0.025077831514809999"/>
              <site name="RTOE_marker" group="4" pos="0.1841 0.01248 0.01295" rgba="1 0.1 0.5 0.5" size="0.01"/>
              <site name="RHEE_marker" group="4" pos="-0.01277 0.02009 -0.001019" rgba="1 0.1 0.5 0.5" size="0.01"/>
              <site name="RLatFoot_marker" group="4" pos="0.1113 0.01755 0.0407" rgba="1 0.1 0.5 0.5" size="0.01"/>
            </body>
          </body>
          <site name="bflh_r_bflh_r-P2" pos="-0.036416609383280001 -0.038117115372000007 0.02694425160207"/>
          <site name="bflh_r_bflh_r-P3" pos="-0.031013551611279996 -0.0495522499836 0.032269202511570005"/>
          <site name="bfsh_r_bfsh_r-P2" pos="-0.032526407787439995 -0.045631632402479999 0.033866687784420001"/>
          <site name="edl_r_edl_r-P1" pos="-0.017289784870399998 -0.12600429281544001 0.021832298728950001"/>
          <site name="edl_r_edl_r-P2" pos="0.017722029492160001 -0.40948672513920004 0.01192789003728"/>
          <site name="ehl_r_ehl_r-P1" pos="-0.015128561761599999 -0.16880436807600002 0.020128314437910001"/>
          <site name="ehl_r_ehl_r-P2" pos="0.0076723420362400001 -0.31680768176328 0.017465838983160002"/>
          <site name="ehl_r_ehl_r-P3" pos="0.021612231087999999 -0.40219002019656003 -0.0029819725093200001"/>
          <site name="fdl_r_fdl_r-P1" pos="-0.0024854065751199997 -0.19951587246144001 -0.00191698232742"/>
          <site name="fdl_r_fdl_r-P2" pos="-0.019018763357439999 -0.39696253008839999 -0.013205878255560001"/>
          <site name="fhl_r_fhl_r-P1" pos="-0.033498958186399995 -0.23556377299896 0.021299803638000003"/>
          <site name="fhl_r_fhl_r-P2" pos="-0.026150799616479998 -0.39979408723032001 -0.0080939253824399999"/>
          <site name="grac_r_grac_r-P2" pos="-0.019904864832047998 -0.051784823883960003 -0.031534359286059001"/>
          <site name="grac_r_grac_r-P3" pos="0.0019234885668319996 -0.075820387777104009 -0.016752295561287003"/>
          <site name="GR_at_condyles_r_cylinder_grac_r_1_sidesite" pos="-0.0167 -0.005218 -0.03395" size="0.0005"/>
          <site name="perbrev_r_perbrev_r-P1" pos="-0.026258860771919995 -0.27575010320544002 0.026731253565690002"/>
          <site name="perbrev_r_perbrev_r-P2" pos="-0.036632731694159995 -0.42397122898056 0.02651825552931"/>
          <site name="perbrev_r_perbrev_r-P3" pos="-0.030797429300399998 -0.43605979985568 0.027157249638449999"/>
          <site name="perlong_r_perlong_r-P1" pos="-0.021612231087999999 -0.14952799830216001 0.03003272312958"/>
          <site name="perlong_r_perlong_r-P2" pos="-0.034255386274479993 -0.42473357128800004 0.025240267311030001"/>
          <site name="perlong_r_perlong_r-P3" pos="-0.029392634279679995 -0.43714886029487998 0.0255597643656"/>
          <site name="recfem_r_recfem_r-P5" pos="0.035227936673439993 -0.068741494922303997 -0.00050054538549299996"/>
          <site name="sart_r_sart_r-P3" pos="-0.027123350015439997 -0.043671323611919999 -0.038872141639350002"/>
          <site name="sart_r_sart_r-P4" pos="-0.01718172371496 -0.065234720308080002 -0.028115740802160002"/>
          <site name="sart_r_sart_r-P5" pos="0.014696317139839998 -0.088213895575200013 -0.0027689744729400001"/>
          <site name="semimem_r_semimem_r-P2" pos="-0.031337735077600001 -0.045413820314640002 -0.020873807565240002"/>
          <site name="SM_at_condyles_r_cylinder_semimem_r_1_sidesite" pos="-0.03134 -0.04541 -0.02087" size="0.0005"/>
          <site name="semiten_r_semiten_r-P2" pos="-0.033715080497279996 -0.055324270311360002 -0.024388275165510002"/>
          <site name="semiten_r_semiten_r-P3" pos="0.0020531619533599998 -0.08418437195016 -0.01246038512823"/>
          <site name="ST_at_condyles_r_cylinder_semiten_r_1_sidesite" pos="-0.03795 -0.006811 -0.02637" size="0.0005"/>
          <site name="soleus_r_soleus_r-P1" pos="-0.0082126478134399994 -0.099757936230720004 0.010436903782620001"/>
          <site name="tfl_r_tfl_r-P4" pos="0.01167060478752 -0.044651478007200006 0.036848660293740003"/>
          <site name="tibant_r_tibant_r-P1" pos="0.01664141793776 -0.14288472962304002 0.01725284094678"/>
          <site name="tibant_r_tibant_r-P2" pos="0.027123350015439997 -0.20757491971152001 0.013631874328320002"/>
          <site name="tibant_r_tibant_r-P3" pos="0.025178249217519998 -0.39848721470328002 -0.014057870401080001"/>
          <site name="tibpost_r_tibpost_r-P1" pos="-0.0044305073730400001 -0.14201348127168001 0.010969398873570001"/>
          <site name="tibpost_r_tibpost_r-P2" pos="-0.017722029492160001 -0.39805159052760003 -0.018637328183250004"/>
          <site name="vasint_r_vasint_r-P5" pos="0.035195518326807999 -0.068828619757440007 0.00045794577821700003"/>
          <site name="vaslat_r_vaslat_r-P5" pos="0.035163099980175999 -0.069024650636496016 0.0054420998295090003"/>
          <site name="vasmed_r_vasmed_r-P5" pos="0.034471508585359995 -0.069231572119944004 -0.0072206334332820003"/>
          <site name="RANK_marker" group="4" pos="-0.02098 -0.4183 0.05563" rgba="1 0.1 0.5 0.5" size="0.01"/>
          <site name="RANKmed_marker" group="4" pos="0.01494 -0.3995 -0.03393" rgba="1 0.1 0.5 0.5" size="0.01"/>
          <site name="RTIB_marker" group="4" pos="0.0158 -0.2138 0.05833" rgba="1 0.1 0.5 0.5" size="0.01"/>
          <site name="RTIB2_marker" group="4" pos="-0.05381 -0.216 0.06813" rgba="1 0.1 0.5 0.5" size="0.01"/>
          <site name="RTIB3_marker" group="4" pos="-0.01972 -0.2654 0.06454" rgba="1 0.1 0.5 0.5" size="0.01"/>
        </body>
        <body name="patella_r" pos="-0.008511 -0.4225 -0.002842" euler="-0 0 0">
          <inertial mass="0.065380909823214067" pos="0.0018 0.0264 0" fullinertia="2.1768353966661763e-06 9.9436627352939266e-06 9.9436627352939266e-06 0 0 0"/>
          <geom name="patella_r_geom_1" type="mesh" mesh="patella_r_geom_1_r_patella" rgba="1 1 1 1" group="0"/>
          <joint name="patellofemoral_r_translation1" range="-0.02388 0.05513" limited="true" user="0.05515011545973533" ref="0" axis="1 0 0" type="slide"/>
          <joint name="patellofemoral_r_translation2" range="-0.04225 -0.01118" limited="true" user="-0.011213952937498647" ref="0" axis="0 1 0" type="slide"/>
          <joint name="patellofemoral_r_translation3" limited="false" ref="0" axis="0 0 1" type="slide"/>
          <joint name="patellofemoral_r_rotation1" range="-1.786 0.001137" limited="true" user="0.01050598499723554" ref="0" axis="0 0 1" type="hinge"/>
          <site name="recfem_r_recfem_r-P2" pos="0.01 0.049000000000000002 0.00069999999999999999"/>
          <site name="recfem_r_recfem_r-P3" pos="0.0121 0.043700000000000003 -0.001"/>
          <site name="recfem_r_recfem_r-P4" pos="0.0050000000000000001 0.00247 3.0000000000000001e-05"/>
          <site name="vasint_r_vasint_r-P3" pos="0.0057999999999999996 0.048000000000000001 -0.00059999999999999995"/>
          <site name="vasint_r_vasint_r-P4" pos="0.0050000000000000001 0.00247 -0.00038999999999999999"/>
          <site name="vaslat_r_vaslat_r-P3" pos="0.0103 0.042299999999999997 0.0141"/>
          <site name="vaslat_r_vaslat_r-P4" pos="0.0050000000000000001 0.00247 0.0073299999999999997"/>
          <site name="vasmed_r_vasmed_r-P3" pos="0.0063 0.044499999999999998 -0.017000000000000001"/>
          <site name="vasmed_r_vasmed_r-P4" pos="0.0050000000000000001 0.00247 -0.0085000000000000006"/>
        </body>
        <site name="addbrev_r_addbrev_r-P2" pos="-0.0021041939963999997 -0.12220453303619999 0.025731378522930001"/>
        <site name="AB_at_femshaft_r_cylinder_addbrev_r_1_sidesite" pos="0.001208 -0.1098 0.01501" size="0.0005"/>
        <site name="addlong_r_addlong_r-P2" pos="0.011846612199731998 -0.24789914468538299 0.016358543052931"/>
        <site name="AL_at_femshaft_r_cylinder_addlong_r_1_sidesite" pos="0.01185 -0.2479 0.01636" size="0.0005"/>
        <site name="addmagDist_r_addmagDist_r-P2" pos="0.011836091229749999 -0.27185330442375 0.019944401827010003"/>
        <site name="AMdist_at_femshaft_r_cylinder_addmagDist_r_1_sidesite" pos="0.01184 -0.2719 0.01994" size="0.0005"/>
        <site name="addmagIsch_r_addmagIsch_r-P2" pos="0.0050605865613419995 -0.40179400578012298 -0.033822812010261001"/>
        <site name="AMisch_at_condyles_r_cylinder_addmagIsch_r_1_sidesite" pos="0.005061 -0.4018 -0.03382" size="0.0005"/>
        <site name="addmagMid_r_addmagMid_r-P2" pos="0.0025460747356439994 -0.16818657767015999 0.030195617688354"/>
        <site name="AMmid_at_femshaft_r_cylinder_addmagMid_r_1_sidesite" pos="0.002546 -0.1682 0.0302" size="0.0005"/>
        <site name="addmagProx_r_addmagProx_r-P2" pos="-0.016065521162513998 -0.081669910807073989 0.033089106036314"/>
        <site name="AMprox_at_femshaft_r_cylinder_addmagProx_r_1_sidesite" pos="-0.01687 -0.07597 0.02075" size="0.0005"/>
        <site name="bfsh_r_bfsh_r-P1" pos="0.0052604849909999992 -0.21862183833849 0.024181295479380003"/>
        <site name="gaslat_r_gaslat_r-P1" pos="-0.0031562909946 -0.39498990593226002 0.028624866870890001"/>
        <site name="Gastroc_at_condyles_r_cylinder_gaslat_r_1_sidesite" pos="-0.009086 -0.4478 0.02569" size="0.0005"/>
        <site name="gasmed_r_gasmed_r-P1" pos="0.0084167759855999988 -0.39229726367891998 -0.02149448487056"/>
        <site name="Gastroc_at_condyles_r_cylinder_gasmed_r_1_sidesite" pos="0.001201 -0.4454 -0.01886" size="0.0005"/>
        <site name="glmax1_r_glmax1_r-P3" pos="-0.04671310672008 -0.033761591330339999 0.031208338610140003"/>
        <site name="glmax1_r_glmax1_r-P4" pos="-0.029143086850139995 -0.058616750591939992 0.0485692686979"/>
        <site name="glmax2_r_glmax2_r-P3" pos="-0.047344364918999994 -0.060480887536559995 0.026041395131639999"/>
        <site name="glmax2_r_glmax2_r-P4" pos="-0.016412713171919998 -0.10522017420744 0.043298986349830003"/>
        <site name="glmax3_r_glmax3_r-P3" pos="-0.029563925649419998 -0.11650855903875 0.0097138537395800011"/>
        <site name="glmax3_r_glmax3_r-P4" pos="-0.0063125819892 -0.14695612913421 0.042472275393269997"/>
        <site name="glmed1_r_glmed1_r-P2_0" pos="-0.014615473436660789 -0.01894657540385342 0.061165883919116884"/>
        <site name="glmed2_r_glmed2_r-P2_0" pos="-0.02318402447192866 -0.010313955916227443 0.058000205020272179"/>
        <site name="glmed3_r_glmed3_r-P2_0" pos="-0.032509797244379995 -0.0048674686887299999 0.053529534437260003"/>
        <site name="glmin1_r_glmin1_r-P2" pos="0.005775295808666708 -0.01604048530000524 0.05790883185503326"/>
        <site name="glmin2_r_glmin2_r-P2" pos="0.0037281487758604455 -0.009333390859332942 0.054216043181955151"/>
        <site name="glmin3_r_glmin3_r-P2" pos="-0.003762443357808249 -0.0013118353894406511 0.052973209145447224"/>
        <site name="iliacus_r_iliacus_r-P3" pos="-0.0024198230958599998 -0.058513187428350003 0.014364102870229999"/>
        <site name="iliacus_r_iliacus_r-P4" pos="-0.01283558337804 -0.065969735206829999 0.020254418435720001"/>
        <site name="piri_r_piri_r-P3" pos="-0.015571035573359999 -0.0037282738892399996 0.045159086002090003"/>
        <site name="psoas_r_psoas_r-P3" pos="-0.013887680376239999 -0.048363997396529995 0.0047535880002199998"/>
        <site name="psoas_r_psoas_r-P4" pos="-0.024724279457699998 -0.05426709772116 0.00909382052216"/>
        <site name="KnExt_at_fem_r_cylinder_recfem_r_3_sidesite" pos="-0.01715 -0.4118 -0.01422" size="0.0005"/>
        <site name="KnExt_at_fem_r_cylinder_recfem_r_2_sidesite" pos="0.003589 -0.3788 -0.003842" size="0.0005"/>
        <site name="sart_r_sart_r-P2" pos="-0.0031562909946 -0.36951336768911996 -0.043505664088969997"/>
        <site name="tfl_r_tfl_r-P2" pos="0.030931651747079996 -0.10304534777205 0.061693305133290008"/>
        <site name="tfl_r_tfl_r-P3" pos="0.011257437880739999 -0.41943081253949999 0.033481793740679999"/>
        <site name="vasint_r_vasint_r-P1" pos="0.0305108129478 -0.19925552674715999 0.032035049566700002"/>
        <site name="vasint_r_vasint_r-P2" pos="0.035245249439699998 -0.21582563292155998 0.02945157782745"/>
        <site name="KnExt_at_fem_r_cylinder_vasint_r_3_sidesite" pos="-0.0173 -0.4109 -0.0137" size="0.0005"/>
        <site name="vaslat_r_vaslat_r-P1" pos="0.0050500655913599994 -0.19200610529586001 0.036065265479930005"/>
        <site name="vaslat_r_vaslat_r-P2" pos="0.028301409251579999 -0.26833215686168999 0.042265597654130002"/>
        <site name="KnExt_at_fem_r_cylinder_vaslat_r_3_sidesite" pos="-0.02036 -0.4117 0.01326" size="0.0005"/>
        <site name="KnExt_at_fem_r_cylinder_vaslat_r_2_sidesite" pos="0.001789 -0.3802 0.01126" size="0.0005"/>
        <site name="vasmed_r_vasmed_r-P1" pos="0.0147293579748 -0.21737908037540998 0.019427707479160002"/>
        <site name="vasmed_r_vasmed_r-P2" pos="0.037454653135919995 -0.28676639998070996 0.00093004982612999998"/>
        <site name="KnExt_at_fem_r_cylinder_vasmed_r_4_sidesite" pos="-0.008865 -0.4222 -0.02127" size="0.0005"/>
        <site name="KnExt_at_fem_r_cylinder_vasmed_r_3_sidesite" pos="-0.008865 -0.4222 -0.02127" size="0.0005"/>
        <site name="RKNE_marker" group="4" pos="-0.0009574 -0.4282 0.05637" rgba="1 0.1 0.5 0.5" size="0.01"/>
        <site name="RKNEmed_marker" group="4" pos="-0.02814 -0.4057 -0.06099" rgba="1 0.1 0.5 0.5" size="0.01"/>
        <site name="RTHI_marker" group="4" pos="0.0467 -0.166 0.08276" rgba="1 0.1 0.5 0.5" size="0.01"/>
        <site name="RTHI2_marker" group="4" pos="-0.05619 -0.1669 0.0704" rgba="1 0.1 0.5 0.5" size="0.01"/>
        <site name="RTHI3_marker" group="4" pos="-0.000924 -0.2408 0.0809" rgba="1 0.1 0.5 0.5" size="0.01"/>
      </body>
      <body name="femur_l" pos="-0.05773 -0.07918 -0.07995" euler="-0 0 0">
        <inertial mass="8.1054339410" pos="0.0000000000 -0.1700000000 0.0000000000" fullinertia="0.1166832525 0.0305868720 0.1230446247 0.0000000000 0.0000000000 0.0000000000"/>
        <geom name="femur_l_geom_1" type="mesh" mesh="femur_l_geom_1_l_femur" rgba="1 1 1 1" group="0"/>
        <geom name="Gastroc_at_condyles_l_cylinder" type="cylinder" euler="0 0 0" pos="0.00526 -0.4246 0" size="0.0261 0.05167" rgba="0.19 0.83 0.78 0.2" group="2"/>
        <geom name="KnExt_at_fem_l_cylinder" type="cylinder" euler="0.06234 -0.05076 0" pos="0.003775 -0.4171 -0.002161" size="0.0261 0.05167" rgba="0.19 0.83 0.78 0.2" group="2"/>
        <geom name="AB_at_femshaft_l_cylinder" type="cylinder" euler="-1.662 -0.1866 0" pos="0.01541 -0.1166 -0.02415" size="0.0172 0.03627" rgba="0.19 0.83 0.78 0.2" group="2"/>
        <geom name="AL_at_femshaft_l_cylinder" type="cylinder" euler="-1.777 -0.1365 0" pos="0.03233 -0.2402 -0.01562" size="0.02096 0.05179" rgba="0.19 0.83 0.78 0.2" group="2"/>
        <geom name="AMprox_at_femshaft_l_cylinder" type="cylinder" euler="-1.611 -0.1866 0" pos="0.005453 -0.07549 -0.02625" size="0.022 0.03627" rgba="0.19 0.83 0.78 0.2" group="2"/>
        <geom name="AMmid_at_femshaft_l_cylinder" type="cylinder" euler="-1.611 -0.1366 0" pos="0.02421 -0.1664 -0.02127" size="0.02231 0.06216" rgba="0.19 0.83 0.78 0.2" group="2"/>
        <geom name="AMdist_at_femshaft_l_cylinder" type="cylinder" euler="-1.712 -0.1866 0" pos="0.03325 -0.27 -0.009677" size="0.02273 0.1036" rgba="0.19 0.83 0.78 0.2" group="2"/>
        <geom name="AMisch_at_condyles_l_cylinder" type="cylinder" euler="-1.711 0.4634 0" pos="-0.02383 -0.3903 0.00326" size="0.04165 0.1247" rgba="0.19 0.83 0.78 0.2" group="2"/>
        <geom name="PECT_at_femshaft_l_cylinder" type="cylinder" euler="-1.813 -0.2763 0" pos="0.006403 -0.08751 -0.03146" size="0.01563 0.02592" rgba="0.19 0.83 0.78 0.2" group="2"/>
        <joint name="hip_flexion_l" range="-0.5236 2.094" limited="true" user="0.0" ref="0" axis="0 0 1" type="hinge"/>
        <joint name="hip_adduction_l" range="-0.8727 0.5236" limited="true" user="-0.0" ref="0" axis="-1 -0 -0" type="hinge"/>
        <joint name="hip_rotation_l" range="-0.6981 0.6981" limited="true" user="-0.0" ref="0" axis="-0 -1 -0" type="hinge"/>
        <body name="tibia_l" pos="0.0002302 -0.4186 0.001261" euler="-0 0 0">
          <inertial mass="3.2307928200" pos="0.0000000000 -0.1867000000 0.0000000000" fullinertia="0.0439196111 0.0044442464 0.0445296057 0.0000000000 0.0000000000 0.0000000000"/>
          <geom name="tibia_l_geom_1" type="mesh" mesh="tibia_l_geom_1_l_tibia" rgba="1 1 1 1" group="0"/>
          <geom name="tibia_l_geom_2" type="mesh" mesh="tibia_l_geom_2_l_fibula" rgba="1 1 1 1" group="0"/>
          <geom name="GasLat_at_shank_l_cylinder" type="cylinder" euler="-2.967 0.2797 -1.478" pos="-0.007997 -0.08059 0.003514" size="0.05962 0.05334" rgba="0.19 0.83 0.78 0.2" group="2"/>
          <site name="GasLat_at_shank_l_sidesite" pos="-0.06601 -0.07218 -0.01192" size="0.0005"/>
          <geom name="GasMed_at_shank_l_cylinder" type="cylinder" euler="-2.967 -0.02797 -1.478" pos="-0.007997 -0.08059 0.003514" size="0.05965 0.05329" rgba="0.19 0.83 0.78 0.2" group="2"/>
          <site name="GasMed_at_shank_l_sidesite" pos="-0.06836 -0.07536 0.006151" size="0.0005"/>
          <geom name="GR_at_condyles_l_cylinder" type="cylinder" euler="0 0.4 0" pos="-0.003242 -0.02178 0" size="0.03901 0.05337" rgba="0.19 0.83 0.78 0.2" group="2"/>
          <geom name="SM_at_condyles_l_cylinder" type="cylinder" euler="0 0.1 0" pos="-0.001081 -0.02178 0" size="0.03818 0.05326" rgba="0.19 0.83 0.78 0.2" group="2"/>
          <geom name="ST_at_condyles_l_cylinder" type="cylinder" euler="0 0.2 0" pos="-0.002161 -0.02233 0" size="0.04609 0.05328" rgba="0.19 0.83 0.78 0.2" group="2"/>
          <geom name="BF_at_gastroc_l_cylinder" type="cylinder" euler="0 0 0" pos="-0.06268 -0.06534 0" size="0.03255 0.07987" rgba="0.19 0.83 0.78 0.2" group="2"/>
          <joint name="walker_knee_l_translation1" range="0 0.001656" limited="true" user="9.877164921807263e-08" ref="0" axis="-0.1243 0.9898 0.07016" type="slide"/>
          <joint name="walker_knee_l_translation2" range="-0.007019 0" limited="true" user="-7.949387155481435e-11" ref="0" axis="-0.9922 -0.124 -0.008789" type="slide"/>
          <joint name="knee_angle_l" range="0 2.094" limited="true" user="0.0" ref="0" axis="4.566e-07 0.07071 -0.9975" type="hinge"/>
          <joint name="walker_knee_l_rotation2" range="-0.001678 0.03354" limited="true" user="-1.4732523263838448e-08" ref="0" axis="-0.9922 -0.124 -0.008789" type="hinge"/>
          <joint name="walker_knee_l_rotation3" range="-0.2628 0" limited="true" user="-1.0893911855935912e-08" ref="0" axis="-0.1243 0.9898 0.07016" type="hinge"/>
          <body name="talus_l" pos="-0.01081 -0.4356 0" euler="-0 0 -1.735e-18">
            <inertial mass="0.0871420855" pos="0.0000000000 0.0000000000 0.0000000000" fullinertia="0.0008714209 0.0008714209 0.0008714209 0.0000000000 0.0000000000 0.0000000000"/>
            <geom name="talus_l_geom_1" type="mesh" mesh="talus_l_geom_1_l_talus" rgba="1 1 1 0" group="0"/>
            <joint name="ankle_angle_l" range="-0.6981 0.5236" limited="true" user="0.0" ref="0" type="hinge" axis="0.105 0.174 0.9791"/>
            <body name="calcn_l" pos="-0.04987 -0.04307 -0.008172" euler="-0 0 0">
              <inertial mass="1.0892760688" pos="0.1000000000 0.0300000000 0.0000000000" fullinertia="0.0012199892 0.0033985413 0.0035728255 0.0000000000 0.0000000000 0.0000000000"/>
              <geom name="calcn_l_geom_1" type="mesh" mesh="calcn_l_geom_1_l_foot" rgba="1 1 1 1" group="0"/>
              <joint name="subtalar_angle_l" range="-0.3491 0.3491" limited="true" user="0.0" ref="0" type="hinge" axis="-0.7872 -0.6047 -0.1209"/>
              <body name="toes_l" pos="0.1595 -0.001752 -0.0009638" euler="-0 0 0">
                <inertial mass="0.1887497572" pos="0.0346000000 0.0060000000 0.0175000000" fullinertia="0.0005494308 0.0006365729 0.0008714209 0.0000000000 0.0000000000 0.0000000000"/>
                <geom name="toes_l_geom_1" type="mesh" mesh="toes_l_geom_1_l_bofoot" rgba="1 1 1 1" group="0"/>
                <joint name="mtp_angle_l" range="-0.5236 0.5236" limited="true" user="0.0" ref="0" type="hinge" axis="-0.581 2.16e-06 -0.8139"/>
                <site name="edl_l_edl_l-P5" pos="0.00030722755835999998 0.0048154044965400006 -0.015684474971429999"/>
                <site name="edl_l_edl_l-P6" pos="0.04536726945116 -0.00040982165928000005 -0.025628227077499999"/>
                <site name="ehl_l_ehl_l-P7" pos="0.030517937463760001 0.00420067200762 0.02511566253595"/>
                <site name="ehl_l_ehl_l-P8" pos="0.057656371785560004 0.0034834841038799999 0.019067400945659996"/>
                <site name="fdl_l_fdl_l-P6" pos="-0.0019457745362800002 -0.0079915223559600002 -0.015069397521569999"/>
                <site name="fdl_l_fdl_l-P7" pos="0.029186618044200002 -0.0072743344522200005 -0.022040275286649997"/>
                <site name="fdl_l_fdl_l-P8" pos="0.045162451078920002 -0.0061473248892000001 -0.024808123811019999"/>
                <site name="fhl_l_fhl_l-P6" pos="0.0158734238486 -0.0065571465484800008 0.027165920702149998"/>
                <site name="fhl_l_fhl_l-P7" pos="0.057553962599440005 -0.010450452311640001 0.018554836404110001"/>
              </body>
              <site name="edl_l_edl_l-P3" pos="0.081957015824459994 0.031540855082399996 -0.00071395961608000007"/>
              <site name="edl_l_edl_l-P4" pos="0.14411592771744 0.0048187417487000001 -0.011601843761299999"/>
              <site name="ehl_l_ehl_l-P4" pos="0.086505228889800001 0.034081646186260001 0.01883068487411"/>
              <site name="ehl_l_ehl_l-P5" pos="0.11531057830362 0.02707256727906 0.02293595266657"/>
              <site name="ehl_l_ehl_l-P6" pos="0.15463924422156 0.012178274601259999 0.024988586562800001"/>
              <site name="fdl_l_fdl_l-P3" pos="0.038882762676240003 0.027598248197100002 0.024988586562800001"/>
              <site name="fdl_l_fdl_l-P4" pos="0.063139899024720003 0.015419973595840001 0.023471422378630001"/>
              <site name="fdl_l_fdl_l-P5" pos="0.14786151494772001 -0.00709669239354 -0.01035241443316"/>
              <site name="fhl_l_fhl_l-P3" pos="0.03335356247916 0.024181322229839999 0.02150803343441"/>
              <site name="fhl_l_fhl_l-P4" pos="0.09256951297692001 0.00595771707112 0.022846707714560002"/>
              <site name="fhl_l_fhl_l-P5" pos="0.15392579903483999 -0.0046435147760200005 0.024006892090689999"/>
              <site name="gaslat_l_gaslat_l-P2" pos="0.00392394852696 0.027160180765399999 0.0047299824565300002"/>
              <site name="gasmed_l_gasmed_l-P2" pos="0.00392394852696 0.027160180765399999 0.0047299824565300002"/>
              <site name="perbrev_l_perbrev_l-P4" pos="0.042004085368140001 0.023655641311800001 -0.020794073818330001"/>
              <site name="perbrev_l_perbrev_l-P5" pos="0.060375298926179995 0.019187353508460001 -0.030611018539429997"/>
              <site name="perlong_l_perlong_l-P4" pos="0.039061123972919998 0.020151101858200002 -0.019723134394210001"/>
              <site name="perlong_l_perlong_l-P5" pos="0.060732021519539998 0.009287029552040001 -0.025345566370840001"/>
              <site name="perlong_l_perlong_l-P6" pos="0.07598191238568 0.0060453305574599998 -0.01053090433718"/>
              <site name="perlong_l_perlong_l-P7" pos="0.10728431995302 0.0074471463389000009 0.016421071169839999"/>
              <site name="soleus_l_soleus_l-P2" pos="0.00392394852696 0.027160180765399999 0.0047299824565300002"/>
              <site name="tibant_l_tibant_l-P4" pos="0.10398463596443999 0.01559520056852 0.027219710363050001"/>
              <site name="tibpost_l_tibpost_l-P3" pos="0.037188330357779999 0.029262904437560001 0.025524056274859999"/>
              <site name="tibpost_l_tibpost_l-P4" pos="0.068847460518480008 0.013930544328060001 0.025077831514809999"/>
              <site name="LTOE_marker" group="4" pos="0.1795 0.01193 -0.008255" rgba="1 0.1 0.5 0.5" size="0.01"/>
              <site name="LHEE_marker" group="4" pos="-0.01286 0.02091 0.0006656" rgba="1 0.1 0.5 0.5" size="0.01"/>
              <site name="LLatFoot_marker" group="4" pos="0.1113 0.01503 -0.04714" rgba="1 0.1 0.5 0.5" size="0.01"/>
            </body>
          </body>
          <site name="bflh_l_bflh_l-P2" pos="-0.036416609383280001 -0.038117115372000007 -0.02694425160207"/>
          <site name="bflh_l_bflh_l-P3" pos="-0.031013551611279996 -0.0495522499836 -0.032269202511570005"/>
          <site name="bfsh_l_bfsh_l-P2" pos="-0.032526407787439995 -0.045631632402479999 -0.033866687784420001"/>
          <site name="edl_l_edl_l-P1" pos="-0.017289784870399998 -0.12600429281544001 -0.021832298728950001"/>
          <site name="edl_l_edl_l-P2" pos="0.017722029492160001 -0.40948672513920004 -0.01192789003728"/>
          <site name="ehl_l_ehl_l-P1" pos="-0.015128561761599999 -0.16880436807600002 -0.020128314437910001"/>
          <site name="ehl_l_ehl_l-P2" pos="0.0076723420362400001 -0.31680768176328 -0.017465838983160002"/>
          <site name="ehl_l_ehl_l-P3" pos="0.021612231087999999 -0.40219002019656003 0.0029819725093200001"/>
          <site name="fdl_l_fdl_l-P1" pos="-0.0024854065751199997 -0.19951587246144001 0.00191698232742"/>
          <site name="fdl_l_fdl_l-P2" pos="-0.019018763357439999 -0.39696253008839999 0.013205878255560001"/>
          <site name="fhl_l_fhl_l-P1" pos="-0.033498958186399995 -0.23556377299896 -0.021299803638000003"/>
          <site name="fhl_l_fhl_l-P2" pos="-0.026150799616479998 -0.39979408723032001 0.0080939253824399999"/>
          <site name="grac_l_grac_l-P2" pos="-0.019904864832047998 -0.051784823883960003 0.031534359286059001"/>
          <site name="grac_l_grac_l-P3" pos="0.0019234885668319996 -0.075820387777104009 0.016752295561287003"/>
          <site name="GR_at_condyles_l_cylinder_grac_l_1_sidesite" pos="-0.0167 -0.005218 0.03395" size="0.0005"/>
          <site name="perbrev_l_perbrev_l-P1" pos="-0.026258860771919995 -0.27575010320544002 -0.026731253565690002"/>
          <site name="perbrev_l_perbrev_l-P2" pos="-0.036632731694159995 -0.42397122898056 -0.02651825552931"/>
          <site name="perbrev_l_perbrev_l-P3" pos="-0.030797429300399998 -0.43605979985568 -0.027157249638449999"/>
          <site name="perlong_l_perlong_l-P1" pos="-0.021612231087999999 -0.14952799830216001 -0.03003272312958"/>
          <site name="perlong_l_perlong_l-P2" pos="-0.034255386274479993 -0.42473357128800004 -0.025240267311030001"/>
          <site name="perlong_l_perlong_l-P3" pos="-0.029392634279679995 -0.43714886029487998 -0.0255597643656"/>
          <site name="recfem_l_recfem_l-P5" pos="0.035227936673439993 -0.068741494922303997 0.00050054538549299996"/>
          <site name="sart_l_sart_l-P3" pos="-0.027123350015439997 -0.043671323611919999 0.038872141639350002"/>
          <site name="sart_l_sart_l-P4" pos="-0.01718172371496 -0.065234720308080002 0.028115740802160002"/>
          <site name="sart_l_sart_l-P5" pos="0.014696317139839998 -0.088213895575200013 0.0027689744729400001"/>
          <site name="semimem_l_semimem_l-P2" pos="-0.031337735077600001 -0.045413820314640002 0.020873807565240002"/>
          <site name="SM_at_condyles_l_cylinder_semimem_l_1_sidesite" pos="-0.03134 -0.04541 0.02087" size="0.0005"/>
          <site name="semiten_l_semiten_l-P2" pos="-0.033715080497279996 -0.055324270311360002 0.024388275165510002"/>
          <site name="semiten_l_semiten_l-P3" pos="0.0020531619533599998 -0.08418437195016 0.01246038512823"/>
          <site name="ST_at_condyles_l_cylinder_semiten_l_1_sidesite" pos="-0.03795 -0.006811 0.02637" size="0.0005"/>
          <site name="soleus_l_soleus_l-P1" pos="-0.0082126478134399994 -0.099757936230720004 -0.010436903782620001"/>
          <site name="tfl_l_tfl_l-P4" pos="0.01167060478752 -0.044651478007200006 -0.036848660293740003"/>
          <site name="tibant_l_tibant_l-P1" pos="0.01664141793776 -0.14288472962304002 -0.01725284094678"/>
          <site name="tibant_l_tibant_l-P2" pos="0.027123350015439997 -0.20757491971152001 -0.013631874328320002"/>
          <site name="tibant_l_tibant_l-P3" pos="0.025178249217519998 -0.39848721470328002 0.014057870401080001"/>
          <site name="tibpost_l_tibpost_l-P1" pos="-0.0044305073730400001 -0.14201348127168001 -0.010969398873570001"/>
          <site name="tibpost_l_tibpost_l-P2" pos="-0.017722029492160001 -0.39805159052760003 0.018637328183250004"/>
          <site name="vasint_l_vasint_l-P5" pos="0.035195518326807999 -0.068828619757440007 -0.00045794577821700003"/>
          <site name="vaslat_l_vaslat_l-P5" pos="0.035163099980175999 -0.069024650636496016 -0.0054420998295090003"/>
          <site name="vasmed_l_vasmed_l-P5" pos="0.034471508585359995 -0.069231572119944004 0.0072206334332820003"/>
          <site name="LANK_marker" group="4" pos="-0.02191 -0.4207 -0.05585" rgba="1 0.1 0.5 0.5" size="0.01"/>
          <site name="LANKmed_marker" group="4" pos="0.01203 -0.4028 0.03273" rgba="1 0.1 0.5 0.5" size="0.01"/>
          <site name="LTIB_marker" group="4" pos="0.01856 -0.2305 -0.05554" rgba="1 0.1 0.5 0.5" size="0.01"/>
          <site name="LTIB2_marker" group="4" pos="-0.04936 -0.2418 -0.06717" rgba="1 0.1 0.5 0.5" size="0.01"/>
          <site name="LTIB3_marker" group="4" pos="-0.0113 -0.2776 -0.0636" rgba="1 0.1 0.5 0.5" size="0.01"/>
        </body>
        <body name="patella_l" pos="-0.008511 -0.4225 0.002842" euler="-0 0 0">
          <inertial mass="0.065380909823214067" pos="0.0018 0.0264 0" fullinertia="2.1768353966661763e-06 9.9436627352939266e-06 9.9436627352939266e-06 0 0 0"/>
          <geom name="patella_l_geom_1" type="mesh" mesh="patella_l_geom_1_l_patella" rgba="1 1 1 1" group="0"/>
          <joint name="patellofemoral_l_translation1" range="-0.02388 0.05513" limited="true" user="0.05515011545973533" ref="0" axis="1 0 0" type="slide"/>
          <joint name="patellofemoral_l_translation2" range="-0.04225 -0.01118" limited="true" user="-0.011213952937498647" ref="0" axis="0 1 0" type="slide"/>
          <joint name="patellofemoral_l_translation3" limited="false" ref="0" axis="0 0 1" type="slide"/>
          <joint name="patellofemoral_l_rotation1" range="-1.786 0.001137" limited="true" user="0.01050598499723554" ref="0" axis="0 0 1" type="hinge"/>
          <site name="recfem_l_recfem_l-P2" pos="0.01 0.049000000000000002 -0.00069999999999999999"/>
          <site name="recfem_l_recfem_l-P3" pos="0.0121 0.043700000000000003 0.001"/>
          <site name="recfem_l_recfem_l-P4" pos="0.0050000000000000001 0.00247 -3.0000000000000001e-05"/>
          <site name="vasint_l_vasint_l-P3" pos="0.0057999999999999996 0.048000000000000001 0.00059999999999999995"/>
          <site name="vasint_l_vasint_l-P4" pos="0.0050000000000000001 0.00247 0.00038999999999999999"/>
          <site name="vaslat_l_vaslat_l-P3" pos="0.0103 0.042299999999999997 -0.0141"/>
          <site name="vaslat_l_vaslat_l-P4" pos="0.0050000000000000001 0.00247 -0.0073299999999999997"/>
          <site name="vasmed_l_vasmed_l-P3" pos="0.0063 0.044499999999999998 0.017000000000000001"/>
          <site name="vasmed_l_vasmed_l-P4" pos="0.0050000000000000001 0.00247 0.0085000000000000006"/>
        </body>
        <site name="addbrev_l_addbrev_l-P2" pos="-0.0021041939963999997 -0.12220453303619999 -0.025731378522930001"/>
        <site name="AB_at_femshaft_l_cylinder_addbrev_l_1_sidesite" pos="0.001208 -0.1098 -0.01501" size="0.0005"/>
        <site name="addlong_l_addlong_l-P2" pos="0.011846612199731998 -0.24789914468538299 -0.016358543052931"/>
        <site name="AL_at_femshaft_l_cylinder_addlong_l_1_sidesite" pos="0.01185 -0.2479 -0.01636" size="0.0005"/>
        <site name="addmagDist_l_addmagDist_l-P2" pos="0.011836091229749999 -0.27185330442375 -0.019944401827010003"/>
        <site name="AMdist_at_femshaft_l_cylinder_addmagDist_l_1_sidesite" pos="0.01184 -0.2719 -0.01994" size="0.0005"/>
        <site name="addmagIsch_l_addmagIsch_l-P2" pos="0.0050605865613419995 -0.40179400578012298 0.033822812010261001"/>
        <site name="AMisch_at_condyles_l_cylinder_addmagIsch_l_1_sidesite" pos="0.005061 -0.4018 0.03382" size="0.0005"/>
        <site name="addmagMid_l_addmagMid_l-P2" pos="0.0025460747356439994 -0.16818657767015999 -0.030195617688354"/>
        <site name="AMmid_at_femshaft_l_cylinder_addmagMid_l_1_sidesite" pos="0.002546 -0.1682 -0.0302" size="0.0005"/>
        <site name="addmagProx_l_addmagProx_l-P2" pos="-0.016065521162513998 -0.081669910807073989 -0.033089106036314"/>
        <site name="AMprox_at_femshaft_l_cylinder_addmagProx_l_1_sidesite" pos="-0.01687 -0.07597 -0.02075" size="0.0005"/>
        <site name="bfsh_l_bfsh_l-P1" pos="0.0052604849909999992 -0.21862183833849 -0.024181295479380003"/>
        <site name="gaslat_l_gaslat_l-P1" pos="-0.0031562909946 -0.39498990593226002 -0.028624866870890001"/>
        <site name="Gastroc_at_condyles_l_cylinder_gaslat_l_1_sidesite" pos="-0.009086 -0.4478 -0.02569" size="0.0005"/>
        <site name="gasmed_l_gasmed_l-P1" pos="0.0084167759855999988 -0.39229726367891998 0.02149448487056"/>
        <site name="Gastroc_at_condyles_l_cylinder_gasmed_l_1_sidesite" pos="0.001201 -0.4454 0.01886" size="0.0005"/>
        <site name="glmax1_l_glmax1_l-P3" pos="-0.04671310672008 -0.033761591330339999 -0.031208338610140003"/>
        <site name="glmax1_l_glmax1_l-P4" pos="-0.029143086850139995 -0.058616750591939992 -0.0485692686979"/>
        <site name="glmax2_l_glmax2_l-P3" pos="-0.047344364918999994 -0.060480887536559995 -0.026041395131639999"/>
        <site name="glmax2_l_glmax2_l-P4" pos="-0.016412713171919998 -0.10522017420744 -0.043298986349830003"/>
        <site name="glmax3_l_glmax3_l-P3" pos="-0.029563925649419998 -0.11650855903875 -0.0097138537395800011"/>
        <site name="glmax3_l_glmax3_l-P4" pos="-0.0063125819892 -0.14695612913421 -0.042472275393269997"/>
        <site name="glmed1_l_glmed1_l-P2" pos="-0.0147293579748 -0.018641369446199998 -0.060969933046299996"/>
        <site name="glmed2_l_glmed2_l-P2" pos="-0.023146133960399998 -0.010356316358999999 -0.0578697669592"/>
        <site name="glmed3_l_glmed3_l-P2" pos="-0.032509797244379995 -0.0048674686887299999 -0.053529534437260003"/>
        <site name="glmin1_l_glmin1_l-P2" pos="0.0052604849909999992 -0.015534474538499999 -0.0578697669592"/>
        <site name="glmin2_l_glmin2_l-P2" pos="0.0042083879927999994 -0.0093206847230999992 -0.053736212176399997"/>
        <site name="glmin3_l_glmin3_l-P2" pos="-0.0042083879927999994 -0.0010356316358999999 -0.052702823480699997"/>
        <site name="iliacus_l_iliacus_l-P3" pos="-0.0024198230958599998 -0.058513187428350003 -0.014364102870229999"/>
        <site name="iliacus_l_iliacus_l-P4" pos="-0.01283558337804 -0.065969735206829999 -0.020254418435720001"/>
        <site name="piri_l_piri_l-P3" pos="-0.015571035573359999 -0.0037282738892399996 -0.045159086002090003"/>
        <site name="psoas_l_psoas_l-P3" pos="-0.013887680376239999 -0.048363997396529995 -0.0047535880002199998"/>
        <site name="psoas_l_psoas_l-P4" pos="-0.024724279457699998 -0.05426709772116 -0.00909382052216"/>
        <site name="KnExt_at_fem_l_cylinder_recfem_l_3_sidesite" pos="-0.01715 -0.4118 0.01422" size="0.0005"/>
        <site name="KnExt_at_fem_l_cylinder_recfem_l_2_sidesite" pos="0.003589 -0.3788 0.003842" size="0.0005"/>
        <site name="sart_l_sart_l-P2" pos="-0.0031562909946 -0.36951336768911996 0.043505664088969997"/>
        <site name="tfl_l_tfl_l-P2" pos="0.030931651747079996 -0.10304534777205 -0.061693305133290008"/>
        <site name="tfl_l_tfl_l-P3" pos="0.011257437880739999 -0.41943081253949999 -0.033481793740679999"/>
        <site name="vasint_l_vasint_l-P1" pos="0.0305108129478 -0.19925552674715999 -0.032035049566700002"/>
        <site name="vasint_l_vasint_l-P2" pos="0.035245249439699998 -0.21582563292155998 -0.02945157782745"/>
        <site name="KnExt_at_fem_l_cylinder_vasint_l_3_sidesite" pos="-0.0173 -0.4109 0.0137" size="0.0005"/>
        <site name="vaslat_l_vaslat_l-P1" pos="0.0050500655913599994 -0.19200610529586001 -0.036065265479930005"/>
        <site name="vaslat_l_vaslat_l-P2" pos="0.028301409251579999 -0.26833215686168999 -0.042265597654130002"/>
        <site name="KnExt_at_fem_l_cylinder_vaslat_l_3_sidesite" pos="-0.02036 -0.4117 -0.01326" size="0.0005"/>
        <site name="KnExt_at_fem_l_cylinder_vaslat_l_2_sidesite" pos="0.001789 -0.3802 -0.01126" size="0.0005"/>
        <site name="vasmed_l_vasmed_l-P1" pos="0.0147293579748 -0.21737908037540998 -0.019427707479160002"/>
        <site name="vasmed_l_vasmed_l-P2" pos="0.037454653135919995 -0.28676639998070996 -0.00093004982612999998"/>
        <site name="KnExt_at_fem_l_cylinder_vasmed_l_4_sidesite" pos="-0.008865 -0.4222 0.02127" size="0.0005"/>
        <site name="KnExt_at_fem_l_cylinder_vasmed_l_3_sidesite" pos="-0.008865 -0.4222 0.02127" size="0.0005"/>
        <site name="LKNE_marker" group="4" pos="-0.0009274 -0.4273 -0.05871" rgba="1 0.1 0.5 0.5" size="0.01"/>
        <site name="LKNEmed_marker" group="4" pos="-0.02391 -0.4118 0.05322" rgba="1 0.1 0.5 0.5" size="0.01"/>
        <site name="LTHI_marker" group="4" pos="0.06445 -0.1785 -0.1007" rgba="1 0.1 0.5 0.5" size="0.01"/>
        <site name="LTHI2_marker" group="4" pos="-0.04279 -0.1643 -0.08636" rgba="1 0.1 0.5 0.5" size="0.01"/>
        <site name="LTHI3_marker" group="4" pos="0.001754 -0.2438 -0.095" rgba="1 0.1 0.5 0.5" size="0.01"/>
      </body>
      <body name="torso" pos="-0.1033 0.08222 0" euler="-0 0 0">
        <inertial mass="29.8344872453" pos="-0.0300000000 0.3200000000 0.0000000000" fullinertia="1.2849100507 0.6583584560 1.2473518119 0.0000000000 0.0000000000 0.0000000000"/>
        <geom name="torso_geom_1" type="mesh" mesh="torso_geom_1_hat_spine" rgba="1 1 1 1" group="0"/>
        <geom name="torso_geom_2" type="mesh" mesh="torso_geom_2_hat_jaw" rgba="1 1 1 1" group="0"/>
        <geom name="torso_geom_3" type="mesh" mesh="torso_geom_3_hat_skull" rgba="1 1 1 1" group="0"/>
        <geom name="torso_geom_4" type="mesh" mesh="torso_geom_4_hat_ribs_scap" rgba="1 1 1 1" group="0"/>
        <joint name="lumbar_extension" range="-1.571 1.571" limited="true" user="0.0" ref="0" axis="0 0 1" type="hinge"/>
        <joint name="lumbar_bending" range="-1.571 1.571" limited="true" user="0.0" ref="0" axis="1 0 0" type="hinge"/>
        <joint name="lumbar_rotation" range="-1.571 1.571" limited="true" user="0.0" ref="0" axis="0 1 0" type="hinge"/>
        <site name="CLAV_marker" group="4" pos="0.02766 0.387 0.001007" rgba="1 0.1 0.5 0.5" size="0.01"/>
        <site name="RSHO_marker" group="4" pos="-0.02314 0.3962 0.2036" rgba="1 0.1 0.5 0.5" size="0.01"/>
        <site name="LSHO_marker" group="4" pos="-0.0283 0.3999 -0.198" rgba="1 0.1 0.5 0.5" size="0.01"/>
        <site name="C7_marker" group="4" pos="-0.08174 0.4306 -0.005021" rgba="1 0.1 0.5 0.5" size="0.01"/>
        <site name="T10_marker" group="4" pos="-0.1129 0.1975 -4.856e-05" rgba="1 0.1 0.5 0.5" size="0.01"/>
        <site name="RBAK_marker" group="4" pos="-0.1417 0.3112 0.09869" rgba="1 0.1 0.5 0.5" size="0.01"/>
        <site name="STRN_marker" group="4" pos="0.1156 0.2273 0.002486" rgba="1 0.1 0.5 0.5" size="0.01"/>
      </body>
      <site name="addbrev_r_addbrev_r-P1" pos="-0.019594893823739998 -0.094828040726600005 0.01593649848252"/>
      <site name="addlong_r_addlong_r-P1" pos="-0.0077764028892119991 -0.089683115112710016 0.019537733204544001"/>
      <site name="addmagDist_r_addmagDist_r-P1" pos="-0.075958426110455987 -0.12879463786771303 0.041207231790516004"/>
      <site name="addmagIsch_r_addmagIsch_r-P1" pos="-0.091942114370867994 -0.130903048560464 0.043163074786097995"/>
      <site name="addmagMid_r_addmagMid_r-P1" pos="-0.054024455955923992 -0.121813679975925 0.029534264070851999"/>
      <site name="addmagProx_r_addmagProx_r-P1" pos="-0.031782712599972 -0.10849740191644501 0.014125532745870001"/>
      <site name="bflh_r_bflh_r-P1" pos="-0.10669470982559999 -0.12014914521849 0.060641481238680003"/>
      <site name="glmax1_r_glmax1_r-P1" pos="-0.12628960364934 0.034803908564550005 0.058261354841940005"/>
      <site name="glmax1_r_glmax1_r-P2" pos="-0.12895697139498 -0.024413176442380002 0.080613846220020005"/>
      <site name="Gmax1_at_pelvis_r_cylinder_glmax1_r_2_sidesite" pos="-0.1099 -0.09327 0.1044" size="0.0005"/>
      <site name="glmax2_r_glmax2_r-P1" pos="-0.13511243542338 0.008776637811930001 0.047809495447559996"/>
      <site name="glmax2_r_glmax2_r-P2" pos="-0.13788239423615997 -0.061436464683510009 0.084132293936939995"/>
      <site name="Gmax2_at_pelvis_r_cylinder_glmax2_r_2_sidesite" pos="-0.1233 -0.0962 0.09385" size="0.0005"/>
      <site name="glmax3_r_glmax3_r-P1" pos="-0.13336838728199998 -0.052962469554750001 0.0093135380742"/>
      <site name="glmax3_r_glmax3_r-P2" pos="-0.13059842846921998 -0.12741256961457001 0.045015434025299998"/>
      <site name="Gmax3_at_pelvis_r_cylinder_glmax3_r_1_sidesite" pos="-0.1312 -0.1109 0.03708" size="0.0005"/>
      <site name="glmed1_r_glmed1_r-P1" pos="-0.05041058915900487 0.026383638489380943 0.11930474126356717"/>
      <site name="glmed2_r_glmed2_r-P1" pos="-0.086922667327515649 0.055115184087726858 0.084839626634052034"/>
      <site name="glmed3_r_glmed3_r-P1" pos="-0.10245338893902334 0.0156964504854545 0.066127805728718181"/>
      <site name="glmin1_r_glmin1_r-P1" pos="-0.030345960294101786 -0.00010916992218051168 0.12258117463919589"/>
      <site name="glmin2_r_glmin2_r-P1" pos="-0.063196095792824536 0.01008835831070486 0.10466898818606167"/>
      <site name="glmin3_r_glmin3_r-P1" pos="-0.080944351973459991 -0.01563653863045 0.082580037591239996"/>
      <site name="grac_r_grac_r-P1" pos="-0.048587129397503995 -0.130459172625148 0.025415610566927999"/>
      <site name="iliacus_r_iliacus_r-P1" pos="-0.062067595619699996 0.031172196366510002 0.087236806628340005"/>
      <site name="iliacus_r_iliacus_r-P2" pos="-0.013849794063899998 -0.056190658175230002 0.078233719823280007"/>
      <site name="IL_at_brim_r_cylinder_iliacus_r_2_sidesite" pos="-0.02047 -0.08696 0.08468" size="0.0005"/>
      <site name="piri_r_piri_r-P1" pos="-0.10444796545523399 -0.006587522403667001 0.013980655486938"/>
      <site name="piri_r_piri_r-P2" pos="-0.10466340669622799 -0.030930082219974002 0.063042304386696002"/>
      <site name="psoas_r_psoas_r-P1" pos="-0.062170186686839997 0.062546154521799999 0.040358664988200003"/>
      <site name="psoas_r_psoas_r-P2" pos="-0.021031168763699998 -0.065976104931060001 0.067885344185280014"/>
      <site name="PS_at_brim_r_cylinder_psoas_r_2_sidesite" pos="-0.03336 -0.0896 0.07416" size="0.0005"/>
      <site name="recfem_r_recfem_r-P1" pos="-0.024621856113599998 -0.039141787023320003 0.096550344702539995"/>
      <site name="sart_r_sart_r-P1" pos="-0.020005258092299999 -0.01573741952484 0.10927884673728"/>
      <site name="semimem_r_semimem_r-P1" pos="-0.10125738326717999 -0.11500421960460001 0.06353902641732001"/>
      <site name="semiten_r_semiten_r-P1" pos="-0.10648952769132 -0.12640376067067 0.053294134535699998"/>
      <site name="tfl_r_tfl_r-P1" pos="-0.020866803255542802 0.010946935274171614 0.13380195734161157"/>
      <site name="addbrev_l_addbrev_l-P1" pos="-0.019594893823739998 -0.094828040726600005 -0.01593649848252"/>
      <site name="addlong_l_addlong_l-P1" pos="-0.0077764028892119991 -0.089683115112710016 -0.019537733204544001"/>
      <site name="addmagDist_l_addmagDist_l-P1" pos="-0.075958426110455987 -0.12879463786771303 -0.041207231790516004"/>
      <site name="addmagIsch_l_addmagIsch_l-P1" pos="-0.091942114370867994 -0.130903048560464 -0.043163074786097995"/>
      <site name="addmagMid_l_addmagMid_l-P1" pos="-0.054024455955923992 -0.121813679975925 -0.029534264070851999"/>
      <site name="addmagProx_l_addmagProx_l-P1" pos="-0.031782712599972 -0.10849740191644501 -0.014125532745870001"/>
      <site name="bflh_l_bflh_l-P1" pos="-0.10669470982559999 -0.12014914521849 -0.060641481238680003"/>
      <site name="glmax1_l_glmax1_l-P1" pos="-0.12628960364934 0.034803908564550005 -0.058261354841940005"/>
      <site name="glmax1_l_glmax1_l-P2" pos="-0.12895697139498 -0.024413176442380002 -0.080613846220020005"/>
      <site name="Gmax1_at_pelvis_l_cylinder_glmax1_l_2_sidesite" pos="-0.1099 -0.09327 -0.1044" size="0.0005"/>
      <site name="glmax2_l_glmax2_l-P1" pos="-0.13511243542338 0.008776637811930001 -0.047809495447559996"/>
      <site name="glmax2_l_glmax2_l-P2" pos="-0.13788239423615997 -0.061436464683510009 -0.084132293936939995"/>
      <site name="Gmax2_at_pelvis_l_cylinder_glmax2_l_2_sidesite" pos="-0.1233 -0.0962 -0.09385" size="0.0005"/>
      <site name="glmax3_l_glmax3_l-P1" pos="-0.13336838728199998 -0.052962469554750001 -0.0093135380742"/>
      <site name="glmax3_l_glmax3_l-P2" pos="-0.13059842846921998 -0.12741256961457001 -0.045015434025299998"/>
      <site name="Gmax3_at_pelvis_l_cylinder_glmax3_l_1_sidesite" pos="-0.1312 -0.1109 -0.03708" size="0.0005"/>
      <site name="glmed1_l_glmed1_l-P1" pos="-0.0502696228986 0.026229032541400001 -0.11900631983700001"/>
      <site name="glmed2_l_glmed2_l-P1" pos="-0.087202407068999996 0.055484491914500007 -0.084856680231600007"/>
      <site name="glmed3_l_glmed3_l-P1" pos="-0.10259106713999999 0.016140943102400003 -0.0662296040832"/>
      <site name="glmin1_l_glmin1_l-P1" pos="-0.030777320141999995 0 -0.12211083252839999"/>
      <site name="glmin2_l_glmin2_l-P1" pos="-0.06319609735824 0.010088089439000001 -0.1045185939438"/>
      <site name="glmin3_l_glmin3_l-P1" pos="-0.080944351973459991 -0.01563653863045 -0.082580037591239996"/>
      <site name="grac_l_grac_l-P1" pos="-0.048587129397503995 -0.130459172625148 -0.025415610566927999"/>
      <site name="iliacus_l_iliacus_l-P1" pos="-0.062067595619699996 0.031172196366510002 -0.087236806628340005"/>
      <site name="iliacus_l_iliacus_l-P2" pos="-0.013849794063899998 -0.056190658175230002 -0.078233719823280007"/>
      <site name="IL_at_brim_l_cylinder_iliacus_l_2_sidesite" pos="-0.02047 -0.08696 -0.08468" size="0.0005"/>
      <site name="piri_l_piri_l-P1" pos="-0.10444796545523399 -0.006587522403667001 -0.013980655486938"/>
      <site name="piri_l_piri_l-P2" pos="-0.10466340669622799 -0.030930082219974002 -0.063042304386696002"/>
      <site name="psoas_l_psoas_l-P1" pos="-0.062170186686839997 0.062546154521799999 -0.040358664988200003"/>
      <site name="psoas_l_psoas_l-P2" pos="-0.021031168763699998 -0.065976104931060001 -0.067885344185280014"/>
      <site name="PS_at_brim_l_cylinder_psoas_l_2_sidesite" pos="-0.03336 -0.0896 -0.07416" size="0.0005"/>
      <site name="recfem_l_recfem_l-P1" pos="-0.024621856113599998 -0.039141787023320003 -0.096550344702539995"/>
      <site name="sart_l_sart_l-P1" pos="-0.020005258092299999 -0.01573741952484 -0.10927884673728"/>
      <site name="semimem_l_semimem_l-P1" pos="-0.10125738326717999 -0.11500421960460001 -0.06353902641732001"/>
      <site name="semiten_l_semiten_l-P1" pos="-0.10648952769132 -0.12640376067067 -0.053294134535699998"/>
      <site name="tfl_l_tfl_l-P1" pos="-0.020518213428 0.011096898382900001 -0.13349404573020002"/>
      <site name="RASI_marker" group="4" pos="0.01311 0.01554 0.1322" rgba="1 0.1 0.5 0.5" size="0.01"/>
      <site name="LASI_marker" group="4" pos="0.0123 0.01675 -0.1377" rgba="1 0.1 0.5 0.5" size="0.01"/>
      <site name="RPSI_marker" group="4" pos="-0.1658 0.04571 0.05563" rgba="1 0.1 0.5 0.5" size="0.01"/>
      <site name="LPSI_marker" group="4" pos="-0.1617 0.04833 -0.05695" rgba="1 0.1 0.5 0.5" size="0.01"/>
      <site name="SACR_marker" group="4" pos="-0.1661 0.0508 0.0001781" rgba="1 0.1 0.5 0.5" size="0.01"/>
    </body>
  </worldbody>
  <asset>
    <texture type="skybox" builtin="gradient" rgb1="1 1 1" rgb2="0.6 0.8 1" width="256" height="256"/>
    <mesh name="pelvis_geom_1_r_pelvis" file="Geometry/r_pelvis.stl" scale="1.0259106713999999 1.0088089439000001 1.0348375638"/>
    <mesh name="pelvis_geom_2_l_pelvis" file="Geometry/l_pelvis.stl" scale="1.0259106713999999 1.0088089439000001 1.0348375638"/>
    <mesh name="pelvis_geom_3_sacrum" file="Geometry/sacrum.stl" scale="1.0259106713999999 1.0088089439000001 1.0348375638"/>
    <mesh name="femur_r_geom_1_r_femur" file="Geometry/r_femur.stl" scale="1.0520969981999999 1.0356316359 1.0333886957"/>
    <mesh name="tibia_r_geom_1_r_tibia" file="Geometry/r_tibia.stl" scale="1.0806115543999999 1.0890604392000001 1.0649901819000001"/>
    <mesh name="tibia_r_geom_2_r_fibula" file="Geometry/r_fibula.stl" scale="1.0806115543999999 1.0890604392000001 1.0649901819000001"/>
    <mesh name="talus_r_geom_1_r_talus" file="Geometry/r_talus.stl" scale="1.0226245804 1.0267018264000001 1.0318715833000001"/>
    <mesh name="calcn_r_geom_1_r_foot" file="Geometry/r_foot.stl" scale="0.89180648340000002 0.87613486340000002 0.8924495201"/>
    <mesh name="toes_r_geom_1_r_bofoot" file="Geometry/r_bofoot.stl" scale="1.0240918612000001 1.0245541482 1.0251290830999999"/>
    <mesh name="patella_r_geom_1_r_patella" file="Geometry/r_patella.stl" scale="1 1 1"/>
    <mesh name="femur_l_geom_1_l_femur" file="Geometry/l_femur.stl" scale="1.0520969981999999 1.0356316359 1.0333886957"/>
    <mesh name="tibia_l_geom_1_l_tibia" file="Geometry/l_tibia.stl" scale="1.0806115543999999 1.0890604392000001 1.0649901819000001"/>
    <mesh name="tibia_l_geom_2_l_fibula" file="Geometry/l_fibula.stl" scale="1.0806115543999999 1.0890604392000001 1.0649901819000001"/>
    <mesh name="talus_l_geom_1_l_talus" file="Geometry/l_talus.stl" scale="1.0226245804 1.0267018264000001 1.0318715833000001"/>
    <mesh name="calcn_l_geom_1_l_foot" file="Geometry/l_foot.stl" scale="0.89180648340000002 0.87613486340000002 0.8924495201"/>
    <mesh name="toes_l_geom_1_l_bofoot" file="Geometry/l_bofoot.stl" scale="1.0240918612000001 1.0245541482 1.0251290830999999"/>
    <mesh name="patella_l_geom_1_l_patella" file="Geometry/l_patella.stl" scale="1 1 1"/>
    <mesh name="torso_geom_1_hat_spine" file="Geometry/hat_spine.stl" scale="1.1416956143999999 0.99196010759999997 1.0549967257999999"/>
    <mesh name="torso_geom_2_hat_jaw" file="Geometry/hat_jaw.stl" scale="1.1416956143999999 0.99196010759999997 1.0549967257999999"/>
    <mesh name="torso_geom_3_hat_skull" file="Geometry/hat_skull.stl" scale="1.1416956143999999 0.99196010759999997 1.0549967257999999"/>
    <mesh name="torso_geom_4_hat_ribs_scap" file="Geometry/hat_ribs_scap.stl" scale="1.1416956143999999 0.99196010759999997 1.0549967257999999"/>
  </asset>
  <tendon>
    <!-- Leave this comment here to make 'tendon' element pretty printed !-->
    <spatial name="addbrev_r_tendon">
      <site site="addbrev_r_addbrev_r-P1"/>
      <geom geom="AB_at_femshaft_r_cylinder" sidesite="AB_at_femshaft_r_cylinder_addbrev_r_1_sidesite"/>
      <site site="addbrev_r_addbrev_r-P2"/>
    </spatial>
    <spatial name="addlong_r_tendon">
      <site site="addlong_r_addlong_r-P1"/>
      <geom geom="AL_at_femshaft_r_cylinder" sidesite="AL_at_femshaft_r_cylinder_addlong_r_1_sidesite"/>
      <site site="addlong_r_addlong_r-P2"/>
    </spatial>
    <spatial name="addmagDist_r_tendon">
      <site site="addmagDist_r_addmagDist_r-P1"/>
      <geom geom="AMdist_at_femshaft_r_cylinder" sidesite="AMdist_at_femshaft_r_cylinder_addmagDist_r_1_sidesite"/>
      <site site="addmagDist_r_addmagDist_r-P2"/>
    </spatial>
    <spatial name="addmagIsch_r_tendon">
      <site site="addmagIsch_r_addmagIsch_r-P1"/>
      <geom geom="AMisch_at_condyles_r_cylinder" sidesite="AMisch_at_condyles_r_cylinder_addmagIsch_r_1_sidesite"/>
      <site site="addmagIsch_r_addmagIsch_r-P2"/>
    </spatial>
    <spatial name="addmagMid_r_tendon">
      <site site="addmagMid_r_addmagMid_r-P1"/>
      <geom geom="AMmid_at_femshaft_r_cylinder" sidesite="AMmid_at_femshaft_r_cylinder_addmagMid_r_1_sidesite"/>
      <site site="addmagMid_r_addmagMid_r-P2"/>
    </spatial>
    <spatial name="addmagProx_r_tendon">
      <site site="addmagProx_r_addmagProx_r-P1"/>
      <geom geom="AMprox_at_femshaft_r_cylinder" sidesite="AMprox_at_femshaft_r_cylinder_addmagProx_r_1_sidesite"/>
      <site site="addmagProx_r_addmagProx_r-P2"/>
    </spatial>
    <spatial name="bflh_r_tendon">
      <site site="bflh_r_bflh_r-P1"/>
      <site site="bflh_r_bflh_r-P2"/>
      <site site="bflh_r_bflh_r-P3"/>
    </spatial>
    <spatial name="bfsh_r_tendon">
      <site site="bfsh_r_bfsh_r-P1"/>
      <site site="bfsh_r_bfsh_r-P2"/>
    </spatial>
    <spatial name="edl_r_tendon">
      <site site="edl_r_edl_r-P1"/>
      <site site="edl_r_edl_r-P2"/>
      <site site="edl_r_edl_r-P3"/>
      <site site="edl_r_edl_r-P4"/>
      <site site="edl_r_edl_r-P5"/>
      <site site="edl_r_edl_r-P6"/>
    </spatial>
    <spatial name="ehl_r_tendon">
      <site site="ehl_r_ehl_r-P1"/>
      <site site="ehl_r_ehl_r-P2"/>
      <site site="ehl_r_ehl_r-P3"/>
      <site site="ehl_r_ehl_r-P4"/>
      <site site="ehl_r_ehl_r-P5"/>
      <site site="ehl_r_ehl_r-P6"/>
      <site site="ehl_r_ehl_r-P7"/>
      <site site="ehl_r_ehl_r-P8"/>
    </spatial>
    <spatial name="fdl_r_tendon">
      <site site="fdl_r_fdl_r-P1"/>
      <site site="fdl_r_fdl_r-P2"/>
      <site site="fdl_r_fdl_r-P3"/>
      <site site="fdl_r_fdl_r-P4"/>
      <site site="fdl_r_fdl_r-P5"/>
      <site site="fdl_r_fdl_r-P6"/>
      <site site="fdl_r_fdl_r-P7"/>
      <site site="fdl_r_fdl_r-P8"/>
    </spatial>
    <spatial name="fhl_r_tendon">
      <site site="fhl_r_fhl_r-P1"/>
      <site site="fhl_r_fhl_r-P2"/>
      <site site="fhl_r_fhl_r-P3"/>
      <site site="fhl_r_fhl_r-P4"/>
      <site site="fhl_r_fhl_r-P5"/>
      <site site="fhl_r_fhl_r-P6"/>
      <site site="fhl_r_fhl_r-P7"/>
    </spatial>
    <spatial name="gaslat_r_tendon">
      <site site="gaslat_r_gaslat_r-P1"/>
      <geom geom="Gastroc_at_condyles_r_cylinder" sidesite="Gastroc_at_condyles_r_cylinder_gaslat_r_1_sidesite"/>
      <site site="gaslat_r_gaslat_r-P2"/>
    </spatial>
    <spatial name="gasmed_r_tendon">
      <site site="gasmed_r_gasmed_r-P1"/>
      <geom geom="Gastroc_at_condyles_r_cylinder" sidesite="Gastroc_at_condyles_r_cylinder_gasmed_r_1_sidesite"/>
      <site site="gasmed_r_gasmed_r-P2"/>
    </spatial>
    <spatial name="glmax1_r_tendon">
      <site site="glmax1_r_glmax1_r-P1"/>
      <site site="glmax1_r_glmax1_r-P2"/>
      <geom geom="Gmax1_at_pelvis_r_cylinder" sidesite="Gmax1_at_pelvis_r_cylinder_glmax1_r_2_sidesite"/>
      <site site="glmax1_r_glmax1_r-P3"/>
      <site site="glmax1_r_glmax1_r-P4"/>
    </spatial>
    <spatial name="glmax2_r_tendon">
      <site site="glmax2_r_glmax2_r-P1"/>
      <site site="glmax2_r_glmax2_r-P2"/>
      <geom geom="Gmax2_at_pelvis_r_cylinder" sidesite="Gmax2_at_pelvis_r_cylinder_glmax2_r_2_sidesite"/>
      <site site="glmax2_r_glmax2_r-P3"/>
      <site site="glmax2_r_glmax2_r-P4"/>
    </spatial>
    <spatial name="glmax3_r_tendon">
      <site site="glmax3_r_glmax3_r-P1"/>
      <geom geom="Gmax3_at_pelvis_r_cylinder" sidesite="Gmax3_at_pelvis_r_cylinder_glmax3_r_1_sidesite"/>
      <site site="glmax3_r_glmax3_r-P2"/>
      <site site="glmax3_r_glmax3_r-P3"/>
      <site site="glmax3_r_glmax3_r-P4"/>
    </spatial>
    <spatial name="glmed1_r_tendon">
      <site site="glmed1_r_glmed1_r-P1"/>
      <site site="glmed1_r_glmed1_r-P2_0"/>
    </spatial>
    <spatial name="glmed2_r_tendon">
      <site site="glmed2_r_glmed2_r-P1"/>
      <site site="glmed2_r_glmed2_r-P2_0"/>
    </spatial>
    <spatial name="glmed3_r_tendon">
      <site site="glmed3_r_glmed3_r-P1"/>
      <site site="glmed3_r_glmed3_r-P2_0"/>
    </spatial>
    <spatial name="glmin1_r_tendon">
      <site site="glmin1_r_glmin1_r-P1"/>
      <site site="glmin1_r_glmin1_r-P2"/>
    </spatial>
    <spatial name="glmin2_r_tendon">
      <site site="glmin2_r_glmin2_r-P1"/>
      <site site="glmin2_r_glmin2_r-P2"/>
    </spatial>
    <spatial name="glmin3_r_tendon">
      <site site="glmin3_r_glmin3_r-P1"/>
      <site site="glmin3_r_glmin3_r-P2"/>
    </spatial>
    <spatial name="grac_r_tendon">
      <site site="grac_r_grac_r-P1"/>
      <geom geom="GR_at_condyles_r_cylinder" sidesite="GR_at_condyles_r_cylinder_grac_r_1_sidesite"/>
      <site site="grac_r_grac_r-P2"/>
      <site site="grac_r_grac_r-P3"/>
    </spatial>
    <spatial name="iliacus_r_tendon">
      <site site="iliacus_r_iliacus_r-P1"/>
      <site site="iliacus_r_iliacus_r-P2"/>
      <geom geom="IL_at_brim_r_cylinder" sidesite="IL_at_brim_r_cylinder_iliacus_r_2_sidesite"/>
      <site site="iliacus_r_iliacus_r-P3"/>
      <site site="iliacus_r_iliacus_r-P4"/>
    </spatial>
    <spatial name="perbrev_r_tendon">
      <site site="perbrev_r_perbrev_r-P1"/>
      <site site="perbrev_r_perbrev_r-P2"/>
      <site site="perbrev_r_perbrev_r-P3"/>
      <site site="perbrev_r_perbrev_r-P4"/>
      <site site="perbrev_r_perbrev_r-P5"/>
    </spatial>
    <spatial name="perlong_r_tendon">
      <site site="perlong_r_perlong_r-P1"/>
      <site site="perlong_r_perlong_r-P2"/>
      <site site="perlong_r_perlong_r-P3"/>
      <site site="perlong_r_perlong_r-P4"/>
      <site site="perlong_r_perlong_r-P5"/>
      <site site="perlong_r_perlong_r-P6"/>
      <site site="perlong_r_perlong_r-P7"/>
    </spatial>
    <spatial name="piri_r_tendon">
      <site site="piri_r_piri_r-P1"/>
      <site site="piri_r_piri_r-P2"/>
      <site site="piri_r_piri_r-P3"/>
    </spatial>
    <spatial name="psoas_r_tendon">
      <site site="psoas_r_psoas_r-P1"/>
      <site site="psoas_r_psoas_r-P2"/>
      <geom geom="PS_at_brim_r_cylinder" sidesite="PS_at_brim_r_cylinder_psoas_r_2_sidesite"/>
      <site site="psoas_r_psoas_r-P3"/>
      <site site="psoas_r_psoas_r-P4"/>
    </spatial>
    <spatial name="recfem_r_tendon">
      <site site="recfem_r_recfem_r-P1"/>
      <site site="recfem_r_recfem_r-P2"/>
      <geom geom="KnExt_at_fem_r_cylinder" sidesite="KnExt_at_fem_r_cylinder_recfem_r_2_sidesite"/>
      <site site="recfem_r_recfem_r-P3"/>
      <geom geom="KnExt_at_fem_r_cylinder" sidesite="KnExt_at_fem_r_cylinder_recfem_r_3_sidesite"/>
      <site site="recfem_r_recfem_r-P4"/>
      <site site="recfem_r_recfem_r-P5"/>
    </spatial>
    <spatial name="sart_r_tendon">
      <site site="sart_r_sart_r-P1"/>
      <site site="sart_r_sart_r-P2"/>
      <site site="sart_r_sart_r-P3"/>
      <site site="sart_r_sart_r-P4"/>
      <site site="sart_r_sart_r-P5"/>
    </spatial>
    <spatial name="semimem_r_tendon">
      <site site="semimem_r_semimem_r-P1"/>
      <geom geom="SM_at_condyles_r_cylinder" sidesite="SM_at_condyles_r_cylinder_semimem_r_1_sidesite"/>
      <site site="semimem_r_semimem_r-P2"/>
    </spatial>
    <spatial name="semiten_r_tendon">
      <site site="semiten_r_semiten_r-P1"/>
      <geom geom="ST_at_condyles_r_cylinder" sidesite="ST_at_condyles_r_cylinder_semiten_r_1_sidesite"/>
      <site site="semiten_r_semiten_r-P2"/>
      <site site="semiten_r_semiten_r-P3"/>
    </spatial>
    <spatial name="soleus_r_tendon">
      <site site="soleus_r_soleus_r-P1"/>
      <site site="soleus_r_soleus_r-P2"/>
    </spatial>
    <spatial name="tfl_r_tendon">
      <site site="tfl_r_tfl_r-P1"/>
      <site site="tfl_r_tfl_r-P2"/>
      <site site="tfl_r_tfl_r-P3"/>
      <site site="tfl_r_tfl_r-P4"/>
    </spatial>
    <spatial name="tibant_r_tendon">
      <site site="tibant_r_tibant_r-P1"/>
      <site site="tibant_r_tibant_r-P2"/>
      <site site="tibant_r_tibant_r-P3"/>
      <site site="tibant_r_tibant_r-P4"/>
    </spatial>
    <spatial name="tibpost_r_tendon">
      <site site="tibpost_r_tibpost_r-P1"/>
      <site site="tibpost_r_tibpost_r-P2"/>
      <site site="tibpost_r_tibpost_r-P3"/>
      <site site="tibpost_r_tibpost_r-P4"/>
    </spatial>
    <spatial name="vasint_r_tendon">
      <site site="vasint_r_vasint_r-P1"/>
      <site site="vasint_r_vasint_r-P2"/>
      <site site="vasint_r_vasint_r-P3"/>
      <geom geom="KnExt_at_fem_r_cylinder" sidesite="KnExt_at_fem_r_cylinder_vasint_r_3_sidesite"/>
      <site site="vasint_r_vasint_r-P4"/>
      <site site="vasint_r_vasint_r-P5"/>
    </spatial>
    <spatial name="vaslat_r_tendon">
      <site site="vaslat_r_vaslat_r-P1"/>
      <site site="vaslat_r_vaslat_r-P2"/>
      <geom geom="KnExt_at_fem_r_cylinder" sidesite="KnExt_at_fem_r_cylinder_vaslat_r_2_sidesite"/>
      <site site="vaslat_r_vaslat_r-P3"/>
      <geom geom="KnExt_at_fem_r_cylinder" sidesite="KnExt_at_fem_r_cylinder_vaslat_r_3_sidesite"/>
      <site site="vaslat_r_vaslat_r-P4"/>
      <site site="vaslat_r_vaslat_r-P5"/>
    </spatial>
    <spatial name="vasmed_r_tendon">
      <site site="vasmed_r_vasmed_r-P1"/>
      <site site="vasmed_r_vasmed_r-P2"/>
      <site site="vasmed_r_vasmed_r-P3"/>
      <geom geom="KnExt_at_fem_r_cylinder" sidesite="KnExt_at_fem_r_cylinder_vasmed_r_3_sidesite"/>
      <site site="vasmed_r_vasmed_r-P4"/>
      <geom geom="KnExt_at_fem_r_cylinder" sidesite="KnExt_at_fem_r_cylinder_vasmed_r_4_sidesite"/>
      <site site="vasmed_r_vasmed_r-P5"/>
    </spatial>
    <spatial name="addbrev_l_tendon">
      <site site="addbrev_l_addbrev_l-P1"/>
      <geom geom="AB_at_femshaft_l_cylinder" sidesite="AB_at_femshaft_l_cylinder_addbrev_l_1_sidesite"/>
      <site site="addbrev_l_addbrev_l-P2"/>
    </spatial>
    <spatial name="addlong_l_tendon">
      <site site="addlong_l_addlong_l-P1"/>
      <geom geom="AL_at_femshaft_l_cylinder" sidesite="AL_at_femshaft_l_cylinder_addlong_l_1_sidesite"/>
      <site site="addlong_l_addlong_l-P2"/>
    </spatial>
    <spatial name="addmagDist_l_tendon">
      <site site="addmagDist_l_addmagDist_l-P1"/>
      <geom geom="AMdist_at_femshaft_l_cylinder" sidesite="AMdist_at_femshaft_l_cylinder_addmagDist_l_1_sidesite"/>
      <site site="addmagDist_l_addmagDist_l-P2"/>
    </spatial>
    <spatial name="addmagIsch_l_tendon">
      <site site="addmagIsch_l_addmagIsch_l-P1"/>
      <geom geom="AMisch_at_condyles_l_cylinder" sidesite="AMisch_at_condyles_l_cylinder_addmagIsch_l_1_sidesite"/>
      <site site="addmagIsch_l_addmagIsch_l-P2"/>
    </spatial>
    <spatial name="addmagMid_l_tendon">
      <site site="addmagMid_l_addmagMid_l-P1"/>
      <geom geom="AMmid_at_femshaft_l_cylinder" sidesite="AMmid_at_femshaft_l_cylinder_addmagMid_l_1_sidesite"/>
      <site site="addmagMid_l_addmagMid_l-P2"/>
    </spatial>
    <spatial name="addmagProx_l_tendon">
      <site site="addmagProx_l_addmagProx_l-P1"/>
      <geom geom="AMprox_at_femshaft_l_cylinder" sidesite="AMprox_at_femshaft_l_cylinder_addmagProx_l_1_sidesite"/>
      <site site="addmagProx_l_addmagProx_l-P2"/>
    </spatial>
    <spatial name="bflh_l_tendon">
      <site site="bflh_l_bflh_l-P1"/>
      <site site="bflh_l_bflh_l-P2"/>
      <site site="bflh_l_bflh_l-P3"/>
    </spatial>
    <spatial name="bfsh_l_tendon">
      <site site="bfsh_l_bfsh_l-P1"/>
      <site site="bfsh_l_bfsh_l-P2"/>
    </spatial>
    <spatial name="edl_l_tendon">
      <site site="edl_l_edl_l-P1"/>
      <site site="edl_l_edl_l-P2"/>
      <site site="edl_l_edl_l-P3"/>
      <site site="edl_l_edl_l-P4"/>
      <site site="edl_l_edl_l-P5"/>
      <site site="edl_l_edl_l-P6"/>
    </spatial>
    <spatial name="ehl_l_tendon">
      <site site="ehl_l_ehl_l-P1"/>
      <site site="ehl_l_ehl_l-P2"/>
      <site site="ehl_l_ehl_l-P3"/>
      <site site="ehl_l_ehl_l-P4"/>
      <site site="ehl_l_ehl_l-P5"/>
      <site site="ehl_l_ehl_l-P6"/>
      <site site="ehl_l_ehl_l-P7"/>
      <site site="ehl_l_ehl_l-P8"/>
    </spatial>
    <spatial name="fdl_l_tendon">
      <site site="fdl_l_fdl_l-P1"/>
      <site site="fdl_l_fdl_l-P2"/>
      <site site="fdl_l_fdl_l-P3"/>
      <site site="fdl_l_fdl_l-P4"/>
      <site site="fdl_l_fdl_l-P5"/>
      <site site="fdl_l_fdl_l-P6"/>
      <site site="fdl_l_fdl_l-P7"/>
      <site site="fdl_l_fdl_l-P8"/>
    </spatial>
    <spatial name="fhl_l_tendon">
      <site site="fhl_l_fhl_l-P1"/>
      <site site="fhl_l_fhl_l-P2"/>
      <site site="fhl_l_fhl_l-P3"/>
      <site site="fhl_l_fhl_l-P4"/>
      <site site="fhl_l_fhl_l-P5"/>
      <site site="fhl_l_fhl_l-P6"/>
      <site site="fhl_l_fhl_l-P7"/>
    </spatial>
    <spatial name="gaslat_l_tendon">
      <site site="gaslat_l_gaslat_l-P1"/>
      <geom geom="Gastroc_at_condyles_l_cylinder" sidesite="Gastroc_at_condyles_l_cylinder_gaslat_l_1_sidesite"/>
      <site site="gaslat_l_gaslat_l-P2"/>
    </spatial>
    <spatial name="gasmed_l_tendon">
      <site site="gasmed_l_gasmed_l-P1"/>
      <geom geom="Gastroc_at_condyles_l_cylinder" sidesite="Gastroc_at_condyles_l_cylinder_gasmed_l_1_sidesite"/>
      <site site="gasmed_l_gasmed_l-P2"/>
    </spatial>
    <spatial name="glmax1_l_tendon">
      <site site="glmax1_l_glmax1_l-P1"/>
      <site site="glmax1_l_glmax1_l-P2"/>
      <geom geom="Gmax1_at_pelvis_l_cylinder" sidesite="Gmax1_at_pelvis_l_cylinder_glmax1_l_2_sidesite"/>
      <site site="glmax1_l_glmax1_l-P3"/>
      <site site="glmax1_l_glmax1_l-P4"/>
    </spatial>
    <spatial name="glmax2_l_tendon">
      <site site="glmax2_l_glmax2_l-P1"/>
      <site site="glmax2_l_glmax2_l-P2"/>
      <geom geom="Gmax2_at_pelvis_l_cylinder" sidesite="Gmax2_at_pelvis_l_cylinder_glmax2_l_2_sidesite"/>
      <site site="glmax2_l_glmax2_l-P3"/>
      <site site="glmax2_l_glmax2_l-P4"/>
    </spatial>
    <spatial name="glmax3_l_tendon">
      <site site="glmax3_l_glmax3_l-P1"/>
      <geom geom="Gmax3_at_pelvis_l_cylinder" sidesite="Gmax3_at_pelvis_l_cylinder_glmax3_l_1_sidesite"/>
      <site site="glmax3_l_glmax3_l-P2"/>
      <site site="glmax3_l_glmax3_l-P3"/>
      <site site="glmax3_l_glmax3_l-P4"/>
    </spatial>
    <spatial name="glmed1_l_tendon">
      <site site="glmed1_l_glmed1_l-P1"/>
      <site site="glmed1_l_glmed1_l-P2"/>
    </spatial>
    <spatial name="glmed2_l_tendon">
      <site site="glmed2_l_glmed2_l-P1"/>
      <site site="glmed2_l_glmed2_l-P2"/>
    </spatial>
    <spatial name="glmed3_l_tendon">
      <site site="glmed3_l_glmed3_l-P1"/>
      <site site="glmed3_l_glmed3_l-P2"/>
    </spatial>
    <spatial name="glmin1_l_tendon">
      <site site="glmin1_l_glmin1_l-P1"/>
      <site site="glmin1_l_glmin1_l-P2"/>
    </spatial>
    <spatial name="glmin2_l_tendon">
      <site site="glmin2_l_glmin2_l-P1"/>
      <site site="glmin2_l_glmin2_l-P2"/>
    </spatial>
    <spatial name="glmin3_l_tendon">
      <site site="glmin3_l_glmin3_l-P1"/>
      <site site="glmin3_l_glmin3_l-P2"/>
    </spatial>
    <spatial name="grac_l_tendon">
      <site site="grac_l_grac_l-P1"/>
      <geom geom="GR_at_condyles_l_cylinder" sidesite="GR_at_condyles_l_cylinder_grac_l_1_sidesite"/>
      <site site="grac_l_grac_l-P2"/>
      <site site="grac_l_grac_l-P3"/>
    </spatial>
    <spatial name="iliacus_l_tendon">
      <site site="iliacus_l_iliacus_l-P1"/>
      <site site="iliacus_l_iliacus_l-P2"/>
      <geom geom="IL_at_brim_l_cylinder" sidesite="IL_at_brim_l_cylinder_iliacus_l_2_sidesite"/>
      <site site="iliacus_l_iliacus_l-P3"/>
      <site site="iliacus_l_iliacus_l-P4"/>
    </spatial>
    <spatial name="perbrev_l_tendon">
      <site site="perbrev_l_perbrev_l-P1"/>
      <site site="perbrev_l_perbrev_l-P2"/>
      <site site="perbrev_l_perbrev_l-P3"/>
      <site site="perbrev_l_perbrev_l-P4"/>
      <site site="perbrev_l_perbrev_l-P5"/>
    </spatial>
    <spatial name="perlong_l_tendon">
      <site site="perlong_l_perlong_l-P1"/>
      <site site="perlong_l_perlong_l-P2"/>
      <site site="perlong_l_perlong_l-P3"/>
      <site site="perlong_l_perlong_l-P4"/>
      <site site="perlong_l_perlong_l-P5"/>
      <site site="perlong_l_perlong_l-P6"/>
      <site site="perlong_l_perlong_l-P7"/>
    </spatial>
    <spatial name="piri_l_tendon">
      <site site="piri_l_piri_l-P1"/>
      <site site="piri_l_piri_l-P2"/>
      <site site="piri_l_piri_l-P3"/>
    </spatial>
    <spatial name="psoas_l_tendon">
      <site site="psoas_l_psoas_l-P1"/>
      <site site="psoas_l_psoas_l-P2"/>
      <geom geom="PS_at_brim_l_cylinder" sidesite="PS_at_brim_l_cylinder_psoas_l_2_sidesite"/>
      <site site="psoas_l_psoas_l-P3"/>
      <site site="psoas_l_psoas_l-P4"/>
    </spatial>
    <spatial name="recfem_l_tendon">
      <site site="recfem_l_recfem_l-P1"/>
      <site site="recfem_l_recfem_l-P2"/>
      <geom geom="KnExt_at_fem_l_cylinder" sidesite="KnExt_at_fem_l_cylinder_recfem_l_2_sidesite"/>
      <site site="recfem_l_recfem_l-P3"/>
      <geom geom="KnExt_at_fem_l_cylinder" sidesite="KnExt_at_fem_l_cylinder_recfem_l_3_sidesite"/>
      <site site="recfem_l_recfem_l-P4"/>
      <site site="recfem_l_recfem_l-P5"/>
    </spatial>
    <spatial name="sart_l_tendon">
      <site site="sart_l_sart_l-P1"/>
      <site site="sart_l_sart_l-P2"/>
      <site site="sart_l_sart_l-P3"/>
      <site site="sart_l_sart_l-P4"/>
      <site site="sart_l_sart_l-P5"/>
    </spatial>
    <spatial name="semimem_l_tendon">
      <site site="semimem_l_semimem_l-P1"/>
      <geom geom="SM_at_condyles_l_cylinder" sidesite="SM_at_condyles_l_cylinder_semimem_l_1_sidesite"/>
      <site site="semimem_l_semimem_l-P2"/>
    </spatial>
    <spatial name="semiten_l_tendon">
      <site site="semiten_l_semiten_l-P1"/>
      <geom geom="ST_at_condyles_l_cylinder" sidesite="ST_at_condyles_l_cylinder_semiten_l_1_sidesite"/>
      <site site="semiten_l_semiten_l-P2"/>
      <site site="semiten_l_semiten_l-P3"/>
    </spatial>
    <spatial name="soleus_l_tendon">
      <site site="soleus_l_soleus_l-P1"/>
      <site site="soleus_l_soleus_l-P2"/>
    </spatial>
    <spatial name="tfl_l_tendon">
      <site site="tfl_l_tfl_l-P1"/>
      <site site="tfl_l_tfl_l-P2"/>
      <site site="tfl_l_tfl_l-P3"/>
      <site site="tfl_l_tfl_l-P4"/>
    </spatial>
    <spatial name="tibant_l_tendon">
      <site site="tibant_l_tibant_l-P1"/>
      <site site="tibant_l_tibant_l-P2"/>
      <site site="tibant_l_tibant_l-P3"/>
      <site site="tibant_l_tibant_l-P4"/>
    </spatial>
    <spatial name="tibpost_l_tendon">
      <site site="tibpost_l_tibpost_l-P1"/>
      <site site="tibpost_l_tibpost_l-P2"/>
      <site site="tibpost_l_tibpost_l-P3"/>
      <site site="tibpost_l_tibpost_l-P4"/>
    </spatial>
    <spatial name="vasint_l_tendon">
      <site site="vasint_l_vasint_l-P1"/>
      <site site="vasint_l_vasint_l-P2"/>
      <site site="vasint_l_vasint_l-P3"/>
      <geom geom="KnExt_at_fem_l_cylinder" sidesite="KnExt_at_fem_l_cylinder_vasint_l_3_sidesite"/>
      <site site="vasint_l_vasint_l-P4"/>
      <site site="vasint_l_vasint_l-P5"/>
    </spatial>
    <spatial name="vaslat_l_tendon">
      <site site="vaslat_l_vaslat_l-P1"/>
      <site site="vaslat_l_vaslat_l-P2"/>
      <geom geom="KnExt_at_fem_l_cylinder" sidesite="KnExt_at_fem_l_cylinder_vaslat_l_2_sidesite"/>
      <site site="vaslat_l_vaslat_l-P3"/>
      <geom geom="KnExt_at_fem_l_cylinder" sidesite="KnExt_at_fem_l_cylinder_vaslat_l_3_sidesite"/>
      <site site="vaslat_l_vaslat_l-P4"/>
      <site site="vaslat_l_vaslat_l-P5"/>
    </spatial>
    <spatial name="vasmed_l_tendon">
      <site site="vasmed_l_vasmed_l-P1"/>
      <site site="vasmed_l_vasmed_l-P2"/>
      <site site="vasmed_l_vasmed_l-P3"/>
      <geom geom="KnExt_at_fem_l_cylinder" sidesite="KnExt_at_fem_l_cylinder_vasmed_l_3_sidesite"/>
      <site site="vasmed_l_vasmed_l-P4"/>
      <geom geom="KnExt_at_fem_l_cylinder" sidesite="KnExt_at_fem_l_cylinder_vasmed_l_4_sidesite"/>
      <site site="vasmed_l_vasmed_l-P5"/>
    </spatial>
  </tendon>
  <actuator>
    <!-- Leave this comment here to make 'actuator' element pretty printed !-->
    <motor name="lumbar_ext" ctrllimited="false" joint="lumbar_extension" class="motor"/>
    <motor name="lumbar_bend" ctrllimited="false" joint="lumbar_bending" class="motor"/>
    <motor name="lumbar_rot" ctrllimited="false" joint="lumbar_rotation" class="motor"/>
    <muscle name="addbrev_r" lengthrange="0.01 1" force="625.81967213114797" tendon="addbrev_r_tendon" class="muscle" timeconst="0.01 0.04"/>
    <muscle name="addlong_r" lengthrange="0.01 1" force="916.79999999999995" tendon="addlong_r_tendon" class="muscle" timeconst="0.01 0.04"/>
    <muscle name="addmagDist_r" lengthrange="0.01 1" force="597.29508196721395" tendon="addmagDist_r_tendon" class="muscle" timeconst="0.01 0.04"/>
    <muscle name="addmagIsch_r" lengthrange="0.01 1" force="597.29508196721395" tendon="addmagIsch_r_tendon" class="muscle" timeconst="0.01 0.04"/>
    <muscle name="addmagMid_r" lengthrange="0.01 1" force="597.29508196721395" tendon="addmagMid_r_tendon" class="muscle" timeconst="0.01 0.04"/>
    <muscle name="addmagProx_r" lengthrange="0.01 1" force="597.29508196721395" tendon="addmagProx_r_tendon" class="muscle" timeconst="0.01 0.04"/>
    <muscle name="bflh_r" lengthrange="0.01 1" force="1313.18360655738" tendon="bflh_r_tendon" class="muscle" timeconst="0.01 0.04"/>
    <muscle name="bfsh_r" lengthrange="0.01 1" force="557.11475409835998" tendon="bfsh_r_tendon" class="muscle" timeconst="0.01 0.04"/>
    <muscle name="edl_r" lengthrange="0.01 1" force="603.49815560000002" tendon="edl_r_tendon" class="muscle" timeconst="0.01 0.04"/>
    <muscle name="ehl_r" lengthrange="0.01 1" force="285.86754739999998" tendon="ehl_r_tendon" class="muscle" timeconst="0.01 0.04"/>
    <muscle name="fdl_r" lengthrange="0.01 1" force="423.17704918032803" tendon="fdl_r_tendon" class="muscle" timeconst="0.01 0.04"/>
    <muscle name="fhl_r" lengthrange="0.01 1" force="907.83934426229405" tendon="fhl_r_tendon" class="muscle" timeconst="0.01 0.04"/>
    <muscle name="gaslat_r" lengthrange="0.01 1" force="1575.0590163934401" tendon="gaslat_r_tendon" class="muscle" timeconst="0.01 0.04"/>
    <muscle name="gasmed_r" lengthrange="0.01 1" force="3115.5147540983598" tendon="gasmed_r_tendon" class="muscle" timeconst="0.01 0.04"/>
    <muscle name="glmax1_r" lengthrange="0.01 1" force="983.78360655737799" tendon="glmax1_r_tendon" class="muscle" timeconst="0.01 0.04"/>
    <muscle name="glmax2_r" lengthrange="0.01 1" force="1406.0459016393499" tendon="glmax2_r_tendon" class="muscle" timeconst="0.01 0.04"/>
    <muscle name="glmax3_r" lengthrange="0.01 1" force="947.75409836065603" tendon="glmax3_r_tendon" class="muscle" timeconst="0.01 0.04"/>
    <muscle name="glmed1_r" lengthrange="0.01 1" force="1093.4667688" tendon="glmed1_r_tendon" class="muscle" timeconst="0.01 0.04"/>
    <muscle name="glmed2_r" lengthrange="0.01 1" force="765.09166159999995" tendon="glmed2_r_tendon" class="muscle" timeconst="0.01 0.04"/>
    <muscle name="glmed3_r" lengthrange="0.01 1" force="871.19926420000002" tendon="glmed3_r_tendon" class="muscle" timeconst="0.01 0.04"/>
    <muscle name="glmin1_r" lengthrange="0.01 1" force="374.04590163934398" tendon="glmin1_r_tendon" class="muscle" timeconst="0.01 0.04"/>
    <muscle name="glmin2_r" lengthrange="0.01 1" force="394.81967213114802" tendon="glmin2_r_tendon" class="muscle" timeconst="0.01 0.04"/>
    <muscle name="glmin3_r" lengthrange="0.01 1" force="446.77377049180399" tendon="glmin3_r_tendon" class="muscle" timeconst="0.01 0.04"/>
    <muscle name="grac_r" lengthrange="0.01 1" force="281.31147540983602" tendon="grac_r_tendon" class="muscle" timeconst="0.01 0.04"/>
    <muscle name="iliacus_r" lengthrange="0.01 1" force="1021.14098360656" tendon="iliacus_r_tendon" class="muscle" timeconst="0.01 0.04"/>
    <muscle name="perbrev_r" lengthrange="0.01 1" force="521.20159880000006" tendon="perbrev_r_tendon" class="muscle" timeconst="0.01 0.04"/>
    <muscle name="perlong_r" lengthrange="0.01 1" force="1115.3714213999999" tendon="perlong_r_tendon" class="muscle" timeconst="0.01 0.04"/>
    <muscle name="piri_r" lengthrange="0.01 1" force="1029.7868852459001" tendon="piri_r_tendon" class="muscle" timeconst="0.01 0.04"/>
    <muscle name="psoas_r" lengthrange="0.01 1" force="1426.79016393443" tendon="psoas_r_tendon" class="muscle" timeconst="0.01 0.04"/>
    <muscle name="recfem_r" lengthrange="0.01 1" force="2191.7409836065599" tendon="recfem_r_tendon" class="muscle" timeconst="0.01 0.04"/>
    <muscle name="sart_r" lengthrange="0.01 1" force="249.41311475409799" tendon="sart_r_tendon" class="muscle" timeconst="0.01 0.04"/>
    <muscle name="semimem_r" lengthrange="0.01 1" force="2200.9868852458999" tendon="semimem_r_tendon" class="muscle" timeconst="0.01 0.04"/>
    <muscle name="semiten_r" lengthrange="0.01 1" force="591.29508196721395" tendon="semiten_r_tendon" class="muscle" timeconst="0.01 0.04"/>
    <muscle name="soleus_r" lengthrange="0.01 1" force="6194.8426229508204" tendon="soleus_r_tendon" class="muscle" timeconst="0.01 0.04"/>
    <muscle name="tfl_r" lengthrange="0.01 1" force="411.20655737704999" tendon="tfl_r_tendon" class="muscle" timeconst="0.01 0.04"/>
    <muscle name="tibant_r" lengthrange="0.01 1" force="1227.4524590163901" tendon="tibant_r_tendon" class="muscle" timeconst="0.01 0.04"/>
    <muscle name="tibpost_r" lengthrange="0.01 1" force="1730.1540983606501" tendon="tibpost_r_tendon" class="muscle" timeconst="0.01 0.04"/>
    <muscle name="vasint_r" lengthrange="0.01 1" force="1697.36065573771" tendon="vasint_r_tendon" class="muscle" timeconst="0.01 0.04"/>
    <muscle name="vaslat_r" lengthrange="0.01 1" force="5148.7672131147601" tendon="vaslat_r_tendon" class="muscle" timeconst="0.01 0.04"/>
    <muscle name="vasmed_r" lengthrange="0.01 1" force="2747.82295081966" tendon="vasmed_r_tendon" class="muscle" timeconst="0.01 0.04"/>
    <muscle name="addbrev_l" lengthrange="0.01 1" force="625.81967213114797" tendon="addbrev_l_tendon" class="muscle" timeconst="0.01 0.04"/>
    <muscle name="addlong_l" lengthrange="0.01 1" force="916.79999999999995" tendon="addlong_l_tendon" class="muscle" timeconst="0.01 0.04"/>
    <muscle name="addmagDist_l" lengthrange="0.01 1" force="597.29508196721395" tendon="addmagDist_l_tendon" class="muscle" timeconst="0.01 0.04"/>
    <muscle name="addmagIsch_l" lengthrange="0.01 1" force="597.29508196721395" tendon="addmagIsch_l_tendon" class="muscle" timeconst="0.01 0.04"/>
    <muscle name="addmagMid_l" lengthrange="0.01 1" force="597.29508196721395" tendon="addmagMid_l_tendon" class="muscle" timeconst="0.01 0.04"/>
    <muscle name="addmagProx_l" lengthrange="0.01 1" force="597.29508196721395" tendon="addmagProx_l_tendon" class="muscle" timeconst="0.01 0.04"/>
    <muscle name="bflh_l" lengthrange="0.01 1" force="1313.18360655738" tendon="bflh_l_tendon" class="muscle" timeconst="0.01 0.04"/>
    <muscle name="bfsh_l" lengthrange="0.01 1" force="557.11475409835998" tendon="bfsh_l_tendon" class="muscle" timeconst="0.01 0.04"/>
    <muscle name="edl_l" lengthrange="0.01 1" force="603.49815560000002" tendon="edl_l_tendon" class="muscle" timeconst="0.01 0.04"/>
    <muscle name="ehl_l" lengthrange="0.01 1" force="285.86754739999998" tendon="ehl_l_tendon" class="muscle" timeconst="0.01 0.04"/>
    <muscle name="fdl_l" lengthrange="0.01 1" force="423.17704918032803" tendon="fdl_l_tendon" class="muscle" timeconst="0.01 0.04"/>
    <muscle name="fhl_l" lengthrange="0.01 1" force="907.83934426229405" tendon="fhl_l_tendon" class="muscle" timeconst="0.01 0.04"/>
    <muscle name="gaslat_l" lengthrange="0.01 1" force="1575.0590163934401" tendon="gaslat_l_tendon" class="muscle" timeconst="0.01 0.04"/>
    <muscle name="gasmed_l" lengthrange="0.01 1" force="3115.5147540983598" tendon="gasmed_l_tendon" class="muscle" timeconst="0.01 0.04"/>
    <muscle name="glmax1_l" lengthrange="0.01 1" force="983.78360655737799" tendon="glmax1_l_tendon" class="muscle" timeconst="0.01 0.04"/>
    <muscle name="glmax2_l" lengthrange="0.01 1" force="1406.0459016393499" tendon="glmax2_l_tendon" class="muscle" timeconst="0.01 0.04"/>
    <muscle name="glmax3_l" lengthrange="0.01 1" force="947.75409836065603" tendon="glmax3_l_tendon" class="muscle" timeconst="0.01 0.04"/>
    <muscle name="glmed1_l" lengthrange="0.01 1" force="1093.4667688" tendon="glmed1_l_tendon" class="muscle" timeconst="0.01 0.04"/>
    <muscle name="glmed2_l" lengthrange="0.01 1" force="765.09166159999995" tendon="glmed2_l_tendon" class="muscle" timeconst="0.01 0.04"/>
    <muscle name="glmed3_l" lengthrange="0.01 1" force="871.19926420000002" tendon="glmed3_l_tendon" class="muscle" timeconst="0.01 0.04"/>
    <muscle name="glmin1_l" lengthrange="0.01 1" force="374.04590163934398" tendon="glmin1_l_tendon" class="muscle" timeconst="0.01 0.04"/>
    <muscle name="glmin2_l" lengthrange="0.01 1" force="394.81967213114802" tendon="glmin2_l_tendon" class="muscle" timeconst="0.01 0.04"/>
    <muscle name="glmin3_l" lengthrange="0.01 1" force="446.77377049180399" tendon="glmin3_l_tendon" class="muscle" timeconst="0.01 0.04"/>
    <muscle name="grac_l" lengthrange="0.01 1" force="281.31147540983602" tendon="grac_l_tendon" class="muscle" timeconst="0.01 0.04"/>
    <muscle name="iliacus_l" lengthrange="0.01 1" force="1021.14098360656" tendon="iliacus_l_tendon" class="muscle" timeconst="0.01 0.04"/>
    <muscle name="perbrev_l" lengthrange="0.01 1" force="521.20159880000006" tendon="perbrev_l_tendon" class="muscle" timeconst="0.01 0.04"/>
    <muscle name="perlong_l" lengthrange="0.01 1" force="1115.3714213999999" tendon="perlong_l_tendon" class="muscle" timeconst="0.01 0.04"/>
    <muscle name="piri_l" lengthrange="0.01 1" force="1029.7868852459001" tendon="piri_l_tendon" class="muscle" timeconst="0.01 0.04"/>
    <muscle name="psoas_l" lengthrange="0.01 1" force="1426.79016393443" tendon="psoas_l_tendon" class="muscle" timeconst="0.01 0.04"/>
    <muscle name="recfem_l" lengthrange="0.01 1" force="2191.7409836065599" tendon="recfem_l_tendon" class="muscle" timeconst="0.01 0.04"/>
    <muscle name="sart_l" lengthrange="0.01 1" force="249.41311475409799" tendon="sart_l_tendon" class="muscle" timeconst="0.01 0.04"/>
    <muscle name="semimem_l" lengthrange="0.01 1" force="2200.9868852458999" tendon="semimem_l_tendon" class="muscle" timeconst="0.01 0.04"/>
    <muscle name="semiten_l" lengthrange="0.01 1" force="591.29508196721395" tendon="semiten_l_tendon" class="muscle" timeconst="0.01 0.04"/>
    <muscle name="soleus_l" lengthrange="0.01 1" force="6194.8426229508204" tendon="soleus_l_tendon" class="muscle" timeconst="0.01 0.04"/>
    <muscle name="tfl_l" lengthrange="0.01 1" force="411.20655737704999" tendon="tfl_l_tendon" class="muscle" timeconst="0.01 0.04"/>
    <muscle name="tibant_l" lengthrange="0.01 1" force="1227.4524590163901" tendon="tibant_l_tendon" class="muscle" timeconst="0.01 0.04"/>
    <muscle name="tibpost_l" lengthrange="0.01 1" force="1730.1540983606501" tendon="tibpost_l_tendon" class="muscle" timeconst="0.01 0.04"/>
    <muscle name="vasint_l" lengthrange="0.01 1" force="1697.36065573771" tendon="vasint_l_tendon" class="muscle" timeconst="0.01 0.04"/>
    <muscle name="vaslat_l" lengthrange="0.01 1" force="5148.7672131147601" tendon="vaslat_l_tendon" class="muscle" timeconst="0.01 0.04"/>
    <muscle name="vasmed_l" lengthrange="0.01 1" force="2747.82295081966" tendon="vasmed_l_tendon" class="muscle" timeconst="0.01 0.04"/>
  </actuator>
  <equality>
    <!-- Leave this comment here to make 'equality' element pretty printed !-->
    <joint joint1="walker_knee_r_translation1" joint2="knee_angle_r" polycoef="9.877e-08 0.00324 -0.00239 0.0005816 5.886e-07" solimp="0.9999 0.9999 0.001 0.5 2" active="true"/>
    <joint joint1="walker_knee_r_translation2" joint2="knee_angle_r" polycoef="7.949e-11 0.006076 -0.001298 -2.706e-06 6.452e-07" solimp="0.9999 0.9999 0.001 0.5 2" active="true"/>
    <joint joint1="walker_knee_r_rotation2" joint2="knee_angle_r" polycoef="-1.473e-08 0.0791 -0.03285 -0.02522 0.01083" solimp="0.9999 0.9999 0.001 0.5 2" active="true"/>
    <joint joint1="walker_knee_r_rotation3" joint2="knee_angle_r" polycoef="1.089e-08 0.3695 -0.1695 0.02516 3.505e-07" solimp="0.9999 0.9999 0.001 0.5 2" active="true"/>
    <joint name="mtp_angle_r_locked" active="true" joint1="mtp_angle_r" polycoef="0.0 0 0 0 0" solimp="0.9999 0.9999 0.001 0.5 2"/>
    <joint joint1="patellofemoral_r_translation1" joint2="knee_angle_r" polycoef="0.05515 -0.0158 -0.03583 0.01403 -0.000925" solimp="0.9999 0.9999 0.001 0.5 2" active="true"/>
    <joint joint1="patellofemoral_r_translation2" joint2="knee_angle_r" polycoef="-0.01121 -0.05052 0.009607 0.01364 -0.003621" solimp="0.9999 0.9999 0.001 0.5 2" active="true"/>
    <joint joint1="patellofemoral_r_rotation1" joint2="knee_angle_r" polycoef="0.01051 0.02476 -1.316 0.7163 -0.1383" solimp="0.9999 0.9999 0.001 0.5 2" active="true"/>
    <joint name="patellofemoral_r_translation3_locked" active="true" joint1="patellofemoral_r_translation3" polycoef="0.002841818913175 0 0 0 0" solimp="0.9999 0.9999 0.001 0.5 2"/>
    <joint joint1="walker_knee_l_translation1" joint2="knee_angle_l" polycoef="9.877e-08 0.00324 -0.00239 0.0005816 5.886e-07" solimp="0.9999 0.9999 0.001 0.5 2" active="true"/>
    <joint joint1="walker_knee_l_translation2" joint2="knee_angle_l" polycoef="-7.949e-11 -0.006076 0.001298 2.706e-06 -6.452e-07" solimp="0.9999 0.9999 0.001 0.5 2" active="true"/>
    <joint joint1="walker_knee_l_rotation2" joint2="knee_angle_l" polycoef="-1.473e-08 0.0791 -0.03285 -0.02522 0.01083" solimp="0.9999 0.9999 0.001 0.5 2" active="true"/>
    <joint joint1="walker_knee_l_rotation3" joint2="knee_angle_l" polycoef="-1.089e-08 -0.3695 0.1695 -0.02516 -3.505e-07" solimp="0.9999 0.9999 0.001 0.5 2" active="true"/>
    <joint name="mtp_angle_l_locked" active="true" joint1="mtp_angle_l" polycoef="0.0 0 0 0 0" solimp="0.9999 0.9999 0.001 0.5 2"/>
    <joint joint1="patellofemoral_l_translation1" joint2="knee_angle_l" polycoef="0.05515 -0.0158 -0.03583 0.01403 -0.000925" solimp="0.9999 0.9999 0.001 0.5 2" active="true"/>
    <joint joint1="patellofemoral_l_translation2" joint2="knee_angle_l" polycoef="-0.01121 -0.05052 0.009607 0.01364 -0.003621" solimp="0.9999 0.9999 0.001 0.5 2" active="true"/>
    <joint joint1="patellofemoral_l_rotation1" joint2="knee_angle_l" polycoef="0.01051 0.02476 -1.316 0.7163 -0.1383" solimp="0.9999 0.9999 0.001 0.5 2" active="true"/>
    <joint name="patellofemoral_l_translation3_locked" active="true" joint1="patellofemoral_l_translation3" polycoef="-0.002841818913175 0 0 0 0" solimp="0.9999 0.9999 0.001 0.5 2"/>
  </equality>
  <contact>
    <!-- Leave this comment here to make 'contact' element pretty printed !-->
    <pair geom1="ground-plane" geom2="pelvis_geom_1"/>
    <pair geom1="ground-plane" geom2="pelvis_geom_2"/>
    <pair geom1="ground-plane" geom2="pelvis_geom_3"/>
    <pair geom1="ground-plane" geom2="femur_r_geom_1"/>
    <pair geom1="ground-plane" geom2="tibia_r_geom_1"/>
    <pair geom1="ground-plane" geom2="tibia_r_geom_2"/>
    <pair geom1="ground-plane" geom2="talus_r_geom_1"/>
    <pair geom1="ground-plane" geom2="calcn_r_geom_1"/>
    <pair geom1="ground-plane" geom2="toes_r_geom_1"/>
    <pair geom1="ground-plane" geom2="patella_r_geom_1"/>
    <pair geom1="ground-plane" geom2="femur_l_geom_1"/>
    <pair geom1="ground-plane" geom2="tibia_l_geom_1"/>
    <pair geom1="ground-plane" geom2="tibia_l_geom_2"/>
    <pair geom1="ground-plane" geom2="talus_l_geom_1"/>
    <pair geom1="ground-plane" geom2="calcn_l_geom_1"/>
    <pair geom1="ground-plane" geom2="toes_l_geom_1"/>
    <pair geom1="ground-plane" geom2="patella_l_geom_1"/>
    <pair geom1="ground-plane" geom2="torso_geom_1"/>
    <pair geom1="ground-plane" geom2="torso_geom_2"/>
    <pair geom1="ground-plane" geom2="torso_geom_3"/>
    <pair geom1="ground-plane" geom2="torso_geom_4"/>
  </contact>
  <keyframe>
    <key name="default-pose" qpos="0 0.93 0 0 0 0 0 0 0 9.877e-08 7.949e-11 0 -1.473e-08 1.089e-08 0 0 0 0.05515 -0.01121 0.002842 0.01051 0 -0 -0 9.877e-08 -7.949e-11 0 -1.473e-08 -1.089e-08 0 0 0 0.05515 -0.01121 -0.002842 0.01051 0 0 0"/>
  </keyframe>
</mujoco>
