<mujoco model="template">
  
  
  <compiler inertiafromgeom="auto" angle="radian" balanceinertia="true" boundmass="0.25" boundinertia="0.01" inertiagrouprange="0 1">
    <lengthrange inttotal="50" useexisting="true" />
  </compiler>
  <option />
  <visual>
    <scale framelength="0.5" framewidth="0.01" />
  </visual>
  <default>
    <joint limited="true" damping="0.05" armature="0.01" stiffness="0" />
    <geom rgba="0.8 0.6 .4 1" margin="0.001" contype="0" conaffinity="0" />
    <site size="0.001" />
    <tendon width="0.005" rgba=".95 .3 .3 1" limited="false" />
    <default class="muscle">
      <muscle ctrllimited="true" ctrlrange="0 1" scale="200" />
    </default>
    <default class="motor">
      <general gainprm="5 0 0 0 0 0 0 0 0 0" />
    </default>
  </default>
  <option timestep="0.002" />
  
  <size njmax="1000" nconmax="400" nuser_jnt="1" nkey="1" />
  <worldbody>
    
    <body name="ground" euler="1.571 0 0">
      <geom name="ground-plane" pos="0 0 0" euler="-1.571 0 0" size="10 10 0.125" type="plane" rgba="1.0 0.7 0.4 1.0" condim="3" />
    </body>
    <light directional="true" />
    <body name="pelvis" pos="0 0 0" euler="1.571 0 0">
      <inertial mass="9.7770067292" pos="-0.0707000000 0.0000000000 0.0000000000" fullinertia="0.0853423021 0.0723085069 0.0480673083 0.0000000000 0.0000000000 0.0000000000" />
      <geom name="pelvis_geom_1" type="mesh" mesh="pelvis_geom_1_r_pelvis" rgba="1 1 1 1" group="0" />
      <geom name="pelvis_geom_2" type="mesh" mesh="pelvis_geom_2_l_pelvis" rgba="1 1 1 1" group="0" />
      <geom name="pelvis_geom_3" type="mesh" mesh="pelvis_geom_3_sacrum" rgba="1 1 1 1" group="0" />
      <geom name="Gmax1_at_pelvis_r_cylinder" type="cylinder" euler="-0.6 0.45 0" pos="-0.0808 -0.1073 0.06715" size="0.04295 0.08152" rgba="0.19 0.83 0.78 0.2" group="2" />
      <site name="Gmax1_at_pelvis_r_sidesite" pos="-0.1204 -0.09653 0.08293" size="0.0005" />
      <geom name="Gmax2_at_pelvis_r_cylinder" type="cylinder" euler="-0.75 0.39 0" pos="-0.08395 -0.08998 0.07486" size="0.04295 0.05434" rgba="0.19 0.83 0.78 0.2" group="2" />
      <geom name="Gmax3_at_pelvis_r_cylinder" type="cylinder" euler="-0.1 0 0" pos="-0.08709 -0.0954 0.07486" size="0.04267 0.05504" rgba="0.19 0.83 0.78 0.2" group="2" />
      <geom name="Gmax1_at_pelvis_l_cylinder" type="cylinder" euler="0.6 -0.45 0" pos="-0.0808 -0.1073 -0.06715" size="0.04295 0.08152" rgba="0.19 0.83 0.78 0.2" group="2" />
      <site name="Gmax1_at_pelvis_l_sidesite" pos="-0.1204 -0.09653 -0.08293" size="0.0005" />
      <geom name="Gmax2_at_pelvis_l_cylinder" type="cylinder" euler="0.75 -0.39 0" pos="-0.08395 -0.08998 -0.07486" size="0.04295 0.05434" rgba="0.19 0.83 0.78 0.2" group="2" />
      <geom name="Gmax3_at_pelvis_l_cylinder" type="cylinder" euler="0.1 0 0" pos="-0.08709 -0.0954 -0.07486" size="0.04267 0.05504" rgba="0.19 0.83 0.78 0.2" group="2" />
      <geom name="PS_at_brim_r_cylinder" type="cylinder" euler="-0.25 -0.27 0.1" pos="-0.07765 -0.06505 0.07222" size="0.05345 0.05482" rgba="0.19 0.83 0.78 0.2" group="2" />
      <site name="PS_at_brim_r_sidesite" pos="-0.07241 -0.1172 0.08703" size="0.0005" />
      <geom name="PS_at_brim_l_cylinder" type="cylinder" euler="0.25 0.27 0.1" pos="-0.07765 -0.06505 -0.07222" size="0.05345 0.05482" rgba="0.19 0.83 0.78 0.2" group="2" />
      <site name="PS_at_brim_l_sidesite" pos="-0.07241 -0.1172 -0.08703" size="0.0005" />
      <geom name="IL_at_brim_r_cylinder" type="cylinder" euler="-0.32 -0.24 0.9" pos="-0.0745 -0.07047 0.08323" size="0.05869 0.05482" rgba="0.19 0.83 0.78 0.2" group="2" />
      <site name="IL_at_brim_r_sidesite" pos="-0.02908 -0.1022 0.1054" size="0.0005" />
      <geom name="IL_at_brim_l_cylinder" type="cylinder" euler="0.32 0.24 0.9" pos="-0.0745 -0.07047 -0.08323" size="0.05869 0.05482" rgba="0.19 0.83 0.78 0.2" group="2" />
      <site name="IL_at_brim_l_sidesite" pos="-0.02908 -0.1022 -0.1054" size="0.0005" />
      <joint name="pelvis_tx" range="-40 40" limited="true" user="0.0" ref="0" axis="1 0 0" type="slide" damping="0" stiffness="0" />
      <joint name="pelvis_ty" range="-5 5" limited="true" user="0.93" ref="0" axis="0 1 0" type="slide" damping="0" stiffness="0" />
      <joint name="pelvis_tz" range="-40 40" limited="true" user="0.0" ref="0" axis="0 0 1" type="slide" damping="0" stiffness="0" />
      <joint name="pelvis_tilt" range="-3.142 3.142" limited="true" user="0.0" ref="0" axis="0 0 1" type="hinge" damping="0" stiffness="0" />
      <joint name="pelvis_list" range="-3.142 3.142" limited="true" user="0.0" ref="0" axis="1 0 0" type="hinge" damping="0" stiffness="0" />
      <joint name="pelvis_rotation" range="-3.142 3.142" limited="true" user="0.0" ref="0" axis="0 1 0" type="hinge" damping="0" stiffness="0" />
      <body name="femur_r" pos="-0.05905 -0.08509 0.08505" euler="-0 0 0">
        <inertial mass="7.7218179835" pos="0.0000000000 -0.1700000000 0.0000000000" fullinertia="0.1111608390 0.0291392491 0.1172211387 0.0000000000 0.0000000000 0.0000000000" />
        <geom name="femur_r_geom_1" type="mesh" mesh="femur_r_geom_1_r_femur" rgba="1 1 1 1" group="0" />
        <geom name="Gastroc_at_condyles_r_cylinder" type="cylinder" euler="0 0 0" pos="0.005172 -0.4151 0" size="0.02559 0.052" rgba="0.19 0.83 0.78 0.2" group="2" />
        <geom name="KnExt_at_fem_r_cylinder" type="cylinder" euler="-0.06234 0.05076 0" pos="0.003712 -0.4078 0.002175" size="0.02559 0.052" rgba="0.19 0.83 0.78 0.2" group="2" />
        <geom name="AB_at_femshaft_r_cylinder" type="cylinder" euler="1.662 0.1866 0" pos="0.01515 -0.114 0.0243" size="0.01711 0.03547" rgba="0.19 0.83 0.78 0.2" group="2" />
        <geom name="AL_at_femshaft_r_cylinder" type="cylinder" euler="1.777 0.1365 0" pos="0.03179 -0.2348 0.01572" size="0.02083 0.0507" rgba="0.19 0.83 0.78 0.2" group="2" />
        <geom name="AMprox_at_femshaft_r_cylinder" type="cylinder" euler="1.611 0.1866 0" pos="0.005361 -0.07381 0.02642" size="0.02188 0.03547" rgba="0.19 0.83 0.78 0.2" group="2" />
        <geom name="AMmid_at_femshaft_r_cylinder" type="cylinder" euler="1.611 0.1366 0" pos="0.0238 -0.1627 0.02141" size="0.02219 0.06078" rgba="0.19 0.83 0.78 0.2" group="2" />
        <geom name="AMdist_at_femshaft_r_cylinder" type="cylinder" euler="1.712 0.1866 0" pos="0.03269 -0.264 0.00974" size="0.0226 0.1014" rgba="0.19 0.83 0.78 0.2" group="2" />
        <geom name="AMisch_at_condyles_r_cylinder" type="cylinder" euler="1.711 -0.4634 0" pos="-0.02343 -0.3815 -0.003281" size="0.04139 0.1221" rgba="0.19 0.83 0.78 0.2" group="2" />
        <geom name="PECT_at_femshaft_r_cylinder" type="cylinder" euler="1.813 0.2763 0" pos="0.006295 -0.08556 0.03166" size="0.01554 0.02539" rgba="0.19 0.83 0.78 0.2" group="2" />
        <joint name="hip_flexion_r" range="-0.5236 2.094" limited="true" user="0.0" ref="0" axis="0 0 1" type="hinge" />
        <joint name="hip_adduction_r" range="-0.8727 0.5236" limited="true" user="0.0" ref="0" axis="1 0 0" type="hinge" />
        <joint name="hip_rotation_r" range="-0.6981 0.6981" limited="true" user="0.0" ref="0" axis="0 1 0" type="hinge" />
        <body name="tibia_r" pos="-0.0001422 -0.4095 -0.00137" euler="-0 0 0">
          <inertial mass="3.0778850682" pos="0.0000000000 -0.1867000000 0.0000000000" fullinertia="0.041840973 0.01 0.0424220976 0.0 0.0 0.0" />
          <geom name="tibia_r_geom_1" type="mesh" mesh="tibia_r_geom_1_r_tibia" rgba="1 1 1 1" group="0" />
          <geom name="tibia_r_geom_2" type="mesh" mesh="tibia_r_geom_2_r_fibula" rgba="1 1 1 1" group="0" />
          <geom name="GasLat_at_shank_r_cylinder" type="cylinder" euler="2.967 -0.2797 -1.478" pos="-0.007525 -0.07544 -0.003311" size="0.05596 0.05025" rgba="0.19 0.83 0.78 0.2" group="2" />
          <site name="GasLat_at_shank_r_sidesite" pos="-0.06203 -0.06754 0.0112" size="0.0005" />
          <geom name="GasMed_at_shank_r_cylinder" type="cylinder" euler="2.967 0.02797 -1.478" pos="-0.007525 -0.07544 -0.003311" size="0.05599 0.0502" rgba="0.19 0.83 0.78 0.2" group="2" />
          <site name="GasMed_at_shank_r_sidesite" pos="-0.06424 -0.07052 -0.005789" size="0.0005" />
          <geom name="GR_at_condyles_r_cylinder" type="cylinder" euler="0 -0.4 0" pos="-0.00305 -0.02039 0" size="0.03662 0.05027" rgba="0.19 0.83 0.78 0.2" group="2" />
          <geom name="SM_at_condyles_r_cylinder" type="cylinder" euler="0 -0.1 0" pos="-0.001017 -0.02039 0" size="0.03584 0.05018" rgba="0.19 0.83 0.78 0.2" group="2" />
          <geom name="ST_at_condyles_r_cylinder" type="cylinder" euler="0 -0.2 0" pos="-0.002034 -0.0209 0" size="0.04326 0.0502" rgba="0.19 0.83 0.78 0.2" group="2" />
          <geom name="BF_at_gastroc_r_cylinder" type="cylinder" euler="0 0 0" pos="-0.05898 -0.06117 0" size="0.03054 0.07526" rgba="0.19 0.83 0.78 0.2" group="2" />
          <site name="BF_at_gastroc_r_sidesite" pos="-0.05898 -0.02962 0" size="0.0005" />
          <joint name="walker_knee_r_translation1" range="0 0.001619" limited="true" user="9.656727133059741e-08" ref="0" axis="-0.1243 0.9898 -0.07016" type="slide" />
          <joint name="walker_knee_r_translation2" range="0 0.007064" limited="true" user="8.000780940542462e-11" ref="0" axis="0.9922 0.124 -0.008789" type="slide" />
          <joint name="knee_angle_r" range="0 2.094" limited="true" user="0.0" ref="0" axis="-4.566e-07 -0.07071 -0.9975" type="hinge" />
          <joint name="walker_knee_r_rotation2" range="-0.001678 0.03354" limited="true" user="-1.4732523263838448e-08" ref="0" axis="0.9922 0.124 -0.008789" type="hinge" />
          <joint name="walker_knee_r_rotation3" range="0 0.2628" limited="true" user="1.0893911855935912e-08" ref="0" axis="-0.1243 0.9898 -0.07016" type="hinge" />
          <body name="talus_r" pos="-0.01017 -0.4078 0" euler="-0 0 0">
            <inertial mass="0.25" pos="0.0000000000 0.0000000000 0.0000000000" fullinertia="0.01 0.01 0.01 0.0 0.0 0.0" />
            <geom name="talus_r_geom_1" type="mesh" mesh="talus_r_geom_1_r_talus" rgba="1 1 1 0" group="0" />
            <joint name="ankle_angle_r" range="-0.6981 0.5236" limited="true" user="0.0" ref="0" type="hinge" axis="-0.105 -0.174 0.9791" />
            <body name="calcn_r" pos="-0.05925 -0.0522 0.009647" euler="-0 0 0">
              <inertial mass="1.0377225449" pos="0.1000000000 0.0300000000 0.0000000000" fullinertia="0.01 0.01 0.01 0.0 0.0 0.0" />
              <geom name="calcn_r_geom_1" type="mesh" mesh="calcn_r_geom_1_r_foot" rgba="1 1 1 1" group="0" />
              <joint name="subtalar_angle_r" range="-0.3491 0.3491" limited="true" user="0.0" ref="0" type="hinge" axis="0.7872 0.6047 -0.1209" />
              <body name="toes_r" pos="0.1767 -0.001978 0.001091" euler="-0 0 0">
                <inertial mass="0.25" pos="0.0346000000 0.0060000000 -0.0175000000" fullinertia="0.01 0.01 0.01 0.0 0.0 0.0" />
                <geom name="toes_r_geom_1" type="mesh" mesh="toes_r_geom_1_r_bofoot" rgba="1 1 1 1" group="0" />
                <joint name="mtp_angle_r" range="-0.5236 0.5236" limited="true" user="0.0" ref="0" type="hinge" axis="0.581 2.16e-06 -0.8139" />
                <site name="edl_r_edl_r-P5" pos="0.00032068305785999999 0.0050222131045900001 0.016352987153939999" />
                <site name="edl_r_edl_r-P6" pos="0.047354198210659997 -0.00042742239187999997 0.026720567245" />
                <site name="ehl_r_ehl_r-P7" pos="0.031854517080760002 0.0043810795167700005 -0.026186155900100001" />
                <site name="ehl_r_ehl_r-P8" pos="0.060181520525060005 0.0036330903309799998 -0.019880102030279997" />
                <site name="fdl_r_fdl_r-P6" pos="-0.0020309926997800001 -0.0083347366416599983 0.015711693540059999" />
                <site name="fdl_r_fdl_r-P7" pos="0.030464890496700002 -0.0075867474558700002 0.022979687830699997" />
                <site name="fdl_r_fdl_r-P8" pos="0.047140409505419999 -0.0064113358781999995 0.025865509093159999" />
                <site name="fhl_r_fhl_r-P6" pos="0.016568624656100001 -0.0068387582700799995 -0.028323801279699998" />
                <site name="fhl_r_fhl_r-P7" pos="0.060074626172439999 -0.01089927099294 -0.019345690685380001" />
              </body>
              <site name="edl_r_edl_r-P3" pos="0.090811035737990001 0.03561078132 0.00080810862752000014" />
              <site name="edl_r_edl_r-P4" pos="0.15968512921936001 0.0054405360349999996 0.013131765197199999" />
              <site name="ehl_r_ehl_r-P4" pos="0.095850603553700009 0.038479427593 -0.021313865050840004" />
              <site name="ehl_r_ehl_r-P5" pos="0.12776786638653001 0.030565920633000003 -0.025960489659080002" />
              <site name="ehl_r_ehl_r-P6" pos="0.17134530573414 0.013749718342999999 -0.028283801963200003" />
              <site name="fdl_r_fdl_r-P3" pos="0.04308336407156 0.031159433655000002 -0.028283801963200003" />
              <site name="fdl_r_fdl_r-P4" pos="0.06996105908868 0.017409715312000001 -0.026566571129720003" />
              <site name="fdl_r_fdl_r-P5" pos="0.16383536153818001 -0.0080124257969999991 0.011717575099039999" />
              <site name="fhl_r_fhl_r-P3" pos="0.036956830648540002 0.027301599012000001 -0.024344272404040003" />
              <site name="fhl_r_fhl_r-P4" pos="0.10257002730798001 0.0067264809159999998 -0.025859476080640004" />
              <site name="fhl_r_fhl_r-P5" pos="0.17055478529246001 -0.0052426983610000004 -0.027172652600360003" />
              <site name="gaslat_r_gaslat_r-P2" pos="0.0043478624292400004 0.03066483947 -0.0053537196573200004" />
              <site name="gasmed_r_gasmed_r-P2" pos="0.0043478624292400004 0.03066483947 -0.0053537196573200004" />
              <site name="perbrev_r_perbrev_r-P4" pos="0.046541891003910006 0.026708085990000002 0.023536163776520003" />
              <site name="perbrev_r_perbrev_r-P5" pos="0.066897792377170001 0.021663225303000001 0.034647657404919999" />
              <site name="perlong_r_perlong_r-P4" pos="0.043280994181979997 0.02275133251 0.022324000835240002" />
              <site name="perlong_r_perlong_r-P5" pos="0.067293052598009995 0.010485396722000001 0.028687856276960005" />
              <site name="perlong_r_perlong_r-P6" pos="0.084190427038920004 0.0068253997530000002 0.01191960225592" />
              <site name="perlong_r_perlong_r-P7" pos="0.11887451141763 0.008408101145000001 -0.018586498432960001" />
              <site name="soleus_r_soleus_r-P2" pos="0.0043478624292400004 0.03066483947 -0.0053537196573200004" />
              <site name="tibant_r_tibant_r-P4" pos="0.11521835437486 0.017607552985999999 -0.0308091414242" />
              <site name="tibpost_r_tibpost_r-P3" pos="0.041205878022570003 0.033038891558000001 -0.028889883433840004" />
              <site name="tibpost_r_tibpost_r-P4" pos="0.076285222622120008 0.015728095083 -0.028384815541640001" />
              <site name="R1MT_marker" group="4" pos="0.1882 0.02369 -0.02529" rgba="1 0.1 0.5 0.5" size="0.01" />
              <site name="R5MT_marker" group="4" pos="0.1477 0.01045 0.07745" rgba="1 0.1 0.5 0.5" size="0.01" />
              <site name="RCAL_marker" group="4" pos="-0.01841 0.01813 -0.001468" rgba="1 0.1 0.5 0.5" size="0.01" />
            </body>
          </body>
          <site name="bflh_r_bflh_r-P2" pos="-0.034267238036039996 -0.035682418341500002 0.025386930913849998" />
          <site name="bflh_r_bflh_r-P3" pos="-0.029183078090039997 -0.046387143843949999 0.030404110936349999" />
          <site name="bfsh_r_bfsh_r-P2" pos="-0.030606642874919997 -0.04271695224311 0.031909264943100001" />
          <site name="edl_r_edl_r-P1" pos="-0.016269311827200001 -0.11795588006032999 0.020570438092249999" />
          <site name="edl_r_edl_r-P2" pos="0.016676044622880002 -0.38333112275440001 0.0112384832504" />
          <site name="ehl_r_ehl_r-P1" pos="-0.0142356478488 -0.15802213836949999 0.01896494048505" />
          <site name="ehl_r_ehl_r-P2" pos="0.0072195071233200001 -0.29657187130120999 0.016456350473800001" />
          <site name="ehl_r_ehl_r-P3" pos="0.020336639784 -0.37650048838617001 -0.0028096208126" />
          <site name="fdl_r_fdl_r-P1" pos="-0.00233871357516 -0.18677197257608 -0.0018061848080999999" />
          <site name="fdl_r_fdl_r-P2" pos="-0.017896243009920001 -0.37160689958505 -0.012442606455799999" />
          <site name="fhl_r_fhl_r-P1" pos="-0.0315217916652 -0.22051734535046999 0.020068720089999999" />
          <site name="fhl_r_fhl_r-P2" pos="-0.024607334138639997 -0.37425759351898996 -0.0076261136341999993" />
          <site name="grac_r_grac_r-P2" pos="-0.018730045241063999 -0.048477114061094999 -0.029711740093244999" />
          <site name="grac_r_grac_r-P3" pos="0.0018099609407759999 -0.070977427569578005 -0.015784048350785" />
          <site name="GR_at_condyles_r_cylinder_grac_r_1_sidesite" pos="-0.01559 -0.003714 -0.0327" size="0.0005" />
          <site name="perbrev_r_perbrev_r-P1" pos="-0.024709017337559997 -0.25813680925908 0.025186243712949998" />
          <site name="perbrev_r_perbrev_r-P2" pos="-0.034470604433879996 -0.39689044172416998 0.024985556512049995" />
          <site name="perbrev_r_perbrev_r-P3" pos="-0.0289797116922 -0.40820686582675997 0.025587618114749997" />
          <site name="perlong_r_perlong_r-P1" pos="-0.020336639784 -0.13997702966537001 0.028296895326899996" />
          <site name="perlong_r_perlong_r-P2" pos="-0.032233574057639998 -0.39760409009100001 0.023781433306649998" />
          <site name="perlong_r_perlong_r-P3" pos="-0.027657830106239997 -0.40922636349365998 0.024082464107999999" />
          <site name="recfem_r_recfem_r-P5" pos="0.033148722847919997 -0.064350692734727988 -0.00047161492211499995" />
          <site name="sart_r_sart_r-P3" pos="-0.025522482928919999 -0.040881856442689997 -0.036625414164249998" />
          <site name="sart_r_sart_r-P4" pos="-0.016167628628280001 -0.061067910247310002 -0.026490710518799997" />
          <site name="sart_r_sart_r-P5" pos="0.013828915053119999 -0.082579311018899995 -0.0026089336116999996" />
          <site name="semimem_r_semimem_r-P2" pos="-0.029488127686800002 -0.04251305270973 -0.019667345688199996" />
          <site name="SM_at_condyles_r_cylinder_semimem_r_1_sidesite" pos="-0.02949 -0.04251 -0.01967" size="0.0005" />
          <site name="semiten_r_semiten_r-P2" pos="-0.03172515806304 -0.051790481478520001 -0.02297868450305" />
          <site name="semiten_r_semiten_r-P3" pos="0.0019319807794799999 -0.078807169651369996 -0.011740201252649999" />
          <site name="ST_at_condyles_r_cylinder_semiten_r_1_sidesite" pos="-0.03538 -0.005408 -0.02464" size="0.0005" />
          <site name="soleus_r_soleus_r-P1" pos="-0.0077279231179199995 -0.093385986288039999 0.0098336728440999981" />
          <site name="tfl_r_tfl_r-P4" pos="0.01098178548336 -0.041799404342899998 0.034718885755699994" />
          <site name="tibant_r_tibant_r-P1" pos="0.01565921263368 -0.13375809389728002 0.016255663272899998" />
          <site name="tibant_r_tibant_r-P2" pos="0.025522482928919999 -0.19431625531114 0.012843980857599999" />
          <site name="tibant_r_tibant_r-P3" pos="0.023692185348360002 -0.37303419631870999 -0.013245355259399998" />
          <site name="tibpost_r_tibpost_r-P1" pos="-0.0041690111557200005 -0.13294249576375999 0.010335390846349999" />
          <site name="tibpost_r_tibpost_r-P2" pos="-0.016676044622880002 -0.37262639725195001 -0.01756013007875" />
          <site name="vasint_r_vasint_r-P5" pos="0.033118217888243998 -0.064432252548080007 0.00043147748193499998" />
          <site name="vaslat_r_vaslat_r-P5" pos="0.033087712928567999 -0.064615762128122006 0.0051275579829949992" />
          <site name="vasmed_r_vasmed_r-P5" pos="0.032436940455479998 -0.064809466684833006 -0.0068032961105099991" />
          <site name="RLM_marker" group="4" pos="-0.005673 -0.4197 0.06004" rgba="1 0.1 0.5 0.5" size="0.01" />
          <site name="RMM_marker" group="4" pos="0.0008136 -0.4036 -0.04146" rgba="1 0.1 0.5 0.5" size="0.01" />
          <site name="RS1_marker" group="4" pos="0.03398 -0.1959 0.01037" rgba="1 0.1 0.5 0.5" size="0.01" />
          <site name="RS2_marker" group="4" pos="0.02338 -0.1519 0.06751" rgba="1 0.1 0.5 0.5" size="0.01" />
          <site name="RS3_marker" group="4" pos="0.04304 -0.09667 -0.007675" rgba="1 0.1 0.5 0.5" size="0.01" />
        </body>
        <body name="patella_r" pos="-0.008368 -0.4131 -0.00286" euler="-0 0 0">
          <inertial mass="0.25" pos="0.0018 0.0264 0" fullinertia="0.01 0.01 0.01 0.0 0.0 0.0" />
          <geom name="patella_r_geom_1" type="mesh" mesh="patella_r_geom_1_r_patella" rgba="1 1 1 1" group="0" />
          <joint name="patellofemoral_r_translation1" range="-0.02348 0.0542" limited="true" user="0.05422017724182766" ref="0" axis="1 0 0" type="slide" />
          <joint name="patellofemoral_r_translation2" range="-0.04131 -0.01094" limited="true" user="-0.010963680818873674" ref="0" axis="0 1 0" type="slide" />
          <joint name="patellofemoral_r_translation3" limited="false" ref="0" axis="0 0 1" type="slide" />
          <joint name="patellofemoral_r_rotation1" range="-1.786 0.001137" limited="true" user="0.01050598499723554" ref="0" axis="0 0 1" type="hinge" />
          <site name="recfem_r_recfem_r-P2" pos="0.01 0.049000000000000002 0.00069999999999999999" />
          <site name="recfem_r_recfem_r-P3" pos="0.0121 0.043700000000000003 -0.001" />
          <site name="recfem_r_recfem_r-P4" pos="0.0050000000000000001 0.00247 3.0000000000000001e-05" />
          <site name="vasint_r_vasint_r-P3" pos="0.0057999999999999996 0.048000000000000001 -0.00059999999999999995" />
          <site name="vasint_r_vasint_r-P4" pos="0.0050000000000000001 0.00247 -0.00038999999999999999" />
          <site name="vaslat_r_vaslat_r-P3" pos="0.0103 0.042299999999999997 0.0141" />
          <site name="vaslat_r_vaslat_r-P4" pos="0.0050000000000000001 0.00247 0.0073299999999999997" />
          <site name="vasmed_r_vasmed_r-P3" pos="0.0063 0.044499999999999998 -0.017000000000000001" />
          <site name="vasmed_r_vasmed_r-P4" pos="0.0050000000000000001 0.00247 -0.0085000000000000006" />
        </body>
        <site name="addbrev_r_addbrev_r-P2" pos="-0.0020687131928000002 -0.11947718189079999 0.025897732327859996" />
        <site name="AB_at_femshaft_r_cylinder_addbrev_r_1_sidesite" pos="0.001294 -0.1075 0.01461" size="0.0005" />
        <site name="addlong_r_addlong_r-P2" pos="0.011646855275464 -0.242366551094922 0.016464301315261998" />
        <site name="AL_at_femshaft_r_cylinder_addlong_r_1_sidesite" pos="0.01165 -0.2424 0.01646" size="0.0005" />
        <site name="addmagDist_r_addmagDist_r-P2" pos="0.011636511709500001 -0.26578610378250001 0.020073342728019999" />
        <site name="AMdist_at_femshaft_r_cylinder_addmagDist_r_1_sidesite" pos="0.01164 -0.2658 0.02007" size="0.0005" />
        <site name="addmagIsch_r_addmagIsch_r-P2" pos="0.0049752552286840002 -0.39282679879808197 -0.034041477071921997" />
        <site name="AMisch_at_condyles_r_cylinder_addmagIsch_r_1_sidesite" pos="0.004975 -0.3928 -0.03404" size="0.0005" />
        <site name="addmagMid_r_addmagMid_r-P2" pos="0.002503142963288 -0.16443300287343998 0.030390832876307998" />
        <site name="AMmid_at_femshaft_r_cylinder_addmagMid_r_1_sidesite" pos="0.002503 -0.1644 0.03039" size="0.0005" />
        <site name="addmagProx_r_addmagProx_r-P2" pos="-0.015794625227028004 -0.079847208168716002 0.033303027676227996" />
        <site name="AMprox_at_femshaft_r_cylinder_addmagProx_r_1_sidesite" pos="-0.01666 -0.0747 0.02027" size="0.0005" />
        <site name="bfsh_r_bfsh_r-P1" pos="0.005171782982000001 -0.21374265336566001 0.024337627970759997" />
        <site name="gaslat_r_gaslat_r-P1" pos="-0.0031030697892000005 -0.38617455231483999 0.028809927127779997" />
        <site name="Gastroc_at_condyles_r_cylinder_gaslat_r_1_sidesite" pos="-0.01 -0.4365 0.02593" size="0.0005" />
        <site name="gasmed_r_gasmed_r-P1" pos="0.0082748527712000006 -0.38354200423928003 -0.021633447085119998" />
        <site name="Gastroc_at_condyles_r_cylinder_gasmed_r_1_sidesite" pos="0.0001094 -0.4341 -0.0189" size="0.0005" />
        <site name="glmax1_r_glmax1_r-P3" pos="-0.04592543288016001 -0.03300810279356 0.031410101056279997" />
        <site name="glmax1_r_glmax1_r-P4" pos="-0.028651677720280003 -0.057308546567959993 0.048883269855799993" />
        <site name="glmax2_r_glmax2_r-P3" pos="-0.046546046838000003 -0.059131079851039998 0.026209753199279998" />
        <site name="glmax2_r_glmax2_r-P4" pos="-0.01613596290384 -0.10287187864495999 0.043578915041659998" />
        <site name="glmax3_r_glmax3_r-P3" pos="-0.029065420358840004 -0.1139083301925 0.0097766539711599994" />
        <site name="glmax3_r_glmax3_r-P4" pos="-0.0062061395784000009 -0.14367637381613999 0.042746859384539995" />
        <site name="glmed1_r_glmed1_r-P2_0" pos="-0.014369028126288088 -0.018523727225923717 0.061561322411181514" />
        <site name="glmed2_r_glmed2_r-P2_0" pos="-0.022793096724604302 -0.0100837698602536 0.058375177343781545" />
        <site name="glmed3_r_glmed3_r-P2_0" pos="-0.031961618828760002 -0.0047588369058200004 0.053875603798519994" />
        <site name="glmin1_r_glmin1_r-P2" pos="0.005677913087933837 -0.015682495012175394 0.058283213449457034" />
        <site name="glmin2_r_glmin2_r-P2" pos="0.0036652849359606102 -0.0091250889770850292 0.054566550834062873" />
        <site name="glmin3_r_glmin3_r-P2" pos="-0.0036990012445511492 -0.0012825579505185828 0.05331568185412254" />
        <site name="iliacus_r_iliacus_r-P3" pos="-0.0023790201717200001 -0.057207294718900001 0.014456967042459998" />
        <site name="iliacus_r_iliacus_r-P4" pos="-0.012619150476080003 -0.064497427851220007 0.020385363599439998" />
        <site name="piri_r_piri_r-P3" pos="-0.015308477626720001 -0.0036450665661599997 0.045451040270180001" />
        <site name="psoas_r_psoas_r-P3" pos="-0.013653507072480002 -0.04728461351102 0.0047843200284399994" />
        <site name="psoas_r_psoas_r-P4" pos="-0.024307380015400004 -0.05305596890744 0.0091526122283199993" />
        <site name="KnExt_at_fem_r_cylinder_recfem_r_3_sidesite" pos="-0.01645 -0.4022 -0.01423" size="0.0005" />
        <site name="sart_r_sart_r-P2" pos="-0.0031030697892000005 -0.36126659744608003 -0.043786928955939997" />
        <site name="tfl_r_tfl_r-P2" pos="0.030410083934160004 -0.1007455898147 0.062092153412579995" />
        <site name="tfl_r_tfl_r-P3" pos="0.011067615581480001 -0.41006998869300004 0.033698254113359992" />
        <site name="vasint_r_vasint_r-P1" pos="0.029996341295600006 -0.19480855759143997 0.0322421567134" />
        <site name="vasint_r_vasint_r-P2" pos="0.034650945979400008 -0.21100885344104001 0.029641982784899996" />
        <site name="KnExt_at_fem_r_cylinder_vasint_r_3_sidesite" pos="-0.01663 -0.4013 -0.01368" size="0.0005" />
        <site name="vaslat_r_vaslat_r-P1" pos="0.0049649116627200002 -0.18772092815724001 0.036298428041859995" />
        <site name="vaslat_r_vaslat_r-P2" pos="0.027824192443160003 -0.26234354091445999 0.042538845470259996" />
        <site name="KnExt_at_fem_r_cylinder_vaslat_r_3_sidesite" pos="-0.01978 -0.402 0.0132" size="0.0005" />
        <site name="KnExt_at_fem_r_cylinder_vaslat_r_2_sidesite" pos="0.001932 -0.3708 0.01124" size="0.0005" />
        <site name="vasmed_r_vasmed_r-P1" pos="0.014480992349600002 -0.21252763117694001 0.019553307942319999" />
        <site name="vasmed_r_vasmed_r-P2" pos="0.03682309483184 -0.28036637004713999 0.00093606261425999984" />
        <site name="KnExt_at_fem_r_cylinder_vasmed_r_4_sidesite" pos="-0.008406 -0.4126 -0.02099" size="0.0005" />
        <site name="KnExt_at_fem_r_cylinder_vasmed_r_3_sidesite" pos="-0.008406 -0.4126 -0.02099" size="0.0005" />
        <site name="RLFE_marker" group="4" pos="0.008047 -0.41 0.06573" rgba="1 0.1 0.5 0.5" size="0.01" />
        <site name="RMFE_marker" group="4" pos="-0.002906 -0.4106 -0.05815" rgba="1 0.1 0.5 0.5" size="0.01" />
        <site name="RT1_marker" group="4" pos="0.07015 -0.2866 0.07019" rgba="1 0.1 0.5 0.5" size="0.01" />
        <site name="RT2_marker" group="4" pos="0.107 -0.2497 0.01699" rgba="1 0.1 0.5 0.5" size="0.01" />
        <site name="RT3_marker" group="4" pos="0.0882 -0.2082 0.06769" rgba="1 0.1 0.5 0.5" size="0.01" />
        <site name="RTRC_marker" group="4" pos="-0.01897 -0.02277 0.0938" rgba="1 0.1 0.5 0.5" size="0.01" />
      </body>
      <body name="femur_l" pos="-0.05905 -0.08509 -0.08505" euler="-0 0 0">
        <inertial mass="7.7218179835" pos="0.0000000000 -0.1700000000 0.0000000000" fullinertia="0.1111608390 0.0291392491 0.1172211387 0.0000000000 0.0000000000 0.0000000000" />
        <geom name="femur_l_geom_1" type="mesh" mesh="femur_l_geom_1_l_femur" rgba="1 1 1 1" group="0" />
        <geom name="Gastroc_at_condyles_l_cylinder" type="cylinder" euler="0 0 0" pos="0.005172 -0.4151 0" size="0.02559 0.052" rgba="0.19 0.83 0.78 0.2" group="2" />
        <geom name="KnExt_at_fem_l_cylinder" type="cylinder" euler="0.06234 -0.05076 0" pos="0.003712 -0.4078 -0.002175" size="0.02559 0.052" rgba="0.19 0.83 0.78 0.2" group="2" />
        <geom name="AB_at_femshaft_l_cylinder" type="cylinder" euler="-1.662 -0.1866 0" pos="0.01515 -0.114 -0.0243" size="0.01711 0.03547" rgba="0.19 0.83 0.78 0.2" group="2" />
        <geom name="AL_at_femshaft_l_cylinder" type="cylinder" euler="-1.777 -0.1365 0" pos="0.03179 -0.2348 -0.01572" size="0.02083 0.0507" rgba="0.19 0.83 0.78 0.2" group="2" />
        <geom name="AMprox_at_femshaft_l_cylinder" type="cylinder" euler="-1.611 -0.1866 0" pos="0.005361 -0.07381 -0.02642" size="0.02188 0.03547" rgba="0.19 0.83 0.78 0.2" group="2" />
        <geom name="AMmid_at_femshaft_l_cylinder" type="cylinder" euler="-1.611 -0.1366 0" pos="0.0238 -0.1627 -0.02141" size="0.02219 0.06078" rgba="0.19 0.83 0.78 0.2" group="2" />
        <geom name="AMdist_at_femshaft_l_cylinder" type="cylinder" euler="-1.712 -0.1866 0" pos="0.03269 -0.264 -0.00974" size="0.0226 0.1014" rgba="0.19 0.83 0.78 0.2" group="2" />
        <geom name="AMisch_at_condyles_l_cylinder" type="cylinder" euler="-1.711 0.4634 0" pos="-0.02343 -0.3815 0.003281" size="0.04139 0.1221" rgba="0.19 0.83 0.78 0.2" group="2" />
        <geom name="PECT_at_femshaft_l_cylinder" type="cylinder" euler="-1.813 -0.2763 0" pos="0.006295 -0.08556 -0.03166" size="0.01554 0.02539" rgba="0.19 0.83 0.78 0.2" group="2" />
        <joint name="hip_flexion_l" range="-0.5236 2.094" limited="true" user="0.0" ref="0" axis="0 0 1" type="hinge" />
        <joint name="hip_adduction_l" range="-0.8727 0.5236" limited="true" user="-0.0" ref="0" axis="-1 -0 -0" type="hinge" />
        <joint name="hip_rotation_l" range="-0.6981 0.6981" limited="true" user="-0.0" ref="0" axis="-0 -1 -0" type="hinge" />
        <body name="tibia_l" pos="-0.0001422 -0.4095 0.00137" euler="-0 0 0">
          <inertial mass="3.0778850682" pos="0.0000000000 -0.1867000000 0.0000000000" fullinertia="0.041840973 0.01 0.0424220976 0.0 0.0 0.0" />
          <geom name="tibia_l_geom_1" type="mesh" mesh="tibia_l_geom_1_l_tibia" rgba="1 1 1 1" group="0" />
          <geom name="tibia_l_geom_2" type="mesh" mesh="tibia_l_geom_2_l_fibula" rgba="1 1 1 1" group="0" />
          <geom name="GasLat_at_shank_l_cylinder" type="cylinder" euler="-2.967 0.2797 -1.478" pos="-0.007525 -0.07544 0.003311" size="0.05596 0.05025" rgba="0.19 0.83 0.78 0.2" group="2" />
          <site name="GasLat_at_shank_l_sidesite" pos="-0.06203 -0.06754 -0.0112" size="0.0005" />
          <geom name="GasMed_at_shank_l_cylinder" type="cylinder" euler="-2.967 -0.02797 -1.478" pos="-0.007525 -0.07544 0.003311" size="0.05599 0.0502" rgba="0.19 0.83 0.78 0.2" group="2" />
          <site name="GasMed_at_shank_l_sidesite" pos="-0.06424 -0.07052 0.005789" size="0.0005" />
          <geom name="GR_at_condyles_l_cylinder" type="cylinder" euler="0 0.4 0" pos="-0.00305 -0.02039 0" size="0.03662 0.05027" rgba="0.19 0.83 0.78 0.2" group="2" />
          <geom name="SM_at_condyles_l_cylinder" type="cylinder" euler="0 0.1 0" pos="-0.001017 -0.02039 0" size="0.03584 0.05018" rgba="0.19 0.83 0.78 0.2" group="2" />
          <geom name="ST_at_condyles_l_cylinder" type="cylinder" euler="0 0.2 0" pos="-0.002034 -0.0209 0" size="0.04326 0.0502" rgba="0.19 0.83 0.78 0.2" group="2" />
          <geom name="BF_at_gastroc_l_cylinder" type="cylinder" euler="0 0 0" pos="-0.05898 -0.06117 0" size="0.03054 0.07526" rgba="0.19 0.83 0.78 0.2" group="2" />
          <joint name="walker_knee_l_translation1" range="0 0.001619" limited="true" user="9.656727133059741e-08" ref="0" axis="-0.1243 0.9898 0.07016" type="slide" />
          <joint name="walker_knee_l_translation2" range="-0.007064 0" limited="true" user="-8.000780940542462e-11" ref="0" axis="-0.9922 -0.124 -0.008789" type="slide" />
          <joint name="knee_angle_l" range="0 2.094" limited="true" user="0.0" ref="0" axis="4.566e-07 0.07071 -0.9975" type="hinge" />
          <joint name="walker_knee_l_rotation2" range="-0.001678 0.03354" limited="true" user="-1.4732523263838448e-08" ref="0" axis="-0.9922 -0.124 -0.008789" type="hinge" />
          <joint name="walker_knee_l_rotation3" range="-0.2628 0" limited="true" user="-1.0893911855935912e-08" ref="0" axis="-0.1243 0.9898 0.07016" type="hinge" />
          <body name="talus_l" pos="-0.01017 -0.4078 0" euler="-0 0 0">
            <inertial mass="0.25" pos="0.0000000000 0.0000000000 0.0000000000" fullinertia="0.01 0.01 0.01 0.0 0.0 0.0" />
            <geom name="talus_l_geom_1" type="mesh" mesh="talus_l_geom_1_l_talus" rgba="1 1 1 0" group="0" />
            <joint name="ankle_angle_l" range="-0.6981 0.5236" limited="true" user="0.0" ref="0" type="hinge" axis="0.105 0.174 0.9791" />
            <body name="calcn_l" pos="-0.05925 -0.0522 -0.009647" euler="-0 0 0">
              <inertial mass="1.0377225449" pos="0.1000000000 0.0300000000 0.0000000000" fullinertia="0.01 0.01 0.01 0.0 0.0 0.0" />
              <geom name="calcn_l_geom_1" type="mesh" mesh="calcn_l_geom_1_l_foot" rgba="1 1 1 1" group="0" />
              <joint name="subtalar_angle_l" range="-0.3491 0.3491" limited="true" user="0.0" ref="0" type="hinge" axis="-0.7872 -0.6047 -0.1209" />
              <body name="toes_l" pos="0.1767 -0.001978 -0.001091" euler="-0 0 0">
                <inertial mass="0.25" pos="0.0346000000 0.0060000000 0.0175000000" fullinertia="0.01 0.01 0.01 0.0 0.0 0.0" />
                <geom name="toes_l_geom_1" type="mesh" mesh="toes_l_geom_1_l_bofoot" rgba="1 1 1 1" group="0" />
                <joint name="mtp_angle_l" range="-0.5236 0.5236" limited="true" user="0.0" ref="0" type="hinge" axis="-0.581 2.16e-06 -0.8139" />
                <site name="edl_l_edl_l-P5" pos="0.00032068305785999999 0.0050222131045900001 -0.016352987153939999" />
                <site name="edl_l_edl_l-P6" pos="0.047354198210659997 -0.00042742239187999997 -0.026720567245" />
                <site name="ehl_l_ehl_l-P7" pos="0.031854517080760002 0.0043810795167700005 0.026186155900100001" />
                <site name="ehl_l_ehl_l-P8" pos="0.060181520525060005 0.0036330903309799998 0.019880102030279997" />
                <site name="fdl_l_fdl_l-P6" pos="-0.0020309926997800001 -0.0083347366416599983 -0.015711693540059999" />
                <site name="fdl_l_fdl_l-P7" pos="0.030464890496700002 -0.0075867474558700002 -0.022979687830699997" />
                <site name="fdl_l_fdl_l-P8" pos="0.047140409505419999 -0.0064113358781999995 -0.025865509093159999" />
                <site name="fhl_l_fhl_l-P6" pos="0.016568624656100001 -0.0068387582700799995 0.028323801279699998" />
                <site name="fhl_l_fhl_l-P7" pos="0.060074626172439999 -0.01089927099294 0.019345690685380001" />
              </body>
              <site name="edl_l_edl_l-P3" pos="0.090811035737990001 0.03561078132 -0.00080810862752000014" />
              <site name="edl_l_edl_l-P4" pos="0.15968512921936001 0.0054405360349999996 -0.013131765197199999" />
              <site name="ehl_l_ehl_l-P4" pos="0.095850603553700009 0.038479427593 0.021313865050840004" />
              <site name="ehl_l_ehl_l-P5" pos="0.12776786638653001 0.030565920633000003 0.025960489659080002" />
              <site name="ehl_l_ehl_l-P6" pos="0.17134530573414 0.013749718342999999 0.028283801963200003" />
              <site name="fdl_l_fdl_l-P3" pos="0.04308336407156 0.031159433655000002 0.028283801963200003" />
              <site name="fdl_l_fdl_l-P4" pos="0.06996105908868 0.017409715312000001 0.026566571129720003" />
              <site name="fdl_l_fdl_l-P5" pos="0.16383536153818001 -0.0080124257969999991 -0.011717575099039999" />
              <site name="fhl_l_fhl_l-P3" pos="0.036956830648540002 0.027301599012000001 0.024344272404040003" />
              <site name="fhl_l_fhl_l-P4" pos="0.10257002730798001 0.0067264809159999998 0.025859476080640004" />
              <site name="fhl_l_fhl_l-P5" pos="0.17055478529246001 -0.0052426983610000004 0.027172652600360003" />
              <site name="gaslat_l_gaslat_l-P2" pos="0.0043478624292400004 0.03066483947 0.0053537196573200004" />
              <site name="gasmed_l_gasmed_l-P2" pos="0.0043478624292400004 0.03066483947 0.0053537196573200004" />
              <site name="perbrev_l_perbrev_l-P4" pos="0.046541891003910006 0.026708085990000002 -0.023536163776520003" />
              <site name="perbrev_l_perbrev_l-P5" pos="0.066897792377170001 0.021663225303000001 -0.034647657404919999" />
              <site name="perlong_l_perlong_l-P4" pos="0.043280994181979997 0.02275133251 -0.022324000835240002" />
              <site name="perlong_l_perlong_l-P5" pos="0.067293052598009995 0.010485396722000001 -0.028687856276960005" />
              <site name="perlong_l_perlong_l-P6" pos="0.084190427038920004 0.0068253997530000002 -0.01191960225592" />
              <site name="perlong_l_perlong_l-P7" pos="0.11887451141763 0.008408101145000001 0.018586498432960001" />
              <site name="soleus_l_soleus_l-P2" pos="0.0043478624292400004 0.03066483947 0.0053537196573200004" />
              <site name="tibant_l_tibant_l-P4" pos="0.11521835437486 0.017607552985999999 0.0308091414242" />
              <site name="tibpost_l_tibpost_l-P3" pos="0.041205878022570003 0.033038891558000001 0.028889883433840004" />
              <site name="tibpost_l_tibpost_l-P4" pos="0.076285222622120008 0.015728095083 0.028384815541640001" />
              <site name="L1MT_marker" group="4" pos="0.1868 0.02547 0.02716" rgba="1 0.1 0.5 0.5" size="0.01" />
              <site name="L5MT_marker" group="4" pos="0.1491 0.01497 -0.06863" rgba="1 0.1 0.5 0.5" size="0.01" />
              <site name="LCAL_marker" group="4" pos="-0.01915 0.01795 0.001153" rgba="1 0.1 0.5 0.5" size="0.01" />
            </body>
          </body>
          <site name="bflh_l_bflh_l-P2" pos="-0.034267238036039996 -0.035682418341500002 -0.025386930913849998" />
          <site name="bflh_l_bflh_l-P3" pos="-0.029183078090039997 -0.046387143843949999 -0.030404110936349999" />
          <site name="bfsh_l_bfsh_l-P2" pos="-0.030606642874919997 -0.04271695224311 -0.031909264943100001" />
          <site name="edl_l_edl_l-P1" pos="-0.016269311827200001 -0.11795588006032999 -0.020570438092249999" />
          <site name="edl_l_edl_l-P2" pos="0.016676044622880002 -0.38333112275440001 -0.0112384832504" />
          <site name="ehl_l_ehl_l-P1" pos="-0.0142356478488 -0.15802213836949999 -0.01896494048505" />
          <site name="ehl_l_ehl_l-P2" pos="0.0072195071233200001 -0.29657187130120999 -0.016456350473800001" />
          <site name="ehl_l_ehl_l-P3" pos="0.020336639784 -0.37650048838617001 0.0028096208126" />
          <site name="fdl_l_fdl_l-P1" pos="-0.00233871357516 -0.18677197257608 0.0018061848080999999" />
          <site name="fdl_l_fdl_l-P2" pos="-0.017896243009920001 -0.37160689958505 0.012442606455799999" />
          <site name="fhl_l_fhl_l-P1" pos="-0.0315217916652 -0.22051734535046999 -0.020068720089999999" />
          <site name="fhl_l_fhl_l-P2" pos="-0.024607334138639997 -0.37425759351898996 0.0076261136341999993" />
          <site name="grac_l_grac_l-P2" pos="-0.018730045241063999 -0.048477114061094999 0.029711740093244999" />
          <site name="grac_l_grac_l-P3" pos="0.0018099609407759999 -0.070977427569578005 0.015784048350785" />
          <site name="GR_at_condyles_l_cylinder_grac_l_1_sidesite" pos="-0.01559 -0.003714 0.0327" size="0.0005" />
          <site name="perbrev_l_perbrev_l-P1" pos="-0.024709017337559997 -0.25813680925908 -0.025186243712949998" />
          <site name="perbrev_l_perbrev_l-P2" pos="-0.034470604433879996 -0.39689044172416998 -0.024985556512049995" />
          <site name="perbrev_l_perbrev_l-P3" pos="-0.0289797116922 -0.40820686582675997 -0.025587618114749997" />
          <site name="perlong_l_perlong_l-P1" pos="-0.020336639784 -0.13997702966537001 -0.028296895326899996" />
          <site name="perlong_l_perlong_l-P2" pos="-0.032233574057639998 -0.39760409009100001 -0.023781433306649998" />
          <site name="perlong_l_perlong_l-P3" pos="-0.027657830106239997 -0.40922636349365998 -0.024082464107999999" />
          <site name="recfem_l_recfem_l-P5" pos="0.033148722847919997 -0.064350692734727988 0.00047161492211499995" />
          <site name="sart_l_sart_l-P3" pos="-0.025522482928919999 -0.040881856442689997 0.036625414164249998" />
          <site name="sart_l_sart_l-P4" pos="-0.016167628628280001 -0.061067910247310002 0.026490710518799997" />
          <site name="sart_l_sart_l-P5" pos="0.013828915053119999 -0.082579311018899995 0.0026089336116999996" />
          <site name="semimem_l_semimem_l-P2" pos="-0.029488127686800002 -0.04251305270973 0.019667345688199996" />
          <site name="SM_at_condyles_l_cylinder_semimem_l_1_sidesite" pos="-0.02949 -0.04251 0.01967" size="0.0005" />
          <site name="semiten_l_semiten_l-P2" pos="-0.03172515806304 -0.051790481478520001 0.02297868450305" />
          <site name="semiten_l_semiten_l-P3" pos="0.0019319807794799999 -0.078807169651369996 0.011740201252649999" />
          <site name="ST_at_condyles_l_cylinder_semiten_l_1_sidesite" pos="-0.03538 -0.005408 0.02464" size="0.0005" />
          <site name="soleus_l_soleus_l-P1" pos="-0.0077279231179199995 -0.093385986288039999 -0.0098336728440999981" />
          <site name="tfl_l_tfl_l-P4" pos="0.01098178548336 -0.041799404342899998 -0.034718885755699994" />
          <site name="tibant_l_tibant_l-P1" pos="0.01565921263368 -0.13375809389728002 -0.016255663272899998" />
          <site name="tibant_l_tibant_l-P2" pos="0.025522482928919999 -0.19431625531114 -0.012843980857599999" />
          <site name="tibant_l_tibant_l-P3" pos="0.023692185348360002 -0.37303419631870999 0.013245355259399998" />
          <site name="tibpost_l_tibpost_l-P1" pos="-0.0041690111557200005 -0.13294249576375999 -0.010335390846349999" />
          <site name="tibpost_l_tibpost_l-P2" pos="-0.016676044622880002 -0.37262639725195001 0.01756013007875" />
          <site name="vasint_l_vasint_l-P5" pos="0.033118217888243998 -0.064432252548080007 -0.00043147748193499998" />
          <site name="vaslat_l_vaslat_l-P5" pos="0.033087712928567999 -0.064615762128122006 -0.0051275579829949992" />
          <site name="vasmed_l_vasmed_l-P5" pos="0.032436940455479998 -0.064809466684833006 0.0068032961105099991" />
          <site name="LLM_marker" group="4" pos="-0.006831 -0.4162 -0.05789" rgba="1 0.1 0.5 0.5" size="0.01" />
          <site name="LMM_marker" group="4" pos="0.004555 -0.4023 0.04746" rgba="1 0.1 0.5 0.5" size="0.01" />
          <site name="LS1_marker" group="4" pos="0.02385 -0.2302 0.01213" rgba="1 0.1 0.5 0.5" size="0.01" />
          <site name="LS2_marker" group="4" pos="0.01237 -0.1828 -0.05935" rgba="1 0.1 0.5 0.5" size="0.01" />
          <site name="LS3_marker" group="4" pos="0.03227 -0.1379 0.003768" rgba="1 0.1 0.5 0.5" size="0.01" />
        </body>
        <body name="patella_l" pos="-0.008368 -0.4131 0.00286" euler="-0 0 0">
          <inertial mass="0.25" pos="0.0018 0.0264 0" fullinertia="0.01 0.01 0.01 0.0 0.0 0.0" />
          <geom name="patella_l_geom_1" type="mesh" mesh="patella_l_geom_1_l_patella" rgba="1 1 1 1" group="0" />
          <joint name="patellofemoral_l_translation1" range="-0.02348 0.0542" limited="true" user="0.05422017724182766" ref="0" axis="1 0 0" type="slide" />
          <joint name="patellofemoral_l_translation2" range="-0.04131 -0.01094" limited="true" user="-0.010963680818873674" ref="0" axis="0 1 0" type="slide" />
          <joint name="patellofemoral_l_translation3" limited="false" ref="0" axis="0 0 1" type="slide" />
          <joint name="patellofemoral_l_rotation1" range="-1.786 0.001137" limited="true" user="0.01050598499723554" ref="0" axis="0 0 1" type="hinge" />
          <site name="recfem_l_recfem_l-P2" pos="0.01 0.049000000000000002 -0.00069999999999999999" />
          <site name="recfem_l_recfem_l-P3" pos="0.0121 0.043700000000000003 0.001" />
          <site name="recfem_l_recfem_l-P4" pos="0.0050000000000000001 0.00247 -3.0000000000000001e-05" />
          <site name="vasint_l_vasint_l-P3" pos="0.0057999999999999996 0.048000000000000001 0.00059999999999999995" />
          <site name="vasint_l_vasint_l-P4" pos="0.0050000000000000001 0.00247 0.00038999999999999999" />
          <site name="vaslat_l_vaslat_l-P3" pos="0.0103 0.042299999999999997 -0.0141" />
          <site name="vaslat_l_vaslat_l-P4" pos="0.0050000000000000001 0.00247 -0.0073299999999999997" />
          <site name="vasmed_l_vasmed_l-P3" pos="0.0063 0.044499999999999998 0.017000000000000001" />
          <site name="vasmed_l_vasmed_l-P4" pos="0.0050000000000000001 0.00247 0.0085000000000000006" />
        </body>
        <site name="addbrev_l_addbrev_l-P2" pos="-0.0020687131928000002 -0.11947718189079999 -0.025897732327859996" />
        <site name="AB_at_femshaft_l_cylinder_addbrev_l_1_sidesite" pos="0.001294 -0.1075 -0.01461" size="0.0005" />
        <site name="addlong_l_addlong_l-P2" pos="0.011646855275464 -0.242366551094922 -0.016464301315261998" />
        <site name="AL_at_femshaft_l_cylinder_addlong_l_1_sidesite" pos="0.01165 -0.2424 -0.01646" size="0.0005" />
        <site name="addmagDist_l_addmagDist_l-P2" pos="0.011636511709500001 -0.26578610378250001 -0.020073342728019999" />
        <site name="AMdist_at_femshaft_l_cylinder_addmagDist_l_1_sidesite" pos="0.01164 -0.2658 -0.02007" size="0.0005" />
        <site name="addmagIsch_l_addmagIsch_l-P2" pos="0.0049752552286840002 -0.39282679879808197 0.034041477071921997" />
        <site name="AMisch_at_condyles_l_cylinder_addmagIsch_l_1_sidesite" pos="0.004975 -0.3928 0.03404" size="0.0005" />
        <site name="addmagMid_l_addmagMid_l-P2" pos="0.002503142963288 -0.16443300287343998 -0.030390832876307998" />
        <site name="AMmid_at_femshaft_l_cylinder_addmagMid_l_1_sidesite" pos="0.002503 -0.1644 -0.03039" size="0.0005" />
        <site name="addmagProx_l_addmagProx_l-P2" pos="-0.015794625227028004 -0.079847208168716002 -0.033303027676227996" />
        <site name="AMprox_at_femshaft_l_cylinder_addmagProx_l_1_sidesite" pos="-0.01666 -0.0747 -0.02027" size="0.0005" />
        <site name="bfsh_l_bfsh_l-P1" pos="0.005171782982000001 -0.21374265336566001 -0.024337627970759997" />
        <site name="gaslat_l_gaslat_l-P1" pos="-0.0031030697892000005 -0.38617455231483999 -0.028809927127779997" />
        <site name="Gastroc_at_condyles_l_cylinder_gaslat_l_1_sidesite" pos="-0.01 -0.4365 -0.02593" size="0.0005" />
        <site name="gasmed_l_gasmed_l-P1" pos="0.0082748527712000006 -0.38354200423928003 0.021633447085119998" />
        <site name="Gastroc_at_condyles_l_cylinder_gasmed_l_1_sidesite" pos="0.0001094 -0.4341 0.0189" size="0.0005" />
        <site name="glmax1_l_glmax1_l-P3" pos="-0.04592543288016001 -0.03300810279356 -0.031410101056279997" />
        <site name="glmax1_l_glmax1_l-P4" pos="-0.028651677720280003 -0.057308546567959993 -0.048883269855799993" />
        <site name="glmax2_l_glmax2_l-P3" pos="-0.046546046838000003 -0.059131079851039998 -0.026209753199279998" />
        <site name="glmax2_l_glmax2_l-P4" pos="-0.01613596290384 -0.10287187864495999 -0.043578915041659998" />
        <site name="glmax3_l_glmax3_l-P3" pos="-0.029065420358840004 -0.1139083301925 -0.0097766539711599994" />
        <site name="glmax3_l_glmax3_l-P4" pos="-0.0062061395784000009 -0.14367637381613999 -0.042746859384539995" />
        <site name="glmed1_l_glmed1_l-P2" pos="-0.014480992349600002 -0.018225332830799999 -0.061364104712599989" />
        <site name="glmed2_l_glmed2_l-P2" pos="-0.022755845120800002 -0.010125184906 -0.058243895998399998" />
        <site name="glmed3_l_glmed3_l-P2" pos="-0.031961618828760002 -0.0047588369058200004 -0.053875603798519994" />
        <site name="glmin1_l_glmin1_l-P2" pos="0.005171782982000001 -0.015187777358999999 -0.058243895998399998" />
        <site name="glmin2_l_glmin2_l-P2" pos="0.0041374263856000003 -0.0091126664153999993 -0.054083617712799993" />
        <site name="glmin3_l_glmin3_l-P2" pos="-0.0041374263856000003 -0.0010125184906000001 -0.053043548141399992" />
        <site name="iliacus_l_iliacus_l-P3" pos="-0.0023790201717200001 -0.057207294718900001 -0.014456967042459998" />
        <site name="iliacus_l_iliacus_l-P4" pos="-0.012619150476080003 -0.064497427851220007 -0.020385363599439998" />
        <site name="piri_l_piri_l-P3" pos="-0.015308477626720001 -0.0036450665661599997 -0.045451040270180001" />
        <site name="psoas_l_psoas_l-P3" pos="-0.013653507072480002 -0.04728461351102 -0.0047843200284399994" />
        <site name="psoas_l_psoas_l-P4" pos="-0.024307380015400004 -0.05305596890744 -0.0091526122283199993" />
        <site name="KnExt_at_fem_l_cylinder_recfem_l_3_sidesite" pos="-0.01645 -0.4022 0.01423" size="0.0005" />
        <site name="sart_l_sart_l-P2" pos="-0.0031030697892000005 -0.36126659744608003 0.043786928955939997" />
        <site name="tfl_l_tfl_l-P2" pos="0.030410083934160004 -0.1007455898147 -0.062092153412579995" />
        <site name="tfl_l_tfl_l-P3" pos="0.011067615581480001 -0.41006998869300004 -0.033698254113359992" />
        <site name="vasint_l_vasint_l-P1" pos="0.029996341295600006 -0.19480855759143997 -0.0322421567134" />
        <site name="vasint_l_vasint_l-P2" pos="0.034650945979400008 -0.21100885344104001 -0.029641982784899996" />
        <site name="KnExt_at_fem_l_cylinder_vasint_l_3_sidesite" pos="-0.01663 -0.4013 0.01368" size="0.0005" />
        <site name="vaslat_l_vaslat_l-P1" pos="0.0049649116627200002 -0.18772092815724001 -0.036298428041859995" />
        <site name="vaslat_l_vaslat_l-P2" pos="0.027824192443160003 -0.26234354091445999 -0.042538845470259996" />
        <site name="KnExt_at_fem_l_cylinder_vaslat_l_3_sidesite" pos="-0.01978 -0.402 -0.0132" size="0.0005" />
        <site name="KnExt_at_fem_l_cylinder_vaslat_l_2_sidesite" pos="0.001932 -0.3708 -0.01124" size="0.0005" />
        <site name="vasmed_l_vasmed_l-P1" pos="0.014480992349600002 -0.21252763117694001 -0.019553307942319999" />
        <site name="vasmed_l_vasmed_l-P2" pos="0.03682309483184 -0.28036637004713999 -0.00093606261425999984" />
        <site name="KnExt_at_fem_l_cylinder_vasmed_l_4_sidesite" pos="-0.008406 -0.4126 0.02099" size="0.0005" />
        <site name="KnExt_at_fem_l_cylinder_vasmed_l_3_sidesite" pos="-0.008406 -0.4126 0.02099" size="0.0005" />
        <site name="LLFE_marker" group="4" pos="-0.0004603 -0.4103 -0.06565" rgba="1 0.1 0.5 0.5" size="0.01" />
        <site name="LMFE_marker" group="4" pos="-0.002628 -0.4098 0.05941" rgba="1 0.1 0.5 0.5" size="0.01" />
        <site name="LT1_marker" group="4" pos="0.04992 -0.321 -0.05823" rgba="1 0.1 0.5 0.5" size="0.01" />
        <site name="LT2_marker" group="4" pos="0.1046 -0.2519 0.001502" rgba="1 0.1 0.5 0.5" size="0.01" />
        <site name="LT3_marker" group="4" pos="0.06242 -0.1936 -0.07252" rgba="1 0.1 0.5 0.5" size="0.01" />
        <site name="LTRC_marker" group="4" pos="-0.01897 -0.02014 -0.09366" rgba="1 0.1 0.5 0.5" size="0.01" />
      </body>
      <body name="torso" pos="-0.1057 0.08835 0" euler="-0 0 0">
        <inertial mass="28.4224733452" pos="-0.0300000000 0.3200000000 0.0000000000" fullinertia="1.2240975140 0.6271995062 1.1883168406 0.0000000000 0.0000000000 0.0000000000" />
        <geom name="torso_geom_1" type="mesh" mesh="torso_geom_1_hat_spine" rgba="1 1 1 1" group="0" />
        <geom name="torso_geom_2" type="mesh" mesh="torso_geom_2_hat_jaw" rgba="1 1 1 1" group="0" />
        <geom name="torso_geom_3" type="mesh" mesh="torso_geom_3_hat_skull" rgba="1 1 1 1" group="0" />
        <geom name="torso_geom_4" type="mesh" mesh="torso_geom_4_hat_ribs_scap" rgba="1 1 1 1" group="0" />
        <joint name="lumbar_extension" range="-1.571 1.571" limited="true" user="0.0" ref="0" axis="0 0 1" type="hinge" />
        <joint name="lumbar_bending" range="-1.571 1.571" limited="true" user="0.0" ref="0" axis="1 0 0" type="hinge" />
        <joint name="lumbar_rotation" range="-1.571 1.571" limited="true" user="0.0" ref="0" axis="0 1 0" type="hinge" />
        <site name="C7_marker" group="4" pos="-0.09112 0.3506 -0.0003719" rgba="1 0.1 0.5 0.5" size="0.01" />
        <site name="CLAV_marker" group="4" pos="0.07143 0.3339 0.0004936" rgba="1 0.1 0.5 0.5" size="0.01" />
        <site name="LACR_marker" group="4" pos="0.00108 0.3576 -0.1438" rgba="1 0.1 0.5 0.5" size="0.01" />
        <site name="RACR_marker" group="4" pos="0.0008042 0.3573 0.1431" rgba="1 0.1 0.5 0.5" size="0.01" />
      </body>
      <site name="addbrev_r_addbrev_r-P1" pos="-0.02004216174018 -0.10190536551139999 0.0169535677542" />
      <site name="addlong_r_addlong_r-P1" pos="-0.0079539050256840008 -0.09637645738259 0.020784633714240001" />
      <site name="addmagDist_r_addmagDist_r-P1" pos="-0.077692233258792001 -0.13840700015787699 0.043837082335859999" />
      <site name="addmagIsch_r_addmagIsch_r-P1" pos="-0.094040761002876019 -0.14067276839105597 0.045917747469329993" />
      <site name="addmagMid_r_addmagMid_r-P1" pos="-0.055257604043868001 -0.13090503069682499 0.031419144396419997" />
      <site name="addmagProx_r_addmagProx_r-P1" pos="-0.032508176477004005 -0.116594915539905 0.015027025963949999" />
      <site name="bflh_r_bflh_r-P1" pos="-0.10913009533920001 -0.12911626630220999 0.064511627947799993" />
      <site name="glmax1_r_glmax1_r-P1" pos="-0.12917225707938002 0.037401437341949999 0.0619796015949" />
      <site name="glmax1_r_glmax1_r-P2" pos="-0.13190050946286003 -0.026235211121019997 0.085758631691699991" />
      <site name="Gmax1_at_pelvis_r_cylinder_glmax1_r_2_sidesite" pos="-0.111 -0.09768 0.1096" size="0.0005" />
      <site name="glmax2_r_glmax2_r-P1" pos="-0.13819647650166003 0.0094316668079699982 0.050860703262599991" />
      <site name="glmax2_r_glmax2_r-P2" pos="-0.14102966166912001 -0.066021667655789998 0.089501627169899983" />
      <site name="Gmax2_at_pelvis_r_cylinder_glmax2_r_2_sidesite" pos="-0.1253 -0.1008 0.09917" size="0.0005" />
      <site name="Gmax2_at_pelvis_r_cylinder_glmax2_r_1_sidesite" pos="-0.141 -0.06602 0.0895" size="0.0005" />
      <site name="glmax3_r_glmax3_r-P1" pos="-0.13641261917400002 -0.05691523073774999 0.0099079292069999981" />
      <site name="glmax3_r_glmax3_r-P2" pos="-0.13357943400654002 -0.13692178366052998 0.047888324500499992" />
      <site name="Gmax3_at_pelvis_r_cylinder_glmax3_r_1_sidesite" pos="-0.1342 -0.1191 0.03945" size="0.0005" />
      <site name="glmed1_r_glmed1_r-P1" pos="-0.051561248069559647 0.028352735152808266 0.12691878436331083" />
      <site name="glmed2_r_glmed2_r-P1" pos="-0.088906741375412934 0.059228609350698319 0.090254101925782107" />
      <site name="glmed3_r_glmed3_r-P1" pos="-0.10479196317245228 0.016867927584452831 0.070348090334152319" />
      <site name="glmin1_r_glmin1_r-P1" pos="-0.031038629239144501 -0.00011731762817636161 0.13040432011551958" />
      <site name="glmin2_r_glmin2_r-P1" pos="-0.06463859333053279 0.010841285269473781 0.11134897574409684" />
      <site name="glmin3_r_glmin3_r-P1" pos="-0.082791966560220004 -0.016803544313049999 0.087850305635399986" />
      <site name="grac_r_grac_r-P1" pos="-0.049696166492928004 -0.14019576455249197 0.027037637924879995" />
      <site name="iliacus_r_iliacus_r-P1" pos="-0.063484334307900001 0.03349867866279 0.092804270238899991" />
      <site name="iliacus_r_iliacus_r-P2" pos="-0.014165925837300001 -0.060384349563669996 0.083226605338799997" />
      <site name="IL_at_brim_r_cylinder_iliacus_r_2_sidesite" pos="-0.02546 -0.1033 0.09225" size="0.0005" />
      <site name="piri_r_piri_r-P1" pos="-0.106832067370038 -0.0070791706041429996 0.014872902620729997" />
      <site name="piri_r_piri_r-P2" pos="-0.107052426216396 -0.033238494750845997 0.067065671921160003" />
      <site name="psoas_r_psoas_r-P1" pos="-0.063589267091880008 0.067214177252199997 0.042934359896999993" />
      <site name="psoas_r_psoas_r-P2" pos="-0.021511220715900004 -0.070900116004739999 0.072217795108799998" />
      <site name="PS_at_brim_r_cylinder_psoas_r_2_sidesite" pos="-0.03285 -0.09525 0.07895" size="0.0005" />
      <site name="recfem_r_recfem_r-P1" pos="-0.025183868155200004 -0.042063065764279997 0.10271219944589999" />
      <site name="sart_r_sart_r-P1" pos="-0.0204618928761 -0.016911954276359997 0.11625303602879999" />
      <site name="semimem_r_semimem_r-P1" pos="-0.10356865778826001 -0.1235873581734 0.067594094812199995" />
      <site name="semiten_r_semiten_r-P1" pos="-0.10892022977124001 -0.13583768402742999 0.056695372684499992" />
      <site name="tfl_r_tfl_r-P1" pos="-0.021343103443684813 0.01176394062132273 0.14234121453490639" />
      <site name="addbrev_l_addbrev_l-P1" pos="-0.02004216174018 -0.10190536551139999 -0.0169535677542" />
      <site name="addlong_l_addlong_l-P1" pos="-0.0079539050256840008 -0.09637645738259 -0.020784633714240001" />
      <site name="addmagDist_l_addmagDist_l-P1" pos="-0.077692233258792001 -0.13840700015787699 -0.043837082335859999" />
      <site name="addmagIsch_l_addmagIsch_l-P1" pos="-0.094040761002876019 -0.14067276839105597 -0.045917747469329993" />
      <site name="addmagMid_l_addmagMid_l-P1" pos="-0.055257604043868001 -0.13090503069682499 -0.031419144396419997" />
      <site name="addmagProx_l_addmagProx_l-P1" pos="-0.032508176477004005 -0.116594915539905 -0.015027025963949999" />
      <site name="bflh_l_bflh_l-P1" pos="-0.10913009533920001 -0.12911626630220999 -0.064511627947799993" />
      <site name="glmax1_l_glmax1_l-P1" pos="-0.12917225707938002 0.037401437341949999 -0.0619796015949" />
      <site name="glmax1_l_glmax1_l-P2" pos="-0.13190050946286003 -0.026235211121019997 -0.085758631691699991" />
      <site name="Gmax1_at_pelvis_l_cylinder_glmax1_l_2_sidesite" pos="-0.111 -0.09768 -0.1096" size="0.0005" />
      <site name="glmax2_l_glmax2_l-P1" pos="-0.13819647650166003 0.0094316668079699982 -0.050860703262599991" />
      <site name="glmax2_l_glmax2_l-P2" pos="-0.14102966166912001 -0.066021667655789998 -0.089501627169899983" />
      <site name="Gmax2_at_pelvis_l_cylinder_glmax2_l_2_sidesite" pos="-0.1253 -0.1008 -0.09917" size="0.0005" />
      <site name="Gmax2_at_pelvis_l_cylinder_glmax2_l_1_sidesite" pos="-0.141 -0.06602 -0.0895" size="0.0005" />
      <site name="glmax3_l_glmax3_l-P1" pos="-0.13641261917400002 -0.05691523073774999 -0.0099079292069999981" />
      <site name="glmax3_l_glmax3_l-P2" pos="-0.13357943400654002 -0.13692178366052998 -0.047888324500499992" />
      <site name="Gmax3_at_pelvis_l_cylinder_glmax3_l_1_sidesite" pos="-0.1342 -0.1191 -0.03945" size="0.0005" />
      <site name="glmed1_l_glmed1_l-P1" pos="-0.051417064150200011 0.028186590460599997 -0.12660131764499999" />
      <site name="glmed2_l_glmed2_l-P1" pos="-0.089192866383000016 0.059625479820499996 -0.090272243885999998" />
      <site name="glmed3_l_glmed3_l-P1" pos="-0.10493278398000001 0.0173455941296 -0.070456385471999991" />
      <site name="glmin1_l_glmin1_l-P1" pos="-0.031479835194000001 0 -0.12990396071399998" />
      <site name="glmin2_l_glmin2_l-P1" pos="-0.064638594931680005 0.010840996330999999 -0.11118898332299999" />
      <site name="glmin3_l_glmin3_l-P1" pos="-0.082791966560220004 -0.016803544313049999 -0.087850305635399986" />
      <site name="grac_l_grac_l-P1" pos="-0.049696166492928004 -0.14019576455249197 -0.027037637924879995" />
      <site name="iliacus_l_iliacus_l-P1" pos="-0.063484334307900001 0.03349867866279 -0.092804270238899991" />
      <site name="iliacus_l_iliacus_l-P2" pos="-0.014165925837300001 -0.060384349563669996 -0.083226605338799997" />
      <site name="IL_at_brim_l_cylinder_iliacus_l_2_sidesite" pos="-0.02546 -0.1033 -0.09225" size="0.0005" />
      <site name="piri_l_piri_l-P1" pos="-0.106832067370038 -0.0070791706041429996 -0.014872902620729997" />
      <site name="piri_l_piri_l-P2" pos="-0.107052426216396 -0.033238494750845997 -0.067065671921160003" />
      <site name="psoas_l_psoas_l-P1" pos="-0.063589267091880008 0.067214177252199997 -0.042934359896999993" />
      <site name="psoas_l_psoas_l-P2" pos="-0.021511220715900004 -0.070900116004739999 -0.072217795108799998" />
      <site name="PS_at_brim_l_cylinder_psoas_l_2_sidesite" pos="-0.03285 -0.09525 -0.07895" size="0.0005" />
      <site name="recfem_l_recfem_l-P1" pos="-0.025183868155200004 -0.042063065764279997 -0.10271219944589999" />
      <site name="sart_l_sart_l-P1" pos="-0.0204618928761 -0.016911954276359997 -0.11625303602879999" />
      <site name="semimem_l_semimem_l-P1" pos="-0.10356865778826001 -0.1235873581734 -0.067594094812199995" />
      <site name="semiten_l_semiten_l-P1" pos="-0.10892022977124001 -0.13583768402742999 -0.056695372684499992" />
      <site name="tfl_l_tfl_l-P1" pos="-0.020986556796000002 0.011925095964099998 -0.142013651967" />
      <site name="LASI_marker" group="4" pos="0.02952 0.008112 -0.137" rgba="1 0.1 0.5 0.5" size="0.01" />
      <site name="RASI_marker" group="4" pos="0.02993 0.01106 0.1385" rgba="1 0.1 0.5 0.5" size="0.01" />
      <site name="SACR_marker" group="4" pos="-0.1984 0.02538 0.002499" rgba="1 0.1 0.5 0.5" size="0.01" />
    </body>
  </worldbody>
  <asset>
    <texture type="skybox" builtin="gradient" rgb1="1 1 1" rgb2="0.6 0.8 1" width="256" height="256" />
    <mesh name="pelvis_geom_1_r_pelvis" file="Geometry/r_pelvis.stl" scale="1.0493278398000001 1.0840996330999999 1.1008810229999999" />
    <mesh name="pelvis_geom_2_l_pelvis" file="Geometry/l_pelvis.stl" scale="1.0493278398000001 1.0840996330999999 1.1008810229999999" />
    <mesh name="pelvis_geom_3_sacrum" file="Geometry/sacrum.stl" scale="1.0493278398000001 1.0840996330999999 1.1008810229999999" />
    <mesh name="femur_r_geom_1_r_femur" file="Geometry/r_femur.stl" scale="1.0343565964000001 1.0125184906 1.0400695713999999" />
    <mesh name="tibia_r_geom_1_r_tibia" file="Geometry/r_tibia.stl" scale="1.0168319892 1.0194976669 1.0034360044999999" />
    <mesh name="tibia_r_geom_2_r_fibula" file="Geometry/r_fibula.stl" scale="1.0168319892 1.0194976669 1.0034360044999999" />
    <mesh name="talus_r_geom_1_r_talus" file="Geometry/r_talus.stl" scale="1.2148044275000001 1.2443829403 1.2180436447" />
    <mesh name="calcn_r_geom_1_r_foot" file="Geometry/r_foot.stl" scale="0.98815055210000002 0.98918837000000004 1.0101357844000001" />
    <mesh name="toes_r_geom_1_r_bofoot" file="Geometry/r_bofoot.stl" scale="1.0689435262 1.0685559796999999 1.0688226897999999" />
    <mesh name="patella_r_geom_1_r_patella" file="Geometry/r_patella.stl" scale="1 1 1" />
    <mesh name="femur_l_geom_1_l_femur" file="Geometry/l_femur.stl" scale="1.0343565964000001 1.0125184906 1.0400695713999999" />
    <mesh name="tibia_l_geom_1_l_tibia" file="Geometry/l_tibia.stl" scale="1.0168319892 1.0194976669 1.0034360044999999" />
    <mesh name="tibia_l_geom_2_l_fibula" file="Geometry/l_fibula.stl" scale="1.0168319892 1.0194976669 1.0034360044999999" />
    <mesh name="talus_l_geom_1_l_talus" file="Geometry/l_talus.stl" scale="1.2148044275000001 1.2443829403 1.2180436447" />
    <mesh name="calcn_l_geom_1_l_foot" file="Geometry/l_foot.stl" scale="0.98815055210000002 0.98918837000000004 1.0101357844000001" />
    <mesh name="toes_l_geom_1_l_bofoot" file="Geometry/l_bofoot.stl" scale="1.0689435262 1.0685559796999999 1.0688226897999999" />
    <mesh name="patella_l_geom_1_l_patella" file="Geometry/l_patella.stl" scale="1 1 1" />
    <mesh name="torso_geom_1_hat_spine" file="Geometry/hat_spine.stl" scale="1.1222974038 0.84324961669999998 1.0222998121" />
    <mesh name="torso_geom_2_hat_jaw" file="Geometry/hat_jaw.stl" scale="1.1222974038 0.84324961669999998 1.0222998121" />
    <mesh name="torso_geom_3_hat_skull" file="Geometry/hat_skull.stl" scale="1.1222974038 0.84324961669999998 1.0222998121" />
    <mesh name="torso_geom_4_hat_ribs_scap" file="Geometry/hat_ribs_scap.stl" scale="1.1222974038 0.84324961669999998 1.0222998121" />
  </asset>
  <tendon>
    
    <spatial name="addbrev_r_tendon">
      <site site="addbrev_r_addbrev_r-P1" />
      <geom geom="AB_at_femshaft_r_cylinder" sidesite="AB_at_femshaft_r_cylinder_addbrev_r_1_sidesite" />
      <site site="addbrev_r_addbrev_r-P2" />
    </spatial>
    <spatial name="addlong_r_tendon">
      <site site="addlong_r_addlong_r-P1" />
      <geom geom="AL_at_femshaft_r_cylinder" sidesite="AL_at_femshaft_r_cylinder_addlong_r_1_sidesite" />
      <site site="addlong_r_addlong_r-P2" />
    </spatial>
    <spatial name="addmagDist_r_tendon">
      <site site="addmagDist_r_addmagDist_r-P1" />
      <geom geom="AMdist_at_femshaft_r_cylinder" sidesite="AMdist_at_femshaft_r_cylinder_addmagDist_r_1_sidesite" />
      <site site="addmagDist_r_addmagDist_r-P2" />
    </spatial>
    <spatial name="addmagIsch_r_tendon">
      <site site="addmagIsch_r_addmagIsch_r-P1" />
      <geom geom="AMisch_at_condyles_r_cylinder" sidesite="AMisch_at_condyles_r_cylinder_addmagIsch_r_1_sidesite" />
      <site site="addmagIsch_r_addmagIsch_r-P2" />
    </spatial>
    <spatial name="addmagMid_r_tendon">
      <site site="addmagMid_r_addmagMid_r-P1" />
      <geom geom="AMmid_at_femshaft_r_cylinder" sidesite="AMmid_at_femshaft_r_cylinder_addmagMid_r_1_sidesite" />
      <site site="addmagMid_r_addmagMid_r-P2" />
    </spatial>
    <spatial name="addmagProx_r_tendon">
      <site site="addmagProx_r_addmagProx_r-P1" />
      <geom geom="AMprox_at_femshaft_r_cylinder" sidesite="AMprox_at_femshaft_r_cylinder_addmagProx_r_1_sidesite" />
      <site site="addmagProx_r_addmagProx_r-P2" />
    </spatial>
    <spatial name="bflh_r_tendon">
      <site site="bflh_r_bflh_r-P1" />
      <site site="bflh_r_bflh_r-P2" />
      <site site="bflh_r_bflh_r-P3" />
    </spatial>
    <spatial name="bfsh_r_tendon">
      <site site="bfsh_r_bfsh_r-P1" />
      <site site="bfsh_r_bfsh_r-P2" />
    </spatial>
    <spatial name="edl_r_tendon">
      <site site="edl_r_edl_r-P1" />
      <site site="edl_r_edl_r-P2" />
      <site site="edl_r_edl_r-P3" />
      <site site="edl_r_edl_r-P4" />
      <site site="edl_r_edl_r-P5" />
      <site site="edl_r_edl_r-P6" />
    </spatial>
    <spatial name="ehl_r_tendon">
      <site site="ehl_r_ehl_r-P1" />
      <site site="ehl_r_ehl_r-P2" />
      <site site="ehl_r_ehl_r-P3" />
      <site site="ehl_r_ehl_r-P4" />
      <site site="ehl_r_ehl_r-P5" />
      <site site="ehl_r_ehl_r-P6" />
      <site site="ehl_r_ehl_r-P7" />
      <site site="ehl_r_ehl_r-P8" />
    </spatial>
    <spatial name="fdl_r_tendon">
      <site site="fdl_r_fdl_r-P1" />
      <site site="fdl_r_fdl_r-P2" />
      <site site="fdl_r_fdl_r-P3" />
      <site site="fdl_r_fdl_r-P4" />
      <site site="fdl_r_fdl_r-P5" />
      <site site="fdl_r_fdl_r-P6" />
      <site site="fdl_r_fdl_r-P7" />
      <site site="fdl_r_fdl_r-P8" />
    </spatial>
    <spatial name="fhl_r_tendon">
      <site site="fhl_r_fhl_r-P1" />
      <site site="fhl_r_fhl_r-P2" />
      <site site="fhl_r_fhl_r-P3" />
      <site site="fhl_r_fhl_r-P4" />
      <site site="fhl_r_fhl_r-P5" />
      <site site="fhl_r_fhl_r-P6" />
      <site site="fhl_r_fhl_r-P7" />
    </spatial>
    <spatial name="gaslat_r_tendon">
      <site site="gaslat_r_gaslat_r-P1" />
      <geom geom="Gastroc_at_condyles_r_cylinder" sidesite="Gastroc_at_condyles_r_cylinder_gaslat_r_1_sidesite" />
      <site site="gaslat_r_gaslat_r-P2" />
    </spatial>
    <spatial name="gasmed_r_tendon">
      <site site="gasmed_r_gasmed_r-P1" />
      <geom geom="Gastroc_at_condyles_r_cylinder" sidesite="Gastroc_at_condyles_r_cylinder_gasmed_r_1_sidesite" />
      <site site="gasmed_r_gasmed_r-P2" />
    </spatial>
    <spatial name="glmax1_r_tendon">
      <site site="glmax1_r_glmax1_r-P1" />
      <site site="glmax1_r_glmax1_r-P2" />
      <geom geom="Gmax1_at_pelvis_r_cylinder" sidesite="Gmax1_at_pelvis_r_cylinder_glmax1_r_2_sidesite" />
      <site site="glmax1_r_glmax1_r-P3" />
      <site site="glmax1_r_glmax1_r-P4" />
    </spatial>
    <spatial name="glmax2_r_tendon">
      <site site="glmax2_r_glmax2_r-P1" />
      <geom geom="Gmax2_at_pelvis_r_cylinder" sidesite="Gmax2_at_pelvis_r_cylinder_glmax2_r_1_sidesite" />
      <site site="glmax2_r_glmax2_r-P2" />
      <geom geom="Gmax2_at_pelvis_r_cylinder" sidesite="Gmax2_at_pelvis_r_cylinder_glmax2_r_2_sidesite" />
      <site site="glmax2_r_glmax2_r-P3" />
      <site site="glmax2_r_glmax2_r-P4" />
    </spatial>
    <spatial name="glmax3_r_tendon">
      <site site="glmax3_r_glmax3_r-P1" />
      <geom geom="Gmax3_at_pelvis_r_cylinder" sidesite="Gmax3_at_pelvis_r_cylinder_glmax3_r_1_sidesite" />
      <site site="glmax3_r_glmax3_r-P2" />
      <site site="glmax3_r_glmax3_r-P3" />
      <site site="glmax3_r_glmax3_r-P4" />
    </spatial>
    <spatial name="glmed1_r_tendon">
      <site site="glmed1_r_glmed1_r-P1" />
      <site site="glmed1_r_glmed1_r-P2_0" />
    </spatial>
    <spatial name="glmed2_r_tendon">
      <site site="glmed2_r_glmed2_r-P1" />
      <site site="glmed2_r_glmed2_r-P2_0" />
    </spatial>
    <spatial name="glmed3_r_tendon">
      <site site="glmed3_r_glmed3_r-P1" />
      <site site="glmed3_r_glmed3_r-P2_0" />
    </spatial>
    <spatial name="glmin1_r_tendon">
      <site site="glmin1_r_glmin1_r-P1" />
      <site site="glmin1_r_glmin1_r-P2" />
    </spatial>
    <spatial name="glmin2_r_tendon">
      <site site="glmin2_r_glmin2_r-P1" />
      <site site="glmin2_r_glmin2_r-P2" />
    </spatial>
    <spatial name="glmin3_r_tendon">
      <site site="glmin3_r_glmin3_r-P1" />
      <site site="glmin3_r_glmin3_r-P2" />
    </spatial>
    <spatial name="grac_r_tendon">
      <site site="grac_r_grac_r-P1" />
      <geom geom="GR_at_condyles_r_cylinder" sidesite="GR_at_condyles_r_cylinder_grac_r_1_sidesite" />
      <site site="grac_r_grac_r-P2" />
      <site site="grac_r_grac_r-P3" />
    </spatial>
    <spatial name="iliacus_r_tendon">
      <site site="iliacus_r_iliacus_r-P1" />
      <site site="iliacus_r_iliacus_r-P2" />
      <geom geom="IL_at_brim_r_cylinder" sidesite="IL_at_brim_r_cylinder_iliacus_r_2_sidesite" />
      <site site="iliacus_r_iliacus_r-P3" />
      <site site="iliacus_r_iliacus_r-P4" />
    </spatial>
    <spatial name="perbrev_r_tendon">
      <site site="perbrev_r_perbrev_r-P1" />
      <site site="perbrev_r_perbrev_r-P2" />
      <site site="perbrev_r_perbrev_r-P3" />
      <site site="perbrev_r_perbrev_r-P4" />
      <site site="perbrev_r_perbrev_r-P5" />
    </spatial>
    <spatial name="perlong_r_tendon">
      <site site="perlong_r_perlong_r-P1" />
      <site site="perlong_r_perlong_r-P2" />
      <site site="perlong_r_perlong_r-P3" />
      <site site="perlong_r_perlong_r-P4" />
      <site site="perlong_r_perlong_r-P5" />
      <site site="perlong_r_perlong_r-P6" />
      <site site="perlong_r_perlong_r-P7" />
    </spatial>
    <spatial name="piri_r_tendon">
      <site site="piri_r_piri_r-P1" />
      <site site="piri_r_piri_r-P2" />
      <site site="piri_r_piri_r-P3" />
    </spatial>
    <spatial name="psoas_r_tendon">
      <site site="psoas_r_psoas_r-P1" />
      <site site="psoas_r_psoas_r-P2" />
      <geom geom="PS_at_brim_r_cylinder" sidesite="PS_at_brim_r_cylinder_psoas_r_2_sidesite" />
      <site site="psoas_r_psoas_r-P3" />
      <site site="psoas_r_psoas_r-P4" />
    </spatial>
    <spatial name="recfem_r_tendon">
      <site site="recfem_r_recfem_r-P1" />
      <site site="recfem_r_recfem_r-P2" />
      <site site="recfem_r_recfem_r-P3" />
      <geom geom="KnExt_at_fem_r_cylinder" sidesite="KnExt_at_fem_r_cylinder_recfem_r_3_sidesite" />
      <site site="recfem_r_recfem_r-P4" />
      <site site="recfem_r_recfem_r-P5" />
    </spatial>
    <spatial name="sart_r_tendon">
      <site site="sart_r_sart_r-P1" />
      <site site="sart_r_sart_r-P2" />
      <site site="sart_r_sart_r-P3" />
      <site site="sart_r_sart_r-P4" />
      <site site="sart_r_sart_r-P5" />
    </spatial>
    <spatial name="semimem_r_tendon">
      <site site="semimem_r_semimem_r-P1" />
      <geom geom="SM_at_condyles_r_cylinder" sidesite="SM_at_condyles_r_cylinder_semimem_r_1_sidesite" />
      <site site="semimem_r_semimem_r-P2" />
    </spatial>
    <spatial name="semiten_r_tendon">
      <site site="semiten_r_semiten_r-P1" />
      <geom geom="ST_at_condyles_r_cylinder" sidesite="ST_at_condyles_r_cylinder_semiten_r_1_sidesite" />
      <site site="semiten_r_semiten_r-P2" />
      <site site="semiten_r_semiten_r-P3" />
    </spatial>
    <spatial name="soleus_r_tendon">
      <site site="soleus_r_soleus_r-P1" />
      <site site="soleus_r_soleus_r-P2" />
    </spatial>
    <spatial name="tfl_r_tendon">
      <site site="tfl_r_tfl_r-P1" />
      <site site="tfl_r_tfl_r-P2" />
      <site site="tfl_r_tfl_r-P3" />
      <site site="tfl_r_tfl_r-P4" />
    </spatial>
    <spatial name="tibant_r_tendon">
      <site site="tibant_r_tibant_r-P1" />
      <site site="tibant_r_tibant_r-P2" />
      <site site="tibant_r_tibant_r-P3" />
      <site site="tibant_r_tibant_r-P4" />
    </spatial>
    <spatial name="tibpost_r_tendon">
      <site site="tibpost_r_tibpost_r-P1" />
      <site site="tibpost_r_tibpost_r-P2" />
      <site site="tibpost_r_tibpost_r-P3" />
      <site site="tibpost_r_tibpost_r-P4" />
    </spatial>
    <spatial name="vasint_r_tendon">
      <site site="vasint_r_vasint_r-P1" />
      <site site="vasint_r_vasint_r-P2" />
      <site site="vasint_r_vasint_r-P3" />
      <geom geom="KnExt_at_fem_r_cylinder" sidesite="KnExt_at_fem_r_cylinder_vasint_r_3_sidesite" />
      <site site="vasint_r_vasint_r-P4" />
      <site site="vasint_r_vasint_r-P5" />
    </spatial>
    <spatial name="vaslat_r_tendon">
      <site site="vaslat_r_vaslat_r-P1" />
      <site site="vaslat_r_vaslat_r-P2" />
      <geom geom="KnExt_at_fem_r_cylinder" sidesite="KnExt_at_fem_r_cylinder_vaslat_r_2_sidesite" />
      <site site="vaslat_r_vaslat_r-P3" />
      <geom geom="KnExt_at_fem_r_cylinder" sidesite="KnExt_at_fem_r_cylinder_vaslat_r_3_sidesite" />
      <site site="vaslat_r_vaslat_r-P4" />
      <site site="vaslat_r_vaslat_r-P5" />
    </spatial>
    <spatial name="vasmed_r_tendon">
      <site site="vasmed_r_vasmed_r-P1" />
      <site site="vasmed_r_vasmed_r-P2" />
      <site site="vasmed_r_vasmed_r-P3" />
      <geom geom="KnExt_at_fem_r_cylinder" sidesite="KnExt_at_fem_r_cylinder_vasmed_r_3_sidesite" />
      <site site="vasmed_r_vasmed_r-P4" />
      <geom geom="KnExt_at_fem_r_cylinder" sidesite="KnExt_at_fem_r_cylinder_vasmed_r_4_sidesite" />
      <site site="vasmed_r_vasmed_r-P5" />
    </spatial>
    <spatial name="addbrev_l_tendon">
      <site site="addbrev_l_addbrev_l-P1" />
      <geom geom="AB_at_femshaft_l_cylinder" sidesite="AB_at_femshaft_l_cylinder_addbrev_l_1_sidesite" />
      <site site="addbrev_l_addbrev_l-P2" />
    </spatial>
    <spatial name="addlong_l_tendon">
      <site site="addlong_l_addlong_l-P1" />
      <geom geom="AL_at_femshaft_l_cylinder" sidesite="AL_at_femshaft_l_cylinder_addlong_l_1_sidesite" />
      <site site="addlong_l_addlong_l-P2" />
    </spatial>
    <spatial name="addmagDist_l_tendon">
      <site site="addmagDist_l_addmagDist_l-P1" />
      <geom geom="AMdist_at_femshaft_l_cylinder" sidesite="AMdist_at_femshaft_l_cylinder_addmagDist_l_1_sidesite" />
      <site site="addmagDist_l_addmagDist_l-P2" />
    </spatial>
    <spatial name="addmagIsch_l_tendon">
      <site site="addmagIsch_l_addmagIsch_l-P1" />
      <geom geom="AMisch_at_condyles_l_cylinder" sidesite="AMisch_at_condyles_l_cylinder_addmagIsch_l_1_sidesite" />
      <site site="addmagIsch_l_addmagIsch_l-P2" />
    </spatial>
    <spatial name="addmagMid_l_tendon">
      <site site="addmagMid_l_addmagMid_l-P1" />
      <geom geom="AMmid_at_femshaft_l_cylinder" sidesite="AMmid_at_femshaft_l_cylinder_addmagMid_l_1_sidesite" />
      <site site="addmagMid_l_addmagMid_l-P2" />
    </spatial>
    <spatial name="addmagProx_l_tendon">
      <site site="addmagProx_l_addmagProx_l-P1" />
      <geom geom="AMprox_at_femshaft_l_cylinder" sidesite="AMprox_at_femshaft_l_cylinder_addmagProx_l_1_sidesite" />
      <site site="addmagProx_l_addmagProx_l-P2" />
    </spatial>
    <spatial name="bflh_l_tendon">
      <site site="bflh_l_bflh_l-P1" />
      <site site="bflh_l_bflh_l-P2" />
      <site site="bflh_l_bflh_l-P3" />
    </spatial>
    <spatial name="bfsh_l_tendon">
      <site site="bfsh_l_bfsh_l-P1" />
      <site site="bfsh_l_bfsh_l-P2" />
    </spatial>
    <spatial name="edl_l_tendon">
      <site site="edl_l_edl_l-P1" />
      <site site="edl_l_edl_l-P2" />
      <site site="edl_l_edl_l-P3" />
      <site site="edl_l_edl_l-P4" />
      <site site="edl_l_edl_l-P5" />
      <site site="edl_l_edl_l-P6" />
    </spatial>
    <spatial name="ehl_l_tendon">
      <site site="ehl_l_ehl_l-P1" />
      <site site="ehl_l_ehl_l-P2" />
      <site site="ehl_l_ehl_l-P3" />
      <site site="ehl_l_ehl_l-P4" />
      <site site="ehl_l_ehl_l-P5" />
      <site site="ehl_l_ehl_l-P6" />
      <site site="ehl_l_ehl_l-P7" />
      <site site="ehl_l_ehl_l-P8" />
    </spatial>
    <spatial name="fdl_l_tendon">
      <site site="fdl_l_fdl_l-P1" />
      <site site="fdl_l_fdl_l-P2" />
      <site site="fdl_l_fdl_l-P3" />
      <site site="fdl_l_fdl_l-P4" />
      <site site="fdl_l_fdl_l-P5" />
      <site site="fdl_l_fdl_l-P6" />
      <site site="fdl_l_fdl_l-P7" />
      <site site="fdl_l_fdl_l-P8" />
    </spatial>
    <spatial name="fhl_l_tendon">
      <site site="fhl_l_fhl_l-P1" />
      <site site="fhl_l_fhl_l-P2" />
      <site site="fhl_l_fhl_l-P3" />
      <site site="fhl_l_fhl_l-P4" />
      <site site="fhl_l_fhl_l-P5" />
      <site site="fhl_l_fhl_l-P6" />
      <site site="fhl_l_fhl_l-P7" />
    </spatial>
    <spatial name="gaslat_l_tendon">
      <site site="gaslat_l_gaslat_l-P1" />
      <geom geom="Gastroc_at_condyles_l_cylinder" sidesite="Gastroc_at_condyles_l_cylinder_gaslat_l_1_sidesite" />
      <site site="gaslat_l_gaslat_l-P2" />
    </spatial>
    <spatial name="gasmed_l_tendon">
      <site site="gasmed_l_gasmed_l-P1" />
      <geom geom="Gastroc_at_condyles_l_cylinder" sidesite="Gastroc_at_condyles_l_cylinder_gasmed_l_1_sidesite" />
      <site site="gasmed_l_gasmed_l-P2" />
    </spatial>
    <spatial name="glmax1_l_tendon">
      <site site="glmax1_l_glmax1_l-P1" />
      <site site="glmax1_l_glmax1_l-P2" />
      <geom geom="Gmax1_at_pelvis_l_cylinder" sidesite="Gmax1_at_pelvis_l_cylinder_glmax1_l_2_sidesite" />
      <site site="glmax1_l_glmax1_l-P3" />
      <site site="glmax1_l_glmax1_l-P4" />
    </spatial>
    <spatial name="glmax2_l_tendon">
      <site site="glmax2_l_glmax2_l-P1" />
      <geom geom="Gmax2_at_pelvis_l_cylinder" sidesite="Gmax2_at_pelvis_l_cylinder_glmax2_l_1_sidesite" />
      <site site="glmax2_l_glmax2_l-P2" />
      <geom geom="Gmax2_at_pelvis_l_cylinder" sidesite="Gmax2_at_pelvis_l_cylinder_glmax2_l_2_sidesite" />
      <site site="glmax2_l_glmax2_l-P3" />
      <site site="glmax2_l_glmax2_l-P4" />
    </spatial>
    <spatial name="glmax3_l_tendon">
      <site site="glmax3_l_glmax3_l-P1" />
      <geom geom="Gmax3_at_pelvis_l_cylinder" sidesite="Gmax3_at_pelvis_l_cylinder_glmax3_l_1_sidesite" />
      <site site="glmax3_l_glmax3_l-P2" />
      <site site="glmax3_l_glmax3_l-P3" />
      <site site="glmax3_l_glmax3_l-P4" />
    </spatial>
    <spatial name="glmed1_l_tendon">
      <site site="glmed1_l_glmed1_l-P1" />
      <site site="glmed1_l_glmed1_l-P2" />
    </spatial>
    <spatial name="glmed2_l_tendon">
      <site site="glmed2_l_glmed2_l-P1" />
      <site site="glmed2_l_glmed2_l-P2" />
    </spatial>
    <spatial name="glmed3_l_tendon">
      <site site="glmed3_l_glmed3_l-P1" />
      <site site="glmed3_l_glmed3_l-P2" />
    </spatial>
    <spatial name="glmin1_l_tendon">
      <site site="glmin1_l_glmin1_l-P1" />
      <site site="glmin1_l_glmin1_l-P2" />
    </spatial>
    <spatial name="glmin2_l_tendon">
      <site site="glmin2_l_glmin2_l-P1" />
      <site site="glmin2_l_glmin2_l-P2" />
    </spatial>
    <spatial name="glmin3_l_tendon">
      <site site="glmin3_l_glmin3_l-P1" />
      <site site="glmin3_l_glmin3_l-P2" />
    </spatial>
    <spatial name="grac_l_tendon">
      <site site="grac_l_grac_l-P1" />
      <geom geom="GR_at_condyles_l_cylinder" sidesite="GR_at_condyles_l_cylinder_grac_l_1_sidesite" />
      <site site="grac_l_grac_l-P2" />
      <site site="grac_l_grac_l-P3" />
    </spatial>
    <spatial name="iliacus_l_tendon">
      <site site="iliacus_l_iliacus_l-P1" />
      <site site="iliacus_l_iliacus_l-P2" />
      <geom geom="IL_at_brim_l_cylinder" sidesite="IL_at_brim_l_cylinder_iliacus_l_2_sidesite" />
      <site site="iliacus_l_iliacus_l-P3" />
      <site site="iliacus_l_iliacus_l-P4" />
    </spatial>
    <spatial name="perbrev_l_tendon">
      <site site="perbrev_l_perbrev_l-P1" />
      <site site="perbrev_l_perbrev_l-P2" />
      <site site="perbrev_l_perbrev_l-P3" />
      <site site="perbrev_l_perbrev_l-P4" />
      <site site="perbrev_l_perbrev_l-P5" />
    </spatial>
    <spatial name="perlong_l_tendon">
      <site site="perlong_l_perlong_l-P1" />
      <site site="perlong_l_perlong_l-P2" />
      <site site="perlong_l_perlong_l-P3" />
      <site site="perlong_l_perlong_l-P4" />
      <site site="perlong_l_perlong_l-P5" />
      <site site="perlong_l_perlong_l-P6" />
      <site site="perlong_l_perlong_l-P7" />
    </spatial>
    <spatial name="piri_l_tendon">
      <site site="piri_l_piri_l-P1" />
      <site site="piri_l_piri_l-P2" />
      <site site="piri_l_piri_l-P3" />
    </spatial>
    <spatial name="psoas_l_tendon">
      <site site="psoas_l_psoas_l-P1" />
      <site site="psoas_l_psoas_l-P2" />
      <geom geom="PS_at_brim_l_cylinder" sidesite="PS_at_brim_l_cylinder_psoas_l_2_sidesite" />
      <site site="psoas_l_psoas_l-P3" />
      <site site="psoas_l_psoas_l-P4" />
    </spatial>
    <spatial name="recfem_l_tendon">
      <site site="recfem_l_recfem_l-P1" />
      <site site="recfem_l_recfem_l-P2" />
      <site site="recfem_l_recfem_l-P3" />
      <geom geom="KnExt_at_fem_l_cylinder" sidesite="KnExt_at_fem_l_cylinder_recfem_l_3_sidesite" />
      <site site="recfem_l_recfem_l-P4" />
      <site site="recfem_l_recfem_l-P5" />
    </spatial>
    <spatial name="sart_l_tendon">
      <site site="sart_l_sart_l-P1" />
      <site site="sart_l_sart_l-P2" />
      <site site="sart_l_sart_l-P3" />
      <site site="sart_l_sart_l-P4" />
      <site site="sart_l_sart_l-P5" />
    </spatial>
    <spatial name="semimem_l_tendon">
      <site site="semimem_l_semimem_l-P1" />
      <geom geom="SM_at_condyles_l_cylinder" sidesite="SM_at_condyles_l_cylinder_semimem_l_1_sidesite" />
      <site site="semimem_l_semimem_l-P2" />
    </spatial>
    <spatial name="semiten_l_tendon">
      <site site="semiten_l_semiten_l-P1" />
      <geom geom="ST_at_condyles_l_cylinder" sidesite="ST_at_condyles_l_cylinder_semiten_l_1_sidesite" />
      <site site="semiten_l_semiten_l-P2" />
      <site site="semiten_l_semiten_l-P3" />
    </spatial>
    <spatial name="soleus_l_tendon">
      <site site="soleus_l_soleus_l-P1" />
      <site site="soleus_l_soleus_l-P2" />
    </spatial>
    <spatial name="tfl_l_tendon">
      <site site="tfl_l_tfl_l-P1" />
      <site site="tfl_l_tfl_l-P2" />
      <site site="tfl_l_tfl_l-P3" />
      <site site="tfl_l_tfl_l-P4" />
    </spatial>
    <spatial name="tibant_l_tendon">
      <site site="tibant_l_tibant_l-P1" />
      <site site="tibant_l_tibant_l-P2" />
      <site site="tibant_l_tibant_l-P3" />
      <site site="tibant_l_tibant_l-P4" />
    </spatial>
    <spatial name="tibpost_l_tendon">
      <site site="tibpost_l_tibpost_l-P1" />
      <site site="tibpost_l_tibpost_l-P2" />
      <site site="tibpost_l_tibpost_l-P3" />
      <site site="tibpost_l_tibpost_l-P4" />
    </spatial>
    <spatial name="vasint_l_tendon">
      <site site="vasint_l_vasint_l-P1" />
      <site site="vasint_l_vasint_l-P2" />
      <site site="vasint_l_vasint_l-P3" />
      <geom geom="KnExt_at_fem_l_cylinder" sidesite="KnExt_at_fem_l_cylinder_vasint_l_3_sidesite" />
      <site site="vasint_l_vasint_l-P4" />
      <site site="vasint_l_vasint_l-P5" />
    </spatial>
    <spatial name="vaslat_l_tendon">
      <site site="vaslat_l_vaslat_l-P1" />
      <site site="vaslat_l_vaslat_l-P2" />
      <geom geom="KnExt_at_fem_l_cylinder" sidesite="KnExt_at_fem_l_cylinder_vaslat_l_2_sidesite" />
      <site site="vaslat_l_vaslat_l-P3" />
      <geom geom="KnExt_at_fem_l_cylinder" sidesite="KnExt_at_fem_l_cylinder_vaslat_l_3_sidesite" />
      <site site="vaslat_l_vaslat_l-P4" />
      <site site="vaslat_l_vaslat_l-P5" />
    </spatial>
    <spatial name="vasmed_l_tendon">
      <site site="vasmed_l_vasmed_l-P1" />
      <site site="vasmed_l_vasmed_l-P2" />
      <site site="vasmed_l_vasmed_l-P3" />
      <geom geom="KnExt_at_fem_l_cylinder" sidesite="KnExt_at_fem_l_cylinder_vasmed_l_3_sidesite" />
      <site site="vasmed_l_vasmed_l-P4" />
      <geom geom="KnExt_at_fem_l_cylinder" sidesite="KnExt_at_fem_l_cylinder_vasmed_l_4_sidesite" />
      <site site="vasmed_l_vasmed_l-P5" />
    </spatial>
  </tendon>
  <actuator>
    
    <motor name="lumbar_ext" ctrllimited="false" joint="lumbar_extension" class="motor" />
    <motor name="lumbar_bend" ctrllimited="false" joint="lumbar_bending" class="motor" />
    <motor name="lumbar_rot" ctrllimited="false" joint="lumbar_rotation" class="motor" />
    <muscle name="addbrev_r" lengthrange="0.01 1" force="625.81967213114797" tendon="addbrev_r_tendon" class="muscle" timeconst="0.01 0.04" />
    <muscle name="addlong_r" lengthrange="0.01 1" force="916.79999999999995" tendon="addlong_r_tendon" class="muscle" timeconst="0.01 0.04" />
    <muscle name="addmagDist_r" lengthrange="0.01 1" force="597.29508196721395" tendon="addmagDist_r_tendon" class="muscle" timeconst="0.01 0.04" />
    <muscle name="addmagIsch_r" lengthrange="0.01 1" force="597.29508196721395" tendon="addmagIsch_r_tendon" class="muscle" timeconst="0.01 0.04" />
    <muscle name="addmagMid_r" lengthrange="0.01 1" force="597.29508196721395" tendon="addmagMid_r_tendon" class="muscle" timeconst="0.01 0.04" />
    <muscle name="addmagProx_r" lengthrange="0.01 1" force="597.29508196721395" tendon="addmagProx_r_tendon" class="muscle" timeconst="0.01 0.04" />
    <muscle name="bflh_r" lengthrange="0.01 1" force="1313.18360655738" tendon="bflh_r_tendon" class="muscle" timeconst="0.01 0.04" />
    <muscle name="bfsh_r" lengthrange="0.01 1" force="557.11475409835998" tendon="bfsh_r_tendon" class="muscle" timeconst="0.01 0.04" />
    <muscle name="edl_r" lengthrange="0.01 1" force="603.49815560000002" tendon="edl_r_tendon" class="muscle" timeconst="0.01 0.04" />
    <muscle name="ehl_r" lengthrange="0.01 1" force="285.86754739999998" tendon="ehl_r_tendon" class="muscle" timeconst="0.01 0.04" />
    <muscle name="fdl_r" lengthrange="0.01 1" force="423.17704918032803" tendon="fdl_r_tendon" class="muscle" timeconst="0.01 0.04" />
    <muscle name="fhl_r" lengthrange="0.01 1" force="907.83934426229405" tendon="fhl_r_tendon" class="muscle" timeconst="0.01 0.04" />
    <muscle name="gaslat_r" lengthrange="0.01 1" force="1575.0590163934401" tendon="gaslat_r_tendon" class="muscle" timeconst="0.01 0.04" />
    <muscle name="gasmed_r" lengthrange="0.01 1" force="3115.5147540983598" tendon="gasmed_r_tendon" class="muscle" timeconst="0.01 0.04" />
    <muscle name="glmax1_r" lengthrange="0.01 1" force="983.78360655737799" tendon="glmax1_r_tendon" class="muscle" timeconst="0.01 0.04" />
    <muscle name="glmax2_r" lengthrange="0.01 1" force="1406.0459016393499" tendon="glmax2_r_tendon" class="muscle" timeconst="0.01 0.04" />
    <muscle name="glmax3_r" lengthrange="0.01 1" force="947.75409836065603" tendon="glmax3_r_tendon" class="muscle" timeconst="0.01 0.04" />
    <muscle name="glmed1_r" lengthrange="0.01 1" force="1093.4667688" tendon="glmed1_r_tendon" class="muscle" timeconst="0.01 0.04" />
    <muscle name="glmed2_r" lengthrange="0.01 1" force="765.09166159999995" tendon="glmed2_r_tendon" class="muscle" timeconst="0.01 0.04" />
    <muscle name="glmed3_r" lengthrange="0.01 1" force="871.19926420000002" tendon="glmed3_r_tendon" class="muscle" timeconst="0.01 0.04" />
    <muscle name="glmin1_r" lengthrange="0.01 1" force="374.04590163934398" tendon="glmin1_r_tendon" class="muscle" timeconst="0.01 0.04" />
    <muscle name="glmin2_r" lengthrange="0.01 1" force="394.81967213114802" tendon="glmin2_r_tendon" class="muscle" timeconst="0.01 0.04" />
    <muscle name="glmin3_r" lengthrange="0.01 1" force="446.77377049180399" tendon="glmin3_r_tendon" class="muscle" timeconst="0.01 0.04" />
    <muscle name="grac_r" lengthrange="0.01 1" force="281.31147540983602" tendon="grac_r_tendon" class="muscle" timeconst="0.01 0.04" />
    <muscle name="iliacus_r" lengthrange="0.01 1" force="1021.14098360656" tendon="iliacus_r_tendon" class="muscle" timeconst="0.01 0.04" />
    <muscle name="perbrev_r" lengthrange="0.01 1" force="521.20159880000006" tendon="perbrev_r_tendon" class="muscle" timeconst="0.01 0.04" />
    <muscle name="perlong_r" lengthrange="0.01 1" force="1115.3714213999999" tendon="perlong_r_tendon" class="muscle" timeconst="0.01 0.04" />
    <muscle name="piri_r" lengthrange="0.01 1" force="1029.7868852459001" tendon="piri_r_tendon" class="muscle" timeconst="0.01 0.04" />
    <muscle name="psoas_r" lengthrange="0.01 1" force="1426.79016393443" tendon="psoas_r_tendon" class="muscle" timeconst="0.01 0.04" />
    <muscle name="recfem_r" lengthrange="0.01 1" force="2191.7409836065599" tendon="recfem_r_tendon" class="muscle" timeconst="0.01 0.04" />
    <muscle name="sart_r" lengthrange="0.01 1" force="249.41311475409799" tendon="sart_r_tendon" class="muscle" timeconst="0.01 0.04" />
    <muscle name="semimem_r" lengthrange="0.01 1" force="2200.9868852458999" tendon="semimem_r_tendon" class="muscle" timeconst="0.01 0.04" />
    <muscle name="semiten_r" lengthrange="0.01 1" force="591.29508196721395" tendon="semiten_r_tendon" class="muscle" timeconst="0.01 0.04" />
    <muscle name="soleus_r" lengthrange="0.01 1" force="6194.8426229508204" tendon="soleus_r_tendon" class="muscle" timeconst="0.01 0.04" />
    <muscle name="tfl_r" lengthrange="0.01 1" force="411.20655737704999" tendon="tfl_r_tendon" class="muscle" timeconst="0.01 0.04" />
    <muscle name="tibant_r" lengthrange="0.01 1" force="1227.4524590163901" tendon="tibant_r_tendon" class="muscle" timeconst="0.01 0.04" />
    <muscle name="tibpost_r" lengthrange="0.01 1" force="1730.1540983606501" tendon="tibpost_r_tendon" class="muscle" timeconst="0.01 0.04" />
    <muscle name="vasint_r" lengthrange="0.01 1" force="1697.36065573771" tendon="vasint_r_tendon" class="muscle" timeconst="0.01 0.04" />
    <muscle name="vaslat_r" lengthrange="0.01 1" force="5148.7672131147601" tendon="vaslat_r_tendon" class="muscle" timeconst="0.01 0.04" />
    <muscle name="vasmed_r" lengthrange="0.01 1" force="2747.82295081966" tendon="vasmed_r_tendon" class="muscle" timeconst="0.01 0.04" />
    <muscle name="addbrev_l" lengthrange="0.01 1" force="625.81967213114797" tendon="addbrev_l_tendon" class="muscle" timeconst="0.01 0.04" />
    <muscle name="addlong_l" lengthrange="0.01 1" force="916.79999999999995" tendon="addlong_l_tendon" class="muscle" timeconst="0.01 0.04" />
    <muscle name="addmagDist_l" lengthrange="0.01 1" force="597.29508196721395" tendon="addmagDist_l_tendon" class="muscle" timeconst="0.01 0.04" />
    <muscle name="addmagIsch_l" lengthrange="0.01 1" force="597.29508196721395" tendon="addmagIsch_l_tendon" class="muscle" timeconst="0.01 0.04" />
    <muscle name="addmagMid_l" lengthrange="0.01 1" force="597.29508196721395" tendon="addmagMid_l_tendon" class="muscle" timeconst="0.01 0.04" />
    <muscle name="addmagProx_l" lengthrange="0.01 1" force="597.29508196721395" tendon="addmagProx_l_tendon" class="muscle" timeconst="0.01 0.04" />
    <muscle name="bflh_l" lengthrange="0.01 1" force="1313.18360655738" tendon="bflh_l_tendon" class="muscle" timeconst="0.01 0.04" />
    <muscle name="bfsh_l" lengthrange="0.01 1" force="557.11475409835998" tendon="bfsh_l_tendon" class="muscle" timeconst="0.01 0.04" />
    <muscle name="edl_l" lengthrange="0.01 1" force="603.49815560000002" tendon="edl_l_tendon" class="muscle" timeconst="0.01 0.04" />
    <muscle name="ehl_l" lengthrange="0.01 1" force="285.86754739999998" tendon="ehl_l_tendon" class="muscle" timeconst="0.01 0.04" />
    <muscle name="fdl_l" lengthrange="0.01 1" force="423.17704918032803" tendon="fdl_l_tendon" class="muscle" timeconst="0.01 0.04" />
    <muscle name="fhl_l" lengthrange="0.01 1" force="907.83934426229405" tendon="fhl_l_tendon" class="muscle" timeconst="0.01 0.04" />
    <muscle name="gaslat_l" lengthrange="0.01 1" force="1575.0590163934401" tendon="gaslat_l_tendon" class="muscle" timeconst="0.01 0.04" />
    <muscle name="gasmed_l" lengthrange="0.01 1" force="3115.5147540983598" tendon="gasmed_l_tendon" class="muscle" timeconst="0.01 0.04" />
    <muscle name="glmax1_l" lengthrange="0.01 1" force="983.78360655737799" tendon="glmax1_l_tendon" class="muscle" timeconst="0.01 0.04" />
    <muscle name="glmax2_l" lengthrange="0.01 1" force="1406.0459016393499" tendon="glmax2_l_tendon" class="muscle" timeconst="0.01 0.04" />
    <muscle name="glmax3_l" lengthrange="0.01 1" force="947.75409836065603" tendon="glmax3_l_tendon" class="muscle" timeconst="0.01 0.04" />
    <muscle name="glmed1_l" lengthrange="0.01 1" force="1093.4667688" tendon="glmed1_l_tendon" class="muscle" timeconst="0.01 0.04" />
    <muscle name="glmed2_l" lengthrange="0.01 1" force="765.09166159999995" tendon="glmed2_l_tendon" class="muscle" timeconst="0.01 0.04" />
    <muscle name="glmed3_l" lengthrange="0.01 1" force="871.19926420000002" tendon="glmed3_l_tendon" class="muscle" timeconst="0.01 0.04" />
    <muscle name="glmin1_l" lengthrange="0.01 1" force="374.04590163934398" tendon="glmin1_l_tendon" class="muscle" timeconst="0.01 0.04" />
    <muscle name="glmin2_l" lengthrange="0.01 1" force="394.81967213114802" tendon="glmin2_l_tendon" class="muscle" timeconst="0.01 0.04" />
    <muscle name="glmin3_l" lengthrange="0.01 1" force="446.77377049180399" tendon="glmin3_l_tendon" class="muscle" timeconst="0.01 0.04" />
    <muscle name="grac_l" lengthrange="0.01 1" force="281.31147540983602" tendon="grac_l_tendon" class="muscle" timeconst="0.01 0.04" />
    <muscle name="iliacus_l" lengthrange="0.01 1" force="1021.14098360656" tendon="iliacus_l_tendon" class="muscle" timeconst="0.01 0.04" />
    <muscle name="perbrev_l" lengthrange="0.01 1" force="521.20159880000006" tendon="perbrev_l_tendon" class="muscle" timeconst="0.01 0.04" />
    <muscle name="perlong_l" lengthrange="0.01 1" force="1115.3714213999999" tendon="perlong_l_tendon" class="muscle" timeconst="0.01 0.04" />
    <muscle name="piri_l" lengthrange="0.01 1" force="1029.7868852459001" tendon="piri_l_tendon" class="muscle" timeconst="0.01 0.04" />
    <muscle name="psoas_l" lengthrange="0.01 1" force="1426.79016393443" tendon="psoas_l_tendon" class="muscle" timeconst="0.01 0.04" />
    <muscle name="recfem_l" lengthrange="0.01 1" force="2191.7409836065599" tendon="recfem_l_tendon" class="muscle" timeconst="0.01 0.04" />
    <muscle name="sart_l" lengthrange="0.01 1" force="249.41311475409799" tendon="sart_l_tendon" class="muscle" timeconst="0.01 0.04" />
    <muscle name="semimem_l" lengthrange="0.01 1" force="2200.9868852458999" tendon="semimem_l_tendon" class="muscle" timeconst="0.01 0.04" />
    <muscle name="semiten_l" lengthrange="0.01 1" force="591.29508196721395" tendon="semiten_l_tendon" class="muscle" timeconst="0.01 0.04" />
    <muscle name="soleus_l" lengthrange="0.01 1" force="6194.8426229508204" tendon="soleus_l_tendon" class="muscle" timeconst="0.01 0.04" />
    <muscle name="tfl_l" lengthrange="0.01 1" force="411.20655737704999" tendon="tfl_l_tendon" class="muscle" timeconst="0.01 0.04" />
    <muscle name="tibant_l" lengthrange="0.01 1" force="1227.4524590163901" tendon="tibant_l_tendon" class="muscle" timeconst="0.01 0.04" />
    <muscle name="tibpost_l" lengthrange="0.01 1" force="1730.1540983606501" tendon="tibpost_l_tendon" class="muscle" timeconst="0.01 0.04" />
    <muscle name="vasint_l" lengthrange="0.01 1" force="1697.36065573771" tendon="vasint_l_tendon" class="muscle" timeconst="0.01 0.04" />
    <muscle name="vaslat_l" lengthrange="0.01 1" force="5148.7672131147601" tendon="vaslat_l_tendon" class="muscle" timeconst="0.01 0.04" />
    <muscle name="vasmed_l" lengthrange="0.01 1" force="2747.82295081966" tendon="vasmed_l_tendon" class="muscle" timeconst="0.01 0.04" />
  </actuator>
  <equality>
    
    <joint joint1="walker_knee_r_translation1" joint2="knee_angle_r" polycoef="9.657e-08 0.003168 -0.002337 0.0005686 5.755e-07" solimp="0.9999 0.9999 0.001 0.5 2" active="true" />
    <joint joint1="walker_knee_r_translation2" joint2="knee_angle_r" polycoef="8.001e-11 0.006115 -0.001307 -2.723e-06 6.494e-07" solimp="0.9999 0.9999 0.001 0.5 2" active="true" />
    <joint joint1="walker_knee_r_rotation2" joint2="knee_angle_r" polycoef="-1.473e-08 0.0791 -0.03285 -0.02522 0.01083" solimp="0.9999 0.9999 0.001 0.5 2" active="true" />
    <joint joint1="walker_knee_r_rotation3" joint2="knee_angle_r" polycoef="1.089e-08 0.3695 -0.1695 0.02516 3.505e-07" solimp="0.9999 0.9999 0.001 0.5 2" active="true" />
    <joint name="mtp_angle_r_locked" active="true" joint1="mtp_angle_r" polycoef="0.0 0 0 0 0" solimp="0.9999 0.9999 0.001 0.5 2" />
    <joint joint1="patellofemoral_r_translation1" joint2="knee_angle_r" polycoef="0.05422 -0.01553 -0.03522 0.0138 -0.0009094" solimp="0.9999 0.9999 0.001 0.5 2" active="true" />
    <joint joint1="patellofemoral_r_translation2" joint2="knee_angle_r" polycoef="-0.01096 -0.0494 0.009393 0.01333 -0.003541" solimp="0.9999 0.9999 0.001 0.5 2" active="true" />
    <joint joint1="patellofemoral_r_rotation1" joint2="knee_angle_r" polycoef="0.01051 0.02476 -1.316 0.7163 -0.1383" solimp="0.9999 0.9999 0.001 0.5 2" active="true" />
    <joint name="patellofemoral_r_translation3_locked" active="true" joint1="patellofemoral_r_translation3" polycoef="0.0028601913213499993 0 0 0 0" solimp="0.9999 0.9999 0.001 0.5 2" />
    <joint joint1="walker_knee_l_translation1" joint2="knee_angle_l" polycoef="9.657e-08 0.003168 -0.002337 0.0005686 5.755e-07" solimp="0.9999 0.9999 0.001 0.5 2" active="true" />
    <joint joint1="walker_knee_l_translation2" joint2="knee_angle_l" polycoef="-8.001e-11 -0.006115 0.001307 2.723e-06 -6.494e-07" solimp="0.9999 0.9999 0.001 0.5 2" active="true" />
    <joint joint1="walker_knee_l_rotation2" joint2="knee_angle_l" polycoef="-1.473e-08 0.0791 -0.03285 -0.02522 0.01083" solimp="0.9999 0.9999 0.001 0.5 2" active="true" />
    <joint joint1="walker_knee_l_rotation3" joint2="knee_angle_l" polycoef="-1.089e-08 -0.3695 0.1695 -0.02516 -3.505e-07" solimp="0.9999 0.9999 0.001 0.5 2" active="true" />
    <joint name="mtp_angle_l_locked" active="true" joint1="mtp_angle_l" polycoef="0.0 0 0 0 0" solimp="0.9999 0.9999 0.001 0.5 2" />
    <joint joint1="patellofemoral_l_translation1" joint2="knee_angle_l" polycoef="0.05422 -0.01553 -0.03522 0.0138 -0.0009094" solimp="0.9999 0.9999 0.001 0.5 2" active="true" />
    <joint joint1="patellofemoral_l_translation2" joint2="knee_angle_l" polycoef="-0.01096 -0.0494 0.009393 0.01333 -0.003541" solimp="0.9999 0.9999 0.001 0.5 2" active="true" />
    <joint joint1="patellofemoral_l_rotation1" joint2="knee_angle_l" polycoef="0.01051 0.02476 -1.316 0.7163 -0.1383" solimp="0.9999 0.9999 0.001 0.5 2" active="true" />
    <joint name="patellofemoral_l_translation3_locked" active="true" joint1="patellofemoral_l_translation3" polycoef="-0.0028601913213499993 0 0 0 0" solimp="0.9999 0.9999 0.001 0.5 2" />
  </equality>
  <contact>
    
    <pair geom1="ground-plane" geom2="pelvis_geom_1" />
    <pair geom1="ground-plane" geom2="pelvis_geom_2" />
    <pair geom1="ground-plane" geom2="pelvis_geom_3" />
    <pair geom1="ground-plane" geom2="femur_r_geom_1" />
    <pair geom1="ground-plane" geom2="tibia_r_geom_1" />
    <pair geom1="ground-plane" geom2="tibia_r_geom_2" />
    <pair geom1="ground-plane" geom2="talus_r_geom_1" />
    <pair geom1="ground-plane" geom2="calcn_r_geom_1" />
    <pair geom1="ground-plane" geom2="toes_r_geom_1" />
    <pair geom1="ground-plane" geom2="patella_r_geom_1" />
    <pair geom1="ground-plane" geom2="femur_l_geom_1" />
    <pair geom1="ground-plane" geom2="tibia_l_geom_1" />
    <pair geom1="ground-plane" geom2="tibia_l_geom_2" />
    <pair geom1="ground-plane" geom2="talus_l_geom_1" />
    <pair geom1="ground-plane" geom2="calcn_l_geom_1" />
    <pair geom1="ground-plane" geom2="toes_l_geom_1" />
    <pair geom1="ground-plane" geom2="patella_l_geom_1" />
    <pair geom1="ground-plane" geom2="torso_geom_1" />
    <pair geom1="ground-plane" geom2="torso_geom_2" />
    <pair geom1="ground-plane" geom2="torso_geom_3" />
    <pair geom1="ground-plane" geom2="torso_geom_4" />
  </contact>
  <keyframe>
    <key name="default-pose" qpos="0 0.93 0 0 0 0 0 0 0 9.657e-08 8.001e-11 0 -1.473e-08 1.089e-08 0 0 0 0.05422 -0.01096 0.00286 0.01051 0 -0 -0 9.657e-08 -8.001e-11 0 -1.473e-08 -1.089e-08 0 0 0 0.05422 -0.01096 -0.00286 0.01051 0 0 0" />
  </keyframe>
</mujoco>