<mujoco model="template">
  <!-- This model has been converted from an OpenSim model. Model conversion by MyoConverter https://github.com/MyoHub/myoconverter. This model is licensed under Apache 2.0. -->
  <!-- Note: inertiagrouprange="0 1" means that groups 0-1 will be used to infer masses/inertias, and groups 2-5 are
  only for visualisation (e.g. wrapping objects) !-->
  <compiler inertiafromgeom="auto" angle="radian" balanceinertia="true" boundmass="0.001" boundinertia="0.001" inertiagrouprange="0 1">
    <lengthrange inttotal="50" useexisting="true"/>
  </compiler>
  <option/>
  <visual>
    <scale framelength="0.5" framewidth="0.01"/>
  </visual>
  <default>
    <joint limited="true" damping="0.05" armature="0.00001" stiffness="0"/>
    <geom rgba="0.8 0.6 .4 1" margin="0.001"/>
    <site size="0.001"/>
    <tendon width="0.005" rgba=".95 .3 .3 1" limited="false"/>
    <default class="muscle">
      <muscle ctrllimited="true" ctrlrange="0 1" scale="200"/>
    </default>
    <default class="motor">
      <general gainprm="5 0 0 0 0 0 0 0 0 0"/>
    </default>
  </default>
  <option timestep="0.002"/>
  <!-- nuser_jnt=1, the parameter is used to store default value of the joint, and nkey=1 to store keyframe with
   default joint positions set !-->
  <size njmax="1000" nconmax="400" nuser_jnt="1" nkey="1"/>
  <worldbody>
    <!-- The converter script assumes a body named 'ground' exists as a child element of worldbody -->
    <body name="ground" euler="1.571 0 0">
      <geom name="ground-plane" pos="0 0 0" euler="-1.571 0 0" size="10 10 0.125" type="plane" rgba="1.0 0.7 0.4 1.0" condim="3"/>
    </body>
    <light directional="true"/>
    <body name="pelvis" pos="0 0 0" euler="1.571 0 0">
      <inertial mass="11.8843903912" pos="-0.0707000000 0.0000000000 0.0000000000" fullinertia="0.1037373977 0.0878942348 0.0584279701 0.0000000000 0.0000000000 0.0000000000"/>
      <geom name="pelvis_geom_1" type="mesh" mesh="pelvis_geom_1_r_pelvis" rgba="1 1 1 1" group="0"/>
      <geom name="pelvis_geom_2" type="mesh" mesh="pelvis_geom_2_l_pelvis" rgba="1 1 1 1" group="0"/>
      <geom name="pelvis_geom_3" type="mesh" mesh="pelvis_geom_3_sacrum" rgba="1 1 1 1" group="0"/>
      <geom name="Gmax1_at_pelvis_r_cylinder" type="cylinder" euler="-0.6 0.45 0" pos="-0.08301 -0.09494 0.06846" size="0.04182 0.08054" rgba="0.19 0.83 0.78 0.2" group="2"/>
      <site name="Gmax1_at_pelvis_r_sidesite" pos="-0.1216 -0.08442 0.08383" size="0.0005"/>
      <geom name="Gmax2_at_pelvis_r_cylinder" type="cylinder" euler="-0.75 0.39 0" pos="-0.08624 -0.0796 0.07631" size="0.04224 0.05269" rgba="0.19 0.83 0.78 0.2" group="2"/>
      <geom name="Gmax3_at_pelvis_r_cylinder" type="cylinder" euler="-0.1 0 0" pos="-0.08948 -0.08439 0.07631" size="0.04078 0.05604" rgba="0.19 0.83 0.78 0.2" group="2"/>
      <geom name="Gmax1_at_pelvis_l_cylinder" type="cylinder" euler="0.6 -0.45 0" pos="-0.08301 -0.09494 -0.06846" size="0.04182 0.08054" rgba="0.19 0.83 0.78 0.2" group="2"/>
      <site name="Gmax1_at_pelvis_l_sidesite" pos="-0.1216 -0.08442 -0.08383" size="0.0005"/>
      <geom name="Gmax2_at_pelvis_l_cylinder" type="cylinder" euler="0.75 -0.39 0" pos="-0.08624 -0.0796 -0.07631" size="0.04224 0.05269" rgba="0.19 0.83 0.78 0.2" group="2"/>
      <geom name="Gmax3_at_pelvis_l_cylinder" type="cylinder" euler="0.1 0 0" pos="-0.08948 -0.08439 -0.07631" size="0.04078 0.05604" rgba="0.19 0.83 0.78 0.2" group="2"/>
      <geom name="PS_at_brim_r_cylinder" type="cylinder" euler="-0.25 -0.27 0.1" pos="-0.07978 -0.05754 0.07362" size="0.05127 0.05553" rgba="0.19 0.83 0.78 0.2" group="2"/>
      <site name="PS_at_brim_r_sidesite" pos="-0.07475 -0.1076 0.08784" size="0.0005"/>
      <geom name="PS_at_brim_l_cylinder" type="cylinder" euler="0.25 0.27 0.1" pos="-0.07978 -0.05754 -0.07362" size="0.05127 0.05553" rgba="0.19 0.83 0.78 0.2" group="2"/>
      <site name="PS_at_brim_l_sidesite" pos="-0.07475 -0.1076 -0.08784" size="0.0005"/>
      <geom name="IL_at_brim_r_cylinder" type="cylinder" euler="-0.32 -0.24 0.9" pos="-0.07654 -0.06233 0.08484" size="0.0565 0.05528" rgba="0.19 0.83 0.78 0.2" group="2"/>
      <site name="IL_at_brim_r_sidesite" pos="-0.03279 -0.09289 0.1062" size="0.0005"/>
      <geom name="IL_at_brim_l_cylinder" type="cylinder" euler="0.32 0.24 0.9" pos="-0.07654 -0.06233 -0.08484" size="0.0565 0.05528" rgba="0.19 0.83 0.78 0.2" group="2"/>
      <site name="IL_at_brim_l_sidesite" pos="-0.03279 -0.09289 -0.1062" size="0.0005"/>
      <joint name="pelvis_tx" range="-40 40" limited="true" user="0.0" ref="0" axis="1 0 0" type="slide" damping="0" stiffness="0"/>
      <joint name="pelvis_ty" range="-5 5" limited="true" user="0.93" ref="0" axis="0 1 0" type="slide" damping="0" stiffness="0"/>
      <joint name="pelvis_tz" range="-40 40" limited="true" user="0.0" ref="0" axis="0 0 1" type="slide" damping="0" stiffness="0"/>
      <joint name="pelvis_tilt" range="-3.142 3.142" limited="true" user="0.0" ref="0" axis="0 0 1" type="hinge" damping="0" stiffness="0"/>
      <joint name="pelvis_list" range="-3.142 3.142" limited="true" user="0.0" ref="0" axis="1 0 0" type="hinge" damping="0" stiffness="0"/>
      <joint name="pelvis_rotation" range="-3.142 3.142" limited="true" user="0.0" ref="0" axis="0 1 0" type="hinge" damping="0" stiffness="0"/>
      <body name="femur_r" pos="-0.06067 -0.07527 0.08671" euler="-0 0 0">
        <inertial mass="9.3862162507" pos="0.0000000000 -0.1700000000 0.0000000000" fullinertia="0.1351209878 0.0354200648 0.1424875540 0.0000000000 0.0000000000 0.0000000000"/>
        <geom name="femur_r_geom_1" type="mesh" mesh="femur_r_geom_1_r_femur" rgba="1 1 1 1" group="0"/>
        <geom name="Gastroc_at_condyles_r_cylinder" type="cylinder" euler="0 0 0" pos="0.005013 -0.4147 0" size="0.02518 0.05116" rgba="0.19 0.83 0.78 0.2" group="2"/>
        <geom name="KnExt_at_fem_r_cylinder" type="cylinder" euler="-0.06234 0.05076 0" pos="0.003598 -0.4073 0.002139" size="0.02518 0.05115" rgba="0.19 0.83 0.78 0.2" group="2"/>
        <geom name="AB_at_femshaft_r_cylinder" type="cylinder" euler="1.662 0.1866 0" pos="0.01468 -0.1139 0.0239" size="0.01671 0.03539" rgba="0.19 0.83 0.78 0.2" group="2"/>
        <geom name="AL_at_femshaft_r_cylinder" type="cylinder" euler="1.777 0.1365 0" pos="0.03082 -0.2346 0.01546" size="0.02036 0.05059" rgba="0.19 0.83 0.78 0.2" group="2"/>
        <geom name="AMprox_at_femshaft_r_cylinder" type="cylinder" euler="1.611 0.1866 0" pos="0.005197 -0.07373 0.02599" size="0.02138 0.03539" rgba="0.19 0.83 0.78 0.2" group="2"/>
        <geom name="AMmid_at_femshaft_r_cylinder" type="cylinder" euler="1.611 0.1366 0" pos="0.02307 -0.1625 0.02106" size="0.02168 0.06068" rgba="0.19 0.83 0.78 0.2" group="2"/>
        <geom name="AMdist_at_femshaft_r_cylinder" type="cylinder" euler="1.712 0.1866 0" pos="0.03169 -0.2637 0.009581" size="0.02208 0.1011" rgba="0.19 0.83 0.78 0.2" group="2"/>
        <geom name="AMisch_at_condyles_r_cylinder" type="cylinder" euler="1.711 -0.4634 0" pos="-0.02271 -0.3811 -0.003227" size="0.04055 0.1212" rgba="0.19 0.83 0.78 0.2" group="2"/>
        <geom name="PECT_at_femshaft_r_cylinder" type="cylinder" euler="1.813 0.2763 0" pos="0.006102 -0.08547 0.03114" size="0.01519 0.02528" rgba="0.19 0.83 0.78 0.2" group="2"/>
        <joint name="hip_flexion_r" range="-0.5236 2.094" limited="true" user="0.0" ref="0" axis="0 0 1" type="hinge"/>
        <joint name="hip_adduction_r" range="-0.8727 0.5236" limited="true" user="0.0" ref="0" axis="1 0 0" type="hinge"/>
        <joint name="hip_rotation_r" range="-0.6981 0.6981" limited="true" user="0.0" ref="0" axis="0 1 0" type="hinge"/>
        <body name="tibia_r" pos="0.0002675 -0.4086 -0.001235" euler="-0 0 0">
          <inertial mass="3.7413074107" pos="0.0000000000 -0.1867000000 0.0000000000" fullinertia="0.0508595802 0.0051465051 0.0515659632 0.0000000000 0.0000000000 0.0000000000"/>
          <geom name="tibia_r_geom_1" type="mesh" mesh="tibia_r_geom_1_r_tibia" rgba="1 1 1 1" group="0"/>
          <geom name="tibia_r_geom_2" type="mesh" mesh="tibia_r_geom_2_r_fibula" rgba="1 1 1 1" group="0"/>
          <geom name="GasLat_at_shank_r_cylinder" type="cylinder" euler="2.967 -0.2797 -1.478" pos="-0.007665 -0.08381 -0.003508" size="0.05964 0.05314" rgba="0.19 0.83 0.78 0.2" group="2"/>
          <site name="GasLat_at_shank_r_sidesite" pos="-0.0657 -0.07539 0.01194" size="0.0005"/>
          <geom name="GasMed_at_shank_r_cylinder" type="cylinder" euler="2.967 0.02797 -1.478" pos="-0.007665 -0.08381 -0.003508" size="0.05958 0.05325" rgba="0.19 0.83 0.78 0.2" group="2"/>
          <site name="GasMed_at_shank_r_sidesite" pos="-0.06796 -0.07858 -0.006142" size="0.0005"/>
          <geom name="GR_at_condyles_r_cylinder" type="cylinder" euler="0 -0.4 0" pos="-0.003107 -0.02265 0" size="0.03911 0.05294" rgba="0.19 0.83 0.78 0.2" group="2"/>
          <geom name="SM_at_condyles_r_cylinder" type="cylinder" euler="0 -0.1 0" pos="-0.001036 -0.02265 0" size="0.03817 0.05313" rgba="0.19 0.83 0.78 0.2" group="2"/>
          <geom name="ST_at_condyles_r_cylinder" type="cylinder" euler="0 -0.2 0" pos="-0.002072 -0.02322 0" size="0.0461 0.05309" rgba="0.19 0.83 0.78 0.2" group="2"/>
          <geom name="BF_at_gastroc_r_cylinder" type="cylinder" euler="0 0 0" pos="-0.06008 -0.06795 0" size="0.03253 0.07972" rgba="0.19 0.83 0.78 0.2" group="2"/>
          <site name="BF_at_gastroc_r_sidesite" pos="-0.06008 -0.03443 0" size="0.0005"/>
          <joint name="walker_knee_r_translation1" range="0 0.001617" limited="true" user="9.646127779438379e-08" ref="0" axis="-0.1243 0.9898 -0.07016" type="slide"/>
          <joint name="walker_knee_r_translation2" range="0 0.006949" limited="true" user="7.870253233843716e-11" ref="0" axis="0.9922 0.124 -0.008789" type="slide"/>
          <joint name="knee_angle_r" range="0 2.094" limited="true" user="0.0" ref="0" axis="-4.566e-07 -0.07071 -0.9975" type="hinge"/>
          <joint name="walker_knee_r_rotation2" range="-0.001678 0.03354" limited="true" user="-1.4732523263838448e-08" ref="0" axis="0.9922 0.124 -0.008789" type="hinge"/>
          <joint name="walker_knee_r_rotation3" range="0 0.2628" limited="true" user="1.0893911855935912e-08" ref="0" axis="-0.1243 0.9898 -0.07016" type="hinge"/>
          <body name="talus_r" pos="-0.01036 -0.453 0" euler="-0 0 0">
            <inertial mass="0.1009118654" pos="0.0000000000 0.0000000000 0.0000000000" fullinertia="0.0010091187 0.0010091187 0.0010091187 0.0000000000 0.0000000000 0.0000000000"/>
            <geom name="talus_r_geom_1" type="mesh" mesh="talus_r_geom_1_r_talus" rgba="1 1 1 0" group="0"/>
            <joint name="ankle_angle_r" range="-0.6981 0.5236" limited="true" user="0.0" ref="0" type="hinge" axis="-0.105 -0.174 0.9791"/>
            <body name="calcn_r" pos="-0.05453 -0.04909 0.009075" euler="-0 0 0">
              <inertial mass="1.2613983178" pos="0.1000000000 0.0300000000 0.0000000000" fullinertia="0.0014127661 0.0039355628 0.0041373865 0.0000000000 0.0000000000 0.0000000000"/>
              <geom name="calcn_r_geom_1" type="mesh" mesh="calcn_r_geom_1_r_foot" rgba="1 1 1 1" group="0"/>
              <joint name="subtalar_angle_r" range="-0.3491 0.3491" limited="true" user="0.0" ref="0" type="hinge" axis="0.7872 0.6047 -0.1209"/>
              <body name="toes_r" pos="0.2032 -0.002207 0.001198" euler="-0 0 0">
                <inertial mass="0.2185751005" pos="0.0346000000 0.0060000000 -0.0175000000" fullinertia="0.0006362493 0.0007371612 0.0010091187 0.0000000000 0.0000000000 0.0000000000"/>
                <geom name="toes_r_geom_1" type="mesh" mesh="toes_r_geom_1_r_bofoot" rgba="1 1 1 1" group="0"/>
                <joint name="mtp_angle_r" range="-0.5236 0.5236" limited="true" user="0.0" ref="0" type="hinge" axis="0.581 2.16e-06 -0.8139"/>
                <site name="edl_r_edl_r-P5" pos="0.00032909191158000001 0.0051553221265400002 0.01678671107811"/>
                <site name="edl_r_edl_r-P6" pos="0.048595905609979999 -0.00043875081928000008 0.027429266467500005"/>
                <site name="ehl_r_ehl_r-P7" pos="0.032689796550280002 0.0044971958976200007 -0.026880681138150002"/>
                <site name="ehl_r_ehl_r-P8" pos="0.061759582073180004 0.00372938196388 -0.020407374251820001"/>
                <site name="fdl_r_fdl_r-P6" pos="-0.00208424877334 -0.0085556409759600001 0.016128408682890002"/>
                <site name="fdl_r_fdl_r-P7" pos="0.0312637316001 -0.0077878270422200007 0.023589169162049999"/>
                <site name="fdl_r_fdl_r-P8" pos="0.048376511002260002 -0.0065812622892000008 0.026551529940540001"/>
                <site name="fhl_r_fhl_r-P6" pos="0.017003082098299999 -0.0070200131084800013 -0.029075022455550003"/>
                <site name="fhl_r_fhl_r-P7" pos="0.061649884769320006 -0.011188145891640001 -0.019858788922470002"/>
              </body>
              <site name="edl_r_edl_r-P3" pos="0.10445990896407999 0.039718476018 0.00088708895976000006"/>
              <site name="edl_r_edl_r-P4" pos="0.18368575939711998 0.0060681005027500004 0.0144151955961"/>
              <site name="ehl_r_ehl_r-P4" pos="0.1102569224104 0.042918019919449997 -0.023396971313669999"/>
              <site name="ehl_r_ehl_r-P5" pos="0.14697134090375999 0.034091691915450001 -0.028497732832289999"/>
              <site name="ehl_r_ehl_r-P6" pos="0.19709845717487998 0.01533574490695 -0.0310481135916"/>
              <site name="fdl_r_fdl_r-P3" pos="0.049558781619519994 0.034753666515750001 -0.0310481135916"/>
              <site name="fdl_r_fdl_r-P4" pos="0.080476186666559993 0.019417921608800001 -0.02916304955211"/>
              <site name="fdl_r_fdl_r-P5" pos="0.18845977047055998 -0.0089366571040500001 0.012862789916519998"/>
              <site name="fhl_r_fhl_r-P3" pos="0.042511431939680003 0.030450831613800002 -0.026723554912769999"/>
              <site name="fhl_r_fhl_r-P4" pos="0.11798627367216 0.0075023788033999998 -0.028386846712320002"/>
              <site name="fhl_r_fhl_r-P5" pos="0.19618912173232 -0.0058474423026500001 -0.029828366271929998"/>
              <site name="gaslat_r_gaslat_r-P2" pos="0.0050013449340799996 0.034202021015500003 -0.0058769643584099997"/>
              <site name="gasmed_r_gasmed_r-P2" pos="0.0050013449340799996 0.034202021015500003 -0.0058769643584099997"/>
              <site name="perbrev_r_perbrev_r-P4" pos="0.05353712418072 0.029788857013500002 0.02583646595301"/>
              <site name="perbrev_r_perbrev_r-P5" pos="0.076952511826639994 0.024162072910949999 0.038033939149709997"/>
              <site name="perlong_r_perlong_r-P4" pos="0.049786115480159994 0.0253756930115 0.024505832513370001"/>
              <site name="perlong_r_perlong_r-P5" pos="0.077407179547919994 0.0116948846053 0.031491658071480001"/>
              <site name="perlong_r_perlong_r-P6" pos="0.096844224632639989 0.0076127079034500004 0.013084562156459999"/>
              <site name="perlong_r_perlong_r-P7" pos="0.13674131717495999 0.0093779735042500006 -0.02040304607448"/>
              <site name="soleus_r_soleus_r-P2" pos="0.0050013449340799996 0.034202021015500003 -0.0058769643584099997"/>
              <site name="tibant_r_tibant_r-P4" pos="0.13253564075311999 0.019638579808900002 -0.033820266590849996"/>
              <site name="tibpost_r_tibpost_r-P3" pos="0.047399109943439995 0.036849919416700003 -0.031713430311420002"/>
              <site name="tibpost_r_tibpost_r-P4" pos="0.087750870207040005 0.01754232690795 -0.031158999711570001"/>
              <site name="R.Heel_marker" group="4" pos="-0.02439 0.02203 -0.007841" rgba="1 0.1 0.5 0.5" size="0.01"/>
              <site name="R.MT1_marker" group="4" pos="0.2135 0.02671 -0.02722" rgba="1 0.1 0.5 0.5" size="0.01"/>
              <site name="R.MT2_marker" group="4" pos="0.2073 0.02678 0.00479" rgba="1 0.1 0.5 0.5" size="0.01"/>
              <site name="R.MT5_marker" group="4" pos="0.1617 0.02494 0.0588" rgba="1 0.1 0.5 0.5" size="0.01"/>
            </body>
          </body>
          <site name="bflh_r_bflh_r-P2" pos="-0.034906762919189996 -0.039639080747000004 0.026891696033509997"/>
          <site name="bflh_r_bflh_r-P3" pos="-0.029727717975689998 -0.051530804971099999 0.032206260467010001"/>
          <site name="bfsh_r_bfsh_r-P2" pos="-0.031177850559869998 -0.047453642379979996 0.03380062979706"/>
          <site name="edl_r_edl_r-P1" pos="-0.016572943819199999 -0.13103547549793998 0.021789714177350001"/>
          <site name="edl_r_edl_r-P2" pos="0.016987267414679999 -0.42583698173919998 0.01190462433104"/>
          <site name="ehl_r_ehl_r-P1" pos="-0.0145013258418 -0.17554450045099998 0.020089053558629999"/>
          <site name="ehl_r_ehl_r-P2" pos="0.00735424381977 -0.32945738826577997 0.017431771341880002"/>
          <site name="ehl_r_ehl_r-P3" pos="0.020716179774000001 -0.41824892913905998 -0.00297615608276"/>
          <site name="fdl_r_fdl_r-P1" pos="-0.0023823606740099998 -0.20748227408143999 -0.0019132431960599999"/>
          <site name="fdl_r_fdl_r-P2" pos="-0.018230238201119998 -0.41281271235089995 -0.013180119795079999"/>
          <site name="fhl_r_fhl_r-P1" pos="-0.032110078649699995 -0.24496951901645997 0.021258257733999999"/>
          <site name="fhl_r_fhl_r-P2" pos="-0.025066577526539999 -0.41575732977781998 -0.0080781379389199999"/>
          <site name="GasLat_at_shank_r_cylinder_gaslat_r_1_sidesite" pos="-0.02508 -0.0889 0.05436" size="0.0005"/>
          <site name="grac_r_grac_r-P2" pos="-0.019079601571853996 -0.053852522557710003 -0.031472850575186999"/>
          <site name="grac_r_grac_r-P3" pos="0.0018437399998859998 -0.078847794331603993 -0.016719619707791001"/>
          <site name="GR_at_condyles_r_cylinder_grac_r_1_sidesite" pos="-0.01592 -0.007885 -0.03441" size="0.0005"/>
          <site name="perbrev_r_perbrev_r-P1" pos="-0.025170158425409997 -0.28676043557543995 0.026679113456169998"/>
          <site name="perbrev_r_perbrev_r-P2" pos="-0.035113924716929999 -0.44089983242305997 0.026466530878829997"/>
          <site name="perbrev_r_perbrev_r-P3" pos="-0.029520556177949998 -0.45347108374567996 0.027104278610849998"/>
          <site name="perlong_r_perlong_r-P1" pos="-0.020716179774000001 -0.15549845104466001 0.029974143404939996"/>
          <site name="perlong_r_perlong_r-P2" pos="-0.032835144941789997 -0.44169261403799998 0.025191035414789998"/>
          <site name="perlong_r_perlong_r-P3" pos="-0.028174004492639997 -0.45460362890987993 0.025509909280799999"/>
          <site name="recfem_r_recfem_r-P5" pos="0.033767373031619995 -0.071486250764303996 -0.00049956905674899998"/>
          <site name="sart_r_sart_r-P3" pos="-0.02599880561637 -0.045415061084419991 -0.038796320364549997"/>
          <site name="sart_r_sart_r-P4" pos="-0.016469362920330001 -0.067839455335580001 -0.02806090020888"/>
          <site name="sart_r_sart_r-P5" pos="0.014087002246319999 -0.091736158300200002 -0.0027635735054199998"/>
          <site name="semimem_r_semimem_r-P2" pos="-0.0300384606723 -0.047227133347140002 -0.020833092579319999"/>
          <site name="SM_at_condyles_r_cylinder_semimem_r_1_sidesite" pos="-0.03181 -0.0003635 -0.02036" size="0.0005"/>
          <site name="semiten_r_semiten_r-P2" pos="-0.032317240447439999 -0.057533294341359995 -0.024340705105429999"/>
          <site name="semiten_r_semiten_r-P3" pos="0.0019680370785299999 -0.087545741192659995 -0.01243608077439"/>
          <site name="ST_at_condyles_r_cylinder_semiten_r_1_sidesite" pos="-0.03787 -0.00941 -0.02732" size="0.0005"/>
          <site name="soleus_r_soleus_r-P1" pos="-0.0078721483141199998 -0.10374113704071999 0.01041654628966"/>
          <site name="tfl_r_tfl_r-P4" pos="0.01118673707796 -0.046434351732200001 0.036776785879819994"/>
          <site name="tibant_r_tibant_r-P1" pos="0.015951458425979999 -0.14858992554304001 0.017219188764539997"/>
          <site name="tibant_r_tibant_r-P2" pos="0.02599880561637 -0.21586310829651997 0.01360528494976"/>
          <site name="tibant_r_tibant_r-P3" pos="0.024134349436710001 -0.41439827558077996 -0.01403045010444"/>
          <site name="tibpost_r_tibpost_r-P1" pos="-0.0042468168536699998 -0.14768388941167998 0.01094800273301"/>
          <site name="tibpost_r_tibpost_r-P2" pos="-0.016987267414679999 -0.41394525751509997 -0.018600975517250002"/>
          <site name="vasint_r_vasint_r-P5" pos="0.033736298761959001 -0.071576854377440005 0.00045705254128099995"/>
          <site name="vaslat_r_vaslat_r-P5" pos="0.033705224492298 -0.071780712506995997 0.0054314848510369999"/>
          <site name="vasmed_r_vasmed_r-P5" pos="0.033042306739529993 -0.071995896088193997 -0.0072065493718259993"/>
          <site name="R.HF_marker" group="4" pos="-0.008259 -0.08557 0.07253" rgba="1 0.1 0.5 0.5" size="0.01"/>
          <site name="R.TT_marker" group="4" pos="0.06709 -0.08588 0.01005" rgba="1 0.1 0.5 0.5" size="0.01"/>
          <site name="R.Ankle_marker" group="4" pos="-0.008082 -0.4633 0.06206" rgba="1 0.1 0.5 0.5" size="0.01"/>
          <site name="R.Ankle.Medialv_marker" group="4" pos="0.004784 -0.4468 -0.05396" rgba="1 0.1 0.5 0.5" size="0.01"/>
        </body>
        <body name="patella_r" pos="-0.008112 -0.4126 -0.002814" euler="-0 0 0">
          <inertial mass="0.0734658193723456" pos="0.0018 0.0264 0" fullinertia="2.4460197401233398e-06 1.1173281809413583e-05 1.1173281809413583e-05 0 0 0"/>
          <geom name="patella_r_geom_1" type="mesh" mesh="patella_r_geom_1_r_patella" rgba="1 1 1 1" group="0"/>
          <joint name="patellofemoral_r_translation1" range="-0.02276 0.05254" limited="true" user="0.052560152646325395" ref="0" axis="1 0 0" type="slide"/>
          <joint name="patellofemoral_r_translation2" range="-0.04127 -0.01092" limited="true" user="-0.010951646935493234" ref="0" axis="0 1 0" type="slide"/>
          <joint name="patellofemoral_r_translation3" limited="false" ref="0" axis="0 0 1" type="slide"/>
          <joint name="patellofemoral_r_rotation1" range="-1.786 0.001137" limited="true" user="0.01050598499723554" ref="0" axis="0 0 1" type="hinge"/>
          <site name="recfem_r_recfem_r-P2" pos="0.01 0.049000000000000002 0.00069999999999999999"/>
          <site name="recfem_r_recfem_r-P3" pos="0.0121 0.043700000000000003 -0.001"/>
          <site name="recfem_r_recfem_r-P4" pos="0.0050000000000000001 0.00247 3.0000000000000001e-05"/>
          <site name="vasint_r_vasint_r-P3" pos="0.0057999999999999996 0.048000000000000001 -0.00059999999999999995"/>
          <site name="vasint_r_vasint_r-P4" pos="0.0050000000000000001 0.00247 -0.00038999999999999999"/>
          <site name="vaslat_r_vaslat_r-P3" pos="0.0103 0.042299999999999997 0.0141"/>
          <site name="vaslat_r_vaslat_r-P4" pos="0.0050000000000000001 0.00247 0.0073299999999999997"/>
          <site name="vasmed_r_vasmed_r-P3" pos="0.0063 0.044499999999999998 -0.017000000000000001"/>
          <site name="vasmed_r_vasmed_r-P4" pos="0.0050000000000000001 0.00247 -0.0085000000000000006"/>
        </body>
        <site name="addbrev_r_addbrev_r-P2" pos="-0.0020053767200000003 -0.11934604213059999 0.025475228709539999"/>
        <site name="AB_at_femshaft_r_cylinder_addbrev_r_1_sidesite" pos="0.001556 -0.1072 0.0141" size="0.0005"/>
        <site name="addlong_r_addlong_r-P2" pos="0.011290270933599999 -0.24210052631187898 0.016195697609318001"/>
        <site name="AL_at_femshaft_r_cylinder_addlong_r_1_sidesite" pos="0.01129 -0.2421 0.0162" size="0.0005"/>
        <site name="addmagDist_r_addmagDist_r-P2" pos="0.011280244050000001 -0.26549437338374998 0.019745860003780001"/>
        <site name="AMdist_at_femshaft_r_cylinder_addmagDist_r_1_sidesite" pos="0.01128 -0.2655 0.01975" size="0.0005"/>
        <site name="addmagIsch_r_addmagIsch_r-P2" pos="0.0048229310116000004 -0.39239562682549894 -0.033486113882058001"/>
        <site name="AMisch_at_condyles_r_cylinder_addmagIsch_r_1_sidesite" pos="0.004823 -0.3924 -0.03349" size="0.0005"/>
        <site name="addmagMid_r_addmagMid_r-P2" pos="0.0024265058312000001 -0.16425251900007998 0.029895027425411998"/>
        <site name="AMmid_at_femshaft_r_cylinder_addmagMid_r_1_sidesite" pos="0.002427 -0.1643 0.0299" size="0.0005"/>
        <site name="addmagProx_r_addmagProx_r-P2" pos="-0.015311051257200002 -0.079759566800161996 0.032759711778291997"/>
        <site name="AMprox_at_femshaft_r_cylinder_addmagProx_r_1_sidesite" pos="-0.01621 -0.07409 0.01947" size="0.0005"/>
        <site name="bfsh_r_bfsh_r-P1" pos="0.0050134418000000007 -0.21350804655736999 0.023940576377640001"/>
        <site name="gaslat_r_gaslat_r-P1" pos="-0.0030080650800000004 -0.38575068193737999 0.028339913062419998"/>
        <site name="gasmed_r_gasmed_r-P1" pos="0.0080215068800000011 -0.38312102338196002 -0.021280512335679999"/>
        <site name="Gastroc_at_condyles_r_cylinder_gasmed_r_1_sidesite" pos="0.0005057 -0.4379 -0.0187" size="0.0005"/>
        <site name="glmax1_r_glmax1_r-P3" pos="-0.044519363184000002 -0.032971872656419994 0.030897666948919999"/>
        <site name="glmax1_r_glmax1_r-P4" pos="-0.027774467572 -0.057245643937219995 0.048085773066199995"/>
        <site name="glmax2_r_glmax2_r-P3" pos="-0.045120976200000003 -0.059066176783279994 0.02578215917592"/>
        <site name="glmax2_r_glmax2_r-P4" pos="-0.015641938415999999 -0.10275896508871998 0.042867955137739999"/>
        <site name="glmax3_r_glmax3_r-P3" pos="-0.028175542916000003 -0.11378330287874999 0.0096171546132399997"/>
        <site name="glmax3_r_glmax3_r-P4" pos="-0.0060161301600000008 -0.14351867269773 0.042049473894059997"/>
        <site name="glmed1_r_glmed1_r-P2_0" pos="-0.013929100753924168 -0.01850339533402625 0.060556991949424925"/>
        <site name="glmed2_r_glmed2_r-P2_0" pos="-0.022095255015202472 -0.010072701778964285 0.057422826638492699"/>
        <site name="glmed3_r_glmed3_r-P2_0" pos="-0.030983070324000002 -0.0047536135424900003 0.052996660528279997"/>
        <site name="glmin1_r_glmin1_r-P2" pos="0.0055040760431920568 -0.01566528169493199 0.057332363071595116"/>
        <site name="glmin2_r_glmin2_r-P2" pos="0.0035530672440839952 -0.0091150731568144083 0.053676335240096275"/>
        <site name="glmin3_r_glmin3_r-P2" pos="-0.0035857512819521386 -0.0012811501976789875 0.052445873323731178"/>
        <site name="iliacus_r_iliacus_r-P3" pos="-0.0023061832280000002 -0.057144503223549997 0.014221111608939999"/>
        <site name="iliacus_r_iliacus_r-P4" pos="-0.012232797992000001 -0.064426634607789995 0.020052790470159999"/>
        <site name="piri_r_piri_r-P3" pos="-0.014839787728000001 -0.0036410656921199995 0.044709537936019998"/>
        <site name="psoas_r_psoas_r-P3" pos="-0.013235486352000001 -0.047232713283889997 0.0047062671511599995"/>
        <site name="psoas_r_psoas_r-P4" pos="-0.023563176460000002 -0.052997733963079996 0.0090032936804799995"/>
        <site name="KnExt_at_fem_r_cylinder_recfem_r_3_sidesite" pos="-0.01585 -0.4015 -0.01441" size="0.0005"/>
        <site name="sart_r_sart_r-P2" pos="-0.0030080650800000004 -0.36087006637455998 -0.04307257544866"/>
        <site name="tfl_r_tfl_r-P2" pos="0.029479037784 -0.10063501010165 0.061079162809620002"/>
        <site name="tfl_r_tfl_r-P3" pos="0.010728765451999999 -0.40961989036349999 0.033148490369039996"/>
        <site name="vasint_r_vasint_r-P1" pos="0.029077962440000004 -0.19459473310107997 0.031716148192599998"/>
        <site name="vasint_r_vasint_r-P2" pos="0.033590060060000003 -0.21077724728827998 0.0291583943061"/>
        <site name="KnExt_at_fem_r_cylinder_vasint_r_3_sidesite" pos="-0.01608 -0.4007 -0.01381" size="0.0005"/>
        <site name="vaslat_r_vaslat_r-P1" pos="0.0048129041280000001 -0.18751488314417999 0.035706244255539997"/>
        <site name="vaslat_r_vaslat_r-P2" pos="0.026972316884000001 -0.26205558911896998 0.041844853583139996"/>
        <site name="KnExt_at_fem_r_cylinder_vaslat_r_3_sidesite" pos="-0.01911 -0.4014 0.01375" size="0.0005"/>
        <site name="vasmed_r_vasmed_r-P1" pos="0.01403763704 -0.21229435799332999 0.019234309226479999"/>
        <site name="vasmed_r_vasmed_r-P2" pos="0.035695705616000002 -0.28005863615222998 0.00092079139913999993"/>
        <site name="KnExt_at_fem_r_cylinder_vasmed_r_4_sidesite" pos="-0.007885 -0.4121 -0.02088" size="0.0005"/>
        <site name="KnExt_at_fem_r_cylinder_vasmed_r_3_sidesite" pos="-0.007885 -0.4121 -0.02088" size="0.0005"/>
        <site name="R.GTR_marker" group="4" pos="-0.006993 -0.02329 0.09829" rgba="1 0.1 0.5 0.5" size="0.01"/>
        <site name="R.Knee_marker" group="4" pos="-0.002143 -0.4096 0.06126" rgba="1 0.1 0.5 0.5" size="0.01"/>
        <site name="R.Knee.Medialv_marker" group="4" pos="-0.005466 -0.4105 -0.05698" rgba="1 0.1 0.5 0.5" size="0.01"/>
      </body>
      <body name="femur_l" pos="-0.06067 -0.07527 -0.08671" euler="-0 0 0">
        <inertial mass="9.3862162507" pos="0.0000000000 -0.1700000000 0.0000000000" fullinertia="0.1351209878 0.0354200648 0.1424875540 0.0000000000 0.0000000000 0.0000000000"/>
        <geom name="femur_l_geom_1" type="mesh" mesh="femur_l_geom_1_l_femur" rgba="1 1 1 1" group="0"/>
        <geom name="Gastroc_at_condyles_l_cylinder" type="cylinder" euler="0 0 0" pos="0.005013 -0.4147 0" size="0.02518 0.05116" rgba="0.19 0.83 0.78 0.2" group="2"/>
        <geom name="KnExt_at_fem_l_cylinder" type="cylinder" euler="0.06234 -0.05076 0" pos="0.003598 -0.4073 -0.002139" size="0.02518 0.05115" rgba="0.19 0.83 0.78 0.2" group="2"/>
        <geom name="AB_at_femshaft_l_cylinder" type="cylinder" euler="-1.662 -0.1866 0" pos="0.01468 -0.1139 -0.0239" size="0.01671 0.03539" rgba="0.19 0.83 0.78 0.2" group="2"/>
        <geom name="AL_at_femshaft_l_cylinder" type="cylinder" euler="-1.777 -0.1365 0" pos="0.03082 -0.2346 -0.01546" size="0.02036 0.05059" rgba="0.19 0.83 0.78 0.2" group="2"/>
        <geom name="AMprox_at_femshaft_l_cylinder" type="cylinder" euler="-1.611 -0.1866 0" pos="0.005197 -0.07373 -0.02599" size="0.02138 0.03539" rgba="0.19 0.83 0.78 0.2" group="2"/>
        <geom name="AMmid_at_femshaft_l_cylinder" type="cylinder" euler="-1.611 -0.1366 0" pos="0.02307 -0.1625 -0.02106" size="0.02168 0.06068" rgba="0.19 0.83 0.78 0.2" group="2"/>
        <geom name="AMdist_at_femshaft_l_cylinder" type="cylinder" euler="-1.712 -0.1866 0" pos="0.03169 -0.2637 -0.009581" size="0.02208 0.1011" rgba="0.19 0.83 0.78 0.2" group="2"/>
        <geom name="AMisch_at_condyles_l_cylinder" type="cylinder" euler="-1.711 0.4634 0" pos="-0.02271 -0.3811 0.003227" size="0.04055 0.1212" rgba="0.19 0.83 0.78 0.2" group="2"/>
        <geom name="PECT_at_femshaft_l_cylinder" type="cylinder" euler="-1.813 -0.2763 0" pos="0.006102 -0.08547 -0.03114" size="0.01519 0.02528" rgba="0.19 0.83 0.78 0.2" group="2"/>
        <joint name="hip_flexion_l" range="-0.5236 2.094" limited="true" user="0.0" ref="0" axis="0 0 1" type="hinge"/>
        <joint name="hip_adduction_l" range="-0.8727 0.5236" limited="true" user="-0.0" ref="0" axis="-1 -0 -0" type="hinge"/>
        <joint name="hip_rotation_l" range="-0.6981 0.6981" limited="true" user="-0.0" ref="0" axis="-0 -1 -0" type="hinge"/>
        <body name="tibia_l" pos="0.0002675 -0.4086 0.001235" euler="-0 0 0">
          <inertial mass="3.7413074107" pos="0.0000000000 -0.1867000000 0.0000000000" fullinertia="0.0508595802 0.0051465051 0.0515659632 0.0000000000 0.0000000000 0.0000000000"/>
          <geom name="tibia_l_geom_1" type="mesh" mesh="tibia_l_geom_1_l_tibia" rgba="1 1 1 1" group="0"/>
          <geom name="tibia_l_geom_2" type="mesh" mesh="tibia_l_geom_2_l_fibula" rgba="1 1 1 1" group="0"/>
          <geom name="GasLat_at_shank_l_cylinder" type="cylinder" euler="-2.967 0.2797 -1.478" pos="-0.007665 -0.08381 0.003508" size="0.05964 0.05314" rgba="0.19 0.83 0.78 0.2" group="2"/>
          <site name="GasLat_at_shank_l_sidesite" pos="-0.0657 -0.07539 -0.01194" size="0.0005"/>
          <geom name="GasMed_at_shank_l_cylinder" type="cylinder" euler="-2.967 -0.02797 -1.478" pos="-0.007665 -0.08381 0.003508" size="0.05958 0.05325" rgba="0.19 0.83 0.78 0.2" group="2"/>
          <site name="GasMed_at_shank_l_sidesite" pos="-0.06796 -0.07858 0.006142" size="0.0005"/>
          <geom name="GR_at_condyles_l_cylinder" type="cylinder" euler="0 0.4 0" pos="-0.003107 -0.02265 0" size="0.03911 0.05294" rgba="0.19 0.83 0.78 0.2" group="2"/>
          <geom name="SM_at_condyles_l_cylinder" type="cylinder" euler="0 0.1 0" pos="-0.001036 -0.02265 0" size="0.03817 0.05313" rgba="0.19 0.83 0.78 0.2" group="2"/>
          <geom name="ST_at_condyles_l_cylinder" type="cylinder" euler="0 0.2 0" pos="-0.002072 -0.02322 0" size="0.0461 0.05309" rgba="0.19 0.83 0.78 0.2" group="2"/>
          <geom name="BF_at_gastroc_l_cylinder" type="cylinder" euler="0 0 0" pos="-0.06008 -0.06795 0" size="0.03253 0.07972" rgba="0.19 0.83 0.78 0.2" group="2"/>
          <joint name="walker_knee_l_translation1" range="0 0.001617" limited="true" user="9.646127779438379e-08" ref="0" axis="-0.1243 0.9898 0.07016" type="slide"/>
          <joint name="walker_knee_l_translation2" range="-0.006949 0" limited="true" user="-7.870253233843716e-11" ref="0" axis="-0.9922 -0.124 -0.008789" type="slide"/>
          <joint name="knee_angle_l" range="0 2.094" limited="true" user="0.0" ref="0" axis="4.566e-07 0.07071 -0.9975" type="hinge"/>
          <joint name="walker_knee_l_rotation2" range="-0.001678 0.03354" limited="true" user="-1.4732523263838448e-08" ref="0" axis="-0.9922 -0.124 -0.008789" type="hinge"/>
          <joint name="walker_knee_l_rotation3" range="-0.2628 0" limited="true" user="-1.0893911855935912e-08" ref="0" axis="-0.1243 0.9898 0.07016" type="hinge"/>
          <body name="talus_l" pos="-0.01036 -0.453 0" euler="-0 0 0">
            <inertial mass="0.1009118654" pos="0.0000000000 0.0000000000 0.0000000000" fullinertia="0.0010091187 0.0010091187 0.0010091187 0.0000000000 0.0000000000 0.0000000000"/>
            <geom name="talus_l_geom_1" type="mesh" mesh="talus_l_geom_1_l_talus" rgba="1 1 1 0" group="0"/>
            <joint name="ankle_angle_l" range="-0.6981 0.5236" limited="true" user="0.0" ref="0" type="hinge" axis="0.105 0.174 0.9791"/>
            <body name="calcn_l" pos="-0.05453 -0.04909 -0.009075" euler="-0 0 0">
              <inertial mass="1.2613983178" pos="0.1000000000 0.0300000000 0.0000000000" fullinertia="0.0014127661 0.0039355628 0.0041373865 0.0000000000 0.0000000000 0.0000000000"/>
              <geom name="calcn_l_geom_1" type="mesh" mesh="calcn_l_geom_1_l_foot" rgba="1 1 1 1" group="0"/>
              <joint name="subtalar_angle_l" range="-0.3491 0.3491" limited="true" user="0.0" ref="0" type="hinge" axis="-0.7872 -0.6047 -0.1209"/>
              <body name="toes_l" pos="0.2032 -0.002207 -0.001198" euler="-0 0 0">
                <inertial mass="0.2185751005" pos="0.0346000000 0.0060000000 0.0175000000" fullinertia="0.0006362493 0.0007371612 0.0010091187 0.0000000000 0.0000000000 0.0000000000"/>
                <geom name="toes_l_geom_1" type="mesh" mesh="toes_l_geom_1_l_bofoot" rgba="1 1 1 1" group="0"/>
                <joint name="mtp_angle_l" range="-0.5236 0.5236" limited="true" user="0.0" ref="0" type="hinge" axis="-0.581 2.16e-06 -0.8139"/>
                <site name="edl_l_edl_l-P5" pos="0.00032909191158000001 0.0051553221265400002 -0.01678671107811"/>
                <site name="edl_l_edl_l-P6" pos="0.048595905609979999 -0.00043875081928000008 -0.027429266467500005"/>
                <site name="ehl_l_ehl_l-P7" pos="0.032689796550280002 0.0044971958976200007 0.026880681138150002"/>
                <site name="ehl_l_ehl_l-P8" pos="0.061759582073180004 0.00372938196388 0.020407374251820001"/>
                <site name="fdl_l_fdl_l-P6" pos="-0.00208424877334 -0.0085556409759600001 -0.016128408682890002"/>
                <site name="fdl_l_fdl_l-P7" pos="0.0312637316001 -0.0077878270422200007 -0.023589169162049999"/>
                <site name="fdl_l_fdl_l-P8" pos="0.048376511002260002 -0.0065812622892000008 -0.026551529940540001"/>
                <site name="fhl_l_fhl_l-P6" pos="0.017003082098299999 -0.0070200131084800013 0.029075022455550003"/>
                <site name="fhl_l_fhl_l-P7" pos="0.061649884769320006 -0.011188145891640001 0.019858788922470002"/>
              </body>
              <site name="edl_l_edl_l-P3" pos="0.10445990896407999 0.039718476018 -0.00088708895976000006"/>
              <site name="edl_l_edl_l-P4" pos="0.18368575939711998 0.0060681005027500004 -0.0144151955961"/>
              <site name="ehl_l_ehl_l-P4" pos="0.1102569224104 0.042918019919449997 0.023396971313669999"/>
              <site name="ehl_l_ehl_l-P5" pos="0.14697134090375999 0.034091691915450001 0.028497732832289999"/>
              <site name="ehl_l_ehl_l-P6" pos="0.19709845717487998 0.01533574490695 0.0310481135916"/>
              <site name="fdl_l_fdl_l-P3" pos="0.049558781619519994 0.034753666515750001 0.0310481135916"/>
              <site name="fdl_l_fdl_l-P4" pos="0.080476186666559993 0.019417921608800001 0.02916304955211"/>
              <site name="fdl_l_fdl_l-P5" pos="0.18845977047055998 -0.0089366571040500001 -0.012862789916519998"/>
              <site name="fhl_l_fhl_l-P3" pos="0.042511431939680003 0.030450831613800002 0.026723554912769999"/>
              <site name="fhl_l_fhl_l-P4" pos="0.11798627367216 0.0075023788033999998 0.028386846712320002"/>
              <site name="fhl_l_fhl_l-P5" pos="0.19618912173232 -0.0058474423026500001 0.029828366271929998"/>
              <site name="gaslat_l_gaslat_l-P2" pos="0.0050013449340799996 0.034202021015500003 0.0058769643584099997"/>
              <site name="gasmed_l_gasmed_l-P2" pos="0.0050013449340799996 0.034202021015500003 0.0058769643584099997"/>
              <site name="perbrev_l_perbrev_l-P4" pos="0.05353712418072 0.029788857013500002 -0.02583646595301"/>
              <site name="perbrev_l_perbrev_l-P5" pos="0.076952511826639994 0.024162072910949999 -0.038033939149709997"/>
              <site name="perlong_l_perlong_l-P4" pos="0.049786115480159994 0.0253756930115 -0.024505832513370001"/>
              <site name="perlong_l_perlong_l-P5" pos="0.077407179547919994 0.0116948846053 -0.031491658071480001"/>
              <site name="perlong_l_perlong_l-P6" pos="0.096844224632639989 0.0076127079034500004 -0.013084562156459999"/>
              <site name="perlong_l_perlong_l-P7" pos="0.13674131717495999 0.0093779735042500006 0.02040304607448"/>
              <site name="soleus_l_soleus_l-P2" pos="0.0050013449340799996 0.034202021015500003 0.0058769643584099997"/>
              <site name="tibant_l_tibant_l-P4" pos="0.13253564075311999 0.019638579808900002 0.033820266590849996"/>
              <site name="tibpost_l_tibpost_l-P3" pos="0.047399109943439995 0.036849919416700003 0.031713430311420002"/>
              <site name="tibpost_l_tibpost_l-P4" pos="0.087750870207040005 0.01754232690795 0.031158999711570001"/>
              <site name="L.Heel_marker" group="4" pos="-0.02683 0.021 0.005195" rgba="1 0.1 0.5 0.5" size="0.01"/>
              <site name="L.MT1_marker" group="4" pos="0.22 0.02703 0.02729" rgba="1 0.1 0.5 0.5" size="0.01"/>
              <site name="L.MT2_marker" group="4" pos="0.2064 0.02582 -0.003505" rgba="1 0.1 0.5 0.5" size="0.01"/>
              <site name="L.MT5_marker" group="4" pos="0.1591 0.02325 -0.06441" rgba="1 0.1 0.5 0.5" size="0.01"/>
            </body>
          </body>
          <site name="bflh_l_bflh_l-P2" pos="-0.034906762919189996 -0.039639080747000004 -0.026891696033509997"/>
          <site name="bflh_l_bflh_l-P3" pos="-0.029727717975689998 -0.051530804971099999 -0.032206260467010001"/>
          <site name="bfsh_l_bfsh_l-P2" pos="-0.031177850559869998 -0.047453642379979996 -0.03380062979706"/>
          <site name="edl_l_edl_l-P1" pos="-0.016572943819199999 -0.13103547549793998 -0.021789714177350001"/>
          <site name="edl_l_edl_l-P2" pos="0.016987267414679999 -0.42583698173919998 -0.01190462433104"/>
          <site name="ehl_l_ehl_l-P1" pos="-0.0145013258418 -0.17554450045099998 -0.020089053558629999"/>
          <site name="ehl_l_ehl_l-P2" pos="0.00735424381977 -0.32945738826577997 -0.017431771341880002"/>
          <site name="ehl_l_ehl_l-P3" pos="0.020716179774000001 -0.41824892913905998 0.00297615608276"/>
          <site name="fdl_l_fdl_l-P1" pos="-0.0023823606740099998 -0.20748227408143999 0.0019132431960599999"/>
          <site name="fdl_l_fdl_l-P2" pos="-0.018230238201119998 -0.41281271235089995 0.013180119795079999"/>
          <site name="fhl_l_fhl_l-P1" pos="-0.032110078649699995 -0.24496951901645997 -0.021258257733999999"/>
          <site name="fhl_l_fhl_l-P2" pos="-0.025066577526539999 -0.41575732977781998 0.0080781379389199999"/>
          <site name="GasLat_at_shank_l_cylinder_gaslat_l_1_sidesite" pos="-0.02508 -0.0889 -0.05436" size="0.0005"/>
          <site name="grac_l_grac_l-P2" pos="-0.019079601571853996 -0.053852522557710003 0.031472850575186999"/>
          <site name="grac_l_grac_l-P3" pos="0.0018437399998859998 -0.078847794331603993 0.016719619707791001"/>
          <site name="GR_at_condyles_l_cylinder_grac_l_1_sidesite" pos="-0.01592 -0.007885 0.03441" size="0.0005"/>
          <site name="perbrev_l_perbrev_l-P1" pos="-0.025170158425409997 -0.28676043557543995 -0.026679113456169998"/>
          <site name="perbrev_l_perbrev_l-P2" pos="-0.035113924716929999 -0.44089983242305997 -0.026466530878829997"/>
          <site name="perbrev_l_perbrev_l-P3" pos="-0.029520556177949998 -0.45347108374567996 -0.027104278610849998"/>
          <site name="perlong_l_perlong_l-P1" pos="-0.020716179774000001 -0.15549845104466001 -0.029974143404939996"/>
          <site name="perlong_l_perlong_l-P2" pos="-0.032835144941789997 -0.44169261403799998 -0.025191035414789998"/>
          <site name="perlong_l_perlong_l-P3" pos="-0.028174004492639997 -0.45460362890987993 -0.025509909280799999"/>
          <site name="recfem_l_recfem_l-P5" pos="0.033767373031619995 -0.071486250764303996 0.00049956905674899998"/>
          <site name="sart_l_sart_l-P3" pos="-0.02599880561637 -0.045415061084419991 0.038796320364549997"/>
          <site name="sart_l_sart_l-P4" pos="-0.016469362920330001 -0.067839455335580001 0.02806090020888"/>
          <site name="sart_l_sart_l-P5" pos="0.014087002246319999 -0.091736158300200002 0.0027635735054199998"/>
          <site name="semimem_l_semimem_l-P2" pos="-0.0300384606723 -0.047227133347140002 0.020833092579319999"/>
          <site name="SM_at_condyles_l_cylinder_semimem_l_1_sidesite" pos="-0.03181 -0.0003635 0.02036" size="0.0005"/>
          <site name="semiten_l_semiten_l-P2" pos="-0.032317240447439999 -0.057533294341359995 0.024340705105429999"/>
          <site name="semiten_l_semiten_l-P3" pos="0.0019680370785299999 -0.087545741192659995 0.01243608077439"/>
          <site name="ST_at_condyles_l_cylinder_semiten_l_1_sidesite" pos="-0.03787 -0.00941 0.02732" size="0.0005"/>
          <site name="soleus_l_soleus_l-P1" pos="-0.0078721483141199998 -0.10374113704071999 -0.01041654628966"/>
          <site name="tfl_l_tfl_l-P4" pos="0.01118673707796 -0.046434351732200001 -0.036776785879819994"/>
          <site name="tibant_l_tibant_l-P1" pos="0.015951458425979999 -0.14858992554304001 -0.017219188764539997"/>
          <site name="tibant_l_tibant_l-P2" pos="0.02599880561637 -0.21586310829651997 -0.01360528494976"/>
          <site name="tibant_l_tibant_l-P3" pos="0.024134349436710001 -0.41439827558077996 0.01403045010444"/>
          <site name="tibpost_l_tibpost_l-P1" pos="-0.0042468168536699998 -0.14768388941167998 -0.01094800273301"/>
          <site name="tibpost_l_tibpost_l-P2" pos="-0.016987267414679999 -0.41394525751509997 0.018600975517250002"/>
          <site name="vasint_l_vasint_l-P5" pos="0.033736298761959001 -0.071576854377440005 -0.00045705254128099995"/>
          <site name="vaslat_l_vaslat_l-P5" pos="0.033705224492298 -0.071780712506995997 -0.0054314848510369999"/>
          <site name="vasmed_l_vasmed_l-P5" pos="0.033042306739529993 -0.071995896088193997 0.0072065493718259993"/>
          <site name="L.HF_marker" group="4" pos="-0.005997 -0.08604 -0.0717" rgba="1 0.1 0.5 0.5" size="0.01"/>
          <site name="L.TT_marker" group="4" pos="0.06911 -0.0846 -0.0135" rgba="1 0.1 0.5 0.5" size="0.01"/>
          <site name="L.Ankle_marker" group="4" pos="-0.01004 -0.4677 -0.06333" rgba="1 0.1 0.5 0.5" size="0.01"/>
          <site name="L.Ankle.Medialv_marker" group="4" pos="0.002981 -0.4459 0.04961" rgba="1 0.1 0.5 0.5" size="0.01"/>
        </body>
        <body name="patella_l" pos="-0.008112 -0.4126 0.002814" euler="-0 0 0">
          <inertial mass="0.0734658193723456" pos="0.0018 0.0264 0" fullinertia="2.4460197401233398e-06 1.1173281809413583e-05 1.1173281809413583e-05 0 0 0"/>
          <geom name="patella_l_geom_1" type="mesh" mesh="patella_l_geom_1_l_patella" rgba="1 1 1 1" group="0"/>
          <joint name="patellofemoral_l_translation1" range="-0.02276 0.05254" limited="true" user="0.052560152646325395" ref="0" axis="1 0 0" type="slide"/>
          <joint name="patellofemoral_l_translation2" range="-0.04127 -0.01092" limited="true" user="-0.010951646935493234" ref="0" axis="0 1 0" type="slide"/>
          <joint name="patellofemoral_l_translation3" limited="false" ref="0" axis="0 0 1" type="slide"/>
          <joint name="patellofemoral_l_rotation1" range="-1.786 0.001137" limited="true" user="0.01050598499723554" ref="0" axis="0 0 1" type="hinge"/>
          <site name="recfem_l_recfem_l-P2" pos="0.01 0.049000000000000002 -0.00069999999999999999"/>
          <site name="recfem_l_recfem_l-P3" pos="0.0121 0.043700000000000003 0.001"/>
          <site name="recfem_l_recfem_l-P4" pos="0.0050000000000000001 0.00247 -3.0000000000000001e-05"/>
          <site name="vasint_l_vasint_l-P3" pos="0.0057999999999999996 0.048000000000000001 0.00059999999999999995"/>
          <site name="vasint_l_vasint_l-P4" pos="0.0050000000000000001 0.00247 0.00038999999999999999"/>
          <site name="vaslat_l_vaslat_l-P3" pos="0.0103 0.042299999999999997 -0.0141"/>
          <site name="vaslat_l_vaslat_l-P4" pos="0.0050000000000000001 0.00247 -0.0073299999999999997"/>
          <site name="vasmed_l_vasmed_l-P3" pos="0.0063 0.044499999999999998 0.017000000000000001"/>
          <site name="vasmed_l_vasmed_l-P4" pos="0.0050000000000000001 0.00247 0.0085000000000000006"/>
        </body>
        <site name="addbrev_l_addbrev_l-P2" pos="-0.0020053767200000003 -0.11934604213059999 -0.025475228709539999"/>
        <site name="AB_at_femshaft_l_cylinder_addbrev_l_1_sidesite" pos="0.001556 -0.1072 -0.0141" size="0.0005"/>
        <site name="addlong_l_addlong_l-P2" pos="0.011290270933599999 -0.24210052631187898 -0.016195697609318001"/>
        <site name="AL_at_femshaft_l_cylinder_addlong_l_1_sidesite" pos="0.01129 -0.2421 -0.0162" size="0.0005"/>
        <site name="addmagDist_l_addmagDist_l-P2" pos="0.011280244050000001 -0.26549437338374998 -0.019745860003780001"/>
        <site name="AMdist_at_femshaft_l_cylinder_addmagDist_l_1_sidesite" pos="0.01128 -0.2655 -0.01975" size="0.0005"/>
        <site name="addmagIsch_l_addmagIsch_l-P2" pos="0.0048229310116000004 -0.39239562682549894 0.033486113882058001"/>
        <site name="AMisch_at_condyles_l_cylinder_addmagIsch_l_1_sidesite" pos="0.004823 -0.3924 0.03349" size="0.0005"/>
        <site name="addmagMid_l_addmagMid_l-P2" pos="0.0024265058312000001 -0.16425251900007998 -0.029895027425411998"/>
        <site name="AMmid_at_femshaft_l_cylinder_addmagMid_l_1_sidesite" pos="0.002427 -0.1643 -0.0299" size="0.0005"/>
        <site name="addmagProx_l_addmagProx_l-P2" pos="-0.015311051257200002 -0.079759566800161996 -0.032759711778291997"/>
        <site name="AMprox_at_femshaft_l_cylinder_addmagProx_l_1_sidesite" pos="-0.01621 -0.07409 -0.01947" size="0.0005"/>
        <site name="bfsh_l_bfsh_l-P1" pos="0.0050134418000000007 -0.21350804655736999 -0.023940576377640001"/>
        <site name="gaslat_l_gaslat_l-P1" pos="-0.0030080650800000004 -0.38575068193737999 -0.028339913062419998"/>
        <site name="gasmed_l_gasmed_l-P1" pos="0.0080215068800000011 -0.38312102338196002 0.021280512335679999"/>
        <site name="Gastroc_at_condyles_l_cylinder_gasmed_l_1_sidesite" pos="0.0005057 -0.4379 0.0187" size="0.0005"/>
        <site name="glmax1_l_glmax1_l-P3" pos="-0.044519363184000002 -0.032971872656419994 -0.030897666948919999"/>
        <site name="glmax1_l_glmax1_l-P4" pos="-0.027774467572 -0.057245643937219995 -0.048085773066199995"/>
        <site name="glmax2_l_glmax2_l-P3" pos="-0.045120976200000003 -0.059066176783279994 -0.02578215917592"/>
        <site name="glmax2_l_glmax2_l-P4" pos="-0.015641938415999999 -0.10275896508871998 -0.042867955137739999"/>
        <site name="glmax3_l_glmax3_l-P3" pos="-0.028175542916000003 -0.11378330287874999 -0.0096171546132399997"/>
        <site name="glmax3_l_glmax3_l-P4" pos="-0.0060161301600000008 -0.14351867269773 -0.042049473894059997"/>
        <site name="glmed1_l_glmed1_l-P2" pos="-0.01403763704 -0.018205328460599999 -0.060362991721399993"/>
        <site name="glmed2_l_glmed2_l-P2" pos="-0.02205914392 -0.010114071367 -0.057293687057599997"/>
        <site name="glmed3_l_glmed3_l-P2" pos="-0.030983070324000002 -0.0047536135424900003 -0.052996660528279997"/>
        <site name="glmin1_l_glmin1_l-P2" pos="0.0050134418000000007 -0.015171107050499998 -0.057293687057599997"/>
        <site name="glmin2_l_glmin2_l-P2" pos="0.0040107534400000006 -0.0091026642302999995 -0.053201280839199998"/>
        <site name="glmin3_l_glmin3_l-P2" pos="-0.0040107534400000006 -0.0010114071367 -0.052178179284599994"/>
        <site name="iliacus_l_iliacus_l-P3" pos="-0.0023061832280000002 -0.057144503223549997 -0.014221111608939999"/>
        <site name="iliacus_l_iliacus_l-P4" pos="-0.012232797992000001 -0.064426634607789995 -0.020052790470159999"/>
        <site name="piri_l_piri_l-P3" pos="-0.014839787728000001 -0.0036410656921199995 -0.044709537936019998"/>
        <site name="psoas_l_psoas_l-P3" pos="-0.013235486352000001 -0.047232713283889997 -0.0047062671511599995"/>
        <site name="psoas_l_psoas_l-P4" pos="-0.023563176460000002 -0.052997733963079996 -0.0090032936804799995"/>
        <site name="KnExt_at_fem_l_cylinder_recfem_l_3_sidesite" pos="-0.01585 -0.4015 0.01441" size="0.0005"/>
        <site name="sart_l_sart_l-P2" pos="-0.0030080650800000004 -0.36087006637455998 0.04307257544866"/>
        <site name="tfl_l_tfl_l-P2" pos="0.029479037784 -0.10063501010165 -0.061079162809620002"/>
        <site name="tfl_l_tfl_l-P3" pos="0.010728765451999999 -0.40961989036349999 -0.033148490369039996"/>
        <site name="vasint_l_vasint_l-P1" pos="0.029077962440000004 -0.19459473310107997 -0.031716148192599998"/>
        <site name="vasint_l_vasint_l-P2" pos="0.033590060060000003 -0.21077724728827998 -0.0291583943061"/>
        <site name="KnExt_at_fem_l_cylinder_vasint_l_3_sidesite" pos="-0.01608 -0.4007 0.01381" size="0.0005"/>
        <site name="vaslat_l_vaslat_l-P1" pos="0.0048129041280000001 -0.18751488314417999 -0.035706244255539997"/>
        <site name="vaslat_l_vaslat_l-P2" pos="0.026972316884000001 -0.26205558911896998 -0.041844853583139996"/>
        <site name="KnExt_at_fem_l_cylinder_vaslat_l_3_sidesite" pos="-0.01911 -0.4014 -0.01375" size="0.0005"/>
        <site name="vasmed_l_vasmed_l-P1" pos="0.01403763704 -0.21229435799332999 -0.019234309226479999"/>
        <site name="vasmed_l_vasmed_l-P2" pos="0.035695705616000002 -0.28005863615222998 -0.00092079139913999993"/>
        <site name="KnExt_at_fem_l_cylinder_vasmed_l_4_sidesite" pos="-0.007885 -0.4121 0.02088" size="0.0005"/>
        <site name="KnExt_at_fem_l_cylinder_vasmed_l_3_sidesite" pos="-0.007885 -0.4121 0.02088" size="0.0005"/>
        <site name="L.GTR_marker" group="4" pos="-0.00944 -0.02371 -0.09299" rgba="1 0.1 0.5 0.5" size="0.01"/>
        <site name="L.Knee_marker" group="4" pos="-0.0007695 -0.4093 -0.05891" rgba="1 0.1 0.5 0.5" size="0.01"/>
        <site name="L.Knee.Medialv_marker" group="4" pos="-0.002241 -0.4103 0.05723" rgba="1 0.1 0.5 0.5" size="0.01"/>
      </body>
      <body name="torso" pos="-0.1086 0.07816 0" euler="-0 0 0">
        <inertial mass="34.5487917184" pos="-0.0300000000 0.3200000000 0.0000000000" fullinertia="1.4879454557 0.7623891433 1.4444524417 0.0000000000 0.0000000000 0.0000000000"/>
        <geom name="torso_geom_1" type="mesh" mesh="torso_geom_1_hat_spine" rgba="1 1 1 1" group="0"/>
        <geom name="torso_geom_2" type="mesh" mesh="torso_geom_2_hat_jaw" rgba="1 1 1 1" group="0"/>
        <geom name="torso_geom_3" type="mesh" mesh="torso_geom_3_hat_skull" rgba="1 1 1 1" group="0"/>
        <geom name="torso_geom_4" type="mesh" mesh="torso_geom_4_hat_ribs_scap" rgba="1 1 1 1" group="0"/>
        <joint name="lumbar_extension" range="-1.571 1.571" limited="true" user="0.0" ref="0" axis="0 0 1" type="hinge"/>
        <joint name="lumbar_bending" range="-1.571 1.571" limited="true" user="0.0" ref="0" axis="1 0 0" type="hinge"/>
        <joint name="lumbar_rotation" range="-1.571 1.571" limited="true" user="0.0" ref="0" axis="0 1 0" type="hinge"/>
        <site name="R.Front.Head_marker" group="4" pos="0.03045 0.6462 0.06673" rgba="1 0.1 0.5 0.5" size="0.01"/>
        <site name="R.Back.Head_marker" group="4" pos="-0.1067 0.5941 0.04888" rgba="1 0.1 0.5 0.5" size="0.01"/>
        <site name="L.Front.Head_marker" group="4" pos="0.04183 0.6472 -0.06753" rgba="1 0.1 0.5 0.5" size="0.01"/>
        <site name="L.Back.Head_marker" group="4" pos="-0.07751 0.5989 -0.08848" rgba="1 0.1 0.5 0.5" size="0.01"/>
        <site name="R.Shoulder_marker" group="4" pos="-0.008093 0.4081 0.149" rgba="1 0.1 0.5 0.5" size="0.01"/>
        <site name="L.Shoulder_marker" group="4" pos="-0.006876 0.4078 -0.1501" rgba="1 0.1 0.5 0.5" size="0.01"/>
        <site name="C7_marker" group="4" pos="-0.08775 0.4234 0.003505" rgba="1 0.1 0.5 0.5" size="0.01"/>
        <site name="T2_marker" group="4" pos="-0.133 0.3808 -0.0005287" rgba="1 0.1 0.5 0.5" size="0.01"/>
        <site name="T7_marker" group="4" pos="-0.1455 0.2418 -0.0007485" rgba="1 0.1 0.5 0.5" size="0.01"/>
        <site name="L1_marker" group="4" pos="-0.0827 0.07466 -0.0004798" rgba="1 0.1 0.5 0.5" size="0.01"/>
        <site name="L3_marker" group="4" pos="-0.0675 0.03974 -0.002831" rgba="1 0.1 0.5 0.5" size="0.01"/>
        <site name="L5_marker" group="4" pos="-0.07105 0.006115 -0.0001132" rgba="1 0.1 0.5 0.5" size="0.01"/>
        <site name="IJ_marker" group="4" pos="0.05303 0.3781 -0.0003954" rgba="1 0.1 0.5 0.5" size="0.01"/>
        <site name="PX_marker" group="4" pos="0.1229 0.2134 -0.0001295" rgba="1 0.1 0.5 0.5" size="0.01"/>
      </body>
      <site name="addbrev_r_addbrev_r-P1" pos="-0.020590952041329998 -0.090144845567199997 0.017282955358899999"/>
      <site name="addlong_r_addlong_r-P1" pos="-0.0081716971975539995 -0.085254008201320008 0.02118845436208"/>
      <site name="addmagDist_r_addmagDist_r-P1" pos="-0.079819585818851999 -0.122433962059196 0.044688784570869999"/>
      <site name="addmagIsch_r_addmagIsch_r-P1" pos="-0.096615765546806009 -0.12443824639148798 0.046809874546734992"/>
      <site name="addmagMid_r_addmagMid_r-P1" pos="-0.056770656256358 -0.1157977670451 0.032029580905389994"/>
      <site name="addmagProx_r_addmagProx_r-P1" pos="-0.033398308598973997 -0.10313912915694001 0.015318983159024999"/>
      <site name="bflh_r_bflh_r-P1" pos="-0.11211827289519999 -0.11421543730908 0.065765011950099997"/>
      <site name="glmax1_r_glmax1_r-P1" pos="-0.13270922493653001 0.033085076298600004 0.063183791344550003"/>
      <site name="glmax1_r_glmax1_r-P2" pos="-0.13551218175891 -0.023207502794959999 0.087424819640149989"/>
      <site name="Gmax1_at_pelvis_r_cylinder_glmax1_r_2_sidesite" pos="-0.1119 -0.08935 0.1109" size="0.0005"/>
      <site name="glmax2_r_glmax2_r-P1" pos="-0.14198054365671001 0.0083431931535600003 0.051848866076699994"/>
      <site name="glmax2_r_glmax2_r-P2" pos="-0.14489130651071999 -0.058402352074920005 0.091240537057049986"/>
      <site name="Gmax2_at_pelvis_r_cylinder_glmax2_r_2_sidesite" pos="-0.1275 -0.09215 0.1007" size="0.0005"/>
      <site name="glmax3_r_glmax3_r-P1" pos="-0.140147841119 -0.050346855236999999 0.010100428456499999"/>
      <site name="glmax3_r_glmax3_r-P2" pos="-0.13723707826498999 -0.12112014888443999 0.048818737539749996"/>
      <site name="glmed1_r_glmed1_r-P1" pos="-0.052973087432128786 0.025080651238836925 0.12938466499557541"/>
      <site name="glmed2_r_glmed2_r-P1" pos="-0.091341167262509862 0.052393255411869698 0.092007631500128959"/>
      <site name="glmed3_r_glmed3_r-P1" pos="-0.10766135489641074 0.01492126267845152 0.071714869840763557"/>
      <site name="glmin1_r_glmin1_r-P1" pos="-0.03188852252452222 -0.00010377843621085129 0.1329379205510233"/>
      <site name="glmin2_r_glmin2_r-P1" pos="-0.066408513839090508 0.009590132781157109 0.11351235356155125"/>
      <site name="glmin3_r_glmin3_r-P1" pos="-0.085058958956069991 -0.0148643096414 0.089557132314299986"/>
      <site name="grac_r_grac_r-P1" pos="-0.051056936579968001 -0.12401629179521599 0.027562946987959996"/>
      <site name="iliacus_r_iliacus_r-P1" pos="-0.065222649136150002 0.029632720510920002 0.094607346542549986"/>
      <site name="iliacus_r_iliacus_r-P2" pos="-0.01455381427005 -0.053415615937160002 0.084843599034599995"/>
      <site name="IL_at_brim_r_cylinder_iliacus_r_2_sidesite" pos="-0.02879 -0.09324 0.09328" size="0.0005"/>
      <site name="piri_r_piri_r-P1" pos="-0.109757320802503 -0.0062621898037640003 0.015161865383034998"/>
      <site name="piri_r_piri_r-P2" pos="-0.10998371346892599 -0.029402563458407999 0.06836867795222"/>
      <site name="psoas_r_psoas_r-P1" pos="-0.065330455167779994 0.0594572385656 0.043768523311499996"/>
      <site name="psoas_r_psoas_r-P2" pos="-0.02210023648415 -0.062717796809519999 0.073620900749599996"/>
      <site name="PS_at_brim_r_cylinder_psoas_r_2_sidesite" pos="-0.04177 -0.09236 0.08229" size="0.0005"/>
      <site name="recfem_r_recfem_r-P1" pos="-0.025873447591199999 -0.037208723489440002 0.10470777499904999"/>
      <site name="sart_r_sart_r-P1" pos="-0.021022176167850001 -0.01496020841328 0.11851169388959999"/>
      <site name="semimem_r_semimem_r-P1" pos="-0.10640455321881 -0.1093245999432 0.068907367469899991"/>
      <site name="semiten_r_semiten_r-P1" pos="-0.11190266083194 -0.12016116116563999 0.057796896167749995"/>
      <site name="tfl_r_tfl_r-P1" pos="-0.021927515859779315 0.010406307903897528 0.1451067345944895"/>
      <site name="addbrev_l_addbrev_l-P1" pos="-0.020590952041329998 -0.090144845567199997 -0.017282955358899999"/>
      <site name="addlong_l_addlong_l-P1" pos="-0.0081716971975539995 -0.085254008201320008 -0.02118845436208"/>
      <site name="addmagDist_l_addmagDist_l-P1" pos="-0.079819585818851999 -0.122433962059196 -0.044688784570869999"/>
      <site name="addmagIsch_l_addmagIsch_l-P1" pos="-0.096615765546806009 -0.12443824639148798 -0.046809874546734992"/>
      <site name="addmagMid_l_addmagMid_l-P1" pos="-0.056770656256358 -0.1157977670451 -0.032029580905389994"/>
      <site name="addmagProx_l_addmagProx_l-P1" pos="-0.033398308598973997 -0.10313912915694001 -0.015318983159024999"/>
      <site name="bflh_l_bflh_l-P1" pos="-0.11211827289519999 -0.11421543730908 -0.065765011950099997"/>
      <site name="glmax1_l_glmax1_l-P1" pos="-0.13270922493653001 0.033085076298600004 -0.063183791344550003"/>
      <site name="glmax1_l_glmax1_l-P2" pos="-0.13551218175891 -0.023207502794959999 -0.087424819640149989"/>
      <site name="Gmax1_at_pelvis_l_cylinder_glmax1_l_2_sidesite" pos="-0.1119 -0.08935 -0.1109" size="0.0005"/>
      <site name="glmax2_l_glmax2_l-P1" pos="-0.14198054365671001 0.0083431931535600003 -0.051848866076699994"/>
      <site name="glmax2_l_glmax2_l-P2" pos="-0.14489130651071999 -0.058402352074920005 -0.091240537057049986"/>
      <site name="Gmax2_at_pelvis_l_cylinder_glmax2_l_2_sidesite" pos="-0.1275 -0.09215 -0.1007" size="0.0005"/>
      <site name="glmax3_l_glmax3_l-P1" pos="-0.140147841119 -0.050346855236999999 -0.010100428456499999"/>
      <site name="glmax3_l_glmax3_l-P2" pos="-0.13723707826498999 -0.12112014888443999 -0.048818737539749996"/>
      <site name="glmed1_l_glmed1_l-P1" pos="-0.052824955498700005 0.024933680688799999 -0.12906103027749999"/>
      <site name="glmed2_l_glmed2_l-P1" pos="-0.091635126885500004 0.052744324533999999 -0.092026125936999992"/>
      <site name="glmed3_l_glmed3_l-P1" pos="-0.10780603163000001 0.0153438035008 -0.071825269023999994"/>
      <site name="glmin1_l_glmin1_l-P1" pos="-0.032341809488999999 0 -0.13242783976299999"/>
      <site name="glmin2_l_glmin2_l-P1" pos="-0.06640851548408 0.0095898771879999994 -0.1133492526785"/>
      <site name="glmin3_l_glmin3_l-P1" pos="-0.085058958956069991 -0.0148643096414 -0.089557132314299986"/>
      <site name="grac_l_grac_l-P1" pos="-0.051056936579968001 -0.12401629179521599 -0.027562946987959996"/>
      <site name="iliacus_l_iliacus_l-P1" pos="-0.065222649136150002 0.029632720510920002 -0.094607346542549986"/>
      <site name="iliacus_l_iliacus_l-P2" pos="-0.01455381427005 -0.053415615937160002 -0.084843599034599995"/>
      <site name="IL_at_brim_l_cylinder_iliacus_l_2_sidesite" pos="-0.02879 -0.09324 -0.09328" size="0.0005"/>
      <site name="piri_l_piri_l-P1" pos="-0.109757320802503 -0.0062621898037640003 -0.015161865383034998"/>
      <site name="piri_l_piri_l-P2" pos="-0.10998371346892599 -0.029402563458407999 -0.06836867795222"/>
      <site name="psoas_l_psoas_l-P1" pos="-0.065330455167779994 0.0594572385656 -0.043768523311499996"/>
      <site name="psoas_l_psoas_l-P2" pos="-0.02210023648415 -0.062717796809519999 -0.073620900749599996"/>
      <site name="PS_at_brim_l_cylinder_psoas_l_2_sidesite" pos="-0.04177 -0.09236 -0.08229" size="0.0005"/>
      <site name="recfem_l_recfem_l-P1" pos="-0.025873447591199999 -0.037208723489440002 -0.10470777499904999"/>
      <site name="sart_l_sart_l-P1" pos="-0.021022176167850001 -0.01496020841328 -0.11851169388959999"/>
      <site name="semimem_l_semimem_l-P1" pos="-0.10640455321881 -0.1093245999432 -0.068907367469899991"/>
      <site name="semiten_l_semiten_l-P1" pos="-0.11190266083194 -0.12016116116563999 -0.057796896167749995"/>
      <site name="tfl_l_tfl_l-P1" pos="-0.021561206326000001 0.010548864906799999 -0.14477280787649999"/>
      <site name="L.Iliac.Crestv_marker" group="4" pos="-0.094 0.09115 -0.1668" rgba="1 0.1 0.5 0.5" size="0.01"/>
      <site name="R.Iliac.Crestv_marker" group="4" pos="-0.07044 0.08298 0.1701" rgba="1 0.1 0.5 0.5" size="0.01"/>
      <site name="R.ASIS_marker" group="4" pos="0.02707 0.01032 0.1384" rgba="1 0.1 0.5 0.5" size="0.01"/>
      <site name="L.ASIS_marker" group="4" pos="0.02514 0.01293 -0.135" rgba="1 0.1 0.5 0.5" size="0.01"/>
      <site name="R.PSIS_marker" group="4" pos="-0.1767 0.0354 0.05527" rgba="1 0.1 0.5 0.5" size="0.01"/>
      <site name="L.PSIS_marker" group="4" pos="-0.177 0.03464 -0.04788" rgba="1 0.1 0.5 0.5" size="0.01"/>
    </body>
  </worldbody>
  <asset>
    <texture type="skybox" builtin="gradient" rgb1="1 1 1" rgb2="0.6 0.8 1" width="256" height="256"/>
    <mesh name="pelvis_geom_1_r_pelvis" file="Geometry/r_pelvis.stl" scale="1.0780603163 0.9589877188 1.1222698284999999"/>
    <mesh name="pelvis_geom_2_l_pelvis" file="Geometry/l_pelvis.stl" scale="1.0780603163 0.9589877188 1.1222698284999999"/>
    <mesh name="pelvis_geom_3_sacrum" file="Geometry/sacrum.stl" scale="1.0780603163 0.9589877188 1.1222698284999999"/>
    <mesh name="femur_r_geom_1_r_femur" file="Geometry/r_femur.stl" scale="1.0026883600000001 1.0114071366999999 1.0231015546"/>
    <mesh name="tibia_r_geom_1_r_tibia" file="Geometry/r_tibia.stl" scale="1.0358089886999999 1.1325451642 1.0629128866999999"/>
    <mesh name="tibia_r_geom_2_r_fibula" file="Geometry/r_fibula.stl" scale="1.0358089886999999 1.1325451642 1.0629128866999999"/>
    <mesh name="talus_r_geom_1_r_talus" file="Geometry/r_talus.stl" scale="1.1180400345999999 1.1703062032 1.1458960932"/>
    <mesh name="calcn_r_geom_1_r_foot" file="Geometry/r_foot.stl" scale="1.1366693031999999 1.1032910005000001 1.1088611997"/>
    <mesh name="toes_r_geom_1_r_bofoot" file="Geometry/r_bofoot.stl" scale="1.0969730386000001 1.0968770482000001 1.0971706587000001"/>
    <mesh name="patella_r_geom_1_r_patella" file="Geometry/r_patella.stl" scale="1 1 1"/>
    <mesh name="femur_l_geom_1_l_femur" file="Geometry/l_femur.stl" scale="1.0026883600000001 1.0114071366999999 1.0231015546"/>
    <mesh name="tibia_l_geom_1_l_tibia" file="Geometry/l_tibia.stl" scale="1.0358089886999999 1.1325451642 1.0629128866999999"/>
    <mesh name="tibia_l_geom_2_l_fibula" file="Geometry/l_fibula.stl" scale="1.0358089886999999 1.1325451642 1.0629128866999999"/>
    <mesh name="talus_l_geom_1_l_talus" file="Geometry/l_talus.stl" scale="1.1180400345999999 1.1703062032 1.1458960932"/>
    <mesh name="calcn_l_geom_1_l_foot" file="Geometry/l_foot.stl" scale="1.1366693031999999 1.1032910005000001 1.1088611997"/>
    <mesh name="toes_l_geom_1_l_bofoot" file="Geometry/l_bofoot.stl" scale="1.0969730386000001 1.0968770482000001 1.0971706587000001"/>
    <mesh name="patella_l_geom_1_l_patella" file="Geometry/l_patella.stl" scale="1 1 1"/>
    <mesh name="torso_geom_1_hat_spine" file="Geometry/hat_spine.stl" scale="1.1469736874000001 0.96628462059999998 1.113869759"/>
    <mesh name="torso_geom_2_hat_jaw" file="Geometry/hat_jaw.stl" scale="1.1469736874000001 0.96628462059999998 1.113869759"/>
    <mesh name="torso_geom_3_hat_skull" file="Geometry/hat_skull.stl" scale="1.1469736874000001 0.96628462059999998 1.113869759"/>
    <mesh name="torso_geom_4_hat_ribs_scap" file="Geometry/hat_ribs_scap.stl" scale="1.1469736874000001 0.96628462059999998 1.113869759"/>
  </asset>
  <tendon>
    <!-- Leave this comment here to make 'tendon' element pretty printed !-->
    <spatial name="addbrev_r_tendon">
      <site site="addbrev_r_addbrev_r-P1"/>
      <geom geom="AB_at_femshaft_r_cylinder" sidesite="AB_at_femshaft_r_cylinder_addbrev_r_1_sidesite"/>
      <site site="addbrev_r_addbrev_r-P2"/>
    </spatial>
    <spatial name="addlong_r_tendon">
      <site site="addlong_r_addlong_r-P1"/>
      <geom geom="AL_at_femshaft_r_cylinder" sidesite="AL_at_femshaft_r_cylinder_addlong_r_1_sidesite"/>
      <site site="addlong_r_addlong_r-P2"/>
    </spatial>
    <spatial name="addmagDist_r_tendon">
      <site site="addmagDist_r_addmagDist_r-P1"/>
      <geom geom="AMdist_at_femshaft_r_cylinder" sidesite="AMdist_at_femshaft_r_cylinder_addmagDist_r_1_sidesite"/>
      <site site="addmagDist_r_addmagDist_r-P2"/>
    </spatial>
    <spatial name="addmagIsch_r_tendon">
      <site site="addmagIsch_r_addmagIsch_r-P1"/>
      <geom geom="AMisch_at_condyles_r_cylinder" sidesite="AMisch_at_condyles_r_cylinder_addmagIsch_r_1_sidesite"/>
      <site site="addmagIsch_r_addmagIsch_r-P2"/>
    </spatial>
    <spatial name="addmagMid_r_tendon">
      <site site="addmagMid_r_addmagMid_r-P1"/>
      <geom geom="AMmid_at_femshaft_r_cylinder" sidesite="AMmid_at_femshaft_r_cylinder_addmagMid_r_1_sidesite"/>
      <site site="addmagMid_r_addmagMid_r-P2"/>
    </spatial>
    <spatial name="addmagProx_r_tendon">
      <site site="addmagProx_r_addmagProx_r-P1"/>
      <geom geom="AMprox_at_femshaft_r_cylinder" sidesite="AMprox_at_femshaft_r_cylinder_addmagProx_r_1_sidesite"/>
      <site site="addmagProx_r_addmagProx_r-P2"/>
    </spatial>
    <spatial name="bflh_r_tendon">
      <site site="bflh_r_bflh_r-P1"/>
      <site site="bflh_r_bflh_r-P2"/>
      <site site="bflh_r_bflh_r-P3"/>
    </spatial>
    <spatial name="bfsh_r_tendon">
      <site site="bfsh_r_bfsh_r-P1"/>
      <site site="bfsh_r_bfsh_r-P2"/>
    </spatial>
    <spatial name="edl_r_tendon">
      <site site="edl_r_edl_r-P1"/>
      <site site="edl_r_edl_r-P2"/>
      <site site="edl_r_edl_r-P3"/>
      <site site="edl_r_edl_r-P4"/>
      <site site="edl_r_edl_r-P5"/>
      <site site="edl_r_edl_r-P6"/>
    </spatial>
    <spatial name="ehl_r_tendon">
      <site site="ehl_r_ehl_r-P1"/>
      <site site="ehl_r_ehl_r-P2"/>
      <site site="ehl_r_ehl_r-P3"/>
      <site site="ehl_r_ehl_r-P4"/>
      <site site="ehl_r_ehl_r-P5"/>
      <site site="ehl_r_ehl_r-P6"/>
      <site site="ehl_r_ehl_r-P7"/>
      <site site="ehl_r_ehl_r-P8"/>
    </spatial>
    <spatial name="fdl_r_tendon">
      <site site="fdl_r_fdl_r-P1"/>
      <site site="fdl_r_fdl_r-P2"/>
      <site site="fdl_r_fdl_r-P3"/>
      <site site="fdl_r_fdl_r-P4"/>
      <site site="fdl_r_fdl_r-P5"/>
      <site site="fdl_r_fdl_r-P6"/>
      <site site="fdl_r_fdl_r-P7"/>
      <site site="fdl_r_fdl_r-P8"/>
    </spatial>
    <spatial name="fhl_r_tendon">
      <site site="fhl_r_fhl_r-P1"/>
      <site site="fhl_r_fhl_r-P2"/>
      <site site="fhl_r_fhl_r-P3"/>
      <site site="fhl_r_fhl_r-P4"/>
      <site site="fhl_r_fhl_r-P5"/>
      <site site="fhl_r_fhl_r-P6"/>
      <site site="fhl_r_fhl_r-P7"/>
    </spatial>
    <spatial name="gaslat_r_tendon">
      <site site="gaslat_r_gaslat_r-P1"/>
      <geom geom="GasLat_at_shank_r_cylinder" sidesite="GasLat_at_shank_r_cylinder_gaslat_r_1_sidesite"/>
      <site site="gaslat_r_gaslat_r-P2"/>
    </spatial>
    <spatial name="gasmed_r_tendon">
      <site site="gasmed_r_gasmed_r-P1"/>
      <geom geom="Gastroc_at_condyles_r_cylinder" sidesite="Gastroc_at_condyles_r_cylinder_gasmed_r_1_sidesite"/>
      <site site="gasmed_r_gasmed_r-P2"/>
    </spatial>
    <spatial name="glmax1_r_tendon">
      <site site="glmax1_r_glmax1_r-P1"/>
      <site site="glmax1_r_glmax1_r-P2"/>
      <geom geom="Gmax1_at_pelvis_r_cylinder" sidesite="Gmax1_at_pelvis_r_cylinder_glmax1_r_2_sidesite"/>
      <site site="glmax1_r_glmax1_r-P3"/>
      <site site="glmax1_r_glmax1_r-P4"/>
    </spatial>
    <spatial name="glmax2_r_tendon">
      <site site="glmax2_r_glmax2_r-P1"/>
      <site site="glmax2_r_glmax2_r-P2"/>
      <geom geom="Gmax2_at_pelvis_r_cylinder" sidesite="Gmax2_at_pelvis_r_cylinder_glmax2_r_2_sidesite"/>
      <site site="glmax2_r_glmax2_r-P3"/>
      <site site="glmax2_r_glmax2_r-P4"/>
    </spatial>
    <spatial name="glmax3_r_tendon">
      <site site="glmax3_r_glmax3_r-P1"/>
      <site site="glmax3_r_glmax3_r-P2"/>
      <site site="glmax3_r_glmax3_r-P3"/>
      <site site="glmax3_r_glmax3_r-P4"/>
    </spatial>
    <spatial name="glmed1_r_tendon">
      <site site="glmed1_r_glmed1_r-P1"/>
      <site site="glmed1_r_glmed1_r-P2_0"/>
    </spatial>
    <spatial name="glmed2_r_tendon">
      <site site="glmed2_r_glmed2_r-P1"/>
      <site site="glmed2_r_glmed2_r-P2_0"/>
    </spatial>
    <spatial name="glmed3_r_tendon">
      <site site="glmed3_r_glmed3_r-P1"/>
      <site site="glmed3_r_glmed3_r-P2_0"/>
    </spatial>
    <spatial name="glmin1_r_tendon">
      <site site="glmin1_r_glmin1_r-P1"/>
      <site site="glmin1_r_glmin1_r-P2"/>
    </spatial>
    <spatial name="glmin2_r_tendon">
      <site site="glmin2_r_glmin2_r-P1"/>
      <site site="glmin2_r_glmin2_r-P2"/>
    </spatial>
    <spatial name="glmin3_r_tendon">
      <site site="glmin3_r_glmin3_r-P1"/>
      <site site="glmin3_r_glmin3_r-P2"/>
    </spatial>
    <spatial name="grac_r_tendon">
      <site site="grac_r_grac_r-P1"/>
      <geom geom="GR_at_condyles_r_cylinder" sidesite="GR_at_condyles_r_cylinder_grac_r_1_sidesite"/>
      <site site="grac_r_grac_r-P2"/>
      <site site="grac_r_grac_r-P3"/>
    </spatial>
    <spatial name="iliacus_r_tendon">
      <site site="iliacus_r_iliacus_r-P1"/>
      <site site="iliacus_r_iliacus_r-P2"/>
      <geom geom="IL_at_brim_r_cylinder" sidesite="IL_at_brim_r_cylinder_iliacus_r_2_sidesite"/>
      <site site="iliacus_r_iliacus_r-P3"/>
      <site site="iliacus_r_iliacus_r-P4"/>
    </spatial>
    <spatial name="perbrev_r_tendon">
      <site site="perbrev_r_perbrev_r-P1"/>
      <site site="perbrev_r_perbrev_r-P2"/>
      <site site="perbrev_r_perbrev_r-P3"/>
      <site site="perbrev_r_perbrev_r-P4"/>
      <site site="perbrev_r_perbrev_r-P5"/>
    </spatial>
    <spatial name="perlong_r_tendon">
      <site site="perlong_r_perlong_r-P1"/>
      <site site="perlong_r_perlong_r-P2"/>
      <site site="perlong_r_perlong_r-P3"/>
      <site site="perlong_r_perlong_r-P4"/>
      <site site="perlong_r_perlong_r-P5"/>
      <site site="perlong_r_perlong_r-P6"/>
      <site site="perlong_r_perlong_r-P7"/>
    </spatial>
    <spatial name="piri_r_tendon">
      <site site="piri_r_piri_r-P1"/>
      <site site="piri_r_piri_r-P2"/>
      <site site="piri_r_piri_r-P3"/>
    </spatial>
    <spatial name="psoas_r_tendon">
      <site site="psoas_r_psoas_r-P1"/>
      <site site="psoas_r_psoas_r-P2"/>
      <geom geom="PS_at_brim_r_cylinder" sidesite="PS_at_brim_r_cylinder_psoas_r_2_sidesite"/>
      <site site="psoas_r_psoas_r-P3"/>
      <site site="psoas_r_psoas_r-P4"/>
    </spatial>
    <spatial name="recfem_r_tendon">
      <site site="recfem_r_recfem_r-P1"/>
      <site site="recfem_r_recfem_r-P2"/>
      <site site="recfem_r_recfem_r-P3"/>
      <geom geom="KnExt_at_fem_r_cylinder" sidesite="KnExt_at_fem_r_cylinder_recfem_r_3_sidesite"/>
      <site site="recfem_r_recfem_r-P4"/>
      <site site="recfem_r_recfem_r-P5"/>
    </spatial>
    <spatial name="sart_r_tendon">
      <site site="sart_r_sart_r-P1"/>
      <site site="sart_r_sart_r-P2"/>
      <site site="sart_r_sart_r-P3"/>
      <site site="sart_r_sart_r-P4"/>
      <site site="sart_r_sart_r-P5"/>
    </spatial>
    <spatial name="semimem_r_tendon">
      <site site="semimem_r_semimem_r-P1"/>
      <geom geom="SM_at_condyles_r_cylinder" sidesite="SM_at_condyles_r_cylinder_semimem_r_1_sidesite"/>
      <site site="semimem_r_semimem_r-P2"/>
    </spatial>
    <spatial name="semiten_r_tendon">
      <site site="semiten_r_semiten_r-P1"/>
      <geom geom="ST_at_condyles_r_cylinder" sidesite="ST_at_condyles_r_cylinder_semiten_r_1_sidesite"/>
      <site site="semiten_r_semiten_r-P2"/>
      <site site="semiten_r_semiten_r-P3"/>
    </spatial>
    <spatial name="soleus_r_tendon">
      <site site="soleus_r_soleus_r-P1"/>
      <site site="soleus_r_soleus_r-P2"/>
    </spatial>
    <spatial name="tfl_r_tendon">
      <site site="tfl_r_tfl_r-P1"/>
      <site site="tfl_r_tfl_r-P2"/>
      <site site="tfl_r_tfl_r-P3"/>
      <site site="tfl_r_tfl_r-P4"/>
    </spatial>
    <spatial name="tibant_r_tendon">
      <site site="tibant_r_tibant_r-P1"/>
      <site site="tibant_r_tibant_r-P2"/>
      <site site="tibant_r_tibant_r-P3"/>
      <site site="tibant_r_tibant_r-P4"/>
    </spatial>
    <spatial name="tibpost_r_tendon">
      <site site="tibpost_r_tibpost_r-P1"/>
      <site site="tibpost_r_tibpost_r-P2"/>
      <site site="tibpost_r_tibpost_r-P3"/>
      <site site="tibpost_r_tibpost_r-P4"/>
    </spatial>
    <spatial name="vasint_r_tendon">
      <site site="vasint_r_vasint_r-P1"/>
      <site site="vasint_r_vasint_r-P2"/>
      <site site="vasint_r_vasint_r-P3"/>
      <geom geom="KnExt_at_fem_r_cylinder" sidesite="KnExt_at_fem_r_cylinder_vasint_r_3_sidesite"/>
      <site site="vasint_r_vasint_r-P4"/>
      <site site="vasint_r_vasint_r-P5"/>
    </spatial>
    <spatial name="vaslat_r_tendon">
      <site site="vaslat_r_vaslat_r-P1"/>
      <site site="vaslat_r_vaslat_r-P2"/>
      <site site="vaslat_r_vaslat_r-P3"/>
      <geom geom="KnExt_at_fem_r_cylinder" sidesite="KnExt_at_fem_r_cylinder_vaslat_r_3_sidesite"/>
      <site site="vaslat_r_vaslat_r-P4"/>
      <site site="vaslat_r_vaslat_r-P5"/>
    </spatial>
    <spatial name="vasmed_r_tendon">
      <site site="vasmed_r_vasmed_r-P1"/>
      <site site="vasmed_r_vasmed_r-P2"/>
      <site site="vasmed_r_vasmed_r-P3"/>
      <geom geom="KnExt_at_fem_r_cylinder" sidesite="KnExt_at_fem_r_cylinder_vasmed_r_3_sidesite"/>
      <site site="vasmed_r_vasmed_r-P4"/>
      <geom geom="KnExt_at_fem_r_cylinder" sidesite="KnExt_at_fem_r_cylinder_vasmed_r_4_sidesite"/>
      <site site="vasmed_r_vasmed_r-P5"/>
    </spatial>
    <spatial name="addbrev_l_tendon">
      <site site="addbrev_l_addbrev_l-P1"/>
      <geom geom="AB_at_femshaft_l_cylinder" sidesite="AB_at_femshaft_l_cylinder_addbrev_l_1_sidesite"/>
      <site site="addbrev_l_addbrev_l-P2"/>
    </spatial>
    <spatial name="addlong_l_tendon">
      <site site="addlong_l_addlong_l-P1"/>
      <geom geom="AL_at_femshaft_l_cylinder" sidesite="AL_at_femshaft_l_cylinder_addlong_l_1_sidesite"/>
      <site site="addlong_l_addlong_l-P2"/>
    </spatial>
    <spatial name="addmagDist_l_tendon">
      <site site="addmagDist_l_addmagDist_l-P1"/>
      <geom geom="AMdist_at_femshaft_l_cylinder" sidesite="AMdist_at_femshaft_l_cylinder_addmagDist_l_1_sidesite"/>
      <site site="addmagDist_l_addmagDist_l-P2"/>
    </spatial>
    <spatial name="addmagIsch_l_tendon">
      <site site="addmagIsch_l_addmagIsch_l-P1"/>
      <geom geom="AMisch_at_condyles_l_cylinder" sidesite="AMisch_at_condyles_l_cylinder_addmagIsch_l_1_sidesite"/>
      <site site="addmagIsch_l_addmagIsch_l-P2"/>
    </spatial>
    <spatial name="addmagMid_l_tendon">
      <site site="addmagMid_l_addmagMid_l-P1"/>
      <geom geom="AMmid_at_femshaft_l_cylinder" sidesite="AMmid_at_femshaft_l_cylinder_addmagMid_l_1_sidesite"/>
      <site site="addmagMid_l_addmagMid_l-P2"/>
    </spatial>
    <spatial name="addmagProx_l_tendon">
      <site site="addmagProx_l_addmagProx_l-P1"/>
      <geom geom="AMprox_at_femshaft_l_cylinder" sidesite="AMprox_at_femshaft_l_cylinder_addmagProx_l_1_sidesite"/>
      <site site="addmagProx_l_addmagProx_l-P2"/>
    </spatial>
    <spatial name="bflh_l_tendon">
      <site site="bflh_l_bflh_l-P1"/>
      <site site="bflh_l_bflh_l-P2"/>
      <site site="bflh_l_bflh_l-P3"/>
    </spatial>
    <spatial name="bfsh_l_tendon">
      <site site="bfsh_l_bfsh_l-P1"/>
      <site site="bfsh_l_bfsh_l-P2"/>
    </spatial>
    <spatial name="edl_l_tendon">
      <site site="edl_l_edl_l-P1"/>
      <site site="edl_l_edl_l-P2"/>
      <site site="edl_l_edl_l-P3"/>
      <site site="edl_l_edl_l-P4"/>
      <site site="edl_l_edl_l-P5"/>
      <site site="edl_l_edl_l-P6"/>
    </spatial>
    <spatial name="ehl_l_tendon">
      <site site="ehl_l_ehl_l-P1"/>
      <site site="ehl_l_ehl_l-P2"/>
      <site site="ehl_l_ehl_l-P3"/>
      <site site="ehl_l_ehl_l-P4"/>
      <site site="ehl_l_ehl_l-P5"/>
      <site site="ehl_l_ehl_l-P6"/>
      <site site="ehl_l_ehl_l-P7"/>
      <site site="ehl_l_ehl_l-P8"/>
    </spatial>
    <spatial name="fdl_l_tendon">
      <site site="fdl_l_fdl_l-P1"/>
      <site site="fdl_l_fdl_l-P2"/>
      <site site="fdl_l_fdl_l-P3"/>
      <site site="fdl_l_fdl_l-P4"/>
      <site site="fdl_l_fdl_l-P5"/>
      <site site="fdl_l_fdl_l-P6"/>
      <site site="fdl_l_fdl_l-P7"/>
      <site site="fdl_l_fdl_l-P8"/>
    </spatial>
    <spatial name="fhl_l_tendon">
      <site site="fhl_l_fhl_l-P1"/>
      <site site="fhl_l_fhl_l-P2"/>
      <site site="fhl_l_fhl_l-P3"/>
      <site site="fhl_l_fhl_l-P4"/>
      <site site="fhl_l_fhl_l-P5"/>
      <site site="fhl_l_fhl_l-P6"/>
      <site site="fhl_l_fhl_l-P7"/>
    </spatial>
    <spatial name="gaslat_l_tendon">
      <site site="gaslat_l_gaslat_l-P1"/>
      <geom geom="GasLat_at_shank_l_cylinder" sidesite="GasLat_at_shank_l_cylinder_gaslat_l_1_sidesite"/>
      <site site="gaslat_l_gaslat_l-P2"/>
    </spatial>
    <spatial name="gasmed_l_tendon">
      <site site="gasmed_l_gasmed_l-P1"/>
      <geom geom="Gastroc_at_condyles_l_cylinder" sidesite="Gastroc_at_condyles_l_cylinder_gasmed_l_1_sidesite"/>
      <site site="gasmed_l_gasmed_l-P2"/>
    </spatial>
    <spatial name="glmax1_l_tendon">
      <site site="glmax1_l_glmax1_l-P1"/>
      <site site="glmax1_l_glmax1_l-P2"/>
      <geom geom="Gmax1_at_pelvis_l_cylinder" sidesite="Gmax1_at_pelvis_l_cylinder_glmax1_l_2_sidesite"/>
      <site site="glmax1_l_glmax1_l-P3"/>
      <site site="glmax1_l_glmax1_l-P4"/>
    </spatial>
    <spatial name="glmax2_l_tendon">
      <site site="glmax2_l_glmax2_l-P1"/>
      <site site="glmax2_l_glmax2_l-P2"/>
      <geom geom="Gmax2_at_pelvis_l_cylinder" sidesite="Gmax2_at_pelvis_l_cylinder_glmax2_l_2_sidesite"/>
      <site site="glmax2_l_glmax2_l-P3"/>
      <site site="glmax2_l_glmax2_l-P4"/>
    </spatial>
    <spatial name="glmax3_l_tendon">
      <site site="glmax3_l_glmax3_l-P1"/>
      <site site="glmax3_l_glmax3_l-P2"/>
      <site site="glmax3_l_glmax3_l-P3"/>
      <site site="glmax3_l_glmax3_l-P4"/>
    </spatial>
    <spatial name="glmed1_l_tendon">
      <site site="glmed1_l_glmed1_l-P1"/>
      <site site="glmed1_l_glmed1_l-P2"/>
    </spatial>
    <spatial name="glmed2_l_tendon">
      <site site="glmed2_l_glmed2_l-P1"/>
      <site site="glmed2_l_glmed2_l-P2"/>
    </spatial>
    <spatial name="glmed3_l_tendon">
      <site site="glmed3_l_glmed3_l-P1"/>
      <site site="glmed3_l_glmed3_l-P2"/>
    </spatial>
    <spatial name="glmin1_l_tendon">
      <site site="glmin1_l_glmin1_l-P1"/>
      <site site="glmin1_l_glmin1_l-P2"/>
    </spatial>
    <spatial name="glmin2_l_tendon">
      <site site="glmin2_l_glmin2_l-P1"/>
      <site site="glmin2_l_glmin2_l-P2"/>
    </spatial>
    <spatial name="glmin3_l_tendon">
      <site site="glmin3_l_glmin3_l-P1"/>
      <site site="glmin3_l_glmin3_l-P2"/>
    </spatial>
    <spatial name="grac_l_tendon">
      <site site="grac_l_grac_l-P1"/>
      <geom geom="GR_at_condyles_l_cylinder" sidesite="GR_at_condyles_l_cylinder_grac_l_1_sidesite"/>
      <site site="grac_l_grac_l-P2"/>
      <site site="grac_l_grac_l-P3"/>
    </spatial>
    <spatial name="iliacus_l_tendon">
      <site site="iliacus_l_iliacus_l-P1"/>
      <site site="iliacus_l_iliacus_l-P2"/>
      <geom geom="IL_at_brim_l_cylinder" sidesite="IL_at_brim_l_cylinder_iliacus_l_2_sidesite"/>
      <site site="iliacus_l_iliacus_l-P3"/>
      <site site="iliacus_l_iliacus_l-P4"/>
    </spatial>
    <spatial name="perbrev_l_tendon">
      <site site="perbrev_l_perbrev_l-P1"/>
      <site site="perbrev_l_perbrev_l-P2"/>
      <site site="perbrev_l_perbrev_l-P3"/>
      <site site="perbrev_l_perbrev_l-P4"/>
      <site site="perbrev_l_perbrev_l-P5"/>
    </spatial>
    <spatial name="perlong_l_tendon">
      <site site="perlong_l_perlong_l-P1"/>
      <site site="perlong_l_perlong_l-P2"/>
      <site site="perlong_l_perlong_l-P3"/>
      <site site="perlong_l_perlong_l-P4"/>
      <site site="perlong_l_perlong_l-P5"/>
      <site site="perlong_l_perlong_l-P6"/>
      <site site="perlong_l_perlong_l-P7"/>
    </spatial>
    <spatial name="piri_l_tendon">
      <site site="piri_l_piri_l-P1"/>
      <site site="piri_l_piri_l-P2"/>
      <site site="piri_l_piri_l-P3"/>
    </spatial>
    <spatial name="psoas_l_tendon">
      <site site="psoas_l_psoas_l-P1"/>
      <site site="psoas_l_psoas_l-P2"/>
      <geom geom="PS_at_brim_l_cylinder" sidesite="PS_at_brim_l_cylinder_psoas_l_2_sidesite"/>
      <site site="psoas_l_psoas_l-P3"/>
      <site site="psoas_l_psoas_l-P4"/>
    </spatial>
    <spatial name="recfem_l_tendon">
      <site site="recfem_l_recfem_l-P1"/>
      <site site="recfem_l_recfem_l-P2"/>
      <site site="recfem_l_recfem_l-P3"/>
      <geom geom="KnExt_at_fem_l_cylinder" sidesite="KnExt_at_fem_l_cylinder_recfem_l_3_sidesite"/>
      <site site="recfem_l_recfem_l-P4"/>
      <site site="recfem_l_recfem_l-P5"/>
    </spatial>
    <spatial name="sart_l_tendon">
      <site site="sart_l_sart_l-P1"/>
      <site site="sart_l_sart_l-P2"/>
      <site site="sart_l_sart_l-P3"/>
      <site site="sart_l_sart_l-P4"/>
      <site site="sart_l_sart_l-P5"/>
    </spatial>
    <spatial name="semimem_l_tendon">
      <site site="semimem_l_semimem_l-P1"/>
      <geom geom="SM_at_condyles_l_cylinder" sidesite="SM_at_condyles_l_cylinder_semimem_l_1_sidesite"/>
      <site site="semimem_l_semimem_l-P2"/>
    </spatial>
    <spatial name="semiten_l_tendon">
      <site site="semiten_l_semiten_l-P1"/>
      <geom geom="ST_at_condyles_l_cylinder" sidesite="ST_at_condyles_l_cylinder_semiten_l_1_sidesite"/>
      <site site="semiten_l_semiten_l-P2"/>
      <site site="semiten_l_semiten_l-P3"/>
    </spatial>
    <spatial name="soleus_l_tendon">
      <site site="soleus_l_soleus_l-P1"/>
      <site site="soleus_l_soleus_l-P2"/>
    </spatial>
    <spatial name="tfl_l_tendon">
      <site site="tfl_l_tfl_l-P1"/>
      <site site="tfl_l_tfl_l-P2"/>
      <site site="tfl_l_tfl_l-P3"/>
      <site site="tfl_l_tfl_l-P4"/>
    </spatial>
    <spatial name="tibant_l_tendon">
      <site site="tibant_l_tibant_l-P1"/>
      <site site="tibant_l_tibant_l-P2"/>
      <site site="tibant_l_tibant_l-P3"/>
      <site site="tibant_l_tibant_l-P4"/>
    </spatial>
    <spatial name="tibpost_l_tendon">
      <site site="tibpost_l_tibpost_l-P1"/>
      <site site="tibpost_l_tibpost_l-P2"/>
      <site site="tibpost_l_tibpost_l-P3"/>
      <site site="tibpost_l_tibpost_l-P4"/>
    </spatial>
    <spatial name="vasint_l_tendon">
      <site site="vasint_l_vasint_l-P1"/>
      <site site="vasint_l_vasint_l-P2"/>
      <site site="vasint_l_vasint_l-P3"/>
      <geom geom="KnExt_at_fem_l_cylinder" sidesite="KnExt_at_fem_l_cylinder_vasint_l_3_sidesite"/>
      <site site="vasint_l_vasint_l-P4"/>
      <site site="vasint_l_vasint_l-P5"/>
    </spatial>
    <spatial name="vaslat_l_tendon">
      <site site="vaslat_l_vaslat_l-P1"/>
      <site site="vaslat_l_vaslat_l-P2"/>
      <site site="vaslat_l_vaslat_l-P3"/>
      <geom geom="KnExt_at_fem_l_cylinder" sidesite="KnExt_at_fem_l_cylinder_vaslat_l_3_sidesite"/>
      <site site="vaslat_l_vaslat_l-P4"/>
      <site site="vaslat_l_vaslat_l-P5"/>
    </spatial>
    <spatial name="vasmed_l_tendon">
      <site site="vasmed_l_vasmed_l-P1"/>
      <site site="vasmed_l_vasmed_l-P2"/>
      <site site="vasmed_l_vasmed_l-P3"/>
      <geom geom="KnExt_at_fem_l_cylinder" sidesite="KnExt_at_fem_l_cylinder_vasmed_l_3_sidesite"/>
      <site site="vasmed_l_vasmed_l-P4"/>
      <geom geom="KnExt_at_fem_l_cylinder" sidesite="KnExt_at_fem_l_cylinder_vasmed_l_4_sidesite"/>
      <site site="vasmed_l_vasmed_l-P5"/>
    </spatial>
  </tendon>
  <actuator>
    <!-- Leave this comment here to make 'actuator' element pretty printed !-->
    <motor name="lumbar_ext" ctrllimited="false" joint="lumbar_extension" class="motor"/>
    <motor name="lumbar_bend" ctrllimited="false" joint="lumbar_bending" class="motor"/>
    <motor name="lumbar_rot" ctrllimited="false" joint="lumbar_rotation" class="motor"/>
    <muscle name="addbrev_r" lengthrange="0.01 1" force="625.81967213114797" tendon="addbrev_r_tendon" class="muscle" timeconst="0.01 0.04"/>
    <muscle name="addlong_r" lengthrange="0.01 1" force="916.79999999999995" tendon="addlong_r_tendon" class="muscle" timeconst="0.01 0.04"/>
    <muscle name="addmagDist_r" lengthrange="0.01 1" force="597.29508196721395" tendon="addmagDist_r_tendon" class="muscle" timeconst="0.01 0.04"/>
    <muscle name="addmagIsch_r" lengthrange="0.01 1" force="597.29508196721395" tendon="addmagIsch_r_tendon" class="muscle" timeconst="0.01 0.04"/>
    <muscle name="addmagMid_r" lengthrange="0.01 1" force="597.29508196721395" tendon="addmagMid_r_tendon" class="muscle" timeconst="0.01 0.04"/>
    <muscle name="addmagProx_r" lengthrange="0.01 1" force="597.29508196721395" tendon="addmagProx_r_tendon" class="muscle" timeconst="0.01 0.04"/>
    <muscle name="bflh_r" lengthrange="0.01 1" force="1313.18360655738" tendon="bflh_r_tendon" class="muscle" timeconst="0.01 0.04"/>
    <muscle name="bfsh_r" lengthrange="0.01 1" force="557.11475409835998" tendon="bfsh_r_tendon" class="muscle" timeconst="0.01 0.04"/>
    <muscle name="edl_r" lengthrange="0.01 1" force="603.49815560000002" tendon="edl_r_tendon" class="muscle" timeconst="0.01 0.04"/>
    <muscle name="ehl_r" lengthrange="0.01 1" force="285.86754739999998" tendon="ehl_r_tendon" class="muscle" timeconst="0.01 0.04"/>
    <muscle name="fdl_r" lengthrange="0.01 1" force="423.17704918032803" tendon="fdl_r_tendon" class="muscle" timeconst="0.01 0.04"/>
    <muscle name="fhl_r" lengthrange="0.01 1" force="907.83934426229405" tendon="fhl_r_tendon" class="muscle" timeconst="0.01 0.04"/>
    <muscle name="gaslat_r" lengthrange="0.01 1" force="1575.0590163934401" tendon="gaslat_r_tendon" class="muscle" timeconst="0.01 0.04"/>
    <muscle name="gasmed_r" lengthrange="0.01 1" force="3115.5147540983598" tendon="gasmed_r_tendon" class="muscle" timeconst="0.01 0.04"/>
    <muscle name="glmax1_r" lengthrange="0.01 1" force="983.78360655737799" tendon="glmax1_r_tendon" class="muscle" timeconst="0.01 0.04"/>
    <muscle name="glmax2_r" lengthrange="0.01 1" force="1406.0459016393499" tendon="glmax2_r_tendon" class="muscle" timeconst="0.01 0.04"/>
    <muscle name="glmax3_r" lengthrange="0.01 1" force="947.75409836065603" tendon="glmax3_r_tendon" class="muscle" timeconst="0.01 0.04"/>
    <muscle name="glmed1_r" lengthrange="0.01 1" force="1093.4667688" tendon="glmed1_r_tendon" class="muscle" timeconst="0.01 0.04"/>
    <muscle name="glmed2_r" lengthrange="0.01 1" force="765.09166159999995" tendon="glmed2_r_tendon" class="muscle" timeconst="0.01 0.04"/>
    <muscle name="glmed3_r" lengthrange="0.01 1" force="871.19926420000002" tendon="glmed3_r_tendon" class="muscle" timeconst="0.01 0.04"/>
    <muscle name="glmin1_r" lengthrange="0.01 1" force="374.04590163934398" tendon="glmin1_r_tendon" class="muscle" timeconst="0.01 0.04"/>
    <muscle name="glmin2_r" lengthrange="0.01 1" force="394.81967213114802" tendon="glmin2_r_tendon" class="muscle" timeconst="0.01 0.04"/>
    <muscle name="glmin3_r" lengthrange="0.01 1" force="446.77377049180399" tendon="glmin3_r_tendon" class="muscle" timeconst="0.01 0.04"/>
    <muscle name="grac_r" lengthrange="0.01 1" force="281.31147540983602" tendon="grac_r_tendon" class="muscle" timeconst="0.01 0.04"/>
    <muscle name="iliacus_r" lengthrange="0.01 1" force="1021.14098360656" tendon="iliacus_r_tendon" class="muscle" timeconst="0.01 0.04"/>
    <muscle name="perbrev_r" lengthrange="0.01 1" force="521.20159880000006" tendon="perbrev_r_tendon" class="muscle" timeconst="0.01 0.04"/>
    <muscle name="perlong_r" lengthrange="0.01 1" force="1115.3714213999999" tendon="perlong_r_tendon" class="muscle" timeconst="0.01 0.04"/>
    <muscle name="piri_r" lengthrange="0.01 1" force="1029.7868852459001" tendon="piri_r_tendon" class="muscle" timeconst="0.01 0.04"/>
    <muscle name="psoas_r" lengthrange="0.01 1" force="1426.79016393443" tendon="psoas_r_tendon" class="muscle" timeconst="0.01 0.04"/>
    <muscle name="recfem_r" lengthrange="0.01 1" force="2191.7409836065599" tendon="recfem_r_tendon" class="muscle" timeconst="0.01 0.04"/>
    <muscle name="sart_r" lengthrange="0.01 1" force="249.41311475409799" tendon="sart_r_tendon" class="muscle" timeconst="0.01 0.04"/>
    <muscle name="semimem_r" lengthrange="0.01 1" force="2200.9868852458999" tendon="semimem_r_tendon" class="muscle" timeconst="0.01 0.04"/>
    <muscle name="semiten_r" lengthrange="0.01 1" force="591.29508196721395" tendon="semiten_r_tendon" class="muscle" timeconst="0.01 0.04"/>
    <muscle name="soleus_r" lengthrange="0.01 1" force="6194.8426229508204" tendon="soleus_r_tendon" class="muscle" timeconst="0.01 0.04"/>
    <muscle name="tfl_r" lengthrange="0.01 1" force="411.20655737704999" tendon="tfl_r_tendon" class="muscle" timeconst="0.01 0.04"/>
    <muscle name="tibant_r" lengthrange="0.01 1" force="1227.4524590163901" tendon="tibant_r_tendon" class="muscle" timeconst="0.01 0.04"/>
    <muscle name="tibpost_r" lengthrange="0.01 1" force="1730.1540983606501" tendon="tibpost_r_tendon" class="muscle" timeconst="0.01 0.04"/>
    <muscle name="vasint_r" lengthrange="0.01 1" force="1697.36065573771" tendon="vasint_r_tendon" class="muscle" timeconst="0.01 0.04"/>
    <muscle name="vaslat_r" lengthrange="0.01 1" force="5148.7672131147601" tendon="vaslat_r_tendon" class="muscle" timeconst="0.01 0.04"/>
    <muscle name="vasmed_r" lengthrange="0.01 1" force="2747.82295081966" tendon="vasmed_r_tendon" class="muscle" timeconst="0.01 0.04"/>
    <muscle name="addbrev_l" lengthrange="0.01 1" force="625.81967213114797" tendon="addbrev_l_tendon" class="muscle" timeconst="0.01 0.04"/>
    <muscle name="addlong_l" lengthrange="0.01 1" force="916.79999999999995" tendon="addlong_l_tendon" class="muscle" timeconst="0.01 0.04"/>
    <muscle name="addmagDist_l" lengthrange="0.01 1" force="597.29508196721395" tendon="addmagDist_l_tendon" class="muscle" timeconst="0.01 0.04"/>
    <muscle name="addmagIsch_l" lengthrange="0.01 1" force="597.29508196721395" tendon="addmagIsch_l_tendon" class="muscle" timeconst="0.01 0.04"/>
    <muscle name="addmagMid_l" lengthrange="0.01 1" force="597.29508196721395" tendon="addmagMid_l_tendon" class="muscle" timeconst="0.01 0.04"/>
    <muscle name="addmagProx_l" lengthrange="0.01 1" force="597.29508196721395" tendon="addmagProx_l_tendon" class="muscle" timeconst="0.01 0.04"/>
    <muscle name="bflh_l" lengthrange="0.01 1" force="1313.18360655738" tendon="bflh_l_tendon" class="muscle" timeconst="0.01 0.04"/>
    <muscle name="bfsh_l" lengthrange="0.01 1" force="557.11475409835998" tendon="bfsh_l_tendon" class="muscle" timeconst="0.01 0.04"/>
    <muscle name="edl_l" lengthrange="0.01 1" force="603.49815560000002" tendon="edl_l_tendon" class="muscle" timeconst="0.01 0.04"/>
    <muscle name="ehl_l" lengthrange="0.01 1" force="285.86754739999998" tendon="ehl_l_tendon" class="muscle" timeconst="0.01 0.04"/>
    <muscle name="fdl_l" lengthrange="0.01 1" force="423.17704918032803" tendon="fdl_l_tendon" class="muscle" timeconst="0.01 0.04"/>
    <muscle name="fhl_l" lengthrange="0.01 1" force="907.83934426229405" tendon="fhl_l_tendon" class="muscle" timeconst="0.01 0.04"/>
    <muscle name="gaslat_l" lengthrange="0.01 1" force="1575.0590163934401" tendon="gaslat_l_tendon" class="muscle" timeconst="0.01 0.04"/>
    <muscle name="gasmed_l" lengthrange="0.01 1" force="3115.5147540983598" tendon="gasmed_l_tendon" class="muscle" timeconst="0.01 0.04"/>
    <muscle name="glmax1_l" lengthrange="0.01 1" force="983.78360655737799" tendon="glmax1_l_tendon" class="muscle" timeconst="0.01 0.04"/>
    <muscle name="glmax2_l" lengthrange="0.01 1" force="1406.0459016393499" tendon="glmax2_l_tendon" class="muscle" timeconst="0.01 0.04"/>
    <muscle name="glmax3_l" lengthrange="0.01 1" force="947.75409836065603" tendon="glmax3_l_tendon" class="muscle" timeconst="0.01 0.04"/>
    <muscle name="glmed1_l" lengthrange="0.01 1" force="1093.4667688" tendon="glmed1_l_tendon" class="muscle" timeconst="0.01 0.04"/>
    <muscle name="glmed2_l" lengthrange="0.01 1" force="765.09166159999995" tendon="glmed2_l_tendon" class="muscle" timeconst="0.01 0.04"/>
    <muscle name="glmed3_l" lengthrange="0.01 1" force="871.19926420000002" tendon="glmed3_l_tendon" class="muscle" timeconst="0.01 0.04"/>
    <muscle name="glmin1_l" lengthrange="0.01 1" force="374.04590163934398" tendon="glmin1_l_tendon" class="muscle" timeconst="0.01 0.04"/>
    <muscle name="glmin2_l" lengthrange="0.01 1" force="394.81967213114802" tendon="glmin2_l_tendon" class="muscle" timeconst="0.01 0.04"/>
    <muscle name="glmin3_l" lengthrange="0.01 1" force="446.77377049180399" tendon="glmin3_l_tendon" class="muscle" timeconst="0.01 0.04"/>
    <muscle name="grac_l" lengthrange="0.01 1" force="281.31147540983602" tendon="grac_l_tendon" class="muscle" timeconst="0.01 0.04"/>
    <muscle name="iliacus_l" lengthrange="0.01 1" force="1021.14098360656" tendon="iliacus_l_tendon" class="muscle" timeconst="0.01 0.04"/>
    <muscle name="perbrev_l" lengthrange="0.01 1" force="521.20159880000006" tendon="perbrev_l_tendon" class="muscle" timeconst="0.01 0.04"/>
    <muscle name="perlong_l" lengthrange="0.01 1" force="1115.3714213999999" tendon="perlong_l_tendon" class="muscle" timeconst="0.01 0.04"/>
    <muscle name="piri_l" lengthrange="0.01 1" force="1029.7868852459001" tendon="piri_l_tendon" class="muscle" timeconst="0.01 0.04"/>
    <muscle name="psoas_l" lengthrange="0.01 1" force="1426.79016393443" tendon="psoas_l_tendon" class="muscle" timeconst="0.01 0.04"/>
    <muscle name="recfem_l" lengthrange="0.01 1" force="2191.7409836065599" tendon="recfem_l_tendon" class="muscle" timeconst="0.01 0.04"/>
    <muscle name="sart_l" lengthrange="0.01 1" force="249.41311475409799" tendon="sart_l_tendon" class="muscle" timeconst="0.01 0.04"/>
    <muscle name="semimem_l" lengthrange="0.01 1" force="2200.9868852458999" tendon="semimem_l_tendon" class="muscle" timeconst="0.01 0.04"/>
    <muscle name="semiten_l" lengthrange="0.01 1" force="591.29508196721395" tendon="semiten_l_tendon" class="muscle" timeconst="0.01 0.04"/>
    <muscle name="soleus_l" lengthrange="0.01 1" force="6194.8426229508204" tendon="soleus_l_tendon" class="muscle" timeconst="0.01 0.04"/>
    <muscle name="tfl_l" lengthrange="0.01 1" force="411.20655737704999" tendon="tfl_l_tendon" class="muscle" timeconst="0.01 0.04"/>
    <muscle name="tibant_l" lengthrange="0.01 1" force="1227.4524590163901" tendon="tibant_l_tendon" class="muscle" timeconst="0.01 0.04"/>
    <muscle name="tibpost_l" lengthrange="0.01 1" force="1730.1540983606501" tendon="tibpost_l_tendon" class="muscle" timeconst="0.01 0.04"/>
    <muscle name="vasint_l" lengthrange="0.01 1" force="1697.36065573771" tendon="vasint_l_tendon" class="muscle" timeconst="0.01 0.04"/>
    <muscle name="vaslat_l" lengthrange="0.01 1" force="5148.7672131147601" tendon="vaslat_l_tendon" class="muscle" timeconst="0.01 0.04"/>
    <muscle name="vasmed_l" lengthrange="0.01 1" force="2747.82295081966" tendon="vasmed_l_tendon" class="muscle" timeconst="0.01 0.04"/>
  </actuator>
  <equality>
    <!-- Leave this comment here to make 'equality' element pretty printed !-->
    <joint joint1="walker_knee_r_translation1" joint2="knee_angle_r" polycoef="9.646e-08 0.003164 -0.002334 0.000568 5.748e-07" solimp="0.9999 0.9999 0.001 0.5 2" active="true"/>
    <joint joint1="walker_knee_r_translation2" joint2="knee_angle_r" polycoef="7.87e-11 0.006016 -0.001285 -2.679e-06 6.388e-07" solimp="0.9999 0.9999 0.001 0.5 2" active="true"/>
    <joint joint1="walker_knee_r_rotation2" joint2="knee_angle_r" polycoef="-1.473e-08 0.0791 -0.03285 -0.02522 0.01083" solimp="0.9999 0.9999 0.001 0.5 2" active="true"/>
    <joint joint1="walker_knee_r_rotation3" joint2="knee_angle_r" polycoef="1.089e-08 0.3695 -0.1695 0.02516 3.505e-07" solimp="0.9999 0.9999 0.001 0.5 2" active="true"/>
    <joint name="mtp_angle_r_locked" active="true" joint1="mtp_angle_r" polycoef="0.0 0 0 0 0" solimp="0.9999 0.9999 0.001 0.5 2"/>
    <joint joint1="patellofemoral_r_translation1" joint2="knee_angle_r" polycoef="0.05256 -0.01506 -0.03414 0.01338 -0.0008815" solimp="0.9999 0.9999 0.001 0.5 2" active="true"/>
    <joint joint1="patellofemoral_r_translation2" joint2="knee_angle_r" polycoef="-0.01095 -0.04934 0.009382 0.01332 -0.003537" solimp="0.9999 0.9999 0.001 0.5 2" active="true"/>
    <joint joint1="patellofemoral_r_rotation1" joint2="knee_angle_r" polycoef="0.01051 0.02476 -1.316 0.7163 -0.1383" solimp="0.9999 0.9999 0.001 0.5 2" active="true"/>
    <joint name="patellofemoral_r_translation3_locked" active="true" joint1="patellofemoral_r_translation3" polycoef="0.00281352927515 0 0 0 0" solimp="0.9999 0.9999 0.001 0.5 2"/>
    <joint joint1="walker_knee_l_translation1" joint2="knee_angle_l" polycoef="9.646e-08 0.003164 -0.002334 0.000568 5.748e-07" solimp="0.9999 0.9999 0.001 0.5 2" active="true"/>
    <joint joint1="walker_knee_l_translation2" joint2="knee_angle_l" polycoef="-7.87e-11 -0.006016 0.001285 2.679e-06 -6.388e-07" solimp="0.9999 0.9999 0.001 0.5 2" active="true"/>
    <joint joint1="walker_knee_l_rotation2" joint2="knee_angle_l" polycoef="-1.473e-08 0.0791 -0.03285 -0.02522 0.01083" solimp="0.9999 0.9999 0.001 0.5 2" active="true"/>
    <joint joint1="walker_knee_l_rotation3" joint2="knee_angle_l" polycoef="-1.089e-08 -0.3695 0.1695 -0.02516 -3.505e-07" solimp="0.9999 0.9999 0.001 0.5 2" active="true"/>
    <joint name="mtp_angle_l_locked" active="true" joint1="mtp_angle_l" polycoef="0.0 0 0 0 0" solimp="0.9999 0.9999 0.001 0.5 2"/>
    <joint joint1="patellofemoral_l_translation1" joint2="knee_angle_l" polycoef="0.05256 -0.01506 -0.03414 0.01338 -0.0008815" solimp="0.9999 0.9999 0.001 0.5 2" active="true"/>
    <joint joint1="patellofemoral_l_translation2" joint2="knee_angle_l" polycoef="-0.01095 -0.04934 0.009382 0.01332 -0.003537" solimp="0.9999 0.9999 0.001 0.5 2" active="true"/>
    <joint joint1="patellofemoral_l_rotation1" joint2="knee_angle_l" polycoef="0.01051 0.02476 -1.316 0.7163 -0.1383" solimp="0.9999 0.9999 0.001 0.5 2" active="true"/>
    <joint name="patellofemoral_l_translation3_locked" active="true" joint1="patellofemoral_l_translation3" polycoef="-0.00281352927515 0 0 0 0" solimp="0.9999 0.9999 0.001 0.5 2"/>
  </equality>
  <contact>
    <!-- Leave this comment here to make 'contact' element pretty printed !-->
    <pair geom1="ground-plane" geom2="pelvis_geom_1"/>
    <pair geom1="ground-plane" geom2="pelvis_geom_2"/>
    <pair geom1="ground-plane" geom2="pelvis_geom_3"/>
    <pair geom1="ground-plane" geom2="femur_r_geom_1"/>
    <pair geom1="ground-plane" geom2="tibia_r_geom_1"/>
    <pair geom1="ground-plane" geom2="tibia_r_geom_2"/>
    <pair geom1="ground-plane" geom2="talus_r_geom_1"/>
    <pair geom1="ground-plane" geom2="calcn_r_geom_1"/>
    <pair geom1="ground-plane" geom2="toes_r_geom_1"/>
    <pair geom1="ground-plane" geom2="patella_r_geom_1"/>
    <pair geom1="ground-plane" geom2="femur_l_geom_1"/>
    <pair geom1="ground-plane" geom2="tibia_l_geom_1"/>
    <pair geom1="ground-plane" geom2="tibia_l_geom_2"/>
    <pair geom1="ground-plane" geom2="talus_l_geom_1"/>
    <pair geom1="ground-plane" geom2="calcn_l_geom_1"/>
    <pair geom1="ground-plane" geom2="toes_l_geom_1"/>
    <pair geom1="ground-plane" geom2="patella_l_geom_1"/>
    <pair geom1="ground-plane" geom2="torso_geom_1"/>
    <pair geom1="ground-plane" geom2="torso_geom_2"/>
    <pair geom1="ground-plane" geom2="torso_geom_3"/>
    <pair geom1="ground-plane" geom2="torso_geom_4"/>
  </contact>
  <keyframe>
    <key name="default-pose" qpos="0 0.93 0 0 0 0 0 0 0 9.646e-08 7.87e-11 0 -1.473e-08 1.089e-08 0 0 0 0.05256 -0.01095 0.002814 0.01051 0 -0 -0 9.646e-08 -7.87e-11 0 -1.473e-08 -1.089e-08 0 0 0 0.05256 -0.01095 -0.002814 0.01051 0 0 0"/>
  </keyframe>
</mujoco>
