<mujoco model="template">
  
  
  <compiler inertiafromgeom="auto" angle="radian" balanceinertia="true" boundmass="0.25" boundinertia="0.01" inertiagrouprange="0 1">
    <lengthrange inttotal="50" useexisting="true" />
  </compiler>
  <option />
  <visual>
    <scale framelength="0.5" framewidth="0.01" />
  </visual>
  <default>
    <joint limited="true" damping="0.05" armature="0.01" stiffness="0" />
    <geom rgba="0.8 0.6 .4 1" margin="0.001" contype="0" conaffinity="0" />
    <site size="0.001" />
    <tendon width="0.005" rgba=".95 .3 .3 1" limited="false" />
    <default class="muscle">
      <muscle ctrllimited="true" ctrlrange="0 1" scale="200" />
    </default>
    <default class="motor">
      <general gainprm="5 0 0 0 0 0 0 0 0 0" />
    </default>
  </default>
  <option timestep="0.002" />
  
  <size njmax="1000" nconmax="400" nuser_jnt="1" nkey="1" />
  <worldbody>
    
    <body name="ground" euler="1.571 0 0">
      <geom name="ground-plane" pos="0 0 0" euler="-1.571 0 0" size="10 10 0.125" type="plane" rgba="1.0 0.7 0.4 1.0" condim="3" />
    </body>
    <light directional="true" />
    <body name="pelvis" pos="0 0 0" euler="1.571 0 0">
      <inertial mass="10.1217088896" pos="-0.0707000000 0.0000000000 0.0000000000" fullinertia="0.0883511653 0.0748578453 0.0497619890 0.0000000000 0.0000000000 0.0000000000" />
      <geom name="pelvis_geom_1" type="mesh" mesh="pelvis_geom_1_r_pelvis" rgba="1 1 1 1" group="0" />
      <geom name="pelvis_geom_2" type="mesh" mesh="pelvis_geom_2_l_pelvis" rgba="1 1 1 1" group="0" />
      <geom name="pelvis_geom_3" type="mesh" mesh="pelvis_geom_3_sacrum" rgba="1 1 1 1" group="0" />
      <geom name="Gmax1_at_pelvis_r_cylinder" type="cylinder" euler="-0.6 0.45 0" pos="-0.07342 -0.09862 0.06436" size="0.0397 0.07661" rgba="0.19 0.83 0.78 0.2" group="2" />
      <site name="Gmax1_at_pelvis_r_sidesite" pos="-0.1101 -0.08862 0.07898" size="0.0005" />
      <geom name="Gmax2_at_pelvis_r_cylinder" type="cylinder" euler="-0.75 0.39 0" pos="-0.07628 -0.08268 0.07175" size="0.03977 0.05089" rgba="0.19 0.83 0.78 0.2" group="2" />
      <geom name="Gmax3_at_pelvis_r_cylinder" type="cylinder" euler="-0.1 0 0" pos="-0.07914 -0.08766 0.07175" size="0.03901 0.05273" rgba="0.19 0.83 0.78 0.2" group="2" />
      <geom name="Gmax1_at_pelvis_l_cylinder" type="cylinder" euler="0.6 -0.45 0" pos="-0.07342 -0.09862 -0.06436" size="0.0397 0.07661" rgba="0.19 0.83 0.78 0.2" group="2" />
      <site name="Gmax1_at_pelvis_l_sidesite" pos="-0.1101 -0.08862 -0.07898" size="0.0005" />
      <geom name="Gmax2_at_pelvis_l_cylinder" type="cylinder" euler="0.75 -0.39 0" pos="-0.07628 -0.08268 -0.07175" size="0.03977 0.05089" rgba="0.19 0.83 0.78 0.2" group="2" />
      <geom name="Gmax3_at_pelvis_l_cylinder" type="cylinder" euler="0.1 0 0" pos="-0.07914 -0.08766 -0.07175" size="0.03901 0.05273" rgba="0.19 0.83 0.78 0.2" group="2" />
      <geom name="PS_at_brim_r_cylinder" type="cylinder" euler="-0.25 -0.27 0.1" pos="-0.07056 -0.05977 0.06922" size="0.04902 0.05225" rgba="0.19 0.83 0.78 0.2" group="2" />
      <site name="PS_at_brim_r_sidesite" pos="-0.06575 -0.1077 0.08282" size="0.0005" />
      <geom name="PS_at_brim_l_cylinder" type="cylinder" euler="0.25 0.27 0.1" pos="-0.07056 -0.05977 -0.06922" size="0.04902 0.05225" rgba="0.19 0.83 0.78 0.2" group="2" />
      <site name="PS_at_brim_l_sidesite" pos="-0.06575 -0.1077 -0.08282" size="0.0005" />
      <geom name="IL_at_brim_r_cylinder" type="cylinder" euler="-0.32 -0.24 0.9" pos="-0.0677 -0.06475 0.07977" size="0.05385 0.05221" rgba="0.19 0.83 0.78 0.2" group="2" />
      <site name="IL_at_brim_r_sidesite" pos="-0.02597 -0.0939 0.1002" size="0.0005" />
      <geom name="IL_at_brim_l_cylinder" type="cylinder" euler="0.32 0.24 0.9" pos="-0.0677 -0.06475 -0.07977" size="0.05385 0.05221" rgba="0.19 0.83 0.78 0.2" group="2" />
      <site name="IL_at_brim_l_sidesite" pos="-0.02597 -0.0939 -0.1002" size="0.0005" />
      <joint name="pelvis_tx" range="-40 40" limited="true" user="0.0" ref="0" axis="1 0 0" type="slide" damping="0" stiffness="0" />
      <joint name="pelvis_ty" range="-5 5" limited="true" user="0.93" ref="0" axis="0 1 0" type="slide" damping="0" stiffness="0" />
      <joint name="pelvis_tz" range="-40 40" limited="true" user="0.0" ref="0" axis="0 0 1" type="slide" damping="0" stiffness="0" />
      <joint name="pelvis_tilt" range="-3.142 3.142" limited="true" user="0.0" ref="0" axis="0 0 1" type="hinge" damping="0" stiffness="0" />
      <joint name="pelvis_list" range="-3.142 3.142" limited="true" user="0.0" ref="0" axis="1 0 0" type="hinge" damping="0" stiffness="0" />
      <joint name="pelvis_rotation" range="-3.142 3.142" limited="true" user="0.0" ref="0" axis="0 1 0" type="hinge" damping="0" stiffness="0" />
      <body name="femur_r" pos="-0.05366 -0.07819 0.08152" euler="-0 0 0">
        <inertial mass="7.9940615662" pos="0.0000000000 -0.1700000000 0.0000000000" fullinertia="0.1150799712 0.0301665944 0.1213539352 0.0000000000 0.0000000000 0.0000000000" />
        <geom name="femur_r_geom_1" type="mesh" mesh="femur_r_geom_1_r_femur" rgba="1 1 1 1" group="0" />
        <geom name="Gastroc_at_condyles_r_cylinder" type="cylinder" euler="0 0 0" pos="0.004962 -0.3977 0" size="0.02453 0.04826" rgba="0.19 0.83 0.78 0.2" group="2" />
        <geom name="KnExt_at_fem_r_cylinder" type="cylinder" euler="-0.06234 0.05076 0" pos="0.003561 -0.3906 0.002018" size="0.02453 0.04827" rgba="0.19 0.83 0.78 0.2" group="2" />
        <geom name="AB_at_femshaft_r_cylinder" type="cylinder" euler="1.662 0.1866 0" pos="0.01453 -0.1092 0.02255" size="0.01614 0.03397" rgba="0.19 0.83 0.78 0.2" group="2" />
        <geom name="AL_at_femshaft_r_cylinder" type="cylinder" euler="1.777 0.1365 0" pos="0.0305 -0.2249 0.01459" size="0.01967 0.04851" rgba="0.19 0.83 0.78 0.2" group="2" />
        <geom name="AMprox_at_femshaft_r_cylinder" type="cylinder" euler="1.611 0.1866 0" pos="0.005143 -0.0707 0.02452" size="0.02065 0.03398" rgba="0.19 0.83 0.78 0.2" group="2" />
        <geom name="AMmid_at_femshaft_r_cylinder" type="cylinder" euler="1.611 0.1366 0" pos="0.02284 -0.1559 0.01987" size="0.02094 0.05822" rgba="0.19 0.83 0.78 0.2" group="2" />
        <geom name="AMdist_at_femshaft_r_cylinder" type="cylinder" euler="1.712 0.1866 0" pos="0.03137 -0.2529 0.009039" size="0.02133 0.09706" rgba="0.19 0.83 0.78 0.2" group="2" />
        <geom name="AMisch_at_condyles_r_cylinder" type="cylinder" euler="1.711 -0.4634 0" pos="-0.02248 -0.3655 -0.003045" size="0.03907 0.1169" rgba="0.19 0.83 0.78 0.2" group="2" />
        <geom name="PECT_at_femshaft_r_cylinder" type="cylinder" euler="1.813 0.2763 0" pos="0.006039 -0.08196 0.02938" size="0.01467 0.02428" rgba="0.19 0.83 0.78 0.2" group="2" />
        <joint name="hip_flexion_r" range="-0.5236 2.094" limited="true" user="0.0" ref="0" axis="0 0 1" type="hinge" />
        <joint name="hip_adduction_r" range="-0.8727 0.5236" limited="true" user="0.0" ref="0" axis="1 0 0" type="hinge" />
        <joint name="hip_rotation_r" range="-0.6981 0.6981" limited="true" user="0.0" ref="0" axis="0 1 0" type="hinge" />
        <body name="tibia_r" pos="0.000143 -0.392 -0.001099" euler="-0 0 0">
          <inertial mass="3.1864002469" pos="0.0000000000 -0.1867000000 0.0000000000" fullinertia="0.0433161355 0.01 0.0439177485 0.0 0.0 0.0" />
          <geom name="tibia_r_geom_1" type="mesh" mesh="tibia_r_geom_1_r_tibia" rgba="1 1 1 1" group="0" />
          <geom name="tibia_r_geom_2" type="mesh" mesh="tibia_r_geom_2_r_fibula" rgba="1 1 1 1" group="0" />
          <geom name="GasLat_at_shank_r_cylinder" type="cylinder" euler="2.967 -0.2797 -1.478" pos="-0.007475 -0.07748 -0.003457" size="0.05665 0.05224" rgba="0.19 0.83 0.78 0.2" group="2" />
          <site name="GasLat_at_shank_r_sidesite" pos="-0.06265 -0.06948 0.01123" size="0.0005" />
          <geom name="GasMed_at_shank_r_cylinder" type="cylinder" euler="2.967 0.02797 -1.478" pos="-0.007475 -0.07748 -0.003457" size="0.05657 0.05237" rgba="0.19 0.83 0.78 0.2" group="2" />
          <site name="GasMed_at_shank_r_sidesite" pos="-0.06478 -0.07252 -0.00596" size="0.0005" />
          <geom name="GR_at_condyles_r_cylinder" type="cylinder" euler="0 -0.4 0" pos="-0.00303 -0.02094 0" size="0.03713 0.0521" rgba="0.19 0.83 0.78 0.2" group="2" />
          <geom name="SM_at_condyles_r_cylinder" type="cylinder" euler="0 -0.1 0" pos="-0.00101 -0.02094 0" size="0.03621 0.05236" rgba="0.19 0.83 0.78 0.2" group="2" />
          <geom name="ST_at_condyles_r_cylinder" type="cylinder" euler="0 -0.2 0" pos="-0.00202 -0.02147 0" size="0.04375 0.0523" rgba="0.19 0.83 0.78 0.2" group="2" />
          <geom name="BF_at_gastroc_r_cylinder" type="cylinder" euler="0 0 0" pos="-0.05859 -0.06283 0" size="0.03086 0.07856" rgba="0.19 0.83 0.78 0.2" group="2" />
          <site name="BF_at_gastroc_r_sidesite" pos="-0.05859 -0.03097 0" size="0.0005" />
          <joint name="walker_knee_r_translation1" range="0 0.001551" limited="true" user="9.250779579644472e-08" ref="0" axis="-0.1243 0.9898 -0.07016" type="slide" />
          <joint name="walker_knee_r_translation2" range="0 0.006556" limited="true" user="7.425274024114303e-11" ref="0" axis="0.9922 0.124 -0.008789" type="slide" />
          <joint name="knee_angle_r" range="0 2.094" limited="true" user="0.0" ref="0" axis="-4.566e-07 -0.07071 -0.9975" type="hinge" />
          <joint name="walker_knee_r_rotation2" range="-0.001678 0.03354" limited="true" user="-1.4732523263838448e-08" ref="0" axis="0.9922 0.124 -0.008789" type="hinge" />
          <joint name="walker_knee_r_rotation3" range="0 0.2628" limited="true" user="1.0893911855935912e-08" ref="0" axis="-0.1243 0.9898 -0.07016" type="hinge" />
          <body name="talus_r" pos="-0.0101 -0.4188 0" euler="-0 0 0">
            <inertial mass="0.25" pos="0.0000000000 0.0000000000 0.0000000000" fullinertia="0.01 0.01 0.01 0.0 0.0 0.0" />
            <geom name="talus_r_geom_1" type="mesh" mesh="talus_r_geom_1_r_talus" rgba="1 1 1 0" group="0" />
            <joint name="ankle_angle_r" range="-0.6981 0.5236" limited="true" user="0.0" ref="0" type="hinge" axis="-0.105 -0.174 0.9791" />
            <body name="calcn_r" pos="-0.04975 -0.04416 0.008183" euler="-0 0 0">
              <inertial mass="1.0743089167" pos="0.1000000000 0.0300000000 0.0000000000" fullinertia="0.01 0.01 0.01 0.0 0.0 0.0" />
              <geom name="calcn_r_geom_1" type="mesh" mesh="calcn_r_geom_1_r_foot" rgba="1 1 1 1" group="0" />
              <joint name="subtalar_angle_r" range="-0.3491 0.3491" limited="true" user="0.0" ref="0" type="hinge" axis="0.7872 0.6047 -0.1209" />
              <body name="toes_r" pos="0.1879 -0.002061 0.00108" euler="-0 0 0">
                <inertial mass="0.25" pos="0.0346000000 0.0060000000 -0.0175000000" fullinertia="0.01 0.01 0.01 0.0 0.0 0.0" />
                <geom name="toes_r_geom_1" type="mesh" mesh="toes_r_geom_1_r_bofoot" rgba="1 1 1 1" group="0" />
                <joint name="mtp_angle_r" range="-0.5236 0.5236" limited="true" user="0.0" ref="0" type="hinge" axis="0.581 2.16e-06 -0.8139" />
                <site name="edl_r_edl_r-P5" pos="0.00030642936704999998 0.0048001908038099996 0.01563175551969" />
                <site name="edl_r_edl_r-P6" pos="0.045249403201050004 -0.00040852687691999998 0.025542084182500004" />
                <site name="ehl_r_ehl_r-P7" pos="0.030438650460300001 0.0041874004884300004 -0.025031242498850002" />
                <site name="ehl_r_ehl_r-P8" pos="0.057506577883050004 0.0034724784538199996 -0.019003310631779999" />
                <site name="fdl_r_fdl_r-P6" pos="-0.0019407193246500001 -0.0079662740999399996 0.015018745499310001" />
                <site name="fdl_r_fdl_r-P7" pos="0.029110789869750003 -0.0072513520653300001 0.02196619239695" />
                <site name="fdl_r_fdl_r-P8" pos="0.045045116956350002 -0.0061279031538000002 0.024724737488660001" />
                <site name="fhl_r_fhl_r-P6" pos="0.015832183964249999 -0.0065364300307199997 -0.027074609233450002" />
                <site name="fhl_r_fhl_r-P7" pos="0.0574044347607 -0.01041743536146 -0.018492468948130003" />
              </body>
              <site name="edl_r_edl_r-P3" pos="0.096593916252539991 0.03710527349759999 0.00080013071736000009" />
              <site name="edl_r_edl_r-P4" pos="0.16985393761055997 0.0056688612287999988 0.0130021241571" />
              <site name="ehl_r_ehl_r-P4" pos="0.1019544056202 0.040094309418239993 -0.021103447670370003" />
              <site name="ehl_r_ehl_r-P5" pos="0.13590417161537999 0.03184869308544 -0.025704199295190001" />
              <site name="ehl_r_ehl_r-P6" pos="0.18225663850043999 0.014326758378239999 -0.028004575107600002" />
              <site name="fdl_r_fdl_r-P3" pos="0.045826928711759994 0.032467114310399996 -0.028004575107600002" />
              <site name="fdl_r_fdl_r-P4" pos="0.074416205339279992 0.018140355932159999 -0.026304297333210002" />
              <site name="fdl_r_fdl_r-P5" pos="0.17426845826627999 -0.0083486865369599983 0.01160189540172" />
              <site name="fhl_r_fhl_r-P3" pos="0.039310255362840003 0.028447376348159997 -0.024103937860470003" />
              <site name="fhl_r_fhl_r-P4" pos="0.10910172477707999 0.0070087738828799985 -0.025604182955520003" />
              <site name="fhl_r_fhl_r-P5" pos="0.18141577742315998 -0.0054627208204799998 -0.026904395371230003" />
              <site name="gaslat_r_gaslat_r-P2" pos="0.0046247359250399999 0.031951763289599998 -0.0053008660025100005" />
              <site name="gasmed_r_gasmed_r-P2" pos="0.0046247359250399999 0.031951763289599998 -0.0053008660025100005" />
              <site name="perbrev_r_perbrev_r-P4" pos="0.049505695924860003 0.027828955123199998 0.023303807143110002" />
              <site name="perbrev_r_perbrev_r-P5" pos="0.07115786866481999 0.022572374711039997 0.03430560450681" />
              <site name="perlong_r_perlong_r-P4" pos="0.046037143981079998 0.023706146956799998 0.022103611067070005" />
              <site name="perlong_r_perlong_r-P5" pos="0.071578299203459983 0.01092544164096 0.028404640466280006" />
              <site name="perlong_r_perlong_r-P6" pos="0.089551704730319995 0.0071118440870399993 0.01180192808106" />
              <site name="perlong_r_perlong_r-P7" pos="0.12644448449598 0.0087609673535999997 -0.018403006499280002" />
              <site name="soleus_r_soleus_r-P2" pos="0.0046247359250399999 0.031951763289599998 -0.0053008660025100005" />
              <site name="tibant_r_tibant_r-P4" pos="0.12255550201355998 0.018346496340479999 -0.030504983599350003" />
              <site name="tibpost_r_tibpost_r-P3" pos="0.043829883653219999 0.034425448189439996 -0.028604673145620003" />
              <site name="tibpost_r_tibpost_r-P4" pos="0.081143093957519993 0.016388162461439999 -0.028104591447270004" />
              <site name="R.Heel_marker" group="4" pos="-0.02934 0.01153 -0.00878" rgba="1 0.1 0.5 0.5" size="0.01" />
              <site name="R.Midfoot.Superior_marker" group="4" pos="0.1493 0.008623 0.06125" rgba="1 0.1 0.5 0.5" size="0.01" />
              <site name="R.Midfoot.Lateral_marker" group="4" pos="0.1411 0.001467 0.06592" rgba="1 0.1 0.5 0.5" size="0.01" />
              <site name="R.Toe_marker" group="4" pos="0.2549 0.01343 0.01413" rgba="1 0.1 0.5 0.5" size="0.01" />
            </body>
          </body>
          <site name="bflh_r_bflh_r-P2" pos="-0.034040694167040003 -0.036648281845000005 0.02650256057405" />
          <site name="bflh_r_bflh_r-P3" pos="-0.028990146071040002 -0.0476427663985 0.031740220766549997" />
          <site name="bfsh_r_bfsh_r-P2" pos="-0.030404299537919999 -0.0438732288373 0.033311518824300002" />
          <site name="edl_r_edl_r-P1" pos="-0.0161617539072 -0.12114874884189999 0.02147440678925" />
          <site name="edl_r_edl_r-P2" pos="0.016565797754880002 -0.39370725639199999 0.011732358831199999" />
          <site name="ehl_r_ehl_r-P1" pos="-0.014141534668800002 -0.16229953388500001 0.01979835552765" />
          <site name="ehl_r_ehl_r-P2" pos="0.0071717782963200008 -0.30459957682029998 0.0171795254314" />
          <site name="ehl_r_ehl_r-P3" pos="0.020202192384000003 -0.38669172815310004 -0.0029330897077999999" />
          <site name="fdl_r_fdl_r-P1" pos="-0.00232325212416 -0.19182757811440002 -0.0018855576692999999" />
          <site name="fdl_r_fdl_r-P2" pos="-0.017777929297920003 -0.38166567807149998 -0.012989397277399999" />
          <site name="fhl_r_fhl_r-P1" pos="-0.031313398195200001 -0.22648638180209998 0.020950640770000001" />
          <site name="fhl_r_fhl_r-P2" pos="-0.024444652784640003 -0.38438812186569998 -0.0079612434926000005" />
          <site name="grac_r_grac_r-P2" pos="-0.018606219185664002 -0.049789308620850001 -0.031017423659985" />
          <site name="grac_r_grac_r-P3" pos="0.0017979951221760002 -0.072898668058540006 -0.016477678965605001" />
          <site name="GR_at_condyles_r_cylinder_grac_r_1_sidesite" pos="-0.01561 -0.006327 -0.03363" size="0.0005" />
          <site name="perbrev_r_perbrev_r-P1" pos="-0.02454566374656 -0.26512414180439997 0.026293054166349999" />
          <site name="perbrev_r_perbrev_r-P2" pos="-0.034242716090880004 -0.40763360349309996 0.026083547758649999" />
          <site name="perbrev_r_perbrev_r-P3" pos="-0.028788124147200004 -0.41925634430679998 0.026712066981749997" />
          <site name="perlong_r_perlong_r-P1" pos="-0.020202192384000003 -0.14376597420910001 0.029540403485699997" />
          <site name="perlong_r_perlong_r-P2" pos="-0.032020474928639998 -0.40836656913000002 0.02482650931245" />
          <site name="perlong_r_perlong_r-P3" pos="-0.02747498164224 -0.4203034380738 0.025140768923999999" />
          <site name="recfem_r_recfem_r-P5" pos="0.032929573585919997 -0.06609255857304 -0.00049234005809500002" />
          <site name="sart_r_sart_r-P3" pos="-0.025353751441920001 -0.041988460056699997 -0.038234919405249999" />
          <site name="sart_r_sart_r-P4" pos="-0.016060742945280003 -0.062720916643299998 -0.027654845816400001" />
          <site name="sart_r_sart_r-P5" pos="0.01373749082112 -0.084814595127 -0.0027235833000999999" />
          <site name="semimem_r_semimem_r-P2" pos="-0.029293178956800003 -0.043663810083900002 -0.0205316279546" />
          <site name="SM_at_condyles_r_cylinder_semimem_r_1_sidesite" pos="-0.02929 -0.04366 -0.02053" size="0.0005" />
          <site name="semiten_r_semiten_r-P2" pos="-0.031515420119040002 -0.053192363363599997 -0.023988483681649998" />
          <site name="semiten_r_semiten_r-P3" pos="0.0019192082764800001 -0.080940348189099995 -0.012256124850450001" />
          <site name="ST_at_condyles_r_cylinder_semiten_r_1_sidesite" pos="-0.03563 -0.007868 -0.02622" size="0.0005" />
          <site name="soleus_r_soleus_r-P1" pos="-0.0076768331059200003 -0.095913789057200008 0.0102658139773" />
          <site name="tfl_r_tfl_r-P4" pos="0.010909183887360001 -0.042930844447000002 0.036244608532100001" />
          <site name="tibant_r_tibant_r-P1" pos="0.015555688135680002 -0.13737870223040002 0.0169700190237" />
          <site name="tibant_r_tibant_r-P2" pos="0.025353751441920001 -0.1995760719902 0.013408410092800001" />
          <site name="tibant_r_tibant_r-P3" pos="0.023535554127360005 -0.38313160934529999 -0.0138274229082" />
          <site name="tibpost_r_tibpost_r-P1" pos="-0.0041414494387200006 -0.13654102721679998 0.010789579996549999" />
          <site name="tibpost_r_tibpost_r-P2" pos="-0.016565797754880002 -0.3827127718385 -0.018331810673750001" />
          <site name="vasint_r_vasint_r-P5" pos="0.032899270297344005 -0.066176326074400008 0.00045043877655499999" />
          <site name="vaslat_r_vaslat_r-P5" pos="0.032868967008767999 -0.06636480295246 0.0053528887167349996" />
          <site name="vasmed_r_vasmed_r-P5" pos="0.03222249685248 -0.066563750768190003 -0.0071022672210299996" />
          <site name="R.Shank.Superior_marker" group="4" pos="0.06118 -0.1425 -0.004394" rgba="1 0.1 0.5 0.5" size="0.01" />
          <site name="R.Shank.Inferior_marker" group="4" pos="0.04867 -0.314 -0.0003518" rgba="1 0.1 0.5 0.5" size="0.01" />
          <site name="R.Shank.Lateral_marker" group="4" pos="0.007675 -0.2111 0.05252" rgba="1 0.1 0.5 0.5" size="0.01" />
        </body>
        <body name="patella_r" pos="-0.008028 -0.3957 -0.002654" euler="-0 0 0">
          <inertial mass="0.25" pos="0.0018 0.0264 0" fullinertia="0.01 0.01 0.01 0.0 0.0 0.0" />
          <geom name="patella_r_geom_1" type="mesh" mesh="patella_r_geom_1_r_patella" rgba="1 1 1 1" group="0" />
          <joint name="patellofemoral_r_translation1" range="-0.02253 0.052" limited="true" user="0.052019826017989004" ref="0" axis="1 0 0" type="slide" />
          <joint name="patellofemoral_r_translation2" range="-0.03957 -0.01048" limited="true" user="-0.010502791809301835" ref="0" axis="0 1 0" type="slide" />
          <joint name="patellofemoral_r_translation3" limited="false" ref="0" axis="0 0 1" type="slide" />
          <joint name="patellofemoral_r_rotation1" range="-1.786 0.001137" limited="true" user="0.01050598499723554" ref="0" axis="0 0 1" type="hinge" />
          <site name="recfem_r_recfem_r-P2" pos="0.01 0.049000000000000002 0.00069999999999999999" />
          <site name="recfem_r_recfem_r-P3" pos="0.0121 0.043700000000000003 -0.001" />
          <site name="recfem_r_recfem_r-P4" pos="0.0050000000000000001 0.00247 3.0000000000000001e-05" />
          <site name="vasint_r_vasint_r-P3" pos="0.0057999999999999996 0.048000000000000001 -0.00059999999999999995" />
          <site name="vasint_r_vasint_r-P4" pos="0.0050000000000000001 0.00247 -0.00038999999999999999" />
          <site name="vaslat_r_vaslat_r-P3" pos="0.0103 0.042299999999999997 0.0141" />
          <site name="vaslat_r_vaslat_r-P4" pos="0.0050000000000000001 0.00247 0.0073299999999999997" />
          <site name="vasmed_r_vasmed_r-P3" pos="0.0063 0.044499999999999998 -0.017000000000000001" />
          <site name="vasmed_r_vasmed_r-P4" pos="0.0050000000000000001 0.00247 -0.0085000000000000006" />
          <site name="R.Patella_marker" group="4" pos="0.03402 0.02529 -0.00121" rgba="1 0.1 0.5 0.5" size="0.01" />
        </body>
        <site name="addbrev_r_addbrev_r-P2" pos="-0.0019847611321999999 -0.11445462414419999 0.02403487557279" />
        <site name="AB_at_femshaft_r_cylinder_addbrev_r_1_sidesite" pos="0.001317 -0.1031 0.01353" size="0.0005" />
        <site name="addlong_r_addlong_r-P2" pos="0.011174205174286 -0.23217799475760301 0.015280003225593001" />
        <site name="AL_at_femshaft_r_cylinder_addlong_r_1_sidesite" pos="0.01117 -0.2322 0.01528" size="0.0005" />
        <site name="addmagDist_r_addmagDist_r-P2" pos="0.011164281368625 -0.25461304099875004 0.018629441709030001" />
        <site name="AMdist_at_femshaft_r_cylinder_addmagDist_r_1_sidesite" pos="0.01116 -0.2546 0.01863" size="0.0005" />
        <site name="addmagIsch_r_addmagIsch_r-P2" pos="0.0047733505229410004 -0.37631322482394297 -0.031592830421583" />
        <site name="AMisch_at_condyles_r_cylinder_addmagIsch_r_1_sidesite" pos="0.004773 -0.3763 -0.03159" size="0.0005" />
        <site name="addmagMid_r_addmagMid_r-P2" pos="0.0024015609699620001 -0.15752060136456 0.028204781696262001" />
        <site name="AMmid_at_femshaft_r_cylinder_addmagMid_r_1_sidesite" pos="0.002402 -0.1575 0.0282" size="0.0005" />
        <site name="addmagProx_r_addmagProx_r-P2" pos="-0.015153651244347002 -0.076490607288233994 0.030907498628141999" />
        <site name="AMprox_at_femshaft_r_cylinder_addmagProx_r_1_sidesite" pos="-0.01568 -0.07136 0.01863" size="0.0005" />
        <site name="bfsh_r_bfsh_r-P1" pos="0.0049619028305000002 -0.20475738268509 0.02258699150214" />
        <site name="gaslat_r_gaslat_r-P1" pos="-0.0029771416983000003 -0.36994062414066003 0.026737592504669998" />
        <site name="Gastroc_at_condyles_r_cylinder_gaslat_r_1_sidesite" pos="-0.008767 -0.4203 0.02396" size="0.0005" />
        <site name="gasmed_r_gasmed_r-P1" pos="0.0079390445287999996 -0.36741874259172003 -0.020077325779679998" />
        <site name="Gastroc_at_condyles_r_cylinder_gasmed_r_1_sidesite" pos="0.0009367 -0.418 -0.01765" size="0.0005" />
        <site name="glmax1_r_glmax1_r-P3" pos="-0.044061697134840004 -0.031620514805939998 0.029150732622420003" />
        <site name="glmax1_r_glmax1_r-P4" pos="-0.027488941680969999 -0.05489942141154 0.045367034213700003" />
        <site name="glmax2_r_glmax2_r-P3" pos="-0.044657125474500001 -0.056645339406960003 0.024324452386919999" />
        <site name="glmax2_r_glmax2_r-P4" pos="-0.01548113683116 -0.098547371297039998 0.040444228373490002" />
        <site name="glmax3_r_glmax3_r-P3" pos="-0.02788589390741 -0.10911987471375001 0.0090734068427400002" />
        <site name="glmax3_r_glmax3_r-P4" pos="-0.0059542833966000006 -0.13763653530561001 0.039672023535810001" />
        <site name="glmed1_r_glmed1_r-P2_0" pos="-0.013785907409400068 -0.017745030505745784 0.057133138358118986" />
        <site name="glmed2_r_glmed2_r-P2_0" pos="-0.021868112321669412 -0.009659870370618516 0.054176176749189398" />
        <site name="glmed3_r_glmed3_r-P2_0" pos="-0.030664559492490001 -0.0045587858769300001 0.050000263239779998" />
        <site name="glmin1_r_glmin1_r-P2" pos="0.0054474932765753671 -0.015023237440454225 0.054090827934501824" />
        <site name="glmin2_r_glmin2_r-P2" pos="0.0035165411544973374 -0.0087414903216349732 0.050641509578124307" />
        <site name="glmin3_r_glmin3_r-P2" pos="-0.0035488891953203323 -0.0012286420373048936 0.049480617191481398" />
        <site name="iliacus_r_iliacus_r-P3" pos="-0.0022824753020299999 -0.054802425967350001 0.013417059054689999" />
        <site name="iliacus_r_iliacus_r-P4" pos="-0.012107042906420002 -0.061786097949030006 0.018919018523160001" />
        <site name="piri_r_piri_r-P3" pos="-0.014687232378280001 -0.0034918359908399999 0.042181689258270004" />
        <site name="psoas_r_psoas_r-P3" pos="-0.013099423472519999 -0.045296872436730001 0.0044401778166600001" />
        <site name="psoas_r_psoas_r-P4" pos="-0.023320943303350002 -0.050825612755560003 0.00849425321448" />
        <site name="KnExt_at_fem_r_cylinder_recfem_r_3_sidesite" pos="-0.01554 -0.3842 -0.01365" size="0.0005" />
        <site name="sart_r_sart_r-P2" pos="-0.0029771416983000003 -0.34607974486991999 -0.040637279582909996" />
        <site name="tfl_r_tfl_r-P2" pos="0.029175988643339999 -0.09651046696905001 0.057625786011870003" />
        <site name="tfl_r_tfl_r-P3" pos="0.01061847205727 -0.39283154896950001 0.031274295926040002" />
        <site name="vasint_r_vasint_r-P1" pos="0.028779036416900002 -0.18661923462155999 0.0299229374601" />
        <site name="vasint_r_vasint_r-P2" pos="0.03324474896435 -0.20213850569196001 0.027509797342350002" />
        <site name="KnExt_at_fem_r_cylinder_vasint_r_3_sidesite" pos="-0.01573 -0.3834 -0.01307" size="0.0005" />
        <site name="vaslat_r_vaslat_r-P1" pos="0.0047634267172799996 -0.17982955352826002 0.033687436043790001" />
        <site name="vaslat_r_vaslat_r-P2" pos="0.02669503722809 -0.25131519589628998 0.039478972326389999" />
        <site name="KnExt_at_fem_r_cylinder_vaslat_r_3_sidesite" pos="-0.01792 -0.3842 0.01423" size="0.0005" />
        <site name="vasmed_r_vasmed_r-P1" pos="0.0138933279254 -0.20359343735481 0.01814681368548" />
        <site name="vasmed_r_vasmed_r-P2" pos="0.035328748153159999 -0.26858038496211001 0.00086873044239000002" />
        <site name="KnExt_at_fem_r_cylinder_vasmed_r_4_sidesite" pos="-0.007683 -0.3951 -0.02046" size="0.0005" />
        <site name="KnExt_at_fem_r_cylinder_vasmed_r_3_sidesite" pos="-0.007683 -0.3951 -0.02046" size="0.0005" />
        <site name="R.Thigh.Superior_marker" group="4" pos="0.06677 -0.1477 0.03508" rgba="1 0.1 0.5 0.5" size="0.01" />
        <site name="R.Thigh.Inferior_marker" group="4" pos="0.07752 -0.2933 0.01138" rgba="1 0.1 0.5 0.5" size="0.01" />
        <site name="R.Thigh.Lateral_marker" group="4" pos="0.01847 -0.2334 0.08104" rgba="1 0.1 0.5 0.5" size="0.01" />
      </body>
      <body name="femur_l" pos="-0.05366 -0.07819 -0.08152" euler="-0 0 0">
        <inertial mass="7.9940615662" pos="0.0000000000 -0.1700000000 0.0000000000" fullinertia="0.1150799712 0.0301665944 0.1213539352 0.0000000000 0.0000000000 0.0000000000" />
        <geom name="femur_l_geom_1" type="mesh" mesh="femur_l_geom_1_l_femur" rgba="1 1 1 1" group="0" />
        <geom name="Gastroc_at_condyles_l_cylinder" type="cylinder" euler="0 0 0" pos="0.004962 -0.3977 0" size="0.02453 0.04826" rgba="0.19 0.83 0.78 0.2" group="2" />
        <geom name="KnExt_at_fem_l_cylinder" type="cylinder" euler="0.06234 -0.05076 0" pos="0.003561 -0.3906 -0.002018" size="0.02453 0.04827" rgba="0.19 0.83 0.78 0.2" group="2" />
        <geom name="AB_at_femshaft_l_cylinder" type="cylinder" euler="-1.662 -0.1866 0" pos="0.01453 -0.1092 -0.02255" size="0.01614 0.03397" rgba="0.19 0.83 0.78 0.2" group="2" />
        <geom name="AL_at_femshaft_l_cylinder" type="cylinder" euler="-1.777 -0.1365 0" pos="0.0305 -0.2249 -0.01459" size="0.01967 0.04851" rgba="0.19 0.83 0.78 0.2" group="2" />
        <geom name="AMprox_at_femshaft_l_cylinder" type="cylinder" euler="-1.611 -0.1866 0" pos="0.005143 -0.0707 -0.02452" size="0.02065 0.03398" rgba="0.19 0.83 0.78 0.2" group="2" />
        <geom name="AMmid_at_femshaft_l_cylinder" type="cylinder" euler="-1.611 -0.1366 0" pos="0.02284 -0.1559 -0.01987" size="0.02094 0.05822" rgba="0.19 0.83 0.78 0.2" group="2" />
        <geom name="AMdist_at_femshaft_l_cylinder" type="cylinder" euler="-1.712 -0.1866 0" pos="0.03137 -0.2529 -0.009039" size="0.02133 0.09706" rgba="0.19 0.83 0.78 0.2" group="2" />
        <geom name="AMisch_at_condyles_l_cylinder" type="cylinder" euler="-1.711 0.4634 0" pos="-0.02248 -0.3655 0.003045" size="0.03907 0.1169" rgba="0.19 0.83 0.78 0.2" group="2" />
        <geom name="PECT_at_femshaft_l_cylinder" type="cylinder" euler="-1.813 -0.2763 0" pos="0.006039 -0.08196 -0.02938" size="0.01467 0.02428" rgba="0.19 0.83 0.78 0.2" group="2" />
        <joint name="hip_flexion_l" range="-0.5236 2.094" limited="true" user="0.0" ref="0" axis="0 0 1" type="hinge" />
        <joint name="hip_adduction_l" range="-0.8727 0.5236" limited="true" user="-0.0" ref="0" axis="-1 -0 -0" type="hinge" />
        <joint name="hip_rotation_l" range="-0.6981 0.6981" limited="true" user="-0.0" ref="0" axis="-0 -1 -0" type="hinge" />
        <body name="tibia_l" pos="0.000143 -0.392 0.001099" euler="-0 0 0">
          <inertial mass="3.1864002469" pos="0.0000000000 -0.1867000000 0.0000000000" fullinertia="0.0433161355 0.01 0.0439177485 0.0 0.0 0.0" />
          <geom name="tibia_l_geom_1" type="mesh" mesh="tibia_l_geom_1_l_tibia" rgba="1 1 1 1" group="0" />
          <geom name="tibia_l_geom_2" type="mesh" mesh="tibia_l_geom_2_l_fibula" rgba="1 1 1 1" group="0" />
          <geom name="GasLat_at_shank_l_cylinder" type="cylinder" euler="-2.967 0.2797 -1.478" pos="-0.007475 -0.07748 0.003457" size="0.05665 0.05224" rgba="0.19 0.83 0.78 0.2" group="2" />
          <site name="GasLat_at_shank_l_sidesite" pos="-0.06265 -0.06948 -0.01123" size="0.0005" />
          <geom name="GasMed_at_shank_l_cylinder" type="cylinder" euler="-2.967 -0.02797 -1.478" pos="-0.007475 -0.07748 0.003457" size="0.05657 0.05237" rgba="0.19 0.83 0.78 0.2" group="2" />
          <site name="GasMed_at_shank_l_sidesite" pos="-0.06478 -0.07252 0.00596" size="0.0005" />
          <geom name="GR_at_condyles_l_cylinder" type="cylinder" euler="0 0.4 0" pos="-0.00303 -0.02094 0" size="0.03713 0.0521" rgba="0.19 0.83 0.78 0.2" group="2" />
          <geom name="SM_at_condyles_l_cylinder" type="cylinder" euler="0 0.1 0" pos="-0.00101 -0.02094 0" size="0.03621 0.05236" rgba="0.19 0.83 0.78 0.2" group="2" />
          <geom name="ST_at_condyles_l_cylinder" type="cylinder" euler="0 0.2 0" pos="-0.00202 -0.02147 0" size="0.04375 0.0523" rgba="0.19 0.83 0.78 0.2" group="2" />
          <geom name="BF_at_gastroc_l_cylinder" type="cylinder" euler="0 0 0" pos="-0.05859 -0.06283 0" size="0.03086 0.07856" rgba="0.19 0.83 0.78 0.2" group="2" />
          <joint name="walker_knee_l_translation1" range="0 0.001551" limited="true" user="9.250779579644472e-08" ref="0" axis="-0.1243 0.9898 0.07016" type="slide" />
          <joint name="walker_knee_l_translation2" range="-0.006556 0" limited="true" user="-7.425274024114303e-11" ref="0" axis="-0.9922 -0.124 -0.008789" type="slide" />
          <joint name="knee_angle_l" range="0 2.094" limited="true" user="0.0" ref="0" axis="4.566e-07 0.07071 -0.9975" type="hinge" />
          <joint name="walker_knee_l_rotation2" range="-0.001678 0.03354" limited="true" user="-1.4732523263838448e-08" ref="0" axis="-0.9922 -0.124 -0.008789" type="hinge" />
          <joint name="walker_knee_l_rotation3" range="-0.2628 0" limited="true" user="-1.0893911855935912e-08" ref="0" axis="-0.1243 0.9898 0.07016" type="hinge" />
          <body name="talus_l" pos="-0.0101 -0.4188 0" euler="-0 0 0">
            <inertial mass="0.25" pos="0.0000000000 0.0000000000 0.0000000000" fullinertia="0.01 0.01 0.01 0.0 0.0 0.0" />
            <geom name="talus_l_geom_1" type="mesh" mesh="talus_l_geom_1_l_talus" rgba="1 1 1 0" group="0" />
            <joint name="ankle_angle_l" range="-0.6981 0.5236" limited="true" user="0.0" ref="0" type="hinge" axis="0.105 0.174 0.9791" />
            <body name="calcn_l" pos="-0.04975 -0.04416 -0.008183" euler="-0 0 0">
              <inertial mass="1.0743089167" pos="0.1000000000 0.0300000000 0.0000000000" fullinertia="0.01 0.01 0.01 0.0 0.0 0.0" />
              <geom name="calcn_l_geom_1" type="mesh" mesh="calcn_l_geom_1_l_foot" rgba="1 1 1 1" group="0" />
              <joint name="subtalar_angle_l" range="-0.3491 0.3491" limited="true" user="0.0" ref="0" type="hinge" axis="-0.7872 -0.6047 -0.1209" />
              <body name="toes_l" pos="0.1879 -0.002061 -0.00108" euler="-0 0 0">
                <inertial mass="0.25" pos="0.0346000000 0.0060000000 0.0175000000" fullinertia="0.01 0.01 0.01 0.0 0.0 0.0" />
                <geom name="toes_l_geom_1" type="mesh" mesh="toes_l_geom_1_l_bofoot" rgba="1 1 1 1" group="0" />
                <joint name="mtp_angle_l" range="-0.5236 0.5236" limited="true" user="0.0" ref="0" type="hinge" axis="-0.581 2.16e-06 -0.8139" />
                <site name="edl_l_edl_l-P5" pos="0.00030642936704999998 0.0048001908038099996 -0.01563175551969" />
                <site name="edl_l_edl_l-P6" pos="0.045249403201050004 -0.00040852687691999998 -0.025542084182500004" />
                <site name="ehl_l_ehl_l-P7" pos="0.030438650460300001 0.0041874004884300004 0.025031242498850002" />
                <site name="ehl_l_ehl_l-P8" pos="0.057506577883050004 0.0034724784538199996 0.019003310631779999" />
                <site name="fdl_l_fdl_l-P6" pos="-0.0019407193246500001 -0.0079662740999399996 -0.015018745499310001" />
                <site name="fdl_l_fdl_l-P7" pos="0.029110789869750003 -0.0072513520653300001 -0.02196619239695" />
                <site name="fdl_l_fdl_l-P8" pos="0.045045116956350002 -0.0061279031538000002 -0.024724737488660001" />
                <site name="fhl_l_fhl_l-P6" pos="0.015832183964249999 -0.0065364300307199997 0.027074609233450002" />
                <site name="fhl_l_fhl_l-P7" pos="0.0574044347607 -0.01041743536146 0.018492468948130003" />
              </body>
              <site name="edl_l_edl_l-P3" pos="0.096593916252539991 0.03710527349759999 -0.00080013071736000009" />
              <site name="edl_l_edl_l-P4" pos="0.16985393761055997 0.0056688612287999988 -0.0130021241571" />
              <site name="ehl_l_ehl_l-P4" pos="0.1019544056202 0.040094309418239993 0.021103447670370003" />
              <site name="ehl_l_ehl_l-P5" pos="0.13590417161537999 0.03184869308544 0.025704199295190001" />
              <site name="ehl_l_ehl_l-P6" pos="0.18225663850043999 0.014326758378239999 0.028004575107600002" />
              <site name="fdl_l_fdl_l-P3" pos="0.045826928711759994 0.032467114310399996 0.028004575107600002" />
              <site name="fdl_l_fdl_l-P4" pos="0.074416205339279992 0.018140355932159999 0.026304297333210002" />
              <site name="fdl_l_fdl_l-P5" pos="0.17426845826627999 -0.0083486865369599983 -0.01160189540172" />
              <site name="fhl_l_fhl_l-P3" pos="0.039310255362840003 0.028447376348159997 0.024103937860470003" />
              <site name="fhl_l_fhl_l-P4" pos="0.10910172477707999 0.0070087738828799985 0.025604182955520003" />
              <site name="fhl_l_fhl_l-P5" pos="0.18141577742315998 -0.0054627208204799998 0.026904395371230003" />
              <site name="gaslat_l_gaslat_l-P2" pos="0.0046247359250399999 0.031951763289599998 0.0053008660025100005" />
              <site name="gasmed_l_gasmed_l-P2" pos="0.0046247359250399999 0.031951763289599998 0.0053008660025100005" />
              <site name="perbrev_l_perbrev_l-P4" pos="0.049505695924860003 0.027828955123199998 -0.023303807143110002" />
              <site name="perbrev_l_perbrev_l-P5" pos="0.07115786866481999 0.022572374711039997 -0.03430560450681" />
              <site name="perlong_l_perlong_l-P4" pos="0.046037143981079998 0.023706146956799998 -0.022103611067070005" />
              <site name="perlong_l_perlong_l-P5" pos="0.071578299203459983 0.01092544164096 -0.028404640466280006" />
              <site name="perlong_l_perlong_l-P6" pos="0.089551704730319995 0.0071118440870399993 -0.01180192808106" />
              <site name="perlong_l_perlong_l-P7" pos="0.12644448449598 0.0087609673535999997 0.018403006499280002" />
              <site name="soleus_l_soleus_l-P2" pos="0.0046247359250399999 0.031951763289599998 0.0053008660025100005" />
              <site name="tibant_l_tibant_l-P4" pos="0.12255550201355998 0.018346496340479999 0.030504983599350003" />
              <site name="tibpost_l_tibpost_l-P3" pos="0.043829883653219999 0.034425448189439996 0.028604673145620003" />
              <site name="tibpost_l_tibpost_l-P4" pos="0.081143093957519993 0.016388162461439999 0.028104591447270004" />
              <site name="L.Heel_marker" group="4" pos="-0.0284 0.01079 0.009003" rgba="1 0.1 0.5 0.5" size="0.01" />
              <site name="L.Midfoot.Superior_marker" group="4" pos="0.1493 0.007517 -0.06224" rgba="1 0.1 0.5 0.5" size="0.01" />
              <site name="L.Midfoot.Lateral_marker" group="4" pos="0.1413 0.0003169 -0.06594" rgba="1 0.1 0.5 0.5" size="0.01" />
              <site name="L.Toe_marker" group="4" pos="0.2549 0.01323 -0.01581" rgba="1 0.1 0.5 0.5" size="0.01" />
            </body>
          </body>
          <site name="bflh_l_bflh_l-P2" pos="-0.034040694167040003 -0.036648281845000005 -0.02650256057405" />
          <site name="bflh_l_bflh_l-P3" pos="-0.028990146071040002 -0.0476427663985 -0.031740220766549997" />
          <site name="bfsh_l_bfsh_l-P2" pos="-0.030404299537919999 -0.0438732288373 -0.033311518824300002" />
          <site name="edl_l_edl_l-P1" pos="-0.0161617539072 -0.12114874884189999 -0.02147440678925" />
          <site name="edl_l_edl_l-P2" pos="0.016565797754880002 -0.39370725639199999 -0.011732358831199999" />
          <site name="ehl_l_ehl_l-P1" pos="-0.014141534668800002 -0.16229953388500001 -0.01979835552765" />
          <site name="ehl_l_ehl_l-P2" pos="0.0071717782963200008 -0.30459957682029998 -0.0171795254314" />
          <site name="ehl_l_ehl_l-P3" pos="0.020202192384000003 -0.38669172815310004 0.0029330897077999999" />
          <site name="fdl_l_fdl_l-P1" pos="-0.00232325212416 -0.19182757811440002 0.0018855576692999999" />
          <site name="fdl_l_fdl_l-P2" pos="-0.017777929297920003 -0.38166567807149998 0.012989397277399999" />
          <site name="fhl_l_fhl_l-P1" pos="-0.031313398195200001 -0.22648638180209998 -0.020950640770000001" />
          <site name="fhl_l_fhl_l-P2" pos="-0.024444652784640003 -0.38438812186569998 0.0079612434926000005" />
          <site name="grac_l_grac_l-P2" pos="-0.018606219185664002 -0.049789308620850001 0.031017423659985" />
          <site name="grac_l_grac_l-P3" pos="0.0017979951221760002 -0.072898668058540006 0.016477678965605001" />
          <site name="GR_at_condyles_l_cylinder_grac_l_1_sidesite" pos="-0.01561 -0.006327 0.03363" size="0.0005" />
          <site name="perbrev_l_perbrev_l-P1" pos="-0.02454566374656 -0.26512414180439997 -0.026293054166349999" />
          <site name="perbrev_l_perbrev_l-P2" pos="-0.034242716090880004 -0.40763360349309996 -0.026083547758649999" />
          <site name="perbrev_l_perbrev_l-P3" pos="-0.028788124147200004 -0.41925634430679998 -0.026712066981749997" />
          <site name="perlong_l_perlong_l-P1" pos="-0.020202192384000003 -0.14376597420910001 -0.029540403485699997" />
          <site name="perlong_l_perlong_l-P2" pos="-0.032020474928639998 -0.40836656913000002 -0.02482650931245" />
          <site name="perlong_l_perlong_l-P3" pos="-0.02747498164224 -0.4203034380738 -0.025140768923999999" />
          <site name="recfem_l_recfem_l-P5" pos="0.032929573585919997 -0.06609255857304 0.00049234005809500002" />
          <site name="sart_l_sart_l-P3" pos="-0.025353751441920001 -0.041988460056699997 0.038234919405249999" />
          <site name="sart_l_sart_l-P4" pos="-0.016060742945280003 -0.062720916643299998 0.027654845816400001" />
          <site name="sart_l_sart_l-P5" pos="0.01373749082112 -0.084814595127 0.0027235833000999999" />
          <site name="semimem_l_semimem_l-P2" pos="-0.029293178956800003 -0.043663810083900002 0.0205316279546" />
          <site name="SM_at_condyles_l_cylinder_semimem_l_1_sidesite" pos="-0.02929 -0.04366 0.02053" size="0.0005" />
          <site name="semiten_l_semiten_l-P2" pos="-0.031515420119040002 -0.053192363363599997 0.023988483681649998" />
          <site name="semiten_l_semiten_l-P3" pos="0.0019192082764800001 -0.080940348189099995 0.012256124850450001" />
          <site name="ST_at_condyles_l_cylinder_semiten_l_1_sidesite" pos="-0.03563 -0.007868 0.02622" size="0.0005" />
          <site name="soleus_l_soleus_l-P1" pos="-0.0076768331059200003 -0.095913789057200008 -0.0102658139773" />
          <site name="tfl_l_tfl_l-P4" pos="0.010909183887360001 -0.042930844447000002 -0.036244608532100001" />
          <site name="tibant_l_tibant_l-P1" pos="0.015555688135680002 -0.13737870223040002 -0.0169700190237" />
          <site name="tibant_l_tibant_l-P2" pos="0.025353751441920001 -0.1995760719902 -0.013408410092800001" />
          <site name="tibant_l_tibant_l-P3" pos="0.023535554127360005 -0.38313160934529999 0.0138274229082" />
          <site name="tibpost_l_tibpost_l-P1" pos="-0.0041414494387200006 -0.13654102721679998 -0.010789579996549999" />
          <site name="tibpost_l_tibpost_l-P2" pos="-0.016565797754880002 -0.3827127718385 0.018331810673750001" />
          <site name="vasint_l_vasint_l-P5" pos="0.032899270297344005 -0.066176326074400008 -0.00045043877655499999" />
          <site name="vaslat_l_vaslat_l-P5" pos="0.032868967008767999 -0.06636480295246 -0.0053528887167349996" />
          <site name="vasmed_l_vasmed_l-P5" pos="0.03222249685248 -0.066563750768190003 0.0071022672210299996" />
          <site name="L.Shank.Superior_marker" group="4" pos="0.06028 -0.1408 -0.002995" rgba="1 0.1 0.5 0.5" size="0.01" />
          <site name="L.Shank.Inferior_marker" group="4" pos="0.04865 -0.3143 -7.636e-05" rgba="1 0.1 0.5 0.5" size="0.01" />
          <site name="L.Shank.Lateral_marker" group="4" pos="0.009619 -0.2121 -0.05345" rgba="1 0.1 0.5 0.5" size="0.01" />
        </body>
        <body name="patella_l" pos="-0.008028 -0.3957 0.002654" euler="-0 0 0">
          <inertial mass="0.25" pos="0.0018 0.0264 0" fullinertia="0.01 0.01 0.01 0.0 0.0 0.0" />
          <geom name="patella_l_geom_1" type="mesh" mesh="patella_l_geom_1_l_patella" rgba="1 1 1 1" group="0" />
          <joint name="patellofemoral_l_translation1" range="-0.02253 0.052" limited="true" user="0.052019826017989004" ref="0" axis="1 0 0" type="slide" />
          <joint name="patellofemoral_l_translation2" range="-0.03957 -0.01048" limited="true" user="-0.010502791809301835" ref="0" axis="0 1 0" type="slide" />
          <joint name="patellofemoral_l_translation3" limited="false" ref="0" axis="0 0 1" type="slide" />
          <joint name="patellofemoral_l_rotation1" range="-1.786 0.001137" limited="true" user="0.01050598499723554" ref="0" axis="0 0 1" type="hinge" />
          <site name="recfem_l_recfem_l-P2" pos="0.01 0.049000000000000002 -0.00069999999999999999" />
          <site name="recfem_l_recfem_l-P3" pos="0.0121 0.043700000000000003 0.001" />
          <site name="recfem_l_recfem_l-P4" pos="0.0050000000000000001 0.00247 -3.0000000000000001e-05" />
          <site name="vasint_l_vasint_l-P3" pos="0.0057999999999999996 0.048000000000000001 0.00059999999999999995" />
          <site name="vasint_l_vasint_l-P4" pos="0.0050000000000000001 0.00247 0.00038999999999999999" />
          <site name="vaslat_l_vaslat_l-P3" pos="0.0103 0.042299999999999997 -0.0141" />
          <site name="vaslat_l_vaslat_l-P4" pos="0.0050000000000000001 0.00247 -0.0073299999999999997" />
          <site name="vasmed_l_vasmed_l-P3" pos="0.0063 0.044499999999999998 0.017000000000000001" />
          <site name="vasmed_l_vasmed_l-P4" pos="0.0050000000000000001 0.00247 0.0085000000000000006" />
          <site name="L.Patella_marker" group="4" pos="0.03147 0.02431 -0.0002454" rgba="1 0.1 0.5 0.5" size="0.01" />
        </body>
        <site name="addbrev_l_addbrev_l-P2" pos="-0.0019847611321999999 -0.11445462414419999 -0.02403487557279" />
        <site name="AB_at_femshaft_l_cylinder_addbrev_l_1_sidesite" pos="0.001317 -0.1031 -0.01353" size="0.0005" />
        <site name="addlong_l_addlong_l-P2" pos="0.011174205174286 -0.23217799475760301 -0.015280003225593001" />
        <site name="AL_at_femshaft_l_cylinder_addlong_l_1_sidesite" pos="0.01117 -0.2322 -0.01528" size="0.0005" />
        <site name="addmagDist_l_addmagDist_l-P2" pos="0.011164281368625 -0.25461304099875004 -0.018629441709030001" />
        <site name="AMdist_at_femshaft_l_cylinder_addmagDist_l_1_sidesite" pos="0.01116 -0.2546 -0.01863" size="0.0005" />
        <site name="addmagIsch_l_addmagIsch_l-P2" pos="0.0047733505229410004 -0.37631322482394297 0.031592830421583" />
        <site name="AMisch_at_condyles_l_cylinder_addmagIsch_l_1_sidesite" pos="0.004773 -0.3763 0.03159" size="0.0005" />
        <site name="addmagMid_l_addmagMid_l-P2" pos="0.0024015609699620001 -0.15752060136456 -0.028204781696262001" />
        <site name="AMmid_at_femshaft_l_cylinder_addmagMid_l_1_sidesite" pos="0.002402 -0.1575 -0.0282" size="0.0005" />
        <site name="addmagProx_l_addmagProx_l-P2" pos="-0.015153651244347002 -0.076490607288233994 -0.030907498628141999" />
        <site name="AMprox_at_femshaft_l_cylinder_addmagProx_l_1_sidesite" pos="-0.01568 -0.07136 -0.01863" size="0.0005" />
        <site name="bfsh_l_bfsh_l-P1" pos="0.0049619028305000002 -0.20475738268509 -0.02258699150214" />
        <site name="gaslat_l_gaslat_l-P1" pos="-0.0029771416983000003 -0.36994062414066003 -0.026737592504669998" />
        <site name="Gastroc_at_condyles_l_cylinder_gaslat_l_1_sidesite" pos="-0.008767 -0.4203 -0.02396" size="0.0005" />
        <site name="gasmed_l_gasmed_l-P1" pos="0.0079390445287999996 -0.36741874259172003 0.020077325779679998" />
        <site name="Gastroc_at_condyles_l_cylinder_gasmed_l_1_sidesite" pos="0.0009367 -0.418 0.01765" size="0.0005" />
        <site name="glmax1_l_glmax1_l-P3" pos="-0.044061697134840004 -0.031620514805939998 -0.029150732622420003" />
        <site name="glmax1_l_glmax1_l-P4" pos="-0.027488941680969999 -0.05489942141154 -0.045367034213700003" />
        <site name="glmax2_l_glmax2_l-P3" pos="-0.044657125474500001 -0.056645339406960003 -0.024324452386919999" />
        <site name="glmax2_l_glmax2_l-P4" pos="-0.01548113683116 -0.098547371297039998 -0.040444228373490002" />
        <site name="glmax3_l_glmax3_l-P3" pos="-0.02788589390741 -0.10911987471375001 -0.0090734068427400002" />
        <site name="glmax3_l_glmax3_l-P4" pos="-0.0059542833966000006 -0.13763653530561001 -0.039672023535810001" />
        <site name="glmed1_l_glmed1_l-P2" pos="-0.0138933279254 -0.017459179954199999 -0.0569501067789" />
        <site name="glmed2_l_glmed2_l-P2" pos="-0.0218323724542 -0.0096995444190000005 -0.054054338637600001" />
        <site name="glmed3_l_glmed3_l-P2" pos="-0.030664559492490001 -0.0045587858769300001 -0.050000263239779998" />
        <site name="glmin1_l_glmin1_l-P2" pos="0.0049619028305000002 -0.0145493166285 -0.054054338637600001" />
        <site name="glmin2_l_glmin2_l-P2" pos="0.0039695222643999998 -0.0087295899770999993 -0.050193314449199999" />
        <site name="glmin3_l_glmin3_l-P2" pos="-0.0039695222643999998 -0.00096995444190000008 -0.049228058402099997" />
        <site name="iliacus_l_iliacus_l-P3" pos="-0.0022824753020299999 -0.054802425967350001 -0.013417059054689999" />
        <site name="iliacus_l_iliacus_l-P4" pos="-0.012107042906420002 -0.061786097949030006 -0.018919018523160001" />
        <site name="piri_l_piri_l-P3" pos="-0.014687232378280001 -0.0034918359908399999 -0.042181689258270004" />
        <site name="psoas_l_psoas_l-P3" pos="-0.013099423472519999 -0.045296872436730001 -0.0044401778166600001" />
        <site name="psoas_l_psoas_l-P4" pos="-0.023320943303350002 -0.050825612755560003 -0.00849425321448" />
        <site name="KnExt_at_fem_l_cylinder_recfem_l_3_sidesite" pos="-0.01554 -0.3842 0.01365" size="0.0005" />
        <site name="sart_l_sart_l-P2" pos="-0.0029771416983000003 -0.34607974486991999 0.040637279582909996" />
        <site name="tfl_l_tfl_l-P2" pos="0.029175988643339999 -0.09651046696905001 -0.057625786011870003" />
        <site name="tfl_l_tfl_l-P3" pos="0.01061847205727 -0.39283154896950001 -0.031274295926040002" />
        <site name="vasint_l_vasint_l-P1" pos="0.028779036416900002 -0.18661923462155999 -0.0299229374601" />
        <site name="vasint_l_vasint_l-P2" pos="0.03324474896435 -0.20213850569196001 -0.027509797342350002" />
        <site name="KnExt_at_fem_l_cylinder_vasint_l_3_sidesite" pos="-0.01573 -0.3834 0.01307" size="0.0005" />
        <site name="vaslat_l_vaslat_l-P1" pos="0.0047634267172799996 -0.17982955352826002 -0.033687436043790001" />
        <site name="vaslat_l_vaslat_l-P2" pos="0.02669503722809 -0.25131519589628998 -0.039478972326389999" />
        <site name="KnExt_at_fem_l_cylinder_vaslat_l_3_sidesite" pos="-0.01792 -0.3842 -0.01423" size="0.0005" />
        <site name="vasmed_l_vasmed_l-P1" pos="0.0138933279254 -0.20359343735481 -0.01814681368548" />
        <site name="vasmed_l_vasmed_l-P2" pos="0.035328748153159999 -0.26858038496211001 -0.00086873044239000002" />
        <site name="KnExt_at_fem_l_cylinder_vasmed_l_4_sidesite" pos="-0.007683 -0.3951 0.02046" size="0.0005" />
        <site name="KnExt_at_fem_l_cylinder_vasmed_l_3_sidesite" pos="-0.007683 -0.3951 0.02046" size="0.0005" />
        <site name="L.Thigh.Superior_marker" group="4" pos="0.06582 -0.1481 -0.03519" rgba="1 0.1 0.5 0.5" size="0.01" />
        <site name="L.Thigh.Inferior_marker" group="4" pos="0.07595 -0.2941 -0.01427" rgba="1 0.1 0.5 0.5" size="0.01" />
        <site name="L.Thigh.Lateral_marker" group="4" pos="0.01904 -0.233 -0.08283" rgba="1 0.1 0.5 0.5" size="0.01" />
      </body>
      <body name="torso" pos="-0.09602 0.08119 0" euler="-0 0 0">
        <inertial mass="29.4245477259" pos="-0.0300000000 0.3200000000 0.0000000000" fullinertia="1.2672547981 0.6493123093 1.2302126267 0.0000000000 0.0000000000 0.0000000000" />
        <geom name="torso_geom_1" type="mesh" mesh="torso_geom_1_hat_spine" rgba="1 1 1 1" group="0" />
        <geom name="torso_geom_2" type="mesh" mesh="torso_geom_2_hat_jaw" rgba="1 1 1 1" group="0" />
        <geom name="torso_geom_3" type="mesh" mesh="torso_geom_3_hat_skull" rgba="1 1 1 1" group="0" />
        <geom name="torso_geom_4" type="mesh" mesh="torso_geom_4_hat_ribs_scap" rgba="1 1 1 1" group="0" />
        <joint name="lumbar_extension" range="-1.571 1.571" limited="true" user="0.0" ref="0" axis="0 0 1" type="hinge" />
        <joint name="lumbar_bending" range="-1.571 1.571" limited="true" user="0.0" ref="0" axis="1 0 0" type="hinge" />
        <joint name="lumbar_rotation" range="-1.571 1.571" limited="true" user="0.0" ref="0" axis="0 1 0" type="hinge" />
        <site name="R.Shoulder_marker" group="4" pos="0.008405 0.3484 0.1622" rgba="1 0.1 0.5 0.5" size="0.01" />
        <site name="L.Shoulder_marker" group="4" pos="0.007541 0.351 -0.1513" rgba="1 0.1 0.5 0.5" size="0.01" />
        <site name="Back_marker" group="4" pos="-0.01645 0.3371 -0.01156" rgba="1 0.1 0.5 0.5" size="0.01" />
      </body>
      <site name="addbrev_r_addbrev_r-P1" pos="-0.018212520507409999 -0.093637742442800001 0.016249061559500001" />
      <site name="addlong_r_addlong_r-P1" pos="-0.0072277960966579992 -0.088557396842180003 0.0199209274184" />
      <site name="addmagDist_r_addmagDist_r-P1" pos="-0.07059973918160399 -0.12717798486885401 0.042015430603849997" />
      <site name="addmagIsch_r_addmagIsch_r-P1" pos="-0.085455816119062 -0.12925993041891198 0.044009633613424991" />
      <site name="addmagMid_r_addmagMid_r-P1" pos="-0.050213158634565998 -0.12028465319114999 0.030113520578449997" />
      <site name="addmagProx_r_addmagProx_r-P1" pos="-0.029540517555998 -0.10713552340131001 0.014402577291375" />
      <site name="bflh_r_bflh_r-P1" pos="-0.099167650930399989 -0.11864101196742 0.061830844635499996" />
      <site name="glmax1_r_glmax1_r-P1" pos="-0.11738017143780999 0.034367043768900006 0.059404036740250001" />
      <site name="glmax1_r_glmax1_r-P2" pos="-0.11985936271107001 -0.02410673794804 0.082194928278249993" />
      <site name="Gmax1_at_pelvis_r_cylinder_glmax1_r_2_sidesite" pos="-0.1026 -0.09077 0.1043" size="0.0005" />
      <site name="glmax2_r_glmax2_r-P1" pos="-0.12558057334167 0.008666471906939999 0.048747184678499998" />
      <site name="glmax2_r_glmax2_r-P2" pos="-0.12815511812543998 -0.060665303348580002 0.085782383427749992" />
      <site name="Gmax2_at_pelvis_r_cylinder_glmax2_r_2_sidesite" pos="-0.1149 -0.09363 0.0947" size="0.0005" />
      <site name="Gmax2_at_pelvis_r_cylinder_glmax2_r_1_sidesite" pos="-0.1282 -0.06067 0.08578" size="0.0005" />
      <site name="glmax3_r_glmax3_r-P1" pos="-0.123959563663 -0.052297675300499995 0.0094962048074999986" />
      <site name="glmax3_r_glmax3_r-P2" pos="-0.12138501887922999 -0.12581326458006001 0.045898323236249997" />
      <site name="glmed1_r_glmed1_r-P1" pos="-0.046854241574745194 0.026052466408067437 0.12164466913847301" />
      <site name="glmed2_r_glmed2_r-P1" pos="-0.080790479167750825 0.054423368581171312 0.086503589064673772" />
      <site name="glmed3_r_glmed3_r-P1" pos="-0.095225545179783572 0.015499425871939025 0.067424772590991888" />
      <site name="glmin1_r_glmin1_r-P1" pos="-0.028205124719981319 -0.00010779960207246801 0.12498536331132326" />
      <site name="glmin2_r_glmin2_r-P1" pos="-0.058737761019180892 0.0099617274587798215 0.10672186454705795" />
      <site name="glmin3_r_glmin3_r-P1" pos="-0.075233919792389997 -0.0154402660411 0.084199682626499989" />
      <site name="grac_r_grac_r-P1" pos="-0.045159422577535996 -0.12882162609258399 0.025914087785799997" />
      <site name="iliacus_r_iliacus_r-P1" pos="-0.057688873858549997 0.03078091746258 0.088947785030249998" />
      <site name="iliacus_r_iliacus_r-P2" pos="-0.012872723918849999 -0.055485343128339998 0.079768120382999991" />
      <site name="IL_at_brim_r_cylinder_iliacus_r_2_sidesite" pos="-0.01728 -0.0854 0.08607" size="0.0005" />
      <site name="piri_r_piri_r-P1" pos="-0.097079409050230991 -0.0065048346611860002 0.014254858549924998" />
      <site name="piri_r_piri_r-P2" pos="-0.097279651422301994 -0.030541842375491998 0.064278755208100002" />
      <site name="psoas_r_psoas_r-P1" pos="-0.057784227369059998 0.061761064164399998 0.041150220832500001" />
      <site name="psoas_r_psoas_r-P2" pos="-0.019547469654549999 -0.065147961231480006 0.069216781707999997" />
      <site name="PS_at_brim_r_cylinder_psoas_r_2_sidesite" pos="-0.02999 -0.08832 0.07563" size="0.0005" />
      <site name="recfem_r_recfem_r-P1" pos="-0.022884842522400001 -0.038650472412559998 0.09844398983774999" />
      <site name="sart_r_sart_r-P1" pos="-0.018593934549449999 -0.015539880660719999 0.11142213640799999" />
      <site name="semimem_r_semimem_r-P1" pos="-0.094113914873369994 -0.1135606663668 0.064785219464499999" />
      <site name="semiten_r_semiten_r-P1" pos="-0.09897694390938 -0.12481711838385999 0.054339394176249993" />
      <site name="tfl_r_tfl_r-P1" pos="-0.019394699743421569 0.010809527412848362 0.13642621959962969" />
      <site name="addbrev_l_addbrev_l-P1" pos="-0.018212520507409999 -0.093637742442800001 -0.016249061559500001" />
      <site name="addlong_l_addlong_l-P1" pos="-0.0072277960966579992 -0.088557396842180003 -0.0199209274184" />
      <site name="addmagDist_l_addmagDist_l-P1" pos="-0.07059973918160399 -0.12717798486885401 -0.042015430603849997" />
      <site name="addmagIsch_l_addmagIsch_l-P1" pos="-0.085455816119062 -0.12925993041891198 -0.044009633613424991" />
      <site name="addmagMid_l_addmagMid_l-P1" pos="-0.050213158634565998 -0.12028465319114999 -0.030113520578449997" />
      <site name="addmagProx_l_addmagProx_l-P1" pos="-0.029540517555998 -0.10713552340131001 -0.014402577291375" />
      <site name="bflh_l_bflh_l-P1" pos="-0.099167650930399989 -0.11864101196742 -0.061830844635499996" />
      <site name="glmax1_l_glmax1_l-P1" pos="-0.11738017143780999 0.034367043768900006 -0.059404036740250001" />
      <site name="glmax1_l_glmax1_l-P2" pos="-0.11985936271107001 -0.02410673794804 -0.082194928278249993" />
      <site name="Gmax1_at_pelvis_l_cylinder_glmax1_l_2_sidesite" pos="-0.1026 -0.09077 -0.1043" size="0.0005" />
      <site name="glmax2_l_glmax2_l-P1" pos="-0.12558057334167 0.008666471906939999 -0.048747184678499998" />
      <site name="glmax2_l_glmax2_l-P2" pos="-0.12815511812543998 -0.060665303348580002 -0.085782383427749992" />
      <site name="Gmax2_at_pelvis_l_cylinder_glmax2_l_2_sidesite" pos="-0.1149 -0.09363 -0.0947" size="0.0005" />
      <site name="Gmax2_at_pelvis_l_cylinder_glmax2_l_1_sidesite" pos="-0.1282 -0.06067 -0.08578" size="0.0005" />
      <site name="glmax3_l_glmax3_l-P1" pos="-0.123959563663 -0.052297675300499995 -0.0094962048074999986" />
      <site name="glmax3_l_glmax3_l-P2" pos="-0.12138501887922999 -0.12581326458006001 -0.045898323236249997" />
      <site name="glmed1_l_glmed1_l-P1" pos="-0.046723220149899998 0.0258998011012 -0.1213403947625" />
      <site name="glmed2_l_glmed2_l-P1" pos="-0.081050483933500006 0.054788040790999998 -0.086520977134999996" />
      <site name="glmed3_l_glmed3_l-P1" pos="-0.095353510510000003 0.015938339139200002 -0.067528567519999999" />
      <site name="glmin1_l_glmin1_l-P1" pos="-0.028606053152999997 0 -0.12450579636499999" />
      <site name="glmin2_l_glmin2_l-P1" pos="-0.058737762474160002 0.0099614619620000001 -0.1065685206175" />
      <site name="glmin3_l_glmin3_l-P1" pos="-0.075233919792389997 -0.0154402660411 -0.084199682626499989" />
      <site name="grac_l_grac_l-P1" pos="-0.045159422577535996 -0.12882162609258399 -0.025914087785799997" />
      <site name="iliacus_l_iliacus_l-P1" pos="-0.057688873858549997 0.03078091746258 -0.088947785030249998" />
      <site name="iliacus_l_iliacus_l-P2" pos="-0.012872723918849999 -0.055485343128339998 -0.079768120382999991" />
      <site name="IL_at_brim_l_cylinder_iliacus_l_2_sidesite" pos="-0.01728 -0.0854 -0.08607" size="0.0005" />
      <site name="piri_l_piri_l-P1" pos="-0.097079409050230991 -0.0065048346611860002 -0.014254858549924998" />
      <site name="piri_l_piri_l-P2" pos="-0.097279651422301994 -0.030541842375491998 -0.064278755208100002" />
      <site name="psoas_l_psoas_l-P1" pos="-0.057784227369059998 0.061761064164399998 -0.041150220832500001" />
      <site name="psoas_l_psoas_l-P2" pos="-0.019547469654549999 -0.065147961231480006 -0.069216781707999997" />
      <site name="PS_at_brim_l_cylinder_psoas_l_2_sidesite" pos="-0.02999 -0.08832 -0.07563" size="0.0005" />
      <site name="recfem_l_recfem_l-P1" pos="-0.022884842522400001 -0.038650472412559998 -0.09844398983774999" />
      <site name="sart_l_sart_l-P1" pos="-0.018593934549449999 -0.015539880660719999 -0.11142213640799999" />
      <site name="semimem_l_semimem_l-P1" pos="-0.094113914873369994 -0.1135606663668 -0.064785219464499999" />
      <site name="semiten_l_semiten_l-P1" pos="-0.09897694390938 -0.12481711838385999 -0.054339394176249993" />
      <site name="tfl_l_tfl_l-P1" pos="-0.019070702102000001 0.010957608158199999 -0.1361122689075" />
      <site name="R.ASIS_marker" group="4" pos="0.007662 0.01307 0.1327" rgba="1 0.1 0.5 0.5" size="0.01" />
      <site name="L.ASIS_marker" group="4" pos="0.004921 0.01226 -0.1371" rgba="1 0.1 0.5 0.5" size="0.01" />
      <site name="Sacral_marker" group="4" pos="-0.1999 0.01934 -0.0005081" rgba="1 0.1 0.5 0.5" size="0.01" />
    </body>
  </worldbody>
  <asset>
    <texture type="skybox" builtin="gradient" rgb1="1 1 1" rgb2="0.6 0.8 1" width="256" height="256" />
    <mesh name="pelvis_geom_1_r_pelvis" file="Geometry/r_pelvis.stl" scale="0.95353510509999995 0.9961461962 1.0551338674999999" />
    <mesh name="pelvis_geom_2_l_pelvis" file="Geometry/l_pelvis.stl" scale="0.95353510509999995 0.9961461962 1.0551338674999999" />
    <mesh name="pelvis_geom_3_sacrum" file="Geometry/sacrum.stl" scale="0.95353510509999995 0.9961461962 1.0551338674999999" />
    <mesh name="femur_r_geom_1_r_femur" file="Geometry/r_femur.stl" scale="0.99238056610000003 0.96995444190000002 0.96525604710000001" />
    <mesh name="tibia_r_geom_1_r_tibia" file="Geometry/r_tibia.stl" scale="1.0101096192000001 1.047093767 1.0475320385" />
    <mesh name="tibia_r_geom_2_r_fibula" file="Geometry/r_fibula.stl" scale="1.0101096192000001 1.047093767 1.0475320385" />
    <mesh name="talus_r_geom_1_r_talus" file="Geometry/r_talus.stl" scale="1.0200640039 1.0527852347 1.0331821656" />
    <mesh name="calcn_r_geom_1_r_foot" file="Geometry/r_foot.stl" scale="1.0510763465999999 1.0307020415999999 1.0001633967000001" />
    <mesh name="toes_r_geom_1_r_bofoot" file="Geometry/r_bofoot.stl" scale="1.0214312235 1.0213171923 1.0216833673000001" />
    <mesh name="patella_r_geom_1_r_patella" file="Geometry/r_patella.stl" scale="1 1 1" />
    <mesh name="femur_l_geom_1_l_femur" file="Geometry/l_femur.stl" scale="0.99238056610000003 0.96995444190000002 0.96525604710000001" />
    <mesh name="tibia_l_geom_1_l_tibia" file="Geometry/l_tibia.stl" scale="1.0101096192000001 1.047093767 1.0475320385" />
    <mesh name="tibia_l_geom_2_l_fibula" file="Geometry/l_fibula.stl" scale="1.0101096192000001 1.047093767 1.0475320385" />
    <mesh name="talus_l_geom_1_l_talus" file="Geometry/l_talus.stl" scale="1.0200640039 1.0527852347 1.0331821656" />
    <mesh name="calcn_l_geom_1_l_foot" file="Geometry/l_foot.stl" scale="1.0510763465999999 1.0307020415999999 1.0001633967000001" />
    <mesh name="toes_l_geom_1_l_bofoot" file="Geometry/l_bofoot.stl" scale="1.0214312235 1.0213171923 1.0216833673000001" />
    <mesh name="patella_l_geom_1_l_patella" file="Geometry/l_patella.stl" scale="1 1 1" />
    <mesh name="torso_geom_1_hat_spine" file="Geometry/hat_spine.stl" scale="1.1321903674 0.82878672549999999 1.088499079" />
    <mesh name="torso_geom_2_hat_jaw" file="Geometry/hat_jaw.stl" scale="1.1321903674 0.82878672549999999 1.088499079" />
    <mesh name="torso_geom_3_hat_skull" file="Geometry/hat_skull.stl" scale="1.1321903674 0.82878672549999999 1.088499079" />
    <mesh name="torso_geom_4_hat_ribs_scap" file="Geometry/hat_ribs_scap.stl" scale="1.1321903674 0.82878672549999999 1.088499079" />
  </asset>
  <tendon>
    
    <spatial name="addbrev_r_tendon">
      <site site="addbrev_r_addbrev_r-P1" />
      <geom geom="AB_at_femshaft_r_cylinder" sidesite="AB_at_femshaft_r_cylinder_addbrev_r_1_sidesite" />
      <site site="addbrev_r_addbrev_r-P2" />
    </spatial>
    <spatial name="addlong_r_tendon">
      <site site="addlong_r_addlong_r-P1" />
      <geom geom="AL_at_femshaft_r_cylinder" sidesite="AL_at_femshaft_r_cylinder_addlong_r_1_sidesite" />
      <site site="addlong_r_addlong_r-P2" />
    </spatial>
    <spatial name="addmagDist_r_tendon">
      <site site="addmagDist_r_addmagDist_r-P1" />
      <geom geom="AMdist_at_femshaft_r_cylinder" sidesite="AMdist_at_femshaft_r_cylinder_addmagDist_r_1_sidesite" />
      <site site="addmagDist_r_addmagDist_r-P2" />
    </spatial>
    <spatial name="addmagIsch_r_tendon">
      <site site="addmagIsch_r_addmagIsch_r-P1" />
      <geom geom="AMisch_at_condyles_r_cylinder" sidesite="AMisch_at_condyles_r_cylinder_addmagIsch_r_1_sidesite" />
      <site site="addmagIsch_r_addmagIsch_r-P2" />
    </spatial>
    <spatial name="addmagMid_r_tendon">
      <site site="addmagMid_r_addmagMid_r-P1" />
      <geom geom="AMmid_at_femshaft_r_cylinder" sidesite="AMmid_at_femshaft_r_cylinder_addmagMid_r_1_sidesite" />
      <site site="addmagMid_r_addmagMid_r-P2" />
    </spatial>
    <spatial name="addmagProx_r_tendon">
      <site site="addmagProx_r_addmagProx_r-P1" />
      <geom geom="AMprox_at_femshaft_r_cylinder" sidesite="AMprox_at_femshaft_r_cylinder_addmagProx_r_1_sidesite" />
      <site site="addmagProx_r_addmagProx_r-P2" />
    </spatial>
    <spatial name="bflh_r_tendon">
      <site site="bflh_r_bflh_r-P1" />
      <site site="bflh_r_bflh_r-P2" />
      <site site="bflh_r_bflh_r-P3" />
    </spatial>
    <spatial name="bfsh_r_tendon">
      <site site="bfsh_r_bfsh_r-P1" />
      <site site="bfsh_r_bfsh_r-P2" />
    </spatial>
    <spatial name="edl_r_tendon">
      <site site="edl_r_edl_r-P1" />
      <site site="edl_r_edl_r-P2" />
      <site site="edl_r_edl_r-P3" />
      <site site="edl_r_edl_r-P4" />
      <site site="edl_r_edl_r-P5" />
      <site site="edl_r_edl_r-P6" />
    </spatial>
    <spatial name="ehl_r_tendon">
      <site site="ehl_r_ehl_r-P1" />
      <site site="ehl_r_ehl_r-P2" />
      <site site="ehl_r_ehl_r-P3" />
      <site site="ehl_r_ehl_r-P4" />
      <site site="ehl_r_ehl_r-P5" />
      <site site="ehl_r_ehl_r-P6" />
      <site site="ehl_r_ehl_r-P7" />
      <site site="ehl_r_ehl_r-P8" />
    </spatial>
    <spatial name="fdl_r_tendon">
      <site site="fdl_r_fdl_r-P1" />
      <site site="fdl_r_fdl_r-P2" />
      <site site="fdl_r_fdl_r-P3" />
      <site site="fdl_r_fdl_r-P4" />
      <site site="fdl_r_fdl_r-P5" />
      <site site="fdl_r_fdl_r-P6" />
      <site site="fdl_r_fdl_r-P7" />
      <site site="fdl_r_fdl_r-P8" />
    </spatial>
    <spatial name="fhl_r_tendon">
      <site site="fhl_r_fhl_r-P1" />
      <site site="fhl_r_fhl_r-P2" />
      <site site="fhl_r_fhl_r-P3" />
      <site site="fhl_r_fhl_r-P4" />
      <site site="fhl_r_fhl_r-P5" />
      <site site="fhl_r_fhl_r-P6" />
      <site site="fhl_r_fhl_r-P7" />
    </spatial>
    <spatial name="gaslat_r_tendon">
      <site site="gaslat_r_gaslat_r-P1" />
      <geom geom="Gastroc_at_condyles_r_cylinder" sidesite="Gastroc_at_condyles_r_cylinder_gaslat_r_1_sidesite" />
      <site site="gaslat_r_gaslat_r-P2" />
    </spatial>
    <spatial name="gasmed_r_tendon">
      <site site="gasmed_r_gasmed_r-P1" />
      <geom geom="Gastroc_at_condyles_r_cylinder" sidesite="Gastroc_at_condyles_r_cylinder_gasmed_r_1_sidesite" />
      <site site="gasmed_r_gasmed_r-P2" />
    </spatial>
    <spatial name="glmax1_r_tendon">
      <site site="glmax1_r_glmax1_r-P1" />
      <site site="glmax1_r_glmax1_r-P2" />
      <geom geom="Gmax1_at_pelvis_r_cylinder" sidesite="Gmax1_at_pelvis_r_cylinder_glmax1_r_2_sidesite" />
      <site site="glmax1_r_glmax1_r-P3" />
      <site site="glmax1_r_glmax1_r-P4" />
    </spatial>
    <spatial name="glmax2_r_tendon">
      <site site="glmax2_r_glmax2_r-P1" />
      <geom geom="Gmax2_at_pelvis_r_cylinder" sidesite="Gmax2_at_pelvis_r_cylinder_glmax2_r_1_sidesite" />
      <site site="glmax2_r_glmax2_r-P2" />
      <geom geom="Gmax2_at_pelvis_r_cylinder" sidesite="Gmax2_at_pelvis_r_cylinder_glmax2_r_2_sidesite" />
      <site site="glmax2_r_glmax2_r-P3" />
      <site site="glmax2_r_glmax2_r-P4" />
    </spatial>
    <spatial name="glmax3_r_tendon">
      <site site="glmax3_r_glmax3_r-P1" />
      <site site="glmax3_r_glmax3_r-P2" />
      <site site="glmax3_r_glmax3_r-P3" />
      <site site="glmax3_r_glmax3_r-P4" />
    </spatial>
    <spatial name="glmed1_r_tendon">
      <site site="glmed1_r_glmed1_r-P1" />
      <site site="glmed1_r_glmed1_r-P2_0" />
    </spatial>
    <spatial name="glmed2_r_tendon">
      <site site="glmed2_r_glmed2_r-P1" />
      <site site="glmed2_r_glmed2_r-P2_0" />
    </spatial>
    <spatial name="glmed3_r_tendon">
      <site site="glmed3_r_glmed3_r-P1" />
      <site site="glmed3_r_glmed3_r-P2_0" />
    </spatial>
    <spatial name="glmin1_r_tendon">
      <site site="glmin1_r_glmin1_r-P1" />
      <site site="glmin1_r_glmin1_r-P2" />
    </spatial>
    <spatial name="glmin2_r_tendon">
      <site site="glmin2_r_glmin2_r-P1" />
      <site site="glmin2_r_glmin2_r-P2" />
    </spatial>
    <spatial name="glmin3_r_tendon">
      <site site="glmin3_r_glmin3_r-P1" />
      <site site="glmin3_r_glmin3_r-P2" />
    </spatial>
    <spatial name="grac_r_tendon">
      <site site="grac_r_grac_r-P1" />
      <geom geom="GR_at_condyles_r_cylinder" sidesite="GR_at_condyles_r_cylinder_grac_r_1_sidesite" />
      <site site="grac_r_grac_r-P2" />
      <site site="grac_r_grac_r-P3" />
    </spatial>
    <spatial name="iliacus_r_tendon">
      <site site="iliacus_r_iliacus_r-P1" />
      <site site="iliacus_r_iliacus_r-P2" />
      <geom geom="IL_at_brim_r_cylinder" sidesite="IL_at_brim_r_cylinder_iliacus_r_2_sidesite" />
      <site site="iliacus_r_iliacus_r-P3" />
      <site site="iliacus_r_iliacus_r-P4" />
    </spatial>
    <spatial name="perbrev_r_tendon">
      <site site="perbrev_r_perbrev_r-P1" />
      <site site="perbrev_r_perbrev_r-P2" />
      <site site="perbrev_r_perbrev_r-P3" />
      <site site="perbrev_r_perbrev_r-P4" />
      <site site="perbrev_r_perbrev_r-P5" />
    </spatial>
    <spatial name="perlong_r_tendon">
      <site site="perlong_r_perlong_r-P1" />
      <site site="perlong_r_perlong_r-P2" />
      <site site="perlong_r_perlong_r-P3" />
      <site site="perlong_r_perlong_r-P4" />
      <site site="perlong_r_perlong_r-P5" />
      <site site="perlong_r_perlong_r-P6" />
      <site site="perlong_r_perlong_r-P7" />
    </spatial>
    <spatial name="piri_r_tendon">
      <site site="piri_r_piri_r-P1" />
      <site site="piri_r_piri_r-P2" />
      <site site="piri_r_piri_r-P3" />
    </spatial>
    <spatial name="psoas_r_tendon">
      <site site="psoas_r_psoas_r-P1" />
      <site site="psoas_r_psoas_r-P2" />
      <geom geom="PS_at_brim_r_cylinder" sidesite="PS_at_brim_r_cylinder_psoas_r_2_sidesite" />
      <site site="psoas_r_psoas_r-P3" />
      <site site="psoas_r_psoas_r-P4" />
    </spatial>
    <spatial name="recfem_r_tendon">
      <site site="recfem_r_recfem_r-P1" />
      <site site="recfem_r_recfem_r-P2" />
      <site site="recfem_r_recfem_r-P3" />
      <geom geom="KnExt_at_fem_r_cylinder" sidesite="KnExt_at_fem_r_cylinder_recfem_r_3_sidesite" />
      <site site="recfem_r_recfem_r-P4" />
      <site site="recfem_r_recfem_r-P5" />
    </spatial>
    <spatial name="sart_r_tendon">
      <site site="sart_r_sart_r-P1" />
      <site site="sart_r_sart_r-P2" />
      <site site="sart_r_sart_r-P3" />
      <site site="sart_r_sart_r-P4" />
      <site site="sart_r_sart_r-P5" />
    </spatial>
    <spatial name="semimem_r_tendon">
      <site site="semimem_r_semimem_r-P1" />
      <geom geom="SM_at_condyles_r_cylinder" sidesite="SM_at_condyles_r_cylinder_semimem_r_1_sidesite" />
      <site site="semimem_r_semimem_r-P2" />
    </spatial>
    <spatial name="semiten_r_tendon">
      <site site="semiten_r_semiten_r-P1" />
      <geom geom="ST_at_condyles_r_cylinder" sidesite="ST_at_condyles_r_cylinder_semiten_r_1_sidesite" />
      <site site="semiten_r_semiten_r-P2" />
      <site site="semiten_r_semiten_r-P3" />
    </spatial>
    <spatial name="soleus_r_tendon">
      <site site="soleus_r_soleus_r-P1" />
      <site site="soleus_r_soleus_r-P2" />
    </spatial>
    <spatial name="tfl_r_tendon">
      <site site="tfl_r_tfl_r-P1" />
      <site site="tfl_r_tfl_r-P2" />
      <site site="tfl_r_tfl_r-P3" />
      <site site="tfl_r_tfl_r-P4" />
    </spatial>
    <spatial name="tibant_r_tendon">
      <site site="tibant_r_tibant_r-P1" />
      <site site="tibant_r_tibant_r-P2" />
      <site site="tibant_r_tibant_r-P3" />
      <site site="tibant_r_tibant_r-P4" />
    </spatial>
    <spatial name="tibpost_r_tendon">
      <site site="tibpost_r_tibpost_r-P1" />
      <site site="tibpost_r_tibpost_r-P2" />
      <site site="tibpost_r_tibpost_r-P3" />
      <site site="tibpost_r_tibpost_r-P4" />
    </spatial>
    <spatial name="vasint_r_tendon">
      <site site="vasint_r_vasint_r-P1" />
      <site site="vasint_r_vasint_r-P2" />
      <site site="vasint_r_vasint_r-P3" />
      <geom geom="KnExt_at_fem_r_cylinder" sidesite="KnExt_at_fem_r_cylinder_vasint_r_3_sidesite" />
      <site site="vasint_r_vasint_r-P4" />
      <site site="vasint_r_vasint_r-P5" />
    </spatial>
    <spatial name="vaslat_r_tendon">
      <site site="vaslat_r_vaslat_r-P1" />
      <site site="vaslat_r_vaslat_r-P2" />
      <site site="vaslat_r_vaslat_r-P3" />
      <geom geom="KnExt_at_fem_r_cylinder" sidesite="KnExt_at_fem_r_cylinder_vaslat_r_3_sidesite" />
      <site site="vaslat_r_vaslat_r-P4" />
      <site site="vaslat_r_vaslat_r-P5" />
    </spatial>
    <spatial name="vasmed_r_tendon">
      <site site="vasmed_r_vasmed_r-P1" />
      <site site="vasmed_r_vasmed_r-P2" />
      <site site="vasmed_r_vasmed_r-P3" />
      <geom geom="KnExt_at_fem_r_cylinder" sidesite="KnExt_at_fem_r_cylinder_vasmed_r_3_sidesite" />
      <site site="vasmed_r_vasmed_r-P4" />
      <geom geom="KnExt_at_fem_r_cylinder" sidesite="KnExt_at_fem_r_cylinder_vasmed_r_4_sidesite" />
      <site site="vasmed_r_vasmed_r-P5" />
    </spatial>
    <spatial name="addbrev_l_tendon">
      <site site="addbrev_l_addbrev_l-P1" />
      <geom geom="AB_at_femshaft_l_cylinder" sidesite="AB_at_femshaft_l_cylinder_addbrev_l_1_sidesite" />
      <site site="addbrev_l_addbrev_l-P2" />
    </spatial>
    <spatial name="addlong_l_tendon">
      <site site="addlong_l_addlong_l-P1" />
      <geom geom="AL_at_femshaft_l_cylinder" sidesite="AL_at_femshaft_l_cylinder_addlong_l_1_sidesite" />
      <site site="addlong_l_addlong_l-P2" />
    </spatial>
    <spatial name="addmagDist_l_tendon">
      <site site="addmagDist_l_addmagDist_l-P1" />
      <geom geom="AMdist_at_femshaft_l_cylinder" sidesite="AMdist_at_femshaft_l_cylinder_addmagDist_l_1_sidesite" />
      <site site="addmagDist_l_addmagDist_l-P2" />
    </spatial>
    <spatial name="addmagIsch_l_tendon">
      <site site="addmagIsch_l_addmagIsch_l-P1" />
      <geom geom="AMisch_at_condyles_l_cylinder" sidesite="AMisch_at_condyles_l_cylinder_addmagIsch_l_1_sidesite" />
      <site site="addmagIsch_l_addmagIsch_l-P2" />
    </spatial>
    <spatial name="addmagMid_l_tendon">
      <site site="addmagMid_l_addmagMid_l-P1" />
      <geom geom="AMmid_at_femshaft_l_cylinder" sidesite="AMmid_at_femshaft_l_cylinder_addmagMid_l_1_sidesite" />
      <site site="addmagMid_l_addmagMid_l-P2" />
    </spatial>
    <spatial name="addmagProx_l_tendon">
      <site site="addmagProx_l_addmagProx_l-P1" />
      <geom geom="AMprox_at_femshaft_l_cylinder" sidesite="AMprox_at_femshaft_l_cylinder_addmagProx_l_1_sidesite" />
      <site site="addmagProx_l_addmagProx_l-P2" />
    </spatial>
    <spatial name="bflh_l_tendon">
      <site site="bflh_l_bflh_l-P1" />
      <site site="bflh_l_bflh_l-P2" />
      <site site="bflh_l_bflh_l-P3" />
    </spatial>
    <spatial name="bfsh_l_tendon">
      <site site="bfsh_l_bfsh_l-P1" />
      <site site="bfsh_l_bfsh_l-P2" />
    </spatial>
    <spatial name="edl_l_tendon">
      <site site="edl_l_edl_l-P1" />
      <site site="edl_l_edl_l-P2" />
      <site site="edl_l_edl_l-P3" />
      <site site="edl_l_edl_l-P4" />
      <site site="edl_l_edl_l-P5" />
      <site site="edl_l_edl_l-P6" />
    </spatial>
    <spatial name="ehl_l_tendon">
      <site site="ehl_l_ehl_l-P1" />
      <site site="ehl_l_ehl_l-P2" />
      <site site="ehl_l_ehl_l-P3" />
      <site site="ehl_l_ehl_l-P4" />
      <site site="ehl_l_ehl_l-P5" />
      <site site="ehl_l_ehl_l-P6" />
      <site site="ehl_l_ehl_l-P7" />
      <site site="ehl_l_ehl_l-P8" />
    </spatial>
    <spatial name="fdl_l_tendon">
      <site site="fdl_l_fdl_l-P1" />
      <site site="fdl_l_fdl_l-P2" />
      <site site="fdl_l_fdl_l-P3" />
      <site site="fdl_l_fdl_l-P4" />
      <site site="fdl_l_fdl_l-P5" />
      <site site="fdl_l_fdl_l-P6" />
      <site site="fdl_l_fdl_l-P7" />
      <site site="fdl_l_fdl_l-P8" />
    </spatial>
    <spatial name="fhl_l_tendon">
      <site site="fhl_l_fhl_l-P1" />
      <site site="fhl_l_fhl_l-P2" />
      <site site="fhl_l_fhl_l-P3" />
      <site site="fhl_l_fhl_l-P4" />
      <site site="fhl_l_fhl_l-P5" />
      <site site="fhl_l_fhl_l-P6" />
      <site site="fhl_l_fhl_l-P7" />
    </spatial>
    <spatial name="gaslat_l_tendon">
      <site site="gaslat_l_gaslat_l-P1" />
      <geom geom="Gastroc_at_condyles_l_cylinder" sidesite="Gastroc_at_condyles_l_cylinder_gaslat_l_1_sidesite" />
      <site site="gaslat_l_gaslat_l-P2" />
    </spatial>
    <spatial name="gasmed_l_tendon">
      <site site="gasmed_l_gasmed_l-P1" />
      <geom geom="Gastroc_at_condyles_l_cylinder" sidesite="Gastroc_at_condyles_l_cylinder_gasmed_l_1_sidesite" />
      <site site="gasmed_l_gasmed_l-P2" />
    </spatial>
    <spatial name="glmax1_l_tendon">
      <site site="glmax1_l_glmax1_l-P1" />
      <site site="glmax1_l_glmax1_l-P2" />
      <geom geom="Gmax1_at_pelvis_l_cylinder" sidesite="Gmax1_at_pelvis_l_cylinder_glmax1_l_2_sidesite" />
      <site site="glmax1_l_glmax1_l-P3" />
      <site site="glmax1_l_glmax1_l-P4" />
    </spatial>
    <spatial name="glmax2_l_tendon">
      <site site="glmax2_l_glmax2_l-P1" />
      <geom geom="Gmax2_at_pelvis_l_cylinder" sidesite="Gmax2_at_pelvis_l_cylinder_glmax2_l_1_sidesite" />
      <site site="glmax2_l_glmax2_l-P2" />
      <geom geom="Gmax2_at_pelvis_l_cylinder" sidesite="Gmax2_at_pelvis_l_cylinder_glmax2_l_2_sidesite" />
      <site site="glmax2_l_glmax2_l-P3" />
      <site site="glmax2_l_glmax2_l-P4" />
    </spatial>
    <spatial name="glmax3_l_tendon">
      <site site="glmax3_l_glmax3_l-P1" />
      <site site="glmax3_l_glmax3_l-P2" />
      <site site="glmax3_l_glmax3_l-P3" />
      <site site="glmax3_l_glmax3_l-P4" />
    </spatial>
    <spatial name="glmed1_l_tendon">
      <site site="glmed1_l_glmed1_l-P1" />
      <site site="glmed1_l_glmed1_l-P2" />
    </spatial>
    <spatial name="glmed2_l_tendon">
      <site site="glmed2_l_glmed2_l-P1" />
      <site site="glmed2_l_glmed2_l-P2" />
    </spatial>
    <spatial name="glmed3_l_tendon">
      <site site="glmed3_l_glmed3_l-P1" />
      <site site="glmed3_l_glmed3_l-P2" />
    </spatial>
    <spatial name="glmin1_l_tendon">
      <site site="glmin1_l_glmin1_l-P1" />
      <site site="glmin1_l_glmin1_l-P2" />
    </spatial>
    <spatial name="glmin2_l_tendon">
      <site site="glmin2_l_glmin2_l-P1" />
      <site site="glmin2_l_glmin2_l-P2" />
    </spatial>
    <spatial name="glmin3_l_tendon">
      <site site="glmin3_l_glmin3_l-P1" />
      <site site="glmin3_l_glmin3_l-P2" />
    </spatial>
    <spatial name="grac_l_tendon">
      <site site="grac_l_grac_l-P1" />
      <geom geom="GR_at_condyles_l_cylinder" sidesite="GR_at_condyles_l_cylinder_grac_l_1_sidesite" />
      <site site="grac_l_grac_l-P2" />
      <site site="grac_l_grac_l-P3" />
    </spatial>
    <spatial name="iliacus_l_tendon">
      <site site="iliacus_l_iliacus_l-P1" />
      <site site="iliacus_l_iliacus_l-P2" />
      <geom geom="IL_at_brim_l_cylinder" sidesite="IL_at_brim_l_cylinder_iliacus_l_2_sidesite" />
      <site site="iliacus_l_iliacus_l-P3" />
      <site site="iliacus_l_iliacus_l-P4" />
    </spatial>
    <spatial name="perbrev_l_tendon">
      <site site="perbrev_l_perbrev_l-P1" />
      <site site="perbrev_l_perbrev_l-P2" />
      <site site="perbrev_l_perbrev_l-P3" />
      <site site="perbrev_l_perbrev_l-P4" />
      <site site="perbrev_l_perbrev_l-P5" />
    </spatial>
    <spatial name="perlong_l_tendon">
      <site site="perlong_l_perlong_l-P1" />
      <site site="perlong_l_perlong_l-P2" />
      <site site="perlong_l_perlong_l-P3" />
      <site site="perlong_l_perlong_l-P4" />
      <site site="perlong_l_perlong_l-P5" />
      <site site="perlong_l_perlong_l-P6" />
      <site site="perlong_l_perlong_l-P7" />
    </spatial>
    <spatial name="piri_l_tendon">
      <site site="piri_l_piri_l-P1" />
      <site site="piri_l_piri_l-P2" />
      <site site="piri_l_piri_l-P3" />
    </spatial>
    <spatial name="psoas_l_tendon">
      <site site="psoas_l_psoas_l-P1" />
      <site site="psoas_l_psoas_l-P2" />
      <geom geom="PS_at_brim_l_cylinder" sidesite="PS_at_brim_l_cylinder_psoas_l_2_sidesite" />
      <site site="psoas_l_psoas_l-P3" />
      <site site="psoas_l_psoas_l-P4" />
    </spatial>
    <spatial name="recfem_l_tendon">
      <site site="recfem_l_recfem_l-P1" />
      <site site="recfem_l_recfem_l-P2" />
      <site site="recfem_l_recfem_l-P3" />
      <geom geom="KnExt_at_fem_l_cylinder" sidesite="KnExt_at_fem_l_cylinder_recfem_l_3_sidesite" />
      <site site="recfem_l_recfem_l-P4" />
      <site site="recfem_l_recfem_l-P5" />
    </spatial>
    <spatial name="sart_l_tendon">
      <site site="sart_l_sart_l-P1" />
      <site site="sart_l_sart_l-P2" />
      <site site="sart_l_sart_l-P3" />
      <site site="sart_l_sart_l-P4" />
      <site site="sart_l_sart_l-P5" />
    </spatial>
    <spatial name="semimem_l_tendon">
      <site site="semimem_l_semimem_l-P1" />
      <geom geom="SM_at_condyles_l_cylinder" sidesite="SM_at_condyles_l_cylinder_semimem_l_1_sidesite" />
      <site site="semimem_l_semimem_l-P2" />
    </spatial>
    <spatial name="semiten_l_tendon">
      <site site="semiten_l_semiten_l-P1" />
      <geom geom="ST_at_condyles_l_cylinder" sidesite="ST_at_condyles_l_cylinder_semiten_l_1_sidesite" />
      <site site="semiten_l_semiten_l-P2" />
      <site site="semiten_l_semiten_l-P3" />
    </spatial>
    <spatial name="soleus_l_tendon">
      <site site="soleus_l_soleus_l-P1" />
      <site site="soleus_l_soleus_l-P2" />
    </spatial>
    <spatial name="tfl_l_tendon">
      <site site="tfl_l_tfl_l-P1" />
      <site site="tfl_l_tfl_l-P2" />
      <site site="tfl_l_tfl_l-P3" />
      <site site="tfl_l_tfl_l-P4" />
    </spatial>
    <spatial name="tibant_l_tendon">
      <site site="tibant_l_tibant_l-P1" />
      <site site="tibant_l_tibant_l-P2" />
      <site site="tibant_l_tibant_l-P3" />
      <site site="tibant_l_tibant_l-P4" />
    </spatial>
    <spatial name="tibpost_l_tendon">
      <site site="tibpost_l_tibpost_l-P1" />
      <site site="tibpost_l_tibpost_l-P2" />
      <site site="tibpost_l_tibpost_l-P3" />
      <site site="tibpost_l_tibpost_l-P4" />
    </spatial>
    <spatial name="vasint_l_tendon">
      <site site="vasint_l_vasint_l-P1" />
      <site site="vasint_l_vasint_l-P2" />
      <site site="vasint_l_vasint_l-P3" />
      <geom geom="KnExt_at_fem_l_cylinder" sidesite="KnExt_at_fem_l_cylinder_vasint_l_3_sidesite" />
      <site site="vasint_l_vasint_l-P4" />
      <site site="vasint_l_vasint_l-P5" />
    </spatial>
    <spatial name="vaslat_l_tendon">
      <site site="vaslat_l_vaslat_l-P1" />
      <site site="vaslat_l_vaslat_l-P2" />
      <site site="vaslat_l_vaslat_l-P3" />
      <geom geom="KnExt_at_fem_l_cylinder" sidesite="KnExt_at_fem_l_cylinder_vaslat_l_3_sidesite" />
      <site site="vaslat_l_vaslat_l-P4" />
      <site site="vaslat_l_vaslat_l-P5" />
    </spatial>
    <spatial name="vasmed_l_tendon">
      <site site="vasmed_l_vasmed_l-P1" />
      <site site="vasmed_l_vasmed_l-P2" />
      <site site="vasmed_l_vasmed_l-P3" />
      <geom geom="KnExt_at_fem_l_cylinder" sidesite="KnExt_at_fem_l_cylinder_vasmed_l_3_sidesite" />
      <site site="vasmed_l_vasmed_l-P4" />
      <geom geom="KnExt_at_fem_l_cylinder" sidesite="KnExt_at_fem_l_cylinder_vasmed_l_4_sidesite" />
      <site site="vasmed_l_vasmed_l-P5" />
    </spatial>
  </tendon>
  <actuator>
    
    <motor name="lumbar_ext" ctrllimited="false" joint="lumbar_extension" class="motor" />
    <motor name="lumbar_bend" ctrllimited="false" joint="lumbar_bending" class="motor" />
    <motor name="lumbar_rot" ctrllimited="false" joint="lumbar_rotation" class="motor" />
    <muscle name="addbrev_r" lengthrange="0.01 1" force="625.81967213114797" tendon="addbrev_r_tendon" class="muscle" timeconst="0.01 0.04" />
    <muscle name="addlong_r" lengthrange="0.01 1" force="916.79999999999995" tendon="addlong_r_tendon" class="muscle" timeconst="0.01 0.04" />
    <muscle name="addmagDist_r" lengthrange="0.01 1" force="597.29508196721395" tendon="addmagDist_r_tendon" class="muscle" timeconst="0.01 0.04" />
    <muscle name="addmagIsch_r" lengthrange="0.01 1" force="597.29508196721395" tendon="addmagIsch_r_tendon" class="muscle" timeconst="0.01 0.04" />
    <muscle name="addmagMid_r" lengthrange="0.01 1" force="597.29508196721395" tendon="addmagMid_r_tendon" class="muscle" timeconst="0.01 0.04" />
    <muscle name="addmagProx_r" lengthrange="0.01 1" force="597.29508196721395" tendon="addmagProx_r_tendon" class="muscle" timeconst="0.01 0.04" />
    <muscle name="bflh_r" lengthrange="0.01 1" force="1313.18360655738" tendon="bflh_r_tendon" class="muscle" timeconst="0.01 0.04" />
    <muscle name="bfsh_r" lengthrange="0.01 1" force="557.11475409835998" tendon="bfsh_r_tendon" class="muscle" timeconst="0.01 0.04" />
    <muscle name="edl_r" lengthrange="0.01 1" force="603.49815560000002" tendon="edl_r_tendon" class="muscle" timeconst="0.01 0.04" />
    <muscle name="ehl_r" lengthrange="0.01 1" force="285.86754739999998" tendon="ehl_r_tendon" class="muscle" timeconst="0.01 0.04" />
    <muscle name="fdl_r" lengthrange="0.01 1" force="423.17704918032803" tendon="fdl_r_tendon" class="muscle" timeconst="0.01 0.04" />
    <muscle name="fhl_r" lengthrange="0.01 1" force="907.83934426229405" tendon="fhl_r_tendon" class="muscle" timeconst="0.01 0.04" />
    <muscle name="gaslat_r" lengthrange="0.01 1" force="1575.0590163934401" tendon="gaslat_r_tendon" class="muscle" timeconst="0.01 0.04" />
    <muscle name="gasmed_r" lengthrange="0.01 1" force="3115.5147540983598" tendon="gasmed_r_tendon" class="muscle" timeconst="0.01 0.04" />
    <muscle name="glmax1_r" lengthrange="0.01 1" force="983.78360655737799" tendon="glmax1_r_tendon" class="muscle" timeconst="0.01 0.04" />
    <muscle name="glmax2_r" lengthrange="0.01 1" force="1406.0459016393499" tendon="glmax2_r_tendon" class="muscle" timeconst="0.01 0.04" />
    <muscle name="glmax3_r" lengthrange="0.01 1" force="947.75409836065603" tendon="glmax3_r_tendon" class="muscle" timeconst="0.01 0.04" />
    <muscle name="glmed1_r" lengthrange="0.01 1" force="1093.4667688" tendon="glmed1_r_tendon" class="muscle" timeconst="0.01 0.04" />
    <muscle name="glmed2_r" lengthrange="0.01 1" force="765.09166159999995" tendon="glmed2_r_tendon" class="muscle" timeconst="0.01 0.04" />
    <muscle name="glmed3_r" lengthrange="0.01 1" force="871.19926420000002" tendon="glmed3_r_tendon" class="muscle" timeconst="0.01 0.04" />
    <muscle name="glmin1_r" lengthrange="0.01 1" force="374.04590163934398" tendon="glmin1_r_tendon" class="muscle" timeconst="0.01 0.04" />
    <muscle name="glmin2_r" lengthrange="0.01 1" force="394.81967213114802" tendon="glmin2_r_tendon" class="muscle" timeconst="0.01 0.04" />
    <muscle name="glmin3_r" lengthrange="0.01 1" force="446.77377049180399" tendon="glmin3_r_tendon" class="muscle" timeconst="0.01 0.04" />
    <muscle name="grac_r" lengthrange="0.01 1" force="281.31147540983602" tendon="grac_r_tendon" class="muscle" timeconst="0.01 0.04" />
    <muscle name="iliacus_r" lengthrange="0.01 1" force="1021.14098360656" tendon="iliacus_r_tendon" class="muscle" timeconst="0.01 0.04" />
    <muscle name="perbrev_r" lengthrange="0.01 1" force="521.20159880000006" tendon="perbrev_r_tendon" class="muscle" timeconst="0.01 0.04" />
    <muscle name="perlong_r" lengthrange="0.01 1" force="1115.3714213999999" tendon="perlong_r_tendon" class="muscle" timeconst="0.01 0.04" />
    <muscle name="piri_r" lengthrange="0.01 1" force="1029.7868852459001" tendon="piri_r_tendon" class="muscle" timeconst="0.01 0.04" />
    <muscle name="psoas_r" lengthrange="0.01 1" force="1426.79016393443" tendon="psoas_r_tendon" class="muscle" timeconst="0.01 0.04" />
    <muscle name="recfem_r" lengthrange="0.01 1" force="2191.7409836065599" tendon="recfem_r_tendon" class="muscle" timeconst="0.01 0.04" />
    <muscle name="sart_r" lengthrange="0.01 1" force="249.41311475409799" tendon="sart_r_tendon" class="muscle" timeconst="0.01 0.04" />
    <muscle name="semimem_r" lengthrange="0.01 1" force="2200.9868852458999" tendon="semimem_r_tendon" class="muscle" timeconst="0.01 0.04" />
    <muscle name="semiten_r" lengthrange="0.01 1" force="591.29508196721395" tendon="semiten_r_tendon" class="muscle" timeconst="0.01 0.04" />
    <muscle name="soleus_r" lengthrange="0.01 1" force="6194.8426229508204" tendon="soleus_r_tendon" class="muscle" timeconst="0.01 0.04" />
    <muscle name="tfl_r" lengthrange="0.01 1" force="411.20655737704999" tendon="tfl_r_tendon" class="muscle" timeconst="0.01 0.04" />
    <muscle name="tibant_r" lengthrange="0.01 1" force="1227.4524590163901" tendon="tibant_r_tendon" class="muscle" timeconst="0.01 0.04" />
    <muscle name="tibpost_r" lengthrange="0.01 1" force="1730.1540983606501" tendon="tibpost_r_tendon" class="muscle" timeconst="0.01 0.04" />
    <muscle name="vasint_r" lengthrange="0.01 1" force="1697.36065573771" tendon="vasint_r_tendon" class="muscle" timeconst="0.01 0.04" />
    <muscle name="vaslat_r" lengthrange="0.01 1" force="5148.7672131147601" tendon="vaslat_r_tendon" class="muscle" timeconst="0.01 0.04" />
    <muscle name="vasmed_r" lengthrange="0.01 1" force="2747.82295081966" tendon="vasmed_r_tendon" class="muscle" timeconst="0.01 0.04" />
    <muscle name="addbrev_l" lengthrange="0.01 1" force="625.81967213114797" tendon="addbrev_l_tendon" class="muscle" timeconst="0.01 0.04" />
    <muscle name="addlong_l" lengthrange="0.01 1" force="916.79999999999995" tendon="addlong_l_tendon" class="muscle" timeconst="0.01 0.04" />
    <muscle name="addmagDist_l" lengthrange="0.01 1" force="597.29508196721395" tendon="addmagDist_l_tendon" class="muscle" timeconst="0.01 0.04" />
    <muscle name="addmagIsch_l" lengthrange="0.01 1" force="597.29508196721395" tendon="addmagIsch_l_tendon" class="muscle" timeconst="0.01 0.04" />
    <muscle name="addmagMid_l" lengthrange="0.01 1" force="597.29508196721395" tendon="addmagMid_l_tendon" class="muscle" timeconst="0.01 0.04" />
    <muscle name="addmagProx_l" lengthrange="0.01 1" force="597.29508196721395" tendon="addmagProx_l_tendon" class="muscle" timeconst="0.01 0.04" />
    <muscle name="bflh_l" lengthrange="0.01 1" force="1313.18360655738" tendon="bflh_l_tendon" class="muscle" timeconst="0.01 0.04" />
    <muscle name="bfsh_l" lengthrange="0.01 1" force="557.11475409835998" tendon="bfsh_l_tendon" class="muscle" timeconst="0.01 0.04" />
    <muscle name="edl_l" lengthrange="0.01 1" force="603.49815560000002" tendon="edl_l_tendon" class="muscle" timeconst="0.01 0.04" />
    <muscle name="ehl_l" lengthrange="0.01 1" force="285.86754739999998" tendon="ehl_l_tendon" class="muscle" timeconst="0.01 0.04" />
    <muscle name="fdl_l" lengthrange="0.01 1" force="423.17704918032803" tendon="fdl_l_tendon" class="muscle" timeconst="0.01 0.04" />
    <muscle name="fhl_l" lengthrange="0.01 1" force="907.83934426229405" tendon="fhl_l_tendon" class="muscle" timeconst="0.01 0.04" />
    <muscle name="gaslat_l" lengthrange="0.01 1" force="1575.0590163934401" tendon="gaslat_l_tendon" class="muscle" timeconst="0.01 0.04" />
    <muscle name="gasmed_l" lengthrange="0.01 1" force="3115.5147540983598" tendon="gasmed_l_tendon" class="muscle" timeconst="0.01 0.04" />
    <muscle name="glmax1_l" lengthrange="0.01 1" force="983.78360655737799" tendon="glmax1_l_tendon" class="muscle" timeconst="0.01 0.04" />
    <muscle name="glmax2_l" lengthrange="0.01 1" force="1406.0459016393499" tendon="glmax2_l_tendon" class="muscle" timeconst="0.01 0.04" />
    <muscle name="glmax3_l" lengthrange="0.01 1" force="947.75409836065603" tendon="glmax3_l_tendon" class="muscle" timeconst="0.01 0.04" />
    <muscle name="glmed1_l" lengthrange="0.01 1" force="1093.4667688" tendon="glmed1_l_tendon" class="muscle" timeconst="0.01 0.04" />
    <muscle name="glmed2_l" lengthrange="0.01 1" force="765.09166159999995" tendon="glmed2_l_tendon" class="muscle" timeconst="0.01 0.04" />
    <muscle name="glmed3_l" lengthrange="0.01 1" force="871.19926420000002" tendon="glmed3_l_tendon" class="muscle" timeconst="0.01 0.04" />
    <muscle name="glmin1_l" lengthrange="0.01 1" force="374.04590163934398" tendon="glmin1_l_tendon" class="muscle" timeconst="0.01 0.04" />
    <muscle name="glmin2_l" lengthrange="0.01 1" force="394.81967213114802" tendon="glmin2_l_tendon" class="muscle" timeconst="0.01 0.04" />
    <muscle name="glmin3_l" lengthrange="0.01 1" force="446.77377049180399" tendon="glmin3_l_tendon" class="muscle" timeconst="0.01 0.04" />
    <muscle name="grac_l" lengthrange="0.01 1" force="281.31147540983602" tendon="grac_l_tendon" class="muscle" timeconst="0.01 0.04" />
    <muscle name="iliacus_l" lengthrange="0.01 1" force="1021.14098360656" tendon="iliacus_l_tendon" class="muscle" timeconst="0.01 0.04" />
    <muscle name="perbrev_l" lengthrange="0.01 1" force="521.20159880000006" tendon="perbrev_l_tendon" class="muscle" timeconst="0.01 0.04" />
    <muscle name="perlong_l" lengthrange="0.01 1" force="1115.3714213999999" tendon="perlong_l_tendon" class="muscle" timeconst="0.01 0.04" />
    <muscle name="piri_l" lengthrange="0.01 1" force="1029.7868852459001" tendon="piri_l_tendon" class="muscle" timeconst="0.01 0.04" />
    <muscle name="psoas_l" lengthrange="0.01 1" force="1426.79016393443" tendon="psoas_l_tendon" class="muscle" timeconst="0.01 0.04" />
    <muscle name="recfem_l" lengthrange="0.01 1" force="2191.7409836065599" tendon="recfem_l_tendon" class="muscle" timeconst="0.01 0.04" />
    <muscle name="sart_l" lengthrange="0.01 1" force="249.41311475409799" tendon="sart_l_tendon" class="muscle" timeconst="0.01 0.04" />
    <muscle name="semimem_l" lengthrange="0.01 1" force="2200.9868852458999" tendon="semimem_l_tendon" class="muscle" timeconst="0.01 0.04" />
    <muscle name="semiten_l" lengthrange="0.01 1" force="591.29508196721395" tendon="semiten_l_tendon" class="muscle" timeconst="0.01 0.04" />
    <muscle name="soleus_l" lengthrange="0.01 1" force="6194.8426229508204" tendon="soleus_l_tendon" class="muscle" timeconst="0.01 0.04" />
    <muscle name="tfl_l" lengthrange="0.01 1" force="411.20655737704999" tendon="tfl_l_tendon" class="muscle" timeconst="0.01 0.04" />
    <muscle name="tibant_l" lengthrange="0.01 1" force="1227.4524590163901" tendon="tibant_l_tendon" class="muscle" timeconst="0.01 0.04" />
    <muscle name="tibpost_l" lengthrange="0.01 1" force="1730.1540983606501" tendon="tibpost_l_tendon" class="muscle" timeconst="0.01 0.04" />
    <muscle name="vasint_l" lengthrange="0.01 1" force="1697.36065573771" tendon="vasint_l_tendon" class="muscle" timeconst="0.01 0.04" />
    <muscle name="vaslat_l" lengthrange="0.01 1" force="5148.7672131147601" tendon="vaslat_l_tendon" class="muscle" timeconst="0.01 0.04" />
    <muscle name="vasmed_l" lengthrange="0.01 1" force="2747.82295081966" tendon="vasmed_l_tendon" class="muscle" timeconst="0.01 0.04" />
  </actuator>
  <equality>
    
    <joint joint1="walker_knee_r_translation1" joint2="knee_angle_r" polycoef="9.251e-08 0.003035 -0.002239 0.0005447 5.513e-07" solimp="0.9999 0.9999 0.001 0.5 2" active="true" />
    <joint joint1="walker_knee_r_translation2" joint2="knee_angle_r" polycoef="7.425e-11 0.005675 -0.001213 -2.527e-06 6.027e-07" solimp="0.9999 0.9999 0.001 0.5 2" active="true" />
    <joint joint1="walker_knee_r_rotation2" joint2="knee_angle_r" polycoef="-1.473e-08 0.0791 -0.03285 -0.02522 0.01083" solimp="0.9999 0.9999 0.001 0.5 2" active="true" />
    <joint joint1="walker_knee_r_rotation3" joint2="knee_angle_r" polycoef="1.089e-08 0.3695 -0.1695 0.02516 3.505e-07" solimp="0.9999 0.9999 0.001 0.5 2" active="true" />
    <joint name="mtp_angle_r_locked" active="true" joint1="mtp_angle_r" polycoef="0.0 0 0 0 0" solimp="0.9999 0.9999 0.001 0.5 2" />
    <joint joint1="patellofemoral_r_translation1" joint2="knee_angle_r" polycoef="0.05202 -0.0149 -0.03379 0.01324 -0.0008725" solimp="0.9999 0.9999 0.001 0.5 2" active="true" />
    <joint joint1="patellofemoral_r_translation2" joint2="knee_angle_r" polycoef="-0.0105 -0.04732 0.008998 0.01277 -0.003392" solimp="0.9999 0.9999 0.001 0.5 2" active="true" />
    <joint joint1="patellofemoral_r_rotation1" joint2="knee_angle_r" polycoef="0.01051 0.02476 -1.316 0.7163 -0.1383" solimp="0.9999 0.9999 0.001 0.5 2" active="true" />
    <joint name="patellofemoral_r_translation3_locked" active="true" joint1="patellofemoral_r_translation3" polycoef="0.0026544541295249998 0 0 0 0" solimp="0.9999 0.9999 0.001 0.5 2" />
    <joint joint1="walker_knee_l_translation1" joint2="knee_angle_l" polycoef="9.251e-08 0.003035 -0.002239 0.0005447 5.513e-07" solimp="0.9999 0.9999 0.001 0.5 2" active="true" />
    <joint joint1="walker_knee_l_translation2" joint2="knee_angle_l" polycoef="-7.425e-11 -0.005675 0.001213 2.527e-06 -6.027e-07" solimp="0.9999 0.9999 0.001 0.5 2" active="true" />
    <joint joint1="walker_knee_l_rotation2" joint2="knee_angle_l" polycoef="-1.473e-08 0.0791 -0.03285 -0.02522 0.01083" solimp="0.9999 0.9999 0.001 0.5 2" active="true" />
    <joint joint1="walker_knee_l_rotation3" joint2="knee_angle_l" polycoef="-1.089e-08 -0.3695 0.1695 -0.02516 -3.505e-07" solimp="0.9999 0.9999 0.001 0.5 2" active="true" />
    <joint name="mtp_angle_l_locked" active="true" joint1="mtp_angle_l" polycoef="0.0 0 0 0 0" solimp="0.9999 0.9999 0.001 0.5 2" />
    <joint joint1="patellofemoral_l_translation1" joint2="knee_angle_l" polycoef="0.05202 -0.0149 -0.03379 0.01324 -0.0008725" solimp="0.9999 0.9999 0.001 0.5 2" active="true" />
    <joint joint1="patellofemoral_l_translation2" joint2="knee_angle_l" polycoef="-0.0105 -0.04732 0.008998 0.01277 -0.003392" solimp="0.9999 0.9999 0.001 0.5 2" active="true" />
    <joint joint1="patellofemoral_l_rotation1" joint2="knee_angle_l" polycoef="0.01051 0.02476 -1.316 0.7163 -0.1383" solimp="0.9999 0.9999 0.001 0.5 2" active="true" />
    <joint name="patellofemoral_l_translation3_locked" active="true" joint1="patellofemoral_l_translation3" polycoef="-0.0026544541295249998 0 0 0 0" solimp="0.9999 0.9999 0.001 0.5 2" />
  </equality>
  <contact>
    
    <pair geom1="ground-plane" geom2="pelvis_geom_1" />
    <pair geom1="ground-plane" geom2="pelvis_geom_2" />
    <pair geom1="ground-plane" geom2="pelvis_geom_3" />
    <pair geom1="ground-plane" geom2="femur_r_geom_1" />
    <pair geom1="ground-plane" geom2="tibia_r_geom_1" />
    <pair geom1="ground-plane" geom2="tibia_r_geom_2" />
    <pair geom1="ground-plane" geom2="talus_r_geom_1" />
    <pair geom1="ground-plane" geom2="calcn_r_geom_1" />
    <pair geom1="ground-plane" geom2="toes_r_geom_1" />
    <pair geom1="ground-plane" geom2="patella_r_geom_1" />
    <pair geom1="ground-plane" geom2="femur_l_geom_1" />
    <pair geom1="ground-plane" geom2="tibia_l_geom_1" />
    <pair geom1="ground-plane" geom2="tibia_l_geom_2" />
    <pair geom1="ground-plane" geom2="talus_l_geom_1" />
    <pair geom1="ground-plane" geom2="calcn_l_geom_1" />
    <pair geom1="ground-plane" geom2="toes_l_geom_1" />
    <pair geom1="ground-plane" geom2="patella_l_geom_1" />
    <pair geom1="ground-plane" geom2="torso_geom_1" />
    <pair geom1="ground-plane" geom2="torso_geom_2" />
    <pair geom1="ground-plane" geom2="torso_geom_3" />
    <pair geom1="ground-plane" geom2="torso_geom_4" />
  </contact>
  <keyframe>
    <key name="default-pose" qpos="0 0.93 0 0 0 0 0 0 0 9.251e-08 7.425e-11 0 -1.473e-08 1.089e-08 0 0 0 0.05202 -0.0105 0.002654 0.01051 0 -0 -0 9.251e-08 -7.425e-11 0 -1.473e-08 -1.089e-08 0 0 0 0.05202 -0.0105 -0.002654 0.01051 0 0 0" />
  </keyframe>
</mujoco>